Workbook

Sheet Смета по ТСН-2001(с доп.67
A1: =Source!B1 -> Smeta.RU (495) 974-1589
J2: Форма № 4б
A3: Капитальный ремонт здания Государственного бюджетного общеобразовательного учреждения города Москвы «Школа №1574», расположенного по адресу: г. Москва, Старопименовский переулок, д. 5. 1 этап. | AP3: Капитальный ремонт здания Государственного бюджетного общеобразовательного учреждения города Москвы «Школа №1574», расположенного по адресу: г. Москва, Старопименовский переулок, д. 5. 1 этап.
A4: (наименование стройки и/или объекта)
A6: ЛОКАЛЬНАЯ СМЕТА № 02-01-05
A8: Система водоотведения.
A9: (наименование работ и затрат)
A11: =CONCATENATE( "Основание: чертежи № ", Source!J12) -> Основание: чертежи № 2024-00375-01-01-ИОС3.
I13: В базисном уровне цен | J13: В текущем уровне цен
E14: Сметная стоимость | I14: =I15+I16+I17+I18 -> 790.07 | J14: =J15+J16+J17+J18 -> 7149.3 | K14: тыс.руб.
E15: Строительные работы | I15: =ROUND((Source!F693)/1000, 2) -> 781.6 | J15: =ROUND((Source!P693)/1000, 2) -> 7023.29 | K15: тыс.руб.
E16: Работы по монтажу оборудования | I16: =ROUND((Source!F694)/1000, 2) -> 0 | J16: =ROUND((Source!P694)/1000, 2) -> 0 | K16: тыс.руб.
E17: Оборудование | I17: =ROUND((Source!F685)/1000, 2) -> 8.47 | J17: =ROUND((Source!P685)/1000, 2) -> 126.01 | K17: тыс.руб.
E18: Прочие работы и затраты | I18: =ROUND((Source!F695+Source!F696)/1000, 2) -> 0 | J18: =ROUND((Source!P695+Source!P696)/1000, 2) -> 0 | K18: тыс.руб.
E19: Средства на оплату труда | I19: =(Source!F691+ Source!F690)/1000 -> 25.40605 | J19: =((Source!P691 + Source!P690)/1000) -> 1431.631 | K19: тыс.руб.
E20: Затраты труда | I20: =Source!F698 -> 2029.9267 | K20: чел.-ч.
E21: Кроме того:
E22: Возврат материалов | I22: =SUM(Y1:Y833)/1000 -> 0 | J22: =SUM(Z1:Z833)/1000 -> 0 | K22: тыс.руб.
A24: Составлен(а) по ТСН-2001 с учетом Дополнения №: 81
A25: № и период сборника коэффициентов (индексов) пересчета: Коэффициенты к ТСН-2001 МГЭ Дополнение 81, ремонт №219/81 I квартал 2026 года и Коэффициенты к ТСН-2001.13-2 Дополнение 47 №64/47 I квартал 2026 года | AP25: № и период сборника коэффициентов (индексов) пересчета: Коэффициенты к ТСН-2001 МГЭ Дополнение 81, ремонт №219/81 I квартал 2026 года и Коэффициенты к ТСН-2001.13-2 Дополнение 47 №64/47 I квартал 2026 года
A26: № п/п | B26: Шифр расценки и коды ресурсов | C26: Наименование работ и затрат | D26: Ед. изм. | E26: Кол-во единиц | F26: Цена на ед. изм., руб. | G26: Попра- вочные коэффи- циенты | H26: Коэффи- циенты зимних удорожа- ний | I26: Всего в ценах на январь 2000 года, руб. | J26: Коэффи- циенты (индек- сы) пере- счета, нормы НР и СП | K26: ВСЕГО затрат в текущем уровне цен, руб.
A27: 1 | B27: 2 | C27: 3 | D27: 4 | E27: 5 | F27: 6 | G27: 7 | H27: 8 | I27: 9 | J27: 10 | K27: 11
A29: =CONCATENATE("Локальная смета: ",IF(Source!G20<>"Новая локальная смета", Source!G20, "")) -> Локальная смета: Система водоотведения.
A31: =CONCATENATE("Раздел: ",IF(Source!G24<>"Новый раздел", Source!G24, "")) -> Раздел: Демонтажные работы.
A32: 1 | B32: =Source!F28 -> 6.65-1-2 | C32: Разборка трубопроводов из водогазопроводных труб диаметром до 40 мм | D32: =Source!H28 -> 100 м | E32: =Source!I28 -> 0.38 | Q32: =Source!X28 -> 205.9 | R32: =Source!X29 -> 11602.62 | S32: =Source!Y28 -> 104.13 | T32: =Source!Y29 -> 5867.99 | U32: =ROUND((175/100)*ROUND(Source!R28, 2), 2) -> 0 | V32: =ROUND((0/100)*ROUND(Source!R29, 2), 2) -> 0 | AC32: 0
C33: ="Объем: "&Source!I28&"=(30+"&"8)/"&"100" -> Объем: 0,38=(30+8)/100
C34: ЗП | F34: =Source!AO28 -> 495.71 | G34: 1,2 | H34: =Source!AV29 -> 1.047 | I34: =Source!S28 -> 236.67 | J34: =IF(Source!BA29<> 0, Source!BA29, 1) -> 56.35 | K34: =Source!S29 -> 13336.35
C35: ЭМ | F35: =Source!AM28 -> 1.26 | G35: 1,2 | H35: =Source!AV29 -> 1.047 | I35: =Source!Q28 -> 0.6 | J35: =IF(Source!BB29<> 0, Source!BB29, 1) -> 9.29 | K35: =Source!Q29 -> 5.57
C36: МР | F36: =Source!AL28 -> 46.16 | H36: =Source!AW29 -> 1 | I36: =Source!P28 -> 17.54 | J36: =IF(Source!BC29<> 0, Source!BC29, 1) -> 15.53 | K36: =Source!P29 -> 272.4
C37: НР от ФОТ | D37: % | E37: =Source!BZ29 -> 87 | I37: =SUM(Q32:Q36) -> 205.9 | J37: =Source!AT29 -> 87 | K37: =SUM(R32:R36) -> 11602.62
C38: СП от ФОТ | D38: % | E38: =Source!CA29 -> 44 | I38: =SUM(S32:S37) -> 104.13 | J38: =Source!AU29 -> 44 | K38: =SUM(T32:T37) -> 5867.99
C39: ЗТР | D39: чел-ч | E39: =Source!AQ28 -> 45.52 | G39: 1,2 | H39: =Source!AV29 -> 1.047 | I39: =Source!U28 -> 21.732705
C40: ВСЕГО работ по позиции: | H40: =I34+I35+I36+I37+I38+0-0-0 -> 564.84 | J40: =K34+K35+K36+K37+K38+0-0-0 -> 31084.93
C41: ВСЕГО оборудование по позиции: | H41: =0+0 -> 0 | J41: =0+0 -> 0
C42: ВСЕГО по позиции: | H42: =I34+I35+I36+I37+I38+0 -> 564.84 | J42: =K34+K35+K36+K37+K38+0 -> 31084.93 | O42: =I34+I35+I36+I37+I38+0 -> 564.84 | P42: =K34+K35+K36+K37+K38+0 -> 31084.93
A44: 2 | B44: =Source!F30 -> 6.65-11-5 | C44: Разборка трубопроводов центрального отопления на сварке диаметром труб до 100 мм | D44: =Source!H30 -> 100 м | E44: =Source!I30 -> 0.15 | Q44: =Source!X30 -> 110.12 | R44: =Source!X31 -> 6205.52 | S44: =Source!Y30 -> 55.7 | T44: =Source!Y31 -> 3138.42 | U44: =ROUND((175/100)*ROUND(Source!R30, 2), 2) -> 0 | V44: =ROUND((0/100)*ROUND(Source!R31, 2), 2) -> 0 | AC44: 0
C45: ="Объем: "&Source!I30&"=15/"&"100" -> Объем: 0,15=15/100
C46: ЗП | F46: =Source!AO30 -> 819.08 | G46: 0,82*1,2 | H46: =Source!AV31 -> 1.047 | I46: =Source!S30 -> 126.58 | J46: =IF(Source!BA31<> 0, Source!BA31, 1) -> 56.35 | K46: =Source!S31 -> 7132.78
C47: ЭМ | F47: =Source!AM30 -> 1.82 | G47: 1,2 | H47: =Source!AV31 -> 1.047 | I47: =Source!Q30 -> 0.34 | J47: =IF(Source!BB31<> 0, Source!BB31, 1) -> 9.29 | K47: =Source!Q31 -> 3.16
C48: МР | F48: =Source!AL30 -> 76.84 | H48: =Source!AW31 -> 1 | I48: =Source!P30 -> 11.53 | J48: =IF(Source!BC31<> 0, Source!BC31, 1) -> 15.53 | K48: =Source!P31 -> 179.06
...

Sheet Source
A1: 0 | B1: Smeta.RU (495) 974-1589 | D1: _PS_ | F1: 0 | G1: 0 | H1: 0 | I1: Smeta.RU | K1: 1 | L1: 74603 | M1: 10 | N1: 12 | O1: 1 | P1: 0 | Q1: 1
A4: 8 | B4: 1 | C4: -1 | F4: Новый проект | G4: Капитальный ремонт здания Государственного бюджетного общеобразовательного учреждения города Москвы «Школа №1574», расположенного по адресу: г. Москва, Старопименовский переулок, д. 5. 1 этап | EC4: 0
A12: 1 | B12: 717 | C12: 0 | D12: =ROW(A676) -> 676 | E12: 0 | F12: Новый объект строительства | I12: 0 | J12: 2024-00375-01-01-ИОС3. | K12: 0 | L12: 0 | M12: 4098 | O12: 0 | P12: 0 | Q12: 0 | R12: 0 | S12: 0 | T12: 1 | V12: 2 | BB12: 0 | BH12: Сметные нормы списания | BI12: Коды ОКП для ТСН-2001 МГЭ Дополнение 81 | BJ12: 1 | BK12: 1 | BL12: 0 | BM12: 0 | BN12: 1 | BO12: 0 | BP12: 6 | BQ12: 2 | BR12: 1 | BS12: 1 | BT12: 0 | BU12: 0 | BV12: 0 | BW12: 0 | BX12: 0 | BY12: ТСН-2001 (МГЭ) Доп 81 - Ремонт | BZ12: Типовой расчет для ТСН-2001 МГЭ, Дополнение 81, ремонт | CA12: Территориальные сметные нормативы для Москвы ТСН-2001 (МГЭ), дополнение 81 | CB12: Территориальные сметные нормативы для Москвы ТСН-2001 (МГЭ), дополнение 81 | CC12: Территориальные сметные нормативы для Москвы ТСН-2001 (МГЭ), дополнение 81 | CD12: Территориальные сметные нормативы для Москвы ТСН-2001 (МГЭ), дополнение 81 | CE12: Поправки для ТСН-2001 от 07.04.2026 г. доп.81 | CF12: 0 | CG12: 0 | CH12: 8200 | CK12: 81 | CQ12: Территориальные сметные нормативы для Москвы (ТСН-2001) | CR12: ТЕР | CS12: 41660 | CT12: 1 | CU12: 81 | CY12: 0 | EC12: 0
A15: 15 | B15: 1
A18: 52 | B18: =B676 -> 717 | C18: =C676 -> 1 | D18: =D676 -> 12 | E18: =E676 -> 0 | F18: =F676 -> Новый объект строительства | G18: =G676 | O18: =O676 -> 748838.28 | P18: =P676 -> 722350.83 | Q18: =Q676 -> 1237.2 | R18: =R676 -> 155.8 | S18: =S676 -> 25250.25 | T18: =T676 -> 0 | U18: =U676 -> 2029.9267 | V18: =V676 -> 0 | ... GX18: =GX676 -> 0
A20: 3 | B20: 1 | D20: =ROW(A643) -> 643 | F20: 02-01-05 | G20: Система водоотведения. | I20: 0 | J20: 2024-00375-01-0-ИОС3 | K20: -1 | L20: 02-01-05 | S20: 0 | T20: 0 | V20: 2 | BX20: 0 | CF20: 0 | CG20: 0
A22: 52 | B22: =B643 -> 1 | C22: =C643 -> 3 | D22: =D643 -> 20 | E22: =E643 -> 0 | F22: =F643 -> 02-01-05 | G22: =G643 -> Система водоотведения. | O22: =O643 -> 748838.28 | P22: =P643 -> 722350.83 | Q22: =Q643 -> 1237.2 | R22: =R643 -> 155.8 | S22: =S643 -> 25250.25 | T22: =T643 -> 0 | U22: =U643 -> 2029.9267 | V22: =V643 -> 0 | ... GX22: =GX643 -> 0
A24: 4 | B24: 1 | D24: =ROW(A49) -> 49 | F24: Новый раздел | G24: Демонтажные работы. | I24: 0 | K24: 0 | S24: 0 | T24: 0 | V24: 2 | BX24: 0 | CJ24: 0
A26: 52 | B26: =B49 -> 1 | C26: =C49 -> 4 | D26: =D49 -> 24 | E26: =E49 -> 0 | F26: =F49 -> Новый раздел | G26: =G49 -> Демонтажные работы. | O26: =O49 -> 6485.62 | P26: =P49 -> 29.07 | Q26: =Q49 -> 35.06 | R26: =R49 -> 4.59 | S26: =S49 -> 6421.49 | T26: =T49 -> 0 | U26: =U49 -> 537.80137 | V26: =V49 -> 0 | ... GX26: =GX49 -> 0
A28: 17 | B28: 1 | C28: =ROW(SmtRes!A5) -> 5 | D28: =ROW(EtalonRes!A5) -> 5 | E28: 1 | F28: 6.65-1-2 | G28: Разборка трубопроводов из водогазопроводных труб диаметром до 40 мм | H28: 100 м | I28: =ROUND((30+8)/100,9) -> 0.38 | J28: 0 | K28: =ROUND((30+8)/100,9) -> 0.38 | O28: =ROUND(CP28,2) -> 254.81 | P28: =ROUND((ROUND((AC28*AW28*I28),2)*BC28),2) -> 17.54 | Q28: =(ROUND((ROUND((((ET28*1.2))*AV28*I28),2)*BB28),2)+ROUND((ROUND(((AE28-((EU28*1.2)))*AV28*I28),2)*BS28),2)) -> 0.6 | R28: =(ROUND((ROUND((((EU28*1.2))*AV28*I28),2)*BS28),2)+ROUND((ROUND(((AE28-((EU28*1.2)))*AV28*I28),2)*BS28),2)) -> 0 | S28: =ROUND((ROUND((AF28*AV28*I28),2)*BA28),2) -> 236.67 | T28: =ROUND(CU28*I28,2) -> 0 | U28: =CV28*I28 -> 21.732705 | V28: =CW28*I28 -> 0 | W28: =ROUND(CX28*I28,2) -> 0 | X28: =(ROUND((((S28+ROUND((ROUND((((EU28*1.2))*AV28*I28),2)*BS28),2))*AT28)/100),2)+ROUND(((ROUND((ROUND(((AE28-((EU28*1.2)))*AV28*I28),2)*BS28),2)*AT28)/100),2)) -> 205.9 | Y28: =(ROUND((((S28+ROUND((ROUND((((EU28*1.2))*AV28*I28),2)*BS28),2))*AU28)/100),2)+ROUND(((ROUND((ROUND(((AE28-((EU28*1.2)))*AV28*I28),2)*BS28),2)*AU28)/100),2)) -> 104.13 | AA28: 86549534 | AB28: =ROUND((AC28+AD28+AF28),6) -> 642.524 | AC28: =ROUND(((ES28*1)),6) -> 46.16 | AD28: =ROUND(((((ET28*1.2))-((EU28*1.2)))+AE28),6) -> 1.512 | AE28: =ROUND(((EU28*1.2)),6) -> 0 | AF28: =ROUND(((EV28*1.2)),6) -> 594.852 | AG28: =ROUND((AP28),6) -> 0 | AH28: =((EW28*1.2)) -> 54.624 | AI28: =((EX28*1.2)) -> 0 | AJ28: =(AS28) -> 0 | AK28: 543.13 | AL28: 46.16 | AM28: 1.26 | AN28: 0 | AO28: 495.71 | AP28: 0 | AQ28: 45.52 | AR28: 0 | AS28: 0 | AT28: 87 | AU28: 44 | AV28: 1.047 | AW28: 1 | AZ28: 1 | BA28: 1 | BB28: 1 | BC28: 1 | BH28: 0 | BI28: 1 | BJ28: ТСН-2001.6 Доп. 79, Сб. 65, т. 1, поз. 2 | BM28: 102 | BN28: 0 | BO28: 6.65-1-2 | BP28: 1 | BQ28: 60 | BR28: 0 | BS28: 1 | BT28: 1 | BU28: 1 | BV28: 1 | BW28: 1 | BX28: 1 | BZ28: 87 | CA28: 44 | CE28: 1566 | CF28: 0 | CG28: 0 | CM28: 0 | CN28: Поправка: Гл.12.Прил.8.п.8. 3_12.00.01.11.001 Наименование: При наличии напряженных и стесненных условий производства работ (стесненность, сложность складирования и транспортной логистики и т.п.) для объектов, расположенных в пределах круговой магистральной системы улиц "Садовое кольцо" города Москвы | CO28: 0 | CP28: =(P28+Q28+S28) -> 254.81 | CQ28: =ROUND((ROUND((AC28*AW28*1),2)*BC28),2) -> 46.16 | CR28: =(ROUND((ROUND((((ET28*1.2))*AV28*1),2)*BB28),2)+ROUND((ROUND(((AE28-((EU28*1.2)))*AV28*1),2)*BS28),2)) -> 1.58 | CS28: =(ROUND((ROUND((((EU28*1.2))*AV28*1),2)*BS28),2)+ROUND((ROUND(((AE28-((EU28*1.2)))*AV28*1),2)*BS28),2)) -> 0 | CT28: =ROUND((ROUND((AF28*AV28*1),2)*BA28),2) -> 622.81 | CU28: =AG28 -> 0 | CV28: =(AH28*AV28) -> 57.191328 | CW28: =AI28 -> 0 | CX28: =AJ28 -> 0 | CY28: =(ROUND((((S28+ROUND((ROUND((((EU28*1.2))*AV28*1),2)*BS28),2))*AT28)/100),2)+ROUND(((ROUND((ROUND(((AE28-((EU28*1.2)))*AV28*1),2)*BS28),2)*AT28)/100),2)) -> 205.9 | CZ28: =(ROUND((((S28+ROUND((ROUND((((EU28*1.2))*AV28*1),2)*BS28),2))*AU28)/100),2)+ROUND(((ROUND((ROUND(((AE28-((EU28*1.2)))*AV28*1),2)*BS28),2)*AU28)/100),2)) -> 104.13 | DB28: 1 | DD28: *1 | DE28: *1,2 | DF28: *1,2 | DG28: *1,2 | DI28: *1,2 | DJ28: *1,2 | DN28: 0 | DO28: 0 | DP28: 1 | DQ28: 1 | DU28: 1003 | DV28: 100 м | DW28: 100 м | DX28: 100 | EE28: 85635475 | EF28: 60 | EG28: Ремонтно-строительные работы | EH28: 0 | EJ28: 1 | EK28: 102 | EL28: ТСН-2001.6-65. Внутренние санитарно-технические работы: демонтаж и разборка | EM28: ТСН-2001.6-65-1 | EO28: Поправка: Гл.12.Прил.8.п.8. 3_12.00.01.11.001 | EQ28: 131072 | ER28: 543.13 | ES28: 46.16 | ET28: 1.26 | EU28: 0 | EV28: 495.71 | EW28: 45.52 | EX28: 0 | EY28: 0 | FQ28: 0 | FR28: 0 | FS28: 0 | FX28: 87 | FY28: 44 | GD28: 1 | GF28: -1242219818 | GG28: 2 | GH28: 1 | GI28: 2 | GJ28: 0 | GK28: 0 | GL28: =ROUND(IF(AND(BH28=3,BI28=3,FS28<>0),P28,0),2) -> 0 | GM28: =ROUND(O28+X28+Y28,2)+GX28 -> 564.84 | GN28: =IF(OR(BI28=0,BI28=1),GM28-GX28,0) -> 564.84 | GO28: =IF(BI28=2,GM28-GX28,0) -> 0 | GP28: =IF(BI28=4,GM28-GX28,0) -> 0 | GR28: 0 | GS28: 3 | GT28: 0 | GV28: =ROUND((GT28),6) -> 0 | GW28: 1 | GX28: =ROUND(HC28*I28,2) -> 0 | HA28: 0 | HB28: 0 | HC28: =GV28*GW28 -> 0 | HS28: 0 | IK28: 0
A29: 17 | B29: 1 | C29: =ROW(SmtRes!A10) -> 10 | D29: =ROW(EtalonRes!A10) -> 10 | E29: 1 | F29: 6.65-1-2 | G29: Разборка трубопроводов из водогазопроводных труб диаметром до 40 мм | H29: 100 м | I29: =ROUND((30+8)/100,9) -> 0.38 | J29: 0 | K29: =ROUND((30+8)/100,9) -> 0.38 | O29: =ROUND(CP29,2) -> 13614.32 | P29: =ROUND((ROUND((AC29*AW29*I29),2)*BC29),2) -> 272.4 | Q29: =(ROUND((ROUND((((ET29*1.2))*AV29*I29),2)*BB29),2)+ROUND((ROUND(((AE29-((EU29*1.2)))*AV29*I29),2)*BS29),2)) -> 5.57 | R29: =(ROUND((ROUND((((EU29*1.2))*AV29*I29),2)*BS29),2)+ROUND((ROUND(((AE29-((EU29*1.2)))*AV29*I29),2)*BS29),2)) -> 0 | S29: =ROUND((ROUND((AF29*AV29*I29),2)*BA29),2) -> 13336.35 | T29: =ROUND(CU29*I29,2) -> 0 | U29: =CV29*I29 -> 21.732705 | V29: =CW29*I29 -> 0 | W29: =ROUND(CX29*I29,2) -> 0 | X29: =(ROUND((((S29+ROUND((ROUND((((EU29*1.2))*AV29*I29),2)*BS29),2))*AT29)/100),2)+ROUND(((ROUND((ROUND(((AE29-((EU29*1.2)))*AV29*I29),2)*BS29),2)*AT29)/100),2)) -> 11602.62 | Y29: =(ROUND((((S29+ROUND((ROUND((((EU29*1.2))*AV29*I29),2)*BS29),2))*AU29)/100),2)+ROUND(((ROUND((ROUND(((AE29-((EU29*1.2)))*AV29*I29),2)*BS29),2)*AU29)/100),2)) -> 5867.99 | AA29: 86549536 | AB29: =ROUND((AC29+AD29+AF29),6) -> 642.524 | AC29: =ROUND(((ES29*1)),6) -> 46.16 | AD29: =ROUND(((((ET29*1.2))-((EU29*1.2)))+AE29),6) -> 1.512 | AE29: =ROUND(((EU29*1.2)),6) -> 0 | AF29: =ROUND(((EV29*1.2)),6) -> 594.852 | AG29: =ROUND((AP29),6) -> 0 | AH29: =((EW29*1.2)) -> 54.624 | AI29: =((EX29*1.2)) -> 0 | AJ29: =(AS29) -> 0 | AK29: 543.13 | AL29: 46.16 | AM29: 1.26 | AN29: 0 | AO29: 495.71 | AP29: 0 | AQ29: 45.52 | AR29: 0 | AS29: 0 | AT29: 87 | AU29: 44 | AV29: 1.047 | AW29: 1 | AZ29: 1 | BA29: 56.35 | BB29: 9.29 | BC29: 15.53 | BH29: 0 | BI29: 1 | BJ29: ТСН-2001.6 Доп. 79, Сб. 65, т. 1, поз. 2 | BM29: 102 | BN29: 0 | BO29: 6.65-1-2 | BP29: 1 | BQ29: 60 | BR29: 0 | BS29: 56.35 | BT29: 1 | BU29: 1 | BV29: 1 | BW29: 1 | BX29: 1 | BZ29: 87 | CA29: 44 | CE29: 1566 | CF29: 0 | CG29: 0 | CM29: 0 | CN29: Поправка: Гл.12.Прил.8.п.8. 3_12.00.01.11.001 Наименование: При наличии напряженных и стесненных условий производства работ (стесненность, сложность складирования и транспортной логистики и т.п.) для объектов, расположенных в пределах круговой магистральной системы улиц "Садовое кольцо" города Москвы | CO29: 0 | CP29: =(P29+Q29+S29) -> 13614.32 | CQ29: =ROUND((ROUND((AC29*AW29*1),2)*BC29),2) -> 716.86 | CR29: =(ROUND((ROUND((((ET29*1.2))*AV29*1),2)*BB29),2)+ROUND((ROUND(((AE29-((EU29*1.2)))*AV29*1),2)*BS29),2)) -> 14.68 | CS29: =(ROUND((ROUND((((EU29*1.2))*AV29*1),2)*BS29),2)+ROUND((ROUND(((AE29-((EU29*1.2)))*AV29*1),2)*BS29),2)) -> 0 | CT29: =ROUND((ROUND((AF29*AV29*1),2)*BA29),2) -> 35095.34 | CU29: =AG29 -> 0 | CV29: =(AH29*AV29) -> 57.191328 | CW29: =AI29 -> 0 | CX29: =AJ29 -> 0 | CY29: =(ROUND((((S29+ROUND((ROUND((((EU29*1.2))*AV29*1),2)*BS29),2))*AT29)/100),2)+ROUND(((ROUND((ROUND(((AE29-((EU29*1.2)))*AV29*1),2)*BS29),2)*AT29)/100),2)) -> 11602.62 | CZ29: =(ROUND((((S29+ROUND((ROUND((((EU29*1.2))*AV29*1),2)*BS29),2))*AU29)/100),2)+ROUND(((ROUND((ROUND(((AE29-((EU29*1.2)))*AV29*1),2)*BS29),2)*AU29)/100),2)) -> 5867.99 | DB29: 2 | DD29: *1 | DE29: *1,2 | DF29: *1,2 | DG29: *1,2 | DI29: *1,2 | DJ29: *1,2 | DN29: 0 | DO29: 0 | DP29: 1 | DQ29: 1 | DU29: 1003 | DV29: 100 м | DW29: 100 м | DX29: 100 | EE29: 85635475 | EF29: 60 | EG29: Ремонтно-строительные работы | EH29: 0 | EJ29: 1 | EK29: 102 | EL29: ТСН-2001.6-65. Внутренние санитарно-технические работы: демонтаж и разборка | EM29: ТСН-2001.6-65-1 | EO29: Поправка: Гл.12.Прил.8.п.8. 3_12.00.01.11.001 | EQ29: 131072 | ER29: 543.13 | ES29: 46.16 | ET29: 1.26 | EU29: 0 | EV29: 495.71 | EW29: 45.52 | EX29: 0 | EY29: 0 | FQ29: 0 | FR29: 0 | FS29: 0 | FX29: 87 | FY29: 44 | GD29: 1 | GF29: -1242219818 | GG29: 2 | GH29: 1 | GI29: 2 | GJ29: 0 | GK29: 0 | GL29: =ROUND(IF(AND(BH29=3,BI29=3,FS29<>0),P29,0),2) -> 0 | GM29: =ROUND(O29+X29+Y29,2)+GX29 -> 31084.93 | GN29: =IF(OR(BI29=0,BI29=1),GM29-GX29,0) -> 31084.93 | GO29: =IF(BI29=2,GM29-GX29,0) -> 0 | GP29: =IF(BI29=4,GM29-GX29,0) -> 0 | GR29: 0 | GS29: 3 | GT29: 0 | GV29: =ROUND((GT29),6) -> 0 | GW29: 1 | GX29: =ROUND(HC29*I29,2) -> 0 | HA29: 0 | HB29: 0 | HC29: =GV29*GW29 -> 0 | HS29: 0 | IK29: 0
A30: 17 | B30: 1 | C30: =ROW(SmtRes!A15) -> 15 | D30: =ROW(EtalonRes!A15) -> 15 | E30: 2 | F30: 6.65-11-5 | G30: Разборка трубопроводов центрального отопления на сварке диаметром труб до 100 мм | H30: 100 м | I30: =ROUND(15/100,9) -> 0.15 | J30: 0 | K30: =ROUND(15/100,9) -> 0.15 | O30: =ROUND(CP30,2) -> 138.45 | P30: =ROUND((ROUND((AC30*AW30*I30),2)*BC30),2) -> 11.53 | Q30: =(ROUND((ROUND(((((ET30*1)*1.2))*AV30*I30),2)*BB30),2)+ROUND((ROUND(((AE30-(((EU30*1)*1.2)))*AV30*I30),2)*BS30),2)) -> 0.34 | R30: =(ROUND((ROUND(((((EU30*1)*1.2))*AV30*I30),2)*BS30),2)+ROUND((ROUND(((AE30-(((EU30*1)*1.2)))*AV30*I30),2)*BS30),2)) -> 0 | S30: =ROUND((ROUND((AF30*AV30*I30),2)*BA30),2) -> 126.58 | T30: =ROUND(CU30*I30,2) -> 0 | U30: =CV30*I30 -> 11.517658 | V30: =CW30*I30 -> 0 | W30: =ROUND(CX30*I30,2) -> 0 | X30: =(ROUND((((S30+ROUND((ROUND(((((EU30*1)*1.2))*AV30*I30),2)*BS30),2))*AT30)/100),2)+ROUND(((ROUND((ROUND(((AE30-(((EU30*1)*1.2)))*AV30*I30),2)*BS30),2)*AT30)/100),2)) -> 110.12 | Y30: =(ROUND((((S30+ROUND((ROUND(((((EU30*1)*1.2))*AV30*I30),2)*BS30),2))*AU30)/100),2)+ROUND(((ROUND((ROUND(((AE30-(((EU30*1)*1.2)))*AV30*I30),2)*BS30),2)*AU30)/100),2)) -> 55.7 | AA30: 86549534 | AB30: =ROUND((AC30+AD30+AF30),6) -> 884.99872 | AC30: =ROUND((((ES30*1)*1)),6) -> 76.84 | AD30: =ROUND((((((ET30*1)*1.2))-(((EU30*1)*1.2)))+AE30),6) -> 2.184 | AE30: =ROUND((((EU30*1)*1.2)),6) -> 0 | AF30: =ROUND((((EV30*0.82)*1.2)),6) -> 805.97472 | AG30: =ROUND((AP30),6) -> 0 | AH30: =(((EW30*0.82)*1.2)) -> 73.33752 | AI30: =(((EX30*1)*1.2)) -> 0 | AJ30: =(AS30) -> 0 | AK30: 897.74 | AL30: 76.84 | AM30: 1.82 | AN30: 0 | AO30: 819.08 | AP30: 0 | AQ30: 74.53 | AR30: 0 | AS30: 0 | AT30: 87 | AU30: 44 | AV30: 1.047 | AW30: 1 | AZ30: 1 | BA30: 1 | BB30: 1 | BC30: 1 | BH30: 0 | BI30: 1 | BJ30: ТСН-2001.6 Доп. 79, Сб. 65, т. 11, поз. 5 | BM30: 102 | BN30: 0 | BO30: 6.65-11-5 | BP30: 1 | BQ30: 60 | BR30: 0 | BS30: 1 | BT30: 1 | BU30: 1 | BV30: 1 | BW30: 1 | BX30: 1 | BZ30: 87 | CA30: 44 | CE30: 1566 | CF30: 0 | CG30: 0 | CM30: 0 | CN30: Поправка: Сб.6-65.т3.1.п.3.1.6_06.65.01.28.002 Наименование: При разборке трубопроводов без правки и чистки труб и фасонных частей от накипи и грязи Поправка: Гл.12.Прил.8.п.8. 3_12.00.01.11.001 Наименование: При наличии напряженных и стесненных условий производства работ (стесненность, сложность складирования и транспортной логистики и т.п.) для объектов, расположенных в пределах круговой магистральной системы улиц "Садовое кольцо" города Москвы | CO30: 0 | CP30: =(P30+Q30+S30) -> 138.45 | CQ30: =ROUND((ROUND((AC30*AW30*1),2)*BC30),2) -> 76.84 | CR30: =(ROUND((ROUND(((((ET30*1)*1.2))*AV30*1),2)*BB30),2)+ROUND((ROUND(((AE30-(((EU30*1)*1.2)))*AV30*1),2)*BS30),2)) -> 2.29 | CS30: =(ROUND((ROUND(((((EU30*1)*1.2))*AV30*1),2)*BS30),2)+ROUND((ROUND(((AE30-(((EU30*1)*1.2)))*AV30*1),2)*BS30),2)) -> 0 | CT30: =ROUND((ROUND((AF30*AV30*1),2)*BA30),2) -> 843.86 | CU30: =AG30 -> 0 | CV30: =(AH30*AV30) -> 76.784383 | CW30: =AI30 -> 0 | CX30: =AJ30 -> 0 | CY30: =(ROUND((((S30+ROUND((ROUND(((((EU30*1)*1.2))*AV30*1),2)*BS30),2))*AT30)/100),2)+ROUND(((ROUND((ROUND(((AE30-(((EU30*1)*1.2)))*AV30*1),2)*BS30),2)*AT30)/100),2)) -> 110.12 | CZ30: =(ROUND((((S30+ROUND((ROUND(((((EU30*1)*1.2))*AV30*1),2)*BS30),2))*AU30)/100),2)+ROUND(((ROUND((ROUND(((AE30-(((EU30*1)*1.2)))*AV30*1),2)*BS30),2)*AU30)/100),2)) -> 55.7 | DB30: 3 | DD30: *1)*1 | DE30: *1)*1,2 | DF30: *1)*1,2 | DG30: *0,82)*1,2 | DI30: *0,82)*1,2 | DJ30: *1)*1,2 | DN30: 0 | DO30: 0 | DP30: 1 | DQ30: 1 | DU30: 1003 | DV30: 100 м | DW30: 100 м | DX30: 100 | EE30: 85635475 | EF30: 60 | EG30: Ремонтно-строительные работы | EH30: 0 | EJ30: 1 | EK30: 102 | EL30: ТСН-2001.6-65. Внутренние санитарно-технические работы: демонтаж и разборка | EM30: ТСН-2001.6-65-1 | EO30: Поправка: Сб.6-65.т3.1.п.3.1.6_06.65.01.28.002 Поправка: Гл.12.Прил.8.п.8. 3_12.00.01.11.001 | EQ30: 131072 | ER30: 897.74 | ES30: 76.84 | ET30: 1.82 | EU30: 0 | EV30: 819.08 | EW30: 74.53 | EX30: 0 | EY30: 0 | FQ30: 0 | FR30: 0 | FS30: 0 | FX30: 87 | FY30: 44 | GD30: 1 | GF30: 1211388190 | GG30: 2 | GH30: 1 | GI30: 2 | GJ30: 0 | GK30: 0 | GL30: =ROUND(IF(AND(BH30=3,BI30=3,FS30<>0),P30,0),2) -> 0 | GM30: =ROUND(O30+X30+Y30,2)+GX30 -> 304.27 | GN30: =IF(OR(BI30=0,BI30=1),GM30-GX30,0) -> 304.27 | GO30: =IF(BI30=2,GM30-GX30,0) -> 0 | GP30: =IF(BI30=4,GM30-GX30,0) -> 0 | GR30: 0 | GS30: 3 | GT30: 0 | GV30: =ROUND((GT30),6) -> 0 | GW30: 1 | GX30: =ROUND(HC30*I30,2) -> 0 | HA30: 0 | HB30: 0 | HC30: =GV30*GW30 -> 0 | HS30: 0 | IK30: 0
A31: 17 | B31: 1 | C31: =ROW(SmtRes!A20) -> 20 | D31: =ROW(EtalonRes!A20) -> 20 | E31: 2 | F31: 6.65-11-5 | G31: Разборка трубопроводов центрального отопления на сварке диаметром труб до 100 мм | H31: 100 м | I31: =ROUND(15/100,9) -> 0.15 | J31: 0 | K31: =ROUND(15/100,9) -> 0.15 | O31: =ROUND(CP31,2) -> 7315 | P31: =ROUND((ROUND((AC31*AW31*I31),2)*BC31),2) -> 179.06 | Q31: =(ROUND((ROUND(((((ET31*1)*1.2))*AV31*I31),2)*BB31),2)+ROUND((ROUND(((AE31-(((EU31*1)*1.2)))*AV31*I31),2)*BS31),2)) -> 3.16 | R31: =(ROUND((ROUND(((((EU31*1)*1.2))*AV31*I31),2)*BS31),2)+ROUND((ROUND(((AE31-(((EU31*1)*1.2)))*AV31*I31),2)*BS31),2)) -> 0 | S31: =ROUND((ROUND((AF31*AV31*I31),2)*BA31),2) -> 7132.78 | T31: =ROUND(CU31*I31,2) -> 0 | U31: =CV31*I31 -> 11.517658 | V31: =CW31*I31 -> 0 | W31: =ROUND(CX31*I31,2) -> 0 | X31: =(ROUND((((S31+ROUND((ROUND(((((EU31*1)*1.2))*AV31*I31),2)*BS31),2))*AT31)/100),2)+ROUND(((ROUND((ROUND(((AE31-(((EU31*1)*1.2)))*AV31*I31),2)*BS31),2)*AT31)/100),2)) -> 6205.52 | Y31: =(ROUND((((S31+ROUND((ROUND(((((EU31*1)*1.2))*AV31*I31),2)*BS31),2))*AU31)/100),2)+ROUND(((ROUND((ROUND(((AE31-(((EU31*1)*1.2)))*AV31*I31),2)*BS31),2)*AU31)/100),2)) -> 3138.42 | AA31: 86549536 | AB31: =ROUND((AC31+AD31+AF31),6) -> 884.99872 | AC31: =ROUND((((ES31*1)*1)),6) -> 76.84 | AD31: =ROUND((((((ET31*1)*1.2))-(((EU31*1)*1.2)))+AE31),6) -> 2.184 | AE31: =ROUND((((EU31*1)*1.2)),6) -> 0 | AF31: =ROUND((((EV31*0.82)*1.2)),6) -> 805.97472 | AG31: =ROUND((AP31),6) -> 0 | AH31: =(((EW31*0.82)*1.2)) -> 73.33752 | AI31: =(((EX31*1)*1.2)) -> 0 | AJ31: =(AS31) -> 0 | AK31: 897.74 | AL31: 76.84 | AM31: 1.82 | AN31: 0 | AO31: 819.08 | AP31: 0 | AQ31: 74.53 | AR31: 0 | AS31: 0 | AT31: 87 | AU31: 44 | AV31: 1.047 | AW31: 1 | AZ31: 1 | BA31: 56.35 | BB31: 9.29 | BC31: 15.53 | BH31: 0 | BI31: 1 | BJ31: ТСН-2001.6 Доп. 79, Сб. 65, т. 11, поз. 5 | BM31: 102 | BN31: 0 | BO31: 6.65-11-5 | BP31: 1 | BQ31: 60 | BR31: 0 | BS31: 56.35 | BT31: 1 | BU31: 1 | BV31: 1 | BW31: 1 | BX31: 1 | BZ31: 87 | CA31: 44 | CE31: 1566 | CF31: 0 | CG31: 0 | CM31: 0 | CN31: Поправка: Сб.6-65.т3.1.п.3.1.6_06.65.01.28.002 Наименование: При разборке трубопроводов без правки и чистки труб и фасонных частей от накипи и грязи Поправка: Гл.12.Прил.8.п.8. 3_12.00.01.11.001 Наименование: При наличии напряженных и стесненных условий производства работ (стесненность, сложность складирования и транспортной логистики и т.п.) для объектов, расположенных в пределах круговой магистральной системы улиц "Садовое кольцо" города Москвы | CO31: 0 | CP31: =(P31+Q31+S31) -> 7315 | CQ31: =ROUND((ROUND((AC31*AW31*1),2)*BC31),2) -> 1193.33 | CR31: =(ROUND((ROUND(((((ET31*1)*1.2))*AV31*1),2)*BB31),2)+ROUND((ROUND(((AE31-(((EU31*1)*1.2)))*AV31*1),2)*BS31),2)) -> 21.27 | CS31: =(ROUND((ROUND(((((EU31*1)*1.2))*AV31*1),2)*BS31),2)+ROUND((ROUND(((AE31-(((EU31*1)*1.2)))*AV31*1),2)*BS31),2)) -> 0 | CT31: =ROUND((ROUND((AF31*AV31*1),2)*BA31),2) -> 47551.51 | CU31: =AG31 -> 0 | CV31: =(AH31*AV31) -> 76.784383 | CW31: =AI31 -> 0 | CX31: =AJ31 -> 0 | CY31: =(ROUND((((S31+ROUND((ROUND(((((EU31*1)*1.2))*AV31*1),2)*BS31),2))*AT31)/100),2)+ROUND(((ROUND((ROUND(((AE31-(((EU31*1)*1.2)))*AV31*1),2)*BS31),2)*AT31)/100),2)) -> 6205.52 | CZ31: =(ROUND((((S31+ROUND((ROUND(((((EU31*1)*1.2))*AV31*1),2)*BS31),2))*AU31)/100),2)+ROUND(((ROUND((ROUND(((AE31-(((EU31*1)*1.2)))*AV31*1),2)*BS31),2)*AU31)/100),2)) -> 3138.42 | DB31: 5 | DD31: *1)*1 | DE31: *1)*1,2 | DF31: *1)*1,2 | DG31: *0,82)*1,2 | DI31: *0,82)*1,2 | DJ31: *1)*1,2 | DN31: 0 | DO31: 0 | DP31: 1 | DQ31: 1 | DU31: 1003 | DV31: 100 м | DW31: 100 м | DX31: 100 | EE31: 85635475 | EF31: 60 | EG31: Ремонтно-строительные работы | EH31: 0 | EJ31: 1 | EK31: 102 | EL31: ТСН-2001.6-65. Внутренние санитарно-технические работы: демонтаж и разборка | EM31: ТСН-2001.6-65-1 | EO31: Поправка: Сб.6-65.т3.1.п.3.1.6_06.65.01.28.002 Поправка: Гл.12.Прил.8.п.8. 3_12.00.01.11.001 | EQ31: 131072 | ER31: 897.74 | ES31: 76.84 | ET31: 1.82 | EU31: 0 | EV31: 819.08 | EW31: 74.53 | EX31: 0 | EY31: 0 | FQ31: 0 | FR31: 0 | FS31: 0 | FX31: 87 | FY31: 44 | GD31: 1 | GF31: 1211388190 | GG31: 2 | GH31: 1 | GI31: 2 | GJ31: 0 | GK31: 0 | GL31: =ROUND(IF(AND(BH31=3,BI31=3,FS31<>0),P31,0),2) -> 0 | GM31: =ROUND(O31+X31+Y31,2)+GX31 -> 16658.94 | GN31: =IF(OR(BI31=0,BI31=1),GM31-GX31,0) -> 16658.94 | GO31: =IF(BI31=2,GM31-GX31,0) -> 0 | GP31: =IF(BI31=4,GM31-GX31,0) -> 0 | GR31: 0 | GS31: 3 | GT31: 0 | GV31: =ROUND((GT31),6) -> 0 | GW31: 1 | GX31: =ROUND(HC31*I31,2) -> 0 | HA31: 0 | HB31: 0 | HC31: =GV31*GW31 -> 0 | HS31: 0 | IK31: 0
A32: 17 | B32: 1 | C32: =ROW(SmtRes!A28) -> 28 | D32: =ROW(EtalonRes!A33) -> 33 | E32: 3 | F32: 3.16-40-4 | G32: Прокладка напорного трубопровода водоснабжения и отопления из многослойного полипропилена, армированного стекловолокном, из заранее собранных узлов, наружный диаметр 40 мм (демонтаж) | H32: 100 м | I32: =ROUND((25)/100,9) -> 0.25 | J32: 0 | K32: =ROUND((25)/100,9) -> 0.25 | O32: =ROUND(CP32,2) -> 24.43 | P32: =ROUND((ROUND((AC32*AW32*I32),2)*BC32),2) -> 0 | Q32: =(ROUND((ROUND(((((ET32*0.4)*1.2))*AV32*I32),2)*BB32),2)+ROUND((ROUND(((AE32-(((EU32*0.4)*1.2)))*AV32*I32),2)*BS32),2)) -> 3.09 | R32: =(ROUND((ROUND(((((EU32*0.4)*1.2))*AV32*I32),2)*BS32),2)+ROUND((ROUND(((AE32-(((EU32*0.4)*1.2)))*AV32*I32),2)*BS32),2)) -> 0.19 | S32: =ROUND((ROUND((AF32*AV32*I32),2)*BA32),2) -> 21.34 | T32: =ROUND(CU32*I32,2) -> 0 | U32: =CV32*I32 -> 1.7311008 | V32: =CW32*I32 -> 0 | W32: =ROUND(CX32*I32,2) -> 0 | X32: =(ROUND((((S32+ROUND((ROUND(((((EU32*0.4)*1.2))*AV32*I32),2)*BS32),2))*AT32)/100),2)+ROUND(((ROUND((ROUND(((AE32-(((EU32*0.4)*1.2)))*AV32*I32),2)*BS32),2)*AT32)/100),2)) -> 23.47 | Y32: =(ROUND((((S32+ROUND((ROUND(((((EU32*0.4)*1.2))*AV32*I32),2)*BS32),2))*AU32)/100),2)+ROUND(((ROUND((ROUND(((AE32-(((EU32*0.4)*1.2)))*AV32*I32),2)*BS32),2)*AU32)/100),2)) -> 13.13 | AA32: 86549534 | AB32: =ROUND((AC32+AD32+AF32),6) -> 91.5984 | AC32: =ROUND((((ES32*0)*1)),6) -> 0 | AD32: =ROUND((((((ET32*0.4)*1.2))-(((EU32*0.4)*1.2)))+AE32),6) -> 11.6016 | AE32: =ROUND((((EU32*0.4)*1.2)),6) -> 0.7248 | AF32: =ROUND((((EV32*0.4)*1.2)),6) -> 79.9968 | AG32: =ROUND((AP32),6) -> 0 | AH32: =(((EW32*0.4)*1.2)) -> 6.4896 | AI32: =(((EX32*0.4)*1.2)) -> 0 | AJ32: =(AS32) -> 0 | AK32: 312.82 | AL32: 121.99 | AM32: 24.17 | AN32: 1.51 | AO32: 166.66 | AP32: 0 | AQ32: 13.52 | AR32: 0 | AS32: 0 | AT32: 109 | AU32: 61 | AV32: 1.067 | AW32: 1 | AZ32: 1 | BA32: 1 | BB32: 1 | BC32: 1 | BH32: 0 | BI32: 1 | BJ32: ТСН-2001.3 Доп. 79, Сб. 16, т. 40, поз. 4 | BM32: 21 | BN32: 0 | BO32: 3.16-40-4 | BP32: 1 | BQ32: 30 | BR32: 0 | BS32: 1 | BT32: 1 | BU32: 1 | BV32: 1 | BW32: 1 | BX32: 1 | BZ32: 109 | CA32: 61 | CE32: 1566 | CF32: 0 | CG32: 0 | CM32: 0 | CN32: Поправка: Гл.6.Прил.2.2.п.2.2.13_06.00.01.35.003 Наименование: При демонтаже внутренних санитарно-технических устройств и газопроводов Поправка: Гл.12.Прил.8.п.8. 3_12.00.01.11.001 Наименование: При наличии напряженных и стесненных условий производства работ (стесненность, сложность складирования и транспортной логистики и т.п.) для объектов, расположенных в пределах круговой магистральной системы улиц "Садовое кольцо" города Москвы | CO32: 0 | CP32: =(P32+Q32+S32) -> 24.43 | CQ32: =ROUND((ROUND((AC32*AW32*1),2)*BC32),2) -> 0 | CR32: =(ROUND((ROUND(((((ET32*0.4)*1.2))*AV32*1),2)*BB32),2)+ROUND((ROUND(((AE32-(((EU32*0.4)*1.2)))*AV32*1),2)*BS32),2)) -> 12.38 | CS32: =(ROUND((ROUND(((((EU32*0.4)*1.2))*AV32*1),2)*BS32),2)+ROUND((ROUND(((AE32-(((EU32*0.4)*1.2)))*AV32*1),2)*BS32),2)) -> 0.77 | CT32: =ROUND((ROUND((AF32*AV32*1),2)*BA32),2) -> 85.36 | CU32: =AG32 -> 0 | CV32: =(AH32*AV32) -> 6.9244032 | CW32: =AI32 -> 0 | CX32: =AJ32 -> 0 | CY32: =(ROUND((((S32+ROUND((ROUND(((((EU32*0.4)*1.2))*AV32*1),2)*BS32),2))*AT32)/100),2)+ROUND(((ROUND((ROUND(((AE32-(((EU32*0.4)*1.2)))*AV32*1),2)*BS32),2)*AT32)/100),2)) -> 24.1 | CZ32: =(ROUND((((S32+ROUND((ROUND(((((EU32*0.4)*1.2))*AV32*1),2)*BS32),2))*AU32)/100),2)+ROUND(((ROUND((ROUND(((AE32-(((EU32*0.4)*1.2)))*AV32*1),2)*BS32),2)*AU32)/100),2)) -> 13.49 | DB32: 7 | DD32: *0)*1 | DE32: *0,4)*1,2 | DF32: *0,4)*1,2 | DG32: *0,4)*1,2 | DI32: *0,4)*1,2 | DJ32: *0,4)*1,2 | DN32: 0 | DO32: 0 | DP32: 1 | DQ32: 1 | DU32: 1003 | DV32: 100 м | DW32: 100 м | DX32: 100 | EE32: 85635393 | EF32: 30 | EG32: Строительные работы | EH32: 0 | EJ32: 1 | EK32: 21 | EL32: ТСН-2001.3-16. Трубопроводы внутренние | EM32: ТСН-2001.3-16-1 | EO32: Поправка: Гл.6.Прил.2.2.п.2.2.13_06.00.01.35.003 Поправка: Гл.12.Прил.8.п.8. 3_12.00.01.11.001 | EQ32: 131072 | ER32: 312.82 | ES32: 121.99 | ET32: 24.17 | EU32: 1.51 | EV32: 166.66 | EW32: 13.52 | EX32: 0 | EY32: 0 | FQ32: 0 | FR32: 0 | FS32: 0 | FX32: 109 | FY32: 61 | GD32: 1 | GF32: 1484051559 | GG32: 2 | GH32: 1 | GI32: 2 | GJ32: 0 | GK32: 0 | GL32: =ROUND(IF(AND(BH32=3,BI32=3,FS32<>0),P32,0),2) -> 0 | GM32: =ROUND(O32+X32+Y32,2)+GX32 -> 61.03 | GN32: =IF(OR(BI32=0,BI32=1),GM32-GX32,0) -> 61.03 | GO32: =IF(BI32=2,GM32-GX32,0) -> 0 | GP32: =IF(BI32=4,GM32-GX32,0) -> 0 | GR32: 0 | GS32: 3 | GT32: 0 | GV32: =ROUND((GT32),6) -> 0 | GW32: 1 | GX32: =ROUND(HC32*I32,2) -> 0 | HA32: 0 | HB32: 0 | HC32: =GV32*GW32 -> 0 | HS32: 0 | IK32: 0
A33: 17 | B33: 1 | C33: =ROW(SmtRes!A36) -> 36 | D33: =ROW(EtalonRes!A46) -> 46 | E33: 3 | F33: 3.16-40-4 | G33: Прокладка напорного трубопровода водоснабжения и отопления из многослойного полипропилена, армированного стекловолокном, из заранее собранных узлов, наружный диаметр 40 мм (демонтаж) | H33: 100 м | I33: =ROUND((25)/100,9) -> 0.25 | J33: 0 | K33: =ROUND((25)/100,9) -> 0.25 | O33: =ROUND(CP33,2) -> 1244.78 | P33: =ROUND((ROUND((AC33*AW33*I33),2)*BC33),2) -> 0 | Q33: =(ROUND((ROUND(((((ET33*0.4)*1.2))*AV33*I33),2)*BB33),2)+ROUND((ROUND(((AE33-(((EU33*0.4)*1.2)))*AV33*I33),2)*BS33),2)) -> 42.27 | R33: =(ROUND((ROUND(((((EU33*0.4)*1.2))*AV33*I33),2)*BS33),2)+ROUND((ROUND(((AE33-(((EU33*0.4)*1.2)))*AV33*I33),2)*BS33),2)) -> 10.71 | S33: =ROUND((ROUND((AF33*AV33*I33),2)*BA33),2) -> 1202.51 | T33: =ROUND(CU33*I33,2) -> 0 | U33: =CV33*I33 -> 1.7311008 | V33: =CW33*I33 -> 0 | W33: =ROUND(CX33*I33,2) -> 0 | X33: =(ROUND((((S33+ROUND((ROUND(((((EU33*0.4)*1.2))*AV33*I33),2)*BS33),2))*AT33)/100),2)+ROUND(((ROUND((ROUND(((AE33-(((EU33*0.4)*1.2)))*AV33*I33),2)*BS33),2)*AT33)/100),2)) -> 1322.41 | Y33: =(ROUND((((S33+ROUND((ROUND(((((EU33*0.4)*1.2))*AV33*I33),2)*BS33),2))*AU33)/100),2)+ROUND(((ROUND((ROUND(((AE33-(((EU33*0.4)*1.2)))*AV33*I33),2)*BS33),2)*AU33)/100),2)) -> 740.06 | AA33: 86549536 | AB33: =ROUND((AC33+AD33+AF33),6) -> 91.5984 | AC33: =ROUND((((ES33*0)*1)),6) -> 0 | AD33: =ROUND((((((ET33*0.4)*1.2))-(((EU33*0.4)*1.2)))+AE33),6) -> 11.6016 | AE33: =ROUND((((EU33*0.4)*1.2)),6) -> 0.7248 | AF33: =ROUND((((EV33*0.4)*1.2)),6) -> 79.9968 | AG33: =ROUND((AP33),6) -> 0 | AH33: =(((EW33*0.4)*1.2)) -> 6.4896 | AI33: =(((EX33*0.4)*1.2)) -> 0 | AJ33: =(AS33) -> 0 | AK33: 312.82 | AL33: 121.99 | AM33: 24.17 | AN33: 1.51 | AO33: 166.66 | AP33: 0 | AQ33: 13.52 | AR33: 0 | AS33: 0 | AT33: 109 | AU33: 61 | AV33: 1.067 | AW33: 1 | AZ33: 1 | BA33: 56.35 | BB33: 13.68 | BC33: 2.94 | BH33: 0 | BI33: 1 | BJ33: ТСН-2001.3 Доп. 79, Сб. 16, т. 40, поз. 4 | BM33: 21 | BN33: 0 | BO33: 3.16-40-4 | BP33: 1 | BQ33: 30 | BR33: 0 | BS33: 56.35 | BT33: 1 | BU33: 1 | BV33: 1 | BW33: 1 | BX33: 1 | BZ33: 109 | CA33: 61 | CE33: 1566 | CF33: 0 | CG33: 0 | CM33: 0 | CN33: Поправка: Гл.6.Прил.2.2.п.2.2.13_06.00.01.35.003 Наименование: При демонтаже внутренних санитарно-технических устройств и газопроводов Поправка: Гл.12.Прил.8.п.8. 3_12.00.01.11.001 Наименование: При наличии напряженных и стесненных условий производства работ (стесненность, сложность складирования и транспортной логистики и т.п.) для объектов, расположенных в пределах круговой магистральной системы улиц "Садовое кольцо" города Москвы | CO33: 0 | CP33: =(P33+Q33+S33) -> 1244.78 | CQ33: =ROUND((ROUND((AC33*AW33*1),2)*BC33),2) -> 0 | CR33: =(ROUND((ROUND(((((ET33*0.4)*1.2))*AV33*1),2)*BB33),2)+ROUND((ROUND(((AE33-(((EU33*0.4)*1.2)))*AV33*1),2)*BS33),2)) -> 169.36 | CS33: =(ROUND((ROUND(((((EU33*0.4)*1.2))*AV33*1),2)*BS33),2)+ROUND((ROUND(((AE33-(((EU33*0.4)*1.2)))*AV33*1),2)*BS33),2)) -> 43.39 | CT33: =ROUND((ROUND((AF33*AV33*1),2)*BA33),2) -> 4810.04 | CU33: =AG33 -> 0 | CV33: =(AH33*AV33) -> 6.9244032 | CW33: =AI33 -> 0 | CX33: =AJ33 -> 0 | CY33: =(ROUND((((S33+ROUND((ROUND(((((EU33*0.4)*1.2))*AV33*1),2)*BS33),2))*AT33)/100),2)+ROUND(((ROUND((ROUND(((AE33-(((EU33*0.4)*1.2)))*AV33*1),2)*BS33),2)*AT33)/100),2)) -> 1358.03 | CZ33: =(ROUND((((S33+ROUND((ROUND(((((EU33*0.4)*1.2))*AV33*1),2)*BS33),2))*AU33)/100),2)+ROUND(((ROUND((ROUND(((AE33-(((EU33*0.4)*1.2)))*AV33*1),2)*BS33),2)*AU33)/100),2)) -> 760 | DB33: 9 | DD33: *0)*1 | DE33: *0,4)*1,2 | DF33: *0,4)*1,2 | DG33: *0,4)*1,2 | DI33: *0,4)*1,2 | DJ33: *0,4)*1,2 | DN33: 0 | DO33: 0 | DP33: 1 | DQ33: 1 | DU33: 1003 | DV33: 100 м | DW33: 100 м | DX33: 100 | EE33: 85635393 | EF33: 30 | EG33: Строительные работы | EH33: 0 | EJ33: 1 | EK33: 21 | EL33: ТСН-2001.3-16. Трубопроводы внутренние | EM33: ТСН-2001.3-16-1 | EO33: Поправка: Гл.6.Прил.2.2.п.2.2.13_06.00.01.35.003 Поправка: Гл.12.Прил.8.п.8. 3_12.00.01.11.001 | EQ33: 131072 | ER33: 312.82 | ES33: 121.99 | ET33: 24.17 | EU33: 1.51 | EV33: 166.66 | EW33: 13.52 | EX33: 0 | EY33: 0 | FQ33: 0 | FR33: 0 | FS33: 0 | FX33: 109 | FY33: 61 | GD33: 1 | GF33: 1484051559 | GG33: 2 | GH33: 1 | GI33: 2 | GJ33: 0 | GK33: 0 | GL33: =ROUND(IF(AND(BH33=3,BI33=3,FS33<>0),P33,0),2) -> 0 | GM33: =ROUND(O33+X33+Y33,2)+GX33 -> 3307.25 | GN33: =IF(OR(BI33=0,BI33=1),GM33-GX33,0) -> 3307.25 | GO33: =IF(BI33=2,GM33-GX33,0) -> 0 | GP33: =IF(BI33=4,GM33-GX33,0) -> 0 | GR33: 0 | GS33: 3 | GT33: 0 | GV33: =ROUND((GT33),6) -> 0 | GW33: 1 | GX33: =ROUND(HC33*I33,2) -> 0 | HA33: 0 | HB33: 0 | HC33: =GV33*GW33 -> 0 | HS33: 0 | IK33: 0
A34: 17 | B34: 1 | C34: =ROW(SmtRes!A42) -> 42 | D34: =ROW(EtalonRes!A55) -> 55 | E34: 4 | F34: 3.16-13-2 | G34: Прокладка трубопроводов канализации из ПВХ труб диаметром 100 мм - 150 мм (демонтаж) | H34: 100 м | I34: =ROUND((180+18+32)/100,9) -> 2.3 | J34: 0 | K34: =ROUND((180+18+32)/100,9) -> 2.3 | O34: =ROUND(CP34,2) -> 868.16 | P34: =ROUND((ROUND((AC34*AW34*I34),2)*BC34),2) -> 0 | Q34: =(ROUND((ROUND(((((ET34*0.4)*1.2))*AV34*I34),2)*BB34),2)+ROUND((ROUND(((AE34-(((EU34*0.4)*1.2)))*AV34*I34),2)*BS34),2)) -> 23.79 | R34: =(ROUND((ROUND(((((EU34*0.4)*1.2))*AV34*I34),2)*BS34),2)+ROUND((ROUND(((AE34-(((EU34*0.4)*1.2)))*AV34*I34),2)*BS34),2)) -> 3.37 | S34: =ROUND((ROUND((AF34*AV34*I34),2)*BA34),2) -> 844.37 | T34: =ROUND(CU34*I34,2) -> 0 | U34: =CV34*I34 -> 65.966208 | V34: =CW34*I34 -> 0 | W34: =ROUND(CX34*I34,2) -> 0 | X34: =(ROUND((((S34+ROUND((ROUND(((((EU34*0.4)*1.2))*AV34*I34),2)*BS34),2))*AT34)/100),2)+ROUND(((ROUND((ROUND(((AE34-(((EU34*0.4)*1.2)))*AV34*I34),2)*BS34),2)*AT34)/100),2)) -> 924.04 | Y34: =(ROUND((((S34+ROUND((ROUND(((((EU34*0.4)*1.2))*AV34*I34),2)*BS34),2))*AU34)/100),2)+ROUND(((ROUND((ROUND(((AE34-(((EU34*0.4)*1.2)))*AV34*I34),2)*BS34),2)*AU34)/100),2)) -> 517.12 | AA34: 86549534 | AB34: =ROUND((AC34+AD34+AF34),6) -> 353.76 | AC34: =ROUND((((ES34*0)*1)),6) -> 0 | AD34: =ROUND((((((ET34*0.4)*1.2))-(((EU34*0.4)*1.2)))+AE34),6) -> 9.696 | AE34: =ROUND((((EU34*0.4)*1.2)),6) -> 1.3728 | AF34: =ROUND((((EV34*0.4)*1.2)),6) -> 344.064 | AG34: =ROUND((AP34),6) -> 0 | AH34: =(((EW34*0.4)*1.2)) -> 26.88 | AI34: =(((EX34*0.4)*1.2)) -> 0 | AJ34: =(AS34) -> 0 | AK34: 968.71 | AL34: 231.71 | AM34: 20.2 | AN34: 2.86 | AO34: 716.8 | AP34: 0 | AQ34: 56 | AR34: 0 | AS34: 0 | AT34: 109 | AU34: 61 | AV34: 1.067 | AW34: 1 | AZ34: 1 | BA34: 1 | BB34: 1 | BC34: 1 | BH34: 0 | BI34: 1 | BJ34: ТСН-2001.3 Доп. 79, Сб. 16, т. 13, поз. 2 | BM34: 21 | BN34: 0 | BO34: 3.16-13-2 | BP34: 1 | BQ34: 30 | BR34: 0 | BS34: 1 | BT34: 1 | BU34: 1 | BV34: 1 | BW34: 1 | BX34: 1 | BZ34: 109 | CA34: 61 | CE34: 1566 | CF34: 0 | CG34: 0 | CM34: 0 | CN34: Поправка: Гл.6.Прил.2.2.п.2.2.13_06.00.01.35.003 Наименование: При демонтаже внутренних санитарно-технических устройств и газопроводов Поправка: Гл.12.Прил.8.п.8. 3_12.00.01.11.001 Наименование: При наличии напряженных и стесненных условий производства работ (стесненность, сложность складирования и транспортной логистики и т.п.) для объектов, расположенных в пределах круговой магистральной системы улиц "Садовое кольцо" города Москвы | CO34: 0 | CP34: =(P34+Q34+S34) -> 868.16 | CQ34: =ROUND((ROUND((AC34*AW34*1),2)*BC34),2) -> 0 | CR34: =(ROUND((ROUND(((((ET34*0.4)*1.2))*AV34*1),2)*BB34),2)+ROUND((ROUND(((AE34-(((EU34*0.4)*1.2)))*AV34*1),2)*BS34),2)) -> 10.35 | CS34: =(ROUND((ROUND(((((EU34*0.4)*1.2))*AV34*1),2)*BS34),2)+ROUND((ROUND(((AE34-(((EU34*0.4)*1.2)))*AV34*1),2)*BS34),2)) -> 1.46 | CT34: =ROUND((ROUND((AF34*AV34*1),2)*BA34),2) -> 367.12 | CU34: =AG34 -> 0 | CV34: =(AH34*AV34) -> 28.68096 | CW34: =AI34 -> 0 | CX34: =AJ34 -> 0 | CY34: =(ROUND((((S34+ROUND((ROUND(((((EU34*0.4)*1.2))*AV34*1),2)*BS34),2))*AT34)/100),2)+ROUND(((ROUND((ROUND(((AE34-(((EU34*0.4)*1.2)))*AV34*1),2)*BS34),2)*AT34)/100),2)) -> 921.95 | CZ34: =(ROUND((((S34+ROUND((ROUND(((((EU34*0.4)*1.2))*AV34*1),2)*BS34),2))*AU34)/100),2)+ROUND(((ROUND((ROUND(((AE34-(((EU34*0.4)*1.2)))*AV34*1),2)*BS34),2)*AU34)/100),2)) -> 515.96 | DB34: 11 | DD34: *0)*1 | DE34: *0,4)*1,2 | DF34: *0,4)*1,2 | DG34: *0,4)*1,2 | DI34: *0,4)*1,2 | DJ34: *0,4)*1,2 | DN34: 0 | DO34: 0 | DP34: 1 | DQ34: 1 | DU34: 1003 | DV34: 100 м | DW34: 100 м | DX34: 100 | EE34: 85635393 | EF34: 30 | EG34: Строительные работы | EH34: 0 | EJ34: 1 | EK34: 21 | EL34: ТСН-2001.3-16. Трубопроводы внутренние | EM34: ТСН-2001.3-16-1 | EO34: Поправка: Гл.6.Прил.2.2.п.2.2.13_06.00.01.35.003 Поправка: Гл.12.Прил.8.п.8. 3_12.00.01.11.001 | EQ34: 131072 | ER34: 968.71 | ES34: 231.71 | ET34: 20.2 | EU34: 2.86 | EV34: 716.8 | EW34: 56 | EX34: 0 | EY34: 0 | FQ34: 0 | FR34: 0 | FS34: 0 | FX34: 109 | FY34: 61 | GD34: 1 | GF34: 554786944 | GG34: 2 | GH34: 1 | GI34: 2 | GJ34: 0 | GK34: 0 | GL34: =ROUND(IF(AND(BH34=3,BI34=3,FS34<>0),P34,0),2) -> 0 | GM34: =ROUND(O34+X34+Y34,2)+GX34 -> 2309.32 | GN34: =IF(OR(BI34=0,BI34=1),GM34-GX34,0) -> 2309.32 | GO34: =IF(BI34=2,GM34-GX34,0) -> 0 | GP34: =IF(BI34=4,GM34-GX34,0) -> 0 | GR34: 0 | GS34: 3 | GT34: 0 | GV34: =ROUND((GT34),6) -> 0 | GW34: 1 | GX34: =ROUND(HC34*I34,2) -> 0 | HA34: 0 | HB34: 0 | HC34: =GV34*GW34 -> 0 | HS34: 0 | IK34: 0
A35: 17 | B35: 1 | C35: =ROW(SmtRes!A48) -> 48 | D35: =ROW(EtalonRes!A64) -> 64 | E35: 4 | F35: 3.16-13-2 | G35: Прокладка трубопроводов канализации из ПВХ труб диаметром 100 мм - 150 мм (демонтаж) | H35: 100 м | I35: =ROUND((180+18+32)/100,9) -> 2.3 | J35: 0 | K35: =ROUND((180+18+32)/100,9) -> 2.3 | O35: =ROUND(CP35,2) -> 47975.16 | P35: =ROUND((ROUND((AC35*AW35*I35),2)*BC35),2) -> 0 | Q35: =(ROUND((ROUND(((((ET35*0.4)*1.2))*AV35*I35),2)*BB35),2)+ROUND((ROUND(((AE35-(((EU35*0.4)*1.2)))*AV35*I35),2)*BS35),2)) -> 394.91 | R35: =(ROUND((ROUND(((((EU35*0.4)*1.2))*AV35*I35),2)*BS35),2)+ROUND((ROUND(((AE35-(((EU35*0.4)*1.2)))*AV35*I35),2)*BS35),2)) -> 189.9 | S35: =ROUND((ROUND((AF35*AV35*I35),2)*BA35),2) -> 47580.25 | T35: =ROUND(CU35*I35,2) -> 0 | U35: =CV35*I35 -> 65.966208 | V35: =CW35*I35 -> 0 | W35: =ROUND(CX35*I35,2) -> 0 | X35: =(ROUND((((S35+ROUND((ROUND(((((EU35*0.4)*1.2))*AV35*I35),2)*BS35),2))*AT35)/100),2)+ROUND(((ROUND((ROUND(((AE35-(((EU35*0.4)*1.2)))*AV35*I35),2)*BS35),2)*AT35)/100),2)) -> 52069.46 | Y35: =(ROUND((((S35+ROUND((ROUND(((((EU35*0.4)*1.2))*AV35*I35),2)*BS35),2))*AU35)/100),2)+ROUND(((ROUND((ROUND(((AE35-(((EU35*0.4)*1.2)))*AV35*I35),2)*BS35),2)*AU35)/100),2)) -> 29139.79 | AA35: 86549536 | AB35: =ROUND((AC35+AD35+AF35),6) -> 353.76 | AC35: =ROUND((((ES35*0)*1)),6) -> 0 | AD35: =ROUND((((((ET35*0.4)*1.2))-(((EU35*0.4)*1.2)))+AE35),6) -> 9.696 | AE35: =ROUND((((EU35*0.4)*1.2)),6) -> 1.3728 | AF35: =ROUND((((EV35*0.4)*1.2)),6) -> 344.064 | AG35: =ROUND((AP35),6) -> 0 | AH35: =(((EW35*0.4)*1.2)) -> 26.88 | AI35: =(((EX35*0.4)*1.2)) -> 0 | AJ35: =(AS35) -> 0 | AK35: 968.71 | AL35: 231.71 | AM35: 20.2 | AN35: 2.86 | AO35: 716.8 | AP35: 0 | AQ35: 56 | AR35: 0 | AS35: 0 | AT35: 109 | AU35: 61 | AV35: 1.067 | AW35: 1 | AZ35: 1 | BA35: 56.35 | BB35: 16.6 | BC35: 12.86 | BH35: 0 | BI35: 1 | BJ35: ТСН-2001.3 Доп. 79, Сб. 16, т. 13, поз. 2 | BM35: 21 | BN35: 0 | BO35: 3.16-13-2 | BP35: 1 | BQ35: 30 | BR35: 0 | BS35: 56.35 | BT35: 1 | BU35: 1 | BV35: 1 | BW35: 1 | BX35: 1 | BZ35: 109 | CA35: 61 | CE35: 1566 | CF35: 0 | CG35: 0 | CM35: 0 | CN35: Поправка: Гл.6.Прил.2.2.п.2.2.13_06.00.01.35.003 Наименование: При демонтаже внутренних санитарно-технических устройств и газопроводов Поправка: Гл.12.Прил.8.п.8. 3_12.00.01.11.001 Наименование: При наличии напряженных и стесненных условий производства работ (стесненность, сложность складирования и транспортной логистики и т.п.) для объектов, расположенных в пределах круговой магистральной системы улиц "Садовое кольцо" города Москвы | CO35: 0 | CP35: =(P35+Q35+S35) -> 47975.16 | CQ35: =ROUND((ROUND((AC35*AW35*1),2)*BC35),2) -> 0 | CR35: =(ROUND((ROUND(((((ET35*0.4)*1.2))*AV35*1),2)*BB35),2)+ROUND((ROUND(((AE35-(((EU35*0.4)*1.2)))*AV35*1),2)*BS35),2)) -> 171.81 | CS35: =(ROUND((ROUND(((((EU35*0.4)*1.2))*AV35*1),2)*BS35),2)+ROUND((ROUND(((AE35-(((EU35*0.4)*1.2)))*AV35*1),2)*BS35),2)) -> 82.27 | CT35: =ROUND((ROUND((AF35*AV35*1),2)*BA35),2) -> 20687.21 | CU35: =AG35 -> 0 | CV35: =(AH35*AV35) -> 28.68096 | CW35: =AI35 -> 0 | CX35: =AJ35 -> 0 | CY35: =(ROUND((((S35+ROUND((ROUND(((((EU35*0.4)*1.2))*AV35*1),2)*BS35),2))*AT35)/100),2)+ROUND(((ROUND((ROUND(((AE35-(((EU35*0.4)*1.2)))*AV35*1),2)*BS35),2)*AT35)/100),2)) -> 51952.15 | CZ35: =(ROUND((((S35+ROUND((ROUND(((((EU35*0.4)*1.2))*AV35*1),2)*BS35),2))*AU35)/100),2)+ROUND(((ROUND((ROUND(((AE35-(((EU35*0.4)*1.2)))*AV35*1),2)*BS35),2)*AU35)/100),2)) -> 29074.14 | DB35: 13 | DD35: *0)*1 | DE35: *0,4)*1,2 | DF35: *0,4)*1,2 | DG35: *0,4)*1,2 | DI35: *0,4)*1,2 | DJ35: *0,4)*1,2 | DN35: 0 | DO35: 0 | DP35: 1 | DQ35: 1 | DU35: 1003 | DV35: 100 м | DW35: 100 м | DX35: 100 | EE35: 85635393 | EF35: 30 | EG35: Строительные работы | EH35: 0 | EJ35: 1 | EK35: 21 | EL35: ТСН-2001.3-16. Трубопроводы внутренние | EM35: ТСН-2001.3-16-1 | EO35: Поправка: Гл.6.Прил.2.2.п.2.2.13_06.00.01.35.003 Поправка: Гл.12.Прил.8.п.8. 3_12.00.01.11.001 | EQ35: 131072 | ER35: 968.71 | ES35: 231.71 | ET35: 20.2 | EU35: 2.86 | EV35: 716.8 | EW35: 56 | EX35: 0 | EY35: 0 | FQ35: 0 | FR35: 0 | FS35: 0 | FX35: 109 | FY35: 61 | GD35: 1 | GF35: 554786944 | GG35: 2 | GH35: 1 | GI35: 2 | GJ35: 0 | GK35: 0 | GL35: =ROUND(IF(AND(BH35=3,BI35=3,FS35<>0),P35,0),2) -> 0 | GM35: =ROUND(O35+X35+Y35,2)+GX35 -> 129184.41 | GN35: =IF(OR(BI35=0,BI35=1),GM35-GX35,0) -> 129184.41 | GO35: =IF(BI35=2,GM35-GX35,0) -> 0 | GP35: =IF(BI35=4,GM35-GX35,0) -> 0 | GR35: 0 | GS35: 3 | GT35: 0 | GV35: =ROUND((GT35),6) -> 0 | GW35: 1 | GX35: =ROUND(HC35*I35,2) -> 0 | HA35: 0 | HB35: 0 | HC35: =GV35*GW35 -> 0 | HS35: 0 | IK35: 0
A36: 17 | B36: 1 | C36: =ROW(SmtRes!A54) -> 54 | D36: =ROW(EtalonRes!A73) -> 73 | E36: 5 | F36: 3.16-13-1 | G36: Прокладка трубопроводов канализации из ПВХ труб диаметром до 50 мм (демонтаж) | H36: 100 м | I36: =ROUND((120+20)/100,9) -> 1.4 | J36: 0 | K36: =ROUND((120+20)/100,9) -> 1.4 | O36: =ROUND(CP36,2) -> 543.23 | P36: =ROUND((ROUND((AC36*AW36*I36),2)*BC36),2) -> 0 | Q36: =(ROUND((ROUND(((((ET36*0.4)*1.2))*AV36*I36),2)*BB36),2)+ROUND((ROUND(((AE36-(((EU36*0.4)*1.2)))*AV36*I36),2)*BS36),2)) -> 7.24 | R36: =(ROUND((ROUND(((((EU36*0.4)*1.2))*AV36*I36),2)*BS36),2)+ROUND((ROUND(((AE36-(((EU36*0.4)*1.2)))*AV36*I36),2)*BS36),2)) -> 1.03 | S36: =ROUND((ROUND((AF36*AV36*I36),2)*BA36),2) -> 535.99 | T36: =ROUND(CU36*I36,2) -> 0 | U36: =CV36*I36 -> 41.874202 | V36: =CW36*I36 -> 0 | W36: =ROUND(CX36*I36,2) -> 0 | X36: =(ROUND((((S36+ROUND((ROUND(((((EU36*0.4)*1.2))*AV36*I36),2)*BS36),2))*AT36)/100),2)+ROUND(((ROUND((ROUND(((AE36-(((EU36*0.4)*1.2)))*AV36*I36),2)*BS36),2)*AT36)/100),2)) -> 585.35 | Y36: =(ROUND((((S36+ROUND((ROUND(((((EU36*0.4)*1.2))*AV36*I36),2)*BS36),2))*AU36)/100),2)+ROUND(((ROUND((ROUND(((AE36-(((EU36*0.4)*1.2)))*AV36*I36),2)*BS36),2)*AU36)/100),2)) -> 327.58 | AA36: 86549534 | AB36: =ROUND((AC36+AD36+AF36),6) -> 363.6576 | AC36: =ROUND((((ES36*0)*1)),6) -> 0 | AD36: =ROUND((((((ET36*0.4)*1.2))-(((EU36*0.4)*1.2)))+AE36),6) -> 4.848 | AE36: =ROUND((((EU36*0.4)*1.2)),6) -> 0.6864 | AF36: =ROUND((((EV36*0.4)*1.2)),6) -> 358.8096 | AG36: =ROUND((AP36),6) -> 0 | AH36: =(((EW36*0.4)*1.2)) -> 28.032 | AI36: =(((EX36*0.4)*1.2)) -> 0 | AJ36: =(AS36) -> 0 | AK36: 842.78 | AL36: 85.16 | AM36: 10.1 | AN36: 1.43 | AO36: 747.52 | AP36: 0 | AQ36: 58.4 | AR36: 0 | AS36: 0 | AT36: 109 | AU36: 61 | AV36: 1.067 | AW36: 1 | AZ36: 1 | BA36: 1 | BB36: 1 | BC36: 1 | BH36: 0 | BI36: 1 | BJ36: ТСН-2001.3 Доп. 79, Сб. 16, т. 13, поз. 1 | BM36: 21 | BN36: 0 | BO36: 3.16-13-1 | BP36: 1 | BQ36: 30 | BR36: 0 | BS36: 1 | BT36: 1 | BU36: 1 | BV36: 1 | BW36: 1 | BX36: 1 | BZ36: 109 | CA36: 61 | CE36: 1566 | CF36: 0 | CG36: 0 | CM36: 0 | CN36: Поправка: Гл.6.Прил.2.2.п.2.2.13_06.00.01.35.003 Наименование: При демонтаже внутренних санитарно-технических устройств и газопроводов Поправка: Гл.12.Прил.8.п.8. 3_12.00.01.11.001 Наименование: При наличии напряженных и стесненных условий производства работ (стесненность, сложность складирования и транспортной логистики и т.п.) для объектов, расположенных в пределах круговой магистральной системы улиц "Садовое кольцо" города Москвы | CO36: 0 | CP36: =(P36+Q36+S36) -> 543.23 | CQ36: =ROUND((ROUND((AC36*AW36*1),2)*BC36),2) -> 0 | CR36: =(ROUND((ROUND(((((ET36*0.4)*1.2))*AV36*1),2)*BB36),2)+ROUND((ROUND(((AE36-(((EU36*0.4)*1.2)))*AV36*1),2)*BS36),2)) -> 5.17 | CS36: =(ROUND((ROUND(((((EU36*0.4)*1.2))*AV36*1),2)*BS36),2)+ROUND((ROUND(((AE36-(((EU36*0.4)*1.2)))*AV36*1),2)*BS36),2)) -> 0.73 | CT36: =ROUND((ROUND((AF36*AV36*1),2)*BA36),2) -> 382.85 | CU36: =AG36 -> 0 | CV36: =(AH36*AV36) -> 29.910144 | CW36: =AI36 -> 0 | CX36: =AJ36 -> 0 | CY36: =(ROUND((((S36+ROUND((ROUND(((((EU36*0.4)*1.2))*AV36*1),2)*BS36),2))*AT36)/100),2)+ROUND(((ROUND((ROUND(((AE36-(((EU36*0.4)*1.2)))*AV36*1),2)*BS36),2)*AT36)/100),2)) -> 585.02 | CZ36: =(ROUND((((S36+ROUND((ROUND(((((EU36*0.4)*1.2))*AV36*1),2)*BS36),2))*AU36)/100),2)+ROUND(((ROUND((ROUND(((AE36-(((EU36*0.4)*1.2)))*AV36*1),2)*BS36),2)*AU36)/100),2)) -> 327.4 | DB36: 15 | DD36: *0)*1 | DE36: *0,4)*1,2 | DF36: *0,4)*1,2 | DG36: *0,4)*1,2 | DI36: *0,4)*1,2 | DJ36: *0,4)*1,2 | DN36: 0 | DO36: 0 | DP36: 1 | DQ36: 1 | DU36: 1003 | DV36: 100 м | DW36: 100 м | DX36: 100 | EE36: 85635393 | EF36: 30 | EG36: Строительные работы | EH36: 0 | EJ36: 1 | EK36: 21 | EL36: ТСН-2001.3-16. Трубопроводы внутренние | EM36: ТСН-2001.3-16-1 | EO36: Поправка: Гл.6.Прил.2.2.п.2.2.13_06.00.01.35.003 Поправка: Гл.12.Прил.8.п.8. 3_12.00.01.11.001 | EQ36: 131072 | ER36: 842.78 | ES36: 85.16 | ET36: 10.1 | EU36: 1.43 | EV36: 747.52 | EW36: 58.4 | EX36: 0 | EY36: 0 | FQ36: 0 | FR36: 0 | FS36: 0 | FX36: 109 | FY36: 61 | GD36: 1 | GF36: 1569691367 | GG36: 2 | GH36: 1 | GI36: 2 | GJ36: 0 | GK36: 0 | GL36: =ROUND(IF(AND(BH36=3,BI36=3,FS36<>0),P36,0),2) -> 0 | GM36: =ROUND(O36+X36+Y36,2)+GX36 -> 1456.16 | GN36: =IF(OR(BI36=0,BI36=1),GM36-GX36,0) -> 1456.16 | GO36: =IF(BI36=2,GM36-GX36,0) -> 0 | GP36: =IF(BI36=4,GM36-GX36,0) -> 0 | GR36: 0 | GS36: 3 | GT36: 0 | GV36: =ROUND((GT36),6) -> 0 | GW36: 1 | GX36: =ROUND(HC36*I36,2) -> 0 | HA36: 0 | HB36: 0 | HC36: =GV36*GW36 -> 0 | HS36: 0 | IK36: 0
A37: 17 | B37: 1 | C37: =ROW(SmtRes!A60) -> 60 | D37: =ROW(EtalonRes!A82) -> 82 | E37: 5 | F37: 3.16-13-1 | G37: Прокладка трубопроводов канализации из ПВХ труб диаметром до 50 мм (демонтаж) | H37: 100 м | I37: =ROUND((120+20)/100,9) -> 1.4 | J37: 0 | K37: =ROUND((120+20)/100,9) -> 1.4 | O37: =ROUND(CP37,2) -> 30323.22 | P37: =ROUND((ROUND((AC37*AW37*I37),2)*BC37),2) -> 0 | Q37: =(ROUND((ROUND(((((ET37*0.4)*1.2))*AV37*I37),2)*BB37),2)+ROUND((ROUND(((AE37-(((EU37*0.4)*1.2)))*AV37*I37),2)*BS37),2)) -> 120.18 | R37: =(ROUND((ROUND(((((EU37*0.4)*1.2))*AV37*I37),2)*BS37),2)+ROUND((ROUND(((AE37-(((EU37*0.4)*1.2)))*AV37*I37),2)*BS37),2)) -> 58.04 | S37: =ROUND((ROUND((AF37*AV37*I37),2)*BA37),2) -> 30203.04 | T37: =ROUND(CU37*I37,2) -> 0 | U37: =CV37*I37 -> 41.874202 | V37: =CW37*I37 -> 0 | W37: =ROUND(CX37*I37,2) -> 0 | X37: =(ROUND((((S37+ROUND((ROUND(((((EU37*0.4)*1.2))*AV37*I37),2)*BS37),2))*AT37)/100),2)+ROUND(((ROUND((ROUND(((AE37-(((EU37*0.4)*1.2)))*AV37*I37),2)*BS37),2)*AT37)/100),2)) -> 32984.58 | Y37: =(ROUND((((S37+ROUND((ROUND(((((EU37*0.4)*1.2))*AV37*I37),2)*BS37),2))*AU37)/100),2)+ROUND(((ROUND((ROUND(((AE37-(((EU37*0.4)*1.2)))*AV37*I37),2)*BS37),2)*AU37)/100),2)) -> 18459.26 | AA37: 86549536 | AB37: =ROUND((AC37+AD37+AF37),6) -> 363.6576 | AC37: =ROUND((((ES37*0)*1)),6) -> 0 | AD37: =ROUND((((((ET37*0.4)*1.2))-(((EU37*0.4)*1.2)))+AE37),6) -> 4.848 | AE37: =ROUND((((EU37*0.4)*1.2)),6) -> 0.6864 | AF37: =ROUND((((EV37*0.4)*1.2)),6) -> 358.8096 | AG37: =ROUND((AP37),6) -> 0 | AH37: =(((EW37*0.4)*1.2)) -> 28.032 | AI37: =(((EX37*0.4)*1.2)) -> 0 | AJ37: =(AS37) -> 0 | AK37: 842.78 | AL37: 85.16 | AM37: 10.1 | AN37: 1.43 | AO37: 747.52 | AP37: 0 | AQ37: 58.4 | AR37: 0 | AS37: 0 | AT37: 109 | AU37: 61 | AV37: 1.067 | AW37: 1 | AZ37: 1 | BA37: 56.35 | BB37: 16.6 | BC37: 12.82 | BH37: 0 | BI37: 1 | BJ37: ТСН-2001.3 Доп. 79, Сб. 16, т. 13, поз. 1 | BM37: 21 | BN37: 0 | BO37: 3.16-13-1 | BP37: 1 | BQ37: 30 | BR37: 0 | BS37: 56.35 | BT37: 1 | BU37: 1 | BV37: 1 | BW37: 1 | BX37: 1 | BZ37: 109 | CA37: 61 | CE37: 1566 | CF37: 0 | CG37: 0 | CM37: 0 | CN37: Поправка: Гл.6.Прил.2.2.п.2.2.13_06.00.01.35.003 Наименование: При демонтаже внутренних санитарно-технических устройств и газопроводов Поправка: Гл.12.Прил.8.п.8. 3_12.00.01.11.001 Наименование: При наличии напряженных и стесненных условий производства работ (стесненность, сложность складирования и транспортной логистики и т.п.) для объектов, расположенных в пределах круговой магистральной системы улиц "Садовое кольцо" города Москвы | CO37: 0 | CP37: =(P37+Q37+S37) -> 30323.22 | CQ37: =ROUND((ROUND((AC37*AW37*1),2)*BC37),2) -> 0 | CR37: =(ROUND((ROUND(((((ET37*0.4)*1.2))*AV37*1),2)*BB37),2)+ROUND((ROUND(((AE37-(((EU37*0.4)*1.2)))*AV37*1),2)*BS37),2)) -> 85.82 | CS37: =(ROUND((ROUND(((((EU37*0.4)*1.2))*AV37*1),2)*BS37),2)+ROUND((ROUND(((AE37-(((EU37*0.4)*1.2)))*AV37*1),2)*BS37),2)) -> 41.14 | CT37: =ROUND((ROUND((AF37*AV37*1),2)*BA37),2) -> 21573.6 | CU37: =AG37 -> 0 | CV37: =(AH37*AV37) -> 29.910144 | CW37: =AI37 -> 0 | CX37: =AJ37 -> 0 | CY37: =(ROUND((((S37+ROUND((ROUND(((((EU37*0.4)*1.2))*AV37*1),2)*BS37),2))*AT37)/100),2)+ROUND(((ROUND((ROUND(((AE37-(((EU37*0.4)*1.2)))*AV37*1),2)*BS37),2)*AT37)/100),2)) -> 32966.16 | CZ37: =(ROUND((((S37+ROUND((ROUND(((((EU37*0.4)*1.2))*AV37*1),2)*BS37),2))*AU37)/100),2)+ROUND(((ROUND((ROUND(((AE37-(((EU37*0.4)*1.2)))*AV37*1),2)*BS37),2)*AU37)/100),2)) -> 18448.95 | DB37: 17 | DD37: *0)*1 | DE37: *0,4)*1,2 | DF37: *0,4)*1,2 | DG37: *0,4)*1,2 | DI37: *0,4)*1,2 | DJ37: *0,4)*1,2 | DN37: 0 | DO37: 0 | DP37: 1 | DQ37: 1 | DU37: 1003 | DV37: 100 м | DW37: 100 м | DX37: 100 | EE37: 85635393 | EF37: 30 | EG37: Строительные работы | EH37: 0 | EJ37: 1 | EK37: 21 | EL37: ТСН-2001.3-16. Трубопроводы внутренние | EM37: ТСН-2001.3-16-1 | EO37: Поправка: Гл.6.Прил.2.2.п.2.2.13_06.00.01.35.003 Поправка: Гл.12.Прил.8.п.8. 3_12.00.01.11.001 | EQ37: 131072 | ER37: 842.78 | ES37: 85.16 | ET37: 10.1 | EU37: 1.43 | EV37: 747.52 | EW37: 58.4 | EX37: 0 | EY37: 0 | FQ37: 0 | FR37: 0 | FS37: 0 | FX37: 109 | FY37: 61 | GD37: 1 | GF37: 1569691367 | GG37: 2 | GH37: 1 | GI37: 2 | GJ37: 0 | GK37: 0 | GL37: =ROUND(IF(AND(BH37=3,BI37=3,FS37<>0),P37,0),2) -> 0 | GM37: =ROUND(O37+X37+Y37,2)+GX37 -> 81767.06 | GN37: =IF(OR(BI37=0,BI37=1),GM37-GX37,0) -> 81767.06 | GO37: =IF(BI37=2,GM37-GX37,0) -> 0 | GP37: =IF(BI37=4,GM37-GX37,0) -> 0 | GR37: 0 | GS37: 3 | GT37: 0 | GV37: =ROUND((GT37),6) -> 0 | GW37: 1 | GX37: =ROUND(HC37*I37,2) -> 0 | HA37: 0 | HB37: 0 | HC37: =GV37*GW37 -> 0 | HS37: 0 | IK37: 0
A38: 17 | B38: 1 | C38: =ROW(SmtRes!A62) -> 62 | D38: =ROW(EtalonRes!A84) -> 84 | E38: 6 | F38: 6.65-2-2 | G38: Разборка трубопроводов из чугунных канализационных труб диаметром до 100 мм | H38: 100 м | I38: =ROUND((140+30)/100,9) -> 1.7 | J38: 0 | K38: =ROUND((140+30)/100,9) -> 1.7 | O38: =ROUND(CP38,2) -> 2142.57 | P38: =ROUND((ROUND((AC38*AW38*I38),2)*BC38),2) -> 0 | Q38: =(ROUND((ROUND((((ET38*1.2))*AV38*I38),2)*BB38),2)+ROUND((ROUND(((AE38-((EU38*1.2)))*AV38*I38),2)*BS38),2)) -> 0 | R38: =(ROUND((ROUND((((EU38*1.2))*AV38*I38),2)*BS38),2)+ROUND((ROUND(((AE38-((EU38*1.2)))*AV38*I38),2)*BS38),2)) -> 0 | S38: =ROUND((ROUND((AF38*AV38*I38),2)*BA38),2) -> 2142.57 | T38: =ROUND(CU38*I38,2) -> 0 | U38: =CV38*I38 -> 182.19056 | V38: =CW38*I38 -> 0 | W38: =ROUND(CX38*I38,2) -> 0 | X38: =(ROUND((((S38+ROUND((ROUND((((EU38*1.2))*AV38*I38),2)*BS38),2))*AT38)/100),2)+ROUND(((ROUND((ROUND(((AE38-((EU38*1.2)))*AV38*I38),2)*BS38),2)*AT38)/100),2)) -> 1864.04 | Y38: =(ROUND((((S38+ROUND((ROUND((((EU38*1.2))*AV38*I38),2)*BS38),2))*AU38)/100),2)+ROUND(((ROUND((ROUND(((AE38-((EU38*1.2)))*AV38*I38),2)*BS38),2)*AU38)/100),2)) -> 942.73 | AA38: 86549534 | AB38: =ROUND((AC38+AD38+AF38),6) -> 1203.756 | AC38: =ROUND(((ES38*1)),6) -> 0 | AD38: =ROUND(((((ET38*1.2))-((EU38*1.2)))+AE38),6) -> 0 | AE38: =ROUND(((EU38*1.2)),6) -> 0 | AF38: =ROUND(((EV38*1.2)),6) -> 1203.756 | AG38: =ROUND((AP38),6) -> 0 | AH38: =((EW38*1.2)) -> 102.36 | AI38: =((EX38*1.2)) -> 0 | AJ38: =(AS38) -> 0 | AK38: 1003.13 | AL38: 0 | AM38: 0 | AN38: 0 | AO38: 1003.13 | AP38: 0 | AQ38: 85.3 | AR38: 0 | AS38: 0 | AT38: 87 | AU38: 44 | AV38: 1.047 | AW38: 1 | AZ38: 1 | BA38: 1 | BB38: 1 | BC38: 1 | BH38: 0 | BI38: 1 | BJ38: ТСН-2001.6 Доп. 68, Сб. 65, т. 2, поз. 2 | BM38: 102 | BN38: 0 | BO38: 6.65-2-2 | BP38: 1 | BQ38: 60 | BR38: 0 | BS38: 1 | BT38: 1 | BU38: 1 | BV38: 1 | BW38: 1 | BX38: 1 | BZ38: 87 | CA38: 44 | CE38: 1566 | CF38: 0 | CG38: 0 | CM38: 0 | CN38: Поправка: Гл.12.Прил.8.п.8. 3_12.00.01.11.001 Наименование: При наличии напряженных и стесненных условий производства работ (стесненность, сложность складирования и транспортной логистики и т.п.) для объектов, расположенных в пределах круговой магистральной системы улиц "Садовое кольцо" города Москвы | CO38: 0 | CP38: =(P38+Q38+S38) -> 2142.57 | CQ38: =ROUND((ROUND((AC38*AW38*1),2)*BC38),2) -> 0 | CR38: =(ROUND((ROUND((((ET38*1.2))*AV38*1),2)*BB38),2)+ROUND((ROUND(((AE38-((EU38*1.2)))*AV38*1),2)*BS38),2)) -> 0 | CS38: =(ROUND((ROUND((((EU38*1.2))*AV38*1),2)*BS38),2)+ROUND((ROUND(((AE38-((EU38*1.2)))*AV38*1),2)*BS38),2)) -> 0 | CT38: =ROUND((ROUND((AF38*AV38*1),2)*BA38),2) -> 1260.33 | CU38: =AG38 -> 0 | CV38: =(AH38*AV38) -> 107.17092 | CW38: =AI38 -> 0 | CX38: =AJ38 -> 0 | CY38: =(ROUND((((S38+ROUND((ROUND((((EU38*1.2))*AV38*1),2)*BS38),2))*AT38)/100),2)+ROUND(((ROUND((ROUND(((AE38-((EU38*1.2)))*AV38*1),2)*BS38),2)*AT38)/100),2)) -> 1864.04 | CZ38: =(ROUND((((S38+ROUND((ROUND((((EU38*1.2))*AV38*1),2)*BS38),2))*AU38)/100),2)+ROUND(((ROUND((ROUND(((AE38-((EU38*1.2)))*AV38*1),2)*BS38),2)*AU38)/100),2)) -> 942.73 | DB38: 19 | DD38: *1 | DE38: *1,2 | DF38: *1,2 | DG38: *1,2 | DI38: *1,2 | DJ38: *1,2 | DN38: 0 | DO38: 0 | DP38: 1 | DQ38: 1 | DU38: 1003 | DV38: 100 м | DW38: 100 м | DX38: 100 | EE38: 85635475 | EF38: 60 | EG38: Ремонтно-строительные работы | EH38: 0 | EJ38: 1 | EK38: 102 | EL38: ТСН-2001.6-65. Внутренние санитарно-технические работы: демонтаж и разборка | EM38: ТСН-2001.6-65-1 | EO38: Поправка: Гл.12.Прил.8.п.8. 3_12.00.01.11.001 | EQ38: 131072 | ER38: 1003.13 | ES38: 0 | ET38: 0 | EU38: 0 | EV38: 1003.13 | EW38: 85.3 | EX38: 0 | EY38: 0 | FQ38: 0 | FR38: 0 | FS38: 0 | FX38: 87 | FY38: 44 | GD38: 1 | GF38: -1541502670 | GG38: 2 | GH38: 1 | GI38: 2 | GJ38: 0 | GK38: 0 | GL38: =ROUND(IF(AND(BH38=3,BI38=3,FS38<>0),P38,0),2) -> 0 | GM38: =ROUND(O38+X38+Y38,2)+GX38 -> 4949.34 | GN38: =IF(OR(BI38=0,BI38=1),GM38-GX38,0) -> 4949.34 | GO38: =IF(BI38=2,GM38-GX38,0) -> 0 | GP38: =IF(BI38=4,GM38-GX38,0) -> 0 | GR38: 0 | GS38: 3 | GT38: 0 | GV38: =ROUND((GT38),6) -> 0 | GW38: 1 | GX38: =ROUND(HC38*I38,2) -> 0 | HA38: 0 | HB38: 0 | HC38: =GV38*GW38 -> 0 | HS38: 0 | IK38: 0
