Workbook

Sheet замечания МГЭ
A1: Дело: | C1: МГЭ/56181-1/9 от 29.12.2025
A2: Объект: | C2: Капитальный ремонт здания Государственного бюджетного общеобразовательного учреждения города Москвы «Школа № 236». 1 этап
A3: Текущий уровень цен | C3: III квартал 2025 года
A5: № п/п | B5: Шифр | C5: Наименование МТР | D5: Единица измерения | E5: Количество | F5: Заявленная стоимость, руб./ед.изм. с НДС | G5: ВСЕГО заявленная стоимость, руб. с НДС | H5: Примечание по ПД | I5: Объем МТР в ВОР
A6: 45,1 | B6: КА-1 | C6: Трехрожковый настенный кронштейн для флага 81,73 = [950 / 1,2 / 9,88] + 2% Заг.скл | D6: ШТ | E6: 1 | F6: 950 | G6: =F6*E6 -> 950 | I6: Необходимо подтвердить наличие МТР данными ПД/
A7: 49,1 | B7: КА-2 | C7: Пеностекло толщ. 150 мм 2 796,05 = [32 500 / 1,2 / 9,88] + 2% Заг.скл | D7: м3 | E7: 26.83665 | F7: 32500 | G7: =F7*E7 -> 872191.12 | H7: Объемы МТР необходимо привести в соответствие с ВОР АР. | I7: =173.7*0.15 -> 26.055
A8: 61,1 | B8: КА 3 | C8: Металлическое ограждения высотой 1200 мм из нержавеющей полированной стали высотой 1200 мм в осях 18-20/К, поручни на высоте 900 и 500 мм с нетравмирующим завершением, заполнение ограждения из вертикальных элементов-стоек с шагом не более 100 мм 743,31 = [8 639,95 / 1,2 / 9,88] + 2% Заг.скл | D8: МП | E8: 21.35 | F8: 8639.95 | G8: =F8*E8 -> 184462.93 | I8: =E8 -> 21.35
A9: 62,1 | B9: КА 4 | C9: Ограждение лестницы на пандусе высотой 900 мм Поручни на высоте 900 мм: Труба C50х1,5 473,18 = [5 500 / 1,2 / 9,88] + 2% Заг.скл | D9: МП | E9: 56.16 | F9: 5500 | G9: =F9*E9 -> 308880 | I9: =E9 -> 56.16
A10: 63,1 | B10: КА 4 | C10: Ограждение лестницы на служебном входе из пищеблока, входной площадке, дебаркадере, высотой 900 мм Поручни на высоте 900 мм: Труба C50х1,5 473,18 = [5 500 / 1,2 / 9,88] + 2% Заг.скл | D10: МП | E10: 460 | F10: 5500 | G10: =F10*E10 -> 2530000 | I10: =E10 -> 460
A11: 66,5 | B11: КА 5 | C11: Керамогранит толщиной 20 мм 404,35 = [4 700 / 1,2 / 9,88] + 2% Заг.скл | D11: м2 | E11: 32.562 | F11: 4700 | G11: =F11*E11 -> 153041.4 | H11: Объемы МТР необходимо привести в соответствие с ВОР АР. | I11: 30.15
A12: 80,1 | B12: КА 6 | C12: Металлические грязезащитные решетки (Щетка +Резина + Скребок) =1,5 м*0,5 м*8 шт. =6 м2 2 120,01 = [24 642 / 1,2 / 9,88] + 2% Заг.скл | D12: м2 | E12: 6 | F12: 24642 | G12: =F12*E12 -> 147852 | I12: =1.5*0.5*8 -> 6
A13: 123,1 | B13: КА-2 | C13: Пеностекло толщ. 100 мм 2 796,05 = [32 500 / 1,2 / 9,88] + 2% Заг.скл | D13: м3 | E13: 13.4724 | F13: 32500 | G13: =F13*E13 -> 437853 | H13: Необходимо подтвердить наличие МТР данными ПД.
A14: 151,1 | B14: КА -8 | C14: Трансформируемые глухие перегородки по направляющим профилям в полу и потолке с использованием ограничителей хода с заполнением звукоизоляционными панелями 2 777,99 = [32 290 / 1,2 / 9,88] + 2% Заг.скл | D14: м2 | E14: 79.2 | F14: 32290 | G14: =F14*E14 -> 2557368 | I14: =6*3.3*4 -> 79.2
A15: 157,1 | B15: КА 9 | C15: Т-образный профиль из нержавеющей стали 2700х9х14 мм 98,14 = [1 140,74 / 1,2 / 9,88] + 2% Заг.скл | D15: м | E15: 168 | F15: 1140.74 | G15: =F15*E15 -> 191644.32 | H15: Объемы МТР необходимо привести в соответствие с ВОР АР. | I15: 160
A16: 158,1 | B16: КА -10 | C16: Остекленные перегородки из алюминиевого профиля. Заполнение однокамерным стеклопакетом толщиной 50 мм с огнестойким стеклом, противопожарную с пределом огнестойкости не менее EIW30, класс защиты остекления СМ4 1 591,60 = [18 500 / 1,2 / 9,88] + 2% Заг.скл | D16: м2 | E16: 67.2 | F16: 18500 | G16: =F16*E16 -> 1243200 | I16: 67.2
A17: 159,1 | B17: КА 11 | C17: Сантехнические перегородки из HPL 731,28 = [8 500 / 1,2 / 9,88] + 2% Заг.скл | D17: м2 | E17: 89.2 | F17: 8500 | G17: =F17*E17 -> 758200 | I17: 89.2
A18: 164,1 | B18: КА 12 | C18: Декоративные стеновые панели кубообразные 80х80 мм 258,10 = [3 000 / 1,2 / 9,88] + 2% Заг.скл | D18: м2 | E18: 33.6 | F18: 3000 | G18: =F18*E18 -> 100800 | I18: 33.6
A19: 165,1 | B19: КА 4.1 | C19: Ограждение на внутренних лестничных клетках из нержавеющей полированной стали высотой 1200 мм (с двумя поручными): Поручни на высоте 500, 900 602,11 = [6 998,56 / 1,2 / 9,88] + 2% Заг.скл | D19: м | E19: 69.18 | F19: 6998.56 | G19: =F19*E19 -> 484160.38 | I19: 69.18
A20: 166,1 | B20: КА 13 | C20: Пристенный поручень для внутренних лестницы с двойным поручнем на высота 900 и 500 мм 473,18 = [5 500 / 1,2 / 9,88] + 2% Заг.скл | D20: м2 | E20: 64.4 | F20: 5500 | G20: =F20*E20 -> 354200 | H20: Единицы измерения МТР необходимо привести в соответствие с ПД - м.п. | I20: 64.4
A21: 167,1 | B21: КА 4.2 | C21: Ограждение лестницы в проеме окна (высота 1200) Вертикальное заполнение ригелей с шагом 100 мм 743,31 = [8 639,95 / 1,2 / 9,88] + 2% Заг.скл | D21: м | E21: 64.4 | F21: 8639.95 | G21: =F21*E21 -> 556412.78 | I21: 64.4
A22: 183,3 | B22: КА 30 | C22: Окно ПВХ ОК-1, ОК-1/1, ОК-1/2, ОК-1/3, ОК-1/4. Профильная система REHAU 70 Delight. Цвет RAL 7016. Ламинация. Фурнитура ROTO или аналог. Заполнение - двухкамерный стеклопакет (СМ4). Индивидуальное изготовление. Габариты: 2300*2050 2 460,53 = [28 600 / 1,2 / 9,88] + 2% Заг.скл | D22: м2 | E22: 1065.6 | F22: 28600 | G22: =F22*E22 -> 30476160 | I22: =[1]ПД!P3 -> 1065.59
A23: 183,4 | B23: КА 31 | C23: Окно Е30. ОК-1/1* Алюминиевый профиль Realit RW71, цвет RAL 7016. Заполнение -огнестойкое стекло, Размеры: 2300*2050 5 306,31 = [61 678 / 1,2 / 9,88] + 2% Заг.скл | D23: м2 | E23: 9.43 | F23: 61678 | G23: =F23*E23 -> 581623.54 | H23: Технические характеристики МТР необходимо привести в соответствие с ПД - окно ПВХ, а не алюминиевое. | I23: =2.3*2.05*2 -> 9.43
A24: 184,3 | B24: КА 32 | C24: Окно ПВХ ОК-3, ОК-4. Профильная система REHAU 70 Delight. Цвет RAL 7016. Ламинация. Фурнитура ROTO или аналог. Заполнение -двухкамерный стеклопакет (СМ4 ). Индивидуальное изготовление. Размеры: 2300*776 2 460,53 = [28 600 / 1,2 / 9,88] + 2% Заг.скл | D24: м2 | E24: 29.28 | F24: 28600 | G24: =F24*E24 -> 837408 | I24: =2.3*0.776*4+0.9*2.05*12 -> 29.2792
A25: 184,4 | B25: КА 33 | C25: Окно ЕЗО. ОК-1/4* Алюминиевый профиль Realit RW71, цвет RAL 7016. Заполнение - огнестойкое стекло. Индивидуальное изготовление. Размеры: 2400*400 5 306,31 = [61 678 / 1,2 / 9,88] + 2% Заг.скл | D25: м2 | E25: 2.88 | F25: 61678 | G25: =F25*E25 -> 177632.64 | H25: Технические характеристики МТР необходимо привести в соответствие с ПД - окно ПВХ, а не алюминиевое. | I25: =2.4*0.4*3 -> 2.88
A26: 185,3 | B26: КА 34 | C26: Окно ПВХ. ОК-3/1 Профильная система REHAU 70 Delight. Цвет RAL 7016. Ламинация. Фурнитура ROTO или аналог. Заполнение - двухкамерный стеклопакет (СМ4 ). Индивидуальное изготовление. Размеры: 2300*776 2 460,53 = [28 600 / 1,2 / 9,88] + 2% Заг.скл | D26: м2 | E26: 10.71 | F26: 28600 | G26: =F26*E26 -> 306306 | I26: =2.3*0.776*6 -> 10.7088
A27: 185,4 | B27: КА 35 | C27: Окно ПВХ. ОК-5 Профильная система REHAU 70 Delight. Цвет RAL 7016. Ламинация. Фурнитура ROTO или аналог. Заполнение -двухкамерный стеклопакет (СМ4 ). Индивидуальное изготовление. Размеры: 900*2050 2 460,53 = [28 600 / 1,2 / 9,88] + 2% Заг.скл | D27: м2 | E27: 5.54 | F27: 28600 | G27: =F27*E27 -> 158444 | I27: =0.9*2.05*3 -> 5.535
A28: 186,3 | B28: КА 36 | C28: Окно ПВХ. ОК-2/1 Профильная система REHAU 70 Delight. Цвет RAL 7016. Ламинация. Фурнитура ROTO или аналог. Заполнение - двухкамерный стеклопакет (СМ4). Размеры: 2300*2050 2 460,53 = [28 600 / 1,2 / 9,88] + 2% Заг.скл | D28: м2 | E28: 9.43 | F28: 28600 | G28: =F28*E28 -> 269698 | I28: =2.3*2.05*2 -> 9.43
A29: 187,3 | B29: КА 37 | C29: Окно Е30. ОК-1* Алюминиевый профиль Realit RW71, цвет RAL 7016. Заполнение -огнестойкое стекло. Размеры: 2300*2050 5 306,31 = [61 678 / 1,2 / 9,88] + 2% Заг.скл | D29: м2 | E29: 169.74 | F29: 61678 | G29: =F29*E29 -> 10469224 | I29: =2.3*2.05*36 -> 169.74
A30: 188,3 | B30: КА 38 | C30: Окно Е30. ОК-3* Алюминиевый профиль Realit RW71, цвет RAL 7016. Заполнение -огнестойкое стекло. Размеры: 2300*776 5 306,31 = [61 678 / 1,2 / 9,88] + 2% Заг.скл | D30: м2 | E30: 17.848 | F30: 61678 | G30: =F30*E30 -> 1100828.9 | I30: =2.3*0.776*10 -> 17.848
A31: 189,1 | B31: КА 68 | C31: Рольставни металлические 700х1272 мм 1 471,16 = [17 100 / 1,2 / 9,88] + 2% Заг.скл | D31: шт. | E31: 4 | F31: 17100 | G31: =F31*E31 -> 68400 | I31: Необходимо подтвердить наличие МТР данными ПД/
A32: 192,1 | B32: КА 63 | C32: Керамическая плитка Kerama Marazzi Монфорте белый матовый обрезной 14010R 269,03 = [3 127 / 1,2 / 9,88] + 2% Заг.скл | D32: м2 | E32: 233.32 | F32: 3127 | G32: =F32*E32 -> 729591.64 | I32: =583.3*0.4 -> 233.32
A33: 193,1 | B33: КА 63 | C33: Подоконники деревянные, совмещенные с защитными экранами радиаторов отопления: подоконник толщиной 24мм, материал фанера березовая с покрытием огнестойким лаком КМ1; фасад экрана толщиной 12мм, материал МДФ с противопожарной обработкой КМ1 с 2-х сторон и окрашенный с 2-х сторон 1 743,02 = [20 260 / 1,2 / 9,88] + 2% Заг.скл | D33: м | E33: 1457.5 | F33: 20260 | G33: =F33*E33 -> 29528950 | I33: =E33 -> 1457.5
A34: 198,1 | B34: КА 39 | C34: Витраж. / ВН-1, ВН-2, ВН-3, ВН-4, ВН-5 Алюминиевый профиль Realit RF50, окрашенный порошковой краской, цвет RAL 7016. Заполнение - Стемалит \ Стеклопакет. (6М1/зак-12-4М1-10-441 И) (СМ4) Индивидуальное изготовление (без учета квадратуры дверей) 4 668,89 = [54 269 / 1,2 / 9,88] + 2% Заг.скл | D34: м2 | E34: 127.14 | F34: 54269 | G34: =F34*E34 -> 6899760.7 | H34: Объемы МТР необходимо привести в соответствие с ВОР АР - необходимо вычесть площади дверей, т.к. они включены в смету отдельно. | I34: =[1]ПД!P94 -> 117.012
A35: 198,2 | B35: КА 43 | C35: Бронированная пленка к ВН-1, ВН-2, ВН-3, ВН-4, ВН-5 335,53 = [3 900 / 1,2 / 9,88] + 2% Заг.скл | D35: м2 | E35: 127.14 | F35: 3900 | G35: =F35*E35 -> 495846 | I35: =I34 -> 117.012
A36: 198,3 | B36: КА 44 | C36: Ручка-поручень, на высоту створки.нержавеющая сталь комплект/ ВН-4, ВН-5 2 354,16 = [27 363,7 / 1,2 / 9,88] + 2% Заг.скл | D36: компл. | E36: 4 | F36: 27363.7 | G36: =F36*E36 -> 109454.8 | I36: 4
A37: 200,1 | B37: КА 40 | C37: Вв-6, Вв-7 Витраж EIW30 с дверью. Перегородка Алюминиевый профиль Realit RF50, окрашенный порошковой краской, цвет RAL 7016. Заполнение - огнестойкое стекло. Индивидуальное изготовление 5 201,35 = [60 458 / 1,2 / 9,88] + 2% Заг.скл | D37: м2 | E37: 71.99 | F37: 60458 | G37: =F37*E37 -> 4352371.4 | I37: =[1]ПД!P163 -> 71.99325
A38: 200,2 | B38: КА 44 | C38: Ручка-поручень, на высоту створки.нержавеющая сталь комплект/ Вв-6 -5 шт., Вв-7 -5 шт. 2 354,16 = [27 363,7 / 1,2 / 9,88] + 2% Заг.скл | D38: компл. | E38: 10 | F38: 27363.7 | G38: =F38*E38 -> 273637 | I38: 10
A39: 202,1 | B39: КА 41 | C39: Вв-8, 9, 10, 11, 11.1 Витраж ЕI30 Перегородка Алюминиевый профиль Realit RF50, окрашенный порошковой краской, цвет RAL 901 О. Заполнение -огнестойкое стекло. Индивидуальное изготовление 5 201,35 = [60 458 / 1,2 / 9,88] + 2% Заг.скл | D39: м2 | E39: 22.8 | F39: 60458 | G39: =F39*E39 -> 1378442.4 | I39: =E39 -> 22.8
A40: 202,2 | B40: КА 43 | C40: Бронированная пленка к Вв-8, 9, 10, 11, 11.1 335,53 = [3 900 / 1,2 / 9,88] + 2% Заг.скл | D40: м2 | E40: 22.8 | F40: 3900 | G40: =F40*E40 -> 88920 | I40: =E40 -> 22.8
A41: 202,3 | B41: КА 44 | C41: Ручка-поручень, на высоту створки.нержавеющая сталь комплект/ Вв-8, 9, 10, 11, 11.1 2 354,16 = [27 363,7 / 1,2 / 9,88] + 2% Заг.скл | D41: компл. | E41: 5 | F41: 27363.7 | G41: =F41*E41 -> 136818.5 | I41: 5
...
