Workbook
Name пищеблок: 'П1 Воздух Школа ст.П'!$B$54:$Q$71

Sheet П1 Воздух Школа ст.П
C1: Приложение 1. Расчет воздухообменов | U1: Псистемы
C2: № | D2: Наименование | E2: Катег. Пом. | F2: Класс чистоты | G2: S, м2 | H2: V, м3 | I2: Кол. чел. | J2: Кратность | L2: Воздухообмен, м3/ч | N2: Система | P2: Примечание | Q2: Расположение на плане | U2: —
J3: Приток | K3: Вытяжка | L3: Приток | M3: Выт | N3: Приток | O3: Выт | U3: П1 | V3: Спортивный зал | W3: =L8 -> 2190
B4: Подвал | U4: П2 | V4: Актовый зал, Технический центр, Артистическая | W4: =SUM(M155:M157) -> 3320
C5: 0.01 | D5: Технологическая лестница | G5: 10.1 | H5: =G5*2.65 -> 26.765 | J5: - | K5: - | L5: - | M5: - | Q5: Левое крыло | U5: П3 | V5: Обеденный зал | W5: =L55 -> 3190
C6: 0.01а | D6: Тамбур-шлюз 1-ого типа | G6: 4.6 | H6: =G6*2.65 -> 12.19 | J6: - | K6: - | L6: - | M6: - | N6: - | Q6: Центр | U6: П4 | V6: Пищеблок. Производственные помещения | W6: =SUM(L56,L60,L61,L63,L65,L68) -> 8685
C7: 0.02 | D7: Технологическая лестница | G7: 7.3 | H7: =G7*2.65 -> 19.345 | J7: - | K7: - | L7: - | M7: - | Q7: Правое крыло | U7: П5 | V7: Учебные кабинеты. Левое крыло | W7: =SUM(L27,L29,L33,L36,L44,L81,L97,L98,L99,L100,L101,L102,L112,L127,L128,L129,L130,L131,L132,L139,L159,L160,L161,L162,L166) -> 9055
C8: 0.03 | D8: Спортивный зал | G8: 262.7 | H8: =G8*2.65 -> 696.155 | I8: 26 | J8: 80 м3/час на 1 ч. + компенс. | K8: 80 м3/час на 1 ч. | L8: =SUM(M8:M10) -> 2190 | M8: =80*I8 -> 2080 | N8: П1 | O8: В1 | Q8: Центр | U8: П6 | V8: Учебные кабинеты. Правое крыло | W8: =SUM(L49,L53,L83,L103,L104,L105,L109,L133,L134,L141,L163,L164,L165,L135) -> 5755
C9: 0.04 | D9: Снарядная | E9: В3 | G9: 9.8 | H9: =G9*2.65 -> 25.97 | J9: - | K9: 1 | L9: - | M9: =ROUND(H9*K9,-1) -> 30 | N9: — | O9: В1 | P9: Через ОЗК | Q9: Центр | U9: П7 | V9: Медблок | W9: =SUM(L72,L73,L75) -> 520
C10: 0.05 | D10: Снарядная | E10: В3 | G10: 28.6 | H10: =G10*2.65 -> 75.79 | J10: - | K10: 1 | L10: - | M10: =ROUND(H10*K10,-1) -> 80 | N10: — | O10: В1 | P10: Через ОЗК | Q10: Центр | U10: П8 | V10: Админ. кабинеты Коридоры с реакреациями, Помещения СС, Комната охраны, Коридор 1-этажа. | W10: =SUM(L25,L76,L77,L82,L84,L85,L88,L95,L96,L113,L117,L118,L119,L126,L140,L142,L146,L147,L154,L24) -> 5790
C11: 0.06 | D11: Тамбур-шлюз 1-ого типа | G11: 8.7 | H11: =G11*2.65 -> 23.055 | J11: - | K11: - | L11: - | M11: - | N11: — | P11: Через ОЗК | Q11: Центр | U11: П9 | V11: Гимнастический зал (хореография) | W11: =SUM(L106) -> 1320
C12: 0.07 | D12: Коридор | G12: 40.4 | H12: =G12*2.65 -> 107.06 | J12: - | K12: По балансу | L12: - | M12: =SUM(L12:L14)-SUM(M13:M14) -> 180 | N12: — | O12: ВЕ | Q12: Левое крыло | U12: П10 | V12: Венткамеры. Правое крыло | W12: =SUM(L15,L18,L20) -> 550
C13: 0.08 | D13: Кладовая | E13: В3 | G13: 18 | H13: =G13*2.65 -> 47.7 | J13: - | K13: 1 | L13: - | M13: =ROUND(H13*K13,-1) -> 50 | N13: — | O13: ВЕ | P13: Через ОЗК | Q13: Левое крыло | U13: П11 | V13: ИТП | W13: =L19 -> 1070
C14: 0.09 | D14: Венткамера | E14: В4 | G14: 44.2 | H14: =G14*2.65 -> 117.13 | J14: 2 | K14: - | L14: =ROUND(H14*J14,-1) -> 230 | M14: - | N14: П12 | O14: — | P14: Через ОЗК | Q14: Левое крыло | U14: П12 | V14: Венткамера. Левое крыло | W14: =L14 -> 230 | X14: =SUM(W3:W14) -> 41675
C15: 0.10 | D15: Венткамера | E15: В4 | G15: 36.2 | H15: =G15*2.65 -> 95.93 | J15: 2 | K15: - | L15: =ROUND(H15*J15,-1) -> 190 | M15: - | N15: П10 | O15: — | P15: Через ОЗК | Q15: Правое крыло | U15: Всистемы
C16: 0.11 | D16: Коридор | G16: 102.8 | H16: =G16*2.65 -> 272.42 | J16: - | K16: По балансу | L16: - | M16: =SUM(L15:L20)-SUM(M15,M17:M20) -> 460 | N16: - | O16: ВЕ | Q16: Правое крыло | U16: В1 | V16: Спортивный зал | W16: =SUM(M8:M10) -> 2190
C17: 0.12 | D17: Насосная | E17: В4 | G17: 16.4 | H17: =G17*2.65 -> 43.46 | J17: - | K17: 2 | L17: - | M17: =ROUND(H17*K17,-1) -> 90 | N17: - | O17: В18 | P17: Через ОЗК | Q17: Правое крыло | U17: В2 | V17: Актовый зал, Технический центр, Артистическая | W17: =SUM(M155:M157) -> 3320
C18: 0.13 | D18: Венткамера | E18: В4 | G18: 24.1 | H18: =G18*2.65 -> 63.865 | J18: 2 | K18: - | L18: =ROUND(H18*J18,-1) -> 130 | M18: - | N18: П10 | O18: — | P18: Через ОЗК | Q18: Правое крыло | U18: В3 | V18: Обеденный зал | W18: =M55 -> 2200
C19: 0.14 | D19: ИТП | E19: Д | G19: 80.8 | H19: =G19*2.65 -> 214.12 | J19: 5 | K19: 5 | L19: =ROUND(H19*J19,-1) -> 1070 | M19: =ROUND(H19*K19,-1) -> 1070 | N19: П11 | O19: В23 | P19: Через ОЗК | Q19: Правое крыло | U19: В4 | V19: Пищеблок. Производственные помещения | W19: =SUM(M56,M61,M68) -> 1070
C20: 0.15 | D20: Венткамера | E20: В4 | G20: 43.1 | H20: =G20*2.65 -> 114.215 | J20: 2 | K20: - | L20: =ROUND(H20*J20,-1) -> 230 | M20: - | N20: П10 | O20: — | P20: Через ОЗК | Q20: Правое крыло | U20: В5 | V20: Санузлы и душевые женские, санузел МГН, санузел персонала 1-й этаж | W20: =SUM(M38,M39,M41,M42,M45,M46,M93,M124,M152) -> 1355
D21: ИТОГО по подвалу | L21: =SUM(L5:L20) -> 4040 | M21: =SUM(M8:M20) -> 4040 | U21: В6 | V21: Санузлы и душевые мужские | W21: =SUM(M47,M48,M51,M53,M94,M125,M153) -> 1055
B22: 1 этаж | U22: В7 | V22: Санузлы персонала 2-4 этажи, Подсобные помещения. Левое крыло | W22: =SUM(M89,M120,M148,M91,M122,M150) -> 210
C23: 101 | D23: Тамбур | G23: 12.5 | H23: =G23*3.46 -> 43.25 | J23: - | K23: - | L23: - | M23: - | N23: - | O23: - | Q23: Общий | U23: В8 | V23: Помещение для хранения уборочного инвентаря, приготовления дезинфицирующих растворов | W23: =SUM(M74) -> 100
C24: 102 | D24: Коридор | G24: 268.8 | H24: =G24*3.46 -> 930.048 | J24: По балансу | K24: - | L24: =SUM(M23:M78)-SUM(L25:L78) -> 3010 | M24: - | N24: П8 | O24: - | Q24: Общий | U24: В9 | V24: Гимнастический зал и раздевальные к нему | W24: =SUM(M106:M108) -> 1320
C25: 103 | D25: Комната охраны (с диспетчерским пунктом) | G25: 16.2 | H25: =G25*3.46 -> 56.052 | I25: 2 | J25: 60 м3/час на 1 ч. | K25: 60 м3/час на 1 ч. | L25: =60*I25 -> 120 | M25: =60*I25 -> 120 | N25: П8 | O25: В13 | Q25: Левое крыло | U25: В10 | V25: Кабинет учителей 1-й этаж, Административный кабинет 2-й этаж. Правое крыло | W25: =SUM(M96,M77) -> 480
C26: 104 | D26: Гардероб для обучающихся | G26: 46.2 | H26: =G26*3.46 -> 159.852 | J26: - | K26: 1 | L26: - | M26: =ROUND(H26*K26,-1) -> 160 | N26: - | O26: В11 | Q26: Левое крыло | U26: В11 | V26: Гардеробы, кладовая | W26: =SUM(M26,M28,M35,M43,M78,M158) -> 660
C27: 105 | D27: Коридор | G27: 59.9 | H27: =G27*3.46 -> 207.254 | J27: По балансу с пом. 110 | K27: - | L27: =M35 -> 60 | M27: - | N27: П5 | O27: - | Q27: Левое крыло | U27: В12 | V27: Электрощитовая | W27: =M32 -> 50
C28: 106 | D28: Гардероб для обучающихся | G28: 53.7 | H28: =G28*3.46 -> 185.802 | J28: - | K28: 1 | L28: - | M28: =ROUND(H28*K28,-1) -> 190 | N28: - | O28: В11 | Q28: Левое крыло | U28: В13 | V28: Комната охраны | W28: =M25 -> 120
C29: 107 | D29: Кабинет материальной технологии Тип 1 | G29: 66.1 | H29: =G29*3.46 -> 228.706 | I29: 21 | J29: 20 м3/ч на 1 ч., но не менее 2 | K29: 20 м3/ч на 1 ч., но не менее 2 | L29: =MAX(20*I29,ROUND(H29*2,-1)) -> 460 | M29: =MAX(20*I29,ROUND(H29*2,-1)) -> 460 | N29: П5 | O29: ВЕ | Q29: Левое крыло | U29: В14 | V29: Подсобные помещения. Правое крыло | W29: =SUM(M90,M121,M149) -> 30
D30: ТХ п.52 Зонт вытяжной 900х600 | J30: - | K30: По расчету (0,3) | L30: - | M30: 600 | N30: - | O30: МО1 | P30: Через ОЗК | U30: В15 | V30: Библиотечный центр | W30: =SUM(M135:M136) -> 1270
D31: ТХ п.52 Зонт вытяжной 900х600 | J31: - | K31: По расчету (0,3) | L31: - | M31: 600 | N31: - | O31: МО1 | P31: Через ОЗК | U31: В16 | V31: Лаборантская биологии | W31: =SUM(M161) -> 120
C32: 108 | D32: Электрощитовая | E32: В3 | G32: 15.5 | H32: =G32*3.46 -> 53.63 | J32: - | K32: 1 | L32: - | M32: =ROUND(H32*K32,-1) -> 50 | N32: - | O32: В12 | P32: Через ОЗК | Q32: Левое крыло | U32: В17 | V32: Медблок | W32: =SUM(M72:M73) -> 420
C33: 109 | D33: Кабинет материальной технологии Тип 2 | G33: 58.5 | H33: =G33*3.46 -> 202.41 | I33: 21 | J33: 20 м3/ч на 1 ч., но не менее 2 | K33: 20 м3/ч на 1 ч., но не менее 2 | L33: =MAX(20*I33,ROUND(H33*2,-1)) -> 420 | M33: =MAX(20*I33,ROUND(H33*2,-1)) -> 420 | N33: П5 | O33: ВЕ | Q33: Левое крыло | U33: В18 | V33: Насосная | W33: =M17 -> 90
D34: ТХ п.69 Вытяжная система для лазерного станка, фильтрующая | J34: - | K34: По расчету | L34: - | M34: 700 | N34: - | O34: МО2 | P34: Через ОЗК | U34: В19 | V34: Помещение временного хранения пищевых отходов | W34: =M66 -> 170
C35: 110 | D35: Кладовая кабинета материальной технологии | E35: В3 | G35: 18 | H35: =G35*3.46 -> 62.28 | J35: - | K35: 1 | L35: - | M35: =ROUND(H35*K35,-1) -> 60 | N35: - | O35: В11 | P35: Через ОЗК | Q35: Левое крыло | U35: В20 | V35: Помещения СС. Левое крыло | W35: =SUM(M85,M118,M146) -> 90
C36: 111 | D36: Учебный кабинет (математика) | G36: 53.3 | H36: =G36*3.46 -> 184.418 | I36: 21 | J36: 20 м3/ч на 1 ч., но не менее 2 | K36: 20 м3/ч на 1 ч., но не менее 2 | L36: =MAX(20*I36,ROUND(H36*2,-1)) -> 420 | M36: =MAX(20*I36,ROUND(H36*2,-1)) -> 420 | N36: П5 | O36: ВЕ | Q36: Левое крыло | U36: В21 | V36: Помещения СС. Правое крыло | W36: =SUM(M76,M88,M119,M147) -> 220
C37: 112 | D37: Лестничная клетка (Тип Л1) | G37: 27.8 | H37: =G37*3.46 -> 96.188 | J37: - | K37: - | L37: - | M37: - | N37: - | O37: - | Q37: Левое крыло | U37: В22 | V37: ПУИ. Правое крыло | W37: =SUM(M92,M123,M151) -> 120
C38: 113 | D38: Туалет для персонала | G38: 3.3 | H38: =G38*3.46 -> 11.418 | I38: 1ун. | J38: - | K38: 50 м3/час на 1 ун. | L38: - | M38: 50 | N38: - | O38: В5 | Q38: Левое крыло | U38: В23 | V38: ИТП | W38: =M19 -> 1070
C39: 114 | D39: Уборная для девочек | G39: 17 | H39: =G39*3.46 -> 58.82 | I39: 3ун. | J39: - | K39: 50 м3/час на 1 ун. | L39: - | M39: =50*3 -> 150 | N39: - | O39: В5 | Q39: Левое крыло | U39: В24 | V39: Пищеблок. Помещение персонала санузлом, ПУИ | W39: =SUM(M65,M67) -> 185 | X39: =SUM(W16:W39) -> 17915
C40: 115 | D40: Технологическая лестница | G40: 17.8 | H40: =G40*3.46 -> 61.588 | J40: - | K40: - | L40: - | M40: - | N40: - | O40: - | Q40: Левое крыло | U40: В25 | V40: Кладовая сухих продуктов | W40: =M64 -> 50
...

Sheet Таблица ХОВС
A1: Вес, кг | B1: № | C1: Наименование | D1: L, м3/ч | I1: Установка | J1: Фильтр | K1: Напор, Па | L1: N, Вт | M1: Водяной нагреватель | P1: Электрический нагреватель | S1: Заслонка | T1: Шумоглуш. | U1: Г.В. | V1: Исполнение
M2: Темп., С | O2: Q, кВт | P2: Темп., С | R2: Nуст, кВт
D3: П | E3: +(10-15)% | F3: В | G3: +(10-15)% | H3: Всего | M3: от | N3: до | P3: от | Q3: до
B4: П1 | C4: ='П1 Воздух Школа ст.П'!V3 -> Спортивный зал | D4: ='П1 Воздух Школа ст.П'!W3 -> 2190 | E4: =ROUND(D4*1.14,-1) -> 2500 | H4: =SUM(D4:D15) -> 41675 | J4: G4, F7 | K4: 300 | L4: 0.25 | M4: - | N4: - | O4: - | P4: -26 | Q4: 20 | R4: =(E4*1.2*1.005*(Q4-P4))/3600 -> 38.525 | S4: + | T4: + | U4: + | V4: Наружное
B5: П2 | C5: ='П1 Воздух Школа ст.П'!V4 -> Актовый зал, Технический центр, Артистическая | D5: ='П1 Воздух Школа ст.П'!W4 -> 3320 | E5: =ROUND(D5*1.14,-1) -> 3780 | J5: G4, F7 | K5: 300 | L5: 0.25 | M5: - | N5: - | O5: - | P5: -26 | Q5: 20 | R5: =(E5*1.2*1.005*(Q5-P5))/3600 -> 58.2498 | S5: + | T5: + | U5: + | V5: Наружное
B6: П3 | C6: ='П1 Воздух Школа ст.П'!V5 -> Обеденный зал | D6: ='П1 Воздух Школа ст.П'!W5 -> 3190 | E6: =ROUND(D6*1.14,-1) -> 3640 | J6: G4, F7 | K6: 300 | L6: 0.37 | M6: -26 | N6: 20 | O6: =(E6*1.23*1.005*(N6-M6))/3600 -> 57.49471 | P6: - | Q6: - | R6: - | S6: + | T6: + | U6: + | V6: Внутренне
B7: П4 | C7: ='П1 Воздух Школа ст.П'!V6 -> Пищеблок. Производственные помещения | D7: ='П1 Воздух Школа ст.П'!W6 -> 8685 | E7: =ROUND(D7*1.14,-1) -> 9900 | J7: G4, F7 | K7: 400 | L7: 1.1 | M7: -26 | N7: 18 | O7: =(E7*1.23*1.005*(N7-M7))/3600 -> 149.57415 | P7: - | Q7: - | R7: - | S7: + | T7: + | U7: + | V7: Внутренне
B8: П5 | C8: ='П1 Воздух Школа ст.П'!V7 -> Учебные кабинеты. Левое крыло | D8: ='П1 Воздух Школа ст.П'!W7 -> 9055 | E8: =ROUND(D8*1.14,-1) -> 10320 | J8: G4, F7 | K8: 400 | L8: 1.1 | M8: -26 | N8: 20 | O8: =(E8*1.23*1.005*(N8-M8))/3600 -> 163.00698 | P8: - | Q8: - | R8: - | S8: + | T8: + | U8: + | V8: Внутренне
B9: П6 | C9: ='П1 Воздух Школа ст.П'!V8 -> Учебные кабинеты. Правое крыло | D9: ='П1 Воздух Школа ст.П'!W8 -> 5755 | E9: =ROUND(D9*1.14,-1) -> 6560 | J9: G4, F7 | K9: 400 | L9: 5.5 | M9: -26 | N9: 20 | O9: =(E9*1.23*1.005*(N9-M9))/3600 -> 103.61684 | P9: - | Q9: - | R9: - | S9: + | T9: + | U9: + | V9: Внутренне
B10: П7 | C10: ='П1 Воздух Школа ст.П'!V9 -> Медблок | D10: ='П1 Воздух Школа ст.П'!W9 -> 520 | E10: =ROUND(D10*1.14,-1) -> 590 | J10: G4, F7, F9 | K10: 200 | L10: 1.5 | M10: - | N10: - | O10: - | P10: -26 | Q10: 20 | R10: =(E10*1.2*1.005*(Q10-P10))/3600 -> 9.0919 | S10: + | T10: + | U10: + | V10: Наружное
B11: П8 | C11: ='П1 Воздух Школа ст.П'!V10 -> Админ. кабинеты Коридоры с реакреациями, Помещения СС, Комната охраны, Коридор 1-этажа. | D11: ='П1 Воздух Школа ст.П'!W10 -> 5790 | E11: =ROUND(D11*1.14,-1) -> 6600 | J11: G4, F7 | K11: 400 | L11: 4 | M11: -26 | N11: 20 | O11: =(E11*1.23*1.005*(N11-M11))/3600 -> 104.24865 | P11: - | Q11: - | R11: - | S11: + | T11: + | U11: + | V11: Внутренне
B12: П9 | C12: ='П1 Воздух Школа ст.П'!V11 -> Гимнастический зал (хореография) | D12: ='П1 Воздух Школа ст.П'!W11 -> 1320 | E12: =ROUND(D12*1.14,-1) -> 1500 | J12: G4, F7 | K12: 200 | L12: 0.75 | M12: -26 | N12: 20 | O12: =(E12*1.23*1.005*(N12-M12))/3600 -> 23.692875 | P12: - | Q12: - | R12: - | S12: + | T12: + | U12: + | V12: Внутренне
B13: П10 | C13: ='П1 Воздух Школа ст.П'!V12 -> Венткамеры. Правое крыло | D13: ='П1 Воздух Школа ст.П'!W12 -> 550 | E13: =ROUND(D13*1.14,-1) -> 630 | J13: G4 | K13: 200 | L13: 7.5 | M13: -26 | N13: 18 | O13: =(E13*1.23*1.005*(N13-M13))/3600 -> 9.518355 | P13: - | Q13: - | R13: - | S13: + | T13: + | U13: + | V13: Внутренне
B14: П11 | C14: ='П1 Воздух Школа ст.П'!V13 -> ИТП | D14: ='П1 Воздух Школа ст.П'!W13 -> 1070 | E14: =ROUND(D14*1.14,-1) -> 1220 | J14: G4 | K14: 200 | L14: 7.5 | M14: - | N14: - | O14: - | P14: - | Q14: - | R14: - | S14: + | T14: + | U14: + | V14: Внутренне
B15: П12 | C15: ='П1 Воздух Школа ст.П'!V14 -> Венткамера. Левое крыло | D15: ='П1 Воздух Школа ст.П'!W14 -> 230 | E15: =ROUND(D15*1.14,-1) -> 260 | J15: G4 | K15: 200 | L15: 7.5 | M15: -26 | N15: 18 | O15: =(E15*1.23*1.005*(N15-M15))/3600 -> 3.92821 | P15: - | Q15: - | R15: - | S15: + | T15: + | U15: + | V15: Внутренне
B17: В1 | C17: ='П1 Воздух Школа ст.П'!V16 -> Спортивный зал | F17: ='П1 Воздух Школа ст.П'!W16 -> 2190 | G17: =ROUND(F17*1.13,-1) -> 2470 | H17: =SUM(F17:F40) -> 17915 | J17: - | K17: 300 | L17: 0.27 | M17: - | N17: - | O17: - | P17: - | Q17: - | R17: - | S17: + | T17: + | U17: + | V17: Наружное
B18: В2 | C18: ='П1 Воздух Школа ст.П'!V17 -> Актовый зал, Технический центр, Артистическая | F18: ='П1 Воздух Школа ст.П'!W17 -> 3320 | G18: =ROUND(F18*1.13,-1) -> 3750 | J18: - | K18: 300 | L18: 0.27 | M18: - | N18: - | O18: - | P18: - | Q18: - | R18: - | S18: + | T18: + | U18: + | V18: Наружное
B19: В3 | C19: ='П1 Воздух Школа ст.П'!V18 -> Обеденный зал | F19: ='П1 Воздух Школа ст.П'!W18 -> 2200 | G19: =ROUND(F19*1.13,-1) -> 2490 | J19: - | K19: 300 | L19: 0.87 | M19: - | N19: - | O19: - | P19: - | Q19: - | R19: - | S19: + | T19: + | U19: + | V19: Внутренне
B20: В4 | C20: ='П1 Воздух Школа ст.П'!V19 -> Пищеблок. Производственные помещения | F20: ='П1 Воздух Школа ст.П'!W19 -> 1070 | G20: =ROUND(F20*1.13,-1) -> 1210 | J20: - | K20: 400 | L20: 0.87 | M20: - | N20: - | O20: - | P20: - | Q20: - | R20: - | S20: + | T20: + | U20: + | V20: Внутренне
B21: В5 | C21: ='П1 Воздух Школа ст.П'!V20 -> Санузлы и душевые женские, санузел МГН, санузел персонала 1-й этаж | F21: ='П1 Воздух Школа ст.П'!W20 -> 1355 | G21: =ROUND(F21*1.13,-1) -> 1530 | J21: - | K21: 400 | L21: 0.55 | M21: - | N21: - | O21: - | P21: - | Q21: - | R21: - | S21: + | T21: + | U21: + | V21: Внутренне
B22: В6 | C22: ='П1 Воздух Школа ст.П'!V21 -> Санузлы и душевые мужские | F22: ='П1 Воздух Школа ст.П'!W21 -> 1055 | G22: =ROUND(F22*1.13,-1) -> 1190 | J22: - | K22: 300 | L22: 0.07 | M22: - | N22: - | O22: - | P22: - | Q22: - | R22: - | S22: + | T22: + | U22: + | V22: Внутренне
B23: В7 | C23: ='П1 Воздух Школа ст.П'!V22 -> Санузлы персонала 2-4 этажи, Подсобные помещения. Левое крыло | F23: ='П1 Воздух Школа ст.П'!W22 -> 210 | G23: =ROUND(F23*1.13,-1) -> 240 | J23: - | K23: 300 | L23: 0.07 | M23: - | N23: - | O23: - | P23: - | Q23: - | R23: - | S23: + | T23: + | U23: + | V23: Внутренне
B24: В8 | C24: ='П1 Воздух Школа ст.П'!V23 -> Помещение для хранения уборочного инвентаря, приготовления дезинфицирующих растворов | F24: ='П1 Воздух Школа ст.П'!W23 -> 100 | G24: =ROUND(F24*1.13,-1) -> 110 | J24: - | K24: 400 | L24: 5.5 | M24: - | N24: - | O24: - | P24: - | Q24: - | R24: - | S24: + | T24: + | U24: + | V24: Внутренне
B25: В9 | C25: ='П1 Воздух Школа ст.П'!V24 -> Гимнастический зал и раздевальные к нему | F25: ='П1 Воздух Школа ст.П'!W24 -> 1320 | G25: =ROUND(F25*1.13,-1) -> 1490 | J25: - | K25: 400 | L25: 1.5 | M25: - | N25: - | O25: - | P25: - | Q25: - | R25: - | S25: + | T25: + | U25: + | V25: Внутренне
B26: В10 | C26: ='П1 Воздух Школа ст.П'!V25 -> Кабинет учителей 1-й этаж, Административный кабинет 2-й этаж. Правое крыло | F26: ='П1 Воздух Школа ст.П'!W25 -> 480 | G26: =ROUND(F26*1.13,-1) -> 540 | J26: - | K26: 300 | L26: 0.25 | M26: - | N26: - | O26: - | P26: - | Q26: - | R26: - | S26: + | T26: + | U26: + | V26: Внутренне
B27: В11 | C27: ='П1 Воздух Школа ст.П'!V26 -> Гардеробы, кладовая | F27: ='П1 Воздух Школа ст.П'!W26 -> 660 | G27: =ROUND(F27*1.13,-1) -> 750 | J27: - | K27: 300 | L27: 0.18 | M27: - | N27: - | O27: - | P27: - | Q27: - | R27: - | S27: + | T27: + | U27: + | V27: Внутренне
B28: В12 | C28: ='П1 Воздух Школа ст.П'!V27 -> Электрощитовая | F28: ='П1 Воздух Школа ст.П'!W27 -> 50 | G28: =ROUND(F28*1.13,-1) -> 60 | J28: - | K28: 400 | L28: 3.5 | M28: - | N28: - | O28: - | P28: - | Q28: - | R28: - | S28: + | T28: + | U28: + | V28: Внутренне
B29: В13 | C29: ='П1 Воздух Школа ст.П'!V28 -> Комната охраны | F29: ='П1 Воздух Школа ст.П'!W28 -> 120 | G29: =ROUND(F29*1.13,-1) -> 140 | J29: - | K29: 300 | L29: 0.115 | M29: - | N29: - | O29: - | P29: - | Q29: - | R29: - | S29: + | T29: + | U29: + | V29: Внутренне
... B41: В25 | C41: ='П1 Воздух Школа ст.П'!V40 -> Кладовая сухих продуктов | F41: ='П1 Воздух Школа ст.П'!W40 -> 50 | G41: =ROUND(F41*1.13,-1) -> 60 | J41: - | K41: 50 | L41: 0.07 | M41: - | N41: - | O41: - | P41: - | Q41: - | R41: - | S41: + | T41: + | U41: + | V41: Внутренне
B43: МО1 | C43: Зонт вытяжной над оборудованием №52 по ТХ | F43: =SUM('П1 Воздух Школа ст.П'!M30,'П1 Воздух Школа ст.П'!M31) -> 1200 | J43: - | K43: 300 | L43: 0.07 | M43: - | N43: - | O43: - | P43: - | Q43: - | R43: - | S43: + | T43: + | U43: +
B44: МО2 | C44: Зонт вытяжной над лазерным станком №69 по ТХ | F44: =SUM('П1 Воздух Школа ст.П'!M34) -> 700 | J44: - | K44: 300 | L44: 0.07 | M44: - | N44: - | O44: - | P44: - | Q44: - | R44: - | S44: + | T44: + | U44: +
B45: МО3 | C45: Зонт вытяжной над оборудованием №124 по ТХ | F45: =SUM('П1 Воздух Школа ст.П'!M57) -> 2000 | J45: - | K45: 300 | L45: 0.07 | M45: - | N45: - | O45: - | P45: - | Q45: - | R45: - | S45: + | T45: + | U45: +
B46: МО4 | C46: Зонт вытяжной над оборудованием №126,218 по ТХ | F46: =SUM('П1 Воздух Школа ст.П'!M58,'П1 Воздух Школа ст.П'!M59) -> 1500 | J46: - | K46: 300 | L46: 0.07 | M46: - | N46: - | O46: - | P46: - | Q46: - | R46: - | S46: + | T46: + | U46: +
B47: МО5 | C47: Зонт вытяжной над оборудованием №132 по ТХ | F47: =SUM('П1 Воздух Школа ст.П'!M62) -> 800 | J47: - | K47: 300 | L47: 0.22 | M47: - | N47: - | O47: - | P47: - | Q47: - | R47: - | S47: + | T47: + | U47: +
B48: МО6 | C48: Зонт вытяжной над оборудованием №136 по ТХ | F48: =SUM('П1 Воздух Школа ст.П'!M69) -> 1300 | J48: - | K48: 300 | L48: 0.22 | M48: - | N48: - | O48: - | P48: - | Q48: - | R48: - | S48: + | T48: + | U48: +
B49: МО7 | C49: Зонт вытяжной над оборудованием №164 по ТХ | F49: =SUM('П1 Воздух Школа ст.П'!M70) -> 1400 | J49: - | K49: 300 | L49: 0.22 | M49: - | N49: - | O49: - | P49: - | Q49: - | R49: - | S49: + | T49: + | U49: +
B50: МО8 | C50: Зонт вытяжной над оборудованием №122 по ТХ | F50: =SUM('П1 Воздух Школа ст.П'!M71) -> 1200 | J50: - | K50: 300 | L50: 0.22 | M50: - | N50: - | O50: - | P50: - | Q50: - | R50: - | S50: + | T50: + | U50: +
B52: ВЕ | F52: ='П1 Воздух Школа ст.П'!W42 -> 13610 | G52: =ROUND(F52*1.1,-1) -> 14970 | I52: Естественная | J52: - | K52: 300 | L52: 0.07 | M52: - | N52: - | O52: - | P52: - | Q52: - | R52: - | S52: + | T52: + | U52: +
D54: =SUM(D4:D50) -> 41675 | F54: =SUM(F4:F50,F52) -> 41675 | L54: =SUM(L4:L50) -> 60.06 | O54: =SUM(O4:O15) -> 615.08077 | R54: =SUM(R4:R15) -> 105.8667
O55: =O54/1.163/1000 -> 0.52887426

Sheet Легенда систем
A1: Система | B1: Цвет | C1: Тип | D1: Наименование по ХОВС / примечание
A3: П1 | C3: Приток | D3: Спортивный зал
A4: П2 | C4: Приток | D4: Актовый зал, Технический центр, Артистическая
A5: П3 | C5: Приток | D5: Обеденный зал
A6: П4 | C6: Приток | D6: Пищеблок. Производственные помещения
A7: П5 | C7: Приток | D7: Админ. кабинеты + реакреации. Левое крыло
A8: П6 | C8: Приток | D8: Админ. кабинеты + реакреации, Помещения СС. Правое крыло
A9: П7 | C9: Приток | D9: Медблок
A10: П8 | C10: Приток | D10: Коридоры, помещения СС. Левое крыло
A11: П9 | C11: Приток | D11: Гимнастический зал (хореография)
A12: П10 | C12: Приток | D12: Венткамеры
A13: П11 | C13: Приток | D13: ИТП
A15: В1 | C15: Вытяжка | D15: Спортивный зал
... A47: МО8 | C47: Местный отсос | D47: Зонт вытяжной над оборудованием №122 по ТХ
A48: ВЕ | C48: Вытяжка естественная
