Workbook

Sheet Смета по ТСН-2001(с доп.67
A1: =Source!B1 -> Smeta.RU (495) 974-1589
J2: Форма № 4б
B3: "СОГЛАСОВАНО" | G3: "УТВЕРЖДАЮ"
B6: =CONCATENATE("______________________ ", IF(Source!AL12<>"", Source!AL12, "")) -> ______________________ | G6: =CONCATENATE("______________________ ", IF(Source!AH12<>"", Source!AH12, "")) -> ______________________
B7: "_____"________________ 2026 г. | G7: "_____"________________ 2026 г.
A10: Капитальный ремонт здания Государственного бюджетного общеобразовательного учреждения города Москвы «Школа №1574», расположенного по адресу: г. Москва, Старопименовский переулок, д. 5. 1 этап. | AQ10: Капитальный ремонт здания Государственного бюджетного общеобразовательного учреждения города Москвы «Школа №1574», расположенного по адресу: г. Москва, Старопименовский переулок, д. 5. 1 этап. 02-01-10 СОТС
A11: (наименование стройки и/или объекта)
A13: =CONCATENATE( "ЛОКАЛЬНАЯ СМЕТА № ",IF(Source!F12<>"Новый объект", Source!F12, "")) -> ЛОКАЛЬНАЯ СМЕТА № 02-01-10
A15: =Source!G20 -> Система охранной сигнализации
A16: (наименование работ и затрат)
A18: =CONCATENATE( "Основание: чертежи № ", Source!J12) -> Основание: чертежи № 2024-00375-01-0-ИОС5.3
I20: В базисном уровне цен | J20: В текущем уровне цен
E21: Сметная стоимость | I21: =I22+I23+I24+I25 -> 200.58 | J21: =J22+J23+J24+J25 -> 4913.17 | K21: тыс.руб.
E22: Строительные работы | I22: =ROUND((Source!F518)/1000, 2) -> 30.62 | J22: =ROUND((Source!P518)/1000, 2) -> 1725.57 | K22: тыс.руб.
E23: Работы по монтажу оборудования | I23: =ROUND((Source!F519)/1000, 2) -> 100.95 | J23: =ROUND((Source!P519)/1000, 2) -> 2521.9 | K23: тыс.руб.
E24: Оборудование | I24: =ROUND((Source!F510)/1000, 2) -> 69.01 | J24: =ROUND((Source!P510)/1000, 2) -> 665.7 | K24: тыс.руб.
E25: Прочие работы и затраты | I25: =ROUND((Source!F520+Source!F521)/1000, 2) -> 0 | J25: =ROUND((Source!P520+Source!P521)/1000, 2) -> 0 | K25: тыс.руб.
E26: Средства на оплату труда | I26: =(Source!F516+ Source!F515)/1000 -> 28.31254 | J26: =((Source!P516 + Source!P515)/1000) -> 1595.4116 | K26: тыс.руб.
E27: Затраты труда | I27: =Source!F523 -> 2479.672 | K27: чел.-ч.
E28: Кроме того:
E29: Возврат материалов | I29: =SUM(Z1:Z535)/1000 -> 0 | J29: =SUM(AA1:AA535)/1000 -> 0 | K29: тыс.руб.
A31: Составлен(а) по ТСН-2001 с учетом Дополнения №: 81
A32: № и период сборника коэффициентов (индексов) пересчета: Коэффициенты к ТСН-2001 МГЭ Дополнение 81, строительство №219/81 I квартал 2026 года и Коэффициенты к ТСН-2001.13-2 Дополнение 47 №64/47 I квартал 2026 года | AQ32: № и период сборника коэффициентов (индексов) пересчета: Коэффициенты к ТСН-2001 МГЭ Дополнение 81, строительство №219/81 I квартал 2026 года и Коэффициенты к ТСН-2001.13-2 Дополнение 47 №64/47 I квартал 2026 года
A33: № п/п | B33: Шифр расценки и коды ресурсов | C33: Наименование работ и затрат | D33: Ед. изм. | E33: Кол-во единиц | F33: Цена на ед. изм., руб. | G33: Попра- вочные коэффи- циенты | H33: Коэффи- циенты зимних удорожа- ний | I33: Всего в ценах на январь 2000 года, руб. | J33: Коэффи- циенты (индек- сы) пере- счета, нормы НР и СП | K33: ВСЕГО затрат в текущем уровне цен, руб.
A34: 1 | B34: 2 | C34: 3 | D34: 4 | E34: 5 | F34: 6 | G34: 7 | H34: 8 | I34: 9 | J34: 10 | K34: 11
A36: =CONCATENATE("Локальная смета: ",IF(Source!G20<>"Новая локальная смета", Source!G20, "")) -> Локальная смета: Система охранной сигнализации
A38: =CONCATENATE("Раздел: ",IF(Source!G24<>"Новый раздел", Source!G24, "")) -> Раздел: Демонтажные работы
A39: 1 | B39: =Source!F28 -> 4.10-80-9 | C39: Аппараты приемные, приборы приемно-контрольные объектовые на 2 луча / демонтаж контроллера адресных устрорйств | D39: =Source!H28 -> 1 ШТ. | E39: =Source!I28 -> 1 | R39: =Source!X28 -> 26.24 | S39: =Source!X29 -> 1478.34 | T39: =Source!Y28 -> 13.41 | U39: =Source!Y29 -> 755.6 | V39: =ROUND((175/100)*ROUND(Source!R28, 2), 2) -> 0 | W39: =ROUND((0/100)*ROUND(Source!R29, 2), 2) -> 0 | AD39: 0
C40: ЗП | F40: =Source!AO28 -> 77.35 | G40: 1,2*0,3 | H40: =Source!AV29 -> 1.047 | I40: =Source!S28 -> 29.15 | J40: =IF(Source!BA29<> 0, Source!BA29, 1) -> 56.35 | K40: =Source!S29 -> 1642.6
C41: ЭМ | F41: =Source!AM28 -> 0.05 | G41: 1,2*0,3 | H41: =Source!AV29 -> 1.047 | I41: =Source!Q28 -> 0.02 | J41: =IF(Source!BB29<> 0, Source!BB29, 1) -> 20 | K41: =Source!Q29 -> 0.4
C42: НР от ФОТ | D42: % | E42: =Source!BZ29 -> 90 | I42: =SUM(R39:R41) -> 26.24 | J42: =Source!AT29 -> 90 | K42: =SUM(S39:S41) -> 1478.34
C43: СП от ФОТ | D43: % | E43: =Source!CA29 -> 46 | I43: =SUM(T39:T42) -> 13.41 | J43: =Source!AU29 -> 46 | K43: =SUM(U39:U42) -> 755.6
C44: ЗТР | D44: чел-ч | E44: =Source!AQ28 -> 5.7 | G44: 1,2*0,3 | H44: =Source!AV29 -> 1.047 | I44: =Source!U28 -> 2.148444
C45: ВСЕГО работ по позиции: | H45: =I40+I41+I42+I43+0-0-0 -> 68.82 | J45: =K40+K41+K42+K43+0-0-0 -> 3876.94
C46: ВСЕГО оборудование по позиции: | H46: =0+0 -> 0 | J46: =0+0 -> 0
C47: ВСЕГО по позиции: | H47: =I40+I41+I42+I43+0 -> 68.82 | J47: =K40+K41+K42+K43+0 -> 3876.94 | P47: =I40+I41+I42+I43+0 -> 68.82 | Q47: =K40+K41+K42+K43+0 -> 3876.94
A49: 2 | B49: =Source!F30 -> 4.10-170-2 | C49: Монтаж блока информационно-управляющего (БИУ) в диспетчерской / демонтаж БИУ | D49: =Source!H30 -> 1 ШТ. | E49: =Source!I30 -> 1 | R49: =Source!X30 -> 11.36 | S49: =Source!X31 -> 640.03 | T49: =Source!Y30 -> 5.81 | U49: =Source!Y31 -> 327.12 | V49: =ROUND((175/100)*ROUND(Source!R30, 2), 2) -> 0 | W49: =ROUND((0/100)*ROUND(Source!R31, 2), 2) -> 0 | AD49: 0
C50: ЗП | F50: =Source!AO30 -> 33.47 | G50: 1,2*0,3 | H50: =Source!AV31 -> 1.047 | I50: =Source!S30 -> 12.62 | J50: =IF(Source!BA31<> 0, Source!BA31, 1) -> 56.35 | K50: =Source!S31 -> 711.14
C51: НР от ФОТ | D51: % | E51: =Source!BZ31 -> 90 | I51: =SUM(R49:R50) -> 11.36 | J51: =Source!AT31 -> 90 | K51: =SUM(S49:S50) -> 640.03
C52: СП от ФОТ | D52: % | E52: =Source!CA31 -> 46 | I52: =SUM(T49:T51) -> 5.81 | J52: =Source!AU31 -> 46 | K52: =SUM(U49:U51) -> 327.12
...

Sheet Source
A1: 0 | B1: Smeta.RU (495) 974-1589 | D1: _PS_ | F1: 0 | G1: 0 | H1: 0 | I1: Smeta.RU | K1: 1 | L1: 74599 | M1: 10 | N1: 12 | O1: 1 | P1: 0 | Q1: 1
A4: 1 | B4: 1 | C4: -1 | G4: Капитальный ремонт здания Государственного бюджетного общеобразовательного учреждения города Москвы «Школа №1574», расположенного по адресу: г. Москва, Старопименовский переулок, д. 5. 1 этап | EC4: 0
A5: 8 | B5: 1 | C5: -1 | G5: Капитальный ремонт здания Государственного бюджетного общеобразовательного учреждения города Москвы «Школа №1574», расположенного по адресу: г. Москва, Старопименовский переулок, д. 5. 1 этап | EC5: 0
A12: 1 | B12: 540 | C12: 0 | D12: =ROW(A501) -> 501 | E12: 0 | F12: 02-01-10 | G12: 02-01-10 СОТС | I12: 0 | J12: 2024-00375-01-0-ИОС5.3 | K12: 0 | L12: 0 | M12: 4098 | O12: 0 | P12: 0 | Q12: 0 | R12: 0 | S12: 0 | T12: 1 | V12: 0 | BB12: 0 | BH12: Сметные нормы списания | BI12: Коды ОКП для ТСН-2001 МГЭ Дополнение 81 | BJ12: 1 | BK12: 1 | BL12: 0 | BM12: 0 | BN12: 1 | BO12: 0 | BP12: 6 | BQ12: 2 | BR12: 1 | BS12: 1 | BT12: 0 | BU12: 0 | BV12: 0 | BW12: 0 | BX12: 0 | BY12: ТСН-2001 (МГЭ) Доп 81 - Новое строительство | BZ12: Типовой расчет для ТСН-2001 МГЭ, Дополнение 81, строительство | CA12: Территориальные сметные нормативы для Москвы ТСН-2001 (МГЭ), дополнение 81 | CB12: Территориальные сметные нормативы для Москвы ТСН-2001 (МГЭ), дополнение 81 | CC12: Территориальные сметные нормативы для Москвы ТСН-2001 (МГЭ), дополнение 81 | CD12: Территориальные сметные нормативы для Москвы ТСН-2001 (МГЭ), дополнение 81 | CE12: Поправки для ТСН-2001 от 07.04.2026 г. доп.81 | CF12: 0 | CG12: 0 | CH12: 8200 | CK12: 81 | CQ12: Территориальные сметные нормативы для Москвы (ТСН-2001) | CR12: ТЕР | CS12: 41660 | CT12: 1 | CU12: 81 | CY12: 0 | EC12: 0
A15: 15 | B15: 1
A18: 52 | B18: =B501 -> 540 | C18: =C501 -> 1 | D18: =D501 -> 12 | E18: =E501 -> 0 | F18: =F501 -> 02-01-10 | G18: =G501 -> 02-01-10 СОТС | O18: =O501 -> 161307.06 | P18: =P501 -> 132376.21 | Q18: =Q501 -> 670.24 | R18: =R501 -> 51.93 | S18: =S501 -> 28260.61 | T18: =T501 -> 0 | U18: =U501 -> 2479.672 | V18: =V501 -> 0 | ... GX18: =GX501 -> 0
A20: 3 | B20: 1 | D20: =ROW(A471) -> 471 | F20: 02-01-10 | G20: Система охранной сигнализации | I20: 0 | J20: 2024-00375-01-0-ИОС5.3 | K20: -1 | L20: 02-01-10 | S20: 0 | T20: 0 | V20: 0 | BX20: 0 | CF20: 0 | CG20: 0
A22: 52 | B22: =B471 -> 1 | C22: =C471 -> 3 | D22: =D471 -> 20 | E22: =E471 -> 0 | F22: =F471 -> 02-01-10 | G22: =G471 -> Система охранной сигнализации | O22: =O471 -> 161307.06 | P22: =P471 -> 132376.21 | Q22: =Q471 -> 670.24 | R22: =R471 -> 51.93 | S22: =S471 -> 28260.61 | T22: =T471 -> 0 | U22: =U471 -> 2479.672 | V22: =V471 -> 0 | ... GX22: =GX471 -> 0
A24: 4 | B24: 1 | D24: =ROW(A59) -> 59 | F24: Новый раздел | G24: Демонтажные работы | I24: 0 | K24: 0 | S24: 0 | T24: 0 | V24: 0 | BX24: 0 | CJ24: 0
A26: 52 | B26: =B59 -> 1 | C26: =C59 -> 4 | D26: =D59 -> 24 | E26: =E59 -> 0 | F26: =F59 -> Новый раздел | G26: =G59 -> Демонтажные работы | O26: =O59 -> 14645.99 | P26: =P59 -> 0 | Q26: =Q59 -> 72.85 | R26: =R59 -> 4.55 | S26: =S59 -> 14573.14 | T26: =T59 -> 0 | U26: =U59 -> 1367.56 | V26: =V59 -> 0 | ... GX26: =GX59 -> 0
A28: 17 | B28: 1 | C28: =ROW(SmtRes!A1) -> 1 | D28: =ROW(EtalonRes!A1) -> 1 | E28: 1 | F28: 4.10-80-9 | G28: Аппараты приемные, приборы приемно-контрольные объектовые на 2 луча / демонтаж контроллера адресных устрорйств | H28: 1 ШТ. | I28: 1 | J28: 0 | K28: 1 | O28: =ROUND(CP28,2) -> 29.17 | P28: =ROUND((ROUND((AC28*AW28*I28),2)*BC28),2) -> 0 | Q28: =(ROUND((ROUND(((((ET28*1.2)*0.3))*AV28*I28),2)*BB28),2)+ROUND((ROUND(((AE28-(((EU28*1.2)*0.3)))*AV28*I28),2)*BS28),2)) -> 0.02 | R28: =(ROUND((ROUND(((((EU28*1.2)*0.3))*AV28*I28),2)*BS28),2)+ROUND((ROUND(((AE28-(((EU28*1.2)*0.3)))*AV28*I28),2)*BS28),2)) -> 0 | S28: =ROUND((ROUND((AF28*AV28*I28),2)*BA28),2) -> 29.15 | T28: =ROUND(CU28*I28,2) -> 0 | U28: =CV28*I28 -> 2.148444 | V28: =CW28*I28 -> 0 | W28: =ROUND(CX28*I28,2) -> 0 | X28: =(ROUND((((S28+ROUND((ROUND(((((EU28*1.2)*0.3))*AV28*I28),2)*BS28),2))*AT28)/100),2)+ROUND(((ROUND((ROUND(((AE28-(((EU28*1.2)*0.3)))*AV28*I28),2)*BS28),2)*AT28)/100),2)) -> 26.24 | Y28: =(ROUND((((S28+ROUND((ROUND(((((EU28*1.2)*0.3))*AV28*I28),2)*BS28),2))*AU28)/100),2)+ROUND(((ROUND((ROUND(((AE28-(((EU28*1.2)*0.3)))*AV28*I28),2)*BS28),2)*AU28)/100),2)) -> 13.41 | AA28: 55915256 | AB28: =ROUND((AC28+AD28+AF28),6) -> 27.864 | AC28: =ROUND((((ES28*1)*0)),6) -> 0 | AD28: =ROUND((((((ET28*1.2)*0.3))-(((EU28*1.2)*0.3)))+AE28),6) -> 0.018 | AE28: =ROUND((((EU28*1.2)*0.3)),6) -> 0.0036 | AF28: =ROUND((((EV28*1.2)*0.3)),6) -> 27.846 | AG28: =ROUND((AP28),6) -> 0 | AH28: =(((EW28*1.2)*0.3)) -> 2.052 | AI28: =(((EX28*1.2)*0.3)) -> 0 | AJ28: =(AS28) -> 0 | AK28: 82.23 | AL28: 4.83 | AM28: 0.05 | AN28: 0.01 | AO28: 77.35 | AP28: 0 | AQ28: 5.7 | AR28: 0 | AS28: 0 | AT28: 90 | AU28: 46 | AV28: 1.047 | AW28: 1 | AZ28: 1 | BA28: 1 | BB28: 1 | BC28: 1 | BH28: 0 | BI28: 2 | BJ28: ТСН-2001.4. Доп. 1-42. Сб. 10, т. 80, поз. 9 | BM28: 68 | BN28: 0 | BO28: 4.10-80-9 | BP28: 1 | BQ28: 40 | BR28: 0 | BS28: 1 | BT28: 1 | BU28: 1 | BV28: 1 | BW28: 1 | BX28: 1 | BZ28: 90 | CA28: 46 | CE28: 1566 | CF28: 0 | CG28: 0 | CM28: 0 | CN28: Поправка: Гл.12.Прил.8.п.8. 3_12.00.01.11.001 Наименование: При наличии напряженных и стесненных условий производства работ (стесненность, сложность складирования и транспортной логистики и т.п.) для объектов, расположенных в пределах круговой магистральной системы улиц "Садовое кольцо" города Москвы Поправка: Гл.4.Прил.2.2.п.2.2.29_04.00.01.35.003 Наименование: При демонтаже оборудования, предназначенного в лом | CO28: 0 | CP28: =(P28+Q28+S28) -> 29.17 | CQ28: =ROUND((ROUND((AC28*AW28*1),2)*BC28),2) -> 0 | CR28: =(ROUND((ROUND(((((ET28*1.2)*0.3))*AV28*1),2)*BB28),2)+ROUND((ROUND(((AE28-(((EU28*1.2)*0.3)))*AV28*1),2)*BS28),2)) -> 0.02 | CS28: =(ROUND((ROUND(((((EU28*1.2)*0.3))*AV28*1),2)*BS28),2)+ROUND((ROUND(((AE28-(((EU28*1.2)*0.3)))*AV28*1),2)*BS28),2)) -> 0 | CT28: =ROUND((ROUND((AF28*AV28*1),2)*BA28),2) -> 29.15 | CU28: =AG28 -> 0 | CV28: =(AH28*AV28) -> 2.148444 | CW28: =AI28 -> 0 | CX28: =AJ28 -> 0 | CY28: =(ROUND((((S28+ROUND((ROUND(((((EU28*1.2)*0.3))*AV28*1),2)*BS28),2))*AT28)/100),2)+ROUND(((ROUND((ROUND(((AE28-(((EU28*1.2)*0.3)))*AV28*1),2)*BS28),2)*AT28)/100),2)) -> 26.24 | CZ28: =(ROUND((((S28+ROUND((ROUND(((((EU28*1.2)*0.3))*AV28*1),2)*BS28),2))*AU28)/100),2)+ROUND(((ROUND((ROUND(((AE28-(((EU28*1.2)*0.3)))*AV28*1),2)*BS28),2)*AU28)/100),2)) -> 13.41 | DB28: 1 | DD28: *1)*0 | DE28: *1,2)*0,3 | DF28: *1,2)*0,3 | DG28: *1,2)*0,3 | DI28: *1,2)*0,3 | DJ28: *1,2)*0,3 | DN28: 0 | DO28: 0 | DP28: 1 | DQ28: 1 | DU28: 1013 | DV28: 1 ШТ. | DW28: 1 ШТ. | DX28: 1 | EE28: 55393700 | EF28: 40 | EG28: Монтаж оборудования | EH28: 0 | EJ28: 2 | EK28: 68 | EL28: ТСН-2001.4-10. Прокладка и монтаж сетей связи | EM28: ТСН-2001.4-10-1 | EO28: Поправка: Гл.12.Прил.8.п.8. 3_12.00.01.11.001 Поправка: Гл.4.Прил.2.2.п.2.2.29_04.00.01.35.003 | EQ28: 0 | ER28: 82.23 | ES28: 4.83 | ET28: 0.05 | EU28: 0.01 | EV28: 77.35 | EW28: 5.7 | EX28: 0 | EY28: 0 | FQ28: 0 | FR28: 0 | FS28: 0 | FX28: 90 | FY28: 46 | GD28: 1 | GF28: -168461099 | GG28: 2 | GH28: 1 | GI28: 2 | GJ28: 0 | GK28: 0 | GL28: =ROUND(IF(AND(BH28=3,BI28=3,FS28<>0),P28,0),2) -> 0 | GM28: =ROUND(O28+X28+Y28,2)+GX28 -> 68.82 | GN28: =IF(OR(BI28=0,BI28=1),GM28-GX28,0) -> 0 | GO28: =IF(BI28=2,GM28-GX28,0) -> 68.82 | GP28: =IF(BI28=4,GM28-GX28,0) -> 0 | GR28: 0 | GS28: 3 | GT28: 0 | GV28: =ROUND((GT28),6) -> 0 | GW28: 1 | GX28: =ROUND(HC28*I28,2) -> 0 | HA28: 0 | HB28: 0 | HC28: =GV28*GW28 -> 0 | HS28: 0 | IK28: 0
A29: 17 | B29: 1 | C29: =ROW(SmtRes!A2) -> 2 | D29: =ROW(EtalonRes!A2) -> 2 | E29: 1 | F29: 4.10-80-9 | G29: Аппараты приемные, приборы приемно-контрольные объектовые на 2 луча / демонтаж контроллера адресных устрорйств | H29: 1 ШТ. | I29: 1 | J29: 0 | K29: 1 | O29: =ROUND(CP29,2) -> 1643 | P29: =ROUND((ROUND((AC29*AW29*I29),2)*BC29),2) -> 0 | Q29: =(ROUND((ROUND(((((ET29*1.2)*0.3))*AV29*I29),2)*BB29),2)+ROUND((ROUND(((AE29-(((EU29*1.2)*0.3)))*AV29*I29),2)*BS29),2)) -> 0.4 | R29: =(ROUND((ROUND(((((EU29*1.2)*0.3))*AV29*I29),2)*BS29),2)+ROUND((ROUND(((AE29-(((EU29*1.2)*0.3)))*AV29*I29),2)*BS29),2)) -> 0 | S29: =ROUND((ROUND((AF29*AV29*I29),2)*BA29),2) -> 1642.6 | T29: =ROUND(CU29*I29,2) -> 0 | U29: =CV29*I29 -> 2.148444 | V29: =CW29*I29 -> 0 | W29: =ROUND(CX29*I29,2) -> 0 | X29: =(ROUND((((S29+ROUND((ROUND(((((EU29*1.2)*0.3))*AV29*I29),2)*BS29),2))*AT29)/100),2)+ROUND(((ROUND((ROUND(((AE29-(((EU29*1.2)*0.3)))*AV29*I29),2)*BS29),2)*AT29)/100),2)) -> 1478.34 | Y29: =(ROUND((((S29+ROUND((ROUND(((((EU29*1.2)*0.3))*AV29*I29),2)*BS29),2))*AU29)/100),2)+ROUND(((ROUND((ROUND(((AE29-(((EU29*1.2)*0.3)))*AV29*I29),2)*BS29),2)*AU29)/100),2)) -> 755.6 | AA29: 55915258 | AB29: =ROUND((AC29+AD29+AF29),6) -> 27.864 | AC29: =ROUND((((ES29*1)*0)),6) -> 0 | AD29: =ROUND((((((ET29*1.2)*0.3))-(((EU29*1.2)*0.3)))+AE29),6) -> 0.018 | AE29: =ROUND((((EU29*1.2)*0.3)),6) -> 0.0036 | AF29: =ROUND((((EV29*1.2)*0.3)),6) -> 27.846 | AG29: =ROUND((AP29),6) -> 0 | AH29: =(((EW29*1.2)*0.3)) -> 2.052 | AI29: =(((EX29*1.2)*0.3)) -> 0 | AJ29: =(AS29) -> 0 | AK29: 82.23 | AL29: 4.83 | AM29: 0.05 | AN29: 0.01 | AO29: 77.35 | AP29: 0 | AQ29: 5.7 | AR29: 0 | AS29: 0 | AT29: 90 | AU29: 46 | AV29: 1.047 | AW29: 1 | AZ29: 1 | BA29: 56.35 | BB29: 20 | BC29: 9.84 | BH29: 0 | BI29: 2 | BJ29: ТСН-2001.4. Доп. 1-42. Сб. 10, т. 80, поз. 9 | BM29: 68 | BN29: 0 | BO29: 4.10-80-9 | BP29: 1 | BQ29: 40 | BR29: 0 | BS29: 56.35 | BT29: 1 | BU29: 1 | BV29: 1 | BW29: 1 | BX29: 1 | BZ29: 90 | CA29: 46 | CE29: 1566 | CF29: 0 | CG29: 0 | CM29: 0 | CN29: Поправка: Гл.12.Прил.8.п.8. 3_12.00.01.11.001 Наименование: При наличии напряженных и стесненных условий производства работ (стесненность, сложность складирования и транспортной логистики и т.п.) для объектов, расположенных в пределах круговой магистральной системы улиц "Садовое кольцо" города Москвы Поправка: Гл.4.Прил.2.2.п.2.2.29_04.00.01.35.003 Наименование: При демонтаже оборудования, предназначенного в лом | CO29: 0 | CP29: =(P29+Q29+S29) -> 1643 | CQ29: =ROUND((ROUND((AC29*AW29*1),2)*BC29),2) -> 0 | CR29: =(ROUND((ROUND(((((ET29*1.2)*0.3))*AV29*1),2)*BB29),2)+ROUND((ROUND(((AE29-(((EU29*1.2)*0.3)))*AV29*1),2)*BS29),2)) -> 0.4 | CS29: =(ROUND((ROUND(((((EU29*1.2)*0.3))*AV29*1),2)*BS29),2)+ROUND((ROUND(((AE29-(((EU29*1.2)*0.3)))*AV29*1),2)*BS29),2)) -> 0 | CT29: =ROUND((ROUND((AF29*AV29*1),2)*BA29),2) -> 1642.6 | CU29: =AG29 -> 0 | CV29: =(AH29*AV29) -> 2.148444 | CW29: =AI29 -> 0 | CX29: =AJ29 -> 0 | CY29: =(ROUND((((S29+ROUND((ROUND(((((EU29*1.2)*0.3))*AV29*1),2)*BS29),2))*AT29)/100),2)+ROUND(((ROUND((ROUND(((AE29-(((EU29*1.2)*0.3)))*AV29*1),2)*BS29),2)*AT29)/100),2)) -> 1478.34 | CZ29: =(ROUND((((S29+ROUND((ROUND(((((EU29*1.2)*0.3))*AV29*1),2)*BS29),2))*AU29)/100),2)+ROUND(((ROUND((ROUND(((AE29-(((EU29*1.2)*0.3)))*AV29*1),2)*BS29),2)*AU29)/100),2)) -> 755.6 | DB29: 3 | DD29: *1)*0 | DE29: *1,2)*0,3 | DF29: *1,2)*0,3 | DG29: *1,2)*0,3 | DI29: *1,2)*0,3 | DJ29: *1,2)*0,3 | DN29: 0 | DO29: 0 | DP29: 1 | DQ29: 1 | DU29: 1013 | DV29: 1 ШТ. | DW29: 1 ШТ. | DX29: 1 | EE29: 55393700 | EF29: 40 | EG29: Монтаж оборудования | EH29: 0 | EJ29: 2 | EK29: 68 | EL29: ТСН-2001.4-10. Прокладка и монтаж сетей связи | EM29: ТСН-2001.4-10-1 | EO29: Поправка: Гл.12.Прил.8.п.8. 3_12.00.01.11.001 Поправка: Гл.4.Прил.2.2.п.2.2.29_04.00.01.35.003 | EQ29: 0 | ER29: 82.23 | ES29: 4.83 | ET29: 0.05 | EU29: 0.01 | EV29: 77.35 | EW29: 5.7 | EX29: 0 | EY29: 0 | FQ29: 0 | FR29: 0 | FS29: 0 | FX29: 90 | FY29: 46 | GD29: 1 | GF29: -168461099 | GG29: 2 | GH29: 1 | GI29: 2 | GJ29: 0 | GK29: 0 | GL29: =ROUND(IF(AND(BH29=3,BI29=3,FS29<>0),P29,0),2) -> 0 | GM29: =ROUND(O29+X29+Y29,2)+GX29 -> 3876.94 | GN29: =IF(OR(BI29=0,BI29=1),GM29-GX29,0) -> 0 | GO29: =IF(BI29=2,GM29-GX29,0) -> 3876.94 | GP29: =IF(BI29=4,GM29-GX29,0) -> 0 | GR29: 0 | GS29: 3 | GT29: 0 | GV29: =ROUND((GT29),6) -> 0 | GW29: 1 | GX29: =ROUND(HC29*I29,2) -> 0 | HA29: 0 | HB29: 0 | HC29: =GV29*GW29 -> 0 | HS29: 0 | IK29: 0
A30: 17 | B30: 1 | C30: =ROW(SmtRes!A6) -> 6 | D30: =ROW(EtalonRes!A7) -> 7 | E30: 2 | F30: 4.10-170-2 | G30: Монтаж блока информационно-управляющего (БИУ) в диспетчерской / демонтаж БИУ | H30: 1 ШТ. | I30: 1 | J30: 0 | K30: 1 | O30: =ROUND(CP30,2) -> 12.62 | P30: =ROUND((ROUND((AC30*AW30*I30),2)*BC30),2) -> 0 | Q30: =(ROUND((ROUND(((((ET30*1.2)*0.3))*AV30*I30),2)*BB30),2)+ROUND((ROUND(((AE30-(((EU30*1.2)*0.3)))*AV30*I30),2)*BS30),2)) -> 0 | R30: =(ROUND((ROUND(((((EU30*1.2)*0.3))*AV30*I30),2)*BS30),2)+ROUND((ROUND(((AE30-(((EU30*1.2)*0.3)))*AV30*I30),2)*BS30),2)) -> 0 | S30: =ROUND((ROUND((AF30*AV30*I30),2)*BA30),2) -> 12.62 | T30: =ROUND(CU30*I30,2) -> 0 | U30: =CV30*I30 -> 0.998838 | V30: =CW30*I30 -> 0 | W30: =ROUND(CX30*I30,2) -> 0 | X30: =(ROUND((((S30+ROUND((ROUND(((((EU30*1.2)*0.3))*AV30*I30),2)*BS30),2))*AT30)/100),2)+ROUND(((ROUND((ROUND(((AE30-(((EU30*1.2)*0.3)))*AV30*I30),2)*BS30),2)*AT30)/100),2)) -> 11.36 | Y30: =(ROUND((((S30+ROUND((ROUND(((((EU30*1.2)*0.3))*AV30*I30),2)*BS30),2))*AU30)/100),2)+ROUND(((ROUND((ROUND(((AE30-(((EU30*1.2)*0.3)))*AV30*I30),2)*BS30),2)*AU30)/100),2)) -> 5.81 | AA30: 55915256 | AB30: =ROUND((AC30+AD30+AF30),6) -> 12.0492 | AC30: =ROUND((((ES30*1)*0)),6) -> 0 | AD30: =ROUND((((((ET30*1.2)*0.3))-(((EU30*1.2)*0.3)))+AE30),6) -> 0 | AE30: =ROUND((((EU30*1.2)*0.3)),6) -> 0 | AF30: =ROUND((((EV30*1.2)*0.3)),6) -> 12.0492 | AG30: =ROUND((AP30),6) -> 0 | AH30: =(((EW30*1.2)*0.3)) -> 0.954 | AI30: =(((EX30*1.2)*0.3)) -> 0 | AJ30: =(AS30) -> 0 | AK30: 35.81 | AL30: 2.34 | AM30: 0 | AN30: 0 | AO30: 33.47 | AP30: 0 | AQ30: 2.65 | AR30: 0 | AS30: 0 | AT30: 90 | AU30: 46 | AV30: 1.047 | AW30: 1 | AZ30: 1 | BA30: 1 | BB30: 1 | BC30: 1 | BH30: 0 | BI30: 2 | BJ30: ТСН-2001.4 Доп. 67, Сб. 10, т. 170, поз. 2 | BM30: 68 | BN30: 0 | BO30: 4.10-170-2 | BP30: 1 | BQ30: 40 | BR30: 0 | BS30: 1 | BT30: 1 | BU30: 1 | BV30: 1 | BW30: 1 | BX30: 1 | BZ30: 90 | CA30: 46 | CE30: 1566 | CF30: 0 | CG30: 0 | CM30: 0 | CN30: Поправка: Гл.12.Прил.8.п.8. 3_12.00.01.11.001 Наименование: При наличии напряженных и стесненных условий производства работ (стесненность, сложность складирования и транспортной логистики и т.п.) для объектов, расположенных в пределах круговой магистральной системы улиц "Садовое кольцо" города Москвы Поправка: Гл.4.Прил.2.2.п.2.2.29_04.00.01.35.003 Наименование: При демонтаже оборудования, предназначенного в лом | CO30: 0 | CP30: =(P30+Q30+S30) -> 12.62 | CQ30: =ROUND((ROUND((AC30*AW30*1),2)*BC30),2) -> 0 | CR30: =(ROUND((ROUND(((((ET30*1.2)*0.3))*AV30*1),2)*BB30),2)+ROUND((ROUND(((AE30-(((EU30*1.2)*0.3)))*AV30*1),2)*BS30),2)) -> 0 | CS30: =(ROUND((ROUND(((((EU30*1.2)*0.3))*AV30*1),2)*BS30),2)+ROUND((ROUND(((AE30-(((EU30*1.2)*0.3)))*AV30*1),2)*BS30),2)) -> 0 | CT30: =ROUND((ROUND((AF30*AV30*1),2)*BA30),2) -> 12.62 | CU30: =AG30 -> 0 | CV30: =(AH30*AV30) -> 0.998838 | CW30: =AI30 -> 0 | CX30: =AJ30 -> 0 | CY30: =(ROUND((((S30+ROUND((ROUND(((((EU30*1.2)*0.3))*AV30*1),2)*BS30),2))*AT30)/100),2)+ROUND(((ROUND((ROUND(((AE30-(((EU30*1.2)*0.3)))*AV30*1),2)*BS30),2)*AT30)/100),2)) -> 11.36 | CZ30: =(ROUND((((S30+ROUND((ROUND(((((EU30*1.2)*0.3))*AV30*1),2)*BS30),2))*AU30)/100),2)+ROUND(((ROUND((ROUND(((AE30-(((EU30*1.2)*0.3)))*AV30*1),2)*BS30),2)*AU30)/100),2)) -> 5.81 | DB30: 5 | DD30: *1)*0 | DE30: *1,2)*0,3 | DF30: *1,2)*0,3 | DG30: *1,2)*0,3 | DI30: *1,2)*0,3 | DJ30: *1,2)*0,3 | DN30: 0 | DO30: 0 | DP30: 1 | DQ30: 1 | DU30: 1013 | DV30: 1 ШТ. | DW30: 1 ШТ. | DX30: 1 | EE30: 55393700 | EF30: 40 | EG30: Монтаж оборудования | EH30: 0 | EJ30: 2 | EK30: 68 | EL30: ТСН-2001.4-10. Прокладка и монтаж сетей связи | EM30: ТСН-2001.4-10-1 | EO30: Поправка: Гл.12.Прил.8.п.8. 3_12.00.01.11.001 Поправка: Гл.4.Прил.2.2.п.2.2.29_04.00.01.35.003 | EQ30: 0 | ER30: 35.81 | ES30: 2.34 | ET30: 0 | EU30: 0 | EV30: 33.47 | EW30: 2.65 | EX30: 0 | EY30: 0 | FQ30: 0 | FR30: 0 | FS30: 0 | FX30: 90 | FY30: 46 | GD30: 1 | GF30: 2145468006 | GG30: 2 | GH30: 1 | GI30: 2 | GJ30: 0 | GK30: 0 | GL30: =ROUND(IF(AND(BH30=3,BI30=3,FS30<>0),P30,0),2) -> 0 | GM30: =ROUND(O30+X30+Y30,2)+GX30 -> 29.79 | GN30: =IF(OR(BI30=0,BI30=1),GM30-GX30,0) -> 0 | GO30: =IF(BI30=2,GM30-GX30,0) -> 29.79 | GP30: =IF(BI30=4,GM30-GX30,0) -> 0 | GR30: 0 | GS30: 3 | GT30: 0 | GV30: =ROUND((GT30),6) -> 0 | GW30: 1 | GX30: =ROUND(HC30*I30,2) -> 0 | HA30: 0 | HB30: 0 | HC30: =GV30*GW30 -> 0 | HS30: 0 | IK30: 0
A31: 17 | B31: 1 | C31: =ROW(SmtRes!A10) -> 10 | D31: =ROW(EtalonRes!A12) -> 12 | E31: 2 | F31: 4.10-170-2 | G31: Монтаж блока информационно-управляющего (БИУ) в диспетчерской / демонтаж БИУ | H31: 1 ШТ. | I31: 1 | J31: 0 | K31: 1 | O31: =ROUND(CP31,2) -> 711.14 | P31: =ROUND((ROUND((AC31*AW31*I31),2)*BC31),2) -> 0 | Q31: =(ROUND((ROUND(((((ET31*1.2)*0.3))*AV31*I31),2)*BB31),2)+ROUND((ROUND(((AE31-(((EU31*1.2)*0.3)))*AV31*I31),2)*BS31),2)) -> 0 | R31: =(ROUND((ROUND(((((EU31*1.2)*0.3))*AV31*I31),2)*BS31),2)+ROUND((ROUND(((AE31-(((EU31*1.2)*0.3)))*AV31*I31),2)*BS31),2)) -> 0 | S31: =ROUND((ROUND((AF31*AV31*I31),2)*BA31),2) -> 711.14 | T31: =ROUND(CU31*I31,2) -> 0 | U31: =CV31*I31 -> 0.998838 | V31: =CW31*I31 -> 0 | W31: =ROUND(CX31*I31,2) -> 0 | X31: =(ROUND((((S31+ROUND((ROUND(((((EU31*1.2)*0.3))*AV31*I31),2)*BS31),2))*AT31)/100),2)+ROUND(((ROUND((ROUND(((AE31-(((EU31*1.2)*0.3)))*AV31*I31),2)*BS31),2)*AT31)/100),2)) -> 640.03 | Y31: =(ROUND((((S31+ROUND((ROUND(((((EU31*1.2)*0.3))*AV31*I31),2)*BS31),2))*AU31)/100),2)+ROUND(((ROUND((ROUND(((AE31-(((EU31*1.2)*0.3)))*AV31*I31),2)*BS31),2)*AU31)/100),2)) -> 327.12 | AA31: 55915258 | AB31: =ROUND((AC31+AD31+AF31),6) -> 12.0492 | AC31: =ROUND((((ES31*1)*0)),6) -> 0 | AD31: =ROUND((((((ET31*1.2)*0.3))-(((EU31*1.2)*0.3)))+AE31),6) -> 0 | AE31: =ROUND((((EU31*1.2)*0.3)),6) -> 0 | AF31: =ROUND((((EV31*1.2)*0.3)),6) -> 12.0492 | AG31: =ROUND((AP31),6) -> 0 | AH31: =(((EW31*1.2)*0.3)) -> 0.954 | AI31: =(((EX31*1.2)*0.3)) -> 0 | AJ31: =(AS31) -> 0 | AK31: 35.81 | AL31: 2.34 | AM31: 0 | AN31: 0 | AO31: 33.47 | AP31: 0 | AQ31: 2.65 | AR31: 0 | AS31: 0 | AT31: 90 | AU31: 46 | AV31: 1.047 | AW31: 1 | AZ31: 1 | BA31: 56.35 | BB31: 1 | BC31: 10.24 | BH31: 0 | BI31: 2 | BJ31: ТСН-2001.4 Доп. 67, Сб. 10, т. 170, поз. 2 | BM31: 68 | BN31: 0 | BO31: 4.10-170-2 | BP31: 1 | BQ31: 40 | BR31: 0 | BS31: 56.35 | BT31: 1 | BU31: 1 | BV31: 1 | BW31: 1 | BX31: 1 | BZ31: 90 | CA31: 46 | CE31: 1566 | CF31: 0 | CG31: 0 | CM31: 0 | CN31: Поправка: Гл.12.Прил.8.п.8. 3_12.00.01.11.001 Наименование: При наличии напряженных и стесненных условий производства работ (стесненность, сложность складирования и транспортной логистики и т.п.) для объектов, расположенных в пределах круговой магистральной системы улиц "Садовое кольцо" города Москвы Поправка: Гл.4.Прил.2.2.п.2.2.29_04.00.01.35.003 Наименование: При демонтаже оборудования, предназначенного в лом | CO31: 0 | CP31: =(P31+Q31+S31) -> 711.14 | CQ31: =ROUND((ROUND((AC31*AW31*1),2)*BC31),2) -> 0 | CR31: =(ROUND((ROUND(((((ET31*1.2)*0.3))*AV31*1),2)*BB31),2)+ROUND((ROUND(((AE31-(((EU31*1.2)*0.3)))*AV31*1),2)*BS31),2)) -> 0 | CS31: =(ROUND((ROUND(((((EU31*1.2)*0.3))*AV31*1),2)*BS31),2)+ROUND((ROUND(((AE31-(((EU31*1.2)*0.3)))*AV31*1),2)*BS31),2)) -> 0 | CT31: =ROUND((ROUND((AF31*AV31*1),2)*BA31),2) -> 711.14 | CU31: =AG31 -> 0 | CV31: =(AH31*AV31) -> 0.998838 | CW31: =AI31 -> 0 | CX31: =AJ31 -> 0 | CY31: =(ROUND((((S31+ROUND((ROUND(((((EU31*1.2)*0.3))*AV31*1),2)*BS31),2))*AT31)/100),2)+ROUND(((ROUND((ROUND(((AE31-(((EU31*1.2)*0.3)))*AV31*1),2)*BS31),2)*AT31)/100),2)) -> 640.03 | CZ31: =(ROUND((((S31+ROUND((ROUND(((((EU31*1.2)*0.3))*AV31*1),2)*BS31),2))*AU31)/100),2)+ROUND(((ROUND((ROUND(((AE31-(((EU31*1.2)*0.3)))*AV31*1),2)*BS31),2)*AU31)/100),2)) -> 327.12 | DB31: 7 | DD31: *1)*0 | DE31: *1,2)*0,3 | DF31: *1,2)*0,3 | DG31: *1,2)*0,3 | DI31: *1,2)*0,3 | DJ31: *1,2)*0,3 | DN31: 0 | DO31: 0 | DP31: 1 | DQ31: 1 | DU31: 1013 | DV31: 1 ШТ. | DW31: 1 ШТ. | DX31: 1 | EE31: 55393700 | EF31: 40 | EG31: Монтаж оборудования | EH31: 0 | EJ31: 2 | EK31: 68 | EL31: ТСН-2001.4-10. Прокладка и монтаж сетей связи | EM31: ТСН-2001.4-10-1 | EO31: Поправка: Гл.12.Прил.8.п.8. 3_12.00.01.11.001 Поправка: Гл.4.Прил.2.2.п.2.2.29_04.00.01.35.003 | EQ31: 0 | ER31: 35.81 | ES31: 2.34 | ET31: 0 | EU31: 0 | EV31: 33.47 | EW31: 2.65 | EX31: 0 | EY31: 0 | FQ31: 0 | FR31: 0 | FS31: 0 | FX31: 90 | FY31: 46 | GD31: 1 | GF31: 2145468006 | GG31: 2 | GH31: 1 | GI31: 2 | GJ31: 0 | GK31: 0 | GL31: =ROUND(IF(AND(BH31=3,BI31=3,FS31<>0),P31,0),2) -> 0 | GM31: =ROUND(O31+X31+Y31,2)+GX31 -> 1678.29 | GN31: =IF(OR(BI31=0,BI31=1),GM31-GX31,0) -> 0 | GO31: =IF(BI31=2,GM31-GX31,0) -> 1678.29 | GP31: =IF(BI31=4,GM31-GX31,0) -> 0 | GR31: 0 | GS31: 3 | GT31: 0 | GV31: =ROUND((GT31),6) -> 0 | GW31: 1 | GX31: =ROUND(HC31*I31,2) -> 0 | HA31: 0 | HB31: 0 | HC31: =GV31*GW31 -> 0 | HS31: 0 | IK31: 0
A32: 17 | B32: 1 | C32: =ROW(SmtRes!A11) -> 11 | D32: =ROW(EtalonRes!A13) -> 13 | E32: 3 | F32: 4.10-80-12 | G32: Аппараты приемные, устройства промежуточные на 5 лучей / демонтаж модуля сопряжения | H32: 1 ШТ. | I32: 1 | J32: 0 | K32: 1 | O32: =ROUND(CP32,2) -> 12.3 | P32: =ROUND((ROUND((AC32*AW32*I32),2)*BC32),2) -> 0 | Q32: =(ROUND((ROUND(((((ET32*1.2)*0.3))*AV32*I32),2)*BB32),2)+ROUND((ROUND(((AE32-(((EU32*1.2)*0.3)))*AV32*I32),2)*BS32),2)) -> 0.02 | R32: =(ROUND((ROUND(((((EU32*1.2)*0.3))*AV32*I32),2)*BS32),2)+ROUND((ROUND(((AE32-(((EU32*1.2)*0.3)))*AV32*I32),2)*BS32),2)) -> 0 | S32: =ROUND((ROUND((AF32*AV32*I32),2)*BA32),2) -> 12.28 | T32: =ROUND(CU32*I32,2) -> 0 | U32: =CV32*I32 -> 0.904608 | V32: =CW32*I32 -> 0 | W32: =ROUND(CX32*I32,2) -> 0 | X32: =(ROUND((((S32+ROUND((ROUND(((((EU32*1.2)*0.3))*AV32*I32),2)*BS32),2))*AT32)/100),2)+ROUND(((ROUND((ROUND(((AE32-(((EU32*1.2)*0.3)))*AV32*I32),2)*BS32),2)*AT32)/100),2)) -> 11.05 | Y32: =(ROUND((((S32+ROUND((ROUND(((((EU32*1.2)*0.3))*AV32*I32),2)*BS32),2))*AU32)/100),2)+ROUND(((ROUND((ROUND(((AE32-(((EU32*1.2)*0.3)))*AV32*I32),2)*BS32),2)*AU32)/100),2)) -> 5.65 | AA32: 55915256 | AB32: =ROUND((AC32+AD32+AF32),6) -> 11.7432 | AC32: =ROUND((((ES32*1)*0)),6) -> 0 | AD32: =ROUND((((((ET32*1.2)*0.3))-(((EU32*1.2)*0.3)))+AE32),6) -> 0.018 | AE32: =ROUND((((EU32*1.2)*0.3)),6) -> 0.0036 | AF32: =ROUND((((EV32*1.2)*0.3)),6) -> 11.7252 | AG32: =ROUND((AP32),6) -> 0 | AH32: =(((EW32*1.2)*0.3)) -> 0.864 | AI32: =(((EX32*1.2)*0.3)) -> 0 | AJ32: =(AS32) -> 0 | AK32: 36.33 | AL32: 3.71 | AM32: 0.05 | AN32: 0.01 | AO32: 32.57 | AP32: 0 | AQ32: 2.4 | AR32: 0 | AS32: 0 | AT32: 90 | AU32: 46 | AV32: 1.047 | AW32: 1 | AZ32: 1 | BA32: 1 | BB32: 1 | BC32: 1 | BH32: 0 | BI32: 2 | BJ32: ТСН-2001.4. Доп. 1-42. Сб. 10, т. 80, поз. 12 | BM32: 68 | BN32: 0 | BO32: 4.10-80-12 | BP32: 1 | BQ32: 40 | BR32: 0 | BS32: 1 | BT32: 1 | BU32: 1 | BV32: 1 | BW32: 1 | BX32: 1 | BZ32: 90 | CA32: 46 | CE32: 1566 | CF32: 0 | CG32: 0 | CM32: 0 | CN32: Поправка: Гл.12.Прил.8.п.8. 3_12.00.01.11.001 Наименование: При наличии напряженных и стесненных условий производства работ (стесненность, сложность складирования и транспортной логистики и т.п.) для объектов, расположенных в пределах круговой магистральной системы улиц "Садовое кольцо" города Москвы Поправка: Гл.4.Прил.2.2.п.2.2.29_04.00.01.35.003 Наименование: При демонтаже оборудования, предназначенного в лом | CO32: 0 | CP32: =(P32+Q32+S32) -> 12.3 | CQ32: =ROUND((ROUND((AC32*AW32*1),2)*BC32),2) -> 0 | CR32: =(ROUND((ROUND(((((ET32*1.2)*0.3))*AV32*1),2)*BB32),2)+ROUND((ROUND(((AE32-(((EU32*1.2)*0.3)))*AV32*1),2)*BS32),2)) -> 0.02 | CS32: =(ROUND((ROUND(((((EU32*1.2)*0.3))*AV32*1),2)*BS32),2)+ROUND((ROUND(((AE32-(((EU32*1.2)*0.3)))*AV32*1),2)*BS32),2)) -> 0 | CT32: =ROUND((ROUND((AF32*AV32*1),2)*BA32),2) -> 12.28 | CU32: =AG32 -> 0 | CV32: =(AH32*AV32) -> 0.904608 | CW32: =AI32 -> 0 | CX32: =AJ32 -> 0 | CY32: =(ROUND((((S32+ROUND((ROUND(((((EU32*1.2)*0.3))*AV32*1),2)*BS32),2))*AT32)/100),2)+ROUND(((ROUND((ROUND(((AE32-(((EU32*1.2)*0.3)))*AV32*1),2)*BS32),2)*AT32)/100),2)) -> 11.05 | CZ32: =(ROUND((((S32+ROUND((ROUND(((((EU32*1.2)*0.3))*AV32*1),2)*BS32),2))*AU32)/100),2)+ROUND(((ROUND((ROUND(((AE32-(((EU32*1.2)*0.3)))*AV32*1),2)*BS32),2)*AU32)/100),2)) -> 5.65 | DB32: 9 | DD32: *1)*0 | DE32: *1,2)*0,3 | DF32: *1,2)*0,3 | DG32: *1,2)*0,3 | DI32: *1,2)*0,3 | DJ32: *1,2)*0,3 | DN32: 0 | DO32: 0 | DP32: 1 | DQ32: 1 | DU32: 1013 | DV32: 1 ШТ. | DW32: 1 ШТ. | DX32: 1 | EE32: 55393700 | EF32: 40 | EG32: Монтаж оборудования | EH32: 0 | EJ32: 2 | EK32: 68 | EL32: ТСН-2001.4-10. Прокладка и монтаж сетей связи | EM32: ТСН-2001.4-10-1 | EO32: Поправка: Гл.12.Прил.8.п.8. 3_12.00.01.11.001 Поправка: Гл.4.Прил.2.2.п.2.2.29_04.00.01.35.003 | EQ32: 0 | ER32: 36.33 | ES32: 3.71 | ET32: 0.05 | EU32: 0.01 | EV32: 32.57 | EW32: 2.4 | EX32: 0 | EY32: 0 | FQ32: 0 | FR32: 0 | FS32: 0 | FX32: 90 | FY32: 46 | GD32: 1 | GF32: 1466411927 | GG32: 2 | GH32: 1 | GI32: 2 | GJ32: 0 | GK32: 0 | GL32: =ROUND(IF(AND(BH32=3,BI32=3,FS32<>0),P32,0),2) -> 0 | GM32: =ROUND(O32+X32+Y32,2)+GX32 -> 29 | GN32: =IF(OR(BI32=0,BI32=1),GM32-GX32,0) -> 0 | GO32: =IF(BI32=2,GM32-GX32,0) -> 29 | GP32: =IF(BI32=4,GM32-GX32,0) -> 0 | GR32: 0 | GS32: 3 | GT32: 0 | GV32: =ROUND((GT32),6) -> 0 | GW32: 1 | GX32: =ROUND(HC32*I32,2) -> 0 | HA32: 0 | HB32: 0 | HC32: =GV32*GW32 -> 0 | HS32: 0 | IK32: 0
A33: 17 | B33: 1 | C33: =ROW(SmtRes!A12) -> 12 | D33: =ROW(EtalonRes!A14) -> 14 | E33: 3 | F33: 4.10-80-12 | G33: Аппараты приемные, устройства промежуточные на 5 лучей / демонтаж модуля сопряжения | H33: 1 ШТ. | I33: 1 | J33: 0 | K33: 1 | O33: =ROUND(CP33,2) -> 692.38 | P33: =ROUND((ROUND((AC33*AW33*I33),2)*BC33),2) -> 0 | Q33: =(ROUND((ROUND(((((ET33*1.2)*0.3))*AV33*I33),2)*BB33),2)+ROUND((ROUND(((AE33-(((EU33*1.2)*0.3)))*AV33*I33),2)*BS33),2)) -> 0.4 | R33: =(ROUND((ROUND(((((EU33*1.2)*0.3))*AV33*I33),2)*BS33),2)+ROUND((ROUND(((AE33-(((EU33*1.2)*0.3)))*AV33*I33),2)*BS33),2)) -> 0 | S33: =ROUND((ROUND((AF33*AV33*I33),2)*BA33),2) -> 691.98 | T33: =ROUND(CU33*I33,2) -> 0 | U33: =CV33*I33 -> 0.904608 | V33: =CW33*I33 -> 0 | W33: =ROUND(CX33*I33,2) -> 0 | X33: =(ROUND((((S33+ROUND((ROUND(((((EU33*1.2)*0.3))*AV33*I33),2)*BS33),2))*AT33)/100),2)+ROUND(((ROUND((ROUND(((AE33-(((EU33*1.2)*0.3)))*AV33*I33),2)*BS33),2)*AT33)/100),2)) -> 622.78 | Y33: =(ROUND((((S33+ROUND((ROUND(((((EU33*1.2)*0.3))*AV33*I33),2)*BS33),2))*AU33)/100),2)+ROUND(((ROUND((ROUND(((AE33-(((EU33*1.2)*0.3)))*AV33*I33),2)*BS33),2)*AU33)/100),2)) -> 318.31 | AA33: 55915258 | AB33: =ROUND((AC33+AD33+AF33),6) -> 11.7432 | AC33: =ROUND((((ES33*1)*0)),6) -> 0 | AD33: =ROUND((((((ET33*1.2)*0.3))-(((EU33*1.2)*0.3)))+AE33),6) -> 0.018 | AE33: =ROUND((((EU33*1.2)*0.3)),6) -> 0.0036 | AF33: =ROUND((((EV33*1.2)*0.3)),6) -> 11.7252 | AG33: =ROUND((AP33),6) -> 0 | AH33: =(((EW33*1.2)*0.3)) -> 0.864 | AI33: =(((EX33*1.2)*0.3)) -> 0 | AJ33: =(AS33) -> 0 | AK33: 36.33 | AL33: 3.71 | AM33: 0.05 | AN33: 0.01 | AO33: 32.57 | AP33: 0 | AQ33: 2.4 | AR33: 0 | AS33: 0 | AT33: 90 | AU33: 46 | AV33: 1.047 | AW33: 1 | AZ33: 1 | BA33: 56.35 | BB33: 20 | BC33: 9.84 | BH33: 0 | BI33: 2 | BJ33: ТСН-2001.4. Доп. 1-42. Сб. 10, т. 80, поз. 12 | BM33: 68 | BN33: 0 | BO33: 4.10-80-12 | BP33: 1 | BQ33: 40 | BR33: 0 | BS33: 56.35 | BT33: 1 | BU33: 1 | BV33: 1 | BW33: 1 | BX33: 1 | BZ33: 90 | CA33: 46 | CE33: 1566 | CF33: 0 | CG33: 0 | CM33: 0 | CN33: Поправка: Гл.12.Прил.8.п.8. 3_12.00.01.11.001 Наименование: При наличии напряженных и стесненных условий производства работ (стесненность, сложность складирования и транспортной логистики и т.п.) для объектов, расположенных в пределах круговой магистральной системы улиц "Садовое кольцо" города Москвы Поправка: Гл.4.Прил.2.2.п.2.2.29_04.00.01.35.003 Наименование: При демонтаже оборудования, предназначенного в лом | CO33: 0 | CP33: =(P33+Q33+S33) -> 692.38 | CQ33: =ROUND((ROUND((AC33*AW33*1),2)*BC33),2) -> 0 | CR33: =(ROUND((ROUND(((((ET33*1.2)*0.3))*AV33*1),2)*BB33),2)+ROUND((ROUND(((AE33-(((EU33*1.2)*0.3)))*AV33*1),2)*BS33),2)) -> 0.4 | CS33: =(ROUND((ROUND(((((EU33*1.2)*0.3))*AV33*1),2)*BS33),2)+ROUND((ROUND(((AE33-(((EU33*1.2)*0.3)))*AV33*1),2)*BS33),2)) -> 0 | CT33: =ROUND((ROUND((AF33*AV33*1),2)*BA33),2) -> 691.98 | CU33: =AG33 -> 0 | CV33: =(AH33*AV33) -> 0.904608 | CW33: =AI33 -> 0 | CX33: =AJ33 -> 0 | CY33: =(ROUND((((S33+ROUND((ROUND(((((EU33*1.2)*0.3))*AV33*1),2)*BS33),2))*AT33)/100),2)+ROUND(((ROUND((ROUND(((AE33-(((EU33*1.2)*0.3)))*AV33*1),2)*BS33),2)*AT33)/100),2)) -> 622.78 | CZ33: =(ROUND((((S33+ROUND((ROUND(((((EU33*1.2)*0.3))*AV33*1),2)*BS33),2))*AU33)/100),2)+ROUND(((ROUND((ROUND(((AE33-(((EU33*1.2)*0.3)))*AV33*1),2)*BS33),2)*AU33)/100),2)) -> 318.31 | DB33: 11 | DD33: *1)*0 | DE33: *1,2)*0,3 | DF33: *1,2)*0,3 | DG33: *1,2)*0,3 | DI33: *1,2)*0,3 | DJ33: *1,2)*0,3 | DN33: 0 | DO33: 0 | DP33: 1 | DQ33: 1 | DU33: 1013 | DV33: 1 ШТ. | DW33: 1 ШТ. | DX33: 1 | EE33: 55393700 | EF33: 40 | EG33: Монтаж оборудования | EH33: 0 | EJ33: 2 | EK33: 68 | EL33: ТСН-2001.4-10. Прокладка и монтаж сетей связи | EM33: ТСН-2001.4-10-1 | EO33: Поправка: Гл.12.Прил.8.п.8. 3_12.00.01.11.001 Поправка: Гл.4.Прил.2.2.п.2.2.29_04.00.01.35.003 | EQ33: 0 | ER33: 36.33 | ES33: 3.71 | ET33: 0.05 | EU33: 0.01 | EV33: 32.57 | EW33: 2.4 | EX33: 0 | EY33: 0 | FQ33: 0 | FR33: 0 | FS33: 0 | FX33: 90 | FY33: 46 | GD33: 1 | GF33: 1466411927 | GG33: 2 | GH33: 1 | GI33: 2 | GJ33: 0 | GK33: 0 | GL33: =ROUND(IF(AND(BH33=3,BI33=3,FS33<>0),P33,0),2) -> 0 | GM33: =ROUND(O33+X33+Y33,2)+GX33 -> 1633.47 | GN33: =IF(OR(BI33=0,BI33=1),GM33-GX33,0) -> 0 | GO33: =IF(BI33=2,GM33-GX33,0) -> 1633.47 | GP33: =IF(BI33=4,GM33-GX33,0) -> 0 | GR33: 0 | GS33: 3 | GT33: 0 | GV33: =ROUND((GT33),6) -> 0 | GW33: 1 | GX33: =ROUND(HC33*I33,2) -> 0 | HA33: 0 | HB33: 0 | HC33: =GV33*GW33 -> 0 | HS33: 0 | IK33: 0
A34: 17 | B34: 1 | C34: =ROW(SmtRes!A13) -> 13 | D34: =ROW(EtalonRes!A15) -> 15 | E34: 4 | F34: 4.10-80-13 | G34: Аппараты приемные, устройства промежуточные на 1 луч / демонтаж адресной метки | H34: 1 ШТ. | I34: 31 | J34: 0 | K34: 31 | O34: =ROUND(CP34,2) -> 188.35 | P34: =ROUND((ROUND((AC34*AW34*I34),2)*BC34),2) -> 0 | Q34: =(ROUND((ROUND(((((ET34*1.2)*0.3))*AV34*I34),2)*BB34),2)+ROUND((ROUND(((AE34-(((EU34*1.2)*0.3)))*AV34*I34),2)*BS34),2)) -> 0.58 | R34: =(ROUND((ROUND(((((EU34*1.2)*0.3))*AV34*I34),2)*BS34),2)+ROUND((ROUND(((AE34-(((EU34*1.2)*0.3)))*AV34*I34),2)*BS34),2)) -> 0.12 | S34: =ROUND((ROUND((AF34*AV34*I34),2)*BA34),2) -> 187.77 | T34: =ROUND(CU34*I34,2) -> 0 | U34: =CV34*I34 -> 14.021424 | V34: =CW34*I34 -> 0 | W34: =ROUND(CX34*I34,2) -> 0 | X34: =(ROUND((((S34+ROUND((ROUND(((((EU34*1.2)*0.3))*AV34*I34),2)*BS34),2))*AT34)/100),2)+ROUND(((ROUND((ROUND(((AE34-(((EU34*1.2)*0.3)))*AV34*I34),2)*BS34),2)*AT34)/100),2)) -> 169.1 | Y34: =(ROUND((((S34+ROUND((ROUND(((((EU34*1.2)*0.3))*AV34*I34),2)*BS34),2))*AU34)/100),2)+ROUND(((ROUND((ROUND(((AE34-(((EU34*1.2)*0.3)))*AV34*I34),2)*BS34),2)*AU34)/100),2)) -> 86.43 | AA34: 55915256 | AB34: =ROUND((AC34+AD34+AF34),6) -> 5.8032 | AC34: =ROUND((((ES34*1)*0)),6) -> 0 | AD34: =ROUND((((((ET34*1.2)*0.3))-(((EU34*1.2)*0.3)))+AE34),6) -> 0.018 | AE34: =ROUND((((EU34*1.2)*0.3)),6) -> 0.0036 | AF34: =ROUND((((EV34*1.2)*0.3)),6) -> 5.7852 | AG34: =ROUND((AP34),6) -> 0 | AH34: =(((EW34*1.2)*0.3)) -> 0.432 | AI34: =(((EX34*1.2)*0.3)) -> 0 | AJ34: =(AS34) -> 0 | AK34: 18.08 | AL34: 1.96 | AM34: 0.05 | AN34: 0.01 | AO34: 16.07 | AP34: 0 | AQ34: 1.2 | AR34: 0 | AS34: 0 | AT34: 90 | AU34: 46 | AV34: 1.047 | AW34: 1 | AZ34: 1 | BA34: 1 | BB34: 1 | BC34: 1 | BH34: 0 | BI34: 2 | BJ34: ТСН-2001.4. Доп. 1-42. Сб. 10, т. 80, поз. 13 | BM34: 68 | BN34: 0 | BO34: 4.10-80-13 | BP34: 1 | BQ34: 40 | BR34: 0 | BS34: 1 | BT34: 1 | BU34: 1 | BV34: 1 | BW34: 1 | BX34: 1 | BZ34: 90 | CA34: 46 | CE34: 1566 | CF34: 0 | CG34: 0 | CM34: 0 | CN34: Поправка: Гл.12.Прил.8.п.8. 3_12.00.01.11.001 Наименование: При наличии напряженных и стесненных условий производства работ (стесненность, сложность складирования и транспортной логистики и т.п.) для объектов, расположенных в пределах круговой магистральной системы улиц "Садовое кольцо" города Москвы Поправка: Гл.4.Прил.2.2.п.2.2.29_04.00.01.35.003 Наименование: При демонтаже оборудования, предназначенного в лом | CO34: 0 | CP34: =(P34+Q34+S34) -> 188.35 | CQ34: =ROUND((ROUND((AC34*AW34*1),2)*BC34),2) -> 0 | CR34: =(ROUND((ROUND(((((ET34*1.2)*0.3))*AV34*1),2)*BB34),2)+ROUND((ROUND(((AE34-(((EU34*1.2)*0.3)))*AV34*1),2)*BS34),2)) -> 0.02 | CS34: =(ROUND((ROUND(((((EU34*1.2)*0.3))*AV34*1),2)*BS34),2)+ROUND((ROUND(((AE34-(((EU34*1.2)*0.3)))*AV34*1),2)*BS34),2)) -> 0 | CT34: =ROUND((ROUND((AF34*AV34*1),2)*BA34),2) -> 6.06 | CU34: =AG34 -> 0 | CV34: =(AH34*AV34) -> 0.452304 | CW34: =AI34 -> 0 | CX34: =AJ34 -> 0 | CY34: =(ROUND((((S34+ROUND((ROUND(((((EU34*1.2)*0.3))*AV34*1),2)*BS34),2))*AT34)/100),2)+ROUND(((ROUND((ROUND(((AE34-(((EU34*1.2)*0.3)))*AV34*1),2)*BS34),2)*AT34)/100),2)) -> 168.99 | CZ34: =(ROUND((((S34+ROUND((ROUND(((((EU34*1.2)*0.3))*AV34*1),2)*BS34),2))*AU34)/100),2)+ROUND(((ROUND((ROUND(((AE34-(((EU34*1.2)*0.3)))*AV34*1),2)*BS34),2)*AU34)/100),2)) -> 86.37 | DB34: 13 | DD34: *1)*0 | DE34: *1,2)*0,3 | DF34: *1,2)*0,3 | DG34: *1,2)*0,3 | DI34: *1,2)*0,3 | DJ34: *1,2)*0,3 | DN34: 0 | DO34: 0 | DP34: 1 | DQ34: 1 | DU34: 1013 | DV34: 1 ШТ. | DW34: 1 ШТ. | DX34: 1 | EE34: 55393700 | EF34: 40 | EG34: Монтаж оборудования | EH34: 0 | EJ34: 2 | EK34: 68 | EL34: ТСН-2001.4-10. Прокладка и монтаж сетей связи | EM34: ТСН-2001.4-10-1 | EO34: Поправка: Гл.12.Прил.8.п.8. 3_12.00.01.11.001 Поправка: Гл.4.Прил.2.2.п.2.2.29_04.00.01.35.003 | EQ34: 0 | ER34: 18.08 | ES34: 1.96 | ET34: 0.05 | EU34: 0.01 | EV34: 16.07 | EW34: 1.2 | EX34: 0 | EY34: 0 | FQ34: 0 | FR34: 0 | FS34: 0 | FX34: 90 | FY34: 46 | GD34: 1 | GF34: -808829180 | GG34: 2 | GH34: 1 | GI34: 2 | GJ34: 0 | GK34: 0 | GL34: =ROUND(IF(AND(BH34=3,BI34=3,FS34<>0),P34,0),2) -> 0 | GM34: =ROUND(O34+X34+Y34,2)+GX34 -> 443.88 | GN34: =IF(OR(BI34=0,BI34=1),GM34-GX34,0) -> 0 | GO34: =IF(BI34=2,GM34-GX34,0) -> 443.88 | GP34: =IF(BI34=4,GM34-GX34,0) -> 0 | GR34: 0 | GS34: 3 | GT34: 0 | GV34: =ROUND((GT34),6) -> 0 | GW34: 1 | GX34: =ROUND(HC34*I34,2) -> 0 | HA34: 0 | HB34: 0 | HC34: =GV34*GW34 -> 0 | HS34: 0 | IK34: 0
A35: 17 | B35: 1 | C35: =ROW(SmtRes!A14) -> 14 | D35: =ROW(EtalonRes!A16) -> 16 | E35: 4 | F35: 4.10-80-13 | G35: Аппараты приемные, устройства промежуточные на 1 луч / демонтаж адресной метки | H35: 1 ШТ. | I35: 31 | J35: 0 | K35: 31 | O35: =ROUND(CP35,2) -> 10592.44 | P35: =ROUND((ROUND((AC35*AW35*I35),2)*BC35),2) -> 0 | Q35: =(ROUND((ROUND(((((ET35*1.2)*0.3))*AV35*I35),2)*BB35),2)+ROUND((ROUND(((AE35-(((EU35*1.2)*0.3)))*AV35*I35),2)*BS35),2)) -> 11.6 | R35: =(ROUND((ROUND(((((EU35*1.2)*0.3))*AV35*I35),2)*BS35),2)+ROUND((ROUND(((AE35-(((EU35*1.2)*0.3)))*AV35*I35),2)*BS35),2)) -> 6.76 | S35: =ROUND((ROUND((AF35*AV35*I35),2)*BA35),2) -> 10580.84 | T35: =ROUND(CU35*I35,2) -> 0 | U35: =CV35*I35 -> 14.021424 | V35: =CW35*I35 -> 0 | W35: =ROUND(CX35*I35,2) -> 0 | X35: =(ROUND((((S35+ROUND((ROUND(((((EU35*1.2)*0.3))*AV35*I35),2)*BS35),2))*AT35)/100),2)+ROUND(((ROUND((ROUND(((AE35-(((EU35*1.2)*0.3)))*AV35*I35),2)*BS35),2)*AT35)/100),2)) -> 9528.84 | Y35: =(ROUND((((S35+ROUND((ROUND(((((EU35*1.2)*0.3))*AV35*I35),2)*BS35),2))*AU35)/100),2)+ROUND(((ROUND((ROUND(((AE35-(((EU35*1.2)*0.3)))*AV35*I35),2)*BS35),2)*AU35)/100),2)) -> 4870.3 | AA35: 55915258 | AB35: =ROUND((AC35+AD35+AF35),6) -> 5.8032 | AC35: =ROUND((((ES35*1)*0)),6) -> 0 | AD35: =ROUND((((((ET35*1.2)*0.3))-(((EU35*1.2)*0.3)))+AE35),6) -> 0.018 | AE35: =ROUND((((EU35*1.2)*0.3)),6) -> 0.0036 | AF35: =ROUND((((EV35*1.2)*0.3)),6) -> 5.7852 | AG35: =ROUND((AP35),6) -> 0 | AH35: =(((EW35*1.2)*0.3)) -> 0.432 | AI35: =(((EX35*1.2)*0.3)) -> 0 | AJ35: =(AS35) -> 0 | AK35: 18.08 | AL35: 1.96 | AM35: 0.05 | AN35: 0.01 | AO35: 16.07 | AP35: 0 | AQ35: 1.2 | AR35: 0 | AS35: 0 | AT35: 90 | AU35: 46 | AV35: 1.047 | AW35: 1 | AZ35: 1 | BA35: 56.35 | BB35: 20 | BC35: 9.84 | BH35: 0 | BI35: 2 | BJ35: ТСН-2001.4. Доп. 1-42. Сб. 10, т. 80, поз. 13 | BM35: 68 | BN35: 0 | BO35: 4.10-80-13 | BP35: 1 | BQ35: 40 | BR35: 0 | BS35: 56.35 | BT35: 1 | BU35: 1 | BV35: 1 | BW35: 1 | BX35: 1 | BZ35: 90 | CA35: 46 | CE35: 1566 | CF35: 0 | CG35: 0 | CM35: 0 | CN35: Поправка: Гл.12.Прил.8.п.8. 3_12.00.01.11.001 Наименование: При наличии напряженных и стесненных условий производства работ (стесненность, сложность складирования и транспортной логистики и т.п.) для объектов, расположенных в пределах круговой магистральной системы улиц "Садовое кольцо" города Москвы Поправка: Гл.4.Прил.2.2.п.2.2.29_04.00.01.35.003 Наименование: При демонтаже оборудования, предназначенного в лом | CO35: 0 | CP35: =(P35+Q35+S35) -> 10592.44 | CQ35: =ROUND((ROUND((AC35*AW35*1),2)*BC35),2) -> 0 | CR35: =(ROUND((ROUND(((((ET35*1.2)*0.3))*AV35*1),2)*BB35),2)+ROUND((ROUND(((AE35-(((EU35*1.2)*0.3)))*AV35*1),2)*BS35),2)) -> 0.4 | CS35: =(ROUND((ROUND(((((EU35*1.2)*0.3))*AV35*1),2)*BS35),2)+ROUND((ROUND(((AE35-(((EU35*1.2)*0.3)))*AV35*1),2)*BS35),2)) -> 0 | CT35: =ROUND((ROUND((AF35*AV35*1),2)*BA35),2) -> 341.48 | CU35: =AG35 -> 0 | CV35: =(AH35*AV35) -> 0.452304 | CW35: =AI35 -> 0 | CX35: =AJ35 -> 0 | CY35: =(ROUND((((S35+ROUND((ROUND(((((EU35*1.2)*0.3))*AV35*1),2)*BS35),2))*AT35)/100),2)+ROUND(((ROUND((ROUND(((AE35-(((EU35*1.2)*0.3)))*AV35*1),2)*BS35),2)*AT35)/100),2)) -> 9522.76 | CZ35: =(ROUND((((S35+ROUND((ROUND(((((EU35*1.2)*0.3))*AV35*1),2)*BS35),2))*AU35)/100),2)+ROUND(((ROUND((ROUND(((AE35-(((EU35*1.2)*0.3)))*AV35*1),2)*BS35),2)*AU35)/100),2)) -> 4867.19 | DB35: 15 | DD35: *1)*0 | DE35: *1,2)*0,3 | DF35: *1,2)*0,3 | DG35: *1,2)*0,3 | DI35: *1,2)*0,3 | DJ35: *1,2)*0,3 | DN35: 0 | DO35: 0 | DP35: 1 | DQ35: 1 | DU35: 1013 | DV35: 1 ШТ. | DW35: 1 ШТ. | DX35: 1 | EE35: 55393700 | EF35: 40 | EG35: Монтаж оборудования | EH35: 0 | EJ35: 2 | EK35: 68 | EL35: ТСН-2001.4-10. Прокладка и монтаж сетей связи | EM35: ТСН-2001.4-10-1 | EO35: Поправка: Гл.12.Прил.8.п.8. 3_12.00.01.11.001 Поправка: Гл.4.Прил.2.2.п.2.2.29_04.00.01.35.003 | EQ35: 0 | ER35: 18.08 | ES35: 1.96 | ET35: 0.05 | EU35: 0.01 | EV35: 16.07 | EW35: 1.2 | EX35: 0 | EY35: 0 | FQ35: 0 | FR35: 0 | FS35: 0 | FX35: 90 | FY35: 46 | GD35: 1 | GF35: -808829180 | GG35: 2 | GH35: 1 | GI35: 2 | GJ35: 0 | GK35: 0 | GL35: =ROUND(IF(AND(BH35=3,BI35=3,FS35<>0),P35,0),2) -> 0 | GM35: =ROUND(O35+X35+Y35,2)+GX35 -> 24991.58 | GN35: =IF(OR(BI35=0,BI35=1),GM35-GX35,0) -> 0 | GO35: =IF(BI35=2,GM35-GX35,0) -> 24991.58 | GP35: =IF(BI35=4,GM35-GX35,0) -> 0 | GR35: 0 | GS35: 3 | GT35: 0 | GV35: =ROUND((GT35),6) -> 0 | GW35: 1 | GX35: =ROUND(HC35*I35,2) -> 0 | HA35: 0 | HB35: 0 | HC35: =GV35*GW35 -> 0 | HS35: 0 | IK35: 0
A36: 17 | B36: 1 | C36: =ROW(SmtRes!A15) -> 15 | D36: =ROW(EtalonRes!A17) -> 17 | E36: 5 | F36: 4.10-80-9 | G36: Аппараты приемные, приборы приемно-контрольные объектовые на 2 луча / демонтаж контроллера охранно-пожарного | H36: 1 ШТ. | I36: 1 | J36: 0 | K36: 1 | O36: =ROUND(CP36,2) -> 29.17 | P36: =ROUND((ROUND((AC36*AW36*I36),2)*BC36),2) -> 0 | Q36: =(ROUND((ROUND(((((ET36*1.2)*0.3))*AV36*I36),2)*BB36),2)+ROUND((ROUND(((AE36-(((EU36*1.2)*0.3)))*AV36*I36),2)*BS36),2)) -> 0.02 | R36: =(ROUND((ROUND(((((EU36*1.2)*0.3))*AV36*I36),2)*BS36),2)+ROUND((ROUND(((AE36-(((EU36*1.2)*0.3)))*AV36*I36),2)*BS36),2)) -> 0 | S36: =ROUND((ROUND((AF36*AV36*I36),2)*BA36),2) -> 29.15 | T36: =ROUND(CU36*I36,2) -> 0 | U36: =CV36*I36 -> 2.148444 | V36: =CW36*I36 -> 0 | W36: =ROUND(CX36*I36,2) -> 0 | X36: =(ROUND((((S36+ROUND((ROUND(((((EU36*1.2)*0.3))*AV36*I36),2)*BS36),2))*AT36)/100),2)+ROUND(((ROUND((ROUND(((AE36-(((EU36*1.2)*0.3)))*AV36*I36),2)*BS36),2)*AT36)/100),2)) -> 26.24 | Y36: =(ROUND((((S36+ROUND((ROUND(((((EU36*1.2)*0.3))*AV36*I36),2)*BS36),2))*AU36)/100),2)+ROUND(((ROUND((ROUND(((AE36-(((EU36*1.2)*0.3)))*AV36*I36),2)*BS36),2)*AU36)/100),2)) -> 13.41 | AA36: 55915256 | AB36: =ROUND((AC36+AD36+AF36),6) -> 27.864 | AC36: =ROUND((((ES36*1)*0)),6) -> 0 | AD36: =ROUND((((((ET36*1.2)*0.3))-(((EU36*1.2)*0.3)))+AE36),6) -> 0.018 | AE36: =ROUND((((EU36*1.2)*0.3)),6) -> 0.0036 | AF36: =ROUND((((EV36*1.2)*0.3)),6) -> 27.846 | AG36: =ROUND((AP36),6) -> 0 | AH36: =(((EW36*1.2)*0.3)) -> 2.052 | AI36: =(((EX36*1.2)*0.3)) -> 0 | AJ36: =(AS36) -> 0 | AK36: 82.23 | AL36: 4.83 | AM36: 0.05 | AN36: 0.01 | AO36: 77.35 | AP36: 0 | AQ36: 5.7 | AR36: 0 | AS36: 0 | AT36: 90 | AU36: 46 | AV36: 1.047 | AW36: 1 | AZ36: 1 | BA36: 1 | BB36: 1 | BC36: 1 | BH36: 0 | BI36: 2 | BJ36: ТСН-2001.4. Доп. 1-42. Сб. 10, т. 80, поз. 9 | BM36: 68 | BN36: 0 | BO36: 4.10-80-9 | BP36: 1 | BQ36: 40 | BR36: 0 | BS36: 1 | BT36: 1 | BU36: 1 | BV36: 1 | BW36: 1 | BX36: 1 | BZ36: 90 | CA36: 46 | CE36: 1566 | CF36: 0 | CG36: 0 | CM36: 0 | CN36: Поправка: Гл.12.Прил.8.п.8. 3_12.00.01.11.001 Наименование: При наличии напряженных и стесненных условий производства работ (стесненность, сложность складирования и транспортной логистики и т.п.) для объектов, расположенных в пределах круговой магистральной системы улиц "Садовое кольцо" города Москвы Поправка: Гл.4.Прил.2.2.п.2.2.29_04.00.01.35.003 Наименование: При демонтаже оборудования, предназначенного в лом | CO36: 0 | CP36: =(P36+Q36+S36) -> 29.17 | CQ36: =ROUND((ROUND((AC36*AW36*1),2)*BC36),2) -> 0 | CR36: =(ROUND((ROUND(((((ET36*1.2)*0.3))*AV36*1),2)*BB36),2)+ROUND((ROUND(((AE36-(((EU36*1.2)*0.3)))*AV36*1),2)*BS36),2)) -> 0.02 | CS36: =(ROUND((ROUND(((((EU36*1.2)*0.3))*AV36*1),2)*BS36),2)+ROUND((ROUND(((AE36-(((EU36*1.2)*0.3)))*AV36*1),2)*BS36),2)) -> 0 | CT36: =ROUND((ROUND((AF36*AV36*1),2)*BA36),2) -> 29.15 | CU36: =AG36 -> 0 | CV36: =(AH36*AV36) -> 2.148444 | CW36: =AI36 -> 0 | CX36: =AJ36 -> 0 | CY36: =(ROUND((((S36+ROUND((ROUND(((((EU36*1.2)*0.3))*AV36*1),2)*BS36),2))*AT36)/100),2)+ROUND(((ROUND((ROUND(((AE36-(((EU36*1.2)*0.3)))*AV36*1),2)*BS36),2)*AT36)/100),2)) -> 26.24 | CZ36: =(ROUND((((S36+ROUND((ROUND(((((EU36*1.2)*0.3))*AV36*1),2)*BS36),2))*AU36)/100),2)+ROUND(((ROUND((ROUND(((AE36-(((EU36*1.2)*0.3)))*AV36*1),2)*BS36),2)*AU36)/100),2)) -> 13.41 | DB36: 17 | DD36: *1)*0 | DE36: *1,2)*0,3 | DF36: *1,2)*0,3 | DG36: *1,2)*0,3 | DI36: *1,2)*0,3 | DJ36: *1,2)*0,3 | DN36: 0 | DO36: 0 | DP36: 1 | DQ36: 1 | DU36: 1013 | DV36: 1 ШТ. | DW36: 1 ШТ. | DX36: 1 | EE36: 55393700 | EF36: 40 | EG36: Монтаж оборудования | EH36: 0 | EJ36: 2 | EK36: 68 | EL36: ТСН-2001.4-10. Прокладка и монтаж сетей связи | EM36: ТСН-2001.4-10-1 | EO36: Поправка: Гл.12.Прил.8.п.8. 3_12.00.01.11.001 Поправка: Гл.4.Прил.2.2.п.2.2.29_04.00.01.35.003 | EQ36: 0 | ER36: 82.23 | ES36: 4.83 | ET36: 0.05 | EU36: 0.01 | EV36: 77.35 | EW36: 5.7 | EX36: 0 | EY36: 0 | FQ36: 0 | FR36: 0 | FS36: 0 | FX36: 90 | FY36: 46 | GD36: 1 | GF36: -2001728889 | GG36: 2 | GH36: 1 | GI36: 2 | GJ36: 0 | GK36: 0 | GL36: =ROUND(IF(AND(BH36=3,BI36=3,FS36<>0),P36,0),2) -> 0 | GM36: =ROUND(O36+X36+Y36,2)+GX36 -> 68.82 | GN36: =IF(OR(BI36=0,BI36=1),GM36-GX36,0) -> 0 | GO36: =IF(BI36=2,GM36-GX36,0) -> 68.82 | GP36: =IF(BI36=4,GM36-GX36,0) -> 0 | GR36: 0 | GS36: 3 | GT36: 0 | GV36: =ROUND((GT36),6) -> 0 | GW36: 1 | GX36: =ROUND(HC36*I36,2) -> 0 | HA36: 0 | HB36: 0 | HC36: =GV36*GW36 -> 0 | HS36: 0 | IK36: 0
A37: 17 | B37: 1 | C37: =ROW(SmtRes!A16) -> 16 | D37: =ROW(EtalonRes!A18) -> 18 | E37: 5 | F37: 4.10-80-9 | G37: Аппараты приемные, приборы приемно-контрольные объектовые на 2 луча / демонтаж контроллера охранно-пожарного | H37: 1 ШТ. | I37: 1 | J37: 0 | K37: 1 | O37: =ROUND(CP37,2) -> 1643 | P37: =ROUND((ROUND((AC37*AW37*I37),2)*BC37),2) -> 0 | Q37: =(ROUND((ROUND(((((ET37*1.2)*0.3))*AV37*I37),2)*BB37),2)+ROUND((ROUND(((AE37-(((EU37*1.2)*0.3)))*AV37*I37),2)*BS37),2)) -> 0.4 | R37: =(ROUND((ROUND(((((EU37*1.2)*0.3))*AV37*I37),2)*BS37),2)+ROUND((ROUND(((AE37-(((EU37*1.2)*0.3)))*AV37*I37),2)*BS37),2)) -> 0 | S37: =ROUND((ROUND((AF37*AV37*I37),2)*BA37),2) -> 1642.6 | T37: =ROUND(CU37*I37,2) -> 0 | U37: =CV37*I37 -> 2.148444 | V37: =CW37*I37 -> 0 | W37: =ROUND(CX37*I37,2) -> 0 | X37: =(ROUND((((S37+ROUND((ROUND(((((EU37*1.2)*0.3))*AV37*I37),2)*BS37),2))*AT37)/100),2)+ROUND(((ROUND((ROUND(((AE37-(((EU37*1.2)*0.3)))*AV37*I37),2)*BS37),2)*AT37)/100),2)) -> 1478.34 | Y37: =(ROUND((((S37+ROUND((ROUND(((((EU37*1.2)*0.3))*AV37*I37),2)*BS37),2))*AU37)/100),2)+ROUND(((ROUND((ROUND(((AE37-(((EU37*1.2)*0.3)))*AV37*I37),2)*BS37),2)*AU37)/100),2)) -> 755.6 | AA37: 55915258 | AB37: =ROUND((AC37+AD37+AF37),6) -> 27.864 | AC37: =ROUND((((ES37*1)*0)),6) -> 0 | AD37: =ROUND((((((ET37*1.2)*0.3))-(((EU37*1.2)*0.3)))+AE37),6) -> 0.018 | AE37: =ROUND((((EU37*1.2)*0.3)),6) -> 0.0036 | AF37: =ROUND((((EV37*1.2)*0.3)),6) -> 27.846 | AG37: =ROUND((AP37),6) -> 0 | AH37: =(((EW37*1.2)*0.3)) -> 2.052 | AI37: =(((EX37*1.2)*0.3)) -> 0 | AJ37: =(AS37) -> 0 | AK37: 82.23 | AL37: 4.83 | AM37: 0.05 | AN37: 0.01 | AO37: 77.35 | AP37: 0 | AQ37: 5.7 | AR37: 0 | AS37: 0 | AT37: 90 | AU37: 46 | AV37: 1.047 | AW37: 1 | AZ37: 1 | BA37: 56.35 | BB37: 20 | BC37: 9.84 | BH37: 0 | BI37: 2 | BJ37: ТСН-2001.4. Доп. 1-42. Сб. 10, т. 80, поз. 9 | BM37: 68 | BN37: 0 | BO37: 4.10-80-9 | BP37: 1 | BQ37: 40 | BR37: 0 | BS37: 56.35 | BT37: 1 | BU37: 1 | BV37: 1 | BW37: 1 | BX37: 1 | BZ37: 90 | CA37: 46 | CE37: 1566 | CF37: 0 | CG37: 0 | CM37: 0 | CN37: Поправка: Гл.12.Прил.8.п.8. 3_12.00.01.11.001 Наименование: При наличии напряженных и стесненных условий производства работ (стесненность, сложность складирования и транспортной логистики и т.п.) для объектов, расположенных в пределах круговой магистральной системы улиц "Садовое кольцо" города Москвы Поправка: Гл.4.Прил.2.2.п.2.2.29_04.00.01.35.003 Наименование: При демонтаже оборудования, предназначенного в лом | CO37: 0 | CP37: =(P37+Q37+S37) -> 1643 | CQ37: =ROUND((ROUND((AC37*AW37*1),2)*BC37),2) -> 0 | CR37: =(ROUND((ROUND(((((ET37*1.2)*0.3))*AV37*1),2)*BB37),2)+ROUND((ROUND(((AE37-(((EU37*1.2)*0.3)))*AV37*1),2)*BS37),2)) -> 0.4 | CS37: =(ROUND((ROUND(((((EU37*1.2)*0.3))*AV37*1),2)*BS37),2)+ROUND((ROUND(((AE37-(((EU37*1.2)*0.3)))*AV37*1),2)*BS37),2)) -> 0 | CT37: =ROUND((ROUND((AF37*AV37*1),2)*BA37),2) -> 1642.6 | CU37: =AG37 -> 0 | CV37: =(AH37*AV37) -> 2.148444 | CW37: =AI37 -> 0 | CX37: =AJ37 -> 0 | CY37: =(ROUND((((S37+ROUND((ROUND(((((EU37*1.2)*0.3))*AV37*1),2)*BS37),2))*AT37)/100),2)+ROUND(((ROUND((ROUND(((AE37-(((EU37*1.2)*0.3)))*AV37*1),2)*BS37),2)*AT37)/100),2)) -> 1478.34 | CZ37: =(ROUND((((S37+ROUND((ROUND(((((EU37*1.2)*0.3))*AV37*1),2)*BS37),2))*AU37)/100),2)+ROUND(((ROUND((ROUND(((AE37-(((EU37*1.2)*0.3)))*AV37*1),2)*BS37),2)*AU37)/100),2)) -> 755.6 | DB37: 19 | DD37: *1)*0 | DE37: *1,2)*0,3 | DF37: *1,2)*0,3 | DG37: *1,2)*0,3 | DI37: *1,2)*0,3 | DJ37: *1,2)*0,3 | DN37: 0 | DO37: 0 | DP37: 1 | DQ37: 1 | DU37: 1013 | DV37: 1 ШТ. | DW37: 1 ШТ. | DX37: 1 | EE37: 55393700 | EF37: 40 | EG37: Монтаж оборудования | EH37: 0 | EJ37: 2 | EK37: 68 | EL37: ТСН-2001.4-10. Прокладка и монтаж сетей связи | EM37: ТСН-2001.4-10-1 | EO37: Поправка: Гл.12.Прил.8.п.8. 3_12.00.01.11.001 Поправка: Гл.4.Прил.2.2.п.2.2.29_04.00.01.35.003 | EQ37: 0 | ER37: 82.23 | ES37: 4.83 | ET37: 0.05 | EU37: 0.01 | EV37: 77.35 | EW37: 5.7 | EX37: 0 | EY37: 0 | FQ37: 0 | FR37: 0 | FS37: 0 | FX37: 90 | FY37: 46 | GD37: 1 | GF37: -2001728889 | GG37: 2 | GH37: 1 | GI37: 2 | GJ37: 0 | GK37: 0 | GL37: =ROUND(IF(AND(BH37=3,BI37=3,FS37<>0),P37,0),2) -> 0 | GM37: =ROUND(O37+X37+Y37,2)+GX37 -> 3876.94 | GN37: =IF(OR(BI37=0,BI37=1),GM37-GX37,0) -> 0 | GO37: =IF(BI37=2,GM37-GX37,0) -> 3876.94 | GP37: =IF(BI37=4,GM37-GX37,0) -> 0 | GR37: 0 | GS37: 3 | GT37: 0 | GV37: =ROUND((GT37),6) -> 0 | GW37: 1 | GX37: =ROUND(HC37*I37,2) -> 0 | HA37: 0 | HB37: 0 | HC37: =GV37*GW37 -> 0 | HS37: 0 | IK37: 0
A38: 17 | B38: 1 | C38: =ROW(SmtRes!A17) -> 17 | D38: =ROW(EtalonRes!A19) -> 19 | E38: 6 | F38: 4.10-80-5 | G38: Аппараты приемные, приборы ПС приемно-контрольные, пусковые, прибор ПС на 1 луч / демонтаж устройства охранной сигнализации | H38: 1 ШТ. | I38: 1 | J38: 0 | K38: 1 | O38: =ROUND(CP38,2) -> 8.7 | P38: =ROUND((ROUND((AC38*AW38*I38),2)*BC38),2) -> 0 | Q38: =(ROUND((ROUND(((((ET38*1.2)*0.3))*AV38*I38),2)*BB38),2)+ROUND((ROUND(((AE38-(((EU38*1.2)*0.3)))*AV38*I38),2)*BS38),2)) -> 0.02 | R38: =(ROUND((ROUND(((((EU38*1.2)*0.3))*AV38*I38),2)*BS38),2)+ROUND((ROUND(((AE38-(((EU38*1.2)*0.3)))*AV38*I38),2)*BS38),2)) -> 0 | S38: =ROUND((ROUND((AF38*AV38*I38),2)*BA38),2) -> 8.68 | T38: =ROUND(CU38*I38,2) -> 0 | U38: =CV38*I38 -> 0.678456 | V38: =CW38*I38 -> 0 | W38: =ROUND(CX38*I38,2) -> 0 | X38: =(ROUND((((S38+ROUND((ROUND(((((EU38*1.2)*0.3))*AV38*I38),2)*BS38),2))*AT38)/100),2)+ROUND(((ROUND((ROUND(((AE38-(((EU38*1.2)*0.3)))*AV38*I38),2)*BS38),2)*AT38)/100),2)) -> 7.81 | Y38: =(ROUND((((S38+ROUND((ROUND(((((EU38*1.2)*0.3))*AV38*I38),2)*BS38),2))*AU38)/100),2)+ROUND(((ROUND((ROUND(((AE38-(((EU38*1.2)*0.3)))*AV38*I38),2)*BS38),2)*AU38)/100),2)) -> 3.99 | AA38: 55915256 | AB38: =ROUND((AC38+AD38+AF38),6) -> 8.3124 | AC38: =ROUND((((ES38*1)*0)),6) -> 0 | AD38: =ROUND((((((ET38*1.2)*0.3))-(((EU38*1.2)*0.3)))+AE38),6) -> 0.018 | AE38: =ROUND((((EU38*1.2)*0.3)),6) -> 0.0036 | AF38: =ROUND((((EV38*1.2)*0.3)),6) -> 8.2944 | AG38: =ROUND((AP38),6) -> 0 | AH38: =(((EW38*1.2)*0.3)) -> 0.648 | AI38: =(((EX38*1.2)*0.3)) -> 0 | AJ38: =(AS38) -> 0 | AK38: 26.52 | AL38: 3.43 | AM38: 0.05 | AN38: 0.01 | AO38: 23.04 | AP38: 0 | AQ38: 1.8 | AR38: 0 | AS38: 0 | AT38: 90 | AU38: 46 | AV38: 1.047 | AW38: 1 | AZ38: 1 | BA38: 1 | BB38: 1 | BC38: 1 | BH38: 0 | BI38: 2 | BJ38: ТСН-2001.4. Доп. 1-42. Сб. 10, т. 80, поз. 5 | BM38: 68 | BN38: 0 | BO38: 4.10-80-5 | BP38: 1 | BQ38: 40 | BR38: 0 | BS38: 1 | BT38: 1 | BU38: 1 | BV38: 1 | BW38: 1 | BX38: 1 | BZ38: 90 | CA38: 46 | CE38: 1566 | CF38: 0 | CG38: 0 | CM38: 0 | CN38: Поправка: Гл.12.Прил.8.п.8. 3_12.00.01.11.001 Наименование: При наличии напряженных и стесненных условий производства работ (стесненность, сложность складирования и транспортной логистики и т.п.) для объектов, расположенных в пределах круговой магистральной системы улиц "Садовое кольцо" города Москвы Поправка: Гл.4.Прил.2.2.п.2.2.29_04.00.01.35.003 Наименование: При демонтаже оборудования, предназначенного в лом | CO38: 0 | CP38: =(P38+Q38+S38) -> 8.7 | CQ38: =ROUND((ROUND((AC38*AW38*1),2)*BC38),2) -> 0 | CR38: =(ROUND((ROUND(((((ET38*1.2)*0.3))*AV38*1),2)*BB38),2)+ROUND((ROUND(((AE38-(((EU38*1.2)*0.3)))*AV38*1),2)*BS38),2)) -> 0.02 | CS38: =(ROUND((ROUND(((((EU38*1.2)*0.3))*AV38*1),2)*BS38),2)+ROUND((ROUND(((AE38-(((EU38*1.2)*0.3)))*AV38*1),2)*BS38),2)) -> 0 | CT38: =ROUND((ROUND((AF38*AV38*1),2)*BA38),2) -> 8.68 | CU38: =AG38 -> 0 | CV38: =(AH38*AV38) -> 0.678456 | CW38: =AI38 -> 0 | CX38: =AJ38 -> 0 | CY38: =(ROUND((((S38+ROUND((ROUND(((((EU38*1.2)*0.3))*AV38*1),2)*BS38),2))*AT38)/100),2)+ROUND(((ROUND((ROUND(((AE38-(((EU38*1.2)*0.3)))*AV38*1),2)*BS38),2)*AT38)/100),2)) -> 7.81 | CZ38: =(ROUND((((S38+ROUND((ROUND(((((EU38*1.2)*0.3))*AV38*1),2)*BS38),2))*AU38)/100),2)+ROUND(((ROUND((ROUND(((AE38-(((EU38*1.2)*0.3)))*AV38*1),2)*BS38),2)*AU38)/100),2)) -> 3.99 | DB38: 21 | DD38: *1)*0 | DE38: *1,2)*0,3 | DF38: *1,2)*0,3 | DG38: *1,2)*0,3 | DI38: *1,2)*0,3 | DJ38: *1,2)*0,3 | DN38: 0 | DO38: 0 | DP38: 1 | DQ38: 1 | DU38: 1013 | DV38: 1 ШТ. | DW38: 1 ШТ. | DX38: 1 | EE38: 55393700 | EF38: 40 | EG38: Монтаж оборудования | EH38: 0 | EJ38: 2 | EK38: 68 | EL38: ТСН-2001.4-10. Прокладка и монтаж сетей связи | EM38: ТСН-2001.4-10-1 | EO38: Поправка: Гл.12.Прил.8.п.8. 3_12.00.01.11.001 Поправка: Гл.4.Прил.2.2.п.2.2.29_04.00.01.35.003 | EQ38: 0 | ER38: 26.52 | ES38: 3.43 | ET38: 0.05 | EU38: 0.01 | EV38: 23.04 | EW38: 1.8 | EX38: 0 | EY38: 0 | FQ38: 0 | FR38: 0 | FS38: 0 | FX38: 90 | FY38: 46 | GD38: 1 | GF38: 1532692704 | GG38: 2 | GH38: 1 | GI38: 2 | GJ38: 0 | GK38: 0 | GL38: =ROUND(IF(AND(BH38=3,BI38=3,FS38<>0),P38,0),2) -> 0 | GM38: =ROUND(O38+X38+Y38,2)+GX38 -> 20.5 | GN38: =IF(OR(BI38=0,BI38=1),GM38-GX38,0) -> 0 | GO38: =IF(BI38=2,GM38-GX38,0) -> 20.5 | GP38: =IF(BI38=4,GM38-GX38,0) -> 0 | GR38: 0 | GS38: 3 | GT38: 0 | GV38: =ROUND((GT38),6) -> 0 | GW38: 1 | GX38: =ROUND(HC38*I38,2) -> 0 | HA38: 0 | HB38: 0 | HC38: =GV38*GW38 -> 0 | HS38: 0 | IK38: 0
