Workbook

Sheet 02-01-21
A1: =Source!B1 -> Smeta.RU (495) 974-1589
J2: Форма № 4б
A3: =Source!G4 -> Капитальный ремонт здания Государственного бюджетного общеобразовательного учреждения города Москвы «Школа №1574», расположенного по адресу: г. Москва, Старопименовский переулок, д. 5. 1 этап | AP3: Капитальный ремонт здания Государственного бюджетного общеобразовательного учреждения города Москвы «Школа №1574», расположенного по адресу: г. Москва, пер. Старопименовский, д. 5. Спринклерное пожаротушение
A4: (наименование стройки и/или объекта)
A6: =CONCATENATE( "ЛОКАЛЬНАЯ СМЕТА № ",IF(Source!F20<>"Новая локальная смета", Source!F20, "")) -> ЛОКАЛЬНАЯ СМЕТА № 02-01-21
A8: =IF(Source!G20<>"Новая локальная смета", Source!G20, "") -> Спринклерное пожаротушение.
A9: (наименование работ и затрат)
A11: =CONCATENATE( "Основание: чертежи № ", Source!J20) -> Основание: чертежи № 2024-00375-01-0-ИОС3.
I13: В базисном уровне цен | J13: В текущем уровне цен
E14: Сметная стоимость | I14: =I15+I16+I17+I18 -> 904.56 | J14: =J15+J16+J17+J18 -> 19336.73 | K14: тыс.руб.
E15: Строительные работы | I15: =ROUND((Source!F303)/1000, 2) -> 30.02 | J15: =ROUND((Source!P303)/1000, 2) -> 993.63 | K15: тыс.руб.
E16: Работы по монтажу оборудования | I16: =ROUND((Source!F304)/1000, 2) -> 636.59 | J16: =ROUND((Source!P304)/1000, 2) -> 16451.1 | K16: тыс.руб.
E17: Оборудование | I17: =ROUND((Source!F295)/1000, 2) -> 237.95 | J17: =ROUND((Source!P295)/1000, 2) -> 1892 | K17: тыс.руб.
E18: Прочие работы и затраты | I18: =ROUND((Source!F305+Source!F306)/1000, 2) -> 0 | J18: =ROUND((Source!P305+Source!P306)/1000, 2) -> 0 | K18: тыс.руб.
E19: Средства на оплату труда | I19: =(Source!F301+ Source!F300)/1000 -> 97.7491 | J19: =((Source!P301 + Source!P300)/1000) -> 5508.1618 | K19: тыс.руб.
E20: Затраты труда | I20: =Source!F308 -> 7442.2286 | K20: чел.-ч.
E21: Кроме того:
E22: Возврат материалов | I22: =SUM(Y28:Y586)/1000 -> 0 | J22: =SUM(Z28:Z586)/1000 -> 0 | K22: тыс.руб.
A24: Составлен(а) по ТСН-2001 с учетом Дополнения №: 81
A25: № и период сборника коэффициентов (индексов) пересчета: Коэффициенты к ТСН-2001 МГЭ Дополнение 81, ремонт №219/81 I квартал 2026 года и Коэффициенты к ТСН-2001.13-2 Дополнение 47 №64/47 I квартал 2026 года | AP25: № и период сборника коэффициентов (индексов) пересчета: Коэффициенты к ТСН-2001 МГЭ Дополнение 81, ремонт №219/81 I квартал 2026 года и Коэффициенты к ТСН-2001.13-2 Дополнение 47 №64/47 I квартал 2026 года
A26: № п/п | B26: Шифр расценки и коды ресурсов | C26: Наименование работ и затрат | D26: Ед. изм. | E26: Кол-во единиц | F26: Цена на ед. изм., руб. | G26: Попра- вочные коэффи- циенты | H26: Коэффи- циенты зимних удорожа- ний | I26: Всего в ценах на январь 2000 года, руб. | J26: Коэффи- циенты (индек- сы) пере- счета, нормы НР и СП | K26: ВСЕГО затрат в текущем уровне цен, руб.
A27: 1 | B27: 2 | C27: 3 | D27: 4 | E27: 5 | F27: 6 | G27: 7 | H27: 8 | I27: 9 | J27: 10 | K27: 11 | L27: цена за ед с ндс
A29: =CONCATENATE("Раздел: ",IF(Source!G24<>"Новый раздел", Source!G24, "")) -> Раздел: Насосная установка.
A30: 1 | B30: =Source!F28 -> 4.7-21-3 | C30: Монтаж насосного агрегата лопастного центробежного одноступенчатого, многоступенчатого объемного, вихревого, поршневого, приводного, роторного на общей фундаментной плите или моноблочный массой 0,425 т | D30: =Source!H28 -> 1 ШТ. | E30: =Source!I28 -> 2 | Q30: =Source!X28 -> 694.1 | R30: =Source!X29 -> 39112.67 | S30: =Source!Y28 -> 358.49 | T30: =Source!Y29 -> 20201.05 | U30: =ROUND((175/100)*ROUND(Source!R28, 2), 2) -> 9.75 | V30: =ROUND((0/100)*ROUND(Source!R29, 2), 2) -> 0 | AC30: 0
C31: ЗП | F31: =Source!AO28 -> 394.24 | G31: 0,75*1,2 | H31: =Source!AV29 -> 1.067 | I31: =Source!S28 -> 757.18 | J31: =IF(Source!BA29<> 0, Source!BA29, 1) -> 56.35 | K31: =Source!S29 -> 42667.09
C32: ЭМ | F32: =Source!AM28 -> 42.08 | G32: 0,75*1,2 | H32: =Source!AV29 -> 1.067 | I32: =Source!Q28 -> 80.82 | J32: =IF(Source!BB29<> 0, Source!BB29, 1) -> 14.74 | K32: =Source!Q29 -> 1191.29
C33: в т.ч. ЗПМ | F33: =Source!AN28 -> 2.9 | G33: 0,75*1,2 | H33: =Source!AV29 -> 1.067 | I33: =Source!R28 -> 5.57 | J33: =IF(Source!BS29<> 0, Source!BS29, 1) -> 56.35 | K33: =Source!R29 -> 313.87
C34: МР | F34: =Source!AL28 -> 45.53 | G34: 0,75 | H34: =Source!AW29 -> 1.028 | I34: =Source!P28 -> 70.21 | J34: =IF(Source!BC29<> 0, Source!BC29, 1) -> 11.98 | K34: =Source!P29 -> 841.12
C35: НР от ФОТ | D35: % | E35: =Source!BZ29 -> 91 | I35: =SUM(Q30:Q34) -> 694.1 | J35: =Source!AT29 -> 91 | K35: =SUM(R30:R34) -> 39112.67
C36: СП от ФОТ | D36: % | E36: =Source!CA29 -> 47 | I36: =SUM(S30:S35) -> 358.49 | J36: =Source!AU29 -> 47 | K36: =SUM(T30:T35) -> 20201.05
C37: ЗТР | D37: чел-ч | E37: =Source!AQ28 -> 32 | G37: 0,75*1,2 | H37: =Source!AV29 -> 1.067 | I37: =Source!U28 -> 61.4592
C38: ВСЕГО работ по позиции: | H38: =I31+I32+I34+I35+I36+0-0-0 -> 1960.8 | J38: =K31+K32+K34+K35+K36+0-0-0 -> 104013.22
C39: ВСЕГО оборудование по позиции: | H39: =0+0 -> 0 | J39: =0+0 -> 0
C40: ВСЕГО по позиции: | H40: =I31+I32+I34+I35+I36+0 -> 1960.8 | J40: =K31+K32+K34+K35+K36+0 -> 104013.22 | O40: =I31+I32+I34+I35+I36+0 -> 1960.8 | P40: =K31+K32+K34+K35+K36+0 -> 104013.22
A42: 2 | B42: =Source!F30 -> 4.7-21-1 | C42: Монтаж насосного агрегата лопастного центробежного одноступенчатого, многоступенчатого объемного, вихревого, поршневого, приводного, роторного на общей фундаментной плите или моноблочный массой 0,064 т | D42: =Source!H30 -> 1 ШТ. | E42: =Source!I30 -> 1 | Q42: =Source!X30 -> 399.52 | R42: =Source!X31 -> 22512.8 | S42: =Source!Y30 -> 206.34 | T42: =Source!Y31 -> 11627.49 | U42: =ROUND((175/100)*ROUND(Source!R30, 2), 2) -> 0.86 | V42: =ROUND((0/100)*ROUND(Source!R31, 2), 2) -> 0 | AC42: 0
C43: ЗП | F43: =Source!AO30 -> 342.5 | G43: 1,2 | H43: =Source!AV31 -> 1.067 | I43: =Source!S30 -> 438.54 | J43: =IF(Source!BA31<> 0, Source!BA31, 1) -> 56.35 | K43: =Source!S31 -> 24711.73
C44: ЭМ | F44: =Source!AM30 -> 24.5 | G44: 1,2 | H44: =Source!AV31 -> 1.067 | I44: =Source!Q30 -> 31.37 | J44: =IF(Source!BB31<> 0, Source!BB31, 1) -> 13.34 | K44: =Source!Q31 -> 418.48
C45: в т.ч. ЗПМ | F45: =Source!AN30 -> 0.38 | G45: 1,2 | H45: =Source!AV31 -> 1.067 | I45: =Source!R30 -> 0.49 | J45: =IF(Source!BS31<> 0, Source!BS31, 1) -> 56.35 | K45: =Source!R31 -> 27.61
C46: МР | F46: =Source!AL30 -> 42.34 | H46: =Source!AW31 -> 1.028 | I46: =Source!P30 -> 43.53 | J46: =IF(Source!BC31<> 0, Source!BC31, 1) -> 11.66 | K46: =Source!P31 -> 507.56
C47: НР от ФОТ | D47: % | E47: =Source!BZ31 -> 91 | I47: =SUM(Q42:Q46) -> 399.52 | J47: =Source!AT31 -> 91 | K47: =SUM(R42:R46) -> 22512.8
...

Sheet Source
A1: 0 | B1: Smeta.RU (495) 974-1589 | D1: _PS_ | F1: 0 | G1: 0 | H1: 0 | I1: Smeta.RU | K1: 1 | L1: 74600 | M1: 10 | N1: 12 | O1: 1 | P1: 0 | Q1: 1
A4: 8 | B4: 1 | C4: -1 | G4: Капитальный ремонт здания Государственного бюджетного общеобразовательного учреждения города Москвы «Школа №1574», расположенного по адресу: г. Москва, Старопименовский переулок, д. 5. 1 этап | EC4: 0
A12: 1 | B12: 361 | C12: 0 | D12: =ROW(A319) -> 319 | E12: 0 | F12: Новый объект | G12: Спринклерное пожаротушение | I12: 0 | K12: 0 | L12: 0 | M12: 4098 | O12: 0 | P12: 0 | Q12: 0 | R12: 0 | S12: 0 | T12: 1 | V12: 0 | BB12: 0 | BH12: Сметные нормы списания | BI12: Коды ОКП для ТСН-2001 МГЭ Дополнение 81 | BJ12: 1 | BK12: 1 | BL12: 0 | BM12: 0 | BN12: 1 | BO12: 0 | BP12: 6 | BQ12: 2 | BR12: 1 | BS12: 1 | BT12: 0 | BU12: 0 | BV12: 0 | BW12: 0 | BX12: 0 | BY12: ТСН-2001 (МГЭ) Доп 81 - Новое строительство | BZ12: Типовой расчет для ТСН-2001 МГЭ, Дополнение 81, строительство | CA12: Территориальные сметные нормативы для Москвы ТСН-2001 (МГЭ), дополнение 81 | CB12: Территориальные сметные нормативы для Москвы ТСН-2001 (МГЭ), дополнение 81 | CC12: Территориальные сметные нормативы для Москвы ТСН-2001 (МГЭ), дополнение 81 | CD12: Территориальные сметные нормативы для Москвы ТСН-2001 (МГЭ), дополнение 81 | CE12: Поправки для ТСН-2001 от 07.04.2026 г. доп.81 | CF12: 0 | CG12: 0 | CH12: 8200 | CK12: 81 | CQ12: Территориальные сметные нормативы для Москвы (ТСН-2001) | CR12: ТЕР | CS12: 41660 | CT12: 1 | CU12: 81 | CY12: 0 | EC12: 0
A15: 15 | B15: 1
A18: 52 | B18: =B319 -> 361 | C18: =C319 -> 1 | D18: =D319 -> 12 | E18: =E319 -> 0 | F18: =F319 -> Новый объект | G18: =G319 -> Спринклерное пожаротушение | O18: =O319 -> 770382.96 | P18: =P319 -> 651102.71 | Q18: =Q319 -> 25446.09 | R18: =R319 -> 3914.94 | S18: =S319 -> 93834.16 | T18: =T319 -> 0 | U18: =U319 -> 7442.2286 | V18: =V319 -> 0 | ... GX18: =GX319 -> 0
A20: 3 | B20: 1 | D20: =ROW(A286) -> 286 | F20: 02-01-21 | G20: Спринклерное пожаротушение. | I20: 0 | J20: 2024-00375-01-0-ИОС3. | K20: -1 | L20: 02-01-21 | S20: 0 | T20: 0 | V20: 2 | BX20: 0 | CF20: 0 | CG20: 0
A22: 52 | B22: =B286 -> 1 | C22: =C286 -> 3 | D22: =D286 -> 20 | E22: =E286 -> 0 | F22: =F286 -> 02-01-21 | G22: =G286 -> Спринклерное пожаротушение. | O22: =O286 -> 770382.96 | P22: =P286 -> 651102.71 | Q22: =Q286 -> 25446.09 | R22: =R286 -> 3914.94 | S22: =S286 -> 93834.16 | T22: =T286 -> 0 | U22: =U286 -> 7442.2286 | V22: =V286 -> 0 | ... GX22: =GX286 -> 0
A24: 4 | B24: 1 | D24: =ROW(A139) -> 139 | F24: Новый раздел | G24: Насосная установка. | I24: 0 | K24: 0 | S24: 0 | T24: 0 | V24: 2 | BX24: 0 | CJ24: 0
A26: 52 | B26: =B139 -> 1 | C26: =C139 -> 4 | D26: =D139 -> 24 | E26: =E139 -> 0 | F26: =F139 -> Новый раздел | G26: =G139 -> Насосная установка. | O26: =O139 -> 315114.06 | P26: =P139 -> 300967.81 | Q26: =Q139 -> 2307.81 | R26: =R139 -> 330.58 | S26: =S139 -> 11838.44 | T26: =T139 -> 0 | U26: =U139 -> 925.57626 | V26: =V139 -> 0 | ... GX26: =GX139 -> 0
A28: 17 | B28: 1 | C28: =ROW(SmtRes!A10) -> 10 | D28: =ROW(EtalonRes!A11) -> 11 | E28: 1 | F28: 4.7-21-3 | G28: Монтаж насосного агрегата лопастного центробежного одноступенчатого, многоступенчатого объемного, вихревого, поршневого, приводного, роторного на общей фундаментной плите или моноблочный массой 0,425 т | H28: 1 ШТ. | I28: 2 | J28: 0 | K28: 2 | O28: =ROUND(CP28,2) -> 908.21 | P28: =ROUND((ROUND((AC28*AW28*I28),2)*BC28),2) -> 70.21 | Q28: =(ROUND((ROUND(((((ET28*0.75)*1.2))*AV28*I28),2)*BB28),2)+ROUND((ROUND(((AE28-(((EU28*0.75)*1.2)))*AV28*I28),2)*BS28),2)) -> 80.82 | R28: =(ROUND((ROUND(((((EU28*0.75)*1.2))*AV28*I28),2)*BS28),2)+ROUND((ROUND(((AE28-(((EU28*0.75)*1.2)))*AV28*I28),2)*BS28),2)) -> 5.57 | S28: =ROUND((ROUND((AF28*AV28*I28),2)*BA28),2) -> 757.18 | T28: =ROUND(CU28*I28,2) -> 0 | U28: =CV28*I28 -> 61.4592 | V28: =CW28*I28 -> 0 | W28: =ROUND(CX28*I28,2) -> 0 | X28: =(ROUND((((S28+ROUND((ROUND(((((EU28*0.75)*1.2))*AV28*I28),2)*BS28),2))*AT28)/100),2)+ROUND(((ROUND((ROUND(((AE28-(((EU28*0.75)*1.2)))*AV28*I28),2)*BS28),2)*AT28)/100),2)) -> 694.1 | Y28: =(ROUND((((S28+ROUND((ROUND(((((EU28*0.75)*1.2))*AV28*I28),2)*BS28),2))*AU28)/100),2)+ROUND(((ROUND((ROUND(((AE28-(((EU28*0.75)*1.2)))*AV28*I28),2)*BS28),2)*AU28)/100),2)) -> 358.49 | AA28: 85739205 | AB28: =ROUND((AC28+AD28+AF28),6) -> 426.8355 | AC28: =ROUND((((ES28*0.75)*1)),6) -> 34.1475 | AD28: =ROUND((((((ET28*0.75)*1.2))-(((EU28*0.75)*1.2)))+AE28),6) -> 37.872 | AE28: =ROUND((((EU28*0.75)*1.2)),6) -> 2.61 | AF28: =ROUND((((EV28*0.75)*1.2)),6) -> 354.816 | AG28: =ROUND((AP28),6) -> 0 | AH28: =(((EW28*0.75)*1.2)) -> 28.8 | AI28: =(((EX28*0.75)*1.2)) -> 0 | AJ28: =(AS28) -> 0 | AK28: 481.85 | AL28: 45.53 | AM28: 42.08 | AN28: 2.9 | AO28: 394.24 | AP28: 0 | AQ28: 32 | AR28: 0 | AS28: 0 | AT28: 91 | AU28: 47 | AV28: 1.067 | AW28: 1.028 | AZ28: 1 | BA28: 1 | BB28: 1 | BC28: 1 | BH28: 0 | BI28: 2 | BJ28: ТСН-2001.4 Доп. 80, Сб. 7, т. 21, поз. 3 | BM28: 66 | BN28: 0 | BO28: 4.7-21-3 | BP28: 1 | BQ28: 40 | BR28: 0 | BS28: 1 | BT28: 1 | BU28: 1 | BV28: 1 | BW28: 1 | BX28: 1 | BZ28: 91 | CA28: 47 | CE28: 1566 | CF28: 0 | CG28: 0 | CM28: 0 | CN28: Поправка: Гл.4.Прил.2.2.п.2.2.17_04.00.01.24.001 Наименование: При разнице в массе оборудования более 10% к норме и расценке ближайшего по массе оборудования при коэффициенте изменения массы оборудования до 0,5 т Поправка: Гл.12.Прил.8.п.8. 3_12.00.01.11.001 Наименование: При наличии напряженных и стесненных условий производства работ (стесненность, сложность складирования и транспортной логистики и т.п.) для объектов, расположенных в пределах круговой магистральной системы улиц "Садовое кольцо" города Москвы | CO28: 0 | CP28: =(P28+Q28+S28) -> 908.21 | CQ28: =ROUND((ROUND((AC28*AW28*1),2)*BC28),2) -> 35.1 | CR28: =(ROUND((ROUND(((((ET28*0.75)*1.2))*AV28*1),2)*BB28),2)+ROUND((ROUND(((AE28-(((EU28*0.75)*1.2)))*AV28*1),2)*BS28),2)) -> 40.41 | CS28: =(ROUND((ROUND(((((EU28*0.75)*1.2))*AV28*1),2)*BS28),2)+ROUND((ROUND(((AE28-(((EU28*0.75)*1.2)))*AV28*1),2)*BS28),2)) -> 2.78 | CT28: =ROUND((ROUND((AF28*AV28*1),2)*BA28),2) -> 378.59 | CU28: =AG28 -> 0 | CV28: =(AH28*AV28) -> 30.7296 | CW28: =AI28 -> 0 | CX28: =AJ28 -> 0 | CY28: =(ROUND((((S28+ROUND((ROUND(((((EU28*0.75)*1.2))*AV28*1),2)*BS28),2))*AT28)/100),2)+ROUND(((ROUND((ROUND(((AE28-(((EU28*0.75)*1.2)))*AV28*1),2)*BS28),2)*AT28)/100),2)) -> 691.56 | CZ28: =(ROUND((((S28+ROUND((ROUND(((((EU28*0.75)*1.2))*AV28*1),2)*BS28),2))*AU28)/100),2)+ROUND(((ROUND((ROUND(((AE28-(((EU28*0.75)*1.2)))*AV28*1),2)*BS28),2)*AU28)/100),2)) -> 357.18 | DB28: 1 | DD28: *0,75)*1 | DE28: *0,75)*1,2 | DF28: *0,75)*1,2 | DG28: *0,75)*1,2 | DI28: *0,75)*1,2 | DJ28: *0,75)*1,2 | DN28: 0 | DO28: 0 | DP28: 1 | DQ28: 1 | DU28: 1013 | DV28: 1 ШТ. | DW28: 1 ШТ. | DX28: 1 | EE28: 85133415 | EF28: 40 | EG28: Монтаж оборудования | EH28: 0 | EJ28: 2 | EK28: 66 | EL28: ТСН-2001.4-7. Компрессорные машины, насосы, вентиляторы | EM28: ТСН-2001.4-7-1 | EO28: Поправка: Гл.4.Прил.2.2.п.2.2.17_04.00.01.24.001 Поправка: Гл.12.Прил.8.п.8. 3_12.00.01.11.001 | EQ28: 0 | ER28: 481.85 | ES28: 45.53 | ET28: 42.08 | EU28: 2.9 | EV28: 394.24 | EW28: 32 | EX28: 0 | EY28: 0 | FQ28: 0 | FR28: 0 | FS28: 2 | FX28: 91 | FY28: 47 | GD28: 1 | GF28: 2029985936 | GG28: 2 | GH28: 1 | GI28: 2 | GJ28: 0 | GK28: 0 | GL28: =ROUND(IF(AND(BH28=3,BI28=3,FS28<>0),P28,0),2) -> 0 | GM28: =ROUND(O28+X28+Y28,2)+GX28 -> 1960.8 | GN28: =IF(OR(BI28=0,BI28=1),GM28-GX28,0) -> 0 | GO28: =IF(BI28=2,GM28-GX28,0) -> 1960.8 | GP28: =IF(BI28=4,GM28-GX28,0) -> 0 | GR28: 0 | GS28: 3 | GT28: 0 | GV28: =ROUND((GT28),6) -> 0 | GW28: 1 | GX28: =ROUND(HC28*I28,2) -> 0 | HA28: 0 | HB28: 0 | HC28: =GV28*GW28 -> 0 | HS28: 0 | IK28: 0
A29: 17 | B29: 1 | C29: =ROW(SmtRes!A20) -> 20 | D29: =ROW(EtalonRes!A22) -> 22 | E29: 1 | F29: 4.7-21-3 | G29: Монтаж насосного агрегата лопастного центробежного одноступенчатого, многоступенчатого объемного, вихревого, поршневого, приводного, роторного на общей фундаментной плите или моноблочный массой 0,425 т | H29: 1 ШТ. | I29: 2 | J29: 0 | K29: 2 | O29: =ROUND(CP29,2) -> 44699.5 | P29: =ROUND((ROUND((AC29*AW29*I29),2)*BC29),2) -> 841.12 | Q29: =(ROUND((ROUND(((((ET29*0.75)*1.2))*AV29*I29),2)*BB29),2)+ROUND((ROUND(((AE29-(((EU29*0.75)*1.2)))*AV29*I29),2)*BS29),2)) -> 1191.29 | R29: =(ROUND((ROUND(((((EU29*0.75)*1.2))*AV29*I29),2)*BS29),2)+ROUND((ROUND(((AE29-(((EU29*0.75)*1.2)))*AV29*I29),2)*BS29),2)) -> 313.87 | S29: =ROUND((ROUND((AF29*AV29*I29),2)*BA29),2) -> 42667.09 | T29: =ROUND(CU29*I29,2) -> 0 | U29: =CV29*I29 -> 61.4592 | V29: =CW29*I29 -> 0 | W29: =ROUND(CX29*I29,2) -> 0 | X29: =(ROUND((((S29+ROUND((ROUND(((((EU29*0.75)*1.2))*AV29*I29),2)*BS29),2))*AT29)/100),2)+ROUND(((ROUND((ROUND(((AE29-(((EU29*0.75)*1.2)))*AV29*I29),2)*BS29),2)*AT29)/100),2)) -> 39112.67 | Y29: =(ROUND((((S29+ROUND((ROUND(((((EU29*0.75)*1.2))*AV29*I29),2)*BS29),2))*AU29)/100),2)+ROUND(((ROUND((ROUND(((AE29-(((EU29*0.75)*1.2)))*AV29*I29),2)*BS29),2)*AU29)/100),2)) -> 20201.05 | AA29: 85739207 | AB29: =ROUND((AC29+AD29+AF29),6) -> 426.8355 | AC29: =ROUND((((ES29*0.75)*1)),6) -> 34.1475 | AD29: =ROUND((((((ET29*0.75)*1.2))-(((EU29*0.75)*1.2)))+AE29),6) -> 37.872 | AE29: =ROUND((((EU29*0.75)*1.2)),6) -> 2.61 | AF29: =ROUND((((EV29*0.75)*1.2)),6) -> 354.816 | AG29: =ROUND((AP29),6) -> 0 | AH29: =(((EW29*0.75)*1.2)) -> 28.8 | AI29: =(((EX29*0.75)*1.2)) -> 0 | AJ29: =(AS29) -> 0 | AK29: 481.85 | AL29: 45.53 | AM29: 42.08 | AN29: 2.9 | AO29: 394.24 | AP29: 0 | AQ29: 32 | AR29: 0 | AS29: 0 | AT29: 91 | AU29: 47 | AV29: 1.067 | AW29: 1.028 | AZ29: 1 | BA29: 56.35 | BB29: 14.74 | BC29: 11.98 | BH29: 0 | BI29: 2 | BJ29: ТСН-2001.4 Доп. 80, Сб. 7, т. 21, поз. 3 | BM29: 66 | BN29: 0 | BO29: 4.7-21-3 | BP29: 1 | BQ29: 40 | BR29: 0 | BS29: 56.35 | BT29: 1 | BU29: 1 | BV29: 1 | BW29: 1 | BX29: 1 | BZ29: 91 | CA29: 47 | CE29: 1566 | CF29: 0 | CG29: 0 | CM29: 0 | CN29: Поправка: Гл.4.Прил.2.2.п.2.2.17_04.00.01.24.001 Наименование: При разнице в массе оборудования более 10% к норме и расценке ближайшего по массе оборудования при коэффициенте изменения массы оборудования до 0,5 т Поправка: Гл.12.Прил.8.п.8. 3_12.00.01.11.001 Наименование: При наличии напряженных и стесненных условий производства работ (стесненность, сложность складирования и транспортной логистики и т.п.) для объектов, расположенных в пределах круговой магистральной системы улиц "Садовое кольцо" города Москвы | CO29: 0 | CP29: =(P29+Q29+S29) -> 44699.5 | CQ29: =ROUND((ROUND((AC29*AW29*1),2)*BC29),2) -> 420.5 | CR29: =(ROUND((ROUND(((((ET29*0.75)*1.2))*AV29*1),2)*BB29),2)+ROUND((ROUND(((AE29-(((EU29*0.75)*1.2)))*AV29*1),2)*BS29),2)) -> 595.64 | CS29: =(ROUND((ROUND(((((EU29*0.75)*1.2))*AV29*1),2)*BS29),2)+ROUND((ROUND(((AE29-(((EU29*0.75)*1.2)))*AV29*1),2)*BS29),2)) -> 156.65 | CT29: =ROUND((ROUND((AF29*AV29*1),2)*BA29),2) -> 21333.55 | CU29: =AG29 -> 0 | CV29: =(AH29*AV29) -> 30.7296 | CW29: =AI29 -> 0 | CX29: =AJ29 -> 0 | CY29: =(ROUND((((S29+ROUND((ROUND(((((EU29*0.75)*1.2))*AV29*1),2)*BS29),2))*AT29)/100),2)+ROUND(((ROUND((ROUND(((AE29-(((EU29*0.75)*1.2)))*AV29*1),2)*BS29),2)*AT29)/100),2)) -> 38969.6 | CZ29: =(ROUND((((S29+ROUND((ROUND(((((EU29*0.75)*1.2))*AV29*1),2)*BS29),2))*AU29)/100),2)+ROUND(((ROUND((ROUND(((AE29-(((EU29*0.75)*1.2)))*AV29*1),2)*BS29),2)*AU29)/100),2)) -> 20127.16 | DB29: 3 | DD29: *0,75)*1 | DE29: *0,75)*1,2 | DF29: *0,75)*1,2 | DG29: *0,75)*1,2 | DI29: *0,75)*1,2 | DJ29: *0,75)*1,2 | DN29: 0 | DO29: 0 | DP29: 1 | DQ29: 1 | DU29: 1013 | DV29: 1 ШТ. | DW29: 1 ШТ. | DX29: 1 | EE29: 85133415 | EF29: 40 | EG29: Монтаж оборудования | EH29: 0 | EJ29: 2 | EK29: 66 | EL29: ТСН-2001.4-7. Компрессорные машины, насосы, вентиляторы | EM29: ТСН-2001.4-7-1 | EO29: Поправка: Гл.4.Прил.2.2.п.2.2.17_04.00.01.24.001 Поправка: Гл.12.Прил.8.п.8. 3_12.00.01.11.001 | EQ29: 0 | ER29: 481.85 | ES29: 45.53 | ET29: 42.08 | EU29: 2.9 | EV29: 394.24 | EW29: 32 | EX29: 0 | EY29: 0 | FQ29: 0 | FR29: 0 | FS29: 2 | FX29: 91 | FY29: 47 | GD29: 1 | GF29: 2029985936 | GG29: 2 | GH29: 1 | GI29: 2 | GJ29: 0 | GK29: 0 | GL29: =ROUND(IF(AND(BH29=3,BI29=3,FS29<>0),P29,0),2) -> 0 | GM29: =ROUND(O29+X29+Y29,2)+GX29 -> 104013.22 | GN29: =IF(OR(BI29=0,BI29=1),GM29-GX29,0) -> 0 | GO29: =IF(BI29=2,GM29-GX29,0) -> 104013.22 | GP29: =IF(BI29=4,GM29-GX29,0) -> 0 | GR29: 0 | GS29: 3 | GT29: 0 | GV29: =ROUND((GT29),6) -> 0 | GW29: 1 | GX29: =ROUND(HC29*I29,2) -> 0 | HA29: 0 | HB29: 0 | HC29: =GV29*GW29 -> 0 | HS29: 0 | IK29: 0
A30: 17 | B30: 1 | C30: =ROW(SmtRes!A30) -> 30 | D30: =ROW(EtalonRes!A33) -> 33 | E30: 2 | F30: 4.7-21-1 | G30: Монтаж насосного агрегата лопастного центробежного одноступенчатого, многоступенчатого объемного, вихревого, поршневого, приводного, роторного на общей фундаментной плите или моноблочный массой 0,064 т | H30: 1 ШТ. | I30: =ROUND(1,9) -> 1 | J30: 0 | K30: =ROUND(1,9) -> 1 | O30: =ROUND(CP30,2) -> 513.44 | P30: =ROUND((ROUND((AC30*AW30*I30),2)*BC30),2) -> 43.53 | Q30: =(ROUND((ROUND((((ET30*1.2))*AV30*I30),2)*BB30),2)+ROUND((ROUND(((AE30-((EU30*1.2)))*AV30*I30),2)*BS30),2)) -> 31.37 | R30: =(ROUND((ROUND((((EU30*1.2))*AV30*I30),2)*BS30),2)+ROUND((ROUND(((AE30-((EU30*1.2)))*AV30*I30),2)*BS30),2)) -> 0.49 | S30: =ROUND((ROUND((AF30*AV30*I30),2)*BA30),2) -> 438.54 | T30: =ROUND(CU30*I30,2) -> 0 | U30: =CV30*I30 -> 35.59512 | V30: =CW30*I30 -> 0 | W30: =ROUND(CX30*I30,2) -> 0 | X30: =(ROUND((((S30+ROUND((ROUND((((EU30*1.2))*AV30*I30),2)*BS30),2))*AT30)/100),2)+ROUND(((ROUND((ROUND(((AE30-((EU30*1.2)))*AV30*I30),2)*BS30),2)*AT30)/100),2)) -> 399.52 | Y30: =(ROUND((((S30+ROUND((ROUND((((EU30*1.2))*AV30*I30),2)*BS30),2))*AU30)/100),2)+ROUND(((ROUND((ROUND(((AE30-((EU30*1.2)))*AV30*I30),2)*BS30),2)*AU30)/100),2)) -> 206.34 | AA30: 85739205 | AB30: =ROUND((AC30+AD30+AF30),6) -> 482.74 | AC30: =ROUND(((ES30*1)),6) -> 42.34 | AD30: =ROUND(((((ET30*1.2))-((EU30*1.2)))+AE30),6) -> 29.4 | AE30: =ROUND(((EU30*1.2)),6) -> 0.456 | AF30: =ROUND(((EV30*1.2)),6) -> 411 | AG30: =ROUND((AP30),6) -> 0 | AH30: =((EW30*1.2)) -> 33.36 | AI30: =((EX30*1.2)) -> 0 | AJ30: =(AS30) -> 0 | AK30: 409.34 | AL30: 42.34 | AM30: 24.5 | AN30: 0.38 | AO30: 342.5 | AP30: 0 | AQ30: 27.8 | AR30: 0 | AS30: 0 | AT30: 91 | AU30: 47 | AV30: 1.067 | AW30: 1.028 | AZ30: 1 | BA30: 1 | BB30: 1 | BC30: 1 | BH30: 0 | BI30: 2 | BJ30: ТСН-2001.4 Доп. 80, Сб. 7, т. 21, поз. 1 | BM30: 66 | BN30: 0 | BO30: 4.7-21-1 | BP30: 1 | BQ30: 40 | BR30: 0 | BS30: 1 | BT30: 1 | BU30: 1 | BV30: 1 | BW30: 1 | BX30: 1 | BZ30: 91 | CA30: 47 | CE30: 1566 | CF30: 0 | CG30: 0 | CM30: 0 | CN30: Поправка: Гл.12.Прил.8.п.8. 3_12.00.01.11.001 Наименование: При наличии напряженных и стесненных условий производства работ (стесненность, сложность складирования и транспортной логистики и т.п.) для объектов, расположенных в пределах круговой магистральной системы улиц "Садовое кольцо" города Москвы | CO30: 0 | CP30: =(P30+Q30+S30) -> 513.44 | CQ30: =ROUND((ROUND((AC30*AW30*1),2)*BC30),2) -> 43.53 | CR30: =(ROUND((ROUND((((ET30*1.2))*AV30*1),2)*BB30),2)+ROUND((ROUND(((AE30-((EU30*1.2)))*AV30*1),2)*BS30),2)) -> 31.37 | CS30: =(ROUND((ROUND((((EU30*1.2))*AV30*1),2)*BS30),2)+ROUND((ROUND(((AE30-((EU30*1.2)))*AV30*1),2)*BS30),2)) -> 0.49 | CT30: =ROUND((ROUND((AF30*AV30*1),2)*BA30),2) -> 438.54 | CU30: =AG30 -> 0 | CV30: =(AH30*AV30) -> 35.59512 | CW30: =AI30 -> 0 | CX30: =AJ30 -> 0 | CY30: =(ROUND((((S30+ROUND((ROUND((((EU30*1.2))*AV30*1),2)*BS30),2))*AT30)/100),2)+ROUND(((ROUND((ROUND(((AE30-((EU30*1.2)))*AV30*1),2)*BS30),2)*AT30)/100),2)) -> 399.52 | CZ30: =(ROUND((((S30+ROUND((ROUND((((EU30*1.2))*AV30*1),2)*BS30),2))*AU30)/100),2)+ROUND(((ROUND((ROUND(((AE30-((EU30*1.2)))*AV30*1),2)*BS30),2)*AU30)/100),2)) -> 206.34 | DB30: 5 | DD30: *1 | DE30: *1,2 | DF30: *1,2 | DG30: *1,2 | DI30: *1,2 | DJ30: *1,2 | DN30: 0 | DO30: 0 | DP30: 1 | DQ30: 1 | DU30: 1013 | DV30: 1 ШТ. | DW30: 1 ШТ. | DX30: 1 | EE30: 85133415 | EF30: 40 | EG30: Монтаж оборудования | EH30: 0 | EJ30: 2 | EK30: 66 | EL30: ТСН-2001.4-7. Компрессорные машины, насосы, вентиляторы | EM30: ТСН-2001.4-7-1 | EO30: Поправка: Гл.12.Прил.8.п.8. 3_12.00.01.11.001 | EQ30: 0 | ER30: 409.34 | ES30: 42.34 | ET30: 24.5 | EU30: 0.38 | EV30: 342.5 | EW30: 27.8 | EX30: 0 | EY30: 0 | FQ30: 0 | FR30: 0 | FS30: 2 | FX30: 91 | FY30: 47 | GD30: 1 | GF30: -1722888311 | GG30: 2 | GH30: 1 | GI30: 2 | GJ30: 0 | GK30: 0 | GL30: =ROUND(IF(AND(BH30=3,BI30=3,FS30<>0),P30,0),2) -> 0 | GM30: =ROUND(O30+X30+Y30,2)+GX30 -> 1119.3 | GN30: =IF(OR(BI30=0,BI30=1),GM30-GX30,0) -> 0 | GO30: =IF(BI30=2,GM30-GX30,0) -> 1119.3 | GP30: =IF(BI30=4,GM30-GX30,0) -> 0 | GR30: 0 | GS30: 3 | GT30: 0 | GV30: =ROUND((GT30),6) -> 0 | GW30: 1 | GX30: =ROUND(HC30*I30,2) -> 0 | HA30: 0 | HB30: 0 | HC30: =GV30*GW30 -> 0 | HS30: 0 | IK30: 0
A31: 17 | B31: 1 | C31: =ROW(SmtRes!A40) -> 40 | D31: =ROW(EtalonRes!A44) -> 44 | E31: 2 | F31: 4.7-21-1 | G31: Монтаж насосного агрегата лопастного центробежного одноступенчатого, многоступенчатого объемного, вихревого, поршневого, приводного, роторного на общей фундаментной плите или моноблочный массой 0,064 т | H31: 1 ШТ. | I31: =ROUND(1,9) -> 1 | J31: 0 | K31: =ROUND(1,9) -> 1 | O31: =ROUND(CP31,2) -> 25637.77 | P31: =ROUND((ROUND((AC31*AW31*I31),2)*BC31),2) -> 507.56 | Q31: =(ROUND((ROUND((((ET31*1.2))*AV31*I31),2)*BB31),2)+ROUND((ROUND(((AE31-((EU31*1.2)))*AV31*I31),2)*BS31),2)) -> 418.48 | R31: =(ROUND((ROUND((((EU31*1.2))*AV31*I31),2)*BS31),2)+ROUND((ROUND(((AE31-((EU31*1.2)))*AV31*I31),2)*BS31),2)) -> 27.61 | S31: =ROUND((ROUND((AF31*AV31*I31),2)*BA31),2) -> 24711.73 | T31: =ROUND(CU31*I31,2) -> 0 | U31: =CV31*I31 -> 35.59512 | V31: =CW31*I31 -> 0 | W31: =ROUND(CX31*I31,2) -> 0 | X31: =(ROUND((((S31+ROUND((ROUND((((EU31*1.2))*AV31*I31),2)*BS31),2))*AT31)/100),2)+ROUND(((ROUND((ROUND(((AE31-((EU31*1.2)))*AV31*I31),2)*BS31),2)*AT31)/100),2)) -> 22512.8 | Y31: =(ROUND((((S31+ROUND((ROUND((((EU31*1.2))*AV31*I31),2)*BS31),2))*AU31)/100),2)+ROUND(((ROUND((ROUND(((AE31-((EU31*1.2)))*AV31*I31),2)*BS31),2)*AU31)/100),2)) -> 11627.49 | AA31: 85739207 | AB31: =ROUND((AC31+AD31+AF31),6) -> 482.74 | AC31: =ROUND(((ES31*1)),6) -> 42.34 | AD31: =ROUND(((((ET31*1.2))-((EU31*1.2)))+AE31),6) -> 29.4 | AE31: =ROUND(((EU31*1.2)),6) -> 0.456 | AF31: =ROUND(((EV31*1.2)),6) -> 411 | AG31: =ROUND((AP31),6) -> 0 | AH31: =((EW31*1.2)) -> 33.36 | AI31: =((EX31*1.2)) -> 0 | AJ31: =(AS31) -> 0 | AK31: 409.34 | AL31: 42.34 | AM31: 24.5 | AN31: 0.38 | AO31: 342.5 | AP31: 0 | AQ31: 27.8 | AR31: 0 | AS31: 0 | AT31: 91 | AU31: 47 | AV31: 1.067 | AW31: 1.028 | AZ31: 1 | BA31: 56.35 | BB31: 13.34 | BC31: 11.66 | BH31: 0 | BI31: 2 | BJ31: ТСН-2001.4 Доп. 80, Сб. 7, т. 21, поз. 1 | BM31: 66 | BN31: 0 | BO31: 4.7-21-1 | BP31: 1 | BQ31: 40 | BR31: 0 | BS31: 56.35 | BT31: 1 | BU31: 1 | BV31: 1 | BW31: 1 | BX31: 1 | BZ31: 91 | CA31: 47 | CE31: 1566 | CF31: 0 | CG31: 0 | CM31: 0 | CN31: Поправка: Гл.12.Прил.8.п.8. 3_12.00.01.11.001 Наименование: При наличии напряженных и стесненных условий производства работ (стесненность, сложность складирования и транспортной логистики и т.п.) для объектов, расположенных в пределах круговой магистральной системы улиц "Садовое кольцо" города Москвы | CO31: 0 | CP31: =(P31+Q31+S31) -> 25637.77 | CQ31: =ROUND((ROUND((AC31*AW31*1),2)*BC31),2) -> 507.56 | CR31: =(ROUND((ROUND((((ET31*1.2))*AV31*1),2)*BB31),2)+ROUND((ROUND(((AE31-((EU31*1.2)))*AV31*1),2)*BS31),2)) -> 418.48 | CS31: =(ROUND((ROUND((((EU31*1.2))*AV31*1),2)*BS31),2)+ROUND((ROUND(((AE31-((EU31*1.2)))*AV31*1),2)*BS31),2)) -> 27.61 | CT31: =ROUND((ROUND((AF31*AV31*1),2)*BA31),2) -> 24711.73 | CU31: =AG31 -> 0 | CV31: =(AH31*AV31) -> 35.59512 | CW31: =AI31 -> 0 | CX31: =AJ31 -> 0 | CY31: =(ROUND((((S31+ROUND((ROUND((((EU31*1.2))*AV31*1),2)*BS31),2))*AT31)/100),2)+ROUND(((ROUND((ROUND(((AE31-((EU31*1.2)))*AV31*1),2)*BS31),2)*AT31)/100),2)) -> 22512.8 | CZ31: =(ROUND((((S31+ROUND((ROUND((((EU31*1.2))*AV31*1),2)*BS31),2))*AU31)/100),2)+ROUND(((ROUND((ROUND(((AE31-((EU31*1.2)))*AV31*1),2)*BS31),2)*AU31)/100),2)) -> 11627.49 | DB31: 6 | DD31: *1 | DE31: *1,2 | DF31: *1,2 | DG31: *1,2 | DI31: *1,2 | DJ31: *1,2 | DN31: 0 | DO31: 0 | DP31: 1 | DQ31: 1 | DU31: 1013 | DV31: 1 ШТ. | DW31: 1 ШТ. | DX31: 1 | EE31: 85133415 | EF31: 40 | EG31: Монтаж оборудования | EH31: 0 | EJ31: 2 | EK31: 66 | EL31: ТСН-2001.4-7. Компрессорные машины, насосы, вентиляторы | EM31: ТСН-2001.4-7-1 | EO31: Поправка: Гл.12.Прил.8.п.8. 3_12.00.01.11.001 | EQ31: 0 | ER31: 409.34 | ES31: 42.34 | ET31: 24.5 | EU31: 0.38 | EV31: 342.5 | EW31: 27.8 | EX31: 0 | EY31: 0 | FQ31: 0 | FR31: 0 | FS31: 2 | FX31: 91 | FY31: 47 | GD31: 1 | GF31: -1722888311 | GG31: 2 | GH31: 1 | GI31: 2 | GJ31: 0 | GK31: 0 | GL31: =ROUND(IF(AND(BH31=3,BI31=3,FS31<>0),P31,0),2) -> 0 | GM31: =ROUND(O31+X31+Y31,2)+GX31 -> 59778.06 | GN31: =IF(OR(BI31=0,BI31=1),GM31-GX31,0) -> 0 | GO31: =IF(BI31=2,GM31-GX31,0) -> 59778.06 | GP31: =IF(BI31=4,GM31-GX31,0) -> 0 | GR31: 0 | GS31: 3 | GT31: 0 | GV31: =ROUND((GT31),6) -> 0 | GW31: 1 | GX31: =ROUND(HC31*I31,2) -> 0 | HA31: 0 | HB31: 0 | HC31: =GV31*GW31 -> 0 | HS31: 0 | IK31: 0
A32: 17 | B32: 1 | C32: =ROW(SmtRes!A41) -> 41 | D32: =ROW(EtalonRes!A45) -> 45 | E32: 3 | F32: 4.6-48-4 | G32: Бак внутренней установки без давления цилиндрический вертикальный, вместимость 1,0 м3 (60 л.) | H32: 1 Т | I32: 0.009 | J32: 0 | K32: 0.009 | O32: =ROUND(CP32,2) -> 100.94 | P32: =ROUND((ROUND((AC32*AW32*I32),2)*BC32),2) -> 1.23 | Q32: =(ROUND((ROUND((((ET32*1.2))*AV32*I32),2)*BB32),2)+ROUND((ROUND(((AE32-((EU32*1.2)))*AV32*I32),2)*BS32),2)) -> 35.34 | R32: =(ROUND((ROUND((((EU32*1.2))*AV32*I32),2)*BS32),2)+ROUND((ROUND(((AE32-((EU32*1.2)))*AV32*I32),2)*BS32),2)) -> 10.63 | S32: =ROUND((ROUND((AF32*AV32*I32),2)*BA32),2) -> 64.37 | T32: =ROUND(CU32*I32,2) -> 0 | U32: =CV32*I32 -> 5.6119932 | V32: =CW32*I32 -> 0 | W32: =ROUND(CX32*I32,2) -> 0 | X32: =(ROUND((((S32+ROUND((ROUND((((EU32*1.2))*AV32*I32),2)*BS32),2))*AT32)/100),2)+ROUND(((ROUND((ROUND(((AE32-((EU32*1.2)))*AV32*I32),2)*BS32),2)*AT32)/100),2)) -> 66.75 | Y32: =(ROUND((((S32+ROUND((ROUND((((EU32*1.2))*AV32*I32),2)*BS32),2))*AU32)/100),2)+ROUND(((ROUND((ROUND(((AE32-((EU32*1.2)))*AV32*I32),2)*BS32),2)*AU32)/100),2)) -> 33.75 | AA32: 85739205 | AB32: =ROUND((AC32+AD32+AF32),6) -> 10515.652 | AC32: =ROUND(((ES32*1)),6) -> 133 | AD32: =ROUND(((((ET32*1.2))-((EU32*1.2)))+AE32),6) -> 3679.584 | AE32: =ROUND(((EU32*1.2)),6) -> 1107.072 | AF32: =ROUND(((EV32*1.2)),6) -> 6703.068 | AG32: =ROUND((AP32),6) -> 0 | AH32: =((EW32*1.2)) -> 584.4 | AI32: =((EX32*1.2)) -> 0 | AJ32: =(AS32) -> 0 | AK32: 8785.21 | AL32: 133 | AM32: 3066.32 | AN32: 922.56 | AO32: 5585.89 | AP32: 0 | AQ32: 487 | AR32: 0 | AS32: 0 | AT32: 89 | AU32: 45 | AV32: 1.067 | AW32: 1.028 | AZ32: 1 | BA32: 1 | BB32: 1 | BC32: 1 | BH32: 0 | BI32: 2 | BJ32: ТСН-2001.4. Доп. 1-42. Сб. 6, т. 48, поз. 4 | BM32: 65 | BN32: 0 | BO32: 4.6-48-4 | BP32: 1 | BQ32: 40 | BR32: 0 | BS32: 1 | BT32: 1 | BU32: 1 | BV32: 1 | BW32: 1 | BX32: 1 | BZ32: 89 | CA32: 45 | CE32: 1566 | CF32: 0 | CG32: 0 | CM32: 0 | CN32: Поправка: Гл.12.Прил.8.п.8. 3_12.00.01.11.001 Наименование: При наличии напряженных и стесненных условий производства работ (стесненность, сложность складирования и транспортной логистики и т.п.) для объектов, расположенных в пределах круговой магистральной системы улиц "Садовое кольцо" города Москвы | CO32: 0 | CP32: =(P32+Q32+S32) -> 100.94 | CQ32: =ROUND((ROUND((AC32*AW32*1),2)*BC32),2) -> 136.72 | CR32: =(ROUND((ROUND((((ET32*1.2))*AV32*1),2)*BB32),2)+ROUND((ROUND(((AE32-((EU32*1.2)))*AV32*1),2)*BS32),2)) -> 3926.12 | CS32: =(ROUND((ROUND((((EU32*1.2))*AV32*1),2)*BS32),2)+ROUND((ROUND(((AE32-((EU32*1.2)))*AV32*1),2)*BS32),2)) -> 1181.25 | CT32: =ROUND((ROUND((AF32*AV32*1),2)*BA32),2) -> 7152.17 | CU32: =AG32 -> 0 | CV32: =(AH32*AV32) -> 623.5548 | CW32: =AI32 -> 0 | CX32: =AJ32 -> 0 | CY32: =(ROUND((((S32+ROUND((ROUND((((EU32*1.2))*AV32*1),2)*BS32),2))*AT32)/100),2)+ROUND(((ROUND((ROUND(((AE32-((EU32*1.2)))*AV32*1),2)*BS32),2)*AT32)/100),2)) -> 1108.6 | CZ32: =(ROUND((((S32+ROUND((ROUND((((EU32*1.2))*AV32*1),2)*BS32),2))*AU32)/100),2)+ROUND(((ROUND((ROUND(((AE32-((EU32*1.2)))*AV32*1),2)*BS32),2)*AU32)/100),2)) -> 560.53 | DB32: 7 | DD32: *1 | DE32: *1,2 | DF32: *1,2 | DG32: *1,2 | DI32: *1,2 | DJ32: *1,2 | DN32: 0 | DO32: 0 | DP32: 1 | DQ32: 1 | DU32: 1013 | DV32: 1 Т | DW32: 1 Т | DX32: 1 | EE32: 85133414 | EF32: 40 | EG32: Монтаж оборудования | EH32: 0 | EJ32: 2 | EK32: 65 | EL32: ТСН-2001.4-6. Теплосиловое оборудование | EM32: ТСН-2001.4-6-1 | EO32: Поправка: Гл.12.Прил.8.п.8. 3_12.00.01.11.001 | EQ32: 0 | ER32: 8785.21 | ES32: 133 | ET32: 3066.32 | EU32: 922.56 | EV32: 5585.89 | EW32: 487 | EX32: 0 | EY32: 0 | FQ32: 0 | FR32: 0 | FS32: 2 | FX32: 89 | FY32: 45 | GD32: 1 | GF32: -966979253 | GG32: 2 | GH32: 1 | GI32: 2 | GJ32: 0 | GK32: 0 | GL32: =ROUND(IF(AND(BH32=3,BI32=3,FS32<>0),P32,0),2) -> 0 | GM32: =ROUND(O32+X32+Y32,2)+GX32 -> 201.44 | GN32: =IF(OR(BI32=0,BI32=1),GM32-GX32,0) -> 0 | GO32: =IF(BI32=2,GM32-GX32,0) -> 201.44 | GP32: =IF(BI32=4,GM32-GX32,0) -> 0 | GR32: 0 | GS32: 3 | GT32: 0 | GV32: =ROUND((GT32),6) -> 0 | GW32: 1 | GX32: =ROUND(HC32*I32,2) -> 0 | HA32: 0 | HB32: 0 | HC32: =GV32*GW32 -> 0 | HS32: 0 | IK32: 0
A33: 17 | B33: 1 | C33: =ROW(SmtRes!A42) -> 42 | D33: =ROW(EtalonRes!A46) -> 46 | E33: 3 | F33: 4.6-48-4 | G33: Бак внутренней установки без давления цилиндрический вертикальный, вместимость 1,0 м3 (60 л.) | H33: 1 Т | I33: 0.009 | J33: 0 | K33: 0.009 | O33: =ROUND(CP33,2) -> 4509.42 | P33: =ROUND((ROUND((AC33*AW33*I33),2)*BC33),2) -> 12.1 | Q33: =(ROUND((ROUND((((ET33*1.2))*AV33*I33),2)*BB33),2)+ROUND((ROUND(((AE33-((EU33*1.2)))*AV33*I33),2)*BS33),2)) -> 870.07 | R33: =(ROUND((ROUND((((EU33*1.2))*AV33*I33),2)*BS33),2)+ROUND((ROUND(((AE33-((EU33*1.2)))*AV33*I33),2)*BS33),2)) -> 599 | S33: =ROUND((ROUND((AF33*AV33*I33),2)*BA33),2) -> 3627.25 | T33: =ROUND(CU33*I33,2) -> 0 | U33: =CV33*I33 -> 5.6119932 | V33: =CW33*I33 -> 0 | W33: =ROUND(CX33*I33,2) -> 0 | X33: =(ROUND((((S33+ROUND((ROUND((((EU33*1.2))*AV33*I33),2)*BS33),2))*AT33)/100),2)+ROUND(((ROUND((ROUND(((AE33-((EU33*1.2)))*AV33*I33),2)*BS33),2)*AT33)/100),2)) -> 3761.36 | Y33: =(ROUND((((S33+ROUND((ROUND((((EU33*1.2))*AV33*I33),2)*BS33),2))*AU33)/100),2)+ROUND(((ROUND((ROUND(((AE33-((EU33*1.2)))*AV33*I33),2)*BS33),2)*AU33)/100),2)) -> 1901.81 | AA33: 85739207 | AB33: =ROUND((AC33+AD33+AF33),6) -> 10515.652 | AC33: =ROUND(((ES33*1)),6) -> 133 | AD33: =ROUND(((((ET33*1.2))-((EU33*1.2)))+AE33),6) -> 3679.584 | AE33: =ROUND(((EU33*1.2)),6) -> 1107.072 | AF33: =ROUND(((EV33*1.2)),6) -> 6703.068 | AG33: =ROUND((AP33),6) -> 0 | AH33: =((EW33*1.2)) -> 584.4 | AI33: =((EX33*1.2)) -> 0 | AJ33: =(AS33) -> 0 | AK33: 8785.21 | AL33: 133 | AM33: 3066.32 | AN33: 922.56 | AO33: 5585.89 | AP33: 0 | AQ33: 487 | AR33: 0 | AS33: 0 | AT33: 89 | AU33: 45 | AV33: 1.067 | AW33: 1.028 | AZ33: 1 | BA33: 56.35 | BB33: 24.62 | BC33: 9.84 | BH33: 0 | BI33: 2 | BJ33: ТСН-2001.4. Доп. 1-42. Сб. 6, т. 48, поз. 4 | BM33: 65 | BN33: 0 | BO33: 4.6-48-4 | BP33: 1 | BQ33: 40 | BR33: 0 | BS33: 56.35 | BT33: 1 | BU33: 1 | BV33: 1 | BW33: 1 | BX33: 1 | BZ33: 89 | CA33: 45 | CE33: 1566 | CF33: 0 | CG33: 0 | CM33: 0 | CN33: Поправка: Гл.12.Прил.8.п.8. 3_12.00.01.11.001 Наименование: При наличии напряженных и стесненных условий производства работ (стесненность, сложность складирования и транспортной логистики и т.п.) для объектов, расположенных в пределах круговой магистральной системы улиц "Садовое кольцо" города Москвы | CO33: 0 | CP33: =(P33+Q33+S33) -> 4509.42 | CQ33: =ROUND((ROUND((AC33*AW33*1),2)*BC33),2) -> 1345.32 | CR33: =(ROUND((ROUND((((ET33*1.2))*AV33*1),2)*BB33),2)+ROUND((ROUND(((AE33-((EU33*1.2)))*AV33*1),2)*BS33),2)) -> 96661.07 | CS33: =(ROUND((ROUND((((EU33*1.2))*AV33*1),2)*BS33),2)+ROUND((ROUND(((AE33-((EU33*1.2)))*AV33*1),2)*BS33),2)) -> 66563.44 | CT33: =ROUND((ROUND((AF33*AV33*1),2)*BA33),2) -> 403024.78 | CU33: =AG33 -> 0 | CV33: =(AH33*AV33) -> 623.5548 | CW33: =AI33 -> 0 | CX33: =AJ33 -> 0 | CY33: =(ROUND((((S33+ROUND((ROUND((((EU33*1.2))*AV33*1),2)*BS33),2))*AT33)/100),2)+ROUND(((ROUND((ROUND(((AE33-((EU33*1.2)))*AV33*1),2)*BS33),2)*AT33)/100),2)) -> 62469.71 | CZ33: =(ROUND((((S33+ROUND((ROUND((((EU33*1.2))*AV33*1),2)*BS33),2))*AU33)/100),2)+ROUND(((ROUND((ROUND(((AE33-((EU33*1.2)))*AV33*1),2)*BS33),2)*AU33)/100),2)) -> 31585.81 | DB33: 8 | DD33: *1 | DE33: *1,2 | DF33: *1,2 | DG33: *1,2 | DI33: *1,2 | DJ33: *1,2 | DN33: 0 | DO33: 0 | DP33: 1 | DQ33: 1 | DU33: 1013 | DV33: 1 Т | DW33: 1 Т | DX33: 1 | EE33: 85133414 | EF33: 40 | EG33: Монтаж оборудования | EH33: 0 | EJ33: 2 | EK33: 65 | EL33: ТСН-2001.4-6. Теплосиловое оборудование | EM33: ТСН-2001.4-6-1 | EO33: Поправка: Гл.12.Прил.8.п.8. 3_12.00.01.11.001 | EQ33: 0 | ER33: 8785.21 | ES33: 133 | ET33: 3066.32 | EU33: 922.56 | EV33: 5585.89 | EW33: 487 | EX33: 0 | EY33: 0 | FQ33: 0 | FR33: 0 | FS33: 2 | FX33: 89 | FY33: 45 | GD33: 1 | GF33: -966979253 | GG33: 2 | GH33: 1 | GI33: 2 | GJ33: 0 | GK33: 0 | GL33: =ROUND(IF(AND(BH33=3,BI33=3,FS33<>0),P33,0),2) -> 0 | GM33: =ROUND(O33+X33+Y33,2)+GX33 -> 10172.59 | GN33: =IF(OR(BI33=0,BI33=1),GM33-GX33,0) -> 0 | GO33: =IF(BI33=2,GM33-GX33,0) -> 10172.59 | GP33: =IF(BI33=4,GM33-GX33,0) -> 0 | GR33: 0 | GS33: 3 | GT33: 0 | GV33: =ROUND((GT33),6) -> 0 | GW33: 1 | GX33: =ROUND(HC33*I33,2) -> 0 | HA33: 0 | HB33: 0 | HC33: =GV33*GW33 -> 0 | HS33: 0 | IK33: 0
A34: 17 | B34: 1 | C34: =ROW(SmtRes!A50) -> 50 | D34: =ROW(EtalonRes!A55) -> 55 | F34: 3.18-8-1 | G34: Установка баков расширительных круглых и прямоугольных вместимостью до 0,1 м3 (60 л.) | H34: 1 бак | I34: 1 | J34: 0 | K34: 1 | O34: =ROUND(CP34,2) -> 57.22 | P34: =ROUND((ROUND((AC34*AW34*I34),2)*BC34),2) -> 4.19 | Q34: =(ROUND((ROUND(((ET34)*AV34*I34),2)*BB34),2)+ROUND((ROUND(((AE34-(EU34))*AV34*I34),2)*BS34),2)) -> 8.07 | R34: =(ROUND((ROUND(((EU34)*AV34*I34),2)*BS34),2)+ROUND((ROUND(((AE34-(EU34))*AV34*I34),2)*BS34),2)) -> 0.63 | S34: =ROUND((ROUND((AF34*AV34*I34),2)*BA34),2) -> 44.96 | T34: =ROUND(CU34*I34,2) -> 0 | U34: =CV34*I34 -> 3.87321 | V34: =CW34*I34 -> 0 | W34: =ROUND(CX34*I34,2) -> 0 | X34: =(ROUND((((S34+ROUND((ROUND(((EU34)*AV34*I34),2)*BS34),2))*AT34)/100),2)+ROUND(((ROUND((ROUND(((AE34-(EU34))*AV34*I34),2)*BS34),2)*AT34)/100),2)) -> 55.16 | Y34: =(ROUND((((S34+ROUND((ROUND(((EU34)*AV34*I34),2)*BS34),2))*AU34)/100),2)+ROUND(((ROUND((ROUND(((AE34-(EU34))*AV34*I34),2)*BS34),2)*AU34)/100),2)) -> 32.82 | AA34: -1 | AB34: =ROUND((AC34+AD34+AF34),6) -> 53.89 | AC34: =ROUND((ES34),6) -> 4.19 | AD34: =ROUND((((ET34)-(EU34))+AE34),6) -> 7.56 | AE34: =ROUND((EU34),6) -> 0.59 | AF34: =ROUND((EV34),6) -> 42.14 | AG34: =ROUND((AP34),6) -> 0 | AH34: =(EW34) -> 3.63 | AI34: =(EX34) -> 0 | AJ34: =(AS34) -> 0 | AK34: 53.89 | AL34: 4.19 | AM34: 7.56 | AN34: 0.59 | AO34: 42.14 | AP34: 0 | AQ34: 3.63 | AR34: 0 | AS34: 0 | AT34: 121 | AU34: 72 | AV34: 1.067 | AW34: 1 | AZ34: 1 | BA34: 1 | BB34: 1 | BC34: 1 | BH34: 0 | BI34: 1 | BJ34: ТСН-2001.3 Доп. 72, Сб. 18, т. 8, поз. 1 | BM34: 23 | BN34: 0 | BO34: 3.18-8-1 | BP34: 1 | BQ34: 30 | BR34: 0 | BS34: 1 | BT34: 1 | BU34: 1 | BV34: 1 | BW34: 1 | BX34: 1 | BZ34: 121 | CA34: 72 | CE34: 1566 | CF34: 0 | CG34: 0 | CM34: 0 | CO34: 0 | CP34: =(P34+Q34+S34) -> 57.22 | CQ34: =ROUND((ROUND((AC34*AW34*1),2)*BC34),2) -> 4.19 | CR34: =(ROUND((ROUND(((ET34)*AV34*1),2)*BB34),2)+ROUND((ROUND(((AE34-(EU34))*AV34*1),2)*BS34),2)) -> 8.07 | CS34: =(ROUND((ROUND(((EU34)*AV34*1),2)*BS34),2)+ROUND((ROUND(((AE34-(EU34))*AV34*1),2)*BS34),2)) -> 0.63 | CT34: =ROUND((ROUND((AF34*AV34*1),2)*BA34),2) -> 44.96 | CU34: =AG34 -> 0 | CV34: =(AH34*AV34) -> 3.87321 | CW34: =AI34 -> 0 | CX34: =AJ34 -> 0 | CY34: =(ROUND((((S34+ROUND((ROUND(((EU34)*AV34*1),2)*BS34),2))*AT34)/100),2)+ROUND(((ROUND((ROUND(((AE34-(EU34))*AV34*1),2)*BS34),2)*AT34)/100),2)) -> 55.16 | CZ34: =(ROUND((((S34+ROUND((ROUND(((EU34)*AV34*1),2)*BS34),2))*AU34)/100),2)+ROUND(((ROUND((ROUND(((AE34-(EU34))*AV34*1),2)*BS34),2)*AU34)/100),2)) -> 32.82 | DN34: 0 | DO34: 0 | DP34: 1 | DQ34: 1 | DU34: 1013 | DV34: 1 бак | DW34: 1 бак | DX34: 1 | EE34: 85133369 | EF34: 30 | EG34: Строительные работы | EH34: 0 | EJ34: 1 | EK34: 23 | EL34: ТСН-2001.3-18. Отопление - внутренние устройства | EM34: ТСН-2001.3-18-1 | EQ34: 1024 | ER34: 53.89 | ES34: 4.19 | ET34: 7.56 | EU34: 0.59 | EV34: 42.14 | EW34: 3.63 | EX34: 0 | EY34: 0 | FQ34: 0 | FR34: 0 | FS34: 0 | FX34: 121 | FY34: 72 | GD34: 1 | GF34: 1630609332 | GG34: 2 | GH34: 1 | GI34: 2 | GJ34: 0 | GK34: 0 | GL34: =ROUND(IF(AND(BH34=3,BI34=3,FS34<>0),P34,0),2) -> 0 | GM34: =ROUND(O34+X34+Y34,2)+GX34 -> 145.2 | GN34: =IF(OR(BI34=0,BI34=1),GM34-GX34,0) -> 145.2 | GO34: =IF(BI34=2,GM34-GX34,0) -> 0 | GP34: =IF(BI34=4,GM34-GX34,0) -> 0 | GR34: 0 | GS34: 3 | GT34: 0 | GV34: =ROUND((GT34),6) -> 0 | GW34: 1 | GX34: =ROUND(HC34*I34,2) -> 0 | HA34: 0 | HB34: 0 | HC34: =GV34*GW34 -> 0 | HS34: 0 | IK34: 0
A35: 17 | B35: 1 | C35: =ROW(SmtRes!A58) -> 58 | D35: =ROW(EtalonRes!A64) -> 64 | F35: 3.18-8-1 | G35: Установка баков расширительных круглых и прямоугольных вместимостью до 0,1 м3 (60 л.) | H35: 1 бак | I35: 1 | J35: 0 | K35: 1 | O35: =ROUND(CP35,2) -> 2672.58 | P35: =ROUND((ROUND((AC35*AW35*I35),2)*BC35),2) -> 24.89 | Q35: =(ROUND((ROUND(((ET35)*AV35*I35),2)*BB35),2)+ROUND((ROUND(((AE35-(EU35))*AV35*I35),2)*BS35),2)) -> 114.19 | R35: =(ROUND((ROUND(((EU35)*AV35*I35),2)*BS35),2)+ROUND((ROUND(((AE35-(EU35))*AV35*I35),2)*BS35),2)) -> 35.5 | S35: =ROUND((ROUND((AF35*AV35*I35),2)*BA35),2) -> 2533.5 | T35: =ROUND(CU35*I35,2) -> 0 | U35: =CV35*I35 -> 3.87321 | V35: =CW35*I35 -> 0 | W35: =ROUND(CX35*I35,2) -> 0 | X35: =(ROUND((((S35+ROUND((ROUND(((EU35)*AV35*I35),2)*BS35),2))*AT35)/100),2)+ROUND(((ROUND((ROUND(((AE35-(EU35))*AV35*I35),2)*BS35),2)*AT35)/100),2)) -> 3108.49 | Y35: =(ROUND((((S35+ROUND((ROUND(((EU35)*AV35*I35),2)*BS35),2))*AU35)/100),2)+ROUND(((ROUND((ROUND(((AE35-(EU35))*AV35*I35),2)*BS35),2)*AU35)/100),2)) -> 1849.68 | AA35: -1 | AB35: =ROUND((AC35+AD35+AF35),6) -> 53.89 | AC35: =ROUND((ES35),6) -> 4.19 | AD35: =ROUND((((ET35)-(EU35))+AE35),6) -> 7.56 | AE35: =ROUND((EU35),6) -> 0.59 | AF35: =ROUND((EV35),6) -> 42.14 | AG35: =ROUND((AP35),6) -> 0 | AH35: =(EW35) -> 3.63 | AI35: =(EX35) -> 0 | AJ35: =(AS35) -> 0 | AK35: 53.89 | AL35: 4.19 | AM35: 7.56 | AN35: 0.59 | AO35: 42.14 | AP35: 0 | AQ35: 3.63 | AR35: 0 | AS35: 0 | AT35: 121 | AU35: 72 | AV35: 1.067 | AW35: 1 | AZ35: 1 | BA35: 56.35 | BB35: 14.15 | BC35: 5.94 | BH35: 0 | BI35: 1 | BJ35: ТСН-2001.3 Доп. 72, Сб. 18, т. 8, поз. 1 | BM35: 23 | BN35: 0 | BO35: 3.18-8-1 | BP35: 1 | BQ35: 30 | BR35: 0 | BS35: 56.35 | BT35: 1 | BU35: 1 | BV35: 1 | BW35: 1 | BX35: 1 | BZ35: 121 | CA35: 72 | CE35: 1566 | CF35: 0 | CG35: 0 | CM35: 0 | CO35: 0 | CP35: =(P35+Q35+S35) -> 2672.58 | CQ35: =ROUND((ROUND((AC35*AW35*1),2)*BC35),2) -> 24.89 | CR35: =(ROUND((ROUND(((ET35)*AV35*1),2)*BB35),2)+ROUND((ROUND(((AE35-(EU35))*AV35*1),2)*BS35),2)) -> 114.19 | CS35: =(ROUND((ROUND(((EU35)*AV35*1),2)*BS35),2)+ROUND((ROUND(((AE35-(EU35))*AV35*1),2)*BS35),2)) -> 35.5 | CT35: =ROUND((ROUND((AF35*AV35*1),2)*BA35),2) -> 2533.5 | CU35: =AG35 -> 0 | CV35: =(AH35*AV35) -> 3.87321 | CW35: =AI35 -> 0 | CX35: =AJ35 -> 0 | CY35: =(ROUND((((S35+ROUND((ROUND(((EU35)*AV35*1),2)*BS35),2))*AT35)/100),2)+ROUND(((ROUND((ROUND(((AE35-(EU35))*AV35*1),2)*BS35),2)*AT35)/100),2)) -> 3108.49 | CZ35: =(ROUND((((S35+ROUND((ROUND(((EU35)*AV35*1),2)*BS35),2))*AU35)/100),2)+ROUND(((ROUND((ROUND(((AE35-(EU35))*AV35*1),2)*BS35),2)*AU35)/100),2)) -> 1849.68 | DN35: 0 | DO35: 0 | DP35: 1 | DQ35: 1 | DU35: 1013 | DV35: 1 бак | DW35: 1 бак | DX35: 1 | EE35: 85133369 | EF35: 30 | EG35: Строительные работы | EH35: 0 | EJ35: 1 | EK35: 23 | EL35: ТСН-2001.3-18. Отопление - внутренние устройства | EM35: ТСН-2001.3-18-1 | EQ35: 1024 | ER35: 53.89 | ES35: 4.19 | ET35: 7.56 | EU35: 0.59 | EV35: 42.14 | EW35: 3.63 | EX35: 0 | EY35: 0 | FQ35: 0 | FR35: 0 | FS35: 0 | FX35: 121 | FY35: 72 | GD35: 1 | GF35: 1630609332 | GG35: 2 | GH35: 1 | GI35: 2 | GJ35: 0 | GK35: 0 | GL35: =ROUND(IF(AND(BH35=3,BI35=3,FS35<>0),P35,0),2) -> 0 | GM35: =ROUND(O35+X35+Y35,2)+GX35 -> 7630.75 | GN35: =IF(OR(BI35=0,BI35=1),GM35-GX35,0) -> 7630.75 | GO35: =IF(BI35=2,GM35-GX35,0) -> 0 | GP35: =IF(BI35=4,GM35-GX35,0) -> 0 | GR35: 0 | GS35: 3 | GT35: 0 | GV35: =ROUND((GT35),6) -> 0 | GW35: 1 | GX35: =ROUND(HC35*I35,2) -> 0 | HA35: 0 | HB35: 0 | HC35: =GV35*GW35 -> 0 | HS35: 0 | IK35: 0
A36: 17 | B36: 1 | C36: =ROW(SmtRes!A65) -> 65 | D36: =ROW(EtalonRes!A73) -> 73 | E36: 4 | F36: 4.8-240-4 | G36: Монтаж пультов и шкафов управления, шкафа (пульта) управления навесного, высотой, шириной, глубиной до 600х600х350 мм | H36: 1 ШТ. | I36: 1 | J36: 0 | K36: 1 | O36: =ROUND(CP36,2) -> 56.97 | P36: =ROUND((ROUND((AC36*AW36*I36),2)*BC36),2) -> 1.46 | Q36: =(ROUND((ROUND((((ET36*1.2))*AV36*I36),2)*BB36),2)+ROUND((ROUND(((AE36-((EU36*1.2)))*AV36*I36),2)*BS36),2)) -> 21.89 | R36: =(ROUND((ROUND((((EU36*1.2))*AV36*I36),2)*BS36),2)+ROUND((ROUND(((AE36-((EU36*1.2)))*AV36*I36),2)*BS36),2)) -> 3.97 | S36: =ROUND((ROUND((AF36*AV36*I36),2)*BA36),2) -> 33.62 | T36: =ROUND(CU36*I36,2) -> 0 | U36: =CV36*I36 -> 2.588184 | V36: =CW36*I36 -> 0 | W36: =ROUND(CX36*I36,2) -> 0 | X36: =(ROUND((((S36+ROUND((ROUND((((EU36*1.2))*AV36*I36),2)*BS36),2))*AT36)/100),2)+ROUND(((ROUND((ROUND(((AE36-((EU36*1.2)))*AV36*I36),2)*BS36),2)*AT36)/100),2)) -> 36.46 | Y36: =(ROUND((((S36+ROUND((ROUND((((EU36*1.2))*AV36*I36),2)*BS36),2))*AU36)/100),2)+ROUND(((ROUND((ROUND(((AE36-((EU36*1.2)))*AV36*I36),2)*BS36),2)*AU36)/100),2)) -> 19.17 | AA36: 85739205 | AB36: =ROUND((AC36+AD36+AF36),6) -> 54.476 | AC36: =ROUND(((ES36*1)),6) -> 1.46 | AD36: =ROUND(((((ET36*1.2))-((EU36*1.2)))+AE36),6) -> 20.904 | AE36: =ROUND(((EU36*1.2)),6) -> 3.792 | AF36: =ROUND(((EV36*1.2)),6) -> 32.112 | AG36: =ROUND((AP36),6) -> 0 | AH36: =((EW36*1.2)) -> 2.472 | AI36: =((EX36*1.2)) -> 0 | AJ36: =(AS36) -> 0 | AK36: 45.64 | AL36: 1.46 | AM36: 17.42 | AN36: 3.16 | AO36: 26.76 | AP36: 0 | AQ36: 2.06 | AR36: 0 | AS36: 0 | AT36: 97 | AU36: 51 | AV36: 1.047 | AW36: 1 | AZ36: 1 | BA36: 1 | BB36: 1 | BC36: 1 | BH36: 0 | BI36: 2 | BJ36: ТСН-2001.4 Доп. 80, Сб. 8, т. 240, поз. 4 | BM36: 67 | BN36: 0 | BO36: 4.8-240-4 | BP36: 1 | BQ36: 40 | BR36: 0 | BS36: 1 | BT36: 1 | BU36: 1 | BV36: 1 | BW36: 1 | BX36: 1 | BZ36: 97 | CA36: 51 | CE36: 1566 | CF36: 0 | CG36: 0 | CM36: 0 | CN36: Поправка: Гл.12.Прил.8.п.8. 3_12.00.01.11.001 Наименование: При наличии напряженных и стесненных условий производства работ (стесненность, сложность складирования и транспортной логистики и т.п.) для объектов, расположенных в пределах круговой магистральной системы улиц "Садовое кольцо" города Москвы | CO36: 0 | CP36: =(P36+Q36+S36) -> 56.97 | CQ36: =ROUND((ROUND((AC36*AW36*1),2)*BC36),2) -> 1.46 | CR36: =(ROUND((ROUND((((ET36*1.2))*AV36*1),2)*BB36),2)+ROUND((ROUND(((AE36-((EU36*1.2)))*AV36*1),2)*BS36),2)) -> 21.89 | CS36: =(ROUND((ROUND((((EU36*1.2))*AV36*1),2)*BS36),2)+ROUND((ROUND(((AE36-((EU36*1.2)))*AV36*1),2)*BS36),2)) -> 3.97 | CT36: =ROUND((ROUND((AF36*AV36*1),2)*BA36),2) -> 33.62 | CU36: =AG36 -> 0 | CV36: =(AH36*AV36) -> 2.588184 | CW36: =AI36 -> 0 | CX36: =AJ36 -> 0 | CY36: =(ROUND((((S36+ROUND((ROUND((((EU36*1.2))*AV36*1),2)*BS36),2))*AT36)/100),2)+ROUND(((ROUND((ROUND(((AE36-((EU36*1.2)))*AV36*1),2)*BS36),2)*AT36)/100),2)) -> 36.46 | CZ36: =(ROUND((((S36+ROUND((ROUND((((EU36*1.2))*AV36*1),2)*BS36),2))*AU36)/100),2)+ROUND(((ROUND((ROUND(((AE36-((EU36*1.2)))*AV36*1),2)*BS36),2)*AU36)/100),2)) -> 19.17 | DB36: 9 | DD36: *1 | DE36: *1,2 | DF36: *1,2 | DG36: *1,2 | DI36: *1,2 | DJ36: *1,2 | DN36: 0 | DO36: 0 | DP36: 1 | DQ36: 1 | DU36: 1013 | DV36: 1 ШТ. | DW36: 1 ШТ. | DX36: 1 | EE36: 85133416 | EF36: 40 | EG36: Монтаж оборудования | EH36: 0 | EJ36: 2 | EK36: 67 | EL36: ТСН-2001.4-8. Электротехнические установки | EM36: ТСН-2001.4-8-1 | EO36: Поправка: Гл.12.Прил.8.п.8. 3_12.00.01.11.001 | EQ36: 0 | ER36: 45.64 | ES36: 1.46 | ET36: 17.42 | EU36: 3.16 | EV36: 26.76 | EW36: 2.06 | EX36: 0 | EY36: 0 | FQ36: 0 | FR36: 0 | FS36: 0 | FX36: 97 | FY36: 51 | GD36: 1 | GF36: -1842782186 | GG36: 2 | GH36: 1 | GI36: 2 | GJ36: 0 | GK36: 0 | GL36: =ROUND(IF(AND(BH36=3,BI36=3,FS36<>0),P36,0),2) -> 0 | GM36: =ROUND(O36+X36+Y36,2)+GX36 -> 112.6 | GN36: =IF(OR(BI36=0,BI36=1),GM36-GX36,0) -> 0 | GO36: =IF(BI36=2,GM36-GX36,0) -> 112.6 | GP36: =IF(BI36=4,GM36-GX36,0) -> 0 | GR36: 0 | GS36: 3 | GT36: 0 | GV36: =ROUND((GT36),6) -> 0 | GW36: 1 | GX36: =ROUND(HC36*I36,2) -> 0 | HA36: 0 | HB36: 0 | HC36: =GV36*GW36 -> 0 | HS36: 0 | IK36: 0
A37: 17 | B37: 1 | C37: =ROW(SmtRes!A72) -> 72 | D37: =ROW(EtalonRes!A82) -> 82 | E37: 4 | F37: 4.8-240-4 | G37: Монтаж пультов и шкафов управления, шкафа (пульта) управления навесного, высотой, шириной, глубиной до 600х600х350 мм | H37: 1 ШТ. | I37: 1 | J37: 0 | K37: 1 | O37: =ROUND(CP37,2) -> 2346.01 | P37: =ROUND((ROUND((AC37*AW37*I37),2)*BC37),2) -> 16.13 | Q37: =(ROUND((ROUND((((ET37*1.2))*AV37*I37),2)*BB37),2)+ROUND((ROUND(((AE37-((EU37*1.2)))*AV37*I37),2)*BS37),2)) -> 435.39 | R37: =(ROUND((ROUND((((EU37*1.2))*AV37*I37),2)*BS37),2)+ROUND((ROUND(((AE37-((EU37*1.2)))*AV37*I37),2)*BS37),2)) -> 223.71 | S37: =ROUND((ROUND((AF37*AV37*I37),2)*BA37),2) -> 1894.49 | T37: =ROUND(CU37*I37,2) -> 0 | U37: =CV37*I37 -> 2.588184 | V37: =CW37*I37 -> 0 | W37: =ROUND(CX37*I37,2) -> 0 | X37: =(ROUND((((S37+ROUND((ROUND((((EU37*1.2))*AV37*I37),2)*BS37),2))*AT37)/100),2)+ROUND(((ROUND((ROUND(((AE37-((EU37*1.2)))*AV37*I37),2)*BS37),2)*AT37)/100),2)) -> 2054.65 | Y37: =(ROUND((((S37+ROUND((ROUND((((EU37*1.2))*AV37*I37),2)*BS37),2))*AU37)/100),2)+ROUND(((ROUND((ROUND(((AE37-((EU37*1.2)))*AV37*I37),2)*BS37),2)*AU37)/100),2)) -> 1080.28 | AA37: 85739207 | AB37: =ROUND((AC37+AD37+AF37),6) -> 54.476 | AC37: =ROUND(((ES37*1)),6) -> 1.46 | AD37: =ROUND(((((ET37*1.2))-((EU37*1.2)))+AE37),6) -> 20.904 | AE37: =ROUND(((EU37*1.2)),6) -> 3.792 | AF37: =ROUND(((EV37*1.2)),6) -> 32.112 | AG37: =ROUND((AP37),6) -> 0 | AH37: =((EW37*1.2)) -> 2.472 | AI37: =((EX37*1.2)) -> 0 | AJ37: =(AS37) -> 0 | AK37: 45.64 | AL37: 1.46 | AM37: 17.42 | AN37: 3.16 | AO37: 26.76 | AP37: 0 | AQ37: 2.06 | AR37: 0 | AS37: 0 | AT37: 97 | AU37: 51 | AV37: 1.047 | AW37: 1 | AZ37: 1 | BA37: 56.35 | BB37: 19.89 | BC37: 11.05 | BH37: 0 | BI37: 2 | BJ37: ТСН-2001.4 Доп. 80, Сб. 8, т. 240, поз. 4 | BM37: 67 | BN37: 0 | BO37: 4.8-240-4 | BP37: 1 | BQ37: 40 | BR37: 0 | BS37: 56.35 | BT37: 1 | BU37: 1 | BV37: 1 | BW37: 1 | BX37: 1 | BZ37: 97 | CA37: 51 | CE37: 1566 | CF37: 0 | CG37: 0 | CM37: 0 | CN37: Поправка: Гл.12.Прил.8.п.8. 3_12.00.01.11.001 Наименование: При наличии напряженных и стесненных условий производства работ (стесненность, сложность складирования и транспортной логистики и т.п.) для объектов, расположенных в пределах круговой магистральной системы улиц "Садовое кольцо" города Москвы | CO37: 0 | CP37: =(P37+Q37+S37) -> 2346.01 | CQ37: =ROUND((ROUND((AC37*AW37*1),2)*BC37),2) -> 16.13 | CR37: =(ROUND((ROUND((((ET37*1.2))*AV37*1),2)*BB37),2)+ROUND((ROUND(((AE37-((EU37*1.2)))*AV37*1),2)*BS37),2)) -> 435.39 | CS37: =(ROUND((ROUND((((EU37*1.2))*AV37*1),2)*BS37),2)+ROUND((ROUND(((AE37-((EU37*1.2)))*AV37*1),2)*BS37),2)) -> 223.71 | CT37: =ROUND((ROUND((AF37*AV37*1),2)*BA37),2) -> 1894.49 | CU37: =AG37 -> 0 | CV37: =(AH37*AV37) -> 2.588184 | CW37: =AI37 -> 0 | CX37: =AJ37 -> 0 | CY37: =(ROUND((((S37+ROUND((ROUND((((EU37*1.2))*AV37*1),2)*BS37),2))*AT37)/100),2)+ROUND(((ROUND((ROUND(((AE37-((EU37*1.2)))*AV37*1),2)*BS37),2)*AT37)/100),2)) -> 2054.65 | CZ37: =(ROUND((((S37+ROUND((ROUND((((EU37*1.2))*AV37*1),2)*BS37),2))*AU37)/100),2)+ROUND(((ROUND((ROUND(((AE37-((EU37*1.2)))*AV37*1),2)*BS37),2)*AU37)/100),2)) -> 1080.28 | DB37: 10 | DD37: *1 | DE37: *1,2 | DF37: *1,2 | DG37: *1,2 | DI37: *1,2 | DJ37: *1,2 | DN37: 0 | DO37: 0 | DP37: 1 | DQ37: 1 | DU37: 1013 | DV37: 1 ШТ. | DW37: 1 ШТ. | DX37: 1 | EE37: 85133416 | EF37: 40 | EG37: Монтаж оборудования | EH37: 0 | EJ37: 2 | EK37: 67 | EL37: ТСН-2001.4-8. Электротехнические установки | EM37: ТСН-2001.4-8-1 | EO37: Поправка: Гл.12.Прил.8.п.8. 3_12.00.01.11.001 | EQ37: 0 | ER37: 45.64 | ES37: 1.46 | ET37: 17.42 | EU37: 3.16 | EV37: 26.76 | EW37: 2.06 | EX37: 0 | EY37: 0 | FQ37: 0 | FR37: 0 | FS37: 0 | FX37: 97 | FY37: 51 | GD37: 1 | GF37: -1842782186 | GG37: 2 | GH37: 1 | GI37: 2 | GJ37: 0 | GK37: 0 | GL37: =ROUND(IF(AND(BH37=3,BI37=3,FS37<>0),P37,0),2) -> 0 | GM37: =ROUND(O37+X37+Y37,2)+GX37 -> 5480.94 | GN37: =IF(OR(BI37=0,BI37=1),GM37-GX37,0) -> 0 | GO37: =IF(BI37=2,GM37-GX37,0) -> 5480.94 | GP37: =IF(BI37=4,GM37-GX37,0) -> 0 | GR37: 0 | GS37: 3 | GT37: 0 | GV37: =ROUND((GT37),6) -> 0 | GW37: 1 | GX37: =ROUND(HC37*I37,2) -> 0 | HA37: 0 | HB37: 0 | HC37: =GV37*GW37 -> 0 | HS37: 0 | IK37: 0
A38: 17 | B38: 1 | C38: =ROW(SmtRes!A75) -> 75 | D38: =ROW(EtalonRes!A87) -> 87 | E38: 5 | F38: 4.12-48-9 | G38: Монтаж арматуры фланцевой с ручным приводом или без привода на номинальное давление до 4 МПа, номинальный диаметр прохода 80 мм (обратный клапан, затвор поворотный) | H38: 1 ШТ. | I38: =ROUND(2+4,9) -> 6 | J38: 0 | K38: =ROUND(2+4,9) -> 6 | O38: =ROUND(CP38,2) -> 417.65 | P38: =ROUND((ROUND((AC38*AW38*I38),2)*BC38),2) -> 17.09 | Q38: =(ROUND((ROUND((((ET38*1.2))*AV38*I38),2)*BB38),2)+ROUND((ROUND(((AE38-((EU38*1.2)))*AV38*I38),2)*BS38),2)) -> 12.75 | R38: =(ROUND((ROUND((((EU38*1.2))*AV38*I38),2)*BS38),2)+ROUND((ROUND(((AE38-((EU38*1.2)))*AV38*I38),2)*BS38),2)) -> 1.92 | S38: =ROUND((ROUND((AF38*AV38*I38),2)*BA38),2) -> 387.81 | T38: =ROUND(CU38*I38,2) -> 0 | U38: =CV38*I38 -> 30.7296 | V38: =CW38*I38 -> 0 | W38: =ROUND(CX38*I38,2) -> 0 | X38: =(ROUND((((S38+ROUND((ROUND((((EU38*1.2))*AV38*I38),2)*BS38),2))*AT38)/100),2)+ROUND(((ROUND((ROUND(((AE38-((EU38*1.2)))*AV38*I38),2)*BS38),2)*AT38)/100),2)) -> 350.76 | Y38: =(ROUND((((S38+ROUND((ROUND((((EU38*1.2))*AV38*I38),2)*BS38),2))*AU38)/100),2)+ROUND(((ROUND((ROUND(((AE38-((EU38*1.2)))*AV38*I38),2)*BS38),2)*AU38)/100),2)) -> 179.28 | AA38: 85739205 | AB38: =ROUND((AC38+AD38+AF38),6) -> 65.338 | AC38: =ROUND(((ES38*1)),6) -> 2.77 | AD38: =ROUND(((((ET38*1.2))-((EU38*1.2)))+AE38),6) -> 1.992 | AE38: =ROUND(((EU38*1.2)),6) -> 0.3 | AF38: =ROUND(((EV38*1.2)),6) -> 60.576 | AG38: =ROUND((AP38),6) -> 0 | AH38: =((EW38*1.2)) -> 4.8 | AI38: =((EX38*1.2)) -> 0 | AJ38: =(AS38) -> 0 | AK38: 54.91 | AL38: 2.77 | AM38: 1.66 | AN38: 0.25 | AO38: 50.48 | AP38: 0 | AQ38: 4 | AR38: 0 | AS38: 0 | AT38: 90 | AU38: 46 | AV38: 1.067 | AW38: 1.028 | AZ38: 1 | BA38: 1 | BB38: 1 | BC38: 1 | BH38: 0 | BI38: 2 | BJ38: ТСН-2001.4 Доп. 68, Сб. 12, т. 48, поз. 9 | BM38: 73 | BN38: 0 | BO38: 4.12-48-9 | BP38: 1 | BQ38: 40 | BR38: 0 | BS38: 1 | BT38: 1 | BU38: 1 | BV38: 1 | BW38: 1 | BX38: 1 | BZ38: 90 | CA38: 46 | CE38: 1566 | CF38: 0 | CG38: 0 | CM38: 0 | CN38: Поправка: Гл.12.Прил.8.п.8. 3_12.00.01.11.001 Наименование: При наличии напряженных и стесненных условий производства работ (стесненность, сложность складирования и транспортной логистики и т.п.) для объектов, расположенных в пределах круговой магистральной системы улиц "Садовое кольцо" города Москвы | CO38: 0 | CP38: =(P38+Q38+S38) -> 417.65 | CQ38: =ROUND((ROUND((AC38*AW38*1),2)*BC38),2) -> 2.85 | CR38: =(ROUND((ROUND((((ET38*1.2))*AV38*1),2)*BB38),2)+ROUND((ROUND(((AE38-((EU38*1.2)))*AV38*1),2)*BS38),2)) -> 2.13 | CS38: =(ROUND((ROUND((((EU38*1.2))*AV38*1),2)*BS38),2)+ROUND((ROUND(((AE38-((EU38*1.2)))*AV38*1),2)*BS38),2)) -> 0.32 | CT38: =ROUND((ROUND((AF38*AV38*1),2)*BA38),2) -> 64.63 | CU38: =AG38 -> 0 | CV38: =(AH38*AV38) -> 5.1216 | CW38: =AI38 -> 0 | CX38: =AJ38 -> 0 | CY38: =(ROUND((((S38+ROUND((ROUND((((EU38*1.2))*AV38*1),2)*BS38),2))*AT38)/100),2)+ROUND(((ROUND((ROUND(((AE38-((EU38*1.2)))*AV38*1),2)*BS38),2)*AT38)/100),2)) -> 349.32 | CZ38: =(ROUND((((S38+ROUND((ROUND((((EU38*1.2))*AV38*1),2)*BS38),2))*AU38)/100),2)+ROUND(((ROUND((ROUND(((AE38-((EU38*1.2)))*AV38*1),2)*BS38),2)*AU38)/100),2)) -> 178.54 | DB38: 11 | DD38: *1 | DE38: *1,2 | DF38: *1,2 | DG38: *1,2 | DI38: *1,2 | DJ38: *1,2 | DN38: 0 | DO38: 0 | DP38: 1 | DQ38: 1 | DU38: 1013 | DV38: 1 ШТ. | DW38: 1 ШТ. | DX38: 1 | EE38: 85133422 | EF38: 40 | EG38: Монтаж оборудования | EH38: 0 | EJ38: 2 | EK38: 73 | EL38: ТСН-2001.4-12. Технологические трубопроводы | EM38: ТСН-2001.4-12-1 | EO38: Поправка: Гл.12.Прил.8.п.8. 3_12.00.01.11.001 | EQ38: 0 | ER38: 54.91 | ES38: 2.77 | ET38: 1.66 | EU38: 0.25 | EV38: 50.48 | EW38: 4 | EX38: 0 | EY38: 0 | FQ38: 0 | FR38: 0 | FS38: 2 | FX38: 90 | FY38: 46 | GD38: 1 | GF38: 742127146 | GG38: 2 | GH38: 1 | GI38: 2 | GJ38: 0 | GK38: 0 | GL38: =ROUND(IF(AND(BH38=3,BI38=3,FS38<>0),P38,0),2) -> 0 | GM38: =ROUND(O38+X38+Y38,2)+GX38 -> 947.69 | GN38: =IF(OR(BI38=0,BI38=1),GM38-GX38,0) -> 0 | GO38: =IF(BI38=2,GM38-GX38,0) -> 947.69 | GP38: =IF(BI38=4,GM38-GX38,0) -> 0 | GR38: 0 | GS38: 3 | GT38: 0 | GV38: =ROUND((GT38),6) -> 0 | GW38: 1 | GX38: =ROUND(HC38*I38,2) -> 0 | HA38: 0 | HB38: 0 | HC38: =GV38*GW38 -> 0 | HS38: 0 | IK38: 0
A39: 17 | B39: 1 | C39: =ROW(SmtRes!A78) -> 78 | D39: =ROW(EtalonRes!A92) -> 92 | E39: 5 | F39: 4.12-48-9 | G39: Монтаж арматуры фланцевой с ручным приводом или без привода на номинальное давление до 4 МПа, номинальный диаметр прохода 80 мм (обратный клапан, затвор поворотный) | H39: 1 ШТ. | I39: =ROUND(2+4,9) -> 6 | J39: 0 | K39: =ROUND(2+4,9) -> 6 | O39: =ROUND(CP39,2) -> 22147.9 | P39: =ROUND((ROUND((AC39*AW39*I39),2)*BC39),2) -> 76.91 | Q39: =(ROUND((ROUND((((ET39*1.2))*AV39*I39),2)*BB39),2)+ROUND((ROUND(((AE39-((EU39*1.2)))*AV39*I39),2)*BS39),2)) -> 217.9 | R39: =(ROUND((ROUND((((EU39*1.2))*AV39*I39),2)*BS39),2)+ROUND((ROUND(((AE39-((EU39*1.2)))*AV39*I39),2)*BS39),2)) -> 108.19 | S39: =ROUND((ROUND((AF39*AV39*I39),2)*BA39),2) -> 21853.09 | T39: =ROUND(CU39*I39,2) -> 0 | U39: =CV39*I39 -> 30.7296 | V39: =CW39*I39 -> 0 | W39: =ROUND(CX39*I39,2) -> 0 | X39: =(ROUND((((S39+ROUND((ROUND((((EU39*1.2))*AV39*I39),2)*BS39),2))*AT39)/100),2)+ROUND(((ROUND((ROUND(((AE39-((EU39*1.2)))*AV39*I39),2)*BS39),2)*AT39)/100),2)) -> 19765.15 | Y39: =(ROUND((((S39+ROUND((ROUND((((EU39*1.2))*AV39*I39),2)*BS39),2))*AU39)/100),2)+ROUND(((ROUND((ROUND(((AE39-((EU39*1.2)))*AV39*I39),2)*BS39),2)*AU39)/100),2)) -> 10102.19 | AA39: 85739207 | AB39: =ROUND((AC39+AD39+AF39),6) -> 65.338 | AC39: =ROUND(((ES39*1)),6) -> 2.77 | AD39: =ROUND(((((ET39*1.2))-((EU39*1.2)))+AE39),6) -> 1.992 | AE39: =ROUND(((EU39*1.2)),6) -> 0.3 | AF39: =ROUND(((EV39*1.2)),6) -> 60.576 | AG39: =ROUND((AP39),6) -> 0 | AH39: =((EW39*1.2)) -> 4.8 | AI39: =((EX39*1.2)) -> 0 | AJ39: =(AS39) -> 0 | AK39: 54.91 | AL39: 2.77 | AM39: 1.66 | AN39: 0.25 | AO39: 50.48 | AP39: 0 | AQ39: 4 | AR39: 0 | AS39: 0 | AT39: 90 | AU39: 46 | AV39: 1.067 | AW39: 1.028 | AZ39: 1 | BA39: 56.35 | BB39: 17.09 | BC39: 4.5 | BH39: 0 | BI39: 2 | BJ39: ТСН-2001.4 Доп. 68, Сб. 12, т. 48, поз. 9 | BM39: 73 | BN39: 0 | BO39: 4.12-48-9 | BP39: 1 | BQ39: 40 | BR39: 0 | BS39: 56.35 | BT39: 1 | BU39: 1 | BV39: 1 | BW39: 1 | BX39: 1 | BZ39: 90 | CA39: 46 | CE39: 1566 | CF39: 0 | CG39: 0 | CM39: 0 | CN39: Поправка: Гл.12.Прил.8.п.8. 3_12.00.01.11.001 Наименование: При наличии напряженных и стесненных условий производства работ (стесненность, сложность складирования и транспортной логистики и т.п.) для объектов, расположенных в пределах круговой магистральной системы улиц "Садовое кольцо" города Москвы | CO39: 0 | CP39: =(P39+Q39+S39) -> 22147.9 | CQ39: =ROUND((ROUND((AC39*AW39*1),2)*BC39),2) -> 12.83 | CR39: =(ROUND((ROUND((((ET39*1.2))*AV39*1),2)*BB39),2)+ROUND((ROUND(((AE39-((EU39*1.2)))*AV39*1),2)*BS39),2)) -> 36.4 | CS39: =(ROUND((ROUND((((EU39*1.2))*AV39*1),2)*BS39),2)+ROUND((ROUND(((AE39-((EU39*1.2)))*AV39*1),2)*BS39),2)) -> 18.03 | CT39: =ROUND((ROUND((AF39*AV39*1),2)*BA39),2) -> 3641.9 | CU39: =AG39 -> 0 | CV39: =(AH39*AV39) -> 5.1216 | CW39: =AI39 -> 0 | CX39: =AJ39 -> 0 | CY39: =(ROUND((((S39+ROUND((ROUND((((EU39*1.2))*AV39*1),2)*BS39),2))*AT39)/100),2)+ROUND(((ROUND((ROUND(((AE39-((EU39*1.2)))*AV39*1),2)*BS39),2)*AT39)/100),2)) -> 19684.01 | CZ39: =(ROUND((((S39+ROUND((ROUND((((EU39*1.2))*AV39*1),2)*BS39),2))*AU39)/100),2)+ROUND(((ROUND((ROUND(((AE39-((EU39*1.2)))*AV39*1),2)*BS39),2)*AU39)/100),2)) -> 10060.72 | DB39: 12 | DD39: *1 | DE39: *1,2 | DF39: *1,2 | DG39: *1,2 | DI39: *1,2 | DJ39: *1,2 | DN39: 0 | DO39: 0 | DP39: 1 | DQ39: 1 | DU39: 1013 | DV39: 1 ШТ. | DW39: 1 ШТ. | DX39: 1 | EE39: 85133422 | EF39: 40 | EG39: Монтаж оборудования | EH39: 0 | EJ39: 2 | EK39: 73 | EL39: ТСН-2001.4-12. Технологические трубопроводы | EM39: ТСН-2001.4-12-1 | EO39: Поправка: Гл.12.Прил.8.п.8. 3_12.00.01.11.001 | EQ39: 0 | ER39: 54.91 | ES39: 2.77 | ET39: 1.66 | EU39: 0.25 | EV39: 50.48 | EW39: 4 | EX39: 0 | EY39: 0 | FQ39: 0 | FR39: 0 | FS39: 2 | FX39: 90 | FY39: 46 | GD39: 1 | GF39: 742127146 | GG39: 2 | GH39: 1 | GI39: 2 | GJ39: 0 | GK39: 0 | GL39: =ROUND(IF(AND(BH39=3,BI39=3,FS39<>0),P39,0),2) -> 0 | GM39: =ROUND(O39+X39+Y39,2)+GX39 -> 52015.24 | GN39: =IF(OR(BI39=0,BI39=1),GM39-GX39,0) -> 0 | GO39: =IF(BI39=2,GM39-GX39,0) -> 52015.24 | GP39: =IF(BI39=4,GM39-GX39,0) -> 0 | GR39: 0 | GS39: 3 | GT39: 0 | GV39: =ROUND((GT39),6) -> 0 | GW39: 1 | GX39: =ROUND(HC39*I39,2) -> 0 | HA39: 0 | HB39: 0 | HC39: =GV39*GW39 -> 0 | HS39: 0 | IK39: 0
