Workbook

Sheet 02-01-04
A1: =Source!B1 -> Smeta.RU (495) 974-1589
J2: Форма № 4б
A3: =Source!G4 -> Капитальный ремонт здания Государственного бюджетного общеобразовательного учреждения города Москвы «Школа №1574», расположенного по адресу: г. Москва, Старопименовский переулок, д. 5. 1 этап | AP3: Капитальный ремонт здания Государственного бюджетного общеобразовательного учреждения города Москвы «Школа №1574», расположенного по адресу: г. Москва, пер. Старопименовский, д. 5. Водоснабжение.
A4: (наименование стройки и/или объекта)
A6: =CONCATENATE( "ЛОКАЛЬНАЯ СМЕТА № ",IF(Source!F20<>"Новая локальная смета", Source!F20, "")) -> ЛОКАЛЬНАЯ СМЕТА № 02-01-04
A8: =IF(Source!G20<>"Новая локальная смета", Source!G20, "") -> Система водоснабжения.
A9: (наименование работ и затрат)
A11: =CONCATENATE( "Основание: чертежи № ", Source!J20) -> Основание: чертежи № 2024-00375-01-0-ИОС2
I13: В базисном уровне цен | J13: В текущем уровне цен
E14: Сметная стоимость | I14: =I15+I16+I17+I18 -> 335.56 | J14: =J15+J16+J17+J18 -> 6275.41 | K14: тыс.руб.
E15: Строительные работы | I15: =ROUND((Source!F688)/1000, 2) -> 303.96 | J15: =ROUND((Source!P688)/1000, 2) -> 6036.17 | K15: тыс.руб.
E16: Работы по монтажу оборудования | I16: =ROUND((Source!F689)/1000, 2) -> 0 | J16: =ROUND((Source!P689)/1000, 2) -> 0 | K16: тыс.руб.
E17: Оборудование | I17: =ROUND((Source!F680)/1000, 2) -> 31.6 | J17: =ROUND((Source!P680)/1000, 2) -> 239.24 | K17: тыс.руб.
E18: Прочие работы и затраты | I18: =ROUND((Source!F690+Source!F691)/1000, 2) -> 0 | J18: =ROUND((Source!P690+Source!P691)/1000, 2) -> 0 | K18: тыс.руб.
E19: Средства на оплату труда | I19: =(Source!F686+ Source!F685)/1000 -> 25.94258 | J19: =((Source!P686 + Source!P685)/1000) -> 1461.8644 | K19: тыс.руб.
E20: Затраты труда | I20: =Source!F693 -> 2104.7977 | K20: чел.-ч.
E21: Кроме того:
E22: Возврат материалов | I22: =SUM(Y28:Y954)/1000 -> 0 | J22: =SUM(Z28:Z954)/1000 -> 0 | K22: тыс.руб.
A24: Составлен(а) по ТСН-2001 с учетом Дополнения №: 81
A25: № и период сборника коэффициентов (индексов) пересчета: Коэффициенты к ТСН-2001 МГЭ Дополнение 81, ремонт №219/81 I квартал 2026 года и Коэффициенты к ТСН-2001.13-2 Дополнение 47 №64/47 I квартал 2026 года | AP25: № и период сборника коэффициентов (индексов) пересчета: Коэффициенты к ТСН-2001 МГЭ Дополнение 81, ремонт №219/81 I квартал 2026 года и Коэффициенты к ТСН-2001.13-2 Дополнение 47 №64/47 I квартал 2026 года
A26: № п/п | B26: Шифр расценки и коды ресурсов | C26: Наименование работ и затрат | D26: Ед. изм. | E26: Кол-во единиц | F26: Цена на ед. изм., руб. | G26: Попра- вочные коэффи- циенты | H26: Коэффи- циенты зимних удорожа- ний | I26: Всего в ценах на январь 2000 года, руб. | J26: Коэффи- циенты (индек- сы) пере- счета, нормы НР и СП | K26: ВСЕГО затрат в текущем уровне цен, руб.
A27: 1 | B27: 2 | C27: 3 | D27: 4 | E27: 5 | F27: 6 | G27: 7 | H27: 8 | I27: 9 | J27: 10 | K27: 11 | L27: цена за ед с ндс
A29: =CONCATENATE("Раздел: ",IF(Source!G24<>"Новый раздел", Source!G24, "")) -> Раздел: Демонтажные работы.
A30: 1 | B30: =Source!F28 -> 6.65-1-1 | C30: Разборка трубопроводов из водогазопроводных труб диаметром до 25 мм | D30: =Source!H28 -> 100 м | E30: =Source!I28 -> 7.37 | Q30: =Source!X28 -> 2289.41 | R30: =Source!X29 -> 129008.46 | S30: =Source!Y28 -> 1157.86 | T30: =Source!Y29 -> 65245.66 | U30: =ROUND((175/100)*ROUND(Source!R28, 2), 2) -> 0 | V30: =ROUND((0/100)*ROUND(Source!R29, 2), 2) -> 0 | AC30: 0
C31: ="Объем: "&Source!I28&"=(28+"&"45+"&"35+"&"75+"&"90+"&"75+"&"33+"&"87+"&"25+"&"90+"&"100+"&"54)/"&"100" -> Объем: 7,37=(28+45+35+75+90+75+33+87+25+90+100+54)/100
C32: ЗП | F32: =Source!AO28 -> 284.19 | G32: 1,2 | H32: =Source!AV29 -> 1.047 | I32: =Source!S28 -> 2631.51 | J32: =IF(Source!BA29<> 0, Source!BA29, 1) -> 56.35 | K32: =Source!S29 -> 148285.59
C33: ЭМ | F33: =Source!AM28 -> 0.7 | G33: 1,2 | H33: =Source!AV29 -> 1.047 | I33: =Source!Q28 -> 6.48 | J33: =IF(Source!BB29<> 0, Source!BB29, 1) -> 9.29 | K33: =Source!Q29 -> 60.2
C34: МР | F34: =Source!AL28 -> 32.56 | H34: =Source!AW29 -> 1 | I34: =Source!P28 -> 239.97 | J34: =IF(Source!BC29<> 0, Source!BC29, 1) -> 15.53 | K34: =Source!P29 -> 3726.73
C35: НР от ФОТ | D35: % | E35: =Source!BZ29 -> 87 | I35: =SUM(Q30:Q34) -> 2289.41 | J35: =Source!AT29 -> 87 | K35: =SUM(R30:R34) -> 129008.46
C36: СП от ФОТ | D36: % | E36: =Source!CA29 -> 44 | I36: =SUM(S30:S35) -> 1157.86 | J36: =Source!AU29 -> 44 | K36: =SUM(T30:T35) -> 65245.66
C37: ЗТР | D37: чел-ч | E37: =Source!AQ28 -> 26.56 | G37: 1,2 | H37: =Source!AV29 -> 1.047 | I37: =Source!U28 -> 245.93678
C38: ВСЕГО работ по позиции: | H38: =I32+I33+I34+I35+I36+0-0-0 -> 6325.23 | J38: =K32+K33+K34+K35+K36+0-0-0 -> 346326.64
C39: ВСЕГО оборудование по позиции: | H39: =0+0 -> 0 | J39: =0+0 -> 0
C40: ВСЕГО по позиции: | H40: =I32+I33+I34+I35+I36+0 -> 6325.23 | J40: =K32+K33+K34+K35+K36+0 -> 346326.64 | O40: =I32+I33+I34+I35+I36+0 -> 6325.23 | P40: =K32+K33+K34+K35+K36+0 -> 346326.64
A42: 2 | B42: =Source!F30 -> 6.65-1-2 | C42: Разборка трубопроводов из водогазопроводных труб диаметром до 40 мм | D42: =Source!H30 -> 100 м | E42: =Source!I30 -> 3.31 | Q42: =Source!X30 -> 1793.51 | R42: =Source!X31 -> 101064.01 | S42: =Source!Y30 -> 907.06 | T42: =Source!Y31 -> 51112.83 | U42: =ROUND((175/100)*ROUND(Source!R30, 2), 2) -> 0 | V42: =ROUND((0/100)*ROUND(Source!R31, 2), 2) -> 0 | AC42: 0
C43: ="Объем: "&Source!I30&"=(22+"&"55+"&"50+"&"64+"&"95+"&"45)/"&"100" -> Объем: 3,31=(22+55+50+64+95+45)/100
C44: ЗП | F44: =Source!AO30 -> 495.71 | G44: 1,2 | H44: =Source!AV31 -> 1.047 | I44: =Source!S30 -> 2061.5 | J44: =IF(Source!BA31<> 0, Source!BA31, 1) -> 56.35 | K44: =Source!S31 -> 116165.53
C45: ЭМ | F45: =Source!AM30 -> 1.26 | G45: 1,2 | H45: =Source!AV31 -> 1.047 | I45: =Source!Q30 -> 5.24 | J45: =IF(Source!BB31<> 0, Source!BB31, 1) -> 9.29 | K45: =Source!Q31 -> 48.68
C46: МР | F46: =Source!AL30 -> 46.16 | H46: =Source!AW31 -> 1 | I46: =Source!P30 -> 152.79 | J46: =IF(Source!BC31<> 0, Source!BC31, 1) -> 15.53 | K46: =Source!P31 -> 2372.83
C47: НР от ФОТ | D47: % | E47: =Source!BZ31 -> 87 | I47: =SUM(Q42:Q46) -> 1793.51 | J47: =Source!AT31 -> 87 | K47: =SUM(R42:R46) -> 101064.01
...

Sheet Source
A1: 0 | B1: Smeta.RU (495) 974-1589 | D1: _PS_ | F1: 0 | G1: 0 | H1: 0 | I1: Smeta.RU | K1: 1 | L1: 74600 | M1: 10 | N1: 12 | O1: 1 | P1: 0 | Q1: 1
A4: 8 | B4: 1 | C4: -1 | G4: Капитальный ремонт здания Государственного бюджетного общеобразовательного учреждения города Москвы «Школа №1574», расположенного по адресу: г. Москва, Старопименовский переулок, д. 5. 1 этап | EC4: 0
A12: 1 | B12: 748 | C12: 0 | D12: =ROW(A704) -> 704 | E12: 0 | F12: 02-01-04 | G12: Водоснабжение. | I12: 0 | J12: 2024-00375-01-0-ИОС2 | K12: 0 | L12: 0 | M12: 4098 | O12: 0 | P12: 0 | Q12: 0 | R12: 0 | S12: 0 | T12: 1 | V12: 0 | BB12: 0 | BH12: Сметные нормы списания | BI12: Коды ОКП для ТСН-2001 МГЭ Дополнение 81 | BJ12: 1 | BK12: 1 | BL12: 0 | BM12: 0 | BN12: 1 | BO12: 0 | BP12: 6 | BQ12: 2 | BR12: 1 | BS12: 1 | BT12: 0 | BU12: 0 | BV12: 0 | BW12: 0 | BX12: 0 | BY12: ТСН-2001 (МГЭ) Доп 81 - Ремонт | BZ12: Типовой расчет для ТСН-2001 МГЭ, Дополнение 81, ремонт | CA12: Территориальные сметные нормативы для Москвы ТСН-2001 (МГЭ), дополнение 81 | CB12: Территориальные сметные нормативы для Москвы ТСН-2001 (МГЭ), дополнение 81 | CC12: Территориальные сметные нормативы для Москвы ТСН-2001 (МГЭ), дополнение 81 | CD12: Территориальные сметные нормативы для Москвы ТСН-2001 (МГЭ), дополнение 81 | CE12: Поправки для ТСН-2001 от 07.04.2026 г. доп.81 | CF12: 0 | CG12: 0 | CH12: 8200 | CK12: 81 | CQ12: Территориальные сметные нормативы для Москвы (ТСН-2001) | CR12: ТЕР | CS12: 41660 | CT12: 1 | CU12: 81 | CY12: 0 | EC12: 0
A15: 15 | B15: 1
A18: 52 | B18: =B704 -> 748 | C18: =C704 -> 1 | D18: =D704 -> 12 | E18: =E704 -> 0 | F18: =F704 -> 02-01-04 | G18: =G704 -> Водоснабжение. | O18: =O704 -> 296424.21 | P18: =P704 -> 268991.6 | Q18: =Q704 -> 1680.25 | R18: =R704 -> 190.22 | S18: =S704 -> 25752.36 | T18: =T704 -> 0 | U18: =U704 -> 2104.7977 | V18: =V704 -> 0 | ... GX18: =GX704 -> 0
A20: 3 | B20: 1 | D20: =ROW(A671) -> 671 | F20: 02-01-04 | G20: Система водоснабжения. | I20: 0 | J20: 2024-00375-01-0-ИОС2 | K20: -1 | L20: 02-01-04 | S20: 0 | T20: 0 | V20: 0 | BX20: 0 | CF20: 0 | CG20: 0
A22: 52 | B22: =B671 -> 1 | C22: =C671 -> 3 | D22: =D671 -> 20 | E22: =E671 -> 0 | F22: =F671 -> 02-01-04 | G22: =G671 -> Система водоснабжения. | O22: =O671 -> 296424.21 | P22: =P671 -> 268991.6 | Q22: =Q671 -> 1680.25 | R22: =R671 -> 190.22 | S22: =S671 -> 25752.36 | T22: =T671 -> 0 | U22: =U671 -> 2104.7977 | V22: =V671 -> 0 | ... GX22: =GX671 -> 0
A24: 4 | B24: 1 | D24: =ROW(A49) -> 49 | F24: Новый раздел | G24: Демонтажные работы. | I24: 0 | K24: 0 | S24: 0 | T24: 0 | V24: 0 | BX24: 0 | CJ24: 0
A26: 52 | B26: =B49 -> 1 | C26: =C49 -> 4 | D26: =D49 -> 24 | E26: =E49 -> 0 | F26: =F49 -> Новый раздел | G26: =G49 -> Демонтажные работы. | O26: =O49 -> 9788.2 | P26: =P49 -> 484.79 | Q26: =Q49 -> 39.05 | R26: =R49 -> 0.87 | S26: =S49 -> 9264.36 | T26: =T49 -> 0 | U26: =U49 -> 820.47351 | V26: =V49 -> 0 | ... GX26: =GX49 -> 0
A28: 17 | B28: 1 | C28: =ROW(SmtRes!A5) -> 5 | D28: =ROW(EtalonRes!A5) -> 5 | E28: 1 | F28: 6.65-1-1 | G28: Разборка трубопроводов из водогазопроводных труб диаметром до 25 мм | H28: 100 м | I28: =ROUND((28+45+35+75+90+75+33+87+25+90+100+54)/100,9) -> 7.37 | J28: 0 | K28: =ROUND((28+45+35+75+90+75+33+87+25+90+100+54)/100,9) -> 7.37 | O28: =ROUND(CP28,2) -> 2877.96 | P28: =ROUND((ROUND((AC28*AW28*I28),2)*BC28),2) -> 239.97 | Q28: =(ROUND((ROUND((((ET28*1.2))*AV28*I28),2)*BB28),2)+ROUND((ROUND(((AE28-((EU28*1.2)))*AV28*I28),2)*BS28),2)) -> 6.48 | R28: =(ROUND((ROUND((((EU28*1.2))*AV28*I28),2)*BS28),2)+ROUND((ROUND(((AE28-((EU28*1.2)))*AV28*I28),2)*BS28),2)) -> 0 | S28: =ROUND((ROUND((AF28*AV28*I28),2)*BA28),2) -> 2631.51 | T28: =ROUND(CU28*I28,2) -> 0 | U28: =CV28*I28 -> 245.93678 | V28: =CW28*I28 -> 0 | W28: =ROUND(CX28*I28,2) -> 0 | X28: =(ROUND((((S28+ROUND((ROUND((((EU28*1.2))*AV28*I28),2)*BS28),2))*AT28)/100),2)+ROUND(((ROUND((ROUND(((AE28-((EU28*1.2)))*AV28*I28),2)*BS28),2)*AT28)/100),2)) -> 2289.41 | Y28: =(ROUND((((S28+ROUND((ROUND((((EU28*1.2))*AV28*I28),2)*BS28),2))*AU28)/100),2)+ROUND(((ROUND((ROUND(((AE28-((EU28*1.2)))*AV28*I28),2)*BS28),2)*AU28)/100),2)) -> 1157.86 | AA28: 85736471 | AB28: =ROUND((AC28+AD28+AF28),6) -> 374.428 | AC28: =ROUND(((ES28*1)),6) -> 32.56 | AD28: =ROUND(((((ET28*1.2))-((EU28*1.2)))+AE28),6) -> 0.84 | AE28: =ROUND(((EU28*1.2)),6) -> 0 | AF28: =ROUND(((EV28*1.2)),6) -> 341.028 | AG28: =ROUND((AP28),6) -> 0 | AH28: =((EW28*1.2)) -> 31.872 | AI28: =((EX28*1.2)) -> 0 | AJ28: =(AS28) -> 0 | AK28: 317.45 | AL28: 32.56 | AM28: 0.7 | AN28: 0 | AO28: 284.19 | AP28: 0 | AQ28: 26.56 | AR28: 0 | AS28: 0 | AT28: 87 | AU28: 44 | AV28: 1.047 | AW28: 1 | AZ28: 1 | BA28: 1 | BB28: 1 | BC28: 1 | BH28: 0 | BI28: 1 | BJ28: ТСН-2001.6 Доп. 79, Сб. 65, т. 1, поз. 1 | BM28: 102 | BN28: 0 | BO28: 6.65-1-1 | BP28: 1 | BQ28: 60 | BR28: 0 | BS28: 1 | BT28: 1 | BU28: 1 | BV28: 1 | BW28: 1 | BX28: 1 | BZ28: 87 | CA28: 44 | CE28: 1566 | CF28: 0 | CG28: 0 | CM28: 0 | CN28: Поправка: Гл.12.Прил.8.п.8. 3_12.00.01.11.001 Наименование: При наличии напряженных и стесненных условий производства работ (стесненность, сложность складирования и транспортной логистики и т.п.) для объектов, расположенных в пределах круговой магистральной системы улиц "Садовое кольцо" города Москвы | CO28: 0 | CP28: =(P28+Q28+S28) -> 2877.96 | CQ28: =ROUND((ROUND((AC28*AW28*1),2)*BC28),2) -> 32.56 | CR28: =(ROUND((ROUND((((ET28*1.2))*AV28*1),2)*BB28),2)+ROUND((ROUND(((AE28-((EU28*1.2)))*AV28*1),2)*BS28),2)) -> 0.88 | CS28: =(ROUND((ROUND((((EU28*1.2))*AV28*1),2)*BS28),2)+ROUND((ROUND(((AE28-((EU28*1.2)))*AV28*1),2)*BS28),2)) -> 0 | CT28: =ROUND((ROUND((AF28*AV28*1),2)*BA28),2) -> 357.06 | CU28: =AG28 -> 0 | CV28: =(AH28*AV28) -> 33.369984 | CW28: =AI28 -> 0 | CX28: =AJ28 -> 0 | CY28: =(ROUND((((S28+ROUND((ROUND((((EU28*1.2))*AV28*1),2)*BS28),2))*AT28)/100),2)+ROUND(((ROUND((ROUND(((AE28-((EU28*1.2)))*AV28*1),2)*BS28),2)*AT28)/100),2)) -> 2289.41 | CZ28: =(ROUND((((S28+ROUND((ROUND((((EU28*1.2))*AV28*1),2)*BS28),2))*AU28)/100),2)+ROUND(((ROUND((ROUND(((AE28-((EU28*1.2)))*AV28*1),2)*BS28),2)*AU28)/100),2)) -> 1157.86 | DB28: 1 | DD28: *1 | DE28: *1,2 | DF28: *1,2 | DG28: *1,2 | DI28: *1,2 | DJ28: *1,2 | DN28: 0 | DO28: 0 | DP28: 1 | DQ28: 1 | DU28: 1003 | DV28: 100 м | DW28: 100 м | DX28: 100 | EE28: 85133723 | EF28: 60 | EG28: Ремонтно-строительные работы | EH28: 0 | EJ28: 1 | EK28: 102 | EL28: ТСН-2001.6-65. Внутренние санитарно-технические работы: демонтаж и разборка | EM28: ТСН-2001.6-65-1 | EO28: Поправка: Гл.12.Прил.8.п.8. 3_12.00.01.11.001 | EQ28: 0 | ER28: 317.45 | ES28: 32.56 | ET28: 0.7 | EU28: 0 | EV28: 284.19 | EW28: 26.56 | EX28: 0 | EY28: 0 | FQ28: 0 | FR28: 0 | FS28: 0 | FX28: 87 | FY28: 44 | GD28: 1 | GF28: 1544923571 | GG28: 2 | GH28: 1 | GI28: 2 | GJ28: 0 | GK28: 0 | GL28: =ROUND(IF(AND(BH28=3,BI28=3,FS28<>0),P28,0),2) -> 0 | GM28: =ROUND(O28+X28+Y28,2)+GX28 -> 6325.23 | GN28: =IF(OR(BI28=0,BI28=1),GM28-GX28,0) -> 6325.23 | GO28: =IF(BI28=2,GM28-GX28,0) -> 0 | GP28: =IF(BI28=4,GM28-GX28,0) -> 0 | GR28: 0 | GS28: 3 | GT28: 0 | GV28: =ROUND((GT28),6) -> 0 | GW28: 1 | GX28: =ROUND(HC28*I28,2) -> 0 | HA28: 0 | HB28: 0 | HC28: =GV28*GW28 -> 0 | HS28: 0 | IK28: 0
A29: 17 | B29: 1 | C29: =ROW(SmtRes!A10) -> 10 | D29: =ROW(EtalonRes!A10) -> 10 | E29: 1 | F29: 6.65-1-1 | G29: Разборка трубопроводов из водогазопроводных труб диаметром до 25 мм | H29: 100 м | I29: =ROUND((28+45+35+75+90+75+33+87+25+90+100+54)/100,9) -> 7.37 | J29: 0 | K29: =ROUND((28+45+35+75+90+75+33+87+25+90+100+54)/100,9) -> 7.37 | O29: =ROUND(CP29,2) -> 152072.52 | P29: =ROUND((ROUND((AC29*AW29*I29),2)*BC29),2) -> 3726.73 | Q29: =(ROUND((ROUND((((ET29*1.2))*AV29*I29),2)*BB29),2)+ROUND((ROUND(((AE29-((EU29*1.2)))*AV29*I29),2)*BS29),2)) -> 60.2 | R29: =(ROUND((ROUND((((EU29*1.2))*AV29*I29),2)*BS29),2)+ROUND((ROUND(((AE29-((EU29*1.2)))*AV29*I29),2)*BS29),2)) -> 0 | S29: =ROUND((ROUND((AF29*AV29*I29),2)*BA29),2) -> 148285.59 | T29: =ROUND(CU29*I29,2) -> 0 | U29: =CV29*I29 -> 245.93678 | V29: =CW29*I29 -> 0 | W29: =ROUND(CX29*I29,2) -> 0 | X29: =(ROUND((((S29+ROUND((ROUND((((EU29*1.2))*AV29*I29),2)*BS29),2))*AT29)/100),2)+ROUND(((ROUND((ROUND(((AE29-((EU29*1.2)))*AV29*I29),2)*BS29),2)*AT29)/100),2)) -> 129008.46 | Y29: =(ROUND((((S29+ROUND((ROUND((((EU29*1.2))*AV29*I29),2)*BS29),2))*AU29)/100),2)+ROUND(((ROUND((ROUND(((AE29-((EU29*1.2)))*AV29*I29),2)*BS29),2)*AU29)/100),2)) -> 65245.66 | AA29: 85736473 | AB29: =ROUND((AC29+AD29+AF29),6) -> 374.428 | AC29: =ROUND(((ES29*1)),6) -> 32.56 | AD29: =ROUND(((((ET29*1.2))-((EU29*1.2)))+AE29),6) -> 0.84 | AE29: =ROUND(((EU29*1.2)),6) -> 0 | AF29: =ROUND(((EV29*1.2)),6) -> 341.028 | AG29: =ROUND((AP29),6) -> 0 | AH29: =((EW29*1.2)) -> 31.872 | AI29: =((EX29*1.2)) -> 0 | AJ29: =(AS29) -> 0 | AK29: 317.45 | AL29: 32.56 | AM29: 0.7 | AN29: 0 | AO29: 284.19 | AP29: 0 | AQ29: 26.56 | AR29: 0 | AS29: 0 | AT29: 87 | AU29: 44 | AV29: 1.047 | AW29: 1 | AZ29: 1 | BA29: 56.35 | BB29: 9.29 | BC29: 15.53 | BH29: 0 | BI29: 1 | BJ29: ТСН-2001.6 Доп. 79, Сб. 65, т. 1, поз. 1 | BM29: 102 | BN29: 0 | BO29: 6.65-1-1 | BP29: 1 | BQ29: 60 | BR29: 0 | BS29: 56.35 | BT29: 1 | BU29: 1 | BV29: 1 | BW29: 1 | BX29: 1 | BZ29: 87 | CA29: 44 | CE29: 1566 | CF29: 0 | CG29: 0 | CM29: 0 | CN29: Поправка: Гл.12.Прил.8.п.8. 3_12.00.01.11.001 Наименование: При наличии напряженных и стесненных условий производства работ (стесненность, сложность складирования и транспортной логистики и т.п.) для объектов, расположенных в пределах круговой магистральной системы улиц "Садовое кольцо" города Москвы | CO29: 0 | CP29: =(P29+Q29+S29) -> 152072.52 | CQ29: =ROUND((ROUND((AC29*AW29*1),2)*BC29),2) -> 505.66 | CR29: =(ROUND((ROUND((((ET29*1.2))*AV29*1),2)*BB29),2)+ROUND((ROUND(((AE29-((EU29*1.2)))*AV29*1),2)*BS29),2)) -> 8.18 | CS29: =(ROUND((ROUND((((EU29*1.2))*AV29*1),2)*BS29),2)+ROUND((ROUND(((AE29-((EU29*1.2)))*AV29*1),2)*BS29),2)) -> 0 | CT29: =ROUND((ROUND((AF29*AV29*1),2)*BA29),2) -> 20120.33 | CU29: =AG29 -> 0 | CV29: =(AH29*AV29) -> 33.369984 | CW29: =AI29 -> 0 | CX29: =AJ29 -> 0 | CY29: =(ROUND((((S29+ROUND((ROUND((((EU29*1.2))*AV29*1),2)*BS29),2))*AT29)/100),2)+ROUND(((ROUND((ROUND(((AE29-((EU29*1.2)))*AV29*1),2)*BS29),2)*AT29)/100),2)) -> 129008.46 | CZ29: =(ROUND((((S29+ROUND((ROUND((((EU29*1.2))*AV29*1),2)*BS29),2))*AU29)/100),2)+ROUND(((ROUND((ROUND(((AE29-((EU29*1.2)))*AV29*1),2)*BS29),2)*AU29)/100),2)) -> 65245.66 | DB29: 2 | DD29: *1 | DE29: *1,2 | DF29: *1,2 | DG29: *1,2 | DI29: *1,2 | DJ29: *1,2 | DN29: 0 | DO29: 0 | DP29: 1 | DQ29: 1 | DU29: 1003 | DV29: 100 м | DW29: 100 м | DX29: 100 | EE29: 85133723 | EF29: 60 | EG29: Ремонтно-строительные работы | EH29: 0 | EJ29: 1 | EK29: 102 | EL29: ТСН-2001.6-65. Внутренние санитарно-технические работы: демонтаж и разборка | EM29: ТСН-2001.6-65-1 | EO29: Поправка: Гл.12.Прил.8.п.8. 3_12.00.01.11.001 | EQ29: 0 | ER29: 317.45 | ES29: 32.56 | ET29: 0.7 | EU29: 0 | EV29: 284.19 | EW29: 26.56 | EX29: 0 | EY29: 0 | FQ29: 0 | FR29: 0 | FS29: 0 | FX29: 87 | FY29: 44 | GD29: 1 | GF29: 1544923571 | GG29: 2 | GH29: 1 | GI29: 2 | GJ29: 0 | GK29: 0 | GL29: =ROUND(IF(AND(BH29=3,BI29=3,FS29<>0),P29,0),2) -> 0 | GM29: =ROUND(O29+X29+Y29,2)+GX29 -> 346326.64 | GN29: =IF(OR(BI29=0,BI29=1),GM29-GX29,0) -> 346326.64 | GO29: =IF(BI29=2,GM29-GX29,0) -> 0 | GP29: =IF(BI29=4,GM29-GX29,0) -> 0 | GR29: 0 | GS29: 3 | GT29: 0 | GV29: =ROUND((GT29),6) -> 0 | GW29: 1 | GX29: =ROUND(HC29*I29,2) -> 0 | HA29: 0 | HB29: 0 | HC29: =GV29*GW29 -> 0 | HS29: 0 | IK29: 0
A30: 17 | B30: 1 | C30: =ROW(SmtRes!A15) -> 15 | D30: =ROW(EtalonRes!A15) -> 15 | E30: 2 | F30: 6.65-1-2 | G30: Разборка трубопроводов из водогазопроводных труб диаметром до 40 мм | H30: 100 м | I30: =ROUND((22+55+50+64+95+45)/100,9) -> 3.31 | J30: 0 | K30: =ROUND((22+55+50+64+95+45)/100,9) -> 3.31 | O30: =ROUND(CP30,2) -> 2219.53 | P30: =ROUND((ROUND((AC30*AW30*I30),2)*BC30),2) -> 152.79 | Q30: =(ROUND((ROUND((((ET30*1.2))*AV30*I30),2)*BB30),2)+ROUND((ROUND(((AE30-((EU30*1.2)))*AV30*I30),2)*BS30),2)) -> 5.24 | R30: =(ROUND((ROUND((((EU30*1.2))*AV30*I30),2)*BS30),2)+ROUND((ROUND(((AE30-((EU30*1.2)))*AV30*I30),2)*BS30),2)) -> 0 | S30: =ROUND((ROUND((AF30*AV30*I30),2)*BA30),2) -> 2061.5 | T30: =ROUND(CU30*I30,2) -> 0 | U30: =CV30*I30 -> 189.3033 | V30: =CW30*I30 -> 0 | W30: =ROUND(CX30*I30,2) -> 0 | X30: =(ROUND((((S30+ROUND((ROUND((((EU30*1.2))*AV30*I30),2)*BS30),2))*AT30)/100),2)+ROUND(((ROUND((ROUND(((AE30-((EU30*1.2)))*AV30*I30),2)*BS30),2)*AT30)/100),2)) -> 1793.51 | Y30: =(ROUND((((S30+ROUND((ROUND((((EU30*1.2))*AV30*I30),2)*BS30),2))*AU30)/100),2)+ROUND(((ROUND((ROUND(((AE30-((EU30*1.2)))*AV30*I30),2)*BS30),2)*AU30)/100),2)) -> 907.06 | AA30: 85736471 | AB30: =ROUND((AC30+AD30+AF30),6) -> 642.524 | AC30: =ROUND(((ES30*1)),6) -> 46.16 | AD30: =ROUND(((((ET30*1.2))-((EU30*1.2)))+AE30),6) -> 1.512 | AE30: =ROUND(((EU30*1.2)),6) -> 0 | AF30: =ROUND(((EV30*1.2)),6) -> 594.852 | AG30: =ROUND((AP30),6) -> 0 | AH30: =((EW30*1.2)) -> 54.624 | AI30: =((EX30*1.2)) -> 0 | AJ30: =(AS30) -> 0 | AK30: 543.13 | AL30: 46.16 | AM30: 1.26 | AN30: 0 | AO30: 495.71 | AP30: 0 | AQ30: 45.52 | AR30: 0 | AS30: 0 | AT30: 87 | AU30: 44 | AV30: 1.047 | AW30: 1 | AZ30: 1 | BA30: 1 | BB30: 1 | BC30: 1 | BH30: 0 | BI30: 1 | BJ30: ТСН-2001.6 Доп. 79, Сб. 65, т. 1, поз. 2 | BM30: 102 | BN30: 0 | BO30: 6.65-1-2 | BP30: 1 | BQ30: 60 | BR30: 0 | BS30: 1 | BT30: 1 | BU30: 1 | BV30: 1 | BW30: 1 | BX30: 1 | BZ30: 87 | CA30: 44 | CE30: 1566 | CF30: 0 | CG30: 0 | CM30: 0 | CN30: Поправка: Гл.12.Прил.8.п.8. 3_12.00.01.11.001 Наименование: При наличии напряженных и стесненных условий производства работ (стесненность, сложность складирования и транспортной логистики и т.п.) для объектов, расположенных в пределах круговой магистральной системы улиц "Садовое кольцо" города Москвы | CO30: 0 | CP30: =(P30+Q30+S30) -> 2219.53 | CQ30: =ROUND((ROUND((AC30*AW30*1),2)*BC30),2) -> 46.16 | CR30: =(ROUND((ROUND((((ET30*1.2))*AV30*1),2)*BB30),2)+ROUND((ROUND(((AE30-((EU30*1.2)))*AV30*1),2)*BS30),2)) -> 1.58 | CS30: =(ROUND((ROUND((((EU30*1.2))*AV30*1),2)*BS30),2)+ROUND((ROUND(((AE30-((EU30*1.2)))*AV30*1),2)*BS30),2)) -> 0 | CT30: =ROUND((ROUND((AF30*AV30*1),2)*BA30),2) -> 622.81 | CU30: =AG30 -> 0 | CV30: =(AH30*AV30) -> 57.191328 | CW30: =AI30 -> 0 | CX30: =AJ30 -> 0 | CY30: =(ROUND((((S30+ROUND((ROUND((((EU30*1.2))*AV30*1),2)*BS30),2))*AT30)/100),2)+ROUND(((ROUND((ROUND(((AE30-((EU30*1.2)))*AV30*1),2)*BS30),2)*AT30)/100),2)) -> 1793.51 | CZ30: =(ROUND((((S30+ROUND((ROUND((((EU30*1.2))*AV30*1),2)*BS30),2))*AU30)/100),2)+ROUND(((ROUND((ROUND(((AE30-((EU30*1.2)))*AV30*1),2)*BS30),2)*AU30)/100),2)) -> 907.06 | DB30: 3 | DD30: *1 | DE30: *1,2 | DF30: *1,2 | DG30: *1,2 | DI30: *1,2 | DJ30: *1,2 | DN30: 0 | DO30: 0 | DP30: 1 | DQ30: 1 | DU30: 1003 | DV30: 100 м | DW30: 100 м | DX30: 100 | EE30: 85133723 | EF30: 60 | EG30: Ремонтно-строительные работы | EH30: 0 | EJ30: 1 | EK30: 102 | EL30: ТСН-2001.6-65. Внутренние санитарно-технические работы: демонтаж и разборка | EM30: ТСН-2001.6-65-1 | EO30: Поправка: Гл.12.Прил.8.п.8. 3_12.00.01.11.001 | EQ30: 0 | ER30: 543.13 | ES30: 46.16 | ET30: 1.26 | EU30: 0 | EV30: 495.71 | EW30: 45.52 | EX30: 0 | EY30: 0 | FQ30: 0 | FR30: 0 | FS30: 0 | FX30: 87 | FY30: 44 | GD30: 1 | GF30: -1242219818 | GG30: 2 | GH30: 1 | GI30: 2 | GJ30: 0 | GK30: 0 | GL30: =ROUND(IF(AND(BH30=3,BI30=3,FS30<>0),P30,0),2) -> 0 | GM30: =ROUND(O30+X30+Y30,2)+GX30 -> 4920.1 | GN30: =IF(OR(BI30=0,BI30=1),GM30-GX30,0) -> 4920.1 | GO30: =IF(BI30=2,GM30-GX30,0) -> 0 | GP30: =IF(BI30=4,GM30-GX30,0) -> 0 | GR30: 0 | GS30: 3 | GT30: 0 | GV30: =ROUND((GT30),6) -> 0 | GW30: 1 | GX30: =ROUND(HC30*I30,2) -> 0 | HA30: 0 | HB30: 0 | HC30: =GV30*GW30 -> 0 | HS30: 0 | IK30: 0
A31: 17 | B31: 1 | C31: =ROW(SmtRes!A20) -> 20 | D31: =ROW(EtalonRes!A20) -> 20 | E31: 2 | F31: 6.65-1-2 | G31: Разборка трубопроводов из водогазопроводных труб диаметром до 40 мм | H31: 100 м | I31: =ROUND((22+55+50+64+95+45)/100,9) -> 3.31 | J31: 0 | K31: =ROUND((22+55+50+64+95+45)/100,9) -> 3.31 | O31: =ROUND(CP31,2) -> 118587.04 | P31: =ROUND((ROUND((AC31*AW31*I31),2)*BC31),2) -> 2372.83 | Q31: =(ROUND((ROUND((((ET31*1.2))*AV31*I31),2)*BB31),2)+ROUND((ROUND(((AE31-((EU31*1.2)))*AV31*I31),2)*BS31),2)) -> 48.68 | R31: =(ROUND((ROUND((((EU31*1.2))*AV31*I31),2)*BS31),2)+ROUND((ROUND(((AE31-((EU31*1.2)))*AV31*I31),2)*BS31),2)) -> 0 | S31: =ROUND((ROUND((AF31*AV31*I31),2)*BA31),2) -> 116165.53 | T31: =ROUND(CU31*I31,2) -> 0 | U31: =CV31*I31 -> 189.3033 | V31: =CW31*I31 -> 0 | W31: =ROUND(CX31*I31,2) -> 0 | X31: =(ROUND((((S31+ROUND((ROUND((((EU31*1.2))*AV31*I31),2)*BS31),2))*AT31)/100),2)+ROUND(((ROUND((ROUND(((AE31-((EU31*1.2)))*AV31*I31),2)*BS31),2)*AT31)/100),2)) -> 101064.01 | Y31: =(ROUND((((S31+ROUND((ROUND((((EU31*1.2))*AV31*I31),2)*BS31),2))*AU31)/100),2)+ROUND(((ROUND((ROUND(((AE31-((EU31*1.2)))*AV31*I31),2)*BS31),2)*AU31)/100),2)) -> 51112.83 | AA31: 85736473 | AB31: =ROUND((AC31+AD31+AF31),6) -> 642.524 | AC31: =ROUND(((ES31*1)),6) -> 46.16 | AD31: =ROUND(((((ET31*1.2))-((EU31*1.2)))+AE31),6) -> 1.512 | AE31: =ROUND(((EU31*1.2)),6) -> 0 | AF31: =ROUND(((EV31*1.2)),6) -> 594.852 | AG31: =ROUND((AP31),6) -> 0 | AH31: =((EW31*1.2)) -> 54.624 | AI31: =((EX31*1.2)) -> 0 | AJ31: =(AS31) -> 0 | AK31: 543.13 | AL31: 46.16 | AM31: 1.26 | AN31: 0 | AO31: 495.71 | AP31: 0 | AQ31: 45.52 | AR31: 0 | AS31: 0 | AT31: 87 | AU31: 44 | AV31: 1.047 | AW31: 1 | AZ31: 1 | BA31: 56.35 | BB31: 9.29 | BC31: 15.53 | BH31: 0 | BI31: 1 | BJ31: ТСН-2001.6 Доп. 79, Сб. 65, т. 1, поз. 2 | BM31: 102 | BN31: 0 | BO31: 6.65-1-2 | BP31: 1 | BQ31: 60 | BR31: 0 | BS31: 56.35 | BT31: 1 | BU31: 1 | BV31: 1 | BW31: 1 | BX31: 1 | BZ31: 87 | CA31: 44 | CE31: 1566 | CF31: 0 | CG31: 0 | CM31: 0 | CN31: Поправка: Гл.12.Прил.8.п.8. 3_12.00.01.11.001 Наименование: При наличии напряженных и стесненных условий производства работ (стесненность, сложность складирования и транспортной логистики и т.п.) для объектов, расположенных в пределах круговой магистральной системы улиц "Садовое кольцо" города Москвы | CO31: 0 | CP31: =(P31+Q31+S31) -> 118587.04 | CQ31: =ROUND((ROUND((AC31*AW31*1),2)*BC31),2) -> 716.86 | CR31: =(ROUND((ROUND((((ET31*1.2))*AV31*1),2)*BB31),2)+ROUND((ROUND(((AE31-((EU31*1.2)))*AV31*1),2)*BS31),2)) -> 14.68 | CS31: =(ROUND((ROUND((((EU31*1.2))*AV31*1),2)*BS31),2)+ROUND((ROUND(((AE31-((EU31*1.2)))*AV31*1),2)*BS31),2)) -> 0 | CT31: =ROUND((ROUND((AF31*AV31*1),2)*BA31),2) -> 35095.34 | CU31: =AG31 -> 0 | CV31: =(AH31*AV31) -> 57.191328 | CW31: =AI31 -> 0 | CX31: =AJ31 -> 0 | CY31: =(ROUND((((S31+ROUND((ROUND((((EU31*1.2))*AV31*1),2)*BS31),2))*AT31)/100),2)+ROUND(((ROUND((ROUND(((AE31-((EU31*1.2)))*AV31*1),2)*BS31),2)*AT31)/100),2)) -> 101064.01 | CZ31: =(ROUND((((S31+ROUND((ROUND((((EU31*1.2))*AV31*1),2)*BS31),2))*AU31)/100),2)+ROUND(((ROUND((ROUND(((AE31-((EU31*1.2)))*AV31*1),2)*BS31),2)*AU31)/100),2)) -> 51112.83 | DB31: 4 | DD31: *1 | DE31: *1,2 | DF31: *1,2 | DG31: *1,2 | DI31: *1,2 | DJ31: *1,2 | DN31: 0 | DO31: 0 | DP31: 1 | DQ31: 1 | DU31: 1003 | DV31: 100 м | DW31: 100 м | DX31: 100 | EE31: 85133723 | EF31: 60 | EG31: Ремонтно-строительные работы | EH31: 0 | EJ31: 1 | EK31: 102 | EL31: ТСН-2001.6-65. Внутренние санитарно-технические работы: демонтаж и разборка | EM31: ТСН-2001.6-65-1 | EO31: Поправка: Гл.12.Прил.8.п.8. 3_12.00.01.11.001 | EQ31: 0 | ER31: 543.13 | ES31: 46.16 | ET31: 1.26 | EU31: 0 | EV31: 495.71 | EW31: 45.52 | EX31: 0 | EY31: 0 | FQ31: 0 | FR31: 0 | FS31: 0 | FX31: 87 | FY31: 44 | GD31: 1 | GF31: -1242219818 | GG31: 2 | GH31: 1 | GI31: 2 | GJ31: 0 | GK31: 0 | GL31: =ROUND(IF(AND(BH31=3,BI31=3,FS31<>0),P31,0),2) -> 0 | GM31: =ROUND(O31+X31+Y31,2)+GX31 -> 270763.88 | GN31: =IF(OR(BI31=0,BI31=1),GM31-GX31,0) -> 270763.88 | GO31: =IF(BI31=2,GM31-GX31,0) -> 0 | GP31: =IF(BI31=4,GM31-GX31,0) -> 0 | GR31: 0 | GS31: 3 | GT31: 0 | GV31: =ROUND((GT31),6) -> 0 | GW31: 1 | GX31: =ROUND(HC31*I31,2) -> 0 | HA31: 0 | HB31: 0 | HC31: =GV31*GW31 -> 0 | HS31: 0 | IK31: 0
A32: 17 | B32: 1 | C32: =ROW(SmtRes!A25) -> 25 | D32: =ROW(EtalonRes!A25) -> 25 | E32: 3 | F32: 6.65-1-3 | G32: Разборка трубопроводов из водогазопроводных труб диаметром до 50 мм | H32: 100 м | I32: =ROUND((110+12)/100,9) -> 1.22 | J32: 0 | K32: =ROUND((110+12)/100,9) -> 1.22 | O32: =ROUND(CP32,2) -> 1076.41 | P32: =ROUND((ROUND((AC32*AW32*I32),2)*BC32),2) -> 67.44 | Q32: =(ROUND((ROUND((((ET32*1.2))*AV32*I32),2)*BB32),2)+ROUND((ROUND(((AE32-((EU32*1.2)))*AV32*I32),2)*BS32),2)) -> 2.1 | R32: =(ROUND((ROUND((((EU32*1.2))*AV32*I32),2)*BS32),2)+ROUND((ROUND(((AE32-((EU32*1.2)))*AV32*I32),2)*BS32),2)) -> 0 | S32: =ROUND((ROUND((AF32*AV32*I32),2)*BA32),2) -> 1006.87 | T32: =ROUND(CU32*I32,2) -> 0 | U32: =CV32*I32 -> 92.458979 | V32: =CW32*I32 -> 0 | W32: =ROUND(CX32*I32,2) -> 0 | X32: =(ROUND((((S32+ROUND((ROUND((((EU32*1.2))*AV32*I32),2)*BS32),2))*AT32)/100),2)+ROUND(((ROUND((ROUND(((AE32-((EU32*1.2)))*AV32*I32),2)*BS32),2)*AT32)/100),2)) -> 875.98 | Y32: =(ROUND((((S32+ROUND((ROUND((((EU32*1.2))*AV32*I32),2)*BS32),2))*AU32)/100),2)+ROUND(((ROUND((ROUND(((AE32-((EU32*1.2)))*AV32*I32),2)*BS32),2)*AU32)/100),2)) -> 443.02 | AA32: 85736471 | AB32: =ROUND((AC32+AD32+AF32),6) -> 845.18 | AC32: =ROUND(((ES32*1)),6) -> 55.28 | AD32: =ROUND(((((ET32*1.2))-((EU32*1.2)))+AE32),6) -> 1.644 | AE32: =ROUND(((EU32*1.2)),6) -> 0 | AF32: =ROUND(((EV32*1.2)),6) -> 788.256 | AG32: =ROUND((AP32),6) -> 0 | AH32: =((EW32*1.2)) -> 72.384 | AI32: =((EX32*1.2)) -> 0 | AJ32: =(AS32) -> 0 | AK32: 713.53 | AL32: 55.28 | AM32: 1.37 | AN32: 0 | AO32: 656.88 | AP32: 0 | AQ32: 60.32 | AR32: 0 | AS32: 0 | AT32: 87 | AU32: 44 | AV32: 1.047 | AW32: 1 | AZ32: 1 | BA32: 1 | BB32: 1 | BC32: 1 | BH32: 0 | BI32: 1 | BJ32: ТСН-2001.6 Доп. 79, Сб. 65, т. 1, поз. 3 | BM32: 102 | BN32: 0 | BO32: 6.65-1-3 | BP32: 1 | BQ32: 60 | BR32: 0 | BS32: 1 | BT32: 1 | BU32: 1 | BV32: 1 | BW32: 1 | BX32: 1 | BZ32: 87 | CA32: 44 | CE32: 1566 | CF32: 0 | CG32: 0 | CM32: 0 | CN32: Поправка: Гл.12.Прил.8.п.8. 3_12.00.01.11.001 Наименование: При наличии напряженных и стесненных условий производства работ (стесненность, сложность складирования и транспортной логистики и т.п.) для объектов, расположенных в пределах круговой магистральной системы улиц "Садовое кольцо" города Москвы | CO32: 0 | CP32: =(P32+Q32+S32) -> 1076.41 | CQ32: =ROUND((ROUND((AC32*AW32*1),2)*BC32),2) -> 55.28 | CR32: =(ROUND((ROUND((((ET32*1.2))*AV32*1),2)*BB32),2)+ROUND((ROUND(((AE32-((EU32*1.2)))*AV32*1),2)*BS32),2)) -> 1.72 | CS32: =(ROUND((ROUND((((EU32*1.2))*AV32*1),2)*BS32),2)+ROUND((ROUND(((AE32-((EU32*1.2)))*AV32*1),2)*BS32),2)) -> 0 | CT32: =ROUND((ROUND((AF32*AV32*1),2)*BA32),2) -> 825.3 | CU32: =AG32 -> 0 | CV32: =(AH32*AV32) -> 75.786048 | CW32: =AI32 -> 0 | CX32: =AJ32 -> 0 | CY32: =(ROUND((((S32+ROUND((ROUND((((EU32*1.2))*AV32*1),2)*BS32),2))*AT32)/100),2)+ROUND(((ROUND((ROUND(((AE32-((EU32*1.2)))*AV32*1),2)*BS32),2)*AT32)/100),2)) -> 875.98 | CZ32: =(ROUND((((S32+ROUND((ROUND((((EU32*1.2))*AV32*1),2)*BS32),2))*AU32)/100),2)+ROUND(((ROUND((ROUND(((AE32-((EU32*1.2)))*AV32*1),2)*BS32),2)*AU32)/100),2)) -> 443.02 | DB32: 5 | DD32: *1 | DE32: *1,2 | DF32: *1,2 | DG32: *1,2 | DI32: *1,2 | DJ32: *1,2 | DN32: 0 | DO32: 0 | DP32: 1 | DQ32: 1 | DU32: 1003 | DV32: 100 м | DW32: 100 м | DX32: 100 | EE32: 85133723 | EF32: 60 | EG32: Ремонтно-строительные работы | EH32: 0 | EJ32: 1 | EK32: 102 | EL32: ТСН-2001.6-65. Внутренние санитарно-технические работы: демонтаж и разборка | EM32: ТСН-2001.6-65-1 | EO32: Поправка: Гл.12.Прил.8.п.8. 3_12.00.01.11.001 | EQ32: 0 | ER32: 713.53 | ES32: 55.28 | ET32: 1.37 | EU32: 0 | EV32: 656.88 | EW32: 60.32 | EX32: 0 | EY32: 0 | FQ32: 0 | FR32: 0 | FS32: 0 | FX32: 87 | FY32: 44 | GD32: 1 | GF32: -952300200 | GG32: 2 | GH32: 1 | GI32: 2 | GJ32: 0 | GK32: 0 | GL32: =ROUND(IF(AND(BH32=3,BI32=3,FS32<>0),P32,0),2) -> 0 | GM32: =ROUND(O32+X32+Y32,2)+GX32 -> 2395.41 | GN32: =IF(OR(BI32=0,BI32=1),GM32-GX32,0) -> 2395.41 | GO32: =IF(BI32=2,GM32-GX32,0) -> 0 | GP32: =IF(BI32=4,GM32-GX32,0) -> 0 | GR32: 0 | GS32: 3 | GT32: 0 | GV32: =ROUND((GT32),6) -> 0 | GW32: 1 | GX32: =ROUND(HC32*I32,2) -> 0 | HA32: 0 | HB32: 0 | HC32: =GV32*GW32 -> 0 | HS32: 0 | IK32: 0
A33: 17 | B33: 1 | C33: =ROW(SmtRes!A30) -> 30 | D33: =ROW(EtalonRes!A30) -> 30 | E33: 3 | F33: 6.65-1-3 | G33: Разборка трубопроводов из водогазопроводных труб диаметром до 50 мм | H33: 100 м | I33: =ROUND((110+12)/100,9) -> 1.22 | J33: 0 | K33: =ROUND((110+12)/100,9) -> 1.22 | O33: =ROUND(CP33,2) -> 57804.67 | P33: =ROUND((ROUND((AC33*AW33*I33),2)*BC33),2) -> 1048.02 | Q33: =(ROUND((ROUND((((ET33*1.2))*AV33*I33),2)*BB33),2)+ROUND((ROUND(((AE33-((EU33*1.2)))*AV33*I33),2)*BS33),2)) -> 19.53 | R33: =(ROUND((ROUND((((EU33*1.2))*AV33*I33),2)*BS33),2)+ROUND((ROUND(((AE33-((EU33*1.2)))*AV33*I33),2)*BS33),2)) -> 0 | S33: =ROUND((ROUND((AF33*AV33*I33),2)*BA33),2) -> 56737.12 | T33: =ROUND(CU33*I33,2) -> 0 | U33: =CV33*I33 -> 92.458979 | V33: =CW33*I33 -> 0 | W33: =ROUND(CX33*I33,2) -> 0 | X33: =(ROUND((((S33+ROUND((ROUND((((EU33*1.2))*AV33*I33),2)*BS33),2))*AT33)/100),2)+ROUND(((ROUND((ROUND(((AE33-((EU33*1.2)))*AV33*I33),2)*BS33),2)*AT33)/100),2)) -> 49361.29 | Y33: =(ROUND((((S33+ROUND((ROUND((((EU33*1.2))*AV33*I33),2)*BS33),2))*AU33)/100),2)+ROUND(((ROUND((ROUND(((AE33-((EU33*1.2)))*AV33*I33),2)*BS33),2)*AU33)/100),2)) -> 24964.33 | AA33: 85736473 | AB33: =ROUND((AC33+AD33+AF33),6) -> 845.18 | AC33: =ROUND(((ES33*1)),6) -> 55.28 | AD33: =ROUND(((((ET33*1.2))-((EU33*1.2)))+AE33),6) -> 1.644 | AE33: =ROUND(((EU33*1.2)),6) -> 0 | AF33: =ROUND(((EV33*1.2)),6) -> 788.256 | AG33: =ROUND((AP33),6) -> 0 | AH33: =((EW33*1.2)) -> 72.384 | AI33: =((EX33*1.2)) -> 0 | AJ33: =(AS33) -> 0 | AK33: 713.53 | AL33: 55.28 | AM33: 1.37 | AN33: 0 | AO33: 656.88 | AP33: 0 | AQ33: 60.32 | AR33: 0 | AS33: 0 | AT33: 87 | AU33: 44 | AV33: 1.047 | AW33: 1 | AZ33: 1 | BA33: 56.35 | BB33: 9.3 | BC33: 15.54 | BH33: 0 | BI33: 1 | BJ33: ТСН-2001.6 Доп. 79, Сб. 65, т. 1, поз. 3 | BM33: 102 | BN33: 0 | BO33: 6.65-1-3 | BP33: 1 | BQ33: 60 | BR33: 0 | BS33: 56.35 | BT33: 1 | BU33: 1 | BV33: 1 | BW33: 1 | BX33: 1 | BZ33: 87 | CA33: 44 | CE33: 1566 | CF33: 0 | CG33: 0 | CM33: 0 | CN33: Поправка: Гл.12.Прил.8.п.8. 3_12.00.01.11.001 Наименование: При наличии напряженных и стесненных условий производства работ (стесненность, сложность складирования и транспортной логистики и т.п.) для объектов, расположенных в пределах круговой магистральной системы улиц "Садовое кольцо" города Москвы | CO33: 0 | CP33: =(P33+Q33+S33) -> 57804.67 | CQ33: =ROUND((ROUND((AC33*AW33*1),2)*BC33),2) -> 859.05 | CR33: =(ROUND((ROUND((((ET33*1.2))*AV33*1),2)*BB33),2)+ROUND((ROUND(((AE33-((EU33*1.2)))*AV33*1),2)*BS33),2)) -> 16 | CS33: =(ROUND((ROUND((((EU33*1.2))*AV33*1),2)*BS33),2)+ROUND((ROUND(((AE33-((EU33*1.2)))*AV33*1),2)*BS33),2)) -> 0 | CT33: =ROUND((ROUND((AF33*AV33*1),2)*BA33),2) -> 46505.66 | CU33: =AG33 -> 0 | CV33: =(AH33*AV33) -> 75.786048 | CW33: =AI33 -> 0 | CX33: =AJ33 -> 0 | CY33: =(ROUND((((S33+ROUND((ROUND((((EU33*1.2))*AV33*1),2)*BS33),2))*AT33)/100),2)+ROUND(((ROUND((ROUND(((AE33-((EU33*1.2)))*AV33*1),2)*BS33),2)*AT33)/100),2)) -> 49361.29 | CZ33: =(ROUND((((S33+ROUND((ROUND((((EU33*1.2))*AV33*1),2)*BS33),2))*AU33)/100),2)+ROUND(((ROUND((ROUND(((AE33-((EU33*1.2)))*AV33*1),2)*BS33),2)*AU33)/100),2)) -> 24964.33 | DB33: 6 | DD33: *1 | DE33: *1,2 | DF33: *1,2 | DG33: *1,2 | DI33: *1,2 | DJ33: *1,2 | DN33: 0 | DO33: 0 | DP33: 1 | DQ33: 1 | DU33: 1003 | DV33: 100 м | DW33: 100 м | DX33: 100 | EE33: 85133723 | EF33: 60 | EG33: Ремонтно-строительные работы | EH33: 0 | EJ33: 1 | EK33: 102 | EL33: ТСН-2001.6-65. Внутренние санитарно-технические работы: демонтаж и разборка | EM33: ТСН-2001.6-65-1 | EO33: Поправка: Гл.12.Прил.8.п.8. 3_12.00.01.11.001 | EQ33: 0 | ER33: 713.53 | ES33: 55.28 | ET33: 1.37 | EU33: 0 | EV33: 656.88 | EW33: 60.32 | EX33: 0 | EY33: 0 | FQ33: 0 | FR33: 0 | FS33: 0 | FX33: 87 | FY33: 44 | GD33: 1 | GF33: -952300200 | GG33: 2 | GH33: 1 | GI33: 2 | GJ33: 0 | GK33: 0 | GL33: =ROUND(IF(AND(BH33=3,BI33=3,FS33<>0),P33,0),2) -> 0 | GM33: =ROUND(O33+X33+Y33,2)+GX33 -> 132130.29 | GN33: =IF(OR(BI33=0,BI33=1),GM33-GX33,0) -> 132130.29 | GO33: =IF(BI33=2,GM33-GX33,0) -> 0 | GP33: =IF(BI33=4,GM33-GX33,0) -> 0 | GR33: 0 | GS33: 3 | GT33: 0 | GV33: =ROUND((GT33),6) -> 0 | GW33: 1 | GX33: =ROUND(HC33*I33,2) -> 0 | HA33: 0 | HB33: 0 | HC33: =GV33*GW33 -> 0 | HS33: 0 | IK33: 0
A34: 17 | B34: 1 | C34: =ROW(SmtRes!A35) -> 35 | D34: =ROW(EtalonRes!A35) -> 35 | E34: 4 | F34: 6.65-11-5 | G34: Разборка трубопроводов центрального отопления на сварке диаметром труб до 100 мм | H34: 100 м | I34: =ROUND((16+16)/100,9) -> 0.32 | J34: 0 | K34: =ROUND((16+16)/100,9) -> 0.32 | O34: =ROUND(CP34,2) -> 295.35 | P34: =ROUND((ROUND((AC34*AW34*I34),2)*BC34),2) -> 24.59 | Q34: =(ROUND((ROUND(((((ET34*1)*1.2))*AV34*I34),2)*BB34),2)+ROUND((ROUND(((AE34-(((EU34*1)*1.2)))*AV34*I34),2)*BS34),2)) -> 0.73 | R34: =(ROUND((ROUND(((((EU34*1)*1.2))*AV34*I34),2)*BS34),2)+ROUND((ROUND(((AE34-(((EU34*1)*1.2)))*AV34*I34),2)*BS34),2)) -> 0 | S34: =ROUND((ROUND((AF34*AV34*I34),2)*BA34),2) -> 270.03 | T34: =ROUND(CU34*I34,2) -> 0 | U34: =CV34*I34 -> 24.571003 | V34: =CW34*I34 -> 0 | W34: =ROUND(CX34*I34,2) -> 0 | X34: =(ROUND((((S34+ROUND((ROUND(((((EU34*1)*1.2))*AV34*I34),2)*BS34),2))*AT34)/100),2)+ROUND(((ROUND((ROUND(((AE34-(((EU34*1)*1.2)))*AV34*I34),2)*BS34),2)*AT34)/100),2)) -> 234.93 | Y34: =(ROUND((((S34+ROUND((ROUND(((((EU34*1)*1.2))*AV34*I34),2)*BS34),2))*AU34)/100),2)+ROUND(((ROUND((ROUND(((AE34-(((EU34*1)*1.2)))*AV34*I34),2)*BS34),2)*AU34)/100),2)) -> 118.81 | AA34: 85736471 | AB34: =ROUND((AC34+AD34+AF34),6) -> 884.99872 | AC34: =ROUND((((ES34*1)*1)),6) -> 76.84 | AD34: =ROUND((((((ET34*1)*1.2))-(((EU34*1)*1.2)))+AE34),6) -> 2.184 | AE34: =ROUND((((EU34*1)*1.2)),6) -> 0 | AF34: =ROUND((((EV34*0.82)*1.2)),6) -> 805.97472 | AG34: =ROUND((AP34),6) -> 0 | AH34: =(((EW34*0.82)*1.2)) -> 73.33752 | AI34: =(((EX34*1)*1.2)) -> 0 | AJ34: =(AS34) -> 0 | AK34: 897.74 | AL34: 76.84 | AM34: 1.82 | AN34: 0 | AO34: 819.08 | AP34: 0 | AQ34: 74.53 | AR34: 0 | AS34: 0 | AT34: 87 | AU34: 44 | AV34: 1.047 | AW34: 1 | AZ34: 1 | BA34: 1 | BB34: 1 | BC34: 1 | BH34: 0 | BI34: 1 | BJ34: ТСН-2001.6 Доп. 79, Сб. 65, т. 11, поз. 5 | BM34: 102 | BN34: 0 | BO34: 6.65-11-5 | BP34: 1 | BQ34: 60 | BR34: 0 | BS34: 1 | BT34: 1 | BU34: 1 | BV34: 1 | BW34: 1 | BX34: 1 | BZ34: 87 | CA34: 44 | CE34: 1566 | CF34: 0 | CG34: 0 | CM34: 0 | CN34: Поправка: Сб.6-65.т3.1.п.3.1.6_06.65.01.28.002 Наименование: При разборке трубопроводов без правки и чистки труб и фасонных частей от накипи и грязи Поправка: Гл.12.Прил.8.п.8. 3_12.00.01.11.001 Наименование: При наличии напряженных и стесненных условий производства работ (стесненность, сложность складирования и транспортной логистики и т.п.) для объектов, расположенных в пределах круговой магистральной системы улиц "Садовое кольцо" города Москвы | CO34: 0 | CP34: =(P34+Q34+S34) -> 295.35 | CQ34: =ROUND((ROUND((AC34*AW34*1),2)*BC34),2) -> 76.84 | CR34: =(ROUND((ROUND(((((ET34*1)*1.2))*AV34*1),2)*BB34),2)+ROUND((ROUND(((AE34-(((EU34*1)*1.2)))*AV34*1),2)*BS34),2)) -> 2.29 | CS34: =(ROUND((ROUND(((((EU34*1)*1.2))*AV34*1),2)*BS34),2)+ROUND((ROUND(((AE34-(((EU34*1)*1.2)))*AV34*1),2)*BS34),2)) -> 0 | CT34: =ROUND((ROUND((AF34*AV34*1),2)*BA34),2) -> 843.86 | CU34: =AG34 -> 0 | CV34: =(AH34*AV34) -> 76.784383 | CW34: =AI34 -> 0 | CX34: =AJ34 -> 0 | CY34: =(ROUND((((S34+ROUND((ROUND(((((EU34*1)*1.2))*AV34*1),2)*BS34),2))*AT34)/100),2)+ROUND(((ROUND((ROUND(((AE34-(((EU34*1)*1.2)))*AV34*1),2)*BS34),2)*AT34)/100),2)) -> 234.93 | CZ34: =(ROUND((((S34+ROUND((ROUND(((((EU34*1)*1.2))*AV34*1),2)*BS34),2))*AU34)/100),2)+ROUND(((ROUND((ROUND(((AE34-(((EU34*1)*1.2)))*AV34*1),2)*BS34),2)*AU34)/100),2)) -> 118.81 | DB34: 7 | DD34: *1)*1 | DE34: *1)*1,2 | DF34: *1)*1,2 | DG34: *0,82)*1,2 | DI34: *0,82)*1,2 | DJ34: *1)*1,2 | DN34: 0 | DO34: 0 | DP34: 1 | DQ34: 1 | DU34: 1003 | DV34: 100 м | DW34: 100 м | DX34: 100 | EE34: 85133723 | EF34: 60 | EG34: Ремонтно-строительные работы | EH34: 0 | EJ34: 1 | EK34: 102 | EL34: ТСН-2001.6-65. Внутренние санитарно-технические работы: демонтаж и разборка | EM34: ТСН-2001.6-65-1 | EO34: Поправка: Сб.6-65.т3.1.п.3.1.6_06.65.01.28.002 Поправка: Гл.12.Прил.8.п.8. 3_12.00.01.11.001 | EQ34: 0 | ER34: 897.74 | ES34: 76.84 | ET34: 1.82 | EU34: 0 | EV34: 819.08 | EW34: 74.53 | EX34: 0 | EY34: 0 | FQ34: 0 | FR34: 0 | FS34: 0 | FX34: 87 | FY34: 44 | GD34: 1 | GF34: 1211388190 | GG34: 2 | GH34: 1 | GI34: 2 | GJ34: 0 | GK34: 0 | GL34: =ROUND(IF(AND(BH34=3,BI34=3,FS34<>0),P34,0),2) -> 0 | GM34: =ROUND(O34+X34+Y34,2)+GX34 -> 649.09 | GN34: =IF(OR(BI34=0,BI34=1),GM34-GX34,0) -> 649.09 | GO34: =IF(BI34=2,GM34-GX34,0) -> 0 | GP34: =IF(BI34=4,GM34-GX34,0) -> 0 | GR34: 0 | GS34: 3 | GT34: 0 | GV34: =ROUND((GT34),6) -> 0 | GW34: 1 | GX34: =ROUND(HC34*I34,2) -> 0 | HA34: 0 | HB34: 0 | HC34: =GV34*GW34 -> 0 | HS34: 0 | IK34: 0
A35: 17 | B35: 1 | C35: =ROW(SmtRes!A40) -> 40 | D35: =ROW(EtalonRes!A40) -> 40 | E35: 4 | F35: 6.65-11-5 | G35: Разборка трубопроводов центрального отопления на сварке диаметром труб до 100 мм | H35: 100 м | I35: =ROUND((16+16)/100,9) -> 0.32 | J35: 0 | K35: =ROUND((16+16)/100,9) -> 0.32 | O35: =ROUND(CP35,2) -> 15604.85 | P35: =ROUND((ROUND((AC35*AW35*I35),2)*BC35),2) -> 381.88 | Q35: =(ROUND((ROUND(((((ET35*1)*1.2))*AV35*I35),2)*BB35),2)+ROUND((ROUND(((AE35-(((EU35*1)*1.2)))*AV35*I35),2)*BS35),2)) -> 6.78 | R35: =(ROUND((ROUND(((((EU35*1)*1.2))*AV35*I35),2)*BS35),2)+ROUND((ROUND(((AE35-(((EU35*1)*1.2)))*AV35*I35),2)*BS35),2)) -> 0 | S35: =ROUND((ROUND((AF35*AV35*I35),2)*BA35),2) -> 15216.19 | T35: =ROUND(CU35*I35,2) -> 0 | U35: =CV35*I35 -> 24.571003 | V35: =CW35*I35 -> 0 | W35: =ROUND(CX35*I35,2) -> 0 | X35: =(ROUND((((S35+ROUND((ROUND(((((EU35*1)*1.2))*AV35*I35),2)*BS35),2))*AT35)/100),2)+ROUND(((ROUND((ROUND(((AE35-(((EU35*1)*1.2)))*AV35*I35),2)*BS35),2)*AT35)/100),2)) -> 13238.09 | Y35: =(ROUND((((S35+ROUND((ROUND(((((EU35*1)*1.2))*AV35*I35),2)*BS35),2))*AU35)/100),2)+ROUND(((ROUND((ROUND(((AE35-(((EU35*1)*1.2)))*AV35*I35),2)*BS35),2)*AU35)/100),2)) -> 6695.12 | AA35: 85736473 | AB35: =ROUND((AC35+AD35+AF35),6) -> 884.99872 | AC35: =ROUND((((ES35*1)*1)),6) -> 76.84 | AD35: =ROUND((((((ET35*1)*1.2))-(((EU35*1)*1.2)))+AE35),6) -> 2.184 | AE35: =ROUND((((EU35*1)*1.2)),6) -> 0 | AF35: =ROUND((((EV35*0.82)*1.2)),6) -> 805.97472 | AG35: =ROUND((AP35),6) -> 0 | AH35: =(((EW35*0.82)*1.2)) -> 73.33752 | AI35: =(((EX35*1)*1.2)) -> 0 | AJ35: =(AS35) -> 0 | AK35: 897.74 | AL35: 76.84 | AM35: 1.82 | AN35: 0 | AO35: 819.08 | AP35: 0 | AQ35: 74.53 | AR35: 0 | AS35: 0 | AT35: 87 | AU35: 44 | AV35: 1.047 | AW35: 1 | AZ35: 1 | BA35: 56.35 | BB35: 9.29 | BC35: 15.53 | BH35: 0 | BI35: 1 | BJ35: ТСН-2001.6 Доп. 79, Сб. 65, т. 11, поз. 5 | BM35: 102 | BN35: 0 | BO35: 6.65-11-5 | BP35: 1 | BQ35: 60 | BR35: 0 | BS35: 56.35 | BT35: 1 | BU35: 1 | BV35: 1 | BW35: 1 | BX35: 1 | BZ35: 87 | CA35: 44 | CE35: 1566 | CF35: 0 | CG35: 0 | CM35: 0 | CN35: Поправка: Сб.6-65.т3.1.п.3.1.6_06.65.01.28.002 Наименование: При разборке трубопроводов без правки и чистки труб и фасонных частей от накипи и грязи Поправка: Гл.12.Прил.8.п.8. 3_12.00.01.11.001 Наименование: При наличии напряженных и стесненных условий производства работ (стесненность, сложность складирования и транспортной логистики и т.п.) для объектов, расположенных в пределах круговой магистральной системы улиц "Садовое кольцо" города Москвы | CO35: 0 | CP35: =(P35+Q35+S35) -> 15604.85 | CQ35: =ROUND((ROUND((AC35*AW35*1),2)*BC35),2) -> 1193.33 | CR35: =(ROUND((ROUND(((((ET35*1)*1.2))*AV35*1),2)*BB35),2)+ROUND((ROUND(((AE35-(((EU35*1)*1.2)))*AV35*1),2)*BS35),2)) -> 21.27 | CS35: =(ROUND((ROUND(((((EU35*1)*1.2))*AV35*1),2)*BS35),2)+ROUND((ROUND(((AE35-(((EU35*1)*1.2)))*AV35*1),2)*BS35),2)) -> 0 | CT35: =ROUND((ROUND((AF35*AV35*1),2)*BA35),2) -> 47551.51 | CU35: =AG35 -> 0 | CV35: =(AH35*AV35) -> 76.784383 | CW35: =AI35 -> 0 | CX35: =AJ35 -> 0 | CY35: =(ROUND((((S35+ROUND((ROUND(((((EU35*1)*1.2))*AV35*1),2)*BS35),2))*AT35)/100),2)+ROUND(((ROUND((ROUND(((AE35-(((EU35*1)*1.2)))*AV35*1),2)*BS35),2)*AT35)/100),2)) -> 13238.09 | CZ35: =(ROUND((((S35+ROUND((ROUND(((((EU35*1)*1.2))*AV35*1),2)*BS35),2))*AU35)/100),2)+ROUND(((ROUND((ROUND(((AE35-(((EU35*1)*1.2)))*AV35*1),2)*BS35),2)*AU35)/100),2)) -> 6695.12 | DB35: 9 | DD35: *1)*1 | DE35: *1)*1,2 | DF35: *1)*1,2 | DG35: *0,82)*1,2 | DI35: *0,82)*1,2 | DJ35: *1)*1,2 | DN35: 0 | DO35: 0 | DP35: 1 | DQ35: 1 | DU35: 1003 | DV35: 100 м | DW35: 100 м | DX35: 100 | EE35: 85133723 | EF35: 60 | EG35: Ремонтно-строительные работы | EH35: 0 | EJ35: 1 | EK35: 102 | EL35: ТСН-2001.6-65. Внутренние санитарно-технические работы: демонтаж и разборка | EM35: ТСН-2001.6-65-1 | EO35: Поправка: Сб.6-65.т3.1.п.3.1.6_06.65.01.28.002 Поправка: Гл.12.Прил.8.п.8. 3_12.00.01.11.001 | EQ35: 0 | ER35: 897.74 | ES35: 76.84 | ET35: 1.82 | EU35: 0 | EV35: 819.08 | EW35: 74.53 | EX35: 0 | EY35: 0 | FQ35: 0 | FR35: 0 | FS35: 0 | FX35: 87 | FY35: 44 | GD35: 1 | GF35: 1211388190 | GG35: 2 | GH35: 1 | GI35: 2 | GJ35: 0 | GK35: 0 | GL35: =ROUND(IF(AND(BH35=3,BI35=3,FS35<>0),P35,0),2) -> 0 | GM35: =ROUND(O35+X35+Y35,2)+GX35 -> 35538.06 | GN35: =IF(OR(BI35=0,BI35=1),GM35-GX35,0) -> 35538.06 | GO35: =IF(BI35=2,GM35-GX35,0) -> 0 | GP35: =IF(BI35=4,GM35-GX35,0) -> 0 | GR35: 0 | GS35: 3 | GT35: 0 | GV35: =ROUND((GT35),6) -> 0 | GW35: 1 | GX35: =ROUND(HC35*I35,2) -> 0 | HA35: 0 | HB35: 0 | HC35: =GV35*GW35 -> 0 | HS35: 0 | IK35: 0
A36: 17 | B36: 1 | C36: =ROW(SmtRes!A48) -> 48 | D36: =ROW(EtalonRes!A53) -> 53 | E36: 5 | F36: 3.16-40-1 | G36: Прокладка напорного трубопровода водоснабжения и отопления из многослойного полипропилена, армированного стекловолокном, из заранее собранных узлов, наружный диаметр 20 мм (демонтаж) | H36: 100 м | I36: =ROUND((43+30)/100,9) -> 0.73 | J36: 0 | K36: =ROUND((43+30)/100,9) -> 0.73 | O36: =ROUND(CP36,2) -> 74.28 | P36: =ROUND((ROUND((AC36*AW36*I36),2)*BC36),2) -> 0 | Q36: =(ROUND((ROUND(((((ET36*0.4)*1.2))*AV36*I36),2)*BB36),2)+ROUND((ROUND(((AE36-(((EU36*0.4)*1.2)))*AV36*I36),2)*BS36),2)) -> 6.87 | R36: =(ROUND((ROUND(((((EU36*0.4)*1.2))*AV36*I36),2)*BS36),2)+ROUND((ROUND(((AE36-(((EU36*0.4)*1.2)))*AV36*I36),2)*BS36),2)) -> 0.19 | S36: =ROUND((ROUND((AF36*AV36*I36),2)*BA36),2) -> 67.41 | T36: =ROUND(CU36*I36,2) -> 0 | U36: =CV36*I36 -> 5.4436462 | V36: =CW36*I36 -> 0 | W36: =ROUND(CX36*I36,2) -> 0 | X36: =(ROUND((((S36+ROUND((ROUND(((((EU36*0.4)*1.2))*AV36*I36),2)*BS36),2))*AT36)/100),2)+ROUND(((ROUND((ROUND(((AE36-(((EU36*0.4)*1.2)))*AV36*I36),2)*BS36),2)*AT36)/100),2)) -> 73.68 | Y36: =(ROUND((((S36+ROUND((ROUND(((((EU36*0.4)*1.2))*AV36*I36),2)*BS36),2))*AU36)/100),2)+ROUND(((ROUND((ROUND(((AE36-(((EU36*0.4)*1.2)))*AV36*I36),2)*BS36),2)*AU36)/100),2)) -> 41.24 | AA36: 85736471 | AB36: =ROUND((AC36+AD36+AF36),6) -> 95.3712 | AC36: =ROUND((((ES36*0)*1)),6) -> 0 | AD36: =ROUND((((((ET36*0.4)*1.2))-(((EU36*0.4)*1.2)))+AE36),6) -> 8.8224 | AE36: =ROUND((((EU36*0.4)*1.2)),6) -> 0.24 | AF36: =ROUND((((EV36*0.4)*1.2)),6) -> 86.5488 | AG36: =ROUND((AP36),6) -> 0 | AH36: =(((EW36*0.4)*1.2)) -> 6.9888 | AI36: =(((EX36*0.4)*1.2)) -> 0 | AJ36: =(AS36) -> 0 | AK36: 351.79 | AL36: 153.1 | AM36: 18.38 | AN36: 0.5 | AO36: 180.31 | AP36: 0 | AQ36: 14.56 | AR36: 0 | AS36: 0 | AT36: 109 | AU36: 61 | AV36: 1.067 | AW36: 1 | AZ36: 1 | BA36: 1 | BB36: 1 | BC36: 1 | BH36: 0 | BI36: 1 | BJ36: ТСН-2001.3 Доп. 79, Сб. 16, т. 40, поз. 1 | BM36: 21 | BN36: 0 | BO36: 3.16-40-1 | BP36: 1 | BQ36: 30 | BR36: 0 | BS36: 1 | BT36: 1 | BU36: 1 | BV36: 1 | BW36: 1 | BX36: 1 | BZ36: 109 | CA36: 61 | CE36: 1566 | CF36: 0 | CG36: 0 | CM36: 0 | CN36: Поправка: Гл.6.Прил.2.2.п.2.2.13_06.00.01.35.003 Наименование: При демонтаже внутренних санитарно-технических устройств и газопроводов Поправка: Гл.12.Прил.8.п.8. 3_12.00.01.11.001 Наименование: При наличии напряженных и стесненных условий производства работ (стесненность, сложность складирования и транспортной логистики и т.п.) для объектов, расположенных в пределах круговой магистральной системы улиц "Садовое кольцо" города Москвы | CO36: 0 | CP36: =(P36+Q36+S36) -> 74.28 | CQ36: =ROUND((ROUND((AC36*AW36*1),2)*BC36),2) -> 0 | CR36: =(ROUND((ROUND(((((ET36*0.4)*1.2))*AV36*1),2)*BB36),2)+ROUND((ROUND(((AE36-(((EU36*0.4)*1.2)))*AV36*1),2)*BS36),2)) -> 9.41 | CS36: =(ROUND((ROUND(((((EU36*0.4)*1.2))*AV36*1),2)*BS36),2)+ROUND((ROUND(((AE36-(((EU36*0.4)*1.2)))*AV36*1),2)*BS36),2)) -> 0.26 | CT36: =ROUND((ROUND((AF36*AV36*1),2)*BA36),2) -> 92.35 | CU36: =AG36 -> 0 | CV36: =(AH36*AV36) -> 7.4570496 | CW36: =AI36 -> 0 | CX36: =AJ36 -> 0 | CY36: =(ROUND((((S36+ROUND((ROUND(((((EU36*0.4)*1.2))*AV36*1),2)*BS36),2))*AT36)/100),2)+ROUND(((ROUND((ROUND(((AE36-(((EU36*0.4)*1.2)))*AV36*1),2)*BS36),2)*AT36)/100),2)) -> 73.76 | CZ36: =(ROUND((((S36+ROUND((ROUND(((((EU36*0.4)*1.2))*AV36*1),2)*BS36),2))*AU36)/100),2)+ROUND(((ROUND((ROUND(((AE36-(((EU36*0.4)*1.2)))*AV36*1),2)*BS36),2)*AU36)/100),2)) -> 41.28 | DB36: 11 | DD36: *0)*1 | DE36: *0,4)*1,2 | DF36: *0,4)*1,2 | DG36: *0,4)*1,2 | DI36: *0,4)*1,2 | DJ36: *0,4)*1,2 | DN36: 0 | DO36: 0 | DP36: 1 | DQ36: 1 | DU36: 1003 | DV36: 100 м | DW36: 100 м | DX36: 100 | EE36: 85133641 | EF36: 30 | EG36: Строительные работы | EH36: 0 | EJ36: 1 | EK36: 21 | EL36: ТСН-2001.3-16. Трубопроводы внутренние | EM36: ТСН-2001.3-16-1 | EO36: Поправка: Гл.6.Прил.2.2.п.2.2.13_06.00.01.35.003 Поправка: Гл.12.Прил.8.п.8. 3_12.00.01.11.001 | EQ36: 0 | ER36: 351.79 | ES36: 153.1 | ET36: 18.38 | EU36: 0.5 | EV36: 180.31 | EW36: 14.56 | EX36: 0 | EY36: 0 | FQ36: 0 | FR36: 0 | FS36: 0 | FX36: 109 | FY36: 61 | GD36: 1 | GF36: 470604376 | GG36: 2 | GH36: 1 | GI36: 2 | GJ36: 0 | GK36: 0 | GL36: =ROUND(IF(AND(BH36=3,BI36=3,FS36<>0),P36,0),2) -> 0 | GM36: =ROUND(O36+X36+Y36,2)+GX36 -> 189.2 | GN36: =IF(OR(BI36=0,BI36=1),GM36-GX36,0) -> 189.2 | GO36: =IF(BI36=2,GM36-GX36,0) -> 0 | GP36: =IF(BI36=4,GM36-GX36,0) -> 0 | GR36: 0 | GS36: 3 | GT36: 0 | GV36: =ROUND((GT36),6) -> 0 | GW36: 1 | GX36: =ROUND(HC36*I36,2) -> 0 | HA36: 0 | HB36: 0 | HC36: =GV36*GW36 -> 0 | HS36: 0 | IK36: 0
A37: 17 | B37: 1 | C37: =ROW(SmtRes!A56) -> 56 | D37: =ROW(EtalonRes!A66) -> 66 | E37: 5 | F37: 3.16-40-1 | G37: Прокладка напорного трубопровода водоснабжения и отопления из многослойного полипропилена, армированного стекловолокном, из заранее собранных узлов, наружный диаметр 20 мм (демонтаж) | H37: 100 м | I37: =ROUND((43+30)/100,9) -> 0.73 | J37: 0 | K37: =ROUND((43+30)/100,9) -> 0.73 | O37: =ROUND(CP37,2) -> 3882.78 | P37: =ROUND((ROUND((AC37*AW37*I37),2)*BC37),2) -> 0 | Q37: =(ROUND((ROUND(((((ET37*0.4)*1.2))*AV37*I37),2)*BB37),2)+ROUND((ROUND(((AE37-(((EU37*0.4)*1.2)))*AV37*I37),2)*BS37),2)) -> 84.23 | R37: =(ROUND((ROUND(((((EU37*0.4)*1.2))*AV37*I37),2)*BS37),2)+ROUND((ROUND(((AE37-(((EU37*0.4)*1.2)))*AV37*I37),2)*BS37),2)) -> 10.71 | S37: =ROUND((ROUND((AF37*AV37*I37),2)*BA37),2) -> 3798.55 | T37: =ROUND(CU37*I37,2) -> 0 | U37: =CV37*I37 -> 5.4436462 | V37: =CW37*I37 -> 0 | W37: =ROUND(CX37*I37,2) -> 0 | X37: =(ROUND((((S37+ROUND((ROUND(((((EU37*0.4)*1.2))*AV37*I37),2)*BS37),2))*AT37)/100),2)+ROUND(((ROUND((ROUND(((AE37-(((EU37*0.4)*1.2)))*AV37*I37),2)*BS37),2)*AT37)/100),2)) -> 4152.09 | Y37: =(ROUND((((S37+ROUND((ROUND(((((EU37*0.4)*1.2))*AV37*I37),2)*BS37),2))*AU37)/100),2)+ROUND(((ROUND((ROUND(((AE37-(((EU37*0.4)*1.2)))*AV37*I37),2)*BS37),2)*AU37)/100),2)) -> 2323.65 | AA37: 85736473 | AB37: =ROUND((AC37+AD37+AF37),6) -> 95.3712 | AC37: =ROUND((((ES37*0)*1)),6) -> 0 | AD37: =ROUND((((((ET37*0.4)*1.2))-(((EU37*0.4)*1.2)))+AE37),6) -> 8.8224 | AE37: =ROUND((((EU37*0.4)*1.2)),6) -> 0.24 | AF37: =ROUND((((EV37*0.4)*1.2)),6) -> 86.5488 | AG37: =ROUND((AP37),6) -> 0 | AH37: =(((EW37*0.4)*1.2)) -> 6.9888 | AI37: =(((EX37*0.4)*1.2)) -> 0 | AJ37: =(AS37) -> 0 | AK37: 351.79 | AL37: 153.1 | AM37: 18.38 | AN37: 0.5 | AO37: 180.31 | AP37: 0 | AQ37: 14.56 | AR37: 0 | AS37: 0 | AT37: 109 | AU37: 61 | AV37: 1.067 | AW37: 1 | AZ37: 1 | BA37: 56.35 | BB37: 12.26 | BC37: 1.98 | BH37: 0 | BI37: 1 | BJ37: ТСН-2001.3 Доп. 79, Сб. 16, т. 40, поз. 1 | BM37: 21 | BN37: 0 | BO37: 3.16-40-1 | BP37: 1 | BQ37: 30 | BR37: 0 | BS37: 56.35 | BT37: 1 | BU37: 1 | BV37: 1 | BW37: 1 | BX37: 1 | BZ37: 109 | CA37: 61 | CE37: 1566 | CF37: 0 | CG37: 0 | CM37: 0 | CN37: Поправка: Гл.6.Прил.2.2.п.2.2.13_06.00.01.35.003 Наименование: При демонтаже внутренних санитарно-технических устройств и газопроводов Поправка: Гл.12.Прил.8.п.8. 3_12.00.01.11.001 Наименование: При наличии напряженных и стесненных условий производства работ (стесненность, сложность складирования и транспортной логистики и т.п.) для объектов, расположенных в пределах круговой магистральной системы улиц "Садовое кольцо" города Москвы | CO37: 0 | CP37: =(P37+Q37+S37) -> 3882.78 | CQ37: =ROUND((ROUND((AC37*AW37*1),2)*BC37),2) -> 0 | CR37: =(ROUND((ROUND(((((ET37*0.4)*1.2))*AV37*1),2)*BB37),2)+ROUND((ROUND(((AE37-(((EU37*0.4)*1.2)))*AV37*1),2)*BS37),2)) -> 115.37 | CS37: =(ROUND((ROUND(((((EU37*0.4)*1.2))*AV37*1),2)*BS37),2)+ROUND((ROUND(((AE37-(((EU37*0.4)*1.2)))*AV37*1),2)*BS37),2)) -> 14.65 | CT37: =ROUND((ROUND((AF37*AV37*1),2)*BA37),2) -> 5203.92 | CU37: =AG37 -> 0 | CV37: =(AH37*AV37) -> 7.4570496 | CW37: =AI37 -> 0 | CX37: =AJ37 -> 0 | CY37: =(ROUND((((S37+ROUND((ROUND(((((EU37*0.4)*1.2))*AV37*1),2)*BS37),2))*AT37)/100),2)+ROUND(((ROUND((ROUND(((AE37-(((EU37*0.4)*1.2)))*AV37*1),2)*BS37),2)*AT37)/100),2)) -> 4156.39 | CZ37: =(ROUND((((S37+ROUND((ROUND(((((EU37*0.4)*1.2))*AV37*1),2)*BS37),2))*AU37)/100),2)+ROUND(((ROUND((ROUND(((AE37-(((EU37*0.4)*1.2)))*AV37*1),2)*BS37),2)*AU37)/100),2)) -> 2326.05 | DB37: 13 | DD37: *0)*1 | DE37: *0,4)*1,2 | DF37: *0,4)*1,2 | DG37: *0,4)*1,2 | DI37: *0,4)*1,2 | DJ37: *0,4)*1,2 | DN37: 0 | DO37: 0 | DP37: 1 | DQ37: 1 | DU37: 1003 | DV37: 100 м | DW37: 100 м | DX37: 100 | EE37: 85133641 | EF37: 30 | EG37: Строительные работы | EH37: 0 | EJ37: 1 | EK37: 21 | EL37: ТСН-2001.3-16. Трубопроводы внутренние | EM37: ТСН-2001.3-16-1 | EO37: Поправка: Гл.6.Прил.2.2.п.2.2.13_06.00.01.35.003 Поправка: Гл.12.Прил.8.п.8. 3_12.00.01.11.001 | EQ37: 0 | ER37: 351.79 | ES37: 153.1 | ET37: 18.38 | EU37: 0.5 | EV37: 180.31 | EW37: 14.56 | EX37: 0 | EY37: 0 | FQ37: 0 | FR37: 0 | FS37: 0 | FX37: 109 | FY37: 61 | GD37: 1 | GF37: 470604376 | GG37: 2 | GH37: 1 | GI37: 2 | GJ37: 0 | GK37: 0 | GL37: =ROUND(IF(AND(BH37=3,BI37=3,FS37<>0),P37,0),2) -> 0 | GM37: =ROUND(O37+X37+Y37,2)+GX37 -> 10358.52 | GN37: =IF(OR(BI37=0,BI37=1),GM37-GX37,0) -> 10358.52 | GO37: =IF(BI37=2,GM37-GX37,0) -> 0 | GP37: =IF(BI37=4,GM37-GX37,0) -> 0 | GR37: 0 | GS37: 3 | GT37: 0 | GV37: =ROUND((GT37),6) -> 0 | GW37: 1 | GX37: =ROUND(HC37*I37,2) -> 0 | HA37: 0 | HB37: 0 | HC37: =GV37*GW37 -> 0 | HS37: 0 | IK37: 0
A38: 17 | B38: 1 | C38: =ROW(SmtRes!A64) -> 64 | D38: =ROW(EtalonRes!A79) -> 79 | E38: 6 | F38: 3.16-40-2 | G38: Прокладка напорного трубопровода водоснабжения и отопления из многослойного полипропилена, армированного стекловолокном, из заранее собранных узлов, наружный диаметр 25 мм (демонтаж) | H38: 100 м | I38: =ROUND((145+30)/100,9) -> 1.75 | J38: 0 | K38: =ROUND((145+30)/100,9) -> 1.75 | O38: =ROUND(CP38,2) -> 173.65 | P38: =ROUND((ROUND((AC38*AW38*I38),2)*BC38),2) -> 0 | Q38: =(ROUND((ROUND(((((ET38*0.4)*1.2))*AV38*I38),2)*BB38),2)+ROUND((ROUND(((AE38-(((EU38*0.4)*1.2)))*AV38*I38),2)*BS38),2)) -> 17.63 | R38: =(ROUND((ROUND(((((EU38*0.4)*1.2))*AV38*I38),2)*BS38),2)+ROUND((ROUND(((AE38-(((EU38*0.4)*1.2)))*AV38*I38),2)*BS38),2)) -> 0.68 | S38: =ROUND((ROUND((AF38*AV38*I38),2)*BA38),2) -> 156.02 | T38: =ROUND(CU38*I38,2) -> 0 | U38: =CV38*I38 -> 12.619622 | V38: =CW38*I38 -> 0 | W38: =ROUND(CX38*I38,2) -> 0 | X38: =(ROUND((((S38+ROUND((ROUND(((((EU38*0.4)*1.2))*AV38*I38),2)*BS38),2))*AT38)/100),2)+ROUND(((ROUND((ROUND(((AE38-(((EU38*0.4)*1.2)))*AV38*I38),2)*BS38),2)*AT38)/100),2)) -> 170.8 | Y38: =(ROUND((((S38+ROUND((ROUND(((((EU38*0.4)*1.2))*AV38*I38),2)*BS38),2))*AU38)/100),2)+ROUND(((ROUND((ROUND(((AE38-(((EU38*0.4)*1.2)))*AV38*I38),2)*BS38),2)*AU38)/100),2)) -> 95.59 | AA38: 85736471 | AB38: =ROUND((AC38+AD38+AF38),6) -> 92.9952 | AC38: =ROUND((((ES38*0)*1)),6) -> 0 | AD38: =ROUND((((((ET38*0.4)*1.2))-(((EU38*0.4)*1.2)))+AE38),6) -> 9.4416 | AE38: =ROUND((((EU38*0.4)*1.2)),6) -> 0.3648 | AF38: =ROUND((((EV38*0.4)*1.2)),6) -> 83.5536 | AG38: =ROUND((AP38),6) -> 0 | AH38: =(((EW38*0.4)*1.2)) -> 6.7584 | AI38: =(((EX38*0.4)*1.2)) -> 0 | AJ38: =(AS38) -> 0 | AK38: 328.44 | AL38: 134.7 | AM38: 19.67 | AN38: 0.76 | AO38: 174.07 | AP38: 0 | AQ38: 14.08 | AR38: 0 | AS38: 0 | AT38: 109 | AU38: 61 | AV38: 1.067 | AW38: 1 | AZ38: 1 | BA38: 1 | BB38: 1 | BC38: 1 | BH38: 0 | BI38: 1 | BJ38: ТСН-2001.3 Доп. 79, Сб. 16, т. 40, поз. 2 | BM38: 21 | BN38: 0 | BO38: 3.16-40-2 | BP38: 1 | BQ38: 30 | BR38: 0 | BS38: 1 | BT38: 1 | BU38: 1 | BV38: 1 | BW38: 1 | BX38: 1 | BZ38: 109 | CA38: 61 | CE38: 1566 | CF38: 0 | CG38: 0 | CM38: 0 | CN38: Поправка: Гл.6.Прил.2.2.п.2.2.13_06.00.01.35.003 Наименование: При демонтаже внутренних санитарно-технических устройств и газопроводов Поправка: Гл.12.Прил.8.п.8. 3_12.00.01.11.001 Наименование: При наличии напряженных и стесненных условий производства работ (стесненность, сложность складирования и транспортной логистики и т.п.) для объектов, расположенных в пределах круговой магистральной системы улиц "Садовое кольцо" города Москвы | CO38: 0 | CP38: =(P38+Q38+S38) -> 173.65 | CQ38: =ROUND((ROUND((AC38*AW38*1),2)*BC38),2) -> 0 | CR38: =(ROUND((ROUND(((((ET38*0.4)*1.2))*AV38*1),2)*BB38),2)+ROUND((ROUND(((AE38-(((EU38*0.4)*1.2)))*AV38*1),2)*BS38),2)) -> 10.07 | CS38: =(ROUND((ROUND(((((EU38*0.4)*1.2))*AV38*1),2)*BS38),2)+ROUND((ROUND(((AE38-(((EU38*0.4)*1.2)))*AV38*1),2)*BS38),2)) -> 0.39 | CT38: =ROUND((ROUND((AF38*AV38*1),2)*BA38),2) -> 89.15 | CU38: =AG38 -> 0 | CV38: =(AH38*AV38) -> 7.2112128 | CW38: =AI38 -> 0 | CX38: =AJ38 -> 0 | CY38: =(ROUND((((S38+ROUND((ROUND(((((EU38*0.4)*1.2))*AV38*1),2)*BS38),2))*AT38)/100),2)+ROUND(((ROUND((ROUND(((AE38-(((EU38*0.4)*1.2)))*AV38*1),2)*BS38),2)*AT38)/100),2)) -> 170.49 | CZ38: =(ROUND((((S38+ROUND((ROUND(((((EU38*0.4)*1.2))*AV38*1),2)*BS38),2))*AU38)/100),2)+ROUND(((ROUND((ROUND(((AE38-(((EU38*0.4)*1.2)))*AV38*1),2)*BS38),2)*AU38)/100),2)) -> 95.41 | DB38: 15 | DD38: *0)*1 | DE38: *0,4)*1,2 | DF38: *0,4)*1,2 | DG38: *0,4)*1,2 | DI38: *0,4)*1,2 | DJ38: *0,4)*1,2 | DN38: 0 | DO38: 0 | DP38: 1 | DQ38: 1 | DU38: 1003 | DV38: 100 м | DW38: 100 м | DX38: 100 | EE38: 85133641 | EF38: 30 | EG38: Строительные работы | EH38: 0 | EJ38: 1 | EK38: 21 | EL38: ТСН-2001.3-16. Трубопроводы внутренние | EM38: ТСН-2001.3-16-1 | EO38: Поправка: Гл.6.Прил.2.2.п.2.2.13_06.00.01.35.003 Поправка: Гл.12.Прил.8.п.8. 3_12.00.01.11.001 | EQ38: 0 | ER38: 328.44 | ES38: 134.7 | ET38: 19.67 | EU38: 0.76 | EV38: 174.07 | EW38: 14.08 | EX38: 0 | EY38: 0 | FQ38: 0 | FR38: 0 | FS38: 0 | FX38: 109 | FY38: 61 | GD38: 1 | GF38: -23638325 | GG38: 2 | GH38: 1 | GI38: 2 | GJ38: 0 | GK38: 0 | GL38: =ROUND(IF(AND(BH38=3,BI38=3,FS38<>0),P38,0),2) -> 0 | GM38: =ROUND(O38+X38+Y38,2)+GX38 -> 440.04 | GN38: =IF(OR(BI38=0,BI38=1),GM38-GX38,0) -> 440.04 | GO38: =IF(BI38=2,GM38-GX38,0) -> 0 | GP38: =IF(BI38=4,GM38-GX38,0) -> 0 | GR38: 0 | GS38: 3 | GT38: 0 | GV38: =ROUND((GT38),6) -> 0 | GW38: 1 | GX38: =ROUND(HC38*I38,2) -> 0 | HA38: 0 | HB38: 0 | HC38: =GV38*GW38 -> 0 | HS38: 0 | IK38: 0
