Workbook

Sheet Смета по ТСН-2001(с доп.67
A1: =Source!B1 -> Smeta.RU (495) 974-1589
J2: Форма № 4б
B3: "СОГЛАСОВАНО" | G3: "УТВЕРЖДАЮ"
B6: =CONCATENATE("______________________ ", IF(Source!AL12<>"", Source!AL12, "")) -> ______________________ | G6: =CONCATENATE("______________________ ", IF(Source!AH12<>"", Source!AH12, "")) -> ______________________
B7: "_____"________________ 2026 г. | G7: "_____"________________ 2026 г.
A10: Капитальный ремонт здания Государственного бюджетного общеобразовательного учреждения города Москвы «Школа №1574», расположенного по адресу: г. Москва, Старопименовский переулок, д. 5. 1 этап. | AP10: Капитальный ремонт здания Государственного бюджетного общеобразовательного учреждения города Москвы «Школа №1574», расположенного по адресу: г. Москва, Старопименовский переулок, д. 5. 1 этап. 02-01-20 ОДИ 16.07.26
A11: (наименование стройки и/или объекта)
A13: =CONCATENATE( "ЛОКАЛЬНАЯ СМЕТА № ",IF(Source!F12<>"Новый объект", Source!F12, "")) -> ЛОКАЛЬНАЯ СМЕТА № 02-01-20
A15: =Source!G20 -> Мероприятия по обеспечению доступа инвалидов
A16: (наименование работ и затрат)
A18: =CONCATENATE( "Основание: чертежи № ", Source!J12) -> Основание: чертежи № 2024-00377-01-0-ОДИ.ВОР
I20: В базисном уровне цен | J20: В текущем уровне цен
E21: Сметная стоимость | I21: =I22+I23+I24+I25 -> 17.89 | J21: =J22+J23+J24+J25 -> 149.04 | K21: тыс.руб.
E22: Строительные работы | I22: =ROUND((Source!F351)/1000, 2) -> 5.06 | J22: =ROUND((Source!P351)/1000, 2) -> 80.24 | K22: тыс.руб.
E23: Работы по монтажу оборудования | I23: =ROUND((Source!F352)/1000, 2) -> 0 | J23: =ROUND((Source!P352)/1000, 2) -> 0 | K23: тыс.руб.
E24: Оборудование | I24: =ROUND((Source!F343)/1000, 2) -> 12.83 | J24: =ROUND((Source!P343)/1000, 2) -> 68.8 | K24: тыс.руб.
E25: Прочие работы и затраты | I25: =ROUND((Source!F353+Source!F354)/1000, 2) -> 0 | J25: =ROUND((Source!P353+Source!P354)/1000, 2) -> 0 | K25: тыс.руб.
E26: Средства на оплату труда | I26: =(Source!F349+ Source!F348)/1000 -> 0.32733 | J26: =((Source!P349 + Source!P348)/1000) -> 18.44505 | K26: тыс.руб.
E27: Затраты труда | I27: =Source!F356 -> 24.208651 | K27: чел.-ч.
E28: Кроме того:
E29: Возврат материалов | I29: =SUM(Y1:Y222)/1000 -> 0 | J29: =SUM(Z1:Z222)/1000 -> 0 | K29: тыс.руб.
A31: Составлен(а) по ТСН-2001 с учетом Дополнения №: 81
A32: № и период сборника коэффициентов (индексов) пересчета: Коэффициенты к ТСН-2001 МГЭ Дополнение 81, ремонт №219/81 I квартал 2026 года и Коэффициенты к ТСН-2001.13-2 Дополнение 47 №64/47 I квартал 2026 года | AP32: № и период сборника коэффициентов (индексов) пересчета: Коэффициенты к ТСН-2001 МГЭ Дополнение 81, ремонт №219/81 I квартал 2026 года и Коэффициенты к ТСН-2001.13-2 Дополнение 47 №64/47 I квартал 2026 года
A33: № п/п | B33: Шифр расценки и коды ресурсов | C33: Наименование работ и затрат | D33: Ед. изм. | E33: Кол-во единиц | F33: Цена на ед. изм., руб. | G33: Попра- вочные коэффи- циенты | H33: Коэффи- циенты зимних удорожа- ний | I33: Всего в ценах на январь 2000 года, руб. | J33: Коэффи- циенты (индек- сы) пере- счета, нормы НР и СП | K33: ВСЕГО затрат в текущем уровне цен, руб.
A34: 1 | B34: 2 | C34: 3 | D34: 4 | E34: 5 | F34: 6 | G34: 7 | H34: 8 | I34: 9 | J34: 10 | K34: 11
A36: =CONCATENATE("Локальная смета: ",IF(Source!G20<>"Новая локальная смета", Source!G20, "")) -> Локальная смета: Мероприятия по обеспечению доступа инвалидов
A38: =CONCATENATE("Раздел: ",IF(Source!G24<>"Новый раздел", Source!G24, "")) -> Раздел: Демонтажные работы (Письмо от АНО «РГТ» об утверждении объёмов демонтажных работ) | AP38: =CONCATENATE("Раздел: ",IF(Source!G24<>"Новый раздел", Source!G24, "")) -> Раздел: Демонтажные работы (Письмо от АНО «РГТ» об утверждении объёмов демонтажных работ)
A40: =CONCATENATE("Итого по разделу: ",IF(Source!G37<>"Новый раздел", Source!G37, "")) -> Итого по разделу: Демонтажные работы (Письмо от АНО «РГТ» об утверждении объёмов демонтажных работ) | H40: =SUM(O38:O39) -> 0 | J40: =SUM(P38:P39) -> 0 | AQ40: =CONCATENATE("Итого по разделу: ",IF(Source!G37<>"Новый раздел", Source!G37, "")) -> Итого по разделу: Демонтажные работы (Письмо от АНО «РГТ» об утверждении объёмов демонтажных работ)
A41: Итого по ТСН-2001.16 | I41: =SUM(W38:W40) -> 0 | J41: =SUM(X38:X40) -> 0
A42: Итого возвратных сумм | I42: =SUM(Y38:Y41) -> 0 | J42: =SUM(Z38:Z41) -> 0
A44: =CONCATENATE("Раздел: ",IF(Source!G67<>"Новый раздел", Source!G67, "")) -> Раздел: Оборудование санузла МГН (универсальная кабина)
A45: 1 | B45: =Source!F71 -> 3.17-2-14 | C45: Установка гарнитуры туалетной: поручней для ванн | D45: =Source!H71 -> 100 шт. | E45: =Source!I71 -> 0.06 | Q45: =Source!X71 -> 18.22 | R45: =Source!X72 -> 1026.97 | S45: =Source!Y71 -> 10.2 | T45: =Source!Y72 -> 574.72 | U45: =ROUND((175/100)*ROUND(Source!R71, 2), 2) -> 0.09 | V45: =ROUND((0/100)*ROUND(Source!R72, 2), 2) -> 0 | AC45: 0
C46: ="Объем: "&Source!I71&"=(1+"&"1+"&"2+"&"1+"&"1)/"&"100" -> Объем: 0,06=(1+1+2+1+1)/100
C47: ЗП | F47: =Source!AO71 -> 188.72 | G47: 1,15*1,2 | H47: =Source!AV72 -> 1.067 | I47: =Source!S71 -> 16.67 | J47: =IF(Source!BA72<> 0, Source!BA72, 1) -> 56.35 | K47: =Source!S72 -> 939.35
C48: ЭМ | F48: =Source!AM71 -> 7.54 | G48: 1,25*1,2 | H48: =Source!AV72 -> 1.067 | I48: =Source!Q71 -> 0.72 | J48: =IF(Source!BB72<> 0, Source!BB72, 1) -> 12.92 | K48: =Source!Q72 -> 9.3
C49: в т.ч. ЗПМ | F49: =Source!AN71 -> 0.5 | G49: 1,25*1,2 | H49: =Source!AV72 -> 1.067 | I49: =Source!R71 -> 0.05 | J49: =IF(Source!BS72<> 0, Source!BS72, 1) -> 56.35 | K49: =Source!R72 -> 2.82
C50: МР | F50: =Source!AL71 -> 5229.82 | H50: =Source!AW72 -> 1 | I50: =Source!P71 -> 313.79 | J50: =IF(Source!BC72<> 0, Source!BC72, 1) -> 0.71 | K50: =Source!P72 -> 222.79
C51: НР от ФОТ | D51: % | E51: =Source!BZ72 -> 109 | I51: =SUM(Q45:Q50) -> 18.22 | J51: =Source!AT72 -> 109 | K51: =SUM(R45:R50) -> 1026.97
C52: СП от ФОТ | D52: % | E52: =Source!CA72 -> 61 | I52: =SUM(S45:S51) -> 10.2 | J52: =Source!AU72 -> 61 | K52: =SUM(T45:T51) -> 574.72
C53: ЗТР | D53: чел-ч | E53: =Source!AQ71 -> 16.89 | G53: 1,15*1,2 | H53: =Source!AV72 -> 1.067 | I53: =Source!U71 -> 1.492191
...

Sheet Source
A1: 0 | B1: Smeta.RU (495) 974-1589 | D1: _PS_ | F1: 0 | G1: 0 | H1: 0 | I1: Smeta.RU | K1: 1 | L1: 74599 | M1: 10 | N1: 12 | O1: 1 | P1: 0 | Q1: 5
A4: 1 | B4: 1 | C4: -1 | G4: Капитальный ремонт здания Государственного бюджетного общеобразовательного учреждения города Москвы «Школа №1574», расположенного по адресу: г. Москва, Старопименовский переулок, д. 5. 1 этап | EC4: 0
A5: 8 | B5: 1 | C5: -1 | G5: Капитальный ремонт здания Государственного бюджетного общеобразовательного учреждения города Москвы «Школа №1574», расположенного по адресу: г. Москва, Старопименовский переулок, д. 5. 1 этап | EC5: 0
A12: 1 | B12: 375 | C12: 0 | D12: =ROW(A334) -> 334 | E12: 0 | F12: 02-01-20 | G12: 02-01-20 ОДИ 16.07.26 | I12: 0 | J12: 2024-00377-01-0-ОДИ.ВОР | K12: 0 | L12: 0 | M12: 4098 | O12: 0 | P12: 0 | Q12: 0 | R12: 0 | S12: 0 | T12: 1 | V12: 0 | AB12: О.А.Гришечкина | AC12: Ведущий инженер-сметчик | AD12: И.В.Феденко | AE12: Начальник отдела | BB12: 0 | BH12: Сметные нормы списания | BI12: Коды ОКП для ТСН-2001 МГЭ Дополнение 81 | BJ12: 1 | BK12: 1 | BL12: 0 | BM12: 0 | BN12: 1 | BO12: 0 | BP12: 6 | BQ12: 2 | BR12: 1 | BS12: 1 | BT12: 0 | BU12: 0 | BV12: 0 | BW12: 0 | BX12: 0 | BY12: ТСН-2001 (МГЭ) Доп 81 - Ремонт | BZ12: Типовой расчет для ТСН-2001 МГЭ, Дополнение 81, ремонт | CA12: Территориальные сметные нормативы для Москвы ТСН-2001 (МГЭ), дополнение 81 | CB12: Территориальные сметные нормативы для Москвы ТСН-2001 (МГЭ), дополнение 81 | CC12: Территориальные сметные нормативы для Москвы ТСН-2001 (МГЭ), дополнение 81 | CD12: Территориальные сметные нормативы для Москвы ТСН-2001 (МГЭ), дополнение 81 | CE12: Поправки для ТСН-2001 от 07.04.2026 г. доп.81 | CF12: 0 | CG12: 0 | CH12: 8200 | CK12: 82 | CQ12: Территориальные сметные нормативы для Москвы (ТСН-2001) | CR12: ТЕР | CS12: 41660 | CT12: 1 | CU12: 81 | CY12: 0 | EC12: 0
A15: 15 | B15: 1
A18: 52 | B18: =B334 -> 375 | C18: =C334 -> 1 | D18: =D334 -> 12 | E18: =E334 -> 0 | F18: =F334 -> 02-01-20 | G18: =G334 -> 02-01-20 ОДИ 16.07.26 | O18: =O334 -> 17437.48 | P18: =P334 -> 17109.22 | Q18: =Q334 -> 1.01 | R18: =R334 -> 0.08 | S18: =S334 -> 327.25 | T18: =T334 -> 0 | U18: =U334 -> 24.208651 | V18: =V334 -> 0 | ... GX18: =GX334 -> 0
A20: 3 | B20: 1 | D20: =ROW(A304) -> 304 | F20: 02-01-20 | G20: Мероприятия по обеспечению доступа инвалидов | I20: 0 | J20: 2024-00377-01-0-ОДИ.ВОР | K20: -1 | L20: 02-01-20 | S20: 0 | T20: 0 | V20: 0 | BX20: 0 | CF20: 0 | CG20: 0
A22: 52 | B22: =B304 -> 1 | C22: =C304 -> 3 | D22: =D304 -> 20 | E22: =E304 -> 0 | F22: =F304 -> 02-01-20 | G22: =G304 -> Мероприятия по обеспечению доступа инвалидов | O22: =O304 -> 17437.48 | P22: =P304 -> 17109.22 | Q22: =Q304 -> 1.01 | R22: =R304 -> 0.08 | S22: =S304 -> 327.25 | T22: =T304 -> 0 | U22: =U304 -> 24.208651 | V22: =V304 -> 0 | ... GX22: =GX304 -> 0
A24: 4 | B24: 1 | D24: =ROW(A37) -> 37 | F24: Новый раздел | G24: Демонтажные работы (Письмо от АНО «РГТ» об утверждении объёмов демонтажных работ) | I24: 0 | K24: -1 | S24: 0 | T24: 0 | V24: 0 | BX24: 0 | CJ24: 0
A26: 52 | B26: =B37 -> 1 | C26: =C37 -> 4 | D26: =D37 -> 24 | E26: =E37 -> 0 | F26: =F37 -> Новый раздел | G26: =G37 -> Демонтажные работы (Письмо от АНО «РГТ» об утверждении объёмов демонтажных работ) | O26: =O37 -> 0 | P26: =P37 -> 0 | Q26: =Q37 -> 0 | R26: =R37 -> 0 | S26: =S37 -> 0 | T26: =T37 -> 0 | U26: =U37 -> 0 | V26: =V37 -> 0 | ... GX26: =GX37 -> 0
A28: 17 | B28: 1 | C28: =ROW(SmtRes!A6) -> 6 | D28: =ROW(EtalonRes!A7) -> 7 | F28: 3.17-2-14 | G28: Установка гарнитуры туалетной: поручней для ванн / демонтаж поручней | H28: 100 шт. | I28: =ROUND((1+1+2+1+1)/100,9) -> 0.06 | J28: 0 | K28: =ROUND((1+1+2+1+1)/100,9) -> 0.06 | O28: =ROUND(CP28,2) -> 198.7 | P28: =ROUND((ROUND((AC28*AW28*I28),2)*BC28),2) -> 188.27 | Q28: =(ROUND((ROUND((((((ET28*1.25)*1.2)*0.6))*AV28*I28),2)*BB28),2)+ROUND((ROUND(((AE28-((((EU28*1.25)*1.2)*0.6)))*AV28*I28),2)*BS28),2)) -> 0.43 | R28: =(ROUND((ROUND((((((EU28*1.25)*1.2)*0.6))*AV28*I28),2)*BS28),2)+ROUND((ROUND(((AE28-((((EU28*1.25)*1.2)*0.6)))*AV28*I28),2)*BS28),2)) -> 0.03 | S28: =ROUND((ROUND((AF28*AV28*I28),2)*BA28),2) -> 10 | T28: =ROUND(CU28*I28,2) -> 0 | U28: =CV28*I28 -> 0.89531458 | V28: =CW28*I28 -> 0 | W28: =ROUND(CX28*I28,2) -> 0 | X28: =(ROUND((((S28+ROUND((ROUND((((((EU28*1.25)*1.2)*0.6))*AV28*I28),2)*BS28),2))*AT28)/100),2)+ROUND(((ROUND((ROUND(((AE28-((((EU28*1.25)*1.2)*0.6)))*AV28*I28),2)*BS28),2)*AT28)/100),2)) -> 10.93 | Y28: =(ROUND((((S28+ROUND((ROUND((((((EU28*1.25)*1.2)*0.6))*AV28*I28),2)*BS28),2))*AU28)/100),2)+ROUND(((ROUND((ROUND(((AE28-((((EU28*1.25)*1.2)*0.6)))*AV28*I28),2)*BS28),2)*AU28)/100),2)) -> 6.12 | AA28: -1 | AB28: =ROUND((AC28+AD28+AF28),6) -> 3300.9382 | AC28: =ROUND(((((ES28*1)*1)*0.6)),6) -> 3137.892 | AD28: =ROUND(((((((ET28*1.25)*1.2)*0.6))-((((EU28*1.25)*1.2)*0.6)))+AE28),6) -> 6.786 | AE28: =ROUND(((((EU28*1.25)*1.2)*0.6)),6) -> 0.45 | AF28: =ROUND(((((EV28*1.15)*1.2)*0.6)),6) -> 156.26016 | AG28: =ROUND((AP28),6) -> 0 | AH28: =((((EW28*1.15)*1.2)*0.6)) -> 13.98492 | AI28: =((((EX28*1.25)*1.2)*0.6)) -> 0 | AJ28: =(AS28) -> 0 | AK28: 5426.08 | AL28: 5229.82 | AM28: 7.54 | AN28: 0.5 | AO28: 188.72 | AP28: 0 | AQ28: 16.89 | AR28: 0 | AS28: 0 | AT28: 109 | AU28: 61 | AV28: 1.067 | AW28: 1 | AZ28: 1 | BA28: 1 | BB28: 1 | BC28: 1 | BH28: 0 | BI28: 1 | BJ28: ТСН-2001.3 Доп. 80, Сб. 17, т. 2, поз. 14 | BM28: 22 | BN28: 0 | BO28: 3.17-2-14 | BP28: 1 | BQ28: 30 | BR28: 0 | BS28: 1 | BT28: 1 | BU28: 1 | BV28: 1 | BW28: 1 | BX28: 1 | BZ28: 109 | CA28: 61 | CE28: 1566 | CF28: 0 | CG28: 0 | CM28: 0 | CN28: Поправка: Гл.6.Прил.2.2.п.2.2.6_06.00.01.07.001 Наименование: При выполнении при капитальном ремонте и реконструкции работ, аналогичных технологическим процессам, характерным для нового строительства, и отсутствующих в сборниках на ремонтно-строительные работы ТСН-2001.6 Поправка: Гл.12.Прил.8.п.8. 3_12.00.01.11.001 Наименование: При наличии напряженных и стесненных условий производства работ (стесненность, сложность складирования и транспортной логистики и т.п.) для объектов, расположенных в пределах круговой магистральной системы улиц "Садовое кольцо" города Москвы Поправка: Гл.6.Прил.2.2.п.2.2.16_06.00.01.35.006 Наименование: При демонтаже металлических конструкций (в т.ч. к стоимости вспомогательных материалов) | CO28: 0 | CP28: =(P28+Q28+S28) -> 198.7 | CQ28: =ROUND((ROUND((AC28*AW28*1),2)*BC28),2) -> 3137.89 | CR28: =(ROUND((ROUND((((((ET28*1.25)*1.2)*0.6))*AV28*1),2)*BB28),2)+ROUND((ROUND(((AE28-((((EU28*1.25)*1.2)*0.6)))*AV28*1),2)*BS28),2)) -> 7.24 | CS28: =(ROUND((ROUND((((((EU28*1.25)*1.2)*0.6))*AV28*1),2)*BS28),2)+ROUND((ROUND(((AE28-((((EU28*1.25)*1.2)*0.6)))*AV28*1),2)*BS28),2)) -> 0.48 | CT28: =ROUND((ROUND((AF28*AV28*1),2)*BA28),2) -> 166.73 | CU28: =AG28 -> 0 | CV28: =(AH28*AV28) -> 14.92191 | CW28: =AI28 -> 0 | CX28: =AJ28 -> 0 | CY28: =(ROUND((((S28+ROUND((ROUND((((((EU28*1.25)*1.2)*0.6))*AV28*1),2)*BS28),2))*AT28)/100),2)+ROUND(((ROUND((ROUND(((AE28-((((EU28*1.25)*1.2)*0.6)))*AV28*1),2)*BS28),2)*AT28)/100),2)) -> 11.42 | CZ28: =(ROUND((((S28+ROUND((ROUND((((((EU28*1.25)*1.2)*0.6))*AV28*1),2)*BS28),2))*AU28)/100),2)+ROUND(((ROUND((ROUND(((AE28-((((EU28*1.25)*1.2)*0.6)))*AV28*1),2)*BS28),2)*AU28)/100),2)) -> 6.39 | DB28: 1 | DD28: *1)*1)*0,6 | DE28: *1,25)*1,2)*0,6 | DF28: *1,25)*1,2)*0,6 | DG28: *1,15)*1,2)*0,6 | DI28: *1,15)*1,2)*0,6 | DJ28: *1,25)*1,2)*0,6 | DN28: 0 | DO28: 0 | DP28: 1 | DQ28: 1 | DU28: 1010 | DV28: 100 шт. | DW28: 100 шт. | DX28: 100 | EE28: 55393925 | EF28: 30 | EG28: Строительные работы | EH28: 0 | EJ28: 1 | EK28: 22 | EL28: ТСН-2001.3-17. Водопровод и канализация - внутренние устройства | EM28: ТСН-2001.3-17-1 | EO28: Поправка: Гл.6.Прил.2.2.п.2.2.6_06.00.01.07.001 Поправка: Гл.12.Прил.8.п.8. 3_12.00.01.11.001 Поправка: Гл.6.Прил.2.2.п.2.2.16_06.00.01.35.006 | EQ28: 1024 | ER28: 5426.08 | ES28: 5229.82 | ET28: 7.54 | EU28: 0.5 | EV28: 188.72 | EW28: 16.89 | EX28: 0 | EY28: 0 | FQ28: 0 | FR28: 0 | FS28: 0 | FX28: 109 | FY28: 61 | GD28: 1 | GF28: 981970529 | GG28: 2 | GH28: 1 | GI28: 2 | GJ28: 0 | GK28: 0 | GL28: =ROUND(IF(AND(BH28=3,BI28=3,FS28<>0),P28,0),2) -> 0 | GM28: =ROUND(O28+X28+Y28,2)+GX28 -> 215.75 | GN28: =IF(OR(BI28=0,BI28=1),GM28-GX28,0) -> 215.75 | GO28: =IF(BI28=2,GM28-GX28,0) -> 0 | GP28: =IF(BI28=4,GM28-GX28,0) -> 0 | GR28: 0 | GS28: 3 | GT28: 0 | GV28: =ROUND((GT28),6) -> 0 | GW28: 1 | GX28: =ROUND(HC28*I28,2) -> 0 | HA28: 0 | HB28: 0 | HC28: =GV28*GW28 -> 0 | HS28: 0 | IK28: 0
A29: 17 | B29: 1 | C29: =ROW(SmtRes!A12) -> 12 | D29: =ROW(EtalonRes!A14) -> 14 | F29: 3.17-2-14 | G29: Установка гарнитуры туалетной: поручней для ванн / демонтаж поручней | H29: 100 шт. | I29: =ROUND((1+1+2+1+1)/100,9) -> 0.06 | J29: 0 | K29: =ROUND((1+1+2+1+1)/100,9) -> 0.06 | O29: =ROUND(CP29,2) -> 702.73 | P29: =ROUND((ROUND((AC29*AW29*I29),2)*BC29),2) -> 133.67 | Q29: =(ROUND((ROUND((((((ET29*1.25)*1.2)*0.6))*AV29*I29),2)*BB29),2)+ROUND((ROUND(((AE29-((((EU29*1.25)*1.2)*0.6)))*AV29*I29),2)*BS29),2)) -> 5.56 | R29: =(ROUND((ROUND((((((EU29*1.25)*1.2)*0.6))*AV29*I29),2)*BS29),2)+ROUND((ROUND(((AE29-((((EU29*1.25)*1.2)*0.6)))*AV29*I29),2)*BS29),2)) -> 1.69 | S29: =ROUND((ROUND((AF29*AV29*I29),2)*BA29),2) -> 563.5 | T29: =ROUND(CU29*I29,2) -> 0 | U29: =CV29*I29 -> 0.89531458 | V29: =CW29*I29 -> 0 | W29: =ROUND(CX29*I29,2) -> 0 | X29: =(ROUND((((S29+ROUND((ROUND((((((EU29*1.25)*1.2)*0.6))*AV29*I29),2)*BS29),2))*AT29)/100),2)+ROUND(((ROUND((ROUND(((AE29-((((EU29*1.25)*1.2)*0.6)))*AV29*I29),2)*BS29),2)*AT29)/100),2)) -> 616.06 | Y29: =(ROUND((((S29+ROUND((ROUND((((((EU29*1.25)*1.2)*0.6))*AV29*I29),2)*BS29),2))*AU29)/100),2)+ROUND(((ROUND((ROUND(((AE29-((((EU29*1.25)*1.2)*0.6)))*AV29*I29),2)*BS29),2)*AU29)/100),2)) -> 344.77 | AA29: -1 | AB29: =ROUND((AC29+AD29+AF29),6) -> 3300.9382 | AC29: =ROUND(((((ES29*1)*1)*0.6)),6) -> 3137.892 | AD29: =ROUND(((((((ET29*1.25)*1.2)*0.6))-((((EU29*1.25)*1.2)*0.6)))+AE29),6) -> 6.786 | AE29: =ROUND(((((EU29*1.25)*1.2)*0.6)),6) -> 0.45 | AF29: =ROUND(((((EV29*1.15)*1.2)*0.6)),6) -> 156.26016 | AG29: =ROUND((AP29),6) -> 0 | AH29: =((((EW29*1.15)*1.2)*0.6)) -> 13.98492 | AI29: =((((EX29*1.25)*1.2)*0.6)) -> 0 | AJ29: =(AS29) -> 0 | AK29: 5426.08 | AL29: 5229.82 | AM29: 7.54 | AN29: 0.5 | AO29: 188.72 | AP29: 0 | AQ29: 16.89 | AR29: 0 | AS29: 0 | AT29: 109 | AU29: 61 | AV29: 1.067 | AW29: 1 | AZ29: 1 | BA29: 56.35 | BB29: 12.92 | BC29: 0.71 | BH29: 0 | BI29: 1 | BJ29: ТСН-2001.3 Доп. 80, Сб. 17, т. 2, поз. 14 | BM29: 22 | BN29: 0 | BO29: 3.17-2-14 | BP29: 1 | BQ29: 30 | BR29: 0 | BS29: 56.35 | BT29: 1 | BU29: 1 | BV29: 1 | BW29: 1 | BX29: 1 | BZ29: 109 | CA29: 61 | CE29: 1566 | CF29: 0 | CG29: 0 | CM29: 0 | CN29: Поправка: Гл.6.Прил.2.2.п.2.2.6_06.00.01.07.001 Наименование: При выполнении при капитальном ремонте и реконструкции работ, аналогичных технологическим процессам, характерным для нового строительства, и отсутствующих в сборниках на ремонтно-строительные работы ТСН-2001.6 Поправка: Гл.12.Прил.8.п.8. 3_12.00.01.11.001 Наименование: При наличии напряженных и стесненных условий производства работ (стесненность, сложность складирования и транспортной логистики и т.п.) для объектов, расположенных в пределах круговой магистральной системы улиц "Садовое кольцо" города Москвы Поправка: Гл.6.Прил.2.2.п.2.2.16_06.00.01.35.006 Наименование: При демонтаже металлических конструкций (в т.ч. к стоимости вспомогательных материалов) | CO29: 0 | CP29: =(P29+Q29+S29) -> 702.73 | CQ29: =ROUND((ROUND((AC29*AW29*1),2)*BC29),2) -> 2227.9 | CR29: =(ROUND((ROUND((((((ET29*1.25)*1.2)*0.6))*AV29*1),2)*BB29),2)+ROUND((ROUND(((AE29-((((EU29*1.25)*1.2)*0.6)))*AV29*1),2)*BS29),2)) -> 93.54 | CS29: =(ROUND((ROUND((((((EU29*1.25)*1.2)*0.6))*AV29*1),2)*BS29),2)+ROUND((ROUND(((AE29-((((EU29*1.25)*1.2)*0.6)))*AV29*1),2)*BS29),2)) -> 27.05 | CT29: =ROUND((ROUND((AF29*AV29*1),2)*BA29),2) -> 9395.24 | CU29: =AG29 -> 0 | CV29: =(AH29*AV29) -> 14.92191 | CW29: =AI29 -> 0 | CX29: =AJ29 -> 0 | CY29: =(ROUND((((S29+ROUND((ROUND((((((EU29*1.25)*1.2)*0.6))*AV29*1),2)*BS29),2))*AT29)/100),2)+ROUND(((ROUND((ROUND(((AE29-((((EU29*1.25)*1.2)*0.6)))*AV29*1),2)*BS29),2)*AT29)/100),2)) -> 643.7 | CZ29: =(ROUND((((S29+ROUND((ROUND((((((EU29*1.25)*1.2)*0.6))*AV29*1),2)*BS29),2))*AU29)/100),2)+ROUND(((ROUND((ROUND(((AE29-((((EU29*1.25)*1.2)*0.6)))*AV29*1),2)*BS29),2)*AU29)/100),2)) -> 360.24 | DB29: 4 | DD29: *1)*1)*0,6 | DE29: *1,25)*1,2)*0,6 | DF29: *1,25)*1,2)*0,6 | DG29: *1,15)*1,2)*0,6 | DI29: *1,15)*1,2)*0,6 | DJ29: *1,25)*1,2)*0,6 | DN29: 0 | DO29: 0 | DP29: 1 | DQ29: 1 | DU29: 1010 | DV29: 100 шт. | DW29: 100 шт. | DX29: 100 | EE29: 55393925 | EF29: 30 | EG29: Строительные работы | EH29: 0 | EJ29: 1 | EK29: 22 | EL29: ТСН-2001.3-17. Водопровод и канализация - внутренние устройства | EM29: ТСН-2001.3-17-1 | EO29: Поправка: Гл.6.Прил.2.2.п.2.2.6_06.00.01.07.001 Поправка: Гл.12.Прил.8.п.8. 3_12.00.01.11.001 Поправка: Гл.6.Прил.2.2.п.2.2.16_06.00.01.35.006 | EQ29: 1024 | ER29: 5426.08 | ES29: 5229.82 | ET29: 7.54 | EU29: 0.5 | EV29: 188.72 | EW29: 16.89 | EX29: 0 | EY29: 0 | FQ29: 0 | FR29: 0 | FS29: 0 | FX29: 109 | FY29: 61 | GD29: 1 | GF29: 981970529 | GG29: 2 | GH29: 1 | GI29: 2 | GJ29: 0 | GK29: 0 | GL29: =ROUND(IF(AND(BH29=3,BI29=3,FS29<>0),P29,0),2) -> 0 | GM29: =ROUND(O29+X29+Y29,2)+GX29 -> 1663.56 | GN29: =IF(OR(BI29=0,BI29=1),GM29-GX29,0) -> 1663.56 | GO29: =IF(BI29=2,GM29-GX29,0) -> 0 | GP29: =IF(BI29=4,GM29-GX29,0) -> 0 | GR29: 0 | GS29: 3 | GT29: 0 | GV29: =ROUND((GT29),6) -> 0 | GW29: 1 | GX29: =ROUND(HC29*I29,2) -> 0 | HA29: 0 | HB29: 0 | HC29: =GV29*GW29 -> 0 | HS29: 0 | IK29: 0
A30: 17 | B30: 1 | C30: =ROW(SmtRes!A18) -> 18 | D30: =ROW(EtalonRes!A21) -> 21 | F30: 3.17-2-13 | G30: Установка гарнитуры туалетной: вешалок, подстаканников, дозаторов настенных и т.п. / демонтаж зеркала и крючка для костылей | H30: 100 шт. | I30: =ROUND((1+1)/100,9) -> 0.02 | J30: 0 | K30: =ROUND((1+1)/100,9) -> 0.02 | O30: =ROUND(CP30,2) -> 28.28 | P30: =ROUND((ROUND((AC30*AW30*I30),2)*BC30),2) -> 26.42 | Q30: =(ROUND((ROUND((((((ET30*1.2)*1.25)*0.6))*AV30*I30),2)*BB30),2)+ROUND((ROUND(((AE30-((((EU30*1.2)*1.25)*0.6)))*AV30*I30),2)*BS30),2)) -> 0.17 | R30: =(ROUND((ROUND((((((EU30*1.2)*1.25)*0.6))*AV30*I30),2)*BS30),2)+ROUND((ROUND(((AE30-((((EU30*1.2)*1.25)*0.6)))*AV30*I30),2)*BS30),2)) -> 0.02 | S30: =ROUND((ROUND((AF30*AV30*I30),2)*BA30),2) -> 1.69 | T30: =ROUND(CU30*I30,2) -> 0 | U30: =CV30*I30 -> 0.15160448 | V30: =CW30*I30 -> 0 | W30: =ROUND(CX30*I30,2) -> 0 | X30: =(ROUND((((S30+ROUND((ROUND((((((EU30*1.2)*1.25)*0.6))*AV30*I30),2)*BS30),2))*AT30)/100),2)+ROUND(((ROUND((ROUND(((AE30-((((EU30*1.2)*1.25)*0.6)))*AV30*I30),2)*BS30),2)*AT30)/100),2)) -> 1.86 | Y30: =(ROUND((((S30+ROUND((ROUND((((((EU30*1.2)*1.25)*0.6))*AV30*I30),2)*BS30),2))*AU30)/100),2)+ROUND(((ROUND((ROUND(((AE30-((((EU30*1.2)*1.25)*0.6)))*AV30*I30),2)*BS30),2)*AU30)/100),2)) -> 1.04 | AA30: -1 | AB30: =ROUND((AC30+AD30+AF30),6) -> 1408.4455 | AC30: =ROUND(((((ES30*1)*1)*0.6)),6) -> 1321.224 | AD30: =ROUND(((((((ET30*1.2)*1.25)*0.6))-((((EU30*1.2)*1.25)*0.6)))+AE30),6) -> 8.073 | AE30: =ROUND(((((EU30*1.2)*1.25)*0.6)),6) -> 0.909 | AF30: =ROUND(((((EV30*1.2)*1.15)*0.6)),6) -> 79.14852 | AG30: =ROUND((AP30),6) -> 0 | AH30: =((((EW30*1.2)*1.15)*0.6)) -> 7.10424 | AI30: =((((EX30*1.2)*1.25)*0.6)) -> 0 | AJ30: =(AS30) -> 0 | AK30: 2306.6 | AL30: 2202.04 | AM30: 8.97 | AN30: 1.01 | AO30: 95.59 | AP30: 0 | AQ30: 8.58 | AR30: 0 | AS30: 0 | AT30: 109 | AU30: 61 | AV30: 1.067 | AW30: 1 | AZ30: 1 | BA30: 1 | BB30: 1 | BC30: 1 | BH30: 0 | BI30: 1 | BJ30: ТСН-2001.3 Доп. 80, Сб. 17, т. 2, поз. 13 | BM30: 22 | BN30: 0 | BO30: 3.17-2-13 | BP30: 1 | BQ30: 30 | BR30: 0 | BS30: 1 | BT30: 1 | BU30: 1 | BV30: 1 | BW30: 1 | BX30: 1 | BZ30: 109 | CA30: 61 | CE30: 1566 | CF30: 0 | CG30: 0 | CM30: 0 | CN30: Поправка: Гл.12.Прил.8.п.8. 3_12.00.01.11.001 Наименование: При наличии напряженных и стесненных условий производства работ (стесненность, сложность складирования и транспортной логистики и т.п.) для объектов, расположенных в пределах круговой магистральной системы улиц "Садовое кольцо" города Москвы Поправка: Гл.6.Прил.2.2.п.2.2.6_06.00.01.07.001 Наименование: При выполнении при капитальном ремонте и реконструкции работ, аналогичных технологическим процессам, характерным для нового строительства, и отсутствующих в сборниках на ремонтно-строительные работы ТСН-2001.6 Поправка: Гл.6.Прил.2.2.п.2.2.16_06.00.01.35.006 Наименование: При демонтаже металлических конструкций (в т.ч. к стоимости вспомогательных материалов) | CO30: 0 | CP30: =(P30+Q30+S30) -> 28.28 | CQ30: =ROUND((ROUND((AC30*AW30*1),2)*BC30),2) -> 1321.22 | CR30: =(ROUND((ROUND((((((ET30*1.2)*1.25)*0.6))*AV30*1),2)*BB30),2)+ROUND((ROUND(((AE30-((((EU30*1.2)*1.25)*0.6)))*AV30*1),2)*BS30),2)) -> 8.61 | CS30: =(ROUND((ROUND((((((EU30*1.2)*1.25)*0.6))*AV30*1),2)*BS30),2)+ROUND((ROUND(((AE30-((((EU30*1.2)*1.25)*0.6)))*AV30*1),2)*BS30),2)) -> 0.97 | CT30: =ROUND((ROUND((AF30*AV30*1),2)*BA30),2) -> 84.45 | CU30: =AG30 -> 0 | CV30: =(AH30*AV30) -> 7.5802241 | CW30: =AI30 -> 0 | CX30: =AJ30 -> 0 | CY30: =(ROUND((((S30+ROUND((ROUND((((((EU30*1.2)*1.25)*0.6))*AV30*1),2)*BS30),2))*AT30)/100),2)+ROUND(((ROUND((ROUND(((AE30-((((EU30*1.2)*1.25)*0.6)))*AV30*1),2)*BS30),2)*AT30)/100),2)) -> 2.9 | CZ30: =(ROUND((((S30+ROUND((ROUND((((((EU30*1.2)*1.25)*0.6))*AV30*1),2)*BS30),2))*AU30)/100),2)+ROUND(((ROUND((ROUND(((AE30-((((EU30*1.2)*1.25)*0.6)))*AV30*1),2)*BS30),2)*AU30)/100),2)) -> 1.62 | DB30: 7 | DD30: *1)*1)*0,6 | DE30: *1,2)*1,25)*0,6 | DF30: *1,2)*1,25)*0,6 | DG30: *1,2)*1,15)*0,6 | DI30: *1,2)*1,15)*0,6 | DJ30: *1,2)*1,25)*0,6 | DN30: 0 | DO30: 0 | DP30: 1 | DQ30: 1 | DU30: 1010 | DV30: 100 шт. | DW30: 100 шт. | DX30: 100 | EE30: 55393925 | EF30: 30 | EG30: Строительные работы | EH30: 0 | EJ30: 1 | EK30: 22 | EL30: ТСН-2001.3-17. Водопровод и канализация - внутренние устройства | EM30: ТСН-2001.3-17-1 | EO30: Поправка: Гл.12.Прил.8.п.8. 3_12.00.01.11.001 Поправка: Гл.6.Прил.2.2.п.2.2.6_06.00.01.07.001 Поправка: Гл.6.Прил.2.2.п.2.2.16_06.00.01.35.006 | EQ30: 1024 | ER30: 2306.6 | ES30: 2202.04 | ET30: 8.97 | EU30: 1.01 | EV30: 95.59 | EW30: 8.58 | EX30: 0 | EY30: 0 | FQ30: 0 | FR30: 0 | FS30: 0 | FX30: 109 | FY30: 61 | GD30: 1 | GF30: 2024075346 | GG30: 2 | GH30: 1 | GI30: 2 | GJ30: 0 | GK30: 0 | GL30: =ROUND(IF(AND(BH30=3,BI30=3,FS30<>0),P30,0),2) -> 0 | GM30: =ROUND(O30+X30+Y30,2)+GX30 -> 31.18 | GN30: =IF(OR(BI30=0,BI30=1),GM30-GX30,0) -> 31.18 | GO30: =IF(BI30=2,GM30-GX30,0) -> 0 | GP30: =IF(BI30=4,GM30-GX30,0) -> 0 | GR30: 0 | GS30: 3 | GT30: 0 | GV30: =ROUND((GT30),6) -> 0 | GW30: 1 | GX30: =ROUND(HC30*I30,2) -> 0 | HA30: 0 | HB30: 0 | HC30: =GV30*GW30 -> 0 | HS30: 0 | IK30: 0
A31: 17 | B31: 1 | C31: =ROW(SmtRes!A24) -> 24 | D31: =ROW(EtalonRes!A28) -> 28 | F31: 3.17-2-13 | G31: Установка гарнитуры туалетной: вешалок, подстаканников, дозаторов настенных и т.п. / демонтаж зеркала и крючка для костылей | H31: 100 шт. | I31: =ROUND((1+1)/100,9) -> 0.02 | J31: 0 | K31: =ROUND((1+1)/100,9) -> 0.02 | O31: =ROUND(CP31,2) -> 116.57 | P31: =ROUND((ROUND((AC31*AW31*I31),2)*BC31),2) -> 18.76 | Q31: =(ROUND((ROUND((((((ET31*1.2)*1.25)*0.6))*AV31*I31),2)*BB31),2)+ROUND((ROUND(((AE31-((((EU31*1.2)*1.25)*0.6)))*AV31*I31),2)*BS31),2)) -> 2.58 | R31: =(ROUND((ROUND((((((EU31*1.2)*1.25)*0.6))*AV31*I31),2)*BS31),2)+ROUND((ROUND(((AE31-((((EU31*1.2)*1.25)*0.6)))*AV31*I31),2)*BS31),2)) -> 1.13 | S31: =ROUND((ROUND((AF31*AV31*I31),2)*BA31),2) -> 95.23 | T31: =ROUND(CU31*I31,2) -> 0 | U31: =CV31*I31 -> 0.15160448 | V31: =CW31*I31 -> 0 | W31: =ROUND(CX31*I31,2) -> 0 | X31: =(ROUND((((S31+ROUND((ROUND((((((EU31*1.2)*1.25)*0.6))*AV31*I31),2)*BS31),2))*AT31)/100),2)+ROUND(((ROUND((ROUND(((AE31-((((EU31*1.2)*1.25)*0.6)))*AV31*I31),2)*BS31),2)*AT31)/100),2)) -> 105.03 | Y31: =(ROUND((((S31+ROUND((ROUND((((((EU31*1.2)*1.25)*0.6))*AV31*I31),2)*BS31),2))*AU31)/100),2)+ROUND(((ROUND((ROUND(((AE31-((((EU31*1.2)*1.25)*0.6)))*AV31*I31),2)*BS31),2)*AU31)/100),2)) -> 58.78 | AA31: -1 | AB31: =ROUND((AC31+AD31+AF31),6) -> 1408.4455 | AC31: =ROUND(((((ES31*1)*1)*0.6)),6) -> 1321.224 | AD31: =ROUND(((((((ET31*1.2)*1.25)*0.6))-((((EU31*1.2)*1.25)*0.6)))+AE31),6) -> 8.073 | AE31: =ROUND(((((EU31*1.2)*1.25)*0.6)),6) -> 0.909 | AF31: =ROUND(((((EV31*1.2)*1.15)*0.6)),6) -> 79.14852 | AG31: =ROUND((AP31),6) -> 0 | AH31: =((((EW31*1.2)*1.15)*0.6)) -> 7.10424 | AI31: =((((EX31*1.2)*1.25)*0.6)) -> 0 | AJ31: =(AS31) -> 0 | AK31: 2306.6 | AL31: 2202.04 | AM31: 8.97 | AN31: 1.01 | AO31: 95.59 | AP31: 0 | AQ31: 8.58 | AR31: 0 | AS31: 0 | AT31: 109 | AU31: 61 | AV31: 1.067 | AW31: 1 | AZ31: 1 | BA31: 56.35 | BB31: 15.15 | BC31: 0.71 | BH31: 0 | BI31: 1 | BJ31: ТСН-2001.3 Доп. 80, Сб. 17, т. 2, поз. 13 | BM31: 22 | BN31: 0 | BO31: 3.17-2-13 | BP31: 1 | BQ31: 30 | BR31: 0 | BS31: 56.35 | BT31: 1 | BU31: 1 | BV31: 1 | BW31: 1 | BX31: 1 | BZ31: 109 | CA31: 61 | CE31: 1566 | CF31: 0 | CG31: 0 | CM31: 0 | CN31: Поправка: Гл.12.Прил.8.п.8. 3_12.00.01.11.001 Наименование: При наличии напряженных и стесненных условий производства работ (стесненность, сложность складирования и транспортной логистики и т.п.) для объектов, расположенных в пределах круговой магистральной системы улиц "Садовое кольцо" города Москвы Поправка: Гл.6.Прил.2.2.п.2.2.6_06.00.01.07.001 Наименование: При выполнении при капитальном ремонте и реконструкции работ, аналогичных технологическим процессам, характерным для нового строительства, и отсутствующих в сборниках на ремонтно-строительные работы ТСН-2001.6 Поправка: Гл.6.Прил.2.2.п.2.2.16_06.00.01.35.006 Наименование: При демонтаже металлических конструкций (в т.ч. к стоимости вспомогательных материалов) | CO31: 0 | CP31: =(P31+Q31+S31) -> 116.57 | CQ31: =ROUND((ROUND((AC31*AW31*1),2)*BC31),2) -> 938.07 | CR31: =(ROUND((ROUND((((((ET31*1.2)*1.25)*0.6))*AV31*1),2)*BB31),2)+ROUND((ROUND(((AE31-((((EU31*1.2)*1.25)*0.6)))*AV31*1),2)*BS31),2)) -> 130.44 | CS31: =(ROUND((ROUND((((((EU31*1.2)*1.25)*0.6))*AV31*1),2)*BS31),2)+ROUND((ROUND(((AE31-((((EU31*1.2)*1.25)*0.6)))*AV31*1),2)*BS31),2)) -> 54.66 | CT31: =ROUND((ROUND((AF31*AV31*1),2)*BA31),2) -> 4758.76 | CU31: =AG31 -> 0 | CV31: =(AH31*AV31) -> 7.5802241 | CW31: =AI31 -> 0 | CX31: =AJ31 -> 0 | CY31: =(ROUND((((S31+ROUND((ROUND((((((EU31*1.2)*1.25)*0.6))*AV31*1),2)*BS31),2))*AT31)/100),2)+ROUND(((ROUND((ROUND(((AE31-((((EU31*1.2)*1.25)*0.6)))*AV31*1),2)*BS31),2)*AT31)/100),2)) -> 163.38 | CZ31: =(ROUND((((S31+ROUND((ROUND((((((EU31*1.2)*1.25)*0.6))*AV31*1),2)*BS31),2))*AU31)/100),2)+ROUND(((ROUND((ROUND(((AE31-((((EU31*1.2)*1.25)*0.6)))*AV31*1),2)*BS31),2)*AU31)/100),2)) -> 91.43 | DB31: 10 | DD31: *1)*1)*0,6 | DE31: *1,2)*1,25)*0,6 | DF31: *1,2)*1,25)*0,6 | DG31: *1,2)*1,15)*0,6 | DI31: *1,2)*1,15)*0,6 | DJ31: *1,2)*1,25)*0,6 | DN31: 0 | DO31: 0 | DP31: 1 | DQ31: 1 | DU31: 1010 | DV31: 100 шт. | DW31: 100 шт. | DX31: 100 | EE31: 55393925 | EF31: 30 | EG31: Строительные работы | EH31: 0 | EJ31: 1 | EK31: 22 | EL31: ТСН-2001.3-17. Водопровод и канализация - внутренние устройства | EM31: ТСН-2001.3-17-1 | EO31: Поправка: Гл.12.Прил.8.п.8. 3_12.00.01.11.001 Поправка: Гл.6.Прил.2.2.п.2.2.6_06.00.01.07.001 Поправка: Гл.6.Прил.2.2.п.2.2.16_06.00.01.35.006 | EQ31: 1024 | ER31: 2306.6 | ES31: 2202.04 | ET31: 8.97 | EU31: 1.01 | EV31: 95.59 | EW31: 8.58 | EX31: 0 | EY31: 0 | FQ31: 0 | FR31: 0 | FS31: 0 | FX31: 109 | FY31: 61 | GD31: 1 | GF31: 2024075346 | GG31: 2 | GH31: 1 | GI31: 2 | GJ31: 0 | GK31: 0 | GL31: =ROUND(IF(AND(BH31=3,BI31=3,FS31<>0),P31,0),2) -> 0 | GM31: =ROUND(O31+X31+Y31,2)+GX31 -> 280.38 | GN31: =IF(OR(BI31=0,BI31=1),GM31-GX31,0) -> 280.38 | GO31: =IF(BI31=2,GM31-GX31,0) -> 0 | GP31: =IF(BI31=4,GM31-GX31,0) -> 0 | GR31: 0 | GS31: 3 | GT31: 0 | GV31: =ROUND((GT31),6) -> 0 | GW31: 1 | GX31: =ROUND(HC31*I31,2) -> 0 | HA31: 0 | HB31: 0 | HC31: =GV31*GW31 -> 0 | HS31: 0 | IK31: 0
A32: 17 | B32: 1 | C32: =ROW(SmtRes!A26) -> 26 | D32: =ROW(EtalonRes!A31) -> 31 | F32: 3.70-61-2 | G32: Установка номерных табличек для этажа, подъезда / демонтаж знака "Туалет для инвалидов" | H32: 1 ШТ. | I32: 1 | J32: 0 | K32: 1 | O32: =ROUND(CP32,2) -> 9.35 | P32: =ROUND((ROUND((AC32*AW32*I32),2)*BC32),2) -> 0 | Q32: =(ROUND((ROUND((((((ET32*1.25)*1.2)*0.8))*AV32*I32),2)*BB32),2)+ROUND((ROUND(((AE32-((((EU32*1.25)*1.2)*0.8)))*AV32*I32),2)*BS32),2)) -> 0 | R32: =(ROUND((ROUND((((((EU32*1.25)*1.2)*0.8))*AV32*I32),2)*BS32),2)+ROUND((ROUND(((AE32-((((EU32*1.25)*1.2)*0.8)))*AV32*I32),2)*BS32),2)) -> 0 | S32: =ROUND((ROUND((AF32*AV32*I32),2)*BA32),2) -> 9.35 | T32: =ROUND(CU32*I32,2) -> 0 | U32: =CV32*I32 -> 0.62402496 | V32: =CW32*I32 -> 0 | W32: =ROUND(CX32*I32,2) -> 0 | X32: =(ROUND((((S32+ROUND((ROUND((((((EU32*1.25)*1.2)*0.8))*AV32*I32),2)*BS32),2))*AT32)/100),2)+ROUND(((ROUND((ROUND(((AE32-((((EU32*1.25)*1.2)*0.8)))*AV32*I32),2)*BS32),2)*AT32)/100),2)) -> 7.85 | Y32: =(ROUND((((S32+ROUND((ROUND((((((EU32*1.25)*1.2)*0.8))*AV32*I32),2)*BS32),2))*AU32)/100),2)+ROUND(((ROUND((ROUND(((AE32-((((EU32*1.25)*1.2)*0.8)))*AV32*I32),2)*BS32),2)*AU32)/100),2)) -> 4.96 | AA32: -1 | AB32: =ROUND((AC32+AD32+AF32),6) -> 8.60016 | AC32: =ROUND(((((ES32*1)*1)*0)),6) -> 0 | AD32: =ROUND(((((((ET32*1.25)*1.2)*0.8))-((((EU32*1.25)*1.2)*0.8)))+AE32),6) -> 0 | AE32: =ROUND(((((EU32*1.25)*1.2)*0.8)),6) -> 0 | AF32: =ROUND(((((EV32*1.15)*1.2)*0.8)),6) -> 8.60016 | AG32: =ROUND((AP32),6) -> 0 | AH32: =((((EW32*1.15)*1.2)*0.8)) -> 0.57408 | AI32: =((((EX32*1.25)*1.2)*0.8)) -> 0 | AJ32: =(AS32) -> 0 | AK32: 8.29 | AL32: 0.5 | AM32: 0 | AN32: 0 | AO32: 7.79 | AP32: 0 | AQ32: 0.52 | AR32: 0 | AS32: 0 | AT32: 84 | AU32: 53 | AV32: 1.087 | AW32: 1 | AZ32: 1 | BA32: 1 | BB32: 1 | BC32: 1 | BH32: 0 | BI32: 1 | BJ32: ТСН-2001.3 Доп. 78, Сб. 70, т. 61, поз. 2 | BM32: 55 | BN32: 0 | BO32: 3.70-61-2 | BP32: 1 | BQ32: 30 | BR32: 0 | BS32: 1 | BT32: 1 | BU32: 1 | BV32: 1 | BW32: 1 | BX32: 1 | BZ32: 84 | CA32: 53 | CE32: 1566 | CF32: 0 | CG32: 0 | CM32: 0 | CN32: Поправка: Гл.6.Прил.2.2.п.2.2.6_06.00.01.07.001 Наименование: При выполнении при капитальном ремонте и реконструкции работ, аналогичных технологическим процессам, характерным для нового строительства, и отсутствующих в сборниках на ремонтно-строительные работы ТСН-2001.6 Поправка: Гл.12.Прил.8.п.8. 3_12.00.01.11.001 Наименование: При наличии напряженных и стесненных условий производства работ (стесненность, сложность складирования и транспортной логистики и т.п.) для объектов, расположенных в пределах круговой магистральной системы улиц "Садовое кольцо" города Москвы Поправка: Гл.6.Прил.2.2.п.2.2.12_06.00.01.35.002 Наименование: При демонтаже сборных деревянных и пластмассовых конструкций | CO32: 0 | CP32: =(P32+Q32+S32) -> 9.35 | CQ32: =ROUND((ROUND((AC32*AW32*1),2)*BC32),2) -> 0 | CR32: =(ROUND((ROUND((((((ET32*1.25)*1.2)*0.8))*AV32*1),2)*BB32),2)+ROUND((ROUND(((AE32-((((EU32*1.25)*1.2)*0.8)))*AV32*1),2)*BS32),2)) -> 0 | CS32: =(ROUND((ROUND((((((EU32*1.25)*1.2)*0.8))*AV32*1),2)*BS32),2)+ROUND((ROUND(((AE32-((((EU32*1.25)*1.2)*0.8)))*AV32*1),2)*BS32),2)) -> 0 | CT32: =ROUND((ROUND((AF32*AV32*1),2)*BA32),2) -> 9.35 | CU32: =AG32 -> 0 | CV32: =(AH32*AV32) -> 0.62402496 | CW32: =AI32 -> 0 | CX32: =AJ32 -> 0 | CY32: =(ROUND((((S32+ROUND((ROUND((((((EU32*1.25)*1.2)*0.8))*AV32*1),2)*BS32),2))*AT32)/100),2)+ROUND(((ROUND((ROUND(((AE32-((((EU32*1.25)*1.2)*0.8)))*AV32*1),2)*BS32),2)*AT32)/100),2)) -> 7.85 | CZ32: =(ROUND((((S32+ROUND((ROUND((((((EU32*1.25)*1.2)*0.8))*AV32*1),2)*BS32),2))*AU32)/100),2)+ROUND(((ROUND((ROUND(((AE32-((((EU32*1.25)*1.2)*0.8)))*AV32*1),2)*BS32),2)*AU32)/100),2)) -> 4.96 | DB32: 13 | DD32: *1)*1)*0 | DE32: *1,25)*1,2)*0,8 | DF32: *1,25)*1,2)*0,8 | DG32: *1,15)*1,2)*0,8 | DI32: *1,15)*1,2)*0,8 | DJ32: *1,25)*1,2)*0,8 | DN32: 0 | DO32: 0 | DP32: 1 | DQ32: 1 | DU32: 1013 | DV32: 1 ШТ. | DW32: 1 ШТ. | DX32: 1 | EE32: 55393960 | EF32: 30 | EG32: Строительные работы | EH32: 0 | EJ32: 1 | EK32: 55 | EL32: ТСН-2001.3-70. Металлические конструкции | EM32: ТСН-2001.3-70-4 | EO32: Поправка: Гл.6.Прил.2.2.п.2.2.6_06.00.01.07.001 Поправка: Гл.12.Прил.8.п.8. 3_12.00.01.11.001 Поправка: Гл.6.Прил.2.2.п.2.2.12_06.00.01.35.002 | EQ32: 1024 | ER32: 8.29 | ES32: 0.5 | ET32: 0 | EU32: 0 | EV32: 7.79 | EW32: 0.52 | EX32: 0 | EY32: 0 | FQ32: 0 | FR32: 0 | FS32: 0 | FX32: 84 | FY32: 53 | GD32: 1 | GF32: 596051590 | GG32: 2 | GH32: 1 | GI32: 2 | GJ32: 0 | GK32: 0 | GL32: =ROUND(IF(AND(BH32=3,BI32=3,FS32<>0),P32,0),2) -> 0 | GM32: =ROUND(O32+X32+Y32,2)+GX32 -> 22.16 | GN32: =IF(OR(BI32=0,BI32=1),GM32-GX32,0) -> 22.16 | GO32: =IF(BI32=2,GM32-GX32,0) -> 0 | GP32: =IF(BI32=4,GM32-GX32,0) -> 0 | GR32: 0 | GS32: 3 | GT32: 0 | GV32: =ROUND((GT32),6) -> 0 | GW32: 1 | GX32: =ROUND(HC32*I32,2) -> 0 | HA32: 0 | HB32: 0 | HC32: =GV32*GW32 -> 0 | HS32: 0 | IK32: 0
A33: 17 | B33: 1 | C33: =ROW(SmtRes!A28) -> 28 | D33: =ROW(EtalonRes!A34) -> 34 | F33: 3.70-61-2 | G33: Установка номерных табличек для этажа, подъезда / демонтаж знака "Туалет для инвалидов" | H33: 1 ШТ. | I33: 1 | J33: 0 | K33: 1 | O33: =ROUND(CP33,2) -> 526.87 | P33: =ROUND((ROUND((AC33*AW33*I33),2)*BC33),2) -> 0 | Q33: =(ROUND((ROUND((((((ET33*1.25)*1.2)*0.8))*AV33*I33),2)*BB33),2)+ROUND((ROUND(((AE33-((((EU33*1.25)*1.2)*0.8)))*AV33*I33),2)*BS33),2)) -> 0 | R33: =(ROUND((ROUND((((((EU33*1.25)*1.2)*0.8))*AV33*I33),2)*BS33),2)+ROUND((ROUND(((AE33-((((EU33*1.25)*1.2)*0.8)))*AV33*I33),2)*BS33),2)) -> 0 | S33: =ROUND((ROUND((AF33*AV33*I33),2)*BA33),2) -> 526.87 | T33: =ROUND(CU33*I33,2) -> 0 | U33: =CV33*I33 -> 0.62402496 | V33: =CW33*I33 -> 0 | W33: =ROUND(CX33*I33,2) -> 0 | X33: =(ROUND((((S33+ROUND((ROUND((((((EU33*1.25)*1.2)*0.8))*AV33*I33),2)*BS33),2))*AT33)/100),2)+ROUND(((ROUND((ROUND(((AE33-((((EU33*1.25)*1.2)*0.8)))*AV33*I33),2)*BS33),2)*AT33)/100),2)) -> 442.57 | Y33: =(ROUND((((S33+ROUND((ROUND((((((EU33*1.25)*1.2)*0.8))*AV33*I33),2)*BS33),2))*AU33)/100),2)+ROUND(((ROUND((ROUND(((AE33-((((EU33*1.25)*1.2)*0.8)))*AV33*I33),2)*BS33),2)*AU33)/100),2)) -> 279.24 | AA33: -1 | AB33: =ROUND((AC33+AD33+AF33),6) -> 8.60016 | AC33: =ROUND(((((ES33*1)*1)*0)),6) -> 0 | AD33: =ROUND(((((((ET33*1.25)*1.2)*0.8))-((((EU33*1.25)*1.2)*0.8)))+AE33),6) -> 0 | AE33: =ROUND(((((EU33*1.25)*1.2)*0.8)),6) -> 0 | AF33: =ROUND(((((EV33*1.15)*1.2)*0.8)),6) -> 8.60016 | AG33: =ROUND((AP33),6) -> 0 | AH33: =((((EW33*1.15)*1.2)*0.8)) -> 0.57408 | AI33: =((((EX33*1.25)*1.2)*0.8)) -> 0 | AJ33: =(AS33) -> 0 | AK33: 8.29 | AL33: 0.5 | AM33: 0 | AN33: 0 | AO33: 7.79 | AP33: 0 | AQ33: 0.52 | AR33: 0 | AS33: 0 | AT33: 84 | AU33: 53 | AV33: 1.087 | AW33: 1 | AZ33: 1 | BA33: 56.35 | BB33: 1 | BC33: 16.42 | BH33: 0 | BI33: 1 | BJ33: ТСН-2001.3 Доп. 78, Сб. 70, т. 61, поз. 2 | BM33: 55 | BN33: 0 | BO33: 3.70-61-2 | BP33: 1 | BQ33: 30 | BR33: 0 | BS33: 56.35 | BT33: 1 | BU33: 1 | BV33: 1 | BW33: 1 | BX33: 1 | BZ33: 84 | CA33: 53 | CE33: 1566 | CF33: 0 | CG33: 0 | CM33: 0 | CN33: Поправка: Гл.6.Прил.2.2.п.2.2.6_06.00.01.07.001 Наименование: При выполнении при капитальном ремонте и реконструкции работ, аналогичных технологическим процессам, характерным для нового строительства, и отсутствующих в сборниках на ремонтно-строительные работы ТСН-2001.6 Поправка: Гл.12.Прил.8.п.8. 3_12.00.01.11.001 Наименование: При наличии напряженных и стесненных условий производства работ (стесненность, сложность складирования и транспортной логистики и т.п.) для объектов, расположенных в пределах круговой магистральной системы улиц "Садовое кольцо" города Москвы Поправка: Гл.6.Прил.2.2.п.2.2.12_06.00.01.35.002 Наименование: При демонтаже сборных деревянных и пластмассовых конструкций | CO33: 0 | CP33: =(P33+Q33+S33) -> 526.87 | CQ33: =ROUND((ROUND((AC33*AW33*1),2)*BC33),2) -> 0 | CR33: =(ROUND((ROUND((((((ET33*1.25)*1.2)*0.8))*AV33*1),2)*BB33),2)+ROUND((ROUND(((AE33-((((EU33*1.25)*1.2)*0.8)))*AV33*1),2)*BS33),2)) -> 0 | CS33: =(ROUND((ROUND((((((EU33*1.25)*1.2)*0.8))*AV33*1),2)*BS33),2)+ROUND((ROUND(((AE33-((((EU33*1.25)*1.2)*0.8)))*AV33*1),2)*BS33),2)) -> 0 | CT33: =ROUND((ROUND((AF33*AV33*1),2)*BA33),2) -> 526.87 | CU33: =AG33 -> 0 | CV33: =(AH33*AV33) -> 0.62402496 | CW33: =AI33 -> 0 | CX33: =AJ33 -> 0 | CY33: =(ROUND((((S33+ROUND((ROUND((((((EU33*1.25)*1.2)*0.8))*AV33*1),2)*BS33),2))*AT33)/100),2)+ROUND(((ROUND((ROUND(((AE33-((((EU33*1.25)*1.2)*0.8)))*AV33*1),2)*BS33),2)*AT33)/100),2)) -> 442.57 | CZ33: =(ROUND((((S33+ROUND((ROUND((((((EU33*1.25)*1.2)*0.8))*AV33*1),2)*BS33),2))*AU33)/100),2)+ROUND(((ROUND((ROUND(((AE33-((((EU33*1.25)*1.2)*0.8)))*AV33*1),2)*BS33),2)*AU33)/100),2)) -> 279.24 | DB33: 16 | DD33: *1)*1)*0 | DE33: *1,25)*1,2)*0,8 | DF33: *1,25)*1,2)*0,8 | DG33: *1,15)*1,2)*0,8 | DI33: *1,15)*1,2)*0,8 | DJ33: *1,25)*1,2)*0,8 | DN33: 0 | DO33: 0 | DP33: 1 | DQ33: 1 | DU33: 1013 | DV33: 1 ШТ. | DW33: 1 ШТ. | DX33: 1 | EE33: 55393960 | EF33: 30 | EG33: Строительные работы | EH33: 0 | EJ33: 1 | EK33: 55 | EL33: ТСН-2001.3-70. Металлические конструкции | EM33: ТСН-2001.3-70-4 | EO33: Поправка: Гл.6.Прил.2.2.п.2.2.6_06.00.01.07.001 Поправка: Гл.12.Прил.8.п.8. 3_12.00.01.11.001 Поправка: Гл.6.Прил.2.2.п.2.2.12_06.00.01.35.002 | EQ33: 1024 | ER33: 8.29 | ES33: 0.5 | ET33: 0 | EU33: 0 | EV33: 7.79 | EW33: 0.52 | EX33: 0 | EY33: 0 | FQ33: 0 | FR33: 0 | FS33: 0 | FX33: 84 | FY33: 53 | GD33: 1 | GF33: 596051590 | GG33: 2 | GH33: 1 | GI33: 2 | GJ33: 0 | GK33: 0 | GL33: =ROUND(IF(AND(BH33=3,BI33=3,FS33<>0),P33,0),2) -> 0 | GM33: =ROUND(O33+X33+Y33,2)+GX33 -> 1248.68 | GN33: =IF(OR(BI33=0,BI33=1),GM33-GX33,0) -> 1248.68 | GO33: =IF(BI33=2,GM33-GX33,0) -> 0 | GP33: =IF(BI33=4,GM33-GX33,0) -> 0 | GR33: 0 | GS33: 3 | GT33: 0 | GV33: =ROUND((GT33),6) -> 0 | GW33: 1 | GX33: =ROUND(HC33*I33,2) -> 0 | HA33: 0 | HB33: 0 | HC33: =GV33*GW33 -> 0 | HS33: 0 | IK33: 0
A34: 17 | B34: 1 | C34: =ROW(SmtRes!A30) -> 30 | D34: =ROW(EtalonRes!A37) -> 37 | F34: 3.70-61-2 | G34: Установка номерных табличек для этажа, подъезда / демонтаж информационных табличек | H34: 1 ШТ. | I34: =ROUND(2+2+1+1+1+1+1+1+2+1+1+1+3,9) -> 18 | J34: 0 | K34: =ROUND(2+2+1+1+1+1+1+1+2+1+1+1+3,9) -> 18 | O34: =ROUND(CP34,2) -> 168.27 | P34: =ROUND((ROUND((AC34*AW34*I34),2)*BC34),2) -> 0 | Q34: =(ROUND((ROUND((((((ET34*1.25)*1.2)*0.8))*AV34*I34),2)*BB34),2)+ROUND((ROUND(((AE34-((((EU34*1.25)*1.2)*0.8)))*AV34*I34),2)*BS34),2)) -> 0 | R34: =(ROUND((ROUND((((((EU34*1.25)*1.2)*0.8))*AV34*I34),2)*BS34),2)+ROUND((ROUND(((AE34-((((EU34*1.25)*1.2)*0.8)))*AV34*I34),2)*BS34),2)) -> 0 | S34: =ROUND((ROUND((AF34*AV34*I34),2)*BA34),2) -> 168.27 | T34: =ROUND(CU34*I34,2) -> 0 | U34: =CV34*I34 -> 11.232449 | V34: =CW34*I34 -> 0 | W34: =ROUND(CX34*I34,2) -> 0 | X34: =(ROUND((((S34+ROUND((ROUND((((((EU34*1.25)*1.2)*0.8))*AV34*I34),2)*BS34),2))*AT34)/100),2)+ROUND(((ROUND((ROUND(((AE34-((((EU34*1.25)*1.2)*0.8)))*AV34*I34),2)*BS34),2)*AT34)/100),2)) -> 141.35 | Y34: =(ROUND((((S34+ROUND((ROUND((((((EU34*1.25)*1.2)*0.8))*AV34*I34),2)*BS34),2))*AU34)/100),2)+ROUND(((ROUND((ROUND(((AE34-((((EU34*1.25)*1.2)*0.8)))*AV34*I34),2)*BS34),2)*AU34)/100),2)) -> 89.18 | AA34: -1 | AB34: =ROUND((AC34+AD34+AF34),6) -> 8.60016 | AC34: =ROUND(((((ES34*1)*1)*0)),6) -> 0 | AD34: =ROUND(((((((ET34*1.25)*1.2)*0.8))-((((EU34*1.25)*1.2)*0.8)))+AE34),6) -> 0 | AE34: =ROUND(((((EU34*1.25)*1.2)*0.8)),6) -> 0 | AF34: =ROUND(((((EV34*1.15)*1.2)*0.8)),6) -> 8.60016 | AG34: =ROUND((AP34),6) -> 0 | AH34: =((((EW34*1.15)*1.2)*0.8)) -> 0.57408 | AI34: =((((EX34*1.25)*1.2)*0.8)) -> 0 | AJ34: =(AS34) -> 0 | AK34: 8.29 | AL34: 0.5 | AM34: 0 | AN34: 0 | AO34: 7.79 | AP34: 0 | AQ34: 0.52 | AR34: 0 | AS34: 0 | AT34: 84 | AU34: 53 | AV34: 1.087 | AW34: 1 | AZ34: 1 | BA34: 1 | BB34: 1 | BC34: 1 | BH34: 0 | BI34: 1 | BJ34: ТСН-2001.3 Доп. 78, Сб. 70, т. 61, поз. 2 | BM34: 55 | BN34: 0 | BO34: 3.70-61-2 | BP34: 1 | BQ34: 30 | BR34: 0 | BS34: 1 | BT34: 1 | BU34: 1 | BV34: 1 | BW34: 1 | BX34: 1 | BZ34: 84 | CA34: 53 | CE34: 1566 | CF34: 0 | CG34: 0 | CM34: 0 | CN34: Поправка: Гл.6.Прил.2.2.п.2.2.6_06.00.01.07.001 Наименование: При выполнении при капитальном ремонте и реконструкции работ, аналогичных технологическим процессам, характерным для нового строительства, и отсутствующих в сборниках на ремонтно-строительные работы ТСН-2001.6 Поправка: Гл.12.Прил.8.п.8. 3_12.00.01.11.001 Наименование: При наличии напряженных и стесненных условий производства работ (стесненность, сложность складирования и транспортной логистики и т.п.) для объектов, расположенных в пределах круговой магистральной системы улиц "Садовое кольцо" города Москвы Поправка: Гл.6.Прил.2.2.п.2.2.12_06.00.01.35.002 Наименование: При демонтаже сборных деревянных и пластмассовых конструкций | CO34: 0 | CP34: =(P34+Q34+S34) -> 168.27 | CQ34: =ROUND((ROUND((AC34*AW34*1),2)*BC34),2) -> 0 | CR34: =(ROUND((ROUND((((((ET34*1.25)*1.2)*0.8))*AV34*1),2)*BB34),2)+ROUND((ROUND(((AE34-((((EU34*1.25)*1.2)*0.8)))*AV34*1),2)*BS34),2)) -> 0 | CS34: =(ROUND((ROUND((((((EU34*1.25)*1.2)*0.8))*AV34*1),2)*BS34),2)+ROUND((ROUND(((AE34-((((EU34*1.25)*1.2)*0.8)))*AV34*1),2)*BS34),2)) -> 0 | CT34: =ROUND((ROUND((AF34*AV34*1),2)*BA34),2) -> 9.35 | CU34: =AG34 -> 0 | CV34: =(AH34*AV34) -> 0.62402496 | CW34: =AI34 -> 0 | CX34: =AJ34 -> 0 | CY34: =(ROUND((((S34+ROUND((ROUND((((((EU34*1.25)*1.2)*0.8))*AV34*1),2)*BS34),2))*AT34)/100),2)+ROUND(((ROUND((ROUND(((AE34-((((EU34*1.25)*1.2)*0.8)))*AV34*1),2)*BS34),2)*AT34)/100),2)) -> 141.35 | CZ34: =(ROUND((((S34+ROUND((ROUND((((((EU34*1.25)*1.2)*0.8))*AV34*1),2)*BS34),2))*AU34)/100),2)+ROUND(((ROUND((ROUND(((AE34-((((EU34*1.25)*1.2)*0.8)))*AV34*1),2)*BS34),2)*AU34)/100),2)) -> 89.18 | DB34: 19 | DD34: *1)*1)*0 | DE34: *1,25)*1,2)*0,8 | DF34: *1,25)*1,2)*0,8 | DG34: *1,15)*1,2)*0,8 | DI34: *1,15)*1,2)*0,8 | DJ34: *1,25)*1,2)*0,8 | DN34: 0 | DO34: 0 | DP34: 1 | DQ34: 1 | DU34: 1013 | DV34: 1 ШТ. | DW34: 1 ШТ. | DX34: 1 | EE34: 55393960 | EF34: 30 | EG34: Строительные работы | EH34: 0 | EJ34: 1 | EK34: 55 | EL34: ТСН-2001.3-70. Металлические конструкции | EM34: ТСН-2001.3-70-4 | EO34: Поправка: Гл.6.Прил.2.2.п.2.2.6_06.00.01.07.001 Поправка: Гл.12.Прил.8.п.8. 3_12.00.01.11.001 Поправка: Гл.6.Прил.2.2.п.2.2.12_06.00.01.35.002 | EQ34: 1024 | ER34: 8.29 | ES34: 0.5 | ET34: 0 | EU34: 0 | EV34: 7.79 | EW34: 0.52 | EX34: 0 | EY34: 0 | FQ34: 0 | FR34: 0 | FS34: 0 | FX34: 84 | FY34: 53 | GD34: 1 | GF34: -349157379 | GG34: 2 | GH34: 1 | GI34: 2 | GJ34: 0 | GK34: 0 | GL34: =ROUND(IF(AND(BH34=3,BI34=3,FS34<>0),P34,0),2) -> 0 | GM34: =ROUND(O34+X34+Y34,2)+GX34 -> 398.8 | GN34: =IF(OR(BI34=0,BI34=1),GM34-GX34,0) -> 398.8 | GO34: =IF(BI34=2,GM34-GX34,0) -> 0 | GP34: =IF(BI34=4,GM34-GX34,0) -> 0 | GR34: 0 | GS34: 3 | GT34: 0 | GV34: =ROUND((GT34),6) -> 0 | GW34: 1 | GX34: =ROUND(HC34*I34,2) -> 0 | HA34: 0 | HB34: 0 | HC34: =GV34*GW34 -> 0 | HS34: 0 | IK34: 0
A35: 17 | B35: 1 | C35: =ROW(SmtRes!A32) -> 32 | D35: =ROW(EtalonRes!A40) -> 40 | F35: 3.70-61-2 | G35: Установка номерных табличек для этажа, подъезда / демонтаж информационных табличек | H35: 1 ШТ. | I35: =ROUND(2+2+1+1+1+1+1+1+2+1+1+1+3,9) -> 18 | J35: 0 | K35: =ROUND(2+2+1+1+1+1+1+1+2+1+1+1+3,9) -> 18 | O35: =ROUND(CP35,2) -> 9482.01 | P35: =ROUND((ROUND((AC35*AW35*I35),2)*BC35),2) -> 0 | Q35: =(ROUND((ROUND((((((ET35*1.25)*1.2)*0.8))*AV35*I35),2)*BB35),2)+ROUND((ROUND(((AE35-((((EU35*1.25)*1.2)*0.8)))*AV35*I35),2)*BS35),2)) -> 0 | R35: =(ROUND((ROUND((((((EU35*1.25)*1.2)*0.8))*AV35*I35),2)*BS35),2)+ROUND((ROUND(((AE35-((((EU35*1.25)*1.2)*0.8)))*AV35*I35),2)*BS35),2)) -> 0 | S35: =ROUND((ROUND((AF35*AV35*I35),2)*BA35),2) -> 9482.01 | T35: =ROUND(CU35*I35,2) -> 0 | U35: =CV35*I35 -> 11.232449 | V35: =CW35*I35 -> 0 | W35: =ROUND(CX35*I35,2) -> 0 | X35: =(ROUND((((S35+ROUND((ROUND((((((EU35*1.25)*1.2)*0.8))*AV35*I35),2)*BS35),2))*AT35)/100),2)+ROUND(((ROUND((ROUND(((AE35-((((EU35*1.25)*1.2)*0.8)))*AV35*I35),2)*BS35),2)*AT35)/100),2)) -> 7964.89 | Y35: =(ROUND((((S35+ROUND((ROUND((((((EU35*1.25)*1.2)*0.8))*AV35*I35),2)*BS35),2))*AU35)/100),2)+ROUND(((ROUND((ROUND(((AE35-((((EU35*1.25)*1.2)*0.8)))*AV35*I35),2)*BS35),2)*AU35)/100),2)) -> 5025.47 | AA35: -1 | AB35: =ROUND((AC35+AD35+AF35),6) -> 8.60016 | AC35: =ROUND(((((ES35*1)*1)*0)),6) -> 0 | AD35: =ROUND(((((((ET35*1.25)*1.2)*0.8))-((((EU35*1.25)*1.2)*0.8)))+AE35),6) -> 0 | AE35: =ROUND(((((EU35*1.25)*1.2)*0.8)),6) -> 0 | AF35: =ROUND(((((EV35*1.15)*1.2)*0.8)),6) -> 8.60016 | AG35: =ROUND((AP35),6) -> 0 | AH35: =((((EW35*1.15)*1.2)*0.8)) -> 0.57408 | AI35: =((((EX35*1.25)*1.2)*0.8)) -> 0 | AJ35: =(AS35) -> 0 | AK35: 8.29 | AL35: 0.5 | AM35: 0 | AN35: 0 | AO35: 7.79 | AP35: 0 | AQ35: 0.52 | AR35: 0 | AS35: 0 | AT35: 84 | AU35: 53 | AV35: 1.087 | AW35: 1 | AZ35: 1 | BA35: 56.35 | BB35: 1 | BC35: 16.42 | BH35: 0 | BI35: 1 | BJ35: ТСН-2001.3 Доп. 78, Сб. 70, т. 61, поз. 2 | BM35: 55 | BN35: 0 | BO35: 3.70-61-2 | BP35: 1 | BQ35: 30 | BR35: 0 | BS35: 56.35 | BT35: 1 | BU35: 1 | BV35: 1 | BW35: 1 | BX35: 1 | BZ35: 84 | CA35: 53 | CE35: 1566 | CF35: 0 | CG35: 0 | CM35: 0 | CN35: Поправка: Гл.6.Прил.2.2.п.2.2.6_06.00.01.07.001 Наименование: При выполнении при капитальном ремонте и реконструкции работ, аналогичных технологическим процессам, характерным для нового строительства, и отсутствующих в сборниках на ремонтно-строительные работы ТСН-2001.6 Поправка: Гл.12.Прил.8.п.8. 3_12.00.01.11.001 Наименование: При наличии напряженных и стесненных условий производства работ (стесненность, сложность складирования и транспортной логистики и т.п.) для объектов, расположенных в пределах круговой магистральной системы улиц "Садовое кольцо" города Москвы Поправка: Гл.6.Прил.2.2.п.2.2.12_06.00.01.35.002 Наименование: При демонтаже сборных деревянных и пластмассовых конструкций | CO35: 0 | CP35: =(P35+Q35+S35) -> 9482.01 | CQ35: =ROUND((ROUND((AC35*AW35*1),2)*BC35),2) -> 0 | CR35: =(ROUND((ROUND((((((ET35*1.25)*1.2)*0.8))*AV35*1),2)*BB35),2)+ROUND((ROUND(((AE35-((((EU35*1.25)*1.2)*0.8)))*AV35*1),2)*BS35),2)) -> 0 | CS35: =(ROUND((ROUND((((((EU35*1.25)*1.2)*0.8))*AV35*1),2)*BS35),2)+ROUND((ROUND(((AE35-((((EU35*1.25)*1.2)*0.8)))*AV35*1),2)*BS35),2)) -> 0 | CT35: =ROUND((ROUND((AF35*AV35*1),2)*BA35),2) -> 526.87 | CU35: =AG35 -> 0 | CV35: =(AH35*AV35) -> 0.62402496 | CW35: =AI35 -> 0 | CX35: =AJ35 -> 0 | CY35: =(ROUND((((S35+ROUND((ROUND((((((EU35*1.25)*1.2)*0.8))*AV35*1),2)*BS35),2))*AT35)/100),2)+ROUND(((ROUND((ROUND(((AE35-((((EU35*1.25)*1.2)*0.8)))*AV35*1),2)*BS35),2)*AT35)/100),2)) -> 7964.89 | CZ35: =(ROUND((((S35+ROUND((ROUND((((((EU35*1.25)*1.2)*0.8))*AV35*1),2)*BS35),2))*AU35)/100),2)+ROUND(((ROUND((ROUND(((AE35-((((EU35*1.25)*1.2)*0.8)))*AV35*1),2)*BS35),2)*AU35)/100),2)) -> 5025.47 | DB35: 22 | DD35: *1)*1)*0 | DE35: *1,25)*1,2)*0,8 | DF35: *1,25)*1,2)*0,8 | DG35: *1,15)*1,2)*0,8 | DI35: *1,15)*1,2)*0,8 | DJ35: *1,25)*1,2)*0,8 | DN35: 0 | DO35: 0 | DP35: 1 | DQ35: 1 | DU35: 1013 | DV35: 1 ШТ. | DW35: 1 ШТ. | DX35: 1 | EE35: 55393960 | EF35: 30 | EG35: Строительные работы | EH35: 0 | EJ35: 1 | EK35: 55 | EL35: ТСН-2001.3-70. Металлические конструкции | EM35: ТСН-2001.3-70-4 | EO35: Поправка: Гл.6.Прил.2.2.п.2.2.6_06.00.01.07.001 Поправка: Гл.12.Прил.8.п.8. 3_12.00.01.11.001 Поправка: Гл.6.Прил.2.2.п.2.2.12_06.00.01.35.002 | EQ35: 1024 | ER35: 8.29 | ES35: 0.5 | ET35: 0 | EU35: 0 | EV35: 7.79 | EW35: 0.52 | EX35: 0 | EY35: 0 | FQ35: 0 | FR35: 0 | FS35: 0 | FX35: 84 | FY35: 53 | GD35: 1 | GF35: -349157379 | GG35: 2 | GH35: 1 | GI35: 2 | GJ35: 0 | GK35: 0 | GL35: =ROUND(IF(AND(BH35=3,BI35=3,FS35<>0),P35,0),2) -> 0 | GM35: =ROUND(O35+X35+Y35,2)+GX35 -> 22472.37 | GN35: =IF(OR(BI35=0,BI35=1),GM35-GX35,0) -> 22472.37 | GO35: =IF(BI35=2,GM35-GX35,0) -> 0 | GP35: =IF(BI35=4,GM35-GX35,0) -> 0 | GR35: 0 | GS35: 3 | GT35: 0 | GV35: =ROUND((GT35),6) -> 0 | GW35: 1 | GX35: =ROUND(HC35*I35,2) -> 0 | HA35: 0 | HB35: 0 | HC35: =GV35*GW35 -> 0 | HS35: 0 | IK35: 0
A37: 51 | B37: =B24 -> 1 | C37: =A24 -> 4 | D37: =ROW(A24) -> 24 | F37: =IF(F24<>"",F24,"") -> Новый раздел | G37: =IF(G24<>"",G24,"") -> Демонтажные работы (Письмо от АНО «РГТ» об утверждении объёмов демонтажных работ) | H37: 0 | O37: =ROUND(AB37,2) -> 0 | P37: =ROUND(AC37,2) -> 0 | Q37: =ROUND(AD37,2) -> 0 | R37: =ROUND(AE37,2) -> 0 | S37: =ROUND(AF37,2) -> 0 | T37: =ROUND(AG37,2) -> 0 | U37: =AH37 -> 0 | V37: =AI37 -> 0 | W37: =ROUND(AJ37,2) -> 0 | X37: =ROUND(AK37,2) -> 0 | Y37: =ROUND(AL37,2) -> 0 | AB37: =ROUND(SUMIF(AA28:AA35,"=55938214",O28:O35),2) -> 0 | AC37: =ROUND(SUMIF(AA28:AA35,"=55938214",P28:P35),2) -> 0 | AD37: =ROUND(SUMIF(AA28:AA35,"=55938214",Q28:Q35),2) -> 0 | AE37: =ROUND(SUMIF(AA28:AA35,"=55938214",R28:R35),2) -> 0 | AF37: =ROUND(SUMIF(AA28:AA35,"=55938214",S28:S35),2) -> 0 | AG37: =ROUND(SUMIF(AA28:AA35,"=55938214",T28:T35),2) -> 0 | AH37: =SUMIF(AA28:AA35,"=55938214",U28:U35) -> 0 | AI37: =SUMIF(AA28:AA35,"=55938214",V28:V35) -> 0 | AJ37: =ROUND(SUMIF(AA28:AA35,"=55938214",W28:W35),2) -> 0 | AK37: =ROUND(SUMIF(AA28:AA35,"=55938214",X28:X35),2) -> 0 | AL37: =ROUND(SUMIF(AA28:AA35,"=55938214",Y28:Y35),2) -> 0 | AO37: =ROUND(BX37,2) -> 0 | AP37: =ROUND(BY37,2) -> 0 | AQ37: =ROUND(BZ37,2) -> 0 | AR37: =ROUND(CA37,2) -> 0 | AS37: =ROUND(CB37,2) -> 0 | AT37: =ROUND(CC37,2) -> 0 | AU37: =ROUND(CD37,2) -> 0 | AV37: =ROUND(CE37,2) -> 0 | ... BD37: =ROUND(CM37,2) -> 0 | BX37: =ROUND(SUMIF(AA28:AA35,"=55938214",FQ28:FQ35),2) -> 0 | BY37: =ROUND(SUMIF(AA28:AA35,"=55938214",FR28:FR35),2) -> 0 | BZ37: =ROUND(SUMIF(AA28:AA35,"=55938214",GL28:GL35),2) -> 0 | CA37: =ROUND(SUMIF(AA28:AA35,"=55938214",GM28:GM35),2) -> 0 | CB37: =ROUND(SUMIF(AA28:AA35,"=55938214",GN28:GN35),2) -> 0 | CC37: =ROUND(SUMIF(AA28:AA35,"=55938214",GO28:GO35),2) -> 0 | CD37: =ROUND(SUMIF(AA28:AA35,"=55938214",GP28:GP35),2) -> 0 | CE37: =AC37-BX37 -> 0 | CF37: =AC37-BY37 -> 0 | CG37: =BX37-BZ37 -> 0 | CH37: =AC37-BX37-BY37+BZ37 -> 0 | CI37: =BY37-BZ37 -> 0 | CJ37: =ROUND(SUMIF(AA28:AA35,"=55938214",GX28:GX35),2) -> 0 | CK37: =ROUND(SUMIF(AA28:AA35,"=55938214",GY28:GY35),2) -> 0 | CL37: =ROUND(SUMIF(AA28:AA35,"=55938214",GZ28:GZ35),2) -> 0 | CM37: =ROUND(SUMIF(AA28:AA35,"=55938214",HD28:HD35),2) -> 0 | DG37: =ROUND(DT37,2) -> 0 | DH37: =ROUND(DU37,2) -> 0 | DI37: =ROUND(DV37,2) -> 0 | DJ37: =ROUND(DW37,2) -> 0 | DK37: =ROUND(DX37,2) -> 0 | DL37: =ROUND(DY37,2) -> 0 | DM37: =DZ37 -> 0 | DN37: =EA37 -> 0 | DO37: =ROUND(EB37,2) -> 0 | DP37: =ROUND(EC37,2) -> 0 | DQ37: =ROUND(ED37,2) -> 0 | DT37: =ROUND(SUMIF(AA28:AA35,"=55938216",O28:O35),2) -> 0 | DU37: =ROUND(SUMIF(AA28:AA35,"=55938216",P28:P35),2) -> 0 | DV37: =ROUND(SUMIF(AA28:AA35,"=55938216",Q28:Q35),2) -> 0 | DW37: =ROUND(SUMIF(AA28:AA35,"=55938216",R28:R35),2) -> 0 | DX37: =ROUND(SUMIF(AA28:AA35,"=55938216",S28:S35),2) -> 0 | DY37: =ROUND(SUMIF(AA28:AA35,"=55938216",T28:T35),2) -> 0 | DZ37: =SUMIF(AA28:AA35,"=55938216",U28:U35) -> 0 | EA37: =SUMIF(AA28:AA35,"=55938216",V28:V35) -> 0 | EB37: =ROUND(SUMIF(AA28:AA35,"=55938216",W28:W35),2) -> 0 | EC37: =ROUND(SUMIF(AA28:AA35,"=55938216",X28:X35),2) -> 0 | ED37: =ROUND(SUMIF(AA28:AA35,"=55938216",Y28:Y35),2) -> 0 | EG37: =ROUND(FP37,2) -> 0 | EH37: =ROUND(FQ37,2) -> 0 | EI37: =ROUND(FR37,2) -> 0 | EJ37: =ROUND(FS37,2) -> 0 | EK37: =ROUND(FT37,2) -> 0 | EL37: =ROUND(FU37,2) -> 0 | EM37: =ROUND(FV37,2) -> 0 | EN37: =ROUND(FW37,2) -> 0 | ... EV37: =ROUND(GE37,2) -> 0 | FP37: =ROUND(SUMIF(AA28:AA35,"=55938216",FQ28:FQ35),2) -> 0 | FQ37: =ROUND(SUMIF(AA28:AA35,"=55938216",FR28:FR35),2) -> 0 | FR37: =ROUND(SUMIF(AA28:AA35,"=55938216",GL28:GL35),2) -> 0 | FS37: =ROUND(SUMIF(AA28:AA35,"=55938216",GM28:GM35),2) -> 0 | FT37: =ROUND(SUMIF(AA28:AA35,"=55938216",GN28:GN35),2) -> 0 | FU37: =ROUND(SUMIF(AA28:AA35,"=55938216",GO28:GO35),2) -> 0 | FV37: =ROUND(SUMIF(AA28:AA35,"=55938216",GP28:GP35),2) -> 0 | FW37: =DU37-FP37 -> 0 | FX37: =DU37-FQ37 -> 0 | FY37: =FP37-FR37 -> 0 | FZ37: =DU37-FP37-FQ37+FR37 -> 0 | GA37: =FQ37-FR37 -> 0 | GB37: =ROUND(SUMIF(AA28:AA35,"=55938216",GX28:GX35),2) -> 0 | GC37: =ROUND(SUMIF(AA28:AA35,"=55938216",GY28:GY35),2) -> 0 | GD37: =ROUND(SUMIF(AA28:AA35,"=55938216",GZ28:GZ35),2) -> 0 | GE37: =ROUND(SUMIF(AA28:AA35,"=55938216",HD28:HD35),2) -> 0 | GX37: 0
A39: 50 | B39: 0 | C39: 0 | D39: 1 | E39: 201 | F39: =ROUND(Source!O37,O39) -> 0 | G39: ПЗ | H39: Прямые затраты | K39: 201 | L39: 1 | M39: 3 | O39: 2 | P39: =ROUND(Source!DG37,O39) -> 0 | W39: 0 | X39: 1 | Y39: 0 | Z39: 0 | AA39: 1 | AB39: 0
A40: 50 | B40: 0 | C40: 0 | D40: 1 | E40: 202 | F40: =ROUND(Source!P37,O40) -> 0 | G40: СтМатОб | H40: Стоимость материальных ресурсов (всего) | K40: 202 | L40: 2 | M40: 3 | O40: 2 | P40: =ROUND(Source!DH37,O40) -> 0 | W40: 0 | X40: 1 | Y40: 0 | Z40: 0 | AA40: 1 | AB40: 0
A41: 50 | B41: 0 | C41: 0 | D41: 1 | E41: 222 | F41: =ROUND(Source!AO37,O41) -> 0 | G41: СтМатОбЗак | H41: Стоимость материалов и оборудования заказчика | K41: 222 | L41: 3 | M41: 3 | O41: 2 | P41: =ROUND(Source!EG37,O41) -> 0 | W41: 0 | X41: 1 | Y41: 0 | Z41: 0 | AA41: 1 | AB41: 0
A42: 50 | B42: 0 | C42: 0 | D42: 1 | E42: 225 | F42: =ROUND(Source!AV37,O42) -> 0 | G42: СтМатОбПод | H42: Стоимость материалов и оборудования подрядчика | K42: 225 | L42: 4 | M42: 3 | O42: 2 | P42: =ROUND(Source!EN37,O42) -> 0 | W42: 0 | X42: 1 | Y42: 0 | Z42: 0 | AA42: 1 | AB42: 0
A43: 50 | B43: 0 | C43: 0 | D43: 1 | E43: 226 | F43: =ROUND(Source!AW37,O43) -> 0 | G43: СтМат | H43: Стоимость материалов (всего) | K43: 226 | L43: 5 | M43: 3 | O43: 2 | P43: =ROUND(Source!EO37,O43) -> 0 | W43: 0 | X43: 1 | Y43: 0 | Z43: 0 | AA43: 1 | AB43: 0
A44: 50 | B44: 0 | C44: 0 | D44: 1 | E44: 227 | F44: =ROUND(Source!AX37,O44) -> 0 | G44: СтМатЗак | H44: Стоимость материалов заказчика | K44: 227 | L44: 6 | M44: 3 | O44: 2 | P44: =ROUND(Source!EP37,O44) -> 0 | W44: 0 | X44: 1 | Y44: 0 | Z44: 0 | AA44: 1 | AB44: 0
A45: 50 | B45: 0 | C45: 0 | D45: 1 | E45: 228 | F45: =ROUND(Source!AY37,O45) -> 0 | G45: СтМатПод | H45: Стоимость материалов подрядчика | K45: 228 | L45: 7 | M45: 3 | O45: 2 | P45: =ROUND(Source!EQ37,O45) -> 0 | W45: 0 | X45: 1 | Y45: 0 | Z45: 0 | AA45: 1 | AB45: 0
A46: 50 | B46: 0 | C46: 0 | D46: 1 | E46: 216 | F46: =ROUND(Source!AP37,O46) -> 0 | G46: Оборуд | H46: Стоимость оборудования (всего) | K46: 216 | L46: 8 | M46: 3 | O46: 2 | P46: =ROUND(Source!EH37,O46) -> 0 | W46: 0 | X46: 1 | Y46: 0 | Z46: 0 | AA46: 1 | AB46: 0
A47: 50 | B47: 0 | C47: 0 | D47: 1 | E47: 223 | F47: =ROUND(Source!AQ37,O47) -> 0 | G47: ОборудЗак | H47: Стоимость оборудования заказчика | K47: 223 | L47: 9 | M47: 3 | O47: 2 | P47: =ROUND(Source!EI37,O47) -> 0 | W47: 0 | X47: 1 | Y47: 0 | Z47: 0 | AA47: 1 | AB47: 0
A48: 50 | B48: 0 | C48: 0 | D48: 1 | E48: 229 | F48: =ROUND(Source!AZ37,O48) -> 0 | G48: ОборудПод | H48: Стоимость оборудования подрядчика | K48: 229 | L48: 10 | M48: 3 | O48: 2 | P48: =ROUND(Source!ER37,O48) -> 0 | W48: 0 | X48: 1 | Y48: 0 | Z48: 0 | AA48: 1 | AB48: 0
A49: 50 | B49: 0 | C49: 0 | D49: 1 | E49: 203 | F49: =ROUND(Source!Q37,O49) -> 0 | G49: ЭММ | H49: Эксплуатация машин | K49: 203 | L49: 11 | M49: 3 | O49: 2 | P49: =ROUND(Source!DI37,O49) -> 0 | W49: 0 | X49: 1 | Y49: 0 | Z49: 0 | AA49: 1 | AB49: 0
A50: 50 | B50: 0 | C50: 0 | D50: 1 | E50: 231 | F50: =ROUND(Source!BB37,O50) -> 0 | G50: ЭММсНРиСП | H50: Эксплуатация машин по ТСН-2001.16 | K50: 231 | L50: 12 | M50: 3 | O50: 2 | P50: =ROUND(Source!ET37,O50) -> 0 | W50: 0 | X50: 1 | Y50: 0 | Z50: 0 | AA50: 1 | AB50: 0
A51: 50 | B51: 0 | C51: 0 | D51: 1 | E51: 204 | F51: =ROUND(Source!R37,O51) -> 0 | G51: ЗПМ | H51: ЗП машинистов | K51: 204 | L51: 13 | M51: 3 | O51: 2 | P51: =ROUND(Source!DJ37,O51) -> 0 | W51: 0 | X51: 1 | Y51: 0 | Z51: 0 | AA51: 1 | AB51: 0
A52: 50 | B52: 0 | C52: 0 | D52: 1 | E52: 205 | F52: =ROUND(Source!S37,O52) -> 0 | G52: ОЗП | H52: Основная ЗП рабочих | K52: 205 | L52: 14 | M52: 3 | O52: 2 | P52: =ROUND(Source!DK37,O52) -> 0 | W52: 0 | X52: 1 | Y52: 0 | Z52: 0 | AA52: 1 | AB52: 0
A53: 50 | B53: 0 | C53: 0 | D53: 1 | E53: 232 | F53: =ROUND(Source!BC37,O53) -> 0 | G53: ОЗПсНРиСП | H53: Основная ЗП рабочих по ТСН-2001.16 | K53: 232 | L53: 15 | M53: 3 | O53: 2 | P53: =ROUND(Source!EU37,O53) -> 0 | W53: 0 | X53: 1 | Y53: 0 | Z53: 0 | AA53: 1 | AB53: 0
A54: 50 | B54: 0 | C54: 0 | D54: 1 | E54: 214 | F54: =ROUND(Source!AS37,O54) -> 0 | G54: Строит | H54: Строительные работы с НР и СП | K54: 214 | L54: 16 | M54: 3 | O54: 2 | P54: =ROUND(Source!EK37,O54) -> 0 | W54: 0 | X54: 1 | Y54: 0 | Z54: 0 | AA54: 1 | AB54: 0
A55: 50 | B55: 0 | C55: 0 | D55: 1 | E55: 215 | F55: =ROUND(Source!AT37,O55) -> 0 | G55: Монтаж | H55: Монтажные работы с НР и СП | K55: 215 | L55: 17 | M55: 3 | O55: 2 | P55: =ROUND(Source!EL37,O55) -> 0 | W55: 0 | X55: 1 | Y55: 0 | Z55: 0 | AA55: 1 | AB55: 0
A56: 50 | B56: 0 | C56: 0 | D56: 1 | E56: 217 | F56: =ROUND(Source!AU37,O56) -> 0 | G56: Прочие | H56: Прочие работы с НР и СП | K56: 217 | L56: 18 | M56: 3 | O56: 2 | P56: =ROUND(Source!EM37,O56) -> 0 | W56: 0 | X56: 1 | Y56: 0 | Z56: 0 | AA56: 1 | AB56: 0
A57: 50 | B57: 0 | C57: 0 | D57: 1 | E57: 230 | F57: =ROUND(Source!BA37,O57) -> 0 | G57: ПрочиеЗатр | H57: Прочие затраты по ТСН-2001.16 | K57: 230 | L57: 19 | M57: 3 | O57: 2 | P57: =ROUND(Source!ES37,O57) -> 0 | W57: 0 | X57: 1 | Y57: 0 | Z57: 0 | AA57: 1 | AB57: 0
A58: 50 | B58: 0 | C58: 0 | D58: 1 | E58: 206 | F58: =ROUND(Source!T37,O58) -> 0 | G58: ВозврМат | H58: Возврат материалов | K58: 206 | L58: 20 | M58: 3 | O58: 2 | P58: =ROUND(Source!DL37,O58) -> 0 | W58: 0 | X58: 1 | Y58: 0 | Z58: 0 | AA58: 1 | AB58: 0
A59: 50 | B59: 0 | C59: 0 | D59: 1 | E59: 207 | F59: =Source!U37 -> 0 | G59: ТрудСтр | H59: Трудозатраты строителей | K59: 207 | L59: 21 | M59: 3 | O59: -1 | P59: =Source!DM37 -> 0 | W59: 0 | X59: 1 | Y59: 0 | Z59: 0 | AA59: 1 | AB59: 0
...

Sheet SourceObSm
A1: 0 | B1: Smeta.RU (495) 974-1589 | D1: _OBSM_ | F1: 0 | G1: 0 | H1: 0 | I1: Smeta.RU | K1: 1 | L1: 74599 | M1: 10 | N1: 12 | O1: 1 | P1: 0 | Q1: 5
A4: 1 | B4: 1 | C4: -1 | G4: Капитальный ремонт здания Государственного бюджетного общеобразовательного учреждения города Москвы «Школа №1574», расположенного по адресу: г. Москва, Старопименовский переулок, д. 5. 1 этап | EC4: 0
A5: 8 | B5: 1 | C5: -1 | G5: Капитальный ремонт здания Государственного бюджетного общеобразовательного учреждения города Москвы «Школа №1574», расположенного по адресу: г. Москва, Старопименовский переулок, д. 5. 1 этап | EC5: 0
