Workbook

Sheet Смета по ТСН-2001(с доп.67
A1: =Source!B1 -> Smeta.RU (495) 974-1589
J2: Форма № 4б
B3: "СОГЛАСОВАНО" | G3: "УТВЕРЖДАЮ"
B6: =CONCATENATE("______________________ ", IF(Source!AL12<>"", Source!AL12, "")) -> ______________________ | G6: =CONCATENATE("______________________ ", IF(Source!AH12<>"", Source!AH12, "")) -> ______________________
B7: "_____"________________ 2026 г. | G7: "_____"________________ 2026 г.
A10: Капитальный ремонт здания Государственного бюджетного общеобразовательного учреждения города Москвы «Школа №1574», расположенного по адресу: г. Москва, Старопименовский переулок, д. 5. 1 этап. | AP10: Капитальный ремонт здания Государственного бюджетного общеобразовательного учреждения города Москвы «Школа №1574», расположенного по адресу: г. Москва, Старопименовский переулок, д. 5. 1 этап. 02-01-16 Электрочасофикация 15.07
A11: (наименование стройки и/или объекта)
A13: =CONCATENATE( "ЛОКАЛЬНАЯ СМЕТА № ",IF(Source!F12<>"Новый объект", Source!F12, "")) -> ЛОКАЛЬНАЯ СМЕТА № 02-01-16
A15: =Source!G20 -> Электрочасофикация
A16: (наименование работ и затрат)
A18: =CONCATENATE( "Основание: чертежи № ", Source!J12) -> Основание: чертежи № 2024-00375-01-0-ИОС5.9
I20: В базисном уровне цен | J20: В текущем уровне цен
E21: Сметная стоимость | I21: =I22+I23+I24+I25 -> 135.22 | J21: =J22+J23+J24+J25 -> 1054.65 | K21: тыс.руб.
E22: Строительные работы | I22: =ROUND((Source!F247)/1000, 2) -> 0 | J22: =ROUND((Source!P247)/1000, 2) -> 0 | K22: тыс.руб.
E23: Работы по монтажу оборудования | I23: =ROUND((Source!F248)/1000, 2) -> 0.74 | J23: =ROUND((Source!P248)/1000, 2) -> 36.65 | K23: тыс.руб.
E24: Оборудование | I24: =ROUND((Source!F239)/1000, 2) -> 134.48 | J24: =ROUND((Source!P239)/1000, 2) -> 1018 | K24: тыс.руб.
E25: Прочие работы и затраты | I25: =ROUND((Source!F249+Source!F250)/1000, 2) -> 0 | J25: =ROUND((Source!P249+Source!P250)/1000, 2) -> 0 | K25: тыс.руб.
E26: Средства на оплату труда | I26: =(Source!F245+ Source!F244)/1000 -> 0.26827 | J26: =((Source!P245 + Source!P244)/1000) -> 15.11703 | K26: тыс.руб.
E27: Затраты труда | I27: =Source!F252 -> 21.315978 | K27: чел.-ч.
E28: Кроме того:
E29: Возврат материалов | I29: =SUM(Y1:Y173)/1000 -> 0 | J29: =SUM(Z1:Z173)/1000 -> 0 | K29: тыс.руб.
A31: Составлен(а) по ТСН-2001 с учетом Дополнения №: 81
A32: № и период сборника коэффициентов (индексов) пересчета: Коэффициенты к ТСН-2001 МГЭ Дополнение 81, ремонт №219/81 I квартал 2026 года и Коэффициенты к ТСН-2001.13-2 Дополнение 47 №64/47 I квартал 2026 года | AP32: № и период сборника коэффициентов (индексов) пересчета: Коэффициенты к ТСН-2001 МГЭ Дополнение 81, ремонт №219/81 I квартал 2026 года и Коэффициенты к ТСН-2001.13-2 Дополнение 47 №64/47 I квартал 2026 года
A33: № п/п | B33: Шифр расценки и коды ресурсов | C33: Наименование работ и затрат | D33: Ед. изм. | E33: Кол-во единиц | F33: Цена на ед. изм., руб. | G33: Попра- вочные коэффи- циенты | H33: Коэффи- циенты зимних удорожа- ний | I33: Всего в ценах на январь 2000 года, руб. | J33: Коэффи- циенты (индек- сы) пере- счета, нормы НР и СП | K33: ВСЕГО затрат в текущем уровне цен, руб.
A34: 1 | B34: 2 | C34: 3 | D34: 4 | E34: 5 | F34: 6 | G34: 7 | H34: 8 | I34: 9 | J34: 10 | K34: 11
A36: =CONCATENATE("Локальная смета: ",IF(Source!G20<>"Новая локальная смета", Source!G20, "")) -> Локальная смета: Электрочасофикация
A38: =CONCATENATE("Раздел: ",IF(Source!G24<>"Новый раздел", Source!G24, "")) -> Раздел: Демонтажные работы (Письмо от АНО «РГТ» об утверждении объёмов демонтажных работ) | AP38: =CONCATENATE("Раздел: ",IF(Source!G24<>"Новый раздел", Source!G24, "")) -> Раздел: Демонтажные работы (Письмо от АНО «РГТ» об утверждении объёмов демонтажных работ)
A39: 1 | B39: =Source!F28 -> 4.10-85-1 | C39: Монтаж часов первичных электрических показывающих кварцевых типа ПКЧЗ-2-РИ-Р24-Р6-1 / демонтаж часовой станции | D39: =Source!H28 -> 1 ШТ. | E39: =Source!I28 -> 1 | Q39: =Source!X28 -> 14.01 | R39: =Source!X29 -> 789.63 | S39: =Source!Y28 -> 7.16 | T39: =Source!Y29 -> 403.59 | U39: =ROUND((175/100)*ROUND(Source!R28, 2), 2) -> 0 | V39: =ROUND((0/100)*ROUND(Source!R29, 2), 2) -> 0 | AC39: 0
C40: ЗП | F40: =Source!AO28 -> 41.31 | G40: 1,2*0,3 | H40: =Source!AV29 -> 1.047 | I40: =Source!S28 -> 15.57 | J40: =IF(Source!BA29<> 0, Source!BA29, 1) -> 56.35 | K40: =Source!S29 -> 877.37
C41: НР от ФОТ | D41: % | E41: =Source!BZ29 -> 90 | I41: =SUM(Q39:Q40) -> 14.01 | J41: =Source!AT29 -> 90 | K41: =SUM(R39:R40) -> 789.63
C42: СП от ФОТ | D42: % | E42: =Source!CA29 -> 46 | I42: =SUM(S39:S41) -> 7.16 | J42: =Source!AU29 -> 46 | K42: =SUM(T39:T41) -> 403.59
C43: ЗТР | D43: чел-ч | E43: =Source!AQ28 -> 3 | G43: 1,2*0,3 | H43: =Source!AV29 -> 1.047 | I43: =Source!U28 -> 1.13076
C44: ВСЕГО работ по позиции: | H44: =I40+I41+I42+0-0-0 -> 36.74 | J44: =K40+K41+K42+0-0-0 -> 2070.59
C45: ВСЕГО оборудование по позиции: | H45: =0+0 -> 0 | J45: =0+0 -> 0
C46: ВСЕГО по позиции: | H46: =I40+I41+I42+0 -> 36.74 | J46: =K40+K41+K42+0 -> 2070.59 | O46: =I40+I41+I42+0 -> 36.74 | P46: =K40+K41+K42+0 -> 2070.59
A48: 2 | B48: =Source!F30 -> 4.10-134-7 | C48: Монтаж антенны дополнительной для приема ТВ на ранее установленной опоре, с действующими ТВ антеннами / демонтаж антенны | D48: =Source!H30 -> 1 антенна | E48: =Source!I30 -> 1 | Q48: =Source!X30 -> 14.81 | R48: =Source!X31 -> 834.58 | S48: =Source!Y30 -> 8.26 | T48: =Source!Y31 -> 465.61 | U48: =ROUND((175/100)*ROUND(Source!R30, 2), 2) -> 0 | V48: =ROUND((0/100)*ROUND(Source!R31, 2), 2) -> 0 | AC48: 0
C49: ЗП | F49: =Source!AO30 -> 39.85 | G49: 1,2*0,3 | H49: =Source!AV31 -> 1.087 | I49: =Source!S30 -> 15.59 | J49: =IF(Source!BA31<> 0, Source!BA31, 1) -> 56.35 | K49: =Source!S31 -> 878.5
C50: НР от ФОТ | D50: % | E50: =Source!BZ31 -> 95 | I50: =SUM(Q48:Q49) -> 14.81 | J50: =Source!AT31 -> 95 | K50: =SUM(R48:R49) -> 834.58
C51: СП от ФОТ | D51: % | E51: =Source!CA31 -> 53 | I51: =SUM(S48:S50) -> 8.26 | J51: =Source!AU31 -> 53 | K51: =SUM(T48:T50) -> 465.61
C52: ЗТР | D52: чел-ч | E52: =Source!AQ30 -> 2.77 | G52: 1,2*0,3 | H52: =Source!AV31 -> 1.087 | I52: =Source!U30 -> 1.0839564
...

Sheet Source
A1: 0 | B1: Smeta.RU (495) 974-1589 | D1: _PS_ | F1: 0 | G1: 0 | H1: 0 | I1: Smeta.RU | K1: 1 | L1: 74599 | M1: 10 | N1: 12 | O1: 1 | P1: 0 | Q1: 5
A4: 1 | B4: 1 | C4: -1 | G4: Капитальный ремонт здания Государственного бюджетного общеобразовательного учреждения города Москвы «Школа №1574», расположенного по адресу: г. Москва, Старопименовский переулок, д. 5. 1 этап | EC4: 0
A5: 8 | B5: 1 | C5: -1 | G5: Капитальный ремонт здания Государственного бюджетного общеобразовательного учреждения города Москвы «Школа №1574», расположенного по адресу: г. Москва, Старопименовский переулок, д. 5. 1 этап | EC5: 0
A12: 1 | B12: 271 | C12: 0 | D12: =ROW(A230) -> 230 | E12: 0 | F12: 02-01-16 | G12: 02-01-16 Электрочасофикация 15.07 | I12: 0 | J12: 2024-00375-01-0-ИОС5.9 | K12: 0 | L12: 0 | M12: 4097 | O12: 0 | P12: 0 | Q12: 0 | R12: 0 | S12: 0 | T12: 1 | U12: Капитальный ремонт здания Государственного бюджетного общеобразовательного учреждения города Москвы «Школа №1574», | V12: 2 | W12: г. Москва, Старопименовский переулок, д. 5. 1 этап | AB12: О.А.Гришечкина | AC12: Ведущий инженер-сметчик | AD12: И.В.Феденко | AE12: Начальник отдела | BB12: 0 | BH12: Сметные нормы списания | BI12: Коды ОКП для ТСН-2001 МГЭ Дополнение 81 | BJ12: 1 | BK12: 1 | BL12: 0 | BM12: 0 | BN12: 1 | BO12: 0 | BP12: 6 | BQ12: 2 | BR12: 1 | BS12: 1 | BT12: 0 | BU12: 0 | BV12: 0 | BW12: 0 | BX12: 0 | BY12: ТСН-2001 (МГЭ) Доп 81 - Ремонт | BZ12: Типовой расчет для ТСН-2001 МГЭ, Дополнение 81, ремонт | CA12: Территориальные сметные нормативы для Москвы ТСН-2001 (МГЭ), дополнение 81 | CB12: Территориальные сметные нормативы для Москвы ТСН-2001 (МГЭ), дополнение 81 | CC12: Территориальные сметные нормативы для Москвы ТСН-2001 (МГЭ), дополнение 81 | CD12: Территориальные сметные нормативы для Москвы ТСН-2001 (МГЭ), дополнение 81 | CE12: Поправки для ТСН-2001 от 07.04.2026 г. доп.81 | CF12: 0 | CG12: 0 | CH12: 8 | CK12: 82 | CQ12: Территориальные сметные нормативы для Москвы (ТСН-2001) | CR12: ТЕР | CS12: 41660 | CT12: 1 | CU12: 81 | CY12: 0 | EC12: 0
A15: 15 | B15: 1
A18: 52 | B18: =B230 -> 271 | C18: =C230 -> 1 | D18: =D230 -> 12 | E18: =E230 -> 0 | F18: =F230 -> 02-01-16 | G18: =G230 -> 02-01-16 Электрочасофикация 15.07 | O18: =O230 -> 134852.23 | P18: =P230 -> 134583.43 | Q18: =Q230 -> 0.63 | R18: =R230 -> 0.1 | S18: =S230 -> 268.17 | T18: =T230 -> 0 | U18: =U230 -> 21.315978 | V18: =V230 -> 0 | ... GX18: =GX230 -> 0
A20: 3 | B20: 1 | D20: =ROW(A200) -> 200 | F20: 02-01-16 | G20: Электрочасофикация | I20: 0 | J20: 2024-00375-01-0-ИОС5.9 | K20: -1 | L20: 02-01-16 | S20: 0 | T20: 0 | V20: 2 | BX20: 0 | CF20: 0 | CG20: 0
A22: 52 | B22: =B200 -> 1 | C22: =C200 -> 3 | D22: =D200 -> 20 | E22: =E200 -> 0 | F22: =F200 -> 02-01-16 | G22: =G200 -> Электрочасофикация | O22: =O200 -> 134852.23 | P22: =P200 -> 134583.43 | Q22: =Q200 -> 0.63 | R22: =R200 -> 0.1 | S22: =S200 -> 268.17 | T22: =T200 -> 0 | U22: =U200 -> 21.315978 | V22: =V200 -> 0 | ... GX22: =GX200 -> 0
A24: 4 | B24: 1 | D24: =ROW(A37) -> 37 | F24: Новый раздел | G24: Демонтажные работы (Письмо от АНО «РГТ» об утверждении объёмов демонтажных работ) | I24: 0 | K24: -1 | S24: 0 | T24: 0 | V24: 2 | BX24: 0 | CJ24: 0
A26: 52 | B26: =B37 -> 1 | C26: =C37 -> 4 | D26: =D37 -> 24 | E26: =E37 -> 0 | F26: =F37 -> Новый раздел | G26: =G37 -> Демонтажные работы (Письмо от АНО «РГТ» об утверждении объёмов демонтажных работ) | O26: =O37 -> 62.38 | P26: =P37 -> 0 | Q26: =Q37 -> 0 | R26: =R37 -> 0 | S26: =S37 -> 62.38 | T26: =T37 -> 0 | U26: =U37 -> 4.7892924 | V26: =V37 -> 0 | ... GX26: =GX37 -> 0
A28: 17 | B28: 1 | C28: =ROW(SmtRes!A3) -> 3 | D28: =ROW(EtalonRes!A3) -> 3 | E28: 1 | F28: 4.10-85-1 | G28: Монтаж часов первичных электрических показывающих кварцевых типа ПКЧЗ-2-РИ-Р24-Р6-1 / демонтаж часовой станции | H28: 1 ШТ. | I28: 1 | J28: 0 | K28: 1 | O28: =ROUND(CP28,2) -> 15.57 | P28: =ROUND((ROUND((AC28*AW28*I28),2)*BC28),2) -> 0 | Q28: =(ROUND((ROUND(((((ET28*1.2)*0.3))*AV28*I28),2)*BB28),2)+ROUND((ROUND(((AE28-(((EU28*1.2)*0.3)))*AV28*I28),2)*BS28),2)) -> 0 | R28: =(ROUND((ROUND(((((EU28*1.2)*0.3))*AV28*I28),2)*BS28),2)+ROUND((ROUND(((AE28-(((EU28*1.2)*0.3)))*AV28*I28),2)*BS28),2)) -> 0 | S28: =ROUND((ROUND((AF28*AV28*I28),2)*BA28),2) -> 15.57 | T28: =ROUND(CU28*I28,2) -> 0 | U28: =CV28*I28 -> 1.13076 | V28: =CW28*I28 -> 0 | W28: =ROUND(CX28*I28,2) -> 0 | X28: =(ROUND((((S28+ROUND((ROUND(((((EU28*1.2)*0.3))*AV28*I28),2)*BS28),2))*AT28)/100),2)+ROUND(((ROUND((ROUND(((AE28-(((EU28*1.2)*0.3)))*AV28*I28),2)*BS28),2)*AT28)/100),2)) -> 14.01 | Y28: =(ROUND((((S28+ROUND((ROUND(((((EU28*1.2)*0.3))*AV28*I28),2)*BS28),2))*AU28)/100),2)+ROUND(((ROUND((ROUND(((AE28-(((EU28*1.2)*0.3)))*AV28*I28),2)*BS28),2)*AU28)/100),2)) -> 7.16 | AA28: 55942966 | AB28: =ROUND((AC28+AD28+AF28),6) -> 14.8716 | AC28: =ROUND((((ES28*1)*0)),6) -> 0 | AD28: =ROUND((((((ET28*1.2)*0.3))-(((EU28*1.2)*0.3)))+AE28),6) -> 0 | AE28: =ROUND((((EU28*1.2)*0.3)),6) -> 0 | AF28: =ROUND((((EV28*1.2)*0.3)),6) -> 14.8716 | AG28: =ROUND((AP28),6) -> 0 | AH28: =(((EW28*1.2)*0.3)) -> 1.08 | AI28: =(((EX28*1.2)*0.3)) -> 0 | AJ28: =(AS28) -> 0 | AK28: 41.77 | AL28: 0.46 | AM28: 0 | AN28: 0 | AO28: 41.31 | AP28: 0 | AQ28: 3 | AR28: 0 | AS28: 0 | AT28: 90 | AU28: 46 | AV28: 1.047 | AW28: 1 | AZ28: 1 | BA28: 1 | BB28: 1 | BC28: 1 | BH28: 0 | BI28: 2 | BJ28: ТСН-2001.4 Доп. 81, Сб. 10, т. 85, поз. 1 | BM28: 68 | BN28: 0 | BO28: 4.10-85-1 | BP28: 1 | BQ28: 40 | BR28: 0 | BS28: 1 | BT28: 1 | BU28: 1 | BV28: 1 | BW28: 1 | BX28: 1 | BZ28: 90 | CA28: 46 | CE28: 1566 | CF28: 0 | CG28: 0 | CM28: 0 | CN28: Поправка: Гл.12.Прил.8.п.8. 3_12.00.01.11.001 Наименование: При наличии напряженных и стесненных условий производства работ (стесненность, сложность складирования и транспортной логистики и т.п.) для объектов, расположенных в пределах круговой магистральной системы улиц "Садовое кольцо" города Москвы Поправка: Гл.4.Прил.2.2.п.2.2.29_04.00.01.35.003 Наименование: При демонтаже оборудования, предназначенного в лом | CO28: 0 | CP28: =(P28+Q28+S28) -> 15.57 | CQ28: =ROUND((ROUND((AC28*AW28*1),2)*BC28),2) -> 0 | CR28: =(ROUND((ROUND(((((ET28*1.2)*0.3))*AV28*1),2)*BB28),2)+ROUND((ROUND(((AE28-(((EU28*1.2)*0.3)))*AV28*1),2)*BS28),2)) -> 0 | CS28: =(ROUND((ROUND(((((EU28*1.2)*0.3))*AV28*1),2)*BS28),2)+ROUND((ROUND(((AE28-(((EU28*1.2)*0.3)))*AV28*1),2)*BS28),2)) -> 0 | CT28: =ROUND((ROUND((AF28*AV28*1),2)*BA28),2) -> 15.57 | CU28: =AG28 -> 0 | CV28: =(AH28*AV28) -> 1.13076 | CW28: =AI28 -> 0 | CX28: =AJ28 -> 0 | CY28: =(ROUND((((S28+ROUND((ROUND(((((EU28*1.2)*0.3))*AV28*1),2)*BS28),2))*AT28)/100),2)+ROUND(((ROUND((ROUND(((AE28-(((EU28*1.2)*0.3)))*AV28*1),2)*BS28),2)*AT28)/100),2)) -> 14.01 | CZ28: =(ROUND((((S28+ROUND((ROUND(((((EU28*1.2)*0.3))*AV28*1),2)*BS28),2))*AU28)/100),2)+ROUND(((ROUND((ROUND(((AE28-(((EU28*1.2)*0.3)))*AV28*1),2)*BS28),2)*AU28)/100),2)) -> 7.16 | DB28: 1 | DD28: *1)*0 | DE28: *1,2)*0,3 | DF28: *1,2)*0,3 | DG28: *1,2)*0,3 | DI28: *1,2)*0,3 | DJ28: *1,2)*0,3 | DN28: 0 | DO28: 0 | DP28: 1 | DQ28: 1 | DU28: 1013 | DV28: 1 ШТ. | DW28: 1 ШТ. | DX28: 1 | EE28: 55393972 | EF28: 40 | EG28: Монтаж оборудования | EH28: 0 | EJ28: 2 | EK28: 68 | EL28: ТСН-2001.4-10. Прокладка и монтаж сетей связи | EM28: ТСН-2001.4-10-1 | EO28: Поправка: Гл.12.Прил.8.п.8. 3_12.00.01.11.001 Поправка: Гл.4.Прил.2.2.п.2.2.29_04.00.01.35.003 | EQ28: 0 | ER28: 41.77 | ES28: 0.46 | ET28: 0 | EU28: 0 | EV28: 41.31 | EW28: 3 | EX28: 0 | EY28: 0 | FQ28: 0 | FR28: 0 | FS28: 0 | FX28: 90 | FY28: 46 | GD28: 1 | GF28: 1212227501 | GG28: 2 | GH28: 1 | GI28: 2 | GJ28: 0 | GK28: 0 | GL28: =ROUND(IF(AND(BH28=3,BI28=3,FS28<>0),P28,0),2) -> 0 | GM28: =ROUND(O28+X28+Y28,2)+GX28 -> 36.74 | GN28: =IF(OR(BI28=0,BI28=1),GM28-GX28,0) -> 0 | GO28: =IF(BI28=2,GM28-GX28,0) -> 36.74 | GP28: =IF(BI28=4,GM28-GX28,0) -> 0 | GR28: 0 | GS28: 3 | GT28: 0 | GV28: =ROUND((GT28),6) -> 0 | GW28: 1 | GX28: =ROUND(HC28*I28,2) -> 0 | HA28: 0 | HB28: 0 | HC28: =GV28*GW28 -> 0 | HS28: 0 | IK28: 0
A29: 17 | B29: 1 | C29: =ROW(SmtRes!A6) -> 6 | D29: =ROW(EtalonRes!A6) -> 6 | E29: 1 | F29: 4.10-85-1 | G29: Монтаж часов первичных электрических показывающих кварцевых типа ПКЧЗ-2-РИ-Р24-Р6-1 / демонтаж часовой станции | H29: 1 ШТ. | I29: 1 | J29: 0 | K29: 1 | O29: =ROUND(CP29,2) -> 877.37 | P29: =ROUND((ROUND((AC29*AW29*I29),2)*BC29),2) -> 0 | Q29: =(ROUND((ROUND(((((ET29*1.2)*0.3))*AV29*I29),2)*BB29),2)+ROUND((ROUND(((AE29-(((EU29*1.2)*0.3)))*AV29*I29),2)*BS29),2)) -> 0 | R29: =(ROUND((ROUND(((((EU29*1.2)*0.3))*AV29*I29),2)*BS29),2)+ROUND((ROUND(((AE29-(((EU29*1.2)*0.3)))*AV29*I29),2)*BS29),2)) -> 0 | S29: =ROUND((ROUND((AF29*AV29*I29),2)*BA29),2) -> 877.37 | T29: =ROUND(CU29*I29,2) -> 0 | U29: =CV29*I29 -> 1.13076 | V29: =CW29*I29 -> 0 | W29: =ROUND(CX29*I29,2) -> 0 | X29: =(ROUND((((S29+ROUND((ROUND(((((EU29*1.2)*0.3))*AV29*I29),2)*BS29),2))*AT29)/100),2)+ROUND(((ROUND((ROUND(((AE29-(((EU29*1.2)*0.3)))*AV29*I29),2)*BS29),2)*AT29)/100),2)) -> 789.63 | Y29: =(ROUND((((S29+ROUND((ROUND(((((EU29*1.2)*0.3))*AV29*I29),2)*BS29),2))*AU29)/100),2)+ROUND(((ROUND((ROUND(((AE29-(((EU29*1.2)*0.3)))*AV29*I29),2)*BS29),2)*AU29)/100),2)) -> 403.59 | AA29: 55942968 | AB29: =ROUND((AC29+AD29+AF29),6) -> 14.8716 | AC29: =ROUND((((ES29*1)*0)),6) -> 0 | AD29: =ROUND((((((ET29*1.2)*0.3))-(((EU29*1.2)*0.3)))+AE29),6) -> 0 | AE29: =ROUND((((EU29*1.2)*0.3)),6) -> 0 | AF29: =ROUND((((EV29*1.2)*0.3)),6) -> 14.8716 | AG29: =ROUND((AP29),6) -> 0 | AH29: =(((EW29*1.2)*0.3)) -> 1.08 | AI29: =(((EX29*1.2)*0.3)) -> 0 | AJ29: =(AS29) -> 0 | AK29: 41.77 | AL29: 0.46 | AM29: 0 | AN29: 0 | AO29: 41.31 | AP29: 0 | AQ29: 3 | AR29: 0 | AS29: 0 | AT29: 90 | AU29: 46 | AV29: 1.047 | AW29: 1 | AZ29: 1 | BA29: 56.35 | BB29: 1 | BC29: 6.83 | BH29: 0 | BI29: 2 | BJ29: ТСН-2001.4 Доп. 81, Сб. 10, т. 85, поз. 1 | BM29: 68 | BN29: 0 | BO29: 4.10-85-1 | BP29: 1 | BQ29: 40 | BR29: 0 | BS29: 56.35 | BT29: 1 | BU29: 1 | BV29: 1 | BW29: 1 | BX29: 1 | BZ29: 90 | CA29: 46 | CE29: 1566 | CF29: 0 | CG29: 0 | CM29: 0 | CN29: Поправка: Гл.12.Прил.8.п.8. 3_12.00.01.11.001 Наименование: При наличии напряженных и стесненных условий производства работ (стесненность, сложность складирования и транспортной логистики и т.п.) для объектов, расположенных в пределах круговой магистральной системы улиц "Садовое кольцо" города Москвы Поправка: Гл.4.Прил.2.2.п.2.2.29_04.00.01.35.003 Наименование: При демонтаже оборудования, предназначенного в лом | CO29: 0 | CP29: =(P29+Q29+S29) -> 877.37 | CQ29: =ROUND((ROUND((AC29*AW29*1),2)*BC29),2) -> 0 | CR29: =(ROUND((ROUND(((((ET29*1.2)*0.3))*AV29*1),2)*BB29),2)+ROUND((ROUND(((AE29-(((EU29*1.2)*0.3)))*AV29*1),2)*BS29),2)) -> 0 | CS29: =(ROUND((ROUND(((((EU29*1.2)*0.3))*AV29*1),2)*BS29),2)+ROUND((ROUND(((AE29-(((EU29*1.2)*0.3)))*AV29*1),2)*BS29),2)) -> 0 | CT29: =ROUND((ROUND((AF29*AV29*1),2)*BA29),2) -> 877.37 | CU29: =AG29 -> 0 | CV29: =(AH29*AV29) -> 1.13076 | CW29: =AI29 -> 0 | CX29: =AJ29 -> 0 | CY29: =(ROUND((((S29+ROUND((ROUND(((((EU29*1.2)*0.3))*AV29*1),2)*BS29),2))*AT29)/100),2)+ROUND(((ROUND((ROUND(((AE29-(((EU29*1.2)*0.3)))*AV29*1),2)*BS29),2)*AT29)/100),2)) -> 789.63 | CZ29: =(ROUND((((S29+ROUND((ROUND(((((EU29*1.2)*0.3))*AV29*1),2)*BS29),2))*AU29)/100),2)+ROUND(((ROUND((ROUND(((AE29-(((EU29*1.2)*0.3)))*AV29*1),2)*BS29),2)*AU29)/100),2)) -> 403.59 | DB29: 3 | DD29: *1)*0 | DE29: *1,2)*0,3 | DF29: *1,2)*0,3 | DG29: *1,2)*0,3 | DI29: *1,2)*0,3 | DJ29: *1,2)*0,3 | DN29: 0 | DO29: 0 | DP29: 1 | DQ29: 1 | DU29: 1013 | DV29: 1 ШТ. | DW29: 1 ШТ. | DX29: 1 | EE29: 55393972 | EF29: 40 | EG29: Монтаж оборудования | EH29: 0 | EJ29: 2 | EK29: 68 | EL29: ТСН-2001.4-10. Прокладка и монтаж сетей связи | EM29: ТСН-2001.4-10-1 | EO29: Поправка: Гл.12.Прил.8.п.8. 3_12.00.01.11.001 Поправка: Гл.4.Прил.2.2.п.2.2.29_04.00.01.35.003 | EQ29: 0 | ER29: 41.77 | ES29: 0.46 | ET29: 0 | EU29: 0 | EV29: 41.31 | EW29: 3 | EX29: 0 | EY29: 0 | FQ29: 0 | FR29: 0 | FS29: 0 | FX29: 90 | FY29: 46 | GD29: 1 | GF29: 1212227501 | GG29: 2 | GH29: 1 | GI29: 2 | GJ29: 0 | GK29: 0 | GL29: =ROUND(IF(AND(BH29=3,BI29=3,FS29<>0),P29,0),2) -> 0 | GM29: =ROUND(O29+X29+Y29,2)+GX29 -> 2070.59 | GN29: =IF(OR(BI29=0,BI29=1),GM29-GX29,0) -> 0 | GO29: =IF(BI29=2,GM29-GX29,0) -> 2070.59 | GP29: =IF(BI29=4,GM29-GX29,0) -> 0 | GR29: 0 | GS29: 3 | GT29: 0 | GV29: =ROUND((GT29),6) -> 0 | GW29: 1 | GX29: =ROUND(HC29*I29,2) -> 0 | HA29: 0 | HB29: 0 | HC29: =GV29*GW29 -> 0 | HS29: 0 | IK29: 0
A30: 17 | B30: 1 | C30: =ROW(SmtRes!A8) -> 8 | D30: =ROW(EtalonRes!A8) -> 8 | E30: 2 | F30: 4.10-134-7 | G30: Монтаж антенны дополнительной для приема ТВ на ранее установленной опоре, с действующими ТВ антеннами / демонтаж антенны | H30: 1 антенна | I30: 1 | J30: 0 | K30: 1 | O30: =ROUND(CP30,2) -> 15.59 | P30: =ROUND((ROUND((AC30*AW30*I30),2)*BC30),2) -> 0 | Q30: =(ROUND((ROUND(((((ET30*1.2)*0.3))*AV30*I30),2)*BB30),2)+ROUND((ROUND(((AE30-(((EU30*1.2)*0.3)))*AV30*I30),2)*BS30),2)) -> 0 | R30: =(ROUND((ROUND(((((EU30*1.2)*0.3))*AV30*I30),2)*BS30),2)+ROUND((ROUND(((AE30-(((EU30*1.2)*0.3)))*AV30*I30),2)*BS30),2)) -> 0 | S30: =ROUND((ROUND((AF30*AV30*I30),2)*BA30),2) -> 15.59 | T30: =ROUND(CU30*I30,2) -> 0 | U30: =CV30*I30 -> 1.0839564 | V30: =CW30*I30 -> 0 | W30: =ROUND(CX30*I30,2) -> 0 | X30: =(ROUND((((S30+ROUND((ROUND(((((EU30*1.2)*0.3))*AV30*I30),2)*BS30),2))*AT30)/100),2)+ROUND(((ROUND((ROUND(((AE30-(((EU30*1.2)*0.3)))*AV30*I30),2)*BS30),2)*AT30)/100),2)) -> 14.81 | Y30: =(ROUND((((S30+ROUND((ROUND(((((EU30*1.2)*0.3))*AV30*I30),2)*BS30),2))*AU30)/100),2)+ROUND(((ROUND((ROUND(((AE30-(((EU30*1.2)*0.3)))*AV30*I30),2)*BS30),2)*AU30)/100),2)) -> 8.26 | AA30: 55942966 | AB30: =ROUND((AC30+AD30+AF30),6) -> 14.346 | AC30: =ROUND((((ES30*1)*0)),6) -> 0 | AD30: =ROUND((((((ET30*1.2)*0.3))-(((EU30*1.2)*0.3)))+AE30),6) -> 0 | AE30: =ROUND((((EU30*1.2)*0.3)),6) -> 0 | AF30: =ROUND((((EV30*1.2)*0.3)),6) -> 14.346 | AG30: =ROUND((AP30),6) -> 0 | AH30: =(((EW30*1.2)*0.3)) -> 0.9972 | AI30: =(((EX30*1.2)*0.3)) -> 0 | AJ30: =(AS30) -> 0 | AK30: 40.03 | AL30: 0.18 | AM30: 0 | AN30: 0 | AO30: 39.85 | AP30: 0 | AQ30: 2.77 | AR30: 0 | AS30: 0 | AT30: 95 | AU30: 53 | AV30: 1.087 | AW30: 1 | AZ30: 1 | BA30: 1 | BB30: 1 | BC30: 1 | BH30: 0 | BI30: 2 | BJ30: ТСН-2001.4 Доп. 81, Сб. 10, т. 134, поз. 7 | BM30: 69 | BN30: 0 | BO30: 4.10-134-7 | BP30: 1 | BQ30: 40 | BR30: 0 | BS30: 1 | BT30: 1 | BU30: 1 | BV30: 1 | BW30: 1 | BX30: 1 | BZ30: 95 | CA30: 53 | CE30: 1566 | CF30: 0 | CG30: 0 | CM30: 0 | CN30: Поправка: Гл.12.Прил.8.п.8. 3_12.00.01.11.001 Наименование: При наличии напряженных и стесненных условий производства работ (стесненность, сложность складирования и транспортной логистики и т.п.) для объектов, расположенных в пределах круговой магистральной системы улиц "Садовое кольцо" города Москвы Поправка: Гл.4.Прил.2.2.п.2.2.29_04.00.01.35.003 Наименование: При демонтаже оборудования, предназначенного в лом | CO30: 0 | CP30: =(P30+Q30+S30) -> 15.59 | CQ30: =ROUND((ROUND((AC30*AW30*1),2)*BC30),2) -> 0 | CR30: =(ROUND((ROUND(((((ET30*1.2)*0.3))*AV30*1),2)*BB30),2)+ROUND((ROUND(((AE30-(((EU30*1.2)*0.3)))*AV30*1),2)*BS30),2)) -> 0 | CS30: =(ROUND((ROUND(((((EU30*1.2)*0.3))*AV30*1),2)*BS30),2)+ROUND((ROUND(((AE30-(((EU30*1.2)*0.3)))*AV30*1),2)*BS30),2)) -> 0 | CT30: =ROUND((ROUND((AF30*AV30*1),2)*BA30),2) -> 15.59 | CU30: =AG30 -> 0 | CV30: =(AH30*AV30) -> 1.0839564 | CW30: =AI30 -> 0 | CX30: =AJ30 -> 0 | CY30: =(ROUND((((S30+ROUND((ROUND(((((EU30*1.2)*0.3))*AV30*1),2)*BS30),2))*AT30)/100),2)+ROUND(((ROUND((ROUND(((AE30-(((EU30*1.2)*0.3)))*AV30*1),2)*BS30),2)*AT30)/100),2)) -> 14.81 | CZ30: =(ROUND((((S30+ROUND((ROUND(((((EU30*1.2)*0.3))*AV30*1),2)*BS30),2))*AU30)/100),2)+ROUND(((ROUND((ROUND(((AE30-(((EU30*1.2)*0.3)))*AV30*1),2)*BS30),2)*AU30)/100),2)) -> 8.26 | DB30: 5 | DD30: *1)*0 | DE30: *1,2)*0,3 | DF30: *1,2)*0,3 | DG30: *1,2)*0,3 | DI30: *1,2)*0,3 | DJ30: *1,2)*0,3 | DN30: 0 | DO30: 0 | DP30: 1 | DQ30: 1 | DU30: 1013 | DV30: 1 антенна | DW30: 1 антенна | DX30: 1 | EE30: 55393973 | EF30: 40 | EG30: Монтаж оборудования | EH30: 0 | EJ30: 2 | EK30: 69 | EL30: ТСН-2001.4-10. Монтаж радиотелевизионного и электронного оборудования | EM30: ТСН-2001.4-10-2 | EO30: Поправка: Гл.12.Прил.8.п.8. 3_12.00.01.11.001 Поправка: Гл.4.Прил.2.2.п.2.2.29_04.00.01.35.003 | EQ30: 0 | ER30: 40.03 | ES30: 0.18 | ET30: 0 | EU30: 0 | EV30: 39.85 | EW30: 2.77 | EX30: 0 | EY30: 0 | FQ30: 0 | FR30: 0 | FS30: 0 | FX30: 95 | FY30: 53 | GD30: 1 | GF30: 338733022 | GG30: 2 | GH30: 1 | GI30: 2 | GJ30: 0 | GK30: 0 | GL30: =ROUND(IF(AND(BH30=3,BI30=3,FS30<>0),P30,0),2) -> 0 | GM30: =ROUND(O30+X30+Y30,2)+GX30 -> 38.66 | GN30: =IF(OR(BI30=0,BI30=1),GM30-GX30,0) -> 0 | GO30: =IF(BI30=2,GM30-GX30,0) -> 38.66 | GP30: =IF(BI30=4,GM30-GX30,0) -> 0 | GR30: 0 | GS30: 3 | GT30: 0 | GV30: =ROUND((GT30),6) -> 0 | GW30: 1 | GX30: =ROUND(HC30*I30,2) -> 0 | HA30: 0 | HB30: 0 | HC30: =GV30*GW30 -> 0 | HS30: 0 | IK30: 0
A31: 17 | B31: 1 | C31: =ROW(SmtRes!A10) -> 10 | D31: =ROW(EtalonRes!A10) -> 10 | E31: 2 | F31: 4.10-134-7 | G31: Монтаж антенны дополнительной для приема ТВ на ранее установленной опоре, с действующими ТВ антеннами / демонтаж антенны | H31: 1 антенна | I31: 1 | J31: 0 | K31: 1 | O31: =ROUND(CP31,2) -> 878.5 | P31: =ROUND((ROUND((AC31*AW31*I31),2)*BC31),2) -> 0 | Q31: =(ROUND((ROUND(((((ET31*1.2)*0.3))*AV31*I31),2)*BB31),2)+ROUND((ROUND(((AE31-(((EU31*1.2)*0.3)))*AV31*I31),2)*BS31),2)) -> 0 | R31: =(ROUND((ROUND(((((EU31*1.2)*0.3))*AV31*I31),2)*BS31),2)+ROUND((ROUND(((AE31-(((EU31*1.2)*0.3)))*AV31*I31),2)*BS31),2)) -> 0 | S31: =ROUND((ROUND((AF31*AV31*I31),2)*BA31),2) -> 878.5 | T31: =ROUND(CU31*I31,2) -> 0 | U31: =CV31*I31 -> 1.0839564 | V31: =CW31*I31 -> 0 | W31: =ROUND(CX31*I31,2) -> 0 | X31: =(ROUND((((S31+ROUND((ROUND(((((EU31*1.2)*0.3))*AV31*I31),2)*BS31),2))*AT31)/100),2)+ROUND(((ROUND((ROUND(((AE31-(((EU31*1.2)*0.3)))*AV31*I31),2)*BS31),2)*AT31)/100),2)) -> 834.58 | Y31: =(ROUND((((S31+ROUND((ROUND(((((EU31*1.2)*0.3))*AV31*I31),2)*BS31),2))*AU31)/100),2)+ROUND(((ROUND((ROUND(((AE31-(((EU31*1.2)*0.3)))*AV31*I31),2)*BS31),2)*AU31)/100),2)) -> 465.61 | AA31: 55942968 | AB31: =ROUND((AC31+AD31+AF31),6) -> 14.346 | AC31: =ROUND((((ES31*1)*0)),6) -> 0 | AD31: =ROUND((((((ET31*1.2)*0.3))-(((EU31*1.2)*0.3)))+AE31),6) -> 0 | AE31: =ROUND((((EU31*1.2)*0.3)),6) -> 0 | AF31: =ROUND((((EV31*1.2)*0.3)),6) -> 14.346 | AG31: =ROUND((AP31),6) -> 0 | AH31: =(((EW31*1.2)*0.3)) -> 0.9972 | AI31: =(((EX31*1.2)*0.3)) -> 0 | AJ31: =(AS31) -> 0 | AK31: 40.03 | AL31: 0.18 | AM31: 0 | AN31: 0 | AO31: 39.85 | AP31: 0 | AQ31: 2.77 | AR31: 0 | AS31: 0 | AT31: 95 | AU31: 53 | AV31: 1.087 | AW31: 1 | AZ31: 1 | BA31: 56.35 | BB31: 1 | BC31: 5.61 | BH31: 0 | BI31: 2 | BJ31: ТСН-2001.4 Доп. 81, Сб. 10, т. 134, поз. 7 | BM31: 69 | BN31: 0 | BO31: 4.10-134-7 | BP31: 1 | BQ31: 40 | BR31: 0 | BS31: 56.35 | BT31: 1 | BU31: 1 | BV31: 1 | BW31: 1 | BX31: 1 | BZ31: 95 | CA31: 53 | CE31: 1566 | CF31: 0 | CG31: 0 | CM31: 0 | CN31: Поправка: Гл.12.Прил.8.п.8. 3_12.00.01.11.001 Наименование: При наличии напряженных и стесненных условий производства работ (стесненность, сложность складирования и транспортной логистики и т.п.) для объектов, расположенных в пределах круговой магистральной системы улиц "Садовое кольцо" города Москвы Поправка: Гл.4.Прил.2.2.п.2.2.29_04.00.01.35.003 Наименование: При демонтаже оборудования, предназначенного в лом | CO31: 0 | CP31: =(P31+Q31+S31) -> 878.5 | CQ31: =ROUND((ROUND((AC31*AW31*1),2)*BC31),2) -> 0 | CR31: =(ROUND((ROUND(((((ET31*1.2)*0.3))*AV31*1),2)*BB31),2)+ROUND((ROUND(((AE31-(((EU31*1.2)*0.3)))*AV31*1),2)*BS31),2)) -> 0 | CS31: =(ROUND((ROUND(((((EU31*1.2)*0.3))*AV31*1),2)*BS31),2)+ROUND((ROUND(((AE31-(((EU31*1.2)*0.3)))*AV31*1),2)*BS31),2)) -> 0 | CT31: =ROUND((ROUND((AF31*AV31*1),2)*BA31),2) -> 878.5 | CU31: =AG31 -> 0 | CV31: =(AH31*AV31) -> 1.0839564 | CW31: =AI31 -> 0 | CX31: =AJ31 -> 0 | CY31: =(ROUND((((S31+ROUND((ROUND(((((EU31*1.2)*0.3))*AV31*1),2)*BS31),2))*AT31)/100),2)+ROUND(((ROUND((ROUND(((AE31-(((EU31*1.2)*0.3)))*AV31*1),2)*BS31),2)*AT31)/100),2)) -> 834.58 | CZ31: =(ROUND((((S31+ROUND((ROUND(((((EU31*1.2)*0.3))*AV31*1),2)*BS31),2))*AU31)/100),2)+ROUND(((ROUND((ROUND(((AE31-(((EU31*1.2)*0.3)))*AV31*1),2)*BS31),2)*AU31)/100),2)) -> 465.61 | DB31: 7 | DD31: *1)*0 | DE31: *1,2)*0,3 | DF31: *1,2)*0,3 | DG31: *1,2)*0,3 | DI31: *1,2)*0,3 | DJ31: *1,2)*0,3 | DN31: 0 | DO31: 0 | DP31: 1 | DQ31: 1 | DU31: 1013 | DV31: 1 антенна | DW31: 1 антенна | DX31: 1 | EE31: 55393973 | EF31: 40 | EG31: Монтаж оборудования | EH31: 0 | EJ31: 2 | EK31: 69 | EL31: ТСН-2001.4-10. Монтаж радиотелевизионного и электронного оборудования | EM31: ТСН-2001.4-10-2 | EO31: Поправка: Гл.12.Прил.8.п.8. 3_12.00.01.11.001 Поправка: Гл.4.Прил.2.2.п.2.2.29_04.00.01.35.003 | EQ31: 0 | ER31: 40.03 | ES31: 0.18 | ET31: 0 | EU31: 0 | EV31: 39.85 | EW31: 2.77 | EX31: 0 | EY31: 0 | FQ31: 0 | FR31: 0 | FS31: 0 | FX31: 95 | FY31: 53 | GD31: 1 | GF31: 338733022 | GG31: 2 | GH31: 1 | GI31: 2 | GJ31: 0 | GK31: 0 | GL31: =ROUND(IF(AND(BH31=3,BI31=3,FS31<>0),P31,0),2) -> 0 | GM31: =ROUND(O31+X31+Y31,2)+GX31 -> 2178.69 | GN31: =IF(OR(BI31=0,BI31=1),GM31-GX31,0) -> 0 | GO31: =IF(BI31=2,GM31-GX31,0) -> 2178.69 | GP31: =IF(BI31=4,GM31-GX31,0) -> 0 | GR31: 0 | GS31: 3 | GT31: 0 | GV31: =ROUND((GT31),6) -> 0 | GW31: 1 | GX31: =ROUND(HC31*I31,2) -> 0 | HA31: 0 | HB31: 0 | HC31: =GV31*GW31 -> 0 | HS31: 0 | IK31: 0
A32: 17 | B32: 1 | C32: =ROW(SmtRes!A12) -> 12 | D32: =ROW(EtalonRes!A12) -> 12 | E32: 3 | F32: 4.10-136-1 | G32: Монтаж коробки телевизионной (ответвители, разветвители магистральные, домовые, абонентские), УСС, / демонтаж модуля грозозащиты для антенны | H32: 1 ШТ. | I32: 1 | J32: 0 | K32: 1 | O32: =ROUND(CP32,2) -> 4.31 | P32: =ROUND((ROUND((AC32*AW32*I32),2)*BC32),2) -> 0 | Q32: =(ROUND((ROUND(((((ET32*1.2)*0.3))*AV32*I32),2)*BB32),2)+ROUND((ROUND(((AE32-(((EU32*1.2)*0.3)))*AV32*I32),2)*BS32),2)) -> 0 | R32: =(ROUND((ROUND(((((EU32*1.2)*0.3))*AV32*I32),2)*BS32),2)+ROUND((ROUND(((AE32-(((EU32*1.2)*0.3)))*AV32*I32),2)*BS32),2)) -> 0 | S32: =ROUND((ROUND((AF32*AV32*I32),2)*BA32),2) -> 4.31 | T32: =ROUND(CU32*I32,2) -> 0 | U32: =CV32*I32 -> 0.313056 | V32: =CW32*I32 -> 0 | W32: =ROUND(CX32*I32,2) -> 0 | X32: =(ROUND((((S32+ROUND((ROUND(((((EU32*1.2)*0.3))*AV32*I32),2)*BS32),2))*AT32)/100),2)+ROUND(((ROUND((ROUND(((AE32-(((EU32*1.2)*0.3)))*AV32*I32),2)*BS32),2)*AT32)/100),2)) -> 4.09 | Y32: =(ROUND((((S32+ROUND((ROUND(((((EU32*1.2)*0.3))*AV32*I32),2)*BS32),2))*AU32)/100),2)+ROUND(((ROUND((ROUND(((AE32-(((EU32*1.2)*0.3)))*AV32*I32),2)*BS32),2)*AU32)/100),2)) -> 2.28 | AA32: 55942966 | AB32: =ROUND((AC32+AD32+AF32),6) -> 3.9672 | AC32: =ROUND((((ES32*1)*0)),6) -> 0 | AD32: =ROUND((((((ET32*1.2)*0.3))-(((EU32*1.2)*0.3)))+AE32),6) -> 0 | AE32: =ROUND((((EU32*1.2)*0.3)),6) -> 0 | AF32: =ROUND((((EV32*1.2)*0.3)),6) -> 3.9672 | AG32: =ROUND((AP32),6) -> 0 | AH32: =(((EW32*1.2)*0.3)) -> 0.288 | AI32: =(((EX32*1.2)*0.3)) -> 0 | AJ32: =(AS32) -> 0 | AK32: 11.32 | AL32: 0.3 | AM32: 0 | AN32: 0 | AO32: 11.02 | AP32: 0 | AQ32: 0.8 | AR32: 0 | AS32: 0 | AT32: 95 | AU32: 53 | AV32: 1.087 | AW32: 1 | AZ32: 1 | BA32: 1 | BB32: 1 | BC32: 1 | BH32: 0 | BI32: 2 | BJ32: ТСН-2001.4 Доп. 81, Сб. 10, т. 136, поз. 1 | BM32: 69 | BN32: 0 | BO32: 4.10-136-1 | BP32: 1 | BQ32: 40 | BR32: 0 | BS32: 1 | BT32: 1 | BU32: 1 | BV32: 1 | BW32: 1 | BX32: 1 | BZ32: 95 | CA32: 53 | CE32: 1566 | CF32: 0 | CG32: 0 | CM32: 0 | CN32: Поправка: Гл.12.Прил.8.п.8. 3_12.00.01.11.001 Наименование: При наличии напряженных и стесненных условий производства работ (стесненность, сложность складирования и транспортной логистики и т.п.) для объектов, расположенных в пределах круговой магистральной системы улиц "Садовое кольцо" города Москвы Поправка: Гл.4.Прил.2.2.п.2.2.29_04.00.01.35.003 Наименование: При демонтаже оборудования, предназначенного в лом | CO32: 0 | CP32: =(P32+Q32+S32) -> 4.31 | CQ32: =ROUND((ROUND((AC32*AW32*1),2)*BC32),2) -> 0 | CR32: =(ROUND((ROUND(((((ET32*1.2)*0.3))*AV32*1),2)*BB32),2)+ROUND((ROUND(((AE32-(((EU32*1.2)*0.3)))*AV32*1),2)*BS32),2)) -> 0 | CS32: =(ROUND((ROUND(((((EU32*1.2)*0.3))*AV32*1),2)*BS32),2)+ROUND((ROUND(((AE32-(((EU32*1.2)*0.3)))*AV32*1),2)*BS32),2)) -> 0 | CT32: =ROUND((ROUND((AF32*AV32*1),2)*BA32),2) -> 4.31 | CU32: =AG32 -> 0 | CV32: =(AH32*AV32) -> 0.313056 | CW32: =AI32 -> 0 | CX32: =AJ32 -> 0 | CY32: =(ROUND((((S32+ROUND((ROUND(((((EU32*1.2)*0.3))*AV32*1),2)*BS32),2))*AT32)/100),2)+ROUND(((ROUND((ROUND(((AE32-(((EU32*1.2)*0.3)))*AV32*1),2)*BS32),2)*AT32)/100),2)) -> 4.09 | CZ32: =(ROUND((((S32+ROUND((ROUND(((((EU32*1.2)*0.3))*AV32*1),2)*BS32),2))*AU32)/100),2)+ROUND(((ROUND((ROUND(((AE32-(((EU32*1.2)*0.3)))*AV32*1),2)*BS32),2)*AU32)/100),2)) -> 2.28 | DB32: 9 | DD32: *1)*0 | DE32: *1,2)*0,3 | DF32: *1,2)*0,3 | DG32: *1,2)*0,3 | DI32: *1,2)*0,3 | DJ32: *1,2)*0,3 | DN32: 0 | DO32: 0 | DP32: 1 | DQ32: 1 | DU32: 1013 | DV32: 1 ШТ. | DW32: 1 ШТ. | DX32: 1 | EE32: 55393973 | EF32: 40 | EG32: Монтаж оборудования | EH32: 0 | EJ32: 2 | EK32: 69 | EL32: ТСН-2001.4-10. Монтаж радиотелевизионного и электронного оборудования | EM32: ТСН-2001.4-10-2 | EO32: Поправка: Гл.12.Прил.8.п.8. 3_12.00.01.11.001 Поправка: Гл.4.Прил.2.2.п.2.2.29_04.00.01.35.003 | EQ32: 0 | ER32: 11.32 | ES32: 0.3 | ET32: 0 | EU32: 0 | EV32: 11.02 | EW32: 0.8 | EX32: 0 | EY32: 0 | FQ32: 0 | FR32: 0 | FS32: 0 | FX32: 95 | FY32: 53 | GD32: 1 | GF32: -1909085749 | GG32: 2 | GH32: 1 | GI32: 2 | GJ32: 0 | GK32: 0 | GL32: =ROUND(IF(AND(BH32=3,BI32=3,FS32<>0),P32,0),2) -> 0 | GM32: =ROUND(O32+X32+Y32,2)+GX32 -> 10.68 | GN32: =IF(OR(BI32=0,BI32=1),GM32-GX32,0) -> 0 | GO32: =IF(BI32=2,GM32-GX32,0) -> 10.68 | GP32: =IF(BI32=4,GM32-GX32,0) -> 0 | GR32: 0 | GS32: 3 | GT32: 0 | GV32: =ROUND((GT32),6) -> 0 | GW32: 1 | GX32: =ROUND(HC32*I32,2) -> 0 | HA32: 0 | HB32: 0 | HC32: =GV32*GW32 -> 0 | HS32: 0 | IK32: 0
A33: 17 | B33: 1 | C33: =ROW(SmtRes!A14) -> 14 | D33: =ROW(EtalonRes!A14) -> 14 | E33: 3 | F33: 4.10-136-1 | G33: Монтаж коробки телевизионной (ответвители, разветвители магистральные, домовые, абонентские), УСС, / демонтаж модуля грозозащиты для антенны | H33: 1 ШТ. | I33: 1 | J33: 0 | K33: 1 | O33: =ROUND(CP33,2) -> 242.87 | P33: =ROUND((ROUND((AC33*AW33*I33),2)*BC33),2) -> 0 | Q33: =(ROUND((ROUND(((((ET33*1.2)*0.3))*AV33*I33),2)*BB33),2)+ROUND((ROUND(((AE33-(((EU33*1.2)*0.3)))*AV33*I33),2)*BS33),2)) -> 0 | R33: =(ROUND((ROUND(((((EU33*1.2)*0.3))*AV33*I33),2)*BS33),2)+ROUND((ROUND(((AE33-(((EU33*1.2)*0.3)))*AV33*I33),2)*BS33),2)) -> 0 | S33: =ROUND((ROUND((AF33*AV33*I33),2)*BA33),2) -> 242.87 | T33: =ROUND(CU33*I33,2) -> 0 | U33: =CV33*I33 -> 0.313056 | V33: =CW33*I33 -> 0 | W33: =ROUND(CX33*I33,2) -> 0 | X33: =(ROUND((((S33+ROUND((ROUND(((((EU33*1.2)*0.3))*AV33*I33),2)*BS33),2))*AT33)/100),2)+ROUND(((ROUND((ROUND(((AE33-(((EU33*1.2)*0.3)))*AV33*I33),2)*BS33),2)*AT33)/100),2)) -> 230.73 | Y33: =(ROUND((((S33+ROUND((ROUND(((((EU33*1.2)*0.3))*AV33*I33),2)*BS33),2))*AU33)/100),2)+ROUND(((ROUND((ROUND(((AE33-(((EU33*1.2)*0.3)))*AV33*I33),2)*BS33),2)*AU33)/100),2)) -> 128.72 | AA33: 55942968 | AB33: =ROUND((AC33+AD33+AF33),6) -> 3.9672 | AC33: =ROUND((((ES33*1)*0)),6) -> 0 | AD33: =ROUND((((((ET33*1.2)*0.3))-(((EU33*1.2)*0.3)))+AE33),6) -> 0 | AE33: =ROUND((((EU33*1.2)*0.3)),6) -> 0 | AF33: =ROUND((((EV33*1.2)*0.3)),6) -> 3.9672 | AG33: =ROUND((AP33),6) -> 0 | AH33: =(((EW33*1.2)*0.3)) -> 0.288 | AI33: =(((EX33*1.2)*0.3)) -> 0 | AJ33: =(AS33) -> 0 | AK33: 11.32 | AL33: 0.3 | AM33: 0 | AN33: 0 | AO33: 11.02 | AP33: 0 | AQ33: 0.8 | AR33: 0 | AS33: 0 | AT33: 95 | AU33: 53 | AV33: 1.087 | AW33: 1 | AZ33: 1 | BA33: 56.35 | BB33: 1 | BC33: 7.37 | BH33: 0 | BI33: 2 | BJ33: ТСН-2001.4 Доп. 81, Сб. 10, т. 136, поз. 1 | BM33: 69 | BN33: 0 | BO33: 4.10-136-1 | BP33: 1 | BQ33: 40 | BR33: 0 | BS33: 56.35 | BT33: 1 | BU33: 1 | BV33: 1 | BW33: 1 | BX33: 1 | BZ33: 95 | CA33: 53 | CE33: 1566 | CF33: 0 | CG33: 0 | CM33: 0 | CN33: Поправка: Гл.12.Прил.8.п.8. 3_12.00.01.11.001 Наименование: При наличии напряженных и стесненных условий производства работ (стесненность, сложность складирования и транспортной логистики и т.п.) для объектов, расположенных в пределах круговой магистральной системы улиц "Садовое кольцо" города Москвы Поправка: Гл.4.Прил.2.2.п.2.2.29_04.00.01.35.003 Наименование: При демонтаже оборудования, предназначенного в лом | CO33: 0 | CP33: =(P33+Q33+S33) -> 242.87 | CQ33: =ROUND((ROUND((AC33*AW33*1),2)*BC33),2) -> 0 | CR33: =(ROUND((ROUND(((((ET33*1.2)*0.3))*AV33*1),2)*BB33),2)+ROUND((ROUND(((AE33-(((EU33*1.2)*0.3)))*AV33*1),2)*BS33),2)) -> 0 | CS33: =(ROUND((ROUND(((((EU33*1.2)*0.3))*AV33*1),2)*BS33),2)+ROUND((ROUND(((AE33-(((EU33*1.2)*0.3)))*AV33*1),2)*BS33),2)) -> 0 | CT33: =ROUND((ROUND((AF33*AV33*1),2)*BA33),2) -> 242.87 | CU33: =AG33 -> 0 | CV33: =(AH33*AV33) -> 0.313056 | CW33: =AI33 -> 0 | CX33: =AJ33 -> 0 | CY33: =(ROUND((((S33+ROUND((ROUND(((((EU33*1.2)*0.3))*AV33*1),2)*BS33),2))*AT33)/100),2)+ROUND(((ROUND((ROUND(((AE33-(((EU33*1.2)*0.3)))*AV33*1),2)*BS33),2)*AT33)/100),2)) -> 230.73 | CZ33: =(ROUND((((S33+ROUND((ROUND(((((EU33*1.2)*0.3))*AV33*1),2)*BS33),2))*AU33)/100),2)+ROUND(((ROUND((ROUND(((AE33-(((EU33*1.2)*0.3)))*AV33*1),2)*BS33),2)*AU33)/100),2)) -> 128.72 | DB33: 11 | DD33: *1)*0 | DE33: *1,2)*0,3 | DF33: *1,2)*0,3 | DG33: *1,2)*0,3 | DI33: *1,2)*0,3 | DJ33: *1,2)*0,3 | DN33: 0 | DO33: 0 | DP33: 1 | DQ33: 1 | DU33: 1013 | DV33: 1 ШТ. | DW33: 1 ШТ. | DX33: 1 | EE33: 55393973 | EF33: 40 | EG33: Монтаж оборудования | EH33: 0 | EJ33: 2 | EK33: 69 | EL33: ТСН-2001.4-10. Монтаж радиотелевизионного и электронного оборудования | EM33: ТСН-2001.4-10-2 | EO33: Поправка: Гл.12.Прил.8.п.8. 3_12.00.01.11.001 Поправка: Гл.4.Прил.2.2.п.2.2.29_04.00.01.35.003 | EQ33: 0 | ER33: 11.32 | ES33: 0.3 | ET33: 0 | EU33: 0 | EV33: 11.02 | EW33: 0.8 | EX33: 0 | EY33: 0 | FQ33: 0 | FR33: 0 | FS33: 0 | FX33: 95 | FY33: 53 | GD33: 1 | GF33: -1909085749 | GG33: 2 | GH33: 1 | GI33: 2 | GJ33: 0 | GK33: 0 | GL33: =ROUND(IF(AND(BH33=3,BI33=3,FS33<>0),P33,0),2) -> 0 | GM33: =ROUND(O33+X33+Y33,2)+GX33 -> 602.32 | GN33: =IF(OR(BI33=0,BI33=1),GM33-GX33,0) -> 0 | GO33: =IF(BI33=2,GM33-GX33,0) -> 602.32 | GP33: =IF(BI33=4,GM33-GX33,0) -> 0 | GR33: 0 | GS33: 3 | GT33: 0 | GV33: =ROUND((GT33),6) -> 0 | GW33: 1 | GX33: =ROUND(HC33*I33,2) -> 0 | HA33: 0 | HB33: 0 | HC33: =GV33*GW33 -> 0 | HS33: 0 | IK33: 0
A34: 17 | B34: 1 | C34: =ROW(SmtRes!A18) -> 18 | D34: =ROW(EtalonRes!A18) -> 18 | E34: 4 | F34: 4.10-86-1 | G34: Монтаж электрочасов вторичных для помещений односторонних на стене / демонтаж часов повторителей | H34: 1 ШТ. | I34: 3 | J34: 0 | K34: 3 | O34: =ROUND(CP34,2) -> 26.91 | P34: =ROUND((ROUND((AC34*AW34*I34),2)*BC34),2) -> 0 | Q34: =(ROUND((ROUND(((((ET34*1.2)*0.3))*AV34*I34),2)*BB34),2)+ROUND((ROUND(((AE34-(((EU34*1.2)*0.3)))*AV34*I34),2)*BS34),2)) -> 0 | R34: =(ROUND((ROUND(((((EU34*1.2)*0.3))*AV34*I34),2)*BS34),2)+ROUND((ROUND(((AE34-(((EU34*1.2)*0.3)))*AV34*I34),2)*BS34),2)) -> 0 | S34: =ROUND((ROUND((AF34*AV34*I34),2)*BA34),2) -> 26.91 | T34: =ROUND(CU34*I34,2) -> 0 | U34: =CV34*I34 -> 2.26152 | V34: =CW34*I34 -> 0 | W34: =ROUND(CX34*I34,2) -> 0 | X34: =(ROUND((((S34+ROUND((ROUND(((((EU34*1.2)*0.3))*AV34*I34),2)*BS34),2))*AT34)/100),2)+ROUND(((ROUND((ROUND(((AE34-(((EU34*1.2)*0.3)))*AV34*I34),2)*BS34),2)*AT34)/100),2)) -> 24.22 | Y34: =(ROUND((((S34+ROUND((ROUND(((((EU34*1.2)*0.3))*AV34*I34),2)*BS34),2))*AU34)/100),2)+ROUND(((ROUND((ROUND(((AE34-(((EU34*1.2)*0.3)))*AV34*I34),2)*BS34),2)*AU34)/100),2)) -> 12.38 | AA34: 55942966 | AB34: =ROUND((AC34+AD34+AF34),6) -> 8.568 | AC34: =ROUND((((ES34*1)*0)),6) -> 0 | AD34: =ROUND((((((ET34*1.2)*0.3))-(((EU34*1.2)*0.3)))+AE34),6) -> 0 | AE34: =ROUND((((EU34*1.2)*0.3)),6) -> 0 | AF34: =ROUND((((EV34*1.2)*0.3)),6) -> 8.568 | AG34: =ROUND((AP34),6) -> 0 | AH34: =(((EW34*1.2)*0.3)) -> 0.72 | AI34: =(((EX34*1.2)*0.3)) -> 0 | AJ34: =(AS34) -> 0 | AK34: 24.38 | AL34: 0.58 | AM34: 0 | AN34: 0 | AO34: 23.8 | AP34: 0 | AQ34: 2 | AR34: 0 | AS34: 0 | AT34: 90 | AU34: 46 | AV34: 1.047 | AW34: 1 | AZ34: 1 | BA34: 1 | BB34: 1 | BC34: 1 | BH34: 0 | BI34: 2 | BJ34: ТСН-2001.4 Доп. 81, Сб. 10, т. 86, поз. 1 | BM34: 68 | BN34: 0 | BO34: 4.10-86-1 | BP34: 1 | BQ34: 40 | BR34: 0 | BS34: 1 | BT34: 1 | BU34: 1 | BV34: 1 | BW34: 1 | BX34: 1 | BZ34: 90 | CA34: 46 | CE34: 1566 | CF34: 0 | CG34: 0 | CM34: 0 | CN34: Поправка: Гл.12.Прил.8.п.8. 3_12.00.01.11.001 Наименование: При наличии напряженных и стесненных условий производства работ (стесненность, сложность складирования и транспортной логистики и т.п.) для объектов, расположенных в пределах круговой магистральной системы улиц "Садовое кольцо" города Москвы Поправка: Гл.4.Прил.2.2.п.2.2.29_04.00.01.35.003 Наименование: При демонтаже оборудования, предназначенного в лом | CO34: 0 | CP34: =(P34+Q34+S34) -> 26.91 | CQ34: =ROUND((ROUND((AC34*AW34*1),2)*BC34),2) -> 0 | CR34: =(ROUND((ROUND(((((ET34*1.2)*0.3))*AV34*1),2)*BB34),2)+ROUND((ROUND(((AE34-(((EU34*1.2)*0.3)))*AV34*1),2)*BS34),2)) -> 0 | CS34: =(ROUND((ROUND(((((EU34*1.2)*0.3))*AV34*1),2)*BS34),2)+ROUND((ROUND(((AE34-(((EU34*1.2)*0.3)))*AV34*1),2)*BS34),2)) -> 0 | CT34: =ROUND((ROUND((AF34*AV34*1),2)*BA34),2) -> 8.97 | CU34: =AG34 -> 0 | CV34: =(AH34*AV34) -> 0.75384 | CW34: =AI34 -> 0 | CX34: =AJ34 -> 0 | CY34: =(ROUND((((S34+ROUND((ROUND(((((EU34*1.2)*0.3))*AV34*1),2)*BS34),2))*AT34)/100),2)+ROUND(((ROUND((ROUND(((AE34-(((EU34*1.2)*0.3)))*AV34*1),2)*BS34),2)*AT34)/100),2)) -> 24.22 | CZ34: =(ROUND((((S34+ROUND((ROUND(((((EU34*1.2)*0.3))*AV34*1),2)*BS34),2))*AU34)/100),2)+ROUND(((ROUND((ROUND(((AE34-(((EU34*1.2)*0.3)))*AV34*1),2)*BS34),2)*AU34)/100),2)) -> 12.38 | DB34: 13 | DD34: *1)*0 | DE34: *1,2)*0,3 | DF34: *1,2)*0,3 | DG34: *1,2)*0,3 | DI34: *1,2)*0,3 | DJ34: *1,2)*0,3 | DN34: 0 | DO34: 0 | DP34: 1 | DQ34: 1 | DU34: 1013 | DV34: 1 ШТ. | DW34: 1 ШТ. | DX34: 1 | EE34: 55393972 | EF34: 40 | EG34: Монтаж оборудования | EH34: 0 | EJ34: 2 | EK34: 68 | EL34: ТСН-2001.4-10. Прокладка и монтаж сетей связи | EM34: ТСН-2001.4-10-1 | EO34: Поправка: Гл.12.Прил.8.п.8. 3_12.00.01.11.001 Поправка: Гл.4.Прил.2.2.п.2.2.29_04.00.01.35.003 | EQ34: 0 | ER34: 24.38 | ES34: 0.58 | ET34: 0 | EU34: 0 | EV34: 23.8 | EW34: 2 | EX34: 0 | EY34: 0 | FQ34: 0 | FR34: 0 | FS34: 0 | FX34: 90 | FY34: 46 | GD34: 1 | GF34: -1108641318 | GG34: 2 | GH34: 1 | GI34: 2 | GJ34: 0 | GK34: 0 | GL34: =ROUND(IF(AND(BH34=3,BI34=3,FS34<>0),P34,0),2) -> 0 | GM34: =ROUND(O34+X34+Y34,2)+GX34 -> 63.51 | GN34: =IF(OR(BI34=0,BI34=1),GM34-GX34,0) -> 0 | GO34: =IF(BI34=2,GM34-GX34,0) -> 63.51 | GP34: =IF(BI34=4,GM34-GX34,0) -> 0 | GR34: 0 | GS34: 3 | GT34: 0 | GV34: =ROUND((GT34),6) -> 0 | GW34: 1 | GX34: =ROUND(HC34*I34,2) -> 0 | HA34: 0 | HB34: 0 | HC34: =GV34*GW34 -> 0 | HS34: 0 | IK34: 0
A35: 17 | B35: 1 | C35: =ROW(SmtRes!A22) -> 22 | D35: =ROW(EtalonRes!A22) -> 22 | E35: 4 | F35: 4.10-86-1 | G35: Монтаж электрочасов вторичных для помещений односторонних на стене / демонтаж часов повторителей | H35: 1 ШТ. | I35: 3 | J35: 0 | K35: 3 | O35: =ROUND(CP35,2) -> 1516.38 | P35: =ROUND((ROUND((AC35*AW35*I35),2)*BC35),2) -> 0 | Q35: =(ROUND((ROUND(((((ET35*1.2)*0.3))*AV35*I35),2)*BB35),2)+ROUND((ROUND(((AE35-(((EU35*1.2)*0.3)))*AV35*I35),2)*BS35),2)) -> 0 | R35: =(ROUND((ROUND(((((EU35*1.2)*0.3))*AV35*I35),2)*BS35),2)+ROUND((ROUND(((AE35-(((EU35*1.2)*0.3)))*AV35*I35),2)*BS35),2)) -> 0 | S35: =ROUND((ROUND((AF35*AV35*I35),2)*BA35),2) -> 1516.38 | T35: =ROUND(CU35*I35,2) -> 0 | U35: =CV35*I35 -> 2.26152 | V35: =CW35*I35 -> 0 | W35: =ROUND(CX35*I35,2) -> 0 | X35: =(ROUND((((S35+ROUND((ROUND(((((EU35*1.2)*0.3))*AV35*I35),2)*BS35),2))*AT35)/100),2)+ROUND(((ROUND((ROUND(((AE35-(((EU35*1.2)*0.3)))*AV35*I35),2)*BS35),2)*AT35)/100),2)) -> 1364.74 | Y35: =(ROUND((((S35+ROUND((ROUND(((((EU35*1.2)*0.3))*AV35*I35),2)*BS35),2))*AU35)/100),2)+ROUND(((ROUND((ROUND(((AE35-(((EU35*1.2)*0.3)))*AV35*I35),2)*BS35),2)*AU35)/100),2)) -> 697.53 | AA35: 55942968 | AB35: =ROUND((AC35+AD35+AF35),6) -> 8.568 | AC35: =ROUND((((ES35*1)*0)),6) -> 0 | AD35: =ROUND((((((ET35*1.2)*0.3))-(((EU35*1.2)*0.3)))+AE35),6) -> 0 | AE35: =ROUND((((EU35*1.2)*0.3)),6) -> 0 | AF35: =ROUND((((EV35*1.2)*0.3)),6) -> 8.568 | AG35: =ROUND((AP35),6) -> 0 | AH35: =(((EW35*1.2)*0.3)) -> 0.72 | AI35: =(((EX35*1.2)*0.3)) -> 0 | AJ35: =(AS35) -> 0 | AK35: 24.38 | AL35: 0.58 | AM35: 0 | AN35: 0 | AO35: 23.8 | AP35: 0 | AQ35: 2 | AR35: 0 | AS35: 0 | AT35: 90 | AU35: 46 | AV35: 1.047 | AW35: 1 | AZ35: 1 | BA35: 56.35 | BB35: 1 | BC35: 7.03 | BH35: 0 | BI35: 2 | BJ35: ТСН-2001.4 Доп. 81, Сб. 10, т. 86, поз. 1 | BM35: 68 | BN35: 0 | BO35: 4.10-86-1 | BP35: 1 | BQ35: 40 | BR35: 0 | BS35: 56.35 | BT35: 1 | BU35: 1 | BV35: 1 | BW35: 1 | BX35: 1 | BZ35: 90 | CA35: 46 | CE35: 1566 | CF35: 0 | CG35: 0 | CM35: 0 | CN35: Поправка: Гл.12.Прил.8.п.8. 3_12.00.01.11.001 Наименование: При наличии напряженных и стесненных условий производства работ (стесненность, сложность складирования и транспортной логистики и т.п.) для объектов, расположенных в пределах круговой магистральной системы улиц "Садовое кольцо" города Москвы Поправка: Гл.4.Прил.2.2.п.2.2.29_04.00.01.35.003 Наименование: При демонтаже оборудования, предназначенного в лом | CO35: 0 | CP35: =(P35+Q35+S35) -> 1516.38 | CQ35: =ROUND((ROUND((AC35*AW35*1),2)*BC35),2) -> 0 | CR35: =(ROUND((ROUND(((((ET35*1.2)*0.3))*AV35*1),2)*BB35),2)+ROUND((ROUND(((AE35-(((EU35*1.2)*0.3)))*AV35*1),2)*BS35),2)) -> 0 | CS35: =(ROUND((ROUND(((((EU35*1.2)*0.3))*AV35*1),2)*BS35),2)+ROUND((ROUND(((AE35-(((EU35*1.2)*0.3)))*AV35*1),2)*BS35),2)) -> 0 | CT35: =ROUND((ROUND((AF35*AV35*1),2)*BA35),2) -> 505.46 | CU35: =AG35 -> 0 | CV35: =(AH35*AV35) -> 0.75384 | CW35: =AI35 -> 0 | CX35: =AJ35 -> 0 | CY35: =(ROUND((((S35+ROUND((ROUND(((((EU35*1.2)*0.3))*AV35*1),2)*BS35),2))*AT35)/100),2)+ROUND(((ROUND((ROUND(((AE35-(((EU35*1.2)*0.3)))*AV35*1),2)*BS35),2)*AT35)/100),2)) -> 1364.74 | CZ35: =(ROUND((((S35+ROUND((ROUND(((((EU35*1.2)*0.3))*AV35*1),2)*BS35),2))*AU35)/100),2)+ROUND(((ROUND((ROUND(((AE35-(((EU35*1.2)*0.3)))*AV35*1),2)*BS35),2)*AU35)/100),2)) -> 697.53 | DB35: 15 | DD35: *1)*0 | DE35: *1,2)*0,3 | DF35: *1,2)*0,3 | DG35: *1,2)*0,3 | DI35: *1,2)*0,3 | DJ35: *1,2)*0,3 | DN35: 0 | DO35: 0 | DP35: 1 | DQ35: 1 | DU35: 1013 | DV35: 1 ШТ. | DW35: 1 ШТ. | DX35: 1 | EE35: 55393972 | EF35: 40 | EG35: Монтаж оборудования | EH35: 0 | EJ35: 2 | EK35: 68 | EL35: ТСН-2001.4-10. Прокладка и монтаж сетей связи | EM35: ТСН-2001.4-10-1 | EO35: Поправка: Гл.12.Прил.8.п.8. 3_12.00.01.11.001 Поправка: Гл.4.Прил.2.2.п.2.2.29_04.00.01.35.003 | EQ35: 0 | ER35: 24.38 | ES35: 0.58 | ET35: 0 | EU35: 0 | EV35: 23.8 | EW35: 2 | EX35: 0 | EY35: 0 | FQ35: 0 | FR35: 0 | FS35: 0 | FX35: 90 | FY35: 46 | GD35: 1 | GF35: -1108641318 | GG35: 2 | GH35: 1 | GI35: 2 | GJ35: 0 | GK35: 0 | GL35: =ROUND(IF(AND(BH35=3,BI35=3,FS35<>0),P35,0),2) -> 0 | GM35: =ROUND(O35+X35+Y35,2)+GX35 -> 3578.65 | GN35: =IF(OR(BI35=0,BI35=1),GM35-GX35,0) -> 0 | GO35: =IF(BI35=2,GM35-GX35,0) -> 3578.65 | GP35: =IF(BI35=4,GM35-GX35,0) -> 0 | GR35: 0 | GS35: 3 | GT35: 0 | GV35: =ROUND((GT35),6) -> 0 | GW35: 1 | GX35: =ROUND(HC35*I35,2) -> 0 | HA35: 0 | HB35: 0 | HC35: =GV35*GW35 -> 0 | HS35: 0 | IK35: 0
A37: 51 | B37: =B24 -> 1 | C37: =A24 -> 4 | D37: =ROW(A24) -> 24 | F37: =IF(F24<>"",F24,"") -> Новый раздел | G37: =IF(G24<>"",G24,"") -> Демонтажные работы (Письмо от АНО «РГТ» об утверждении объёмов демонтажных работ) | H37: 0 | O37: =ROUND(AB37,2) -> 62.38 | P37: =ROUND(AC37,2) -> 0 | Q37: =ROUND(AD37,2) -> 0 | R37: =ROUND(AE37,2) -> 0 | S37: =ROUND(AF37,2) -> 62.38 | T37: =ROUND(AG37,2) -> 0 | U37: =AH37 -> 4.7892924 | V37: =AI37 -> 0 | W37: =ROUND(AJ37,2) -> 0 | X37: =ROUND(AK37,2) -> 57.13 | Y37: =ROUND(AL37,2) -> 30.08 | AB37: =ROUND(SUMIF(AA28:AA35,"=55942966",O28:O35),2) -> 62.38 | AC37: =ROUND(SUMIF(AA28:AA35,"=55942966",P28:P35),2) -> 0 | AD37: =ROUND(SUMIF(AA28:AA35,"=55942966",Q28:Q35),2) -> 0 | AE37: =ROUND(SUMIF(AA28:AA35,"=55942966",R28:R35),2) -> 0 | AF37: =ROUND(SUMIF(AA28:AA35,"=55942966",S28:S35),2) -> 62.38 | AG37: =ROUND(SUMIF(AA28:AA35,"=55942966",T28:T35),2) -> 0 | AH37: =SUMIF(AA28:AA35,"=55942966",U28:U35) -> 4.7892924 | AI37: =SUMIF(AA28:AA35,"=55942966",V28:V35) -> 0 | AJ37: =ROUND(SUMIF(AA28:AA35,"=55942966",W28:W35),2) -> 0 | AK37: =ROUND(SUMIF(AA28:AA35,"=55942966",X28:X35),2) -> 57.13 | AL37: =ROUND(SUMIF(AA28:AA35,"=55942966",Y28:Y35),2) -> 30.08 | AO37: =ROUND(BX37,2) -> 0 | AP37: =ROUND(BY37,2) -> 0 | AQ37: =ROUND(BZ37,2) -> 0 | AR37: =ROUND(CA37,2) -> 149.59 | AS37: =ROUND(CB37,2) -> 0 | AT37: =ROUND(CC37,2) -> 149.59 | AU37: =ROUND(CD37,2) -> 0 | AV37: =ROUND(CE37,2) -> 0 | ... BD37: =ROUND(CM37,2) -> 0 | BX37: =ROUND(SUMIF(AA28:AA35,"=55942966",FQ28:FQ35),2) -> 0 | BY37: =ROUND(SUMIF(AA28:AA35,"=55942966",FR28:FR35),2) -> 0 | BZ37: =ROUND(SUMIF(AA28:AA35,"=55942966",GL28:GL35),2) -> 0 | CA37: =ROUND(SUMIF(AA28:AA35,"=55942966",GM28:GM35),2) -> 149.59 | CB37: =ROUND(SUMIF(AA28:AA35,"=55942966",GN28:GN35),2) -> 0 | CC37: =ROUND(SUMIF(AA28:AA35,"=55942966",GO28:GO35),2) -> 149.59 | CD37: =ROUND(SUMIF(AA28:AA35,"=55942966",GP28:GP35),2) -> 0 | CE37: =AC37-BX37 -> 0 | CF37: =AC37-BY37 -> 0 | CG37: =BX37-BZ37 -> 0 | CH37: =AC37-BX37-BY37+BZ37 -> 0 | CI37: =BY37-BZ37 -> 0 | CJ37: =ROUND(SUMIF(AA28:AA35,"=55942966",GX28:GX35),2) -> 0 | CK37: =ROUND(SUMIF(AA28:AA35,"=55942966",GY28:GY35),2) -> 0 | CL37: =ROUND(SUMIF(AA28:AA35,"=55942966",GZ28:GZ35),2) -> 0 | CM37: =ROUND(SUMIF(AA28:AA35,"=55942966",HD28:HD35),2) -> 0 | DG37: =ROUND(DT37,2) -> 3515.12 | DH37: =ROUND(DU37,2) -> 0 | DI37: =ROUND(DV37,2) -> 0 | DJ37: =ROUND(DW37,2) -> 0 | DK37: =ROUND(DX37,2) -> 3515.12 | DL37: =ROUND(DY37,2) -> 0 | DM37: =DZ37 -> 4.7892924 | DN37: =EA37 -> 0 | DO37: =ROUND(EB37,2) -> 0 | DP37: =ROUND(EC37,2) -> 3219.68 | DQ37: =ROUND(ED37,2) -> 1695.45 | DT37: =ROUND(SUMIF(AA28:AA35,"=55942968",O28:O35),2) -> 3515.12 | DU37: =ROUND(SUMIF(AA28:AA35,"=55942968",P28:P35),2) -> 0 | DV37: =ROUND(SUMIF(AA28:AA35,"=55942968",Q28:Q35),2) -> 0 | DW37: =ROUND(SUMIF(AA28:AA35,"=55942968",R28:R35),2) -> 0 | DX37: =ROUND(SUMIF(AA28:AA35,"=55942968",S28:S35),2) -> 3515.12 | DY37: =ROUND(SUMIF(AA28:AA35,"=55942968",T28:T35),2) -> 0 | DZ37: =SUMIF(AA28:AA35,"=55942968",U28:U35) -> 4.7892924 | EA37: =SUMIF(AA28:AA35,"=55942968",V28:V35) -> 0 | EB37: =ROUND(SUMIF(AA28:AA35,"=55942968",W28:W35),2) -> 0 | EC37: =ROUND(SUMIF(AA28:AA35,"=55942968",X28:X35),2) -> 3219.68 | ED37: =ROUND(SUMIF(AA28:AA35,"=55942968",Y28:Y35),2) -> 1695.45 | EG37: =ROUND(FP37,2) -> 0 | EH37: =ROUND(FQ37,2) -> 0 | EI37: =ROUND(FR37,2) -> 0 | EJ37: =ROUND(FS37,2) -> 8430.25 | EK37: =ROUND(FT37,2) -> 0 | EL37: =ROUND(FU37,2) -> 8430.25 | EM37: =ROUND(FV37,2) -> 0 | EN37: =ROUND(FW37,2) -> 0 | ... EV37: =ROUND(GE37,2) -> 0 | FP37: =ROUND(SUMIF(AA28:AA35,"=55942968",FQ28:FQ35),2) -> 0 | FQ37: =ROUND(SUMIF(AA28:AA35,"=55942968",FR28:FR35),2) -> 0 | FR37: =ROUND(SUMIF(AA28:AA35,"=55942968",GL28:GL35),2) -> 0 | FS37: =ROUND(SUMIF(AA28:AA35,"=55942968",GM28:GM35),2) -> 8430.25 | FT37: =ROUND(SUMIF(AA28:AA35,"=55942968",GN28:GN35),2) -> 0 | FU37: =ROUND(SUMIF(AA28:AA35,"=55942968",GO28:GO35),2) -> 8430.25 | FV37: =ROUND(SUMIF(AA28:AA35,"=55942968",GP28:GP35),2) -> 0 | FW37: =DU37-FP37 -> 0 | FX37: =DU37-FQ37 -> 0 | FY37: =FP37-FR37 -> 0 | FZ37: =DU37-FP37-FQ37+FR37 -> 0 | GA37: =FQ37-FR37 -> 0 | GB37: =ROUND(SUMIF(AA28:AA35,"=55942968",GX28:GX35),2) -> 0 | GC37: =ROUND(SUMIF(AA28:AA35,"=55942968",GY28:GY35),2) -> 0 | GD37: =ROUND(SUMIF(AA28:AA35,"=55942968",GZ28:GZ35),2) -> 0 | GE37: =ROUND(SUMIF(AA28:AA35,"=55942968",HD28:HD35),2) -> 0 | GX37: 0
A39: 50 | B39: 0 | C39: 0 | D39: 1 | E39: 201 | F39: =ROUND(Source!O37,O39) -> 62.38 | G39: ПЗ | H39: Прямые затраты | K39: 201 | L39: 1 | M39: 3 | O39: 2 | P39: =ROUND(Source!DG37,O39) -> 3515.12 | W39: 62.38 | X39: 1 | Y39: 62.38 | Z39: 3515.12 | AA39: 1 | AB39: 3515.12
A40: 50 | B40: 0 | C40: 0 | D40: 1 | E40: 202 | F40: =ROUND(Source!P37,O40) -> 0 | G40: СтМатОб | H40: Стоимость материальных ресурсов (всего) | K40: 202 | L40: 2 | M40: 3 | O40: 2 | P40: =ROUND(Source!DH37,O40) -> 0 | W40: 0 | X40: 1 | Y40: 0 | Z40: 0 | AA40: 1 | AB40: 0
A41: 50 | B41: 0 | C41: 0 | D41: 1 | E41: 222 | F41: =ROUND(Source!AO37,O41) -> 0 | G41: СтМатОбЗак | H41: Стоимость материалов и оборудования заказчика | K41: 222 | L41: 3 | M41: 3 | O41: 2 | P41: =ROUND(Source!EG37,O41) -> 0 | W41: 0 | X41: 1 | Y41: 0 | Z41: 0 | AA41: 1 | AB41: 0
A42: 50 | B42: 0 | C42: 0 | D42: 1 | E42: 225 | F42: =ROUND(Source!AV37,O42) -> 0 | G42: СтМатОбПод | H42: Стоимость материалов и оборудования подрядчика | K42: 225 | L42: 4 | M42: 3 | O42: 2 | P42: =ROUND(Source!EN37,O42) -> 0 | W42: 0 | X42: 1 | Y42: 0 | Z42: 0 | AA42: 1 | AB42: 0
A43: 50 | B43: 0 | C43: 0 | D43: 1 | E43: 226 | F43: =ROUND(Source!AW37,O43) -> 0 | G43: СтМат | H43: Стоимость материалов (всего) | K43: 226 | L43: 5 | M43: 3 | O43: 2 | P43: =ROUND(Source!EO37,O43) -> 0 | W43: 0 | X43: 1 | Y43: 0 | Z43: 0 | AA43: 1 | AB43: 0
A44: 50 | B44: 0 | C44: 0 | D44: 1 | E44: 227 | F44: =ROUND(Source!AX37,O44) -> 0 | G44: СтМатЗак | H44: Стоимость материалов заказчика | K44: 227 | L44: 6 | M44: 3 | O44: 2 | P44: =ROUND(Source!EP37,O44) -> 0 | W44: 0 | X44: 1 | Y44: 0 | Z44: 0 | AA44: 1 | AB44: 0
A45: 50 | B45: 0 | C45: 0 | D45: 1 | E45: 228 | F45: =ROUND(Source!AY37,O45) -> 0 | G45: СтМатПод | H45: Стоимость материалов подрядчика | K45: 228 | L45: 7 | M45: 3 | O45: 2 | P45: =ROUND(Source!EQ37,O45) -> 0 | W45: 0 | X45: 1 | Y45: 0 | Z45: 0 | AA45: 1 | AB45: 0
A46: 50 | B46: 0 | C46: 0 | D46: 1 | E46: 216 | F46: =ROUND(Source!AP37,O46) -> 0 | G46: Оборуд | H46: Стоимость оборудования (всего) | K46: 216 | L46: 8 | M46: 3 | O46: 2 | P46: =ROUND(Source!EH37,O46) -> 0 | W46: 0 | X46: 1 | Y46: 0 | Z46: 0 | AA46: 1 | AB46: 0
A47: 50 | B47: 0 | C47: 0 | D47: 1 | E47: 223 | F47: =ROUND(Source!AQ37,O47) -> 0 | G47: ОборудЗак | H47: Стоимость оборудования заказчика | K47: 223 | L47: 9 | M47: 3 | O47: 2 | P47: =ROUND(Source!EI37,O47) -> 0 | W47: 0 | X47: 1 | Y47: 0 | Z47: 0 | AA47: 1 | AB47: 0
A48: 50 | B48: 0 | C48: 0 | D48: 1 | E48: 229 | F48: =ROUND(Source!AZ37,O48) -> 0 | G48: ОборудПод | H48: Стоимость оборудования подрядчика | K48: 229 | L48: 10 | M48: 3 | O48: 2 | P48: =ROUND(Source!ER37,O48) -> 0 | W48: 0 | X48: 1 | Y48: 0 | Z48: 0 | AA48: 1 | AB48: 0
A49: 50 | B49: 0 | C49: 0 | D49: 1 | E49: 203 | F49: =ROUND(Source!Q37,O49) -> 0 | G49: ЭММ | H49: Эксплуатация машин | K49: 203 | L49: 11 | M49: 3 | O49: 2 | P49: =ROUND(Source!DI37,O49) -> 0 | W49: 0 | X49: 1 | Y49: 0 | Z49: 0 | AA49: 1 | AB49: 0
A50: 50 | B50: 0 | C50: 0 | D50: 1 | E50: 231 | F50: =ROUND(Source!BB37,O50) -> 0 | G50: ЭММсНРиСП | H50: Эксплуатация машин по ТСН-2001.16 | K50: 231 | L50: 12 | M50: 3 | O50: 2 | P50: =ROUND(Source!ET37,O50) -> 0 | W50: 0 | X50: 1 | Y50: 0 | Z50: 0 | AA50: 1 | AB50: 0
A51: 50 | B51: 0 | C51: 0 | D51: 1 | E51: 204 | F51: =ROUND(Source!R37,O51) -> 0 | G51: ЗПМ | H51: ЗП машинистов | K51: 204 | L51: 13 | M51: 3 | O51: 2 | P51: =ROUND(Source!DJ37,O51) -> 0 | W51: 0 | X51: 1 | Y51: 0 | Z51: 0 | AA51: 1 | AB51: 0
A52: 50 | B52: 0 | C52: 0 | D52: 1 | E52: 205 | F52: =ROUND(Source!S37,O52) -> 62.38 | G52: ОЗП | H52: Основная ЗП рабочих | K52: 205 | L52: 14 | M52: 3 | O52: 2 | P52: =ROUND(Source!DK37,O52) -> 3515.12 | W52: 62.38 | X52: 1 | Y52: 62.38 | Z52: 3515.12 | AA52: 1 | AB52: 3515.12
A53: 50 | B53: 0 | C53: 0 | D53: 1 | E53: 232 | F53: =ROUND(Source!BC37,O53) -> 0 | G53: ОЗПсНРиСП | H53: Основная ЗП рабочих по ТСН-2001.16 | K53: 232 | L53: 15 | M53: 3 | O53: 2 | P53: =ROUND(Source!EU37,O53) -> 0 | W53: 0 | X53: 1 | Y53: 0 | Z53: 0 | AA53: 1 | AB53: 0
A54: 50 | B54: 0 | C54: 0 | D54: 1 | E54: 214 | F54: =ROUND(Source!AS37,O54) -> 0 | G54: Строит | H54: Строительные работы с НР и СП | K54: 214 | L54: 16 | M54: 3 | O54: 2 | P54: =ROUND(Source!EK37,O54) -> 0 | W54: 0 | X54: 1 | Y54: 0 | Z54: 0 | AA54: 1 | AB54: 0
A55: 50 | B55: 0 | C55: 0 | D55: 1 | E55: 215 | F55: =ROUND(Source!AT37,O55) -> 149.59 | G55: Монтаж | H55: Монтажные работы с НР и СП | K55: 215 | L55: 17 | M55: 3 | O55: 2 | P55: =ROUND(Source!EL37,O55) -> 8430.25 | W55: 149.59 | X55: 1 | Y55: 149.59 | Z55: 8430.25 | AA55: 1 | AB55: 8430.25
A56: 50 | B56: 0 | C56: 0 | D56: 1 | E56: 217 | F56: =ROUND(Source!AU37,O56) -> 0 | G56: Прочие | H56: Прочие работы с НР и СП | K56: 217 | L56: 18 | M56: 3 | O56: 2 | P56: =ROUND(Source!EM37,O56) -> 0 | W56: 0 | X56: 1 | Y56: 0 | Z56: 0 | AA56: 1 | AB56: 0
A57: 50 | B57: 0 | C57: 0 | D57: 1 | E57: 230 | F57: =ROUND(Source!BA37,O57) -> 0 | G57: ПрочиеЗатр | H57: Прочие затраты по ТСН-2001.16 | K57: 230 | L57: 19 | M57: 3 | O57: 2 | P57: =ROUND(Source!ES37,O57) -> 0 | W57: 0 | X57: 1 | Y57: 0 | Z57: 0 | AA57: 1 | AB57: 0
A58: 50 | B58: 0 | C58: 0 | D58: 1 | E58: 206 | F58: =ROUND(Source!T37,O58) -> 0 | G58: ВозврМат | H58: Возврат материалов | K58: 206 | L58: 20 | M58: 3 | O58: 2 | P58: =ROUND(Source!DL37,O58) -> 0 | W58: 0 | X58: 1 | Y58: 0 | Z58: 0 | AA58: 1 | AB58: 0
A59: 50 | B59: 0 | C59: 0 | D59: 1 | E59: 207 | F59: =Source!U37 -> 4.7892924 | G59: ТрудСтр | H59: Трудозатраты строителей | K59: 207 | L59: 21 | M59: 3 | O59: -1 | P59: =Source!DM37 -> 4.7892924 | W59: 4.7892924 | X59: 1 | Y59: 4.7892924 | Z59: 4.7892924 | AA59: 1 | AB59: 4.7892924
...

Sheet SourceObSm
A1: 0 | B1: Smeta.RU (495) 974-1589 | D1: _OBSM_ | F1: 0 | G1: 0 | H1: 0 | I1: Smeta.RU | K1: 1 | L1: 74599 | M1: 10 | N1: 12 | O1: 1 | P1: 0 | Q1: 5
A4: 1 | B4: 1 | C4: -1 | G4: Капитальный ремонт здания Государственного бюджетного общеобразовательного учреждения города Москвы «Школа №1574», расположенного по адресу: г. Москва, Старопименовский переулок, д. 5. 1 этап | EC4: 0
A5: 8 | B5: 1 | C5: -1 | G5: Капитальный ремонт здания Государственного бюджетного общеобразовательного учреждения города Москвы «Школа №1574», расположенного по адресу: г. Москва, Старопименовский переулок, д. 5. 1 этап | EC5: 0
A12: 1 | B12: 51 | C12: 0 | E12: 0 | F12: 02-01-16 | G12: 02-01-16 Электрочасофикация 15.07 | I12: 0 | J12: 2024-00375-01-0-ИОС5.9 | K12: 0 | L12: 0 | M12: 4097 | O12: 0 | P12: 0 | Q12: 0 | R12: 0 | S12: 0 | T12: 1 | U12: Капитальный ремонт здания Государственного бюджетного общеобразовательного учреждения города Москвы «Школа №1574», | V12: 2 | W12: г. Москва, Старопименовский переулок, д. 5. 1 этап | AB12: О.А.Гришечкина | AC12: Ведущий инженер-сметчик | AD12: И.В.Феденко | AE12: Начальник отдела | BB12: 0 | BH12: Сметные нормы списания | BI12: Коды ОКП для ТСН-2001 МГЭ Дополнение 81 | BJ12: 1 | BK12: 1 | BL12: 0 | BM12: 0 | BN12: 1 | BO12: 0 | BP12: 6 | BQ12: 2 | BR12: 1 | BS12: 1 | BT12: 0 | BU12: 0 | BV12: 0 | BW12: 0 | BX12: 0 | BY12: ТСН-2001 (МГЭ) Доп 81 - Ремонт | BZ12: Типовой расчет для ТСН-2001 МГЭ, Дополнение 81, ремонт | CA12: Территориальные сметные нормативы для Москвы ТСН-2001 (МГЭ), дополнение 81 | CB12: Территориальные сметные нормативы для Москвы ТСН-2001 (МГЭ), дополнение 81 | CC12: Территориальные сметные нормативы для Москвы ТСН-2001 (МГЭ), дополнение 81 | CD12: Территориальные сметные нормативы для Москвы ТСН-2001 (МГЭ), дополнение 81 | CE12: Поправки для ТСН-2001 от 07.04.2026 г. доп.81 | CF12: 0 | CG12: 0 | CH12: 8 | CK12: 82 | CQ12: Территориальные сметные нормативы для Москвы (ТСН-2001) | CR12: ТЕР | CS12: 41660 | CT12: 1 | CU12: 81 | CY12: 0 | EC12: 0
A14: 22 | B14: 1 | C14: 0 | D14: 55942968 | E14: 55942966 | F14: 2 | G14: 1
A16: 3 | B16: 1 | C16: 02-01-16 | D16: Электрочасофикация | E16: =ROUND((Source!P217)/1000,2) -> 0 | F16: =ROUND((Source!P218)/1000,2) -> 36.65 | G16: =ROUND((Source!P209)/1000,2) -> 1018 | H16: =ROUND((Source!P219)/1000+(Source!P220)/1000,2) -> 0 | I16: =E16+F16+G16+H16 -> 1054.65 | J16: =ROUND((Source!P215+Source!P214)/1000,2) -> 15.12 | K16: 2052.78 | L16: 0 | M16: 0 | N16: =I16+L16+M16 -> 1054.65 | T16: =ROUND((Source!F217)/1000,2) -> 0 | U16: =ROUND((Source!F218)/1000,2) -> 0.74 | V16: =ROUND((Source!F209)/1000,2) -> 134.48 | W16: =ROUND((Source!F219)/1000+(Source!F220)/1000,2) -> 0 | X16: =T16+U16+V16+W16 -> 135.22 | Y16: =ROUND((Source!F215+Source!F214)/1000,2) -> 0.27 | Z16: 269.44 | AA16: 0 | AB16: 0 | AC16: =X16+AA16+AB16 -> 135.22 | AI16: 2 | AJ16: -1 | AN16: 0 | AT16: 1033952.3 | AU16: 1018830.2 | AV16: 0 | AW16: 1017996.9 | AX16: 0 | AY16: 10.72 | AZ16: 5.64 | BA16: 15111.39 | BB16: 0 | BC16: 36649.09 | BD16: 0 | BE16: 0 | BF16: 21.315978 | BG16: 0 | BH16: 0 | BI16: 13661.39 | BJ16: 7032.32 | BK16: 1054646 | BR16: 134852.23 | BS16: 134583.43 | BT16: 0 | BU16: 134477.8 | BV16: 0 | BW16: 0.63 | BX16: 0.1 | BY16: 268.17 | BZ16: 0 | CA16: 741.65 | CB16: 0 | CC16: 0 | CD16: 21.315978 | CE16: 0 | CF16: 0 | CG16: 242.43 | CH16: 124.79 | CI16: 135219.45
A18: 51 | E18: 0 | F18: 36.65 | G18: 1018 | H18: 0 | I18: 1054.65 | J18: 15.12 | K18: 2052.78 | L18: 0 | M18: 0 | N18: 1054.65 | T18: 0 | U18: 0.74 | V18: 134.48 | W18: 0 | X18: 135.22 | Y18: 0.27 | Z18: 269.44 | AA18: 0 | AB18: 0 | AC18: 135.22
A20: 50 | B20: 0 | C20: 0 | D20: 1 | E20: 201 | F20: 1033952.3 | G20: ПЗ | H20: Прямые затраты | K20: 201 | L20: 1 | M20: 3 | O20: 2 | P20: 134852.23
A21: 50 | B21: 0 | C21: 0 | D21: 1 | E21: 202 | F21: 1018830.2 | G21: СтМатОб | H21: Стоимость материальных ресурсов (всего) | K21: 202 | L21: 2 | M21: 3 | O21: 2 | P21: 134583.43
A22: 50 | B22: 0 | C22: 0 | D22: 1 | E22: 222 | F22: 0 | G22: СтМатОбЗак | H22: Стоимость материалов и оборудования заказчика | K22: 222 | L22: 3 | M22: 3 | O22: 2 | P22: 0
A23: 50 | B23: 0 | C23: 0 | D23: 1 | E23: 225 | F23: 1018830.2 | G23: СтМатОбПод | H23: Стоимость материалов и оборудования подрядчика | K23: 225 | L23: 4 | M23: 3 | O23: 2 | P23: 134583.43
A24: 50 | B24: 0 | C24: 0 | D24: 1 | E24: 226 | F24: 833.27 | G24: СтМат | H24: Стоимость материалов (всего) | K24: 226 | L24: 5 | M24: 3 | O24: 2 | P24: 105.63
A25: 50 | B25: 0 | C25: 0 | D25: 1 | E25: 227 | F25: 0 | G25: СтМатЗак | H25: Стоимость материалов заказчика | K25: 227 | L25: 6 | M25: 3 | O25: 2 | P25: 0
A26: 50 | B26: 0 | C26: 0 | D26: 1 | E26: 228 | F26: 833.27 | G26: СтМатПод | H26: Стоимость материалов подрядчика | K26: 228 | L26: 7 | M26: 3 | O26: 2 | P26: 105.63
A27: 50 | B27: 0 | C27: 0 | D27: 1 | E27: 216 | F27: 1017996.9 | G27: Оборуд | H27: Стоимость оборудования (всего) | K27: 216 | L27: 8 | M27: 3 | O27: 2 | P27: 134477.8
