Workbook

Sheet Смета по ТСН-2001(с доп.67
A1: =Source!B1 -> Smeta.RU (495) 974-1589
J2: Форма № 4б
A3: Капитальный ремонт здания Государственного бюджетного общеобразовательного учреждения города Москвы «Школа №1574» по адресу: г. Москва, Старопименовский пер., д. №5. | AP3: Капитальный ремонт здания Государственного бюджетного общеобразовательного учреждения города Москвы «Школа №1574» по адресу: г. Москва, Старопименовский пер., д. №5. 02-01-07 Вентиляция и кондиционирование воздуха
A4: (наименование стройки и/или объекта)
A6: =CONCATENATE( "ЛОКАЛЬНАЯ СМЕТА № ",IF(Source!F12<>"Новый объект", Source!F12, "")) -> ЛОКАЛЬНАЯ СМЕТА № 02-01-07
A8: Вентиляция и кондиционирование воздуха
A9: (наименование работ и затрат)
A11: =CONCATENATE( "Основание: чертежи № ", Source!J12) -> Основание: чертежи № 2024-00375-01-0-ИОС4.2
I13: В базисном уровне цен | J13: В текущем уровне цен
E14: Сметная стоимость | I14: =I15+I16+I17+I18 -> 5753.96 | J14: =J15+J16+J17+J18 -> 53075.77 | K14: тыс.руб.
E15: Строительные работы | I15: =ROUND((Source!F1553)/1000, 2) -> 1985.27 | J15: =ROUND((Source!P1553)/1000, 2) -> 24368.16 | K15: тыс.руб.
E16: Работы по монтажу оборудования | I16: =ROUND((Source!F1554)/1000, 2) -> 0.44 | J16: =ROUND((Source!P1554)/1000, 2) -> 23.73 | K16: тыс.руб.
E17: Оборудование | I17: =ROUND((Source!F1545)/1000, 2) -> 3768.25 | J17: =ROUND((Source!P1545)/1000, 2) -> 28683.88 | K17: тыс.руб.
E18: Прочие работы и затраты | I18: =ROUND((Source!F1555+Source!F1556)/1000, 2) -> 0 | J18: =ROUND((Source!P1555+Source!P1556)/1000, 2) -> 0 | K18: тыс.руб.
E19: Средства на оплату труда | I19: =(Source!F1551+ Source!F1550)/1000 -> 94.58857 | J19: =((Source!P1551 + Source!P1550)/1000) -> 5330.0659 | K19: тыс.руб.
E20: Затраты труда | I20: =Source!F1558 -> 7684.5827 | K20: чел.-ч.
E21: Кроме того:
E22: Возврат материалов | I22: =SUM(Y1:Y1692)/1000 -> 0 | J22: =SUM(Z1:Z1692)/1000 -> 0 | K22: тыс.руб.
A24: Составлен(а) по ТСН-2001 с учетом Дополнения №: 81
A25: № и период сборника коэффициентов (индексов) пересчета: Коэффициенты к ТСН-2001 МГЭ Дополнение 81, ремонт №219/81 I квартал 2026 года и Коэффициенты к ТСН-2001.13-2 Дополнение 47 №64/47 I квартал 2026 года | AP25: № и период сборника коэффициентов (индексов) пересчета: Коэффициенты к ТСН-2001 МГЭ Дополнение 81, ремонт №219/81 I квартал 2026 года и Коэффициенты к ТСН-2001.13-2 Дополнение 47 №64/47 I квартал 2026 года
A26: № п/п | B26: Шифр расценки и коды ресурсов | C26: Наименование работ и затрат | D26: Ед. изм. | E26: Кол-во единиц | F26: Цена на ед. изм., руб. | G26: Попра- вочные коэффи- циенты | H26: Коэффи- циенты зимних удорожа- ний | I26: Всего в ценах на январь 2000 года, руб. | J26: Коэффи- циенты (индек- сы) пере- счета, нормы НР и СП | K26: ВСЕГО затрат в текущем уровне цен, руб.
A27: 1 | B27: 2 | C27: 3 | D27: 4 | E27: 5 | F27: 6 | G27: 7 | H27: 8 | I27: 9 | J27: 10 | K27: 11
A29: =CONCATENATE("Локальная смета: ",IF(Source!G20<>"Новая локальная смета", Source!G20, "")) -> Локальная смета: Вентиляция и кондиционирование воздуха
A31: =CONCATENATE("Раздел: ",IF(Source!G24<>"Новый раздел", Source!G24, "")) -> Раздел: Вентиляция
A33: =CONCATENATE("Подраздел: ",IF(Source!G28<>"Новый подраздел", Source!G28, "")) -> Подраздел: Приточные установки
A34: 1 | B34: =Source!F32 -> 3.20-40-1 | C34: Установка камер приточных типовых без секции орошения и установок приточных производительностью до 10 тыс.м3/час | D34: =Source!H32 -> 1 КАМЕРА | E34: =Source!I32 -> 16 | Q34: =Source!X32 -> 13217.43 | R34: =Source!X33 -> 744802.02 | S34: =Source!Y32 -> 7396.91 | T34: =Source!Y33 -> 416815.81 | U34: =ROUND((175/100)*ROUND(Source!R32, 2), 2) -> 337.38 | V34: =ROUND((0/100)*ROUND(Source!R33, 2), 2) -> 0 | AC34: 0
C35: ЗП | F35: =Source!AO32 -> 482.4 | G35: 1,2*1,15*1,05 | H35: =Source!AV33 -> 1.067 | I35: =Source!S32 -> 11933.29 | J35: =IF(Source!BA33<> 0, Source!BA33, 1) -> 56.35 | K35: =Source!S33 -> 672440.89
C36: ЭМ | F36: =Source!AM32 -> 71.07 | G36: 1,2*1,25*1,05 | H36: =Source!AV33 -> 1.067 | I36: =Source!Q32 -> 1910.96 | J36: =IF(Source!BB33<> 0, Source!BB33, 1) -> 15.22 | K36: =Source!Q33 -> 29084.81
C37: в т.ч. ЗПМ | F37: =Source!AN32 -> 7.17 | G37: 1,2*1,25*1,05 | H37: =Source!AV33 -> 1.067 | I37: =Source!R32 -> 192.79 | J37: =IF(Source!BS33<> 0, Source!BS33, 1) -> 56.35 | K37: =Source!R33 -> 10863.72
C38: МР | F38: =Source!AL32 -> 223.41 | H38: =Source!AW33 -> 1 | I38: =Source!P32 -> 3574.56 | J38: =IF(Source!BC33<> 0, Source!BC33, 1) -> 9.16 | K38: =Source!P33 -> 32742.97
C39: НР от ФОТ | D39: % | E39: =Source!BZ33 -> 109 | I39: =SUM(Q34:Q38) -> 13217.43 | J39: =Source!AT33 -> 109 | K39: =SUM(R34:R38) -> 744802.02
C40: СП от ФОТ | D40: % | E40: =Source!CA33 -> 61 | I40: =SUM(S34:S39) -> 7396.91 | J40: =Source!AU33 -> 61 | K40: =SUM(T34:T39) -> 416815.81
C41: ЗТР | D41: чел-ч | E41: =Source!AQ32 -> 40.1 | G41: 1,2*1,15*1,05 | H41: =Source!AV33 -> 1.067 | I41: =Source!U32 -> 991.96685
C42: ВСЕГО работ по позиции: | H42: =I35+I36+I38+I39+I40+0-0-0 -> 38033.15 | J42: =K35+K36+K38+K39+K40+0-0-0 -> 1895886.5
C43: ВСЕГО оборудование по позиции: | H43: =0+0 -> 0 | J43: =0+0 -> 0
C44: ВСЕГО по позиции: | H44: =I35+I36+I38+I39+I40+0 -> 38033.15 | J44: =K35+K36+K38+K39+K40+0 -> 1895886.5 | O44: =I35+I36+I38+I39+I40+0 -> 38033.15 | P44: =K35+K36+K38+K39+K40+0 -> 1895886.5
A46: 2 | B46: =Source!F34 -> КА, п.1 | C46: ОБОРУДОВАНИЕ:_x000D_ Приточная установка П1 (L=1890 м3/ч, Pc=500 Па) 38 705,03 = [342 930 / 1,22 / 7,57] + 3% Трансп + 1,2% Заг.скл | D46: =Source!H34 -> ШТ | E46: =Source!I34 -> 1 | F46: =Source!AL34 -> 38705.03 | H46: =Source!AW35 -> 1 | I46: =Source!P34 -> 38705.03 | J46: =IF(Source!BC35<> 0, Source!BC35, 1) -> 7.57 | K46: =Source!P35 -> 292997.08 | Q46: =Source!X34 -> 0 | R46: =Source!X35 -> 0 | S46: =Source!Y34 -> 0 | T46: =Source!Y35 -> 0 | U46: =ROUND((175/100)*ROUND(Source!R34, 2), 2) -> 0 | V46: =ROUND((0/100)*ROUND(Source!R35, 2), 2) -> 0 | AC46: 5
C47: ВСЕГО по позиции: | H47: =I46+0 -> 38705.03 | J47: =K46+0 -> 292997.08 | O47: =I46+0 -> 38705.03 | P47: =K46+0 -> 292997.08
A49: 3 | B49: =Source!F36 -> КА, п.3 | C49: ОБОРУДОВАНИЕ:_x000D_ Приточная установка П2 (L=3600 м3/ч, Pc=500 Па) 45 981,50 = [407 400 / 1,22 / 7,57] + 3% Трансп + 1,2% Заг.скл | D49: =Source!H36 -> ШТ | E49: =Source!I36 -> 1 | F49: =Source!AL36 -> 45981.5 | H49: =Source!AW37 -> 1 | I49: =Source!P36 -> 45981.5 | J49: =IF(Source!BC37<> 0, Source!BC37, 1) -> 7.57 | K49: =Source!P37 -> 348079.96 | Q49: =Source!X36 -> 0 | R49: =Source!X37 -> 0 | S49: =Source!Y36 -> 0 | T49: =Source!Y37 -> 0 | U49: =ROUND((175/100)*ROUND(Source!R36, 2), 2) -> 0 | V49: =ROUND((0/100)*ROUND(Source!R37, 2), 2) -> 0 | AC49: 5
C50: ВСЕГО по позиции: | H50: =I49+0 -> 45981.5 | J50: =K49+0 -> 348079.96 | O50: =I49+0 -> 45981.5 | P50: =K49+0 -> 348079.96
...

Sheet Source
A1: 0 | B1: Smeta.RU (495) 974-1589 | D1: _PS_ | F1: 0 | G1: 0 | H1: 0 | I1: Smeta.RU | K1: 1 | L1: 74598 | M1: 10 | N1: 12 | O1: 1 | P1: 0 | Q1: 5
A4: 1 | B4: 1 | C4: -1 | G4: Капитальный ремонт здания Государственного бюджетного общеобразовательного учреждения города Москвы «Школа №1574» по адресу: г. Москва, Старопименовский пер., д. №5 | EC4: 0
A5: 8 | B5: 1 | C5: -1 | G5: Капитальный ремонт здания Государственного бюджетного общеобразовательного учреждения города Москвы «Школа №1574» по адресу: г. Москва, Старопименовский пер., д. №5 | EC5: 0
A12: 1 | B12: 1577 | C12: 0 | D12: =ROW(A1536) -> 1536 | E12: 0 | F12: 02-01-07 | G12: 02-01-07 Вентиляция и кондиционирование воздуха | I12: 0 | J12: 2024-00375-01-0-ИОС4.2 | K12: 0 | L12: 0 | M12: 4098 | O12: 0 | P12: 0 | Q12: 0 | R12: 0 | S12: 0 | T12: 1 | U12: Капитальный ремонт здания Государственного бюджетного общеобразовательного учреждения города Москвы «Школа №1574» | V12: 2 | W12: г. Москва, Старопименовский переулок, д. 5. 1 этап | AB12: Гришечкина О.А. | AC12: Ведущий инженер сметчик | AD12: Феденко И.В. | AE12: Руководитель сметного отдела | BB12: 0 | BH12: Сметные нормы списания | BI12: Коды ОКП для ТСН-2001 МГЭ Дополнение 81 | BJ12: 1 | BK12: 1 | BL12: 0 | BM12: 0 | BN12: 1 | BO12: 0 | BP12: 6 | BQ12: 2 | BR12: 1 | BS12: 1 | BT12: 0 | BU12: 0 | BV12: 0 | BW12: 0 | BX12: 0 | BZ12: Типовой расчет для ТСН-2001 МГЭ, Дополнение 81, ремонт | CA12: Территориальные сметные нормативы для Москвы ТСН-2001 (МГЭ), дополнение 81 | CB12: Территориальные сметные нормативы для Москвы ТСН-2001 (МГЭ), дополнение 81 | CC12: Территориальные сметные нормативы для Москвы ТСН-2001 (МГЭ), дополнение 81 | CD12: Территориальные сметные нормативы для Москвы ТСН-2001 (МГЭ), дополнение 81 | CE12: Поправки для ТСН-2001 от 07.04.2026 г. доп.81 | CF12: 0 | CG12: 0 | CH12: 8200 | CK12: 82 | CQ12: Территориальные сметные нормативы для Москвы (ТСН-2001) | CR12: ТЕР | CS12: 41660 | CT12: 1 | CU12: 81 | CY12: 0 | EC12: 0
A15: 15 | B15: 1
A18: 52 | B18: =B1536 -> 1577 | C18: =C1536 -> 1 | D18: =D1536 -> 12 | E18: =E1536 -> 0 | F18: =F1536 -> 02-01-07 | G18: =G1536 -> 02-01-07 Вентиляция и кондиционирование воздуха | O18: =O1536 -> 5596900.2 | P18: =P1536 -> 5491642.6 | Q18: =Q1536 -> 12119.28 | R18: =R1536 -> 1450.29 | S18: =S1536 -> 93138.28 | T18: =T1536 -> 0 | U18: =U1536 -> 7684.5827 | V18: =V1536 -> 0 | ... GX18: =GX1536 -> 0
A20: 3 | B20: 1 | D20: =ROW(A1506) -> 1506 | F20: 02-01-07 | G20: Вентиляция и кондиционирование воздуха | I20: 0 | J20: 2024-00375-01-0-ИОС4.2 | K20: -1 | L20: 02-01-07 | S20: 0 | T20: 0 | V20: 2 | AB20: Гришечкина О.А. | AC20: Ведущий инженер сметчик | AD20: Феденко И.В. | AE20: Руководитель сметного отдела | BX20: 0 | CF20: 0 | CG20: 0
A22: 52 | B22: =B1506 -> 1 | C22: =C1506 -> 3 | D22: =D1506 -> 20 | E22: =E1506 -> 0 | F22: =F1506 -> 02-01-07 | G22: =G1506 -> Вентиляция и кондиционирование воздуха | O22: =O1506 -> 5596900.2 | P22: =P1506 -> 5491642.6 | Q22: =Q1506 -> 12119.28 | R22: =R1506 -> 1450.29 | S22: =S1506 -> 93138.28 | T22: =T1506 -> 0 | U22: =U1506 -> 7684.5827 | V22: =V1506 -> 0 | ... GX22: =GX1506 -> 0
A24: 4 | B24: 1 | D24: =ROW(A357) -> 357 | F24: Новый раздел | G24: Вентиляция | I24: 0 | K24: 0 | S24: 0 | T24: 0 | V24: 2 | BX24: 0 | CJ24: 0
A26: 52 | B26: =B357 -> 1 | C26: =C357 -> 4 | D26: =D357 -> 24 | E26: =E357 -> 0 | F26: =F357 -> Новый раздел | G26: =G357 -> Вентиляция | O26: =O357 -> 2190944.9 | P26: =P357 -> 2141975.3 | Q26: =Q357 -> 5775.02 | R26: =R357 -> 618.14 | S26: =S357 -> 43194.5 | T26: =T357 -> 0 | U26: =U357 -> 3548.3134 | V26: =V357 -> 0 | ... GX26: =GX357 -> 0
A28: 5 | B28: 1 | D28: =ROW(A71) -> 71 | F28: Новый подраздел | G28: Приточные установки | I28: 0 | K28: 0 | S28: 0 | T28: 0 | V28: 2 | BX28: 0 | CJ28: 0
A30: 52 | B30: =B71 -> 1 | C30: =C71 -> 5 | D30: =D71 -> 28 | E30: =E71 -> 0 | F30: =F71 -> Новый подраздел | G30: =G71 -> Приточные установки | O30: =O71 -> 778582.9 | P30: =P71 -> 763458.88 | Q30: =Q71 -> 2152.89 | R30: =R71 -> 218.1 | S30: =S71 -> 12971.13 | T30: =T71 -> 0 | U30: =U71 -> 1078.2383 | V30: =V71 -> 0 | ... GX30: =GX71 -> 0
A32: 17 | B32: 1 | C32: =ROW(SmtRes!A15) -> 15 | D32: =ROW(EtalonRes!A16) -> 16 | E32: 1 | F32: 3.20-40-1 | G32: Установка камер приточных типовых без секции орошения и установок приточных производительностью до 10 тыс.м3/час | H32: 1 КАМЕРА | I32: 16 | J32: 0 | K32: 16 | O32: =ROUND(CP32,2) -> 17418.81 | P32: =ROUND((ROUND((AC32*AW32*I32),2)*BC32),2) -> 3574.56 | Q32: =(ROUND((ROUND((((((ET32*1.2)*1.25)*1.05))*AV32*I32),2)*BB32),2)+ROUND((ROUND(((AE32-((((EU32*1.2)*1.25)*1.05)))*AV32*I32),2)*BS32),2)) -> 1910.96 | R32: =(ROUND((ROUND((((((EU32*1.2)*1.25)*1.05))*AV32*I32),2)*BS32),2)+ROUND((ROUND(((AE32-((((EU32*1.2)*1.25)*1.05)))*AV32*I32),2)*BS32),2)) -> 192.79 | S32: =ROUND((ROUND((AF32*AV32*I32),2)*BA32),2) -> 11933.29 | T32: =ROUND(CU32*I32,2) -> 0 | U32: =CV32*I32 -> 991.96685 | V32: =CW32*I32 -> 0 | W32: =ROUND(CX32*I32,2) -> 0 | X32: =(ROUND((((S32+ROUND((ROUND((((((EU32*1.2)*1.25)*1.05))*AV32*I32),2)*BS32),2))*AT32)/100),2)+ROUND(((ROUND((ROUND(((AE32-((((EU32*1.2)*1.25)*1.05)))*AV32*I32),2)*BS32),2)*AT32)/100),2)) -> 13217.43 | Y32: =(ROUND((((S32+ROUND((ROUND((((((EU32*1.2)*1.25)*1.05))*AV32*I32),2)*BS32),2))*AU32)/100),2)+ROUND(((ROUND((ROUND(((AE32-((((EU32*1.2)*1.25)*1.05)))*AV32*I32),2)*BS32),2)*AU32)/100),2)) -> 7396.91 | AA32: 56661434 | AB32: =ROUND((AC32+AD32+AF32),6) -> 1034.3428 | AC32: =ROUND((((ES32*1)*1)),6) -> 223.41 | AD32: =ROUND(((((((ET32*1.2)*1.25)*1.05))-((((EU32*1.2)*1.25)*1.05)))+AE32),6) -> 111.93525 | AE32: =ROUND(((((EU32*1.2)*1.25)*1.05)),6) -> 11.29275 | AF32: =ROUND(((((EV32*1.2)*1.15)*1.05)),6) -> 698.9976 | AG32: =ROUND((AP32),6) -> 0 | AH32: =((((EW32*1.2)*1.15)*1.05)) -> 58.1049 | AI32: =((((EX32*1.2)*1.25)*1.05)) -> 0 | AJ32: =(AS32) -> 0 | AK32: 776.88 | AL32: 223.41 | AM32: 71.07 | AN32: 7.17 | AO32: 482.4 | AP32: 0 | AQ32: 40.1 | AR32: 0 | AS32: 0 | AT32: 109 | AU32: 61 | AV32: 1.067 | AW32: 1 | AZ32: 1 | BA32: 1 | BB32: 1 | BC32: 1 | BH32: 0 | BI32: 1 | BJ32: ТСН-2001.3 Доп. 79, Сб. 20, т. 40, поз. 1 | BM32: 25 | BN32: 0 | BO32: 3.20-40-1 | BP32: 1 | BQ32: 30 | BR32: 0 | BS32: 1 | BT32: 1 | BU32: 1 | BV32: 1 | BW32: 1 | BX32: 1 | BZ32: 109 | CA32: 61 | CE32: 1566 | CF32: 0 | CG32: 0 | CM32: 0 | CN32: Поправка: Гл.12.Прил.8.п.8. 3_12.00.01.11.001 Наименование: При наличии напряженных и стесненных условий производства работ (стесненность, сложность складирования и транспортной логистики и т.п.) для объектов, расположенных в пределах круговой магистральной системы улиц "Садовое кольцо" города Москвы Поправка: Гл.6.Прил.2.2.п.2.2.6_06.00.01.07.001 Наименование: При выполнении при капитальном ремонте и реконструкции работ, аналогичных технологическим процессам, характерным для нового строительства, и отсутствующих в сборниках на ремонтно-строительные работы ТСН-2001.6 | CO32: 0 | CP32: =(P32+Q32+S32) -> 17418.81 | CQ32: =ROUND((ROUND((AC32*AW32*1),2)*BC32),2) -> 223.41 | CR32: =(ROUND((ROUND((((((ET32*1.2)*1.25)*1.05))*AV32*1),2)*BB32),2)+ROUND((ROUND(((AE32-((((EU32*1.2)*1.25)*1.05)))*AV32*1),2)*BS32),2)) -> 119.43 | CS32: =(ROUND((ROUND((((((EU32*1.2)*1.25)*1.05))*AV32*1),2)*BS32),2)+ROUND((ROUND(((AE32-((((EU32*1.2)*1.25)*1.05)))*AV32*1),2)*BS32),2)) -> 12.05 | CT32: =ROUND((ROUND((AF32*AV32*1),2)*BA32),2) -> 745.83 | CU32: =AG32 -> 0 | CV32: =(AH32*AV32) -> 61.997928 | CW32: =AI32 -> 0 | CX32: =AJ32 -> 0 | CY32: =(ROUND((((S32+ROUND((ROUND((((((EU32*1.2)*1.25)*1.05))*AV32*1),2)*BS32),2))*AT32)/100),2)+ROUND(((ROUND((ROUND(((AE32-((((EU32*1.2)*1.25)*1.05)))*AV32*1),2)*BS32),2)*AT32)/100),2)) -> 13020.42 | CZ32: =(ROUND((((S32+ROUND((ROUND((((((EU32*1.2)*1.25)*1.05))*AV32*1),2)*BS32),2))*AU32)/100),2)+ROUND(((ROUND((ROUND(((AE32-((((EU32*1.2)*1.25)*1.05)))*AV32*1),2)*BS32),2)*AU32)/100),2)) -> 7286.66 | DD32: *1)*1 | DE32: *1,2)*1,25)*1,05 | DF32: *1,2)*1,25)*1,05 | DG32: *1,2)*1,15)*1,05 | DI32: *1,2)*1,15)*1,05 | DJ32: *1,2)*1,25)*1,05 | DN32: 0 | DO32: 0 | DP32: 1 | DQ32: 1 | DU32: 1013 | DV32: 1 КАМЕРА | DW32: 1 КАМЕРА | DX32: 1 | EE32: 56938458 | EF32: 30 | EG32: Строительные работы | EH32: 0 | EJ32: 1 | EK32: 25 | EL32: ТСН-2001.3-20. Вентиляция и кондиционирование воздуха | EM32: ТСН-2001.3-20-1 | EO32: Поправка: Гл.12.Прил.8.п.8. 3_12.00.01.11.001 Поправка: Гл.6.Прил.2.2.п.2.2.6_06.00.01.07.001 | EQ32: 131072 | ER32: 776.88 | ES32: 223.41 | ET32: 71.07 | EU32: 7.17 | EV32: 482.4 | EW32: 40.1 | EX32: 0 | EY32: 0 | FQ32: 0 | FR32: 0 | FS32: 0 | FX32: 109 | FY32: 61 | GD32: 1 | GF32: -129762480 | GG32: 2 | GH32: 1 | GI32: 2 | GJ32: 0 | GK32: 0 | GL32: =ROUND(IF(AND(BH32=3,BI32=3,FS32<>0),P32,0),2) -> 0 | GM32: =ROUND(O32+X32+Y32,2)+GX32 -> 38033.15 | GN32: =IF(OR(BI32=0,BI32=1),GM32-GX32,0) -> 38033.15 | GO32: =IF(BI32=2,GM32-GX32,0) -> 0 | GP32: =IF(BI32=4,GM32-GX32,0) -> 0 | GR32: 0 | GS32: 3 | GT32: 0 | GV32: =ROUND((GT32),6) -> 0 | GW32: 1 | GX32: =ROUND(HC32*I32,2) -> 0 | HA32: 0 | HB32: 0 | HC32: =GV32*GW32 -> 0 | HS32: 0 | IK32: 0
A33: 17 | B33: 1 | C33: =ROW(SmtRes!A30) -> 30 | D33: =ROW(EtalonRes!A32) -> 32 | E33: 1 | F33: 3.20-40-1 | G33: Установка камер приточных типовых без секции орошения и установок приточных производительностью до 10 тыс.м3/час | H33: 1 КАМЕРА | I33: 16 | J33: 0 | K33: 16 | O33: =ROUND(CP33,2) -> 734268.67 | P33: =ROUND((ROUND((AC33*AW33*I33),2)*BC33),2) -> 32742.97 | Q33: =(ROUND((ROUND((((((ET33*1.2)*1.25)*1.05))*AV33*I33),2)*BB33),2)+ROUND((ROUND(((AE33-((((EU33*1.2)*1.25)*1.05)))*AV33*I33),2)*BS33),2)) -> 29084.81 | R33: =(ROUND((ROUND((((((EU33*1.2)*1.25)*1.05))*AV33*I33),2)*BS33),2)+ROUND((ROUND(((AE33-((((EU33*1.2)*1.25)*1.05)))*AV33*I33),2)*BS33),2)) -> 10863.72 | S33: =ROUND((ROUND((AF33*AV33*I33),2)*BA33),2) -> 672440.89 | T33: =ROUND(CU33*I33,2) -> 0 | U33: =CV33*I33 -> 991.96685 | V33: =CW33*I33 -> 0 | W33: =ROUND(CX33*I33,2) -> 0 | X33: =(ROUND((((S33+ROUND((ROUND((((((EU33*1.2)*1.25)*1.05))*AV33*I33),2)*BS33),2))*AT33)/100),2)+ROUND(((ROUND((ROUND(((AE33-((((EU33*1.2)*1.25)*1.05)))*AV33*I33),2)*BS33),2)*AT33)/100),2)) -> 744802.02 | Y33: =(ROUND((((S33+ROUND((ROUND((((((EU33*1.2)*1.25)*1.05))*AV33*I33),2)*BS33),2))*AU33)/100),2)+ROUND(((ROUND((ROUND(((AE33-((((EU33*1.2)*1.25)*1.05)))*AV33*I33),2)*BS33),2)*AU33)/100),2)) -> 416815.81 | AA33: 56661436 | AB33: =ROUND((AC33+AD33+AF33),6) -> 1034.3428 | AC33: =ROUND((((ES33*1)*1)),6) -> 223.41 | AD33: =ROUND(((((((ET33*1.2)*1.25)*1.05))-((((EU33*1.2)*1.25)*1.05)))+AE33),6) -> 111.93525 | AE33: =ROUND(((((EU33*1.2)*1.25)*1.05)),6) -> 11.29275 | AF33: =ROUND(((((EV33*1.2)*1.15)*1.05)),6) -> 698.9976 | AG33: =ROUND((AP33),6) -> 0 | AH33: =((((EW33*1.2)*1.15)*1.05)) -> 58.1049 | AI33: =((((EX33*1.2)*1.25)*1.05)) -> 0 | AJ33: =(AS33) -> 0 | AK33: 776.88 | AL33: 223.41 | AM33: 71.07 | AN33: 7.17 | AO33: 482.4 | AP33: 0 | AQ33: 40.1 | AR33: 0 | AS33: 0 | AT33: 109 | AU33: 61 | AV33: 1.067 | AW33: 1 | AZ33: 1 | BA33: 56.35 | BB33: 15.22 | BC33: 9.16 | BH33: 0 | BI33: 1 | BJ33: ТСН-2001.3 Доп. 79, Сб. 20, т. 40, поз. 1 | BM33: 25 | BN33: 0 | BO33: 3.20-40-1 | BP33: 1 | BQ33: 30 | BR33: 0 | BS33: 56.35 | BT33: 1 | BU33: 1 | BV33: 1 | BW33: 1 | BX33: 1 | BZ33: 109 | CA33: 61 | CE33: 1566 | CF33: 0 | CG33: 0 | CM33: 0 | CN33: Поправка: Гл.12.Прил.8.п.8. 3_12.00.01.11.001 Наименование: При наличии напряженных и стесненных условий производства работ (стесненность, сложность складирования и транспортной логистики и т.п.) для объектов, расположенных в пределах круговой магистральной системы улиц "Садовое кольцо" города Москвы Поправка: Гл.6.Прил.2.2.п.2.2.6_06.00.01.07.001 Наименование: При выполнении при капитальном ремонте и реконструкции работ, аналогичных технологическим процессам, характерным для нового строительства, и отсутствующих в сборниках на ремонтно-строительные работы ТСН-2001.6 | CO33: 0 | CP33: =(P33+Q33+S33) -> 734268.67 | CQ33: =ROUND((ROUND((AC33*AW33*1),2)*BC33),2) -> 2046.44 | CR33: =(ROUND((ROUND((((((ET33*1.2)*1.25)*1.05))*AV33*1),2)*BB33),2)+ROUND((ROUND(((AE33-((((EU33*1.2)*1.25)*1.05)))*AV33*1),2)*BS33),2)) -> 1817.72 | CS33: =(ROUND((ROUND((((((EU33*1.2)*1.25)*1.05))*AV33*1),2)*BS33),2)+ROUND((ROUND(((AE33-((((EU33*1.2)*1.25)*1.05)))*AV33*1),2)*BS33),2)) -> 679.02 | CT33: =ROUND((ROUND((AF33*AV33*1),2)*BA33),2) -> 42027.52 | CU33: =AG33 -> 0 | CV33: =(AH33*AV33) -> 61.997928 | CW33: =AI33 -> 0 | CX33: =AJ33 -> 0 | CY33: =(ROUND((((S33+ROUND((ROUND((((((EU33*1.2)*1.25)*1.05))*AV33*1),2)*BS33),2))*AT33)/100),2)+ROUND(((ROUND((ROUND(((AE33-((((EU33*1.2)*1.25)*1.05)))*AV33*1),2)*BS33),2)*AT33)/100),2)) -> 733700.7 | CZ33: =(ROUND((((S33+ROUND((ROUND((((((EU33*1.2)*1.25)*1.05))*AV33*1),2)*BS33),2))*AU33)/100),2)+ROUND(((ROUND((ROUND(((AE33-((((EU33*1.2)*1.25)*1.05)))*AV33*1),2)*BS33),2)*AU33)/100),2)) -> 410603.15 | DD33: *1)*1 | DE33: *1,2)*1,25)*1,05 | DF33: *1,2)*1,25)*1,05 | DG33: *1,2)*1,15)*1,05 | DI33: *1,2)*1,15)*1,05 | DJ33: *1,2)*1,25)*1,05 | DN33: 0 | DO33: 0 | DP33: 1 | DQ33: 1 | DU33: 1013 | DV33: 1 КАМЕРА | DW33: 1 КАМЕРА | DX33: 1 | EE33: 56938458 | EF33: 30 | EG33: Строительные работы | EH33: 0 | EJ33: 1 | EK33: 25 | EL33: ТСН-2001.3-20. Вентиляция и кондиционирование воздуха | EM33: ТСН-2001.3-20-1 | EO33: Поправка: Гл.12.Прил.8.п.8. 3_12.00.01.11.001 Поправка: Гл.6.Прил.2.2.п.2.2.6_06.00.01.07.001 | EQ33: 131072 | ER33: 776.88 | ES33: 223.41 | ET33: 71.07 | EU33: 7.17 | EV33: 482.4 | EW33: 40.1 | EX33: 0 | EY33: 0 | FQ33: 0 | FR33: 0 | FS33: 0 | FX33: 109 | FY33: 61 | GD33: 1 | GF33: -129762480 | GG33: 2 | GH33: 1 | GI33: 2 | GJ33: 0 | GK33: 0 | GL33: =ROUND(IF(AND(BH33=3,BI33=3,FS33<>0),P33,0),2) -> 0 | GM33: =ROUND(O33+X33+Y33,2)+GX33 -> 1895886.5 | GN33: =IF(OR(BI33=0,BI33=1),GM33-GX33,0) -> 1895886.5 | GO33: =IF(BI33=2,GM33-GX33,0) -> 0 | GP33: =IF(BI33=4,GM33-GX33,0) -> 0 | GR33: 0 | GS33: 3 | GT33: 0 | GV33: =ROUND((GT33),6) -> 0 | GW33: 1 | GX33: =ROUND(HC33*I33,2) -> 0 | HA33: 0 | HB33: 0 | HC33: =GV33*GW33 -> 0 | HS33: 0 | IK33: 0
A34: 17 | B34: 1 | E34: 2 | F34: КА, п.1 | G34: Приточная установка П1 (L=1890 м3/ч, Pc=500 Па) | H34: ШТ | I34: 1 | J34: 0 | K34: 1 | O34: =ROUND(CP34,2) -> 38705.03 | P34: =ROUND((ROUND((AC34*AW34*I34),2)*BC34),2) -> 38705.03 | Q34: =(ROUND((ROUND(((ET34)*AV34*I34),2)*BB34),2)+ROUND((ROUND(((AE34-(EU34))*AV34*I34),2)*BS34),2)) -> 0 | R34: =(ROUND((ROUND(((EU34)*AV34*I34),2)*BS34),2)+ROUND((ROUND(((AE34-(EU34))*AV34*I34),2)*BS34),2)) -> 0 | S34: =ROUND((ROUND((AF34*AV34*I34),2)*BA34),2) -> 0 | T34: =ROUND(CU34*I34,2) -> 0 | U34: =CV34*I34 -> 0 | V34: =CW34*I34 -> 0 | W34: =ROUND(CX34*I34,2) -> 0 | X34: =(ROUND((((S34+ROUND((ROUND(((EU34)*AV34*I34),2)*BS34),2))*AT34)/100),2)+ROUND(((ROUND((ROUND(((AE34-(EU34))*AV34*I34),2)*BS34),2)*AT34)/100),2)) -> 0 | Y34: =(ROUND((((S34+ROUND((ROUND(((EU34)*AV34*I34),2)*BS34),2))*AU34)/100),2)+ROUND(((ROUND((ROUND(((AE34-(EU34))*AV34*I34),2)*BS34),2)*AU34)/100),2)) -> 0 | AA34: 56661434 | AB34: =ROUND((AC34+AD34+AF34),6) -> 38705.03 | AC34: =ROUND((ES34),6) -> 38705.03 | AD34: =ROUND((((ET34)-(EU34))+AE34),6) -> 0 | AE34: =ROUND((EU34),6) -> 0 | AF34: =ROUND((EV34),6) -> 0 | AG34: =ROUND((AP34),6) -> 0 | AH34: =(EW34) -> 0 | AI34: =(EX34) -> 0 | AJ34: =(AS34) -> 0 | AK34: 38705.03 | AL34: 38705.03 | AM34: 0 | AN34: 0 | AO34: 0 | AP34: 0 | AQ34: 0 | AR34: 0 | AS34: 0 | AT34: 0 | AU34: 0 | AV34: 1 | AW34: 1 | AZ34: 1 | BA34: 1 | BB34: 1 | BC34: 1 | BH34: 3 | BI34: 3 | BJ34: КА, п.1 | BM34: 400007 | BN34: 0 | BP34: 0 | BQ34: 214 | BR34: 0 | BS34: 1 | BT34: 1 | BU34: 1 | BV34: 1 | BW34: 1 | BX34: 1 | BZ34: 0 | CA34: 0 | CE34: 1566 | CF34: 0 | CG34: 0 | CM34: 0 | CO34: 0 | CP34: =(P34+Q34+S34) -> 38705.03 | CQ34: =ROUND((ROUND((AC34*AW34*1),2)*BC34),2) -> 38705.03 | CR34: =(ROUND((ROUND(((ET34)*AV34*1),2)*BB34),2)+ROUND((ROUND(((AE34-(EU34))*AV34*1),2)*BS34),2)) -> 0 | CS34: =(ROUND((ROUND(((EU34)*AV34*1),2)*BS34),2)+ROUND((ROUND(((AE34-(EU34))*AV34*1),2)*BS34),2)) -> 0 | CT34: =ROUND((ROUND((AF34*AV34*1),2)*BA34),2) -> 0 | CU34: =AG34 -> 0 | CV34: =(AH34*AV34) -> 0 | CW34: =AI34 -> 0 | CX34: =AJ34 -> 0 | CY34: =(ROUND((((S34+ROUND((ROUND(((EU34)*AV34*1),2)*BS34),2))*AT34)/100),2)+ROUND(((ROUND((ROUND(((AE34-(EU34))*AV34*1),2)*BS34),2)*AT34)/100),2)) -> 0 | CZ34: =(ROUND((((S34+ROUND((ROUND(((EU34)*AV34*1),2)*BS34),2))*AU34)/100),2)+ROUND(((ROUND((ROUND(((AE34-(EU34))*AV34*1),2)*BS34),2)*AU34)/100),2)) -> 0 | DN34: 0 | DO34: 0 | DP34: 1 | DQ34: 1 | DU34: 1013 | DV34: ШТ | DW34: ШТ | DX34: 1 | EE34: 56938434 | EF34: 214 | EG34: Оборудование, отсутствующие в СНБ | EH34: 0 | EJ34: 3 | EK34: 400007 | EL34: Оборудование, отсутствующие в СНБ | EM34: Оборуд. КА | EQ34: 131088 | ER34: 0 | ES34: 38705.03 | ET34: 0 | EU34: 0 | EV34: 0 | EW34: 0 | EX34: 0 | EY34: 0 | FQ34: 0 | FR34: =P34 -> 38705.03 | FS34: 0 | FX34: 0 | FY34: 0 | GA34: [342 930 / 1,22 / 7,57] + 3% Трансп + 1,2% Заг.скл | GD34: 1 | GF34: 1914587062 | GG34: 2 | GH34: 4 | GI34: -2 | GJ34: 0 | GK34: 0 | GL34: =ROUND(IF(AND(BH34=3,BI34=3,FS34<>0),P34,0),2) -> 0 | GM34: =ROUND(O34+X34+Y34,2)+GX34 -> 38705.03 | GN34: =IF(OR(BI34=0,BI34=1),GM34-GX34,0) -> 0 | GO34: =IF(BI34=2,GM34-GX34,0) -> 0 | GP34: =IF(BI34=4,GM34-GX34,0) -> 0 | GR34: 1 | GS34: 2 | GT34: 0 | GV34: =ROUND((GT34),6) -> 0 | GW34: 1 | GX34: =ROUND(HC34*I34,2) -> 0 | HA34: 0 | HB34: 0 | HC34: =GV34*GW34 -> 0 | HE34: 3 | HF34: 1,2 | HS34: 0 | IK34: 0
A35: 17 | B35: 1 | E35: 2 | F35: КА, п.1 | G35: Приточная установка П1 (L=1890 м3/ч, Pc=500 Па) | H35: ШТ | I35: 1 | J35: 0 | K35: 1 | O35: =ROUND(CP35,2) -> 292997.08 | P35: =ROUND((ROUND((AC35*AW35*I35),2)*BC35),2) -> 292997.08 | Q35: =(ROUND((ROUND(((ET35)*AV35*I35),2)*BB35),2)+ROUND((ROUND(((AE35-(EU35))*AV35*I35),2)*BS35),2)) -> 0 | R35: =(ROUND((ROUND(((EU35)*AV35*I35),2)*BS35),2)+ROUND((ROUND(((AE35-(EU35))*AV35*I35),2)*BS35),2)) -> 0 | S35: =ROUND((ROUND((AF35*AV35*I35),2)*BA35),2) -> 0 | T35: =ROUND(CU35*I35,2) -> 0 | U35: =CV35*I35 -> 0 | V35: =CW35*I35 -> 0 | W35: =ROUND(CX35*I35,2) -> 0 | X35: =(ROUND((((S35+ROUND((ROUND(((EU35)*AV35*I35),2)*BS35),2))*AT35)/100),2)+ROUND(((ROUND((ROUND(((AE35-(EU35))*AV35*I35),2)*BS35),2)*AT35)/100),2)) -> 0 | Y35: =(ROUND((((S35+ROUND((ROUND(((EU35)*AV35*I35),2)*BS35),2))*AU35)/100),2)+ROUND(((ROUND((ROUND(((AE35-(EU35))*AV35*I35),2)*BS35),2)*AU35)/100),2)) -> 0 | AA35: 56661436 | AB35: =ROUND((AC35+AD35+AF35),6) -> 38705.03 | AC35: =ROUND((ES35),6) -> 38705.03 | AD35: =ROUND((((ET35)-(EU35))+AE35),6) -> 0 | AE35: =ROUND((EU35),6) -> 0 | AF35: =ROUND((EV35),6) -> 0 | AG35: =ROUND((AP35),6) -> 0 | AH35: =(EW35) -> 0 | AI35: =(EX35) -> 0 | AJ35: =(AS35) -> 0 | AK35: 38705.03 | AL35: 38705.03 | AM35: 0 | AN35: 0 | AO35: 0 | AP35: 0 | AQ35: 0 | AR35: 0 | AS35: 0 | AT35: 0 | AU35: 0 | AV35: 1 | AW35: 1 | AZ35: 1 | BA35: 1 | BB35: 1 | BC35: 7.57 | BH35: 3 | BI35: 3 | BJ35: КА, п.1 | BM35: 400007 | BN35: 0 | BP35: 0 | BQ35: 214 | BR35: 0 | BS35: 1 | BT35: 1 | BU35: 1 | BV35: 1 | BW35: 1 | BX35: 1 | BZ35: 0 | CA35: 0 | CE35: 1566 | CF35: 0 | CG35: 0 | CM35: 0 | CO35: 0 | CP35: =(P35+Q35+S35) -> 292997.08 | CQ35: =ROUND((ROUND((AC35*AW35*1),2)*BC35),2) -> 292997.08 | CR35: =(ROUND((ROUND(((ET35)*AV35*1),2)*BB35),2)+ROUND((ROUND(((AE35-(EU35))*AV35*1),2)*BS35),2)) -> 0 | CS35: =(ROUND((ROUND(((EU35)*AV35*1),2)*BS35),2)+ROUND((ROUND(((AE35-(EU35))*AV35*1),2)*BS35),2)) -> 0 | CT35: =ROUND((ROUND((AF35*AV35*1),2)*BA35),2) -> 0 | CU35: =AG35 -> 0 | CV35: =(AH35*AV35) -> 0 | CW35: =AI35 -> 0 | CX35: =AJ35 -> 0 | CY35: =(ROUND((((S35+ROUND((ROUND(((EU35)*AV35*1),2)*BS35),2))*AT35)/100),2)+ROUND(((ROUND((ROUND(((AE35-(EU35))*AV35*1),2)*BS35),2)*AT35)/100),2)) -> 0 | CZ35: =(ROUND((((S35+ROUND((ROUND(((EU35)*AV35*1),2)*BS35),2))*AU35)/100),2)+ROUND(((ROUND((ROUND(((AE35-(EU35))*AV35*1),2)*BS35),2)*AU35)/100),2)) -> 0 | DN35: 0 | DO35: 0 | DP35: 1 | DQ35: 1 | DU35: 1013 | DV35: ШТ | DW35: ШТ | DX35: 1 | EE35: 56938434 | EF35: 214 | EG35: Оборудование, отсутствующие в СНБ | EH35: 0 | EJ35: 3 | EK35: 400007 | EL35: Оборудование, отсутствующие в СНБ | EM35: Оборуд. КА | EQ35: 131088 | ER35: 0 | ES35: 38705.03 | ET35: 0 | EU35: 0 | EV35: 0 | EW35: 0 | EX35: 0 | EY35: 0 | EZ35: 5 | FC35: 1 | FD35: 18 | FF35: 342930 | FQ35: 0 | FR35: =P35 -> 292997.08 | FS35: 0 | FX35: 0 | FY35: 0 | GA35: [342 930 / 1,22 / 7,57] + 3% Трансп + 1,2% Заг.скл | GD35: 1 | GF35: 1914587062 | GG35: 2 | GH35: 3 | GI35: 3 | GJ35: 0 | GK35: 0 | GL35: =ROUND(IF(AND(BH35=3,BI35=3,FS35<>0),P35,0),2) -> 0 | GM35: =ROUND(O35+X35+Y35,2)+GX35 -> 292997.08 | GN35: =IF(OR(BI35=0,BI35=1),GM35-GX35,0) -> 0 | GO35: =IF(BI35=2,GM35-GX35,0) -> 0 | GP35: =IF(BI35=4,GM35-GX35,0) -> 0 | GR35: 1 | GS35: 1 | GT35: 0 | GV35: =ROUND((GT35),6) -> 0 | GW35: 1 | GX35: =ROUND(HC35*I35,2) -> 0 | HA35: 0 | HB35: 0 | HC35: =GV35*GW35 -> 0 | HE35: 3 | HF35: 1,2 | HS35: 0 | IK35: 0
A36: 17 | B36: 1 | E36: 3 | F36: КА, п.3 | G36: Приточная установка П2 (L=3600 м3/ч, Pc=500 Па) | H36: ШТ | I36: 1 | J36: 0 | K36: 1 | O36: =ROUND(CP36,2) -> 45981.5 | P36: =ROUND((ROUND((AC36*AW36*I36),2)*BC36),2) -> 45981.5 | Q36: =(ROUND((ROUND(((ET36)*AV36*I36),2)*BB36),2)+ROUND((ROUND(((AE36-(EU36))*AV36*I36),2)*BS36),2)) -> 0 | R36: =(ROUND((ROUND(((EU36)*AV36*I36),2)*BS36),2)+ROUND((ROUND(((AE36-(EU36))*AV36*I36),2)*BS36),2)) -> 0 | S36: =ROUND((ROUND((AF36*AV36*I36),2)*BA36),2) -> 0 | T36: =ROUND(CU36*I36,2) -> 0 | U36: =CV36*I36 -> 0 | V36: =CW36*I36 -> 0 | W36: =ROUND(CX36*I36,2) -> 0 | X36: =(ROUND((((S36+ROUND((ROUND(((EU36)*AV36*I36),2)*BS36),2))*AT36)/100),2)+ROUND(((ROUND((ROUND(((AE36-(EU36))*AV36*I36),2)*BS36),2)*AT36)/100),2)) -> 0 | Y36: =(ROUND((((S36+ROUND((ROUND(((EU36)*AV36*I36),2)*BS36),2))*AU36)/100),2)+ROUND(((ROUND((ROUND(((AE36-(EU36))*AV36*I36),2)*BS36),2)*AU36)/100),2)) -> 0 | AA36: 56661434 | AB36: =ROUND((AC36+AD36+AF36),6) -> 45981.5 | AC36: =ROUND((ES36),6) -> 45981.5 | AD36: =ROUND((((ET36)-(EU36))+AE36),6) -> 0 | AE36: =ROUND((EU36),6) -> 0 | AF36: =ROUND((EV36),6) -> 0 | AG36: =ROUND((AP36),6) -> 0 | AH36: =(EW36) -> 0 | AI36: =(EX36) -> 0 | AJ36: =(AS36) -> 0 | AK36: 45981.5 | AL36: 45981.5 | AM36: 0 | AN36: 0 | AO36: 0 | AP36: 0 | AQ36: 0 | AR36: 0 | AS36: 0 | AT36: 0 | AU36: 0 | AV36: 1 | AW36: 1 | AZ36: 1 | BA36: 1 | BB36: 1 | BC36: 1 | BH36: 3 | BI36: 3 | BJ36: КА, п.3 | BM36: 400007 | BN36: 0 | BP36: 0 | BQ36: 214 | BR36: 0 | BS36: 1 | BT36: 1 | BU36: 1 | BV36: 1 | BW36: 1 | BX36: 1 | BZ36: 0 | CA36: 0 | CE36: 1566 | CF36: 0 | CG36: 0 | CM36: 0 | CO36: 0 | CP36: =(P36+Q36+S36) -> 45981.5 | CQ36: =ROUND((ROUND((AC36*AW36*1),2)*BC36),2) -> 45981.5 | CR36: =(ROUND((ROUND(((ET36)*AV36*1),2)*BB36),2)+ROUND((ROUND(((AE36-(EU36))*AV36*1),2)*BS36),2)) -> 0 | CS36: =(ROUND((ROUND(((EU36)*AV36*1),2)*BS36),2)+ROUND((ROUND(((AE36-(EU36))*AV36*1),2)*BS36),2)) -> 0 | CT36: =ROUND((ROUND((AF36*AV36*1),2)*BA36),2) -> 0 | CU36: =AG36 -> 0 | CV36: =(AH36*AV36) -> 0 | CW36: =AI36 -> 0 | CX36: =AJ36 -> 0 | CY36: =(ROUND((((S36+ROUND((ROUND(((EU36)*AV36*1),2)*BS36),2))*AT36)/100),2)+ROUND(((ROUND((ROUND(((AE36-(EU36))*AV36*1),2)*BS36),2)*AT36)/100),2)) -> 0 | CZ36: =(ROUND((((S36+ROUND((ROUND(((EU36)*AV36*1),2)*BS36),2))*AU36)/100),2)+ROUND(((ROUND((ROUND(((AE36-(EU36))*AV36*1),2)*BS36),2)*AU36)/100),2)) -> 0 | DN36: 0 | DO36: 0 | DP36: 1 | DQ36: 1 | DU36: 1013 | DV36: ШТ | DW36: ШТ | DX36: 1 | EE36: 56938434 | EF36: 214 | EG36: Оборудование, отсутствующие в СНБ | EH36: 0 | EJ36: 3 | EK36: 400007 | EL36: Оборудование, отсутствующие в СНБ | EM36: Оборуд. КА | EQ36: 131088 | ER36: 0 | ES36: 45981.5 | ET36: 0 | EU36: 0 | EV36: 0 | EW36: 0 | EX36: 0 | EY36: 0 | FQ36: 0 | FR36: =P36 -> 45981.5 | FS36: 0 | FX36: 0 | FY36: 0 | GA36: [407 400 / 1,22 / 7,57] + 3% Трансп + 1,2% Заг.скл | GD36: 1 | GF36: 1539617914 | GG36: 2 | GH36: 4 | GI36: -2 | GJ36: 0 | GK36: 0 | GL36: =ROUND(IF(AND(BH36=3,BI36=3,FS36<>0),P36,0),2) -> 0 | GM36: =ROUND(O36+X36+Y36,2)+GX36 -> 45981.5 | GN36: =IF(OR(BI36=0,BI36=1),GM36-GX36,0) -> 0 | GO36: =IF(BI36=2,GM36-GX36,0) -> 0 | GP36: =IF(BI36=4,GM36-GX36,0) -> 0 | GR36: 1 | GS36: 2 | GT36: 0 | GV36: =ROUND((GT36),6) -> 0 | GW36: 1 | GX36: =ROUND(HC36*I36,2) -> 0 | HA36: 0 | HB36: 0 | HC36: =GV36*GW36 -> 0 | HE36: 3 | HF36: 1,2 | HS36: 0 | IK36: 0
A37: 17 | B37: 1 | E37: 3 | F37: КА, п.3 | G37: Приточная установка П2 (L=3600 м3/ч, Pc=500 Па) | H37: ШТ | I37: 1 | J37: 0 | K37: 1 | O37: =ROUND(CP37,2) -> 348079.96 | P37: =ROUND((ROUND((AC37*AW37*I37),2)*BC37),2) -> 348079.96 | Q37: =(ROUND((ROUND(((ET37)*AV37*I37),2)*BB37),2)+ROUND((ROUND(((AE37-(EU37))*AV37*I37),2)*BS37),2)) -> 0 | R37: =(ROUND((ROUND(((EU37)*AV37*I37),2)*BS37),2)+ROUND((ROUND(((AE37-(EU37))*AV37*I37),2)*BS37),2)) -> 0 | S37: =ROUND((ROUND((AF37*AV37*I37),2)*BA37),2) -> 0 | T37: =ROUND(CU37*I37,2) -> 0 | U37: =CV37*I37 -> 0 | V37: =CW37*I37 -> 0 | W37: =ROUND(CX37*I37,2) -> 0 | X37: =(ROUND((((S37+ROUND((ROUND(((EU37)*AV37*I37),2)*BS37),2))*AT37)/100),2)+ROUND(((ROUND((ROUND(((AE37-(EU37))*AV37*I37),2)*BS37),2)*AT37)/100),2)) -> 0 | Y37: =(ROUND((((S37+ROUND((ROUND(((EU37)*AV37*I37),2)*BS37),2))*AU37)/100),2)+ROUND(((ROUND((ROUND(((AE37-(EU37))*AV37*I37),2)*BS37),2)*AU37)/100),2)) -> 0 | AA37: 56661436 | AB37: =ROUND((AC37+AD37+AF37),6) -> 45981.5 | AC37: =ROUND((ES37),6) -> 45981.5 | AD37: =ROUND((((ET37)-(EU37))+AE37),6) -> 0 | AE37: =ROUND((EU37),6) -> 0 | AF37: =ROUND((EV37),6) -> 0 | AG37: =ROUND((AP37),6) -> 0 | AH37: =(EW37) -> 0 | AI37: =(EX37) -> 0 | AJ37: =(AS37) -> 0 | AK37: 45981.5 | AL37: 45981.5 | AM37: 0 | AN37: 0 | AO37: 0 | AP37: 0 | AQ37: 0 | AR37: 0 | AS37: 0 | AT37: 0 | AU37: 0 | AV37: 1 | AW37: 1 | AZ37: 1 | BA37: 1 | BB37: 1 | BC37: 7.57 | BH37: 3 | BI37: 3 | BJ37: КА, п.3 | BM37: 400007 | BN37: 0 | BP37: 0 | BQ37: 214 | BR37: 0 | BS37: 1 | BT37: 1 | BU37: 1 | BV37: 1 | BW37: 1 | BX37: 1 | BZ37: 0 | CA37: 0 | CE37: 1566 | CF37: 0 | CG37: 0 | CM37: 0 | CO37: 0 | CP37: =(P37+Q37+S37) -> 348079.96 | CQ37: =ROUND((ROUND((AC37*AW37*1),2)*BC37),2) -> 348079.96 | CR37: =(ROUND((ROUND(((ET37)*AV37*1),2)*BB37),2)+ROUND((ROUND(((AE37-(EU37))*AV37*1),2)*BS37),2)) -> 0 | CS37: =(ROUND((ROUND(((EU37)*AV37*1),2)*BS37),2)+ROUND((ROUND(((AE37-(EU37))*AV37*1),2)*BS37),2)) -> 0 | CT37: =ROUND((ROUND((AF37*AV37*1),2)*BA37),2) -> 0 | CU37: =AG37 -> 0 | CV37: =(AH37*AV37) -> 0 | CW37: =AI37 -> 0 | CX37: =AJ37 -> 0 | CY37: =(ROUND((((S37+ROUND((ROUND(((EU37)*AV37*1),2)*BS37),2))*AT37)/100),2)+ROUND(((ROUND((ROUND(((AE37-(EU37))*AV37*1),2)*BS37),2)*AT37)/100),2)) -> 0 | CZ37: =(ROUND((((S37+ROUND((ROUND(((EU37)*AV37*1),2)*BS37),2))*AU37)/100),2)+ROUND(((ROUND((ROUND(((AE37-(EU37))*AV37*1),2)*BS37),2)*AU37)/100),2)) -> 0 | DN37: 0 | DO37: 0 | DP37: 1 | DQ37: 1 | DU37: 1013 | DV37: ШТ | DW37: ШТ | DX37: 1 | EE37: 56938434 | EF37: 214 | EG37: Оборудование, отсутствующие в СНБ | EH37: 0 | EJ37: 3 | EK37: 400007 | EL37: Оборудование, отсутствующие в СНБ | EM37: Оборуд. КА | EQ37: 131088 | ER37: 0 | ES37: 45981.5 | ET37: 0 | EU37: 0 | EV37: 0 | EW37: 0 | EX37: 0 | EY37: 0 | EZ37: 5 | FC37: 1 | FD37: 18 | FF37: 407400 | FQ37: 0 | FR37: =P37 -> 348079.96 | FS37: 0 | FX37: 0 | FY37: 0 | GA37: [407 400 / 1,22 / 7,57] + 3% Трансп + 1,2% Заг.скл | GD37: 1 | GF37: 1539617914 | GG37: 2 | GH37: 3 | GI37: 3 | GJ37: 0 | GK37: 0 | GL37: =ROUND(IF(AND(BH37=3,BI37=3,FS37<>0),P37,0),2) -> 0 | GM37: =ROUND(O37+X37+Y37,2)+GX37 -> 348079.96 | GN37: =IF(OR(BI37=0,BI37=1),GM37-GX37,0) -> 0 | GO37: =IF(BI37=2,GM37-GX37,0) -> 0 | GP37: =IF(BI37=4,GM37-GX37,0) -> 0 | GR37: 1 | GS37: 1 | GT37: 0 | GV37: =ROUND((GT37),6) -> 0 | GW37: 1 | GX37: =ROUND(HC37*I37,2) -> 0 | HA37: 0 | HB37: 0 | HC37: =GV37*GW37 -> 0 | HE37: 3 | HF37: 1,2 | HS37: 0 | IK37: 0
A38: 17 | B38: 1 | E38: 4 | F38: КА, п.5 | G38: Приточная установка П3 (L=700 м3/ч, Pc=400 Па) | H38: ШТ | I38: 1 | J38: 0 | K38: 1 | O38: =ROUND(CP38,2) -> 64350.39 | P38: =ROUND((ROUND((AC38*AW38*I38),2)*BC38),2) -> 64350.39 | Q38: =(ROUND((ROUND(((ET38)*AV38*I38),2)*BB38),2)+ROUND((ROUND(((AE38-(EU38))*AV38*I38),2)*BS38),2)) -> 0 | R38: =(ROUND((ROUND(((EU38)*AV38*I38),2)*BS38),2)+ROUND((ROUND(((AE38-(EU38))*AV38*I38),2)*BS38),2)) -> 0 | S38: =ROUND((ROUND((AF38*AV38*I38),2)*BA38),2) -> 0 | T38: =ROUND(CU38*I38,2) -> 0 | U38: =CV38*I38 -> 0 | V38: =CW38*I38 -> 0 | W38: =ROUND(CX38*I38,2) -> 0 | X38: =(ROUND((((S38+ROUND((ROUND(((EU38)*AV38*I38),2)*BS38),2))*AT38)/100),2)+ROUND(((ROUND((ROUND(((AE38-(EU38))*AV38*I38),2)*BS38),2)*AT38)/100),2)) -> 0 | Y38: =(ROUND((((S38+ROUND((ROUND(((EU38)*AV38*I38),2)*BS38),2))*AU38)/100),2)+ROUND(((ROUND((ROUND(((AE38-(EU38))*AV38*I38),2)*BS38),2)*AU38)/100),2)) -> 0 | AA38: 56661434 | AB38: =ROUND((AC38+AD38+AF38),6) -> 64350.39 | AC38: =ROUND((ES38),6) -> 64350.39 | AD38: =ROUND((((ET38)-(EU38))+AE38),6) -> 0 | AE38: =ROUND((EU38),6) -> 0 | AF38: =ROUND((EV38),6) -> 0 | AG38: =ROUND((AP38),6) -> 0 | AH38: =(EW38) -> 0 | AI38: =(EX38) -> 0 | AJ38: =(AS38) -> 0 | AK38: 64350.39 | AL38: 64350.39 | AM38: 0 | AN38: 0 | AO38: 0 | AP38: 0 | AQ38: 0 | AR38: 0 | AS38: 0 | AT38: 0 | AU38: 0 | AV38: 1 | AW38: 1 | AZ38: 1 | BA38: 1 | BB38: 1 | BC38: 1 | BH38: 3 | BI38: 3 | BJ38: КА, п.5 | BM38: 400007 | BN38: 0 | BP38: 0 | BQ38: 214 | BR38: 0 | BS38: 1 | BT38: 1 | BU38: 1 | BV38: 1 | BW38: 1 | BX38: 1 | BZ38: 0 | CA38: 0 | CE38: 1566 | CF38: 0 | CG38: 0 | CM38: 0 | CO38: 0 | CP38: =(P38+Q38+S38) -> 64350.39 | CQ38: =ROUND((ROUND((AC38*AW38*1),2)*BC38),2) -> 64350.39 | CR38: =(ROUND((ROUND(((ET38)*AV38*1),2)*BB38),2)+ROUND((ROUND(((AE38-(EU38))*AV38*1),2)*BS38),2)) -> 0 | CS38: =(ROUND((ROUND(((EU38)*AV38*1),2)*BS38),2)+ROUND((ROUND(((AE38-(EU38))*AV38*1),2)*BS38),2)) -> 0 | CT38: =ROUND((ROUND((AF38*AV38*1),2)*BA38),2) -> 0 | CU38: =AG38 -> 0 | CV38: =(AH38*AV38) -> 0 | CW38: =AI38 -> 0 | CX38: =AJ38 -> 0 | CY38: =(ROUND((((S38+ROUND((ROUND(((EU38)*AV38*1),2)*BS38),2))*AT38)/100),2)+ROUND(((ROUND((ROUND(((AE38-(EU38))*AV38*1),2)*BS38),2)*AT38)/100),2)) -> 0 | CZ38: =(ROUND((((S38+ROUND((ROUND(((EU38)*AV38*1),2)*BS38),2))*AU38)/100),2)+ROUND(((ROUND((ROUND(((AE38-(EU38))*AV38*1),2)*BS38),2)*AU38)/100),2)) -> 0 | DN38: 0 | DO38: 0 | DP38: 1 | DQ38: 1 | DU38: 1013 | DV38: ШТ | DW38: ШТ | DX38: 1 | EE38: 56938434 | EF38: 214 | EG38: Оборудование, отсутствующие в СНБ | EH38: 0 | EJ38: 3 | EK38: 400007 | EL38: Оборудование, отсутствующие в СНБ | EM38: Оборуд. КА | EQ38: 131088 | ER38: 0 | ES38: 64350.39 | ET38: 0 | EU38: 0 | EV38: 0 | EW38: 0 | EX38: 0 | EY38: 0 | FQ38: 0 | FR38: =P38 -> 64350.39 | FS38: 0 | FX38: 0 | FY38: 0 | GA38: [570 150 / 1,22 / 7,57] + 3% Трансп + 1,2% Заг.скл | GD38: 1 | GF38: 125658678 | GG38: 2 | GH38: 4 | GI38: -2 | GJ38: 0 | GK38: 0 | GL38: =ROUND(IF(AND(BH38=3,BI38=3,FS38<>0),P38,0),2) -> 0 | GM38: =ROUND(O38+X38+Y38,2)+GX38 -> 64350.39 | GN38: =IF(OR(BI38=0,BI38=1),GM38-GX38,0) -> 0 | GO38: =IF(BI38=2,GM38-GX38,0) -> 0 | GP38: =IF(BI38=4,GM38-GX38,0) -> 0 | GR38: 1 | GS38: 2 | GT38: 0 | GV38: =ROUND((GT38),6) -> 0 | GW38: 1 | GX38: =ROUND(HC38*I38,2) -> 0 | HA38: 0 | HB38: 0 | HC38: =GV38*GW38 -> 0 | HE38: 3 | HF38: 1,2 | HS38: 0 | IK38: 0
A39: 17 | B39: 1 | E39: 4 | F39: КА, п.5 | G39: Приточная установка П3 (L=700 м3/ч, Pc=400 Па) | H39: ШТ | I39: 1 | J39: 0 | K39: 1 | O39: =ROUND(CP39,2) -> 487132.45 | P39: =ROUND((ROUND((AC39*AW39*I39),2)*BC39),2) -> 487132.45 | Q39: =(ROUND((ROUND(((ET39)*AV39*I39),2)*BB39),2)+ROUND((ROUND(((AE39-(EU39))*AV39*I39),2)*BS39),2)) -> 0 | R39: =(ROUND((ROUND(((EU39)*AV39*I39),2)*BS39),2)+ROUND((ROUND(((AE39-(EU39))*AV39*I39),2)*BS39),2)) -> 0 | S39: =ROUND((ROUND((AF39*AV39*I39),2)*BA39),2) -> 0 | T39: =ROUND(CU39*I39,2) -> 0 | U39: =CV39*I39 -> 0 | V39: =CW39*I39 -> 0 | W39: =ROUND(CX39*I39,2) -> 0 | X39: =(ROUND((((S39+ROUND((ROUND(((EU39)*AV39*I39),2)*BS39),2))*AT39)/100),2)+ROUND(((ROUND((ROUND(((AE39-(EU39))*AV39*I39),2)*BS39),2)*AT39)/100),2)) -> 0 | Y39: =(ROUND((((S39+ROUND((ROUND(((EU39)*AV39*I39),2)*BS39),2))*AU39)/100),2)+ROUND(((ROUND((ROUND(((AE39-(EU39))*AV39*I39),2)*BS39),2)*AU39)/100),2)) -> 0 | AA39: 56661436 | AB39: =ROUND((AC39+AD39+AF39),6) -> 64350.39 | AC39: =ROUND((ES39),6) -> 64350.39 | AD39: =ROUND((((ET39)-(EU39))+AE39),6) -> 0 | AE39: =ROUND((EU39),6) -> 0 | AF39: =ROUND((EV39),6) -> 0 | AG39: =ROUND((AP39),6) -> 0 | AH39: =(EW39) -> 0 | AI39: =(EX39) -> 0 | AJ39: =(AS39) -> 0 | AK39: 64350.39 | AL39: 64350.39 | AM39: 0 | AN39: 0 | AO39: 0 | AP39: 0 | AQ39: 0 | AR39: 0 | AS39: 0 | AT39: 0 | AU39: 0 | AV39: 1 | AW39: 1 | AZ39: 1 | BA39: 1 | BB39: 1 | BC39: 7.57 | BH39: 3 | BI39: 3 | BJ39: КА, п.5 | BM39: 400007 | BN39: 0 | BP39: 0 | BQ39: 214 | BR39: 0 | BS39: 1 | BT39: 1 | BU39: 1 | BV39: 1 | BW39: 1 | BX39: 1 | BZ39: 0 | CA39: 0 | CE39: 1566 | CF39: 0 | CG39: 0 | CM39: 0 | CO39: 0 | CP39: =(P39+Q39+S39) -> 487132.45 | CQ39: =ROUND((ROUND((AC39*AW39*1),2)*BC39),2) -> 487132.45 | CR39: =(ROUND((ROUND(((ET39)*AV39*1),2)*BB39),2)+ROUND((ROUND(((AE39-(EU39))*AV39*1),2)*BS39),2)) -> 0 | CS39: =(ROUND((ROUND(((EU39)*AV39*1),2)*BS39),2)+ROUND((ROUND(((AE39-(EU39))*AV39*1),2)*BS39),2)) -> 0 | CT39: =ROUND((ROUND((AF39*AV39*1),2)*BA39),2) -> 0 | CU39: =AG39 -> 0 | CV39: =(AH39*AV39) -> 0 | CW39: =AI39 -> 0 | CX39: =AJ39 -> 0 | CY39: =(ROUND((((S39+ROUND((ROUND(((EU39)*AV39*1),2)*BS39),2))*AT39)/100),2)+ROUND(((ROUND((ROUND(((AE39-(EU39))*AV39*1),2)*BS39),2)*AT39)/100),2)) -> 0 | CZ39: =(ROUND((((S39+ROUND((ROUND(((EU39)*AV39*1),2)*BS39),2))*AU39)/100),2)+ROUND(((ROUND((ROUND(((AE39-(EU39))*AV39*1),2)*BS39),2)*AU39)/100),2)) -> 0 | DN39: 0 | DO39: 0 | DP39: 1 | DQ39: 1 | DU39: 1013 | DV39: ШТ | DW39: ШТ | DX39: 1 | EE39: 56938434 | EF39: 214 | EG39: Оборудование, отсутствующие в СНБ | EH39: 0 | EJ39: 3 | EK39: 400007 | EL39: Оборудование, отсутствующие в СНБ | EM39: Оборуд. КА | EQ39: 131088 | ER39: 0 | ES39: 64350.39 | ET39: 0 | EU39: 0 | EV39: 0 | EW39: 0 | EX39: 0 | EY39: 0 | EZ39: 5 | FC39: 1 | FD39: 18 | FF39: 570150 | FQ39: 0 | FR39: =P39 -> 487132.45 | FS39: 0 | FX39: 0 | FY39: 0 | GA39: [570 150 / 1,22 / 7,57] + 3% Трансп + 1,2% Заг.скл | GD39: 1 | GF39: 125658678 | GG39: 2 | GH39: 3 | GI39: 3 | GJ39: 0 | GK39: 0 | GL39: =ROUND(IF(AND(BH39=3,BI39=3,FS39<>0),P39,0),2) -> 0 | GM39: =ROUND(O39+X39+Y39,2)+GX39 -> 487132.45 | GN39: =IF(OR(BI39=0,BI39=1),GM39-GX39,0) -> 0 | GO39: =IF(BI39=2,GM39-GX39,0) -> 0 | GP39: =IF(BI39=4,GM39-GX39,0) -> 0 | GR39: 1 | GS39: 1 | GT39: 0 | GV39: =ROUND((GT39),6) -> 0 | GW39: 1 | GX39: =ROUND(HC39*I39,2) -> 0 | HA39: 0 | HB39: 0 | HC39: =GV39*GW39 -> 0 | HE39: 3 | HF39: 1,2 | HS39: 0 | IK39: 0
A40: 17 | B40: 1 | E40: 5 | F40: КА, п.7 | G40: Приточная установка П4 (L=4970 м3/ч, Pc=500 Па) | H40: ШТ | I40: 1 | J40: 0 | K40: 1 | O40: =ROUND(CP40,2) -> 59491.52 | P40: =ROUND((ROUND((AC40*AW40*I40),2)*BC40),2) -> 59491.52 | Q40: =(ROUND((ROUND(((ET40)*AV40*I40),2)*BB40),2)+ROUND((ROUND(((AE40-(EU40))*AV40*I40),2)*BS40),2)) -> 0 | R40: =(ROUND((ROUND(((EU40)*AV40*I40),2)*BS40),2)+ROUND((ROUND(((AE40-(EU40))*AV40*I40),2)*BS40),2)) -> 0 | S40: =ROUND((ROUND((AF40*AV40*I40),2)*BA40),2) -> 0 | T40: =ROUND(CU40*I40,2) -> 0 | U40: =CV40*I40 -> 0 | V40: =CW40*I40 -> 0 | W40: =ROUND(CX40*I40,2) -> 0 | X40: =(ROUND((((S40+ROUND((ROUND(((EU40)*AV40*I40),2)*BS40),2))*AT40)/100),2)+ROUND(((ROUND((ROUND(((AE40-(EU40))*AV40*I40),2)*BS40),2)*AT40)/100),2)) -> 0 | Y40: =(ROUND((((S40+ROUND((ROUND(((EU40)*AV40*I40),2)*BS40),2))*AU40)/100),2)+ROUND(((ROUND((ROUND(((AE40-(EU40))*AV40*I40),2)*BS40),2)*AU40)/100),2)) -> 0 | AA40: 56661434 | AB40: =ROUND((AC40+AD40+AF40),6) -> 59491.52 | AC40: =ROUND((ES40),6) -> 59491.52 | AD40: =ROUND((((ET40)-(EU40))+AE40),6) -> 0 | AE40: =ROUND((EU40),6) -> 0 | AF40: =ROUND((EV40),6) -> 0 | AG40: =ROUND((AP40),6) -> 0 | AH40: =(EW40) -> 0 | AI40: =(EX40) -> 0 | AJ40: =(AS40) -> 0 | AK40: 59491.52 | AL40: 59491.52 | AM40: 0 | AN40: 0 | AO40: 0 | AP40: 0 | AQ40: 0 | AR40: 0 | AS40: 0 | AT40: 0 | AU40: 0 | AV40: 1 | AW40: 1 | AZ40: 1 | BA40: 1 | BB40: 1 | BC40: 1 | BH40: 3 | BI40: 3 | BJ40: КА, п.7 | BM40: 400007 | BN40: 0 | BP40: 0 | BQ40: 214 | BR40: 0 | BS40: 1 | BT40: 1 | BU40: 1 | BV40: 1 | BW40: 1 | BX40: 1 | BZ40: 0 | CA40: 0 | CE40: 1566 | CF40: 0 | CG40: 0 | CM40: 0 | CO40: 0 | CP40: =(P40+Q40+S40) -> 59491.52 | CQ40: =ROUND((ROUND((AC40*AW40*1),2)*BC40),2) -> 59491.52 | CR40: =(ROUND((ROUND(((ET40)*AV40*1),2)*BB40),2)+ROUND((ROUND(((AE40-(EU40))*AV40*1),2)*BS40),2)) -> 0 | CS40: =(ROUND((ROUND(((EU40)*AV40*1),2)*BS40),2)+ROUND((ROUND(((AE40-(EU40))*AV40*1),2)*BS40),2)) -> 0 | CT40: =ROUND((ROUND((AF40*AV40*1),2)*BA40),2) -> 0 | CU40: =AG40 -> 0 | CV40: =(AH40*AV40) -> 0 | CW40: =AI40 -> 0 | CX40: =AJ40 -> 0 | CY40: =(ROUND((((S40+ROUND((ROUND(((EU40)*AV40*1),2)*BS40),2))*AT40)/100),2)+ROUND(((ROUND((ROUND(((AE40-(EU40))*AV40*1),2)*BS40),2)*AT40)/100),2)) -> 0 | CZ40: =(ROUND((((S40+ROUND((ROUND(((EU40)*AV40*1),2)*BS40),2))*AU40)/100),2)+ROUND(((ROUND((ROUND(((AE40-(EU40))*AV40*1),2)*BS40),2)*AU40)/100),2)) -> 0 | DN40: 0 | DO40: 0 | DP40: 1 | DQ40: 1 | DU40: 1013 | DV40: ШТ | DW40: ШТ | DX40: 1 | EE40: 56938434 | EF40: 214 | EG40: Оборудование, отсутствующие в СНБ | EH40: 0 | EJ40: 3 | EK40: 400007 | EL40: Оборудование, отсутствующие в СНБ | EM40: Оборуд. КА | EQ40: 131088 | ER40: 0 | ES40: 59491.52 | ET40: 0 | EU40: 0 | EV40: 0 | EW40: 0 | EX40: 0 | EY40: 0 | FQ40: 0 | FR40: =P40 -> 59491.52 | FS40: 0 | FX40: 0 | FY40: 0 | GA40: [527 100 / 1,22 / 7,57] + 3% Трансп + 1,2% Заг.скл | GD40: 1 | GF40: -585811463 | GG40: 2 | GH40: 4 | GI40: -2 | GJ40: 0 | GK40: 0 | GL40: =ROUND(IF(AND(BH40=3,BI40=3,FS40<>0),P40,0),2) -> 0 | GM40: =ROUND(O40+X40+Y40,2)+GX40 -> 59491.52 | GN40: =IF(OR(BI40=0,BI40=1),GM40-GX40,0) -> 0 | GO40: =IF(BI40=2,GM40-GX40,0) -> 0 | GP40: =IF(BI40=4,GM40-GX40,0) -> 0 | GR40: 1 | GS40: 2 | GT40: 0 | GV40: =ROUND((GT40),6) -> 0 | GW40: 1 | GX40: =ROUND(HC40*I40,2) -> 0 | HA40: 0 | HB40: 0 | HC40: =GV40*GW40 -> 0 | HE40: 3 | HF40: 1,2 | HS40: 0 | IK40: 0
A41: 17 | B41: 1 | E41: 5 | F41: КА, п.7 | G41: Приточная установка П4 (L=4970 м3/ч, Pc=500 Па) | H41: ШТ | I41: 1 | J41: 0 | K41: 1 | O41: =ROUND(CP41,2) -> 450350.81 | P41: =ROUND((ROUND((AC41*AW41*I41),2)*BC41),2) -> 450350.81 | Q41: =(ROUND((ROUND(((ET41)*AV41*I41),2)*BB41),2)+ROUND((ROUND(((AE41-(EU41))*AV41*I41),2)*BS41),2)) -> 0 | R41: =(ROUND((ROUND(((EU41)*AV41*I41),2)*BS41),2)+ROUND((ROUND(((AE41-(EU41))*AV41*I41),2)*BS41),2)) -> 0 | S41: =ROUND((ROUND((AF41*AV41*I41),2)*BA41),2) -> 0 | T41: =ROUND(CU41*I41,2) -> 0 | U41: =CV41*I41 -> 0 | V41: =CW41*I41 -> 0 | W41: =ROUND(CX41*I41,2) -> 0 | X41: =(ROUND((((S41+ROUND((ROUND(((EU41)*AV41*I41),2)*BS41),2))*AT41)/100),2)+ROUND(((ROUND((ROUND(((AE41-(EU41))*AV41*I41),2)*BS41),2)*AT41)/100),2)) -> 0 | Y41: =(ROUND((((S41+ROUND((ROUND(((EU41)*AV41*I41),2)*BS41),2))*AU41)/100),2)+ROUND(((ROUND((ROUND(((AE41-(EU41))*AV41*I41),2)*BS41),2)*AU41)/100),2)) -> 0 | AA41: 56661436 | AB41: =ROUND((AC41+AD41+AF41),6) -> 59491.52 | AC41: =ROUND((ES41),6) -> 59491.52 | AD41: =ROUND((((ET41)-(EU41))+AE41),6) -> 0 | AE41: =ROUND((EU41),6) -> 0 | AF41: =ROUND((EV41),6) -> 0 | AG41: =ROUND((AP41),6) -> 0 | AH41: =(EW41) -> 0 | AI41: =(EX41) -> 0 | AJ41: =(AS41) -> 0 | AK41: 59491.52 | AL41: 59491.52 | AM41: 0 | AN41: 0 | AO41: 0 | AP41: 0 | AQ41: 0 | AR41: 0 | AS41: 0 | AT41: 0 | AU41: 0 | AV41: 1 | AW41: 1 | AZ41: 1 | BA41: 1 | BB41: 1 | BC41: 7.57 | BH41: 3 | BI41: 3 | BJ41: КА, п.7 | BM41: 400007 | BN41: 0 | BP41: 0 | BQ41: 214 | BR41: 0 | BS41: 1 | BT41: 1 | BU41: 1 | BV41: 1 | BW41: 1 | BX41: 1 | BZ41: 0 | CA41: 0 | CE41: 1566 | CF41: 0 | CG41: 0 | CM41: 0 | CO41: 0 | CP41: =(P41+Q41+S41) -> 450350.81 | CQ41: =ROUND((ROUND((AC41*AW41*1),2)*BC41),2) -> 450350.81 | CR41: =(ROUND((ROUND(((ET41)*AV41*1),2)*BB41),2)+ROUND((ROUND(((AE41-(EU41))*AV41*1),2)*BS41),2)) -> 0 | CS41: =(ROUND((ROUND(((EU41)*AV41*1),2)*BS41),2)+ROUND((ROUND(((AE41-(EU41))*AV41*1),2)*BS41),2)) -> 0 | CT41: =ROUND((ROUND((AF41*AV41*1),2)*BA41),2) -> 0 | CU41: =AG41 -> 0 | CV41: =(AH41*AV41) -> 0 | CW41: =AI41 -> 0 | CX41: =AJ41 -> 0 | CY41: =(ROUND((((S41+ROUND((ROUND(((EU41)*AV41*1),2)*BS41),2))*AT41)/100),2)+ROUND(((ROUND((ROUND(((AE41-(EU41))*AV41*1),2)*BS41),2)*AT41)/100),2)) -> 0 | CZ41: =(ROUND((((S41+ROUND((ROUND(((EU41)*AV41*1),2)*BS41),2))*AU41)/100),2)+ROUND(((ROUND((ROUND(((AE41-(EU41))*AV41*1),2)*BS41),2)*AU41)/100),2)) -> 0 | DN41: 0 | DO41: 0 | DP41: 1 | DQ41: 1 | DU41: 1013 | DV41: ШТ | DW41: ШТ | DX41: 1 | EE41: 56938434 | EF41: 214 | EG41: Оборудование, отсутствующие в СНБ | EH41: 0 | EJ41: 3 | EK41: 400007 | EL41: Оборудование, отсутствующие в СНБ | EM41: Оборуд. КА | EQ41: 131088 | ER41: 0 | ES41: 59491.52 | ET41: 0 | EU41: 0 | EV41: 0 | EW41: 0 | EX41: 0 | EY41: 0 | EZ41: 5 | FC41: 1 | FD41: 18 | FF41: 527100 | FQ41: 0 | FR41: =P41 -> 450350.81 | FS41: 0 | FX41: 0 | FY41: 0 | GA41: [527 100 / 1,22 / 7,57] + 3% Трансп + 1,2% Заг.скл | GD41: 1 | GF41: -585811463 | GG41: 2 | GH41: 3 | GI41: 3 | GJ41: 0 | GK41: 0 | GL41: =ROUND(IF(AND(BH41=3,BI41=3,FS41<>0),P41,0),2) -> 0 | GM41: =ROUND(O41+X41+Y41,2)+GX41 -> 450350.81 | GN41: =IF(OR(BI41=0,BI41=1),GM41-GX41,0) -> 0 | GO41: =IF(BI41=2,GM41-GX41,0) -> 0 | GP41: =IF(BI41=4,GM41-GX41,0) -> 0 | GR41: 1 | GS41: 1 | GT41: 0 | GV41: =ROUND((GT41),6) -> 0 | GW41: 1 | GX41: =ROUND(HC41*I41,2) -> 0 | HA41: 0 | HB41: 0 | HC41: =GV41*GW41 -> 0 | HE41: 3 | HF41: 1,2 | HS41: 0 | IK41: 0
A42: 17 | B42: 1 | E42: 6 | F42: КА, п.8 | G42: Приточная установка П5 (L=8010 м3/ч, Pc=700 Па) | H42: ШТ | I42: 1 | J42: 0 | K42: 1 | O42: =ROUND(CP42,2) -> 143952.88 | P42: =ROUND((ROUND((AC42*AW42*I42),2)*BC42),2) -> 143952.88 | Q42: =(ROUND((ROUND(((ET42)*AV42*I42),2)*BB42),2)+ROUND((ROUND(((AE42-(EU42))*AV42*I42),2)*BS42),2)) -> 0 | R42: =(ROUND((ROUND(((EU42)*AV42*I42),2)*BS42),2)+ROUND((ROUND(((AE42-(EU42))*AV42*I42),2)*BS42),2)) -> 0 | S42: =ROUND((ROUND((AF42*AV42*I42),2)*BA42),2) -> 0 | T42: =ROUND(CU42*I42,2) -> 0 | U42: =CV42*I42 -> 0 | V42: =CW42*I42 -> 0 | W42: =ROUND(CX42*I42,2) -> 0 | X42: =(ROUND((((S42+ROUND((ROUND(((EU42)*AV42*I42),2)*BS42),2))*AT42)/100),2)+ROUND(((ROUND((ROUND(((AE42-(EU42))*AV42*I42),2)*BS42),2)*AT42)/100),2)) -> 0 | Y42: =(ROUND((((S42+ROUND((ROUND(((EU42)*AV42*I42),2)*BS42),2))*AU42)/100),2)+ROUND(((ROUND((ROUND(((AE42-(EU42))*AV42*I42),2)*BS42),2)*AU42)/100),2)) -> 0 | AA42: 56661434 | AB42: =ROUND((AC42+AD42+AF42),6) -> 143952.88 | AC42: =ROUND((ES42),6) -> 143952.88 | AD42: =ROUND((((ET42)-(EU42))+AE42),6) -> 0 | AE42: =ROUND((EU42),6) -> 0 | AF42: =ROUND((EV42),6) -> 0 | AG42: =ROUND((AP42),6) -> 0 | AH42: =(EW42) -> 0 | AI42: =(EX42) -> 0 | AJ42: =(AS42) -> 0 | AK42: 143952.88 | AL42: 143952.88 | AM42: 0 | AN42: 0 | AO42: 0 | AP42: 0 | AQ42: 0 | AR42: 0 | AS42: 0 | AT42: 0 | AU42: 0 | AV42: 1 | AW42: 1 | AZ42: 1 | BA42: 1 | BB42: 1 | BC42: 1 | BH42: 3 | BI42: 3 | BJ42: КА, п.8 | BM42: 400007 | BN42: 0 | BP42: 0 | BQ42: 214 | BR42: 0 | BS42: 1 | BT42: 1 | BU42: 1 | BV42: 1 | BW42: 1 | BX42: 1 | BZ42: 0 | CA42: 0 | CE42: 1566 | CF42: 0 | CG42: 0 | CM42: 0 | CO42: 0 | CP42: =(P42+Q42+S42) -> 143952.88 | CQ42: =ROUND((ROUND((AC42*AW42*1),2)*BC42),2) -> 143952.88 | CR42: =(ROUND((ROUND(((ET42)*AV42*1),2)*BB42),2)+ROUND((ROUND(((AE42-(EU42))*AV42*1),2)*BS42),2)) -> 0 | CS42: =(ROUND((ROUND(((EU42)*AV42*1),2)*BS42),2)+ROUND((ROUND(((AE42-(EU42))*AV42*1),2)*BS42),2)) -> 0 | CT42: =ROUND((ROUND((AF42*AV42*1),2)*BA42),2) -> 0 | CU42: =AG42 -> 0 | CV42: =(AH42*AV42) -> 0 | CW42: =AI42 -> 0 | CX42: =AJ42 -> 0 | CY42: =(ROUND((((S42+ROUND((ROUND(((EU42)*AV42*1),2)*BS42),2))*AT42)/100),2)+ROUND(((ROUND((ROUND(((AE42-(EU42))*AV42*1),2)*BS42),2)*AT42)/100),2)) -> 0 | CZ42: =(ROUND((((S42+ROUND((ROUND(((EU42)*AV42*1),2)*BS42),2))*AU42)/100),2)+ROUND(((ROUND((ROUND(((AE42-(EU42))*AV42*1),2)*BS42),2)*AU42)/100),2)) -> 0 | DN42: 0 | DO42: 0 | DP42: 1 | DQ42: 1 | DU42: 1013 | DV42: ШТ | DW42: ШТ | DX42: 1 | EE42: 56938434 | EF42: 214 | EG42: Оборудование, отсутствующие в СНБ | EH42: 0 | EJ42: 3 | EK42: 400007 | EL42: Оборудование, отсутствующие в СНБ | EM42: Оборуд. КА | EQ42: 131088 | ER42: 0 | ES42: 143952.88 | ET42: 0 | EU42: 0 | EV42: 0 | EW42: 0 | EX42: 0 | EY42: 0 | FQ42: 0 | FR42: =P42 -> 143952.88 | FS42: 0 | FX42: 0 | FY42: 0 | GA42: [1 275 435 / 1,22 / 7,57] + 3% Трансп + 1,2% Заг.скл | GD42: 1 | GF42: 1510004595 | GG42: 2 | GH42: 4 | GI42: -2 | GJ42: 0 | GK42: 0 | GL42: =ROUND(IF(AND(BH42=3,BI42=3,FS42<>0),P42,0),2) -> 0 | GM42: =ROUND(O42+X42+Y42,2)+GX42 -> 143952.88 | GN42: =IF(OR(BI42=0,BI42=1),GM42-GX42,0) -> 0 | GO42: =IF(BI42=2,GM42-GX42,0) -> 0 | GP42: =IF(BI42=4,GM42-GX42,0) -> 0 | GR42: 1 | GS42: 2 | GT42: 0 | GV42: =ROUND((GT42),6) -> 0 | GW42: 1 | GX42: =ROUND(HC42*I42,2) -> 0 | HA42: 0 | HB42: 0 | HC42: =GV42*GW42 -> 0 | HE42: 3 | HF42: 1,2 | HS42: 0 | IK42: 0
A43: 17 | B43: 1 | E43: 6 | F43: КА, п.8 | G43: Приточная установка П5 (L=8010 м3/ч, Pc=700 Па) | H43: ШТ | I43: 1 | J43: 0 | K43: 1 | O43: =ROUND(CP43,2) -> 1089723.3 | P43: =ROUND((ROUND((AC43*AW43*I43),2)*BC43),2) -> 1089723.3 | Q43: =(ROUND((ROUND(((ET43)*AV43*I43),2)*BB43),2)+ROUND((ROUND(((AE43-(EU43))*AV43*I43),2)*BS43),2)) -> 0 | R43: =(ROUND((ROUND(((EU43)*AV43*I43),2)*BS43),2)+ROUND((ROUND(((AE43-(EU43))*AV43*I43),2)*BS43),2)) -> 0 | S43: =ROUND((ROUND((AF43*AV43*I43),2)*BA43),2) -> 0 | T43: =ROUND(CU43*I43,2) -> 0 | U43: =CV43*I43 -> 0 | V43: =CW43*I43 -> 0 | W43: =ROUND(CX43*I43,2) -> 0 | X43: =(ROUND((((S43+ROUND((ROUND(((EU43)*AV43*I43),2)*BS43),2))*AT43)/100),2)+ROUND(((ROUND((ROUND(((AE43-(EU43))*AV43*I43),2)*BS43),2)*AT43)/100),2)) -> 0 | Y43: =(ROUND((((S43+ROUND((ROUND(((EU43)*AV43*I43),2)*BS43),2))*AU43)/100),2)+ROUND(((ROUND((ROUND(((AE43-(EU43))*AV43*I43),2)*BS43),2)*AU43)/100),2)) -> 0 | AA43: 56661436 | AB43: =ROUND((AC43+AD43+AF43),6) -> 143952.88 | AC43: =ROUND((ES43),6) -> 143952.88 | AD43: =ROUND((((ET43)-(EU43))+AE43),6) -> 0 | AE43: =ROUND((EU43),6) -> 0 | AF43: =ROUND((EV43),6) -> 0 | AG43: =ROUND((AP43),6) -> 0 | AH43: =(EW43) -> 0 | AI43: =(EX43) -> 0 | AJ43: =(AS43) -> 0 | AK43: 143952.88 | AL43: 143952.88 | AM43: 0 | AN43: 0 | AO43: 0 | AP43: 0 | AQ43: 0 | AR43: 0 | AS43: 0 | AT43: 0 | AU43: 0 | AV43: 1 | AW43: 1 | AZ43: 1 | BA43: 1 | BB43: 1 | BC43: 7.57 | BH43: 3 | BI43: 3 | BJ43: КА, п.8 | BM43: 400007 | BN43: 0 | BP43: 0 | BQ43: 214 | BR43: 0 | BS43: 1 | BT43: 1 | BU43: 1 | BV43: 1 | BW43: 1 | BX43: 1 | BZ43: 0 | CA43: 0 | CE43: 1566 | CF43: 0 | CG43: 0 | CM43: 0 | CO43: 0 | CP43: =(P43+Q43+S43) -> 1089723.3 | CQ43: =ROUND((ROUND((AC43*AW43*1),2)*BC43),2) -> 1089723.3 | CR43: =(ROUND((ROUND(((ET43)*AV43*1),2)*BB43),2)+ROUND((ROUND(((AE43-(EU43))*AV43*1),2)*BS43),2)) -> 0 | CS43: =(ROUND((ROUND(((EU43)*AV43*1),2)*BS43),2)+ROUND((ROUND(((AE43-(EU43))*AV43*1),2)*BS43),2)) -> 0 | CT43: =ROUND((ROUND((AF43*AV43*1),2)*BA43),2) -> 0 | CU43: =AG43 -> 0 | CV43: =(AH43*AV43) -> 0 | CW43: =AI43 -> 0 | CX43: =AJ43 -> 0 | CY43: =(ROUND((((S43+ROUND((ROUND(((EU43)*AV43*1),2)*BS43),2))*AT43)/100),2)+ROUND(((ROUND((ROUND(((AE43-(EU43))*AV43*1),2)*BS43),2)*AT43)/100),2)) -> 0 | CZ43: =(ROUND((((S43+ROUND((ROUND(((EU43)*AV43*1),2)*BS43),2))*AU43)/100),2)+ROUND(((ROUND((ROUND(((AE43-(EU43))*AV43*1),2)*BS43),2)*AU43)/100),2)) -> 0 | DN43: 0 | DO43: 0 | DP43: 1 | DQ43: 1 | DU43: 1013 | DV43: ШТ | DW43: ШТ | DX43: 1 | EE43: 56938434 | EF43: 214 | EG43: Оборудование, отсутствующие в СНБ | EH43: 0 | EJ43: 3 | EK43: 400007 | EL43: Оборудование, отсутствующие в СНБ | EM43: Оборуд. КА | EQ43: 131088 | ER43: 0 | ES43: 143952.88 | ET43: 0 | EU43: 0 | EV43: 0 | EW43: 0 | EX43: 0 | EY43: 0 | EZ43: 5 | FC43: 1 | FD43: 18 | FF43: 1275435 | FQ43: 0 | FR43: =P43 -> 1089723.3 | FS43: 0 | FX43: 0 | FY43: 0 | GA43: [1 275 435 / 1,22 / 7,57] + 3% Трансп + 1,2% Заг.скл | GD43: 1 | GF43: 1510004595 | GG43: 2 | GH43: 3 | GI43: 3 | GJ43: 0 | GK43: 0 | GL43: =ROUND(IF(AND(BH43=3,BI43=3,FS43<>0),P43,0),2) -> 0 | GM43: =ROUND(O43+X43+Y43,2)+GX43 -> 1089723.3 | GN43: =IF(OR(BI43=0,BI43=1),GM43-GX43,0) -> 0 | GO43: =IF(BI43=2,GM43-GX43,0) -> 0 | GP43: =IF(BI43=4,GM43-GX43,0) -> 0 | GR43: 1 | GS43: 1 | GT43: 0 | GV43: =ROUND((GT43),6) -> 0 | GW43: 1 | GX43: =ROUND(HC43*I43,2) -> 0 | HA43: 0 | HB43: 0 | HC43: =GV43*GW43 -> 0 | HE43: 3 | HF43: 1,2 | HS43: 0 | IK43: 0
A44: 17 | B44: 1 | E44: 7 | F44: КА, п.10 | G44: Приточная установка П6 (L=620 м3/ч, Pc=400 Па) | H44: ШТ | I44: 1 | J44: 0 | K44: 1 | O44: =ROUND(CP44,2) -> 31120.46 | P44: =ROUND((ROUND((AC44*AW44*I44),2)*BC44),2) -> 31120.46 | Q44: =(ROUND((ROUND(((ET44)*AV44*I44),2)*BB44),2)+ROUND((ROUND(((AE44-(EU44))*AV44*I44),2)*BS44),2)) -> 0 | R44: =(ROUND((ROUND(((EU44)*AV44*I44),2)*BS44),2)+ROUND((ROUND(((AE44-(EU44))*AV44*I44),2)*BS44),2)) -> 0 | S44: =ROUND((ROUND((AF44*AV44*I44),2)*BA44),2) -> 0 | T44: =ROUND(CU44*I44,2) -> 0 | U44: =CV44*I44 -> 0 | V44: =CW44*I44 -> 0 | W44: =ROUND(CX44*I44,2) -> 0 | X44: =(ROUND((((S44+ROUND((ROUND(((EU44)*AV44*I44),2)*BS44),2))*AT44)/100),2)+ROUND(((ROUND((ROUND(((AE44-(EU44))*AV44*I44),2)*BS44),2)*AT44)/100),2)) -> 0 | Y44: =(ROUND((((S44+ROUND((ROUND(((EU44)*AV44*I44),2)*BS44),2))*AU44)/100),2)+ROUND(((ROUND((ROUND(((AE44-(EU44))*AV44*I44),2)*BS44),2)*AU44)/100),2)) -> 0 | AA44: 56661434 | AB44: =ROUND((AC44+AD44+AF44),6) -> 31120.46 | AC44: =ROUND((ES44),6) -> 31120.46 | AD44: =ROUND((((ET44)-(EU44))+AE44),6) -> 0 | AE44: =ROUND((EU44),6) -> 0 | AF44: =ROUND((EV44),6) -> 0 | AG44: =ROUND((AP44),6) -> 0 | AH44: =(EW44) -> 0 | AI44: =(EX44) -> 0 | AJ44: =(AS44) -> 0 | AK44: 31120.46 | AL44: 31120.46 | AM44: 0 | AN44: 0 | AO44: 0 | AP44: 0 | AQ44: 0 | AR44: 0 | AS44: 0 | AT44: 0 | AU44: 0 | AV44: 1 | AW44: 1 | AZ44: 1 | BA44: 1 | BB44: 1 | BC44: 1 | BH44: 3 | BI44: 3 | BJ44: КА, п.10 | BM44: 400007 | BN44: 0 | BP44: 0 | BQ44: 214 | BR44: 0 | BS44: 1 | BT44: 1 | BU44: 1 | BV44: 1 | BW44: 1 | BX44: 1 | BZ44: 0 | CA44: 0 | CE44: 1566 | CF44: 0 | CG44: 0 | CM44: 0 | CO44: 0 | CP44: =(P44+Q44+S44) -> 31120.46 | CQ44: =ROUND((ROUND((AC44*AW44*1),2)*BC44),2) -> 31120.46 | CR44: =(ROUND((ROUND(((ET44)*AV44*1),2)*BB44),2)+ROUND((ROUND(((AE44-(EU44))*AV44*1),2)*BS44),2)) -> 0 | CS44: =(ROUND((ROUND(((EU44)*AV44*1),2)*BS44),2)+ROUND((ROUND(((AE44-(EU44))*AV44*1),2)*BS44),2)) -> 0 | CT44: =ROUND((ROUND((AF44*AV44*1),2)*BA44),2) -> 0 | CU44: =AG44 -> 0 | CV44: =(AH44*AV44) -> 0 | CW44: =AI44 -> 0 | CX44: =AJ44 -> 0 | CY44: =(ROUND((((S44+ROUND((ROUND(((EU44)*AV44*1),2)*BS44),2))*AT44)/100),2)+ROUND(((ROUND((ROUND(((AE44-(EU44))*AV44*1),2)*BS44),2)*AT44)/100),2)) -> 0 | CZ44: =(ROUND((((S44+ROUND((ROUND(((EU44)*AV44*1),2)*BS44),2))*AU44)/100),2)+ROUND(((ROUND((ROUND(((AE44-(EU44))*AV44*1),2)*BS44),2)*AU44)/100),2)) -> 0 | DN44: 0 | DO44: 0 | DP44: 1 | DQ44: 1 | DU44: 1013 | DV44: ШТ | DW44: ШТ | DX44: 1 | EE44: 56938434 | EF44: 214 | EG44: Оборудование, отсутствующие в СНБ | EH44: 0 | EJ44: 3 | EK44: 400007 | EL44: Оборудование, отсутствующие в СНБ | EM44: Оборуд. КА | EQ44: 131088 | ER44: 0 | ES44: 31120.46 | ET44: 0 | EU44: 0 | EV44: 0 | EW44: 0 | EX44: 0 | EY44: 0 | FQ44: 0 | FR44: =P44 -> 31120.46 | FS44: 0 | FX44: 0 | FY44: 0 | GA44: [275 730 / 1,22 / 7,57] + 3% Трансп + 1,2% Заг.скл | GD44: 1 | GF44: -2046315333 | GG44: 2 | GH44: 4 | GI44: -2 | GJ44: 0 | GK44: 0 | GL44: =ROUND(IF(AND(BH44=3,BI44=3,FS44<>0),P44,0),2) -> 0 | GM44: =ROUND(O44+X44+Y44,2)+GX44 -> 31120.46 | GN44: =IF(OR(BI44=0,BI44=1),GM44-GX44,0) -> 0 | GO44: =IF(BI44=2,GM44-GX44,0) -> 0 | GP44: =IF(BI44=4,GM44-GX44,0) -> 0 | GR44: 1 | GS44: 2 | GT44: 0 | GV44: =ROUND((GT44),6) -> 0 | GW44: 1 | GX44: =ROUND(HC44*I44,2) -> 0 | HA44: 0 | HB44: 0 | HC44: =GV44*GW44 -> 0 | HE44: 3 | HF44: 1,2 | HS44: 0 | IK44: 0
