Workbook

Sheet Смета по ТСН-2001(с доп.67
A1: =Source!B1 -> Smeta.RU (495) 974-1589
J2: Форма № 4б
A3: Капитальный ремонт здания Государственного бюджетного общеобразовательного учреждения города Москвы «Школа №1574» по адресу: г. Москва, Старопименовский пер., д. №5. | AP3: Капитальный ремонт здания Государственного бюджетного общеобразовательного учреждения города Москвы «Школа №1574» по адресу: г. Москва, Старопименовский пер., д. №5. 02-01-21 Спринклерное пожаротушение
A4: (наименование стройки и/или объекта)
A6: =CONCATENATE( "ЛОКАЛЬНАЯ СМЕТА № ",IF(Source!F12<>"Новый объект", Source!F12, "")) -> ЛОКАЛЬНАЯ СМЕТА № 02-01-21
A8: Спринклерное пожаротушение
A9: (наименование работ и затрат)
A11: =CONCATENATE( "Основание: чертежи № ", Source!J12) -> Основание: чертежи № 2024-00375-01-0-ИОС2.2
I13: В базисном уровне цен | J13: В текущем уровне цен
E14: Сметная стоимость | I14: =I15+I16+I17+I18 -> 754.65 | J14: =J15+J16+J17+J18 -> 15937.04 | K14: тыс.руб.
E15: Строительные работы | I15: =ROUND((Source!F368)/1000, 2) -> 17 | J15: =ROUND((Source!P368)/1000, 2) -> 410.92 | K15: тыс.руб.
E16: Работы по монтажу оборудования | I16: =ROUND((Source!F369)/1000, 2) -> 528.86 | J16: =ROUND((Source!P369)/1000, 2) -> 13945.56 | K16: тыс.руб.
E17: Оборудование | I17: =ROUND((Source!F360)/1000, 2) -> 208.79 | J17: =ROUND((Source!P360)/1000, 2) -> 1580.56 | K17: тыс.руб.
E18: Прочие работы и затраты | I18: =ROUND((Source!F370+Source!F371)/1000, 2) -> 0 | J18: =ROUND((Source!P370+Source!P371)/1000, 2) -> 0 | K18: тыс.руб.
E19: Средства на оплату труда | I19: =(Source!F366+ Source!F365)/1000 -> 79.48296 | J19: =((Source!P366 + Source!P365)/1000) -> 4478.8648 | K19: тыс.руб.
E20: Затраты труда | I20: =Source!F373 -> 6037.8927 | K20: чел.-ч.
E21: Кроме того:
E22: Возврат материалов | I22: =SUM(Y1:Y462)/1000 -> 0 | J22: =SUM(Z1:Z462)/1000 -> 0 | K22: тыс.руб.
A24: Составлен(а) по ТСН-2001 с учетом Дополнения №: 81
A25: № и период сборника коэффициентов (индексов) пересчета: Коэффициенты к ТСН-2001 МГЭ Дополнение 81, ремонт №219/81 I квартал 2026 года и Коэффициенты к ТСН-2001.13-2 Дополнение 47 №64/47 I квартал 2026 года | AP25: № и период сборника коэффициентов (индексов) пересчета: Коэффициенты к ТСН-2001 МГЭ Дополнение 81, ремонт №219/81 I квартал 2026 года и Коэффициенты к ТСН-2001.13-2 Дополнение 47 №64/47 I квартал 2026 года
A26: № п/п | B26: Шифр расценки и коды ресурсов | C26: Наименование работ и затрат | D26: Ед. изм. | E26: Кол-во единиц | F26: Цена на ед. изм., руб. | G26: Попра- вочные коэффи- циенты | H26: Коэффи- циенты зимних удорожа- ний | I26: Всего в ценах на январь 2000 года, руб. | J26: Коэффи- циенты (индек- сы) пере- счета, нормы НР и СП | K26: ВСЕГО затрат в текущем уровне цен, руб.
A27: 1 | B27: 2 | C27: 3 | D27: 4 | E27: 5 | F27: 6 | G27: 7 | H27: 8 | I27: 9 | J27: 10 | K27: 11
A29: =CONCATENATE("Локальная смета: ",IF(Source!G20<>"Новая локальная смета", Source!G20, "")) -> Локальная смета: Спринклерное пожаротушение.
A31: =CONCATENATE("Раздел: ",IF(Source!G24<>"Новый раздел", Source!G24, "")) -> Раздел: Насосная установка.
A32: 1 | B32: =Source!F30 -> 3.18-11-2 | C32: Установка насосов центробежных с электродвигателем массой агрегата до 0,2 т | D32: =Source!H30 -> 1 насос | E32: =Source!I30 -> 1 | Q32: =Source!X30 -> 356.79 | R32: =Source!X31 -> 20105.26 | S32: =Source!Y30 -> 212.31 | T32: =Source!Y31 -> 11963.46 | U32: =ROUND((175/100)*ROUND(Source!R30, 2), 2) -> 4.01 | V32: =ROUND((0/100)*ROUND(Source!R31, 2), 2) -> 0 | AC32: 0
C33: ЗП | F33: =Source!AO30 -> 198.7 | G33: 1,2*1,15 | H33: =Source!AV31 -> 1.067 | I33: =Source!S30 -> 292.58 | J33: =IF(Source!BA31<> 0, Source!BA31, 1) -> 56.35 | K33: =Source!S31 -> 16486.88
C34: ЭМ | F34: =Source!AM30 -> 15.92 | G34: 1,2*1,25 | H34: =Source!AV31 -> 1.067 | I34: =Source!Q30 -> 25.48 | J34: =IF(Source!BB31<> 0, Source!BB31, 1) -> 15.03 | K34: =Source!Q31 -> 382.96
C35: в т.ч. ЗПМ | F35: =Source!AN30 -> 1.43 | G35: 1,2*1,25 | H35: =Source!AV31 -> 1.067 | I35: =Source!R30 -> 2.29 | J35: =IF(Source!BS31<> 0, Source!BS31, 1) -> 56.35 | K35: =Source!R31 -> 129.04
C36: МР | F36: =Source!AL30 -> 172.01 | H36: =Source!AW31 -> 1 | I36: =Source!P30 -> 172.01 | J36: =IF(Source!BC31<> 0, Source!BC31, 1) -> 7.27 | K36: =Source!P31 -> 1250.51
C37: НР от ФОТ | D37: % | E37: =Source!BZ31 -> 121 | I37: =SUM(Q32:Q36) -> 356.79 | J37: =Source!AT31 -> 121 | K37: =SUM(R32:R36) -> 20105.26
C38: СП от ФОТ | D38: % | E38: =Source!CA31 -> 72 | I38: =SUM(S32:S37) -> 212.31 | J38: =Source!AU31 -> 72 | K38: =SUM(T32:T37) -> 11963.46
C39: ЗТР | D39: чел-ч | E39: =Source!AQ30 -> 16.3 | G39: 1,2*1,15 | H39: =Source!AV31 -> 1.067 | I39: =Source!U30 -> 24.001098
C40: ВСЕГО работ по позиции: | H40: =I33+I34+I36+I37+I38+0-0-0 -> 1059.17 | J40: =K33+K34+K36+K37+K38+0-0-0 -> 50189.07
C41: ВСЕГО оборудование по позиции: | H41: =0+0 -> 0 | J41: =0+0 -> 0
C42: ВСЕГО по позиции: | H42: =I33+I34+I36+I37+I38+0 -> 1059.17 | J42: =K33+K34+K36+K37+K38+0 -> 50189.07 | O42: =I33+I34+I36+I37+I38+0 -> 1059.17 | P42: =K33+K34+K36+K37+K38+0 -> 50189.07
A44: 2 | B44: =Source!F34 -> 3.17-10-1 | C44: Установка насосов погружных центробежных фекальных с электродвигателем производительностью 10 м3/час | D44: =Source!H34 -> 1 ШТ. | E44: =Source!I34 -> 1 | Q44: =Source!X34 -> 289.44 | R44: =Source!X35 -> 16310.18 | S44: =Source!Y34 -> 172.23 | T44: =Source!Y35 -> 9705.23 | U44: =ROUND((175/100)*ROUND(Source!R34, 2), 2) -> 0.84 | V44: =ROUND((0/100)*ROUND(Source!R35, 2), 2) -> 0 | AC44: 0
C45: ЗП | F45: =Source!AO34 -> 162.13 | G45: 1,2*1,15 | H45: =Source!AV35 -> 1.067 | I45: =Source!S34 -> 238.73 | J45: =IF(Source!BA35<> 0, Source!BA35, 1) -> 56.35 | K45: =Source!S35 -> 13452.44
C46: ЭМ | F46: =Source!AM34 -> 6.25 | G46: 1,2*1,25 | H46: =Source!AV35 -> 1.067 | I46: =Source!Q34 -> 10 | J46: =IF(Source!BB35<> 0, Source!BB35, 1) -> 14.22 | K46: =Source!Q35 -> 142.2
C47: в т.ч. ЗПМ | F47: =Source!AN34 -> 0.3 | G47: 1,2*1,25 | H47: =Source!AV35 -> 1.067 | I47: =Source!R34 -> 0.48 | J47: =IF(Source!BS35<> 0, Source!BS35, 1) -> 56.35 | K47: =Source!R35 -> 27.05
C48: МР | F48: =Source!AL34 -> 109.65 | H48: =Source!AW35 -> 1 | I48: =Source!P34 -> 109.65 | J48: =IF(Source!BC35<> 0, Source!BC35, 1) -> 7.21 | K48: =Source!P35 -> 790.58
...

Sheet Source
A1: 0 | B1: Smeta.RU (495) 974-1589 | D1: _PS_ | F1: 0 | G1: 0 | H1: 0 | I1: Smeta.RU | K1: 1 | L1: 74598 | M1: 10 | N1: 12 | O1: 1 | P1: 0 | Q1: 5
A4: 1 | B4: 1 | C4: -1 | G4: Капитальный ремонт здания Государственного бюджетного общеобразовательного учреждения города Москвы «Школа №1574» по адресу: г. Москва, Старопименовский пер., д. №5 | EC4: 0
A5: 8 | B5: 1 | C5: -1 | G5: Капитальный ремонт здания Государственного бюджетного общеобразовательного учреждения города Москвы «Школа №1574» по адресу: г. Москва, Старопименовский пер., д. №5 | EC5: 0
A12: 1 | B12: 393 | C12: 0 | D12: =ROW(A351) -> 351 | E12: 0 | F12: 02-01-21 | G12: 02-01-21 Спринклерное пожаротушение | I12: 0 | J12: 2024-00375-01-0-ИОС2.2 | K12: 0 | L12: 0 | M12: 4098 | O12: 0 | P12: 0 | Q12: 0 | R12: 0 | S12: 0 | T12: 1 | V12: 2 | AB12: Гришечкина О.А. | AC12: Ведущий инженер-сметчик | AD12: Феденко И.В. | AE12: Руководитель сметного отдела | BB12: 0 | BH12: Сметные нормы списания | BI12: Коды ОКП для ТСН-2001 МГЭ Дополнение 81 | BJ12: 1 | BK12: 1 | BL12: 0 | BM12: 0 | BN12: 1 | BO12: 0 | BP12: 6 | BQ12: 2 | BR12: 1 | BS12: 1 | BT12: 0 | BU12: 0 | BV12: 0 | BW12: 0 | BX12: 0 | BY12: ТСН-2001 (МГЭ) Доп 81 - Новое строительство | BZ12: Типовой расчет для ТСН-2001 МГЭ, Дополнение 81, строительство | CA12: Территориальные сметные нормативы для Москвы ТСН-2001 (МГЭ), дополнение 81 | CB12: Территориальные сметные нормативы для Москвы ТСН-2001 (МГЭ), дополнение 81 | CC12: Территориальные сметные нормативы для Москвы ТСН-2001 (МГЭ), дополнение 81 | CD12: Территориальные сметные нормативы для Москвы ТСН-2001 (МГЭ), дополнение 81 | CE12: Поправки для ТСН-2001 от 07.04.2026 г. доп.81 | CF12: 0 | CG12: 0 | CH12: 8200 | CK12: 82 | CQ12: Территориальные сметные нормативы для Москвы (ТСН-2001) | CR12: ТЕР | CS12: 41660 | CT12: 1 | CU12: 81 | CY12: 0 | EC12: 0
A15: 15 | B15: 1
A18: 52 | B18: =B351 -> 393 | C18: =C351 -> 1 | D18: =D351 -> 12 | E18: =E351 -> 0 | F18: =F351 -> 02-01-21 | G18: =G351 -> 02-01-21 Спринклерное пожаротушение | O18: =O351 -> 645901.78 | P18: =P351 -> 549189.04 | Q18: =Q351 -> 21097.16 | R18: =R351 -> 3867.38 | S18: =S351 -> 75615.58 | T18: =T351 -> 0 | U18: =U351 -> 6037.8927 | V18: =V351 -> 0 | ... GX18: =GX351 -> 0
A20: 3 | B20: 1 | D20: =ROW(A318) -> 318 | F20: 02-01-21 | G20: Спринклерное пожаротушение. | I20: 0 | J20: 2024-00375-01-0-ИОС2.2 | K20: -1 | L20: 02-01-21 | S20: 0 | T20: 0 | V20: 2 | AB20: Гришечкина О.А. | AC20: Ведущий инженер-сметчик | AD20: Феденко И.В. | AE20: Руководитель сметного отдела | BX20: 0 | CF20: 0 | CG20: 0
A22: 52 | B22: =B318 -> 1 | C22: =C318 -> 3 | D22: =D318 -> 20 | E22: =E318 -> 0 | F22: =F318 -> 02-01-21 | G22: =G318 -> Спринклерное пожаротушение. | O22: =O318 -> 645901.78 | P22: =P318 -> 549189.04 | Q22: =Q318 -> 21097.16 | R22: =R318 -> 3867.38 | S22: =S318 -> 75615.58 | T22: =T318 -> 0 | U22: =U318 -> 6037.8927 | V22: =V318 -> 0 | ... GX22: =GX318 -> 0
A24: 4 | B24: 1 | D24: =ROW(A167) -> 167 | F24: Новый раздел | G24: Насосная установка. | I24: 0 | K24: 0 | S24: 0 | T24: 0 | V24: 2 | BX24: 0 | CJ24: 0
A26: 52 | B26: =B167 -> 1 | C26: =C167 -> 4 | D26: =D167 -> 24 | E26: =E167 -> 0 | F26: =F167 -> Новый раздел | G26: =G167 -> Насосная установка. | O26: =O167 -> 278528.64 | P26: =P167 -> 270042.49 | Q26: =Q167 -> 1757.79 | R26: =R167 -> 297.02 | S26: =S167 -> 6728.36 | T26: =T167 -> 0 | U26: =U167 -> 531.97169 | V26: =V167 -> 0 | ... GX26: =GX167 -> 0
A28: 17 | B28: 1 | C28: =ROW(SmtRes!A10) -> 10 | D28: =ROW(EtalonRes!A11) -> 11 | F28: 4.7-21-3 | G28: Монтаж насосного агрегата лопастного центробежного одноступенчатого, многоступенчатого объемного, вихревого, поршневого, приводного, роторного на общей фундаментной плите или моноблочный массой 0,425 т | H28: 1 ШТ. | I28: 2 | J28: 0 | K28: 2 | O28: =ROUND(CP28,2) -> 908.21 | P28: =ROUND((ROUND((AC28*AW28*I28),2)*BC28),2) -> 70.21 | Q28: =(ROUND((ROUND(((((ET28*0.75)*1.2))*AV28*I28),2)*BB28),2)+ROUND((ROUND(((AE28-(((EU28*0.75)*1.2)))*AV28*I28),2)*BS28),2)) -> 80.82 | R28: =(ROUND((ROUND(((((EU28*0.75)*1.2))*AV28*I28),2)*BS28),2)+ROUND((ROUND(((AE28-(((EU28*0.75)*1.2)))*AV28*I28),2)*BS28),2)) -> 5.57 | S28: =ROUND((ROUND((AF28*AV28*I28),2)*BA28),2) -> 757.18 | T28: =ROUND(CU28*I28,2) -> 0 | U28: =CV28*I28 -> 61.4592 | V28: =CW28*I28 -> 0 | W28: =ROUND(CX28*I28,2) -> 0 | X28: =(ROUND((((S28+ROUND((ROUND(((((EU28*0.75)*1.2))*AV28*I28),2)*BS28),2))*AT28)/100),2)+ROUND(((ROUND((ROUND(((AE28-(((EU28*0.75)*1.2)))*AV28*I28),2)*BS28),2)*AT28)/100),2)) -> 694.1 | Y28: =(ROUND((((S28+ROUND((ROUND(((((EU28*0.75)*1.2))*AV28*I28),2)*BS28),2))*AU28)/100),2)+ROUND(((ROUND((ROUND(((AE28-(((EU28*0.75)*1.2)))*AV28*I28),2)*BS28),2)*AU28)/100),2)) -> 358.49 | AA28: -1 | AB28: =ROUND((AC28+AD28+AF28),6) -> 426.8355 | AC28: =ROUND((((ES28*0.75)*1)),6) -> 34.1475 | AD28: =ROUND((((((ET28*0.75)*1.2))-(((EU28*0.75)*1.2)))+AE28),6) -> 37.872 | AE28: =ROUND((((EU28*0.75)*1.2)),6) -> 2.61 | AF28: =ROUND((((EV28*0.75)*1.2)),6) -> 354.816 | AG28: =ROUND((AP28),6) -> 0 | AH28: =(((EW28*0.75)*1.2)) -> 28.8 | AI28: =(((EX28*0.75)*1.2)) -> 0 | AJ28: =(AS28) -> 0 | AK28: 481.85 | AL28: 45.53 | AM28: 42.08 | AN28: 2.9 | AO28: 394.24 | AP28: 0 | AQ28: 32 | AR28: 0 | AS28: 0 | AT28: 91 | AU28: 47 | AV28: 1.067 | AW28: 1.028 | AZ28: 1 | BA28: 1 | BB28: 1 | BC28: 1 | BH28: 0 | BI28: 2 | BJ28: ТСН-2001.4 Доп. 80, Сб. 7, т. 21, поз. 3 | BM28: 66 | BN28: 0 | BO28: 4.7-21-3 | BP28: 1 | BQ28: 40 | BR28: 0 | BS28: 1 | BT28: 1 | BU28: 1 | BV28: 1 | BW28: 1 | BX28: 1 | BZ28: 91 | CA28: 47 | CE28: 1566 | CF28: 0 | CG28: 0 | CM28: 0 | CN28: Поправка: Гл.4.Прил.2.2.п.2.2.17_04.00.01.24.001 Наименование: При разнице в массе оборудования более 10% к норме и расценке ближайшего по массе оборудования при коэффициенте изменения массы оборудования до 0,5 т Поправка: Гл.12.Прил.8.п.8. 3_12.00.01.11.001 Наименование: При наличии напряженных и стесненных условий производства работ (стесненность, сложность складирования и транспортной логистики и т.п.) для объектов, расположенных в пределах круговой магистральной системы улиц "Садовое кольцо" города Москвы | CO28: 0 | CP28: =(P28+Q28+S28) -> 908.21 | CQ28: =ROUND((ROUND((AC28*AW28*1),2)*BC28),2) -> 35.1 | CR28: =(ROUND((ROUND(((((ET28*0.75)*1.2))*AV28*1),2)*BB28),2)+ROUND((ROUND(((AE28-(((EU28*0.75)*1.2)))*AV28*1),2)*BS28),2)) -> 40.41 | CS28: =(ROUND((ROUND(((((EU28*0.75)*1.2))*AV28*1),2)*BS28),2)+ROUND((ROUND(((AE28-(((EU28*0.75)*1.2)))*AV28*1),2)*BS28),2)) -> 2.78 | CT28: =ROUND((ROUND((AF28*AV28*1),2)*BA28),2) -> 378.59 | CU28: =AG28 -> 0 | CV28: =(AH28*AV28) -> 30.7296 | CW28: =AI28 -> 0 | CX28: =AJ28 -> 0 | CY28: =(ROUND((((S28+ROUND((ROUND(((((EU28*0.75)*1.2))*AV28*1),2)*BS28),2))*AT28)/100),2)+ROUND(((ROUND((ROUND(((AE28-(((EU28*0.75)*1.2)))*AV28*1),2)*BS28),2)*AT28)/100),2)) -> 691.56 | CZ28: =(ROUND((((S28+ROUND((ROUND(((((EU28*0.75)*1.2))*AV28*1),2)*BS28),2))*AU28)/100),2)+ROUND(((ROUND((ROUND(((AE28-(((EU28*0.75)*1.2)))*AV28*1),2)*BS28),2)*AU28)/100),2)) -> 357.18 | DB28: 1 | DD28: *0,75)*1 | DE28: *0,75)*1,2 | DF28: *0,75)*1,2 | DG28: *0,75)*1,2 | DI28: *0,75)*1,2 | DJ28: *0,75)*1,2 | DN28: 0 | DO28: 0 | DP28: 1 | DQ28: 1 | DU28: 1013 | DV28: 1 ШТ. | DW28: 1 ШТ. | DX28: 1 | EE28: 56938733 | EF28: 40 | EG28: Монтаж оборудования | EH28: 0 | EJ28: 2 | EK28: 66 | EL28: ТСН-2001.4-7. Компрессорные машины, насосы, вентиляторы | EM28: ТСН-2001.4-7-1 | EO28: Поправка: Гл.4.Прил.2.2.п.2.2.17_04.00.01.24.001 Поправка: Гл.12.Прил.8.п.8. 3_12.00.01.11.001 | EQ28: 132096 | ER28: 481.85 | ES28: 45.53 | ET28: 42.08 | EU28: 2.9 | EV28: 394.24 | EW28: 32 | EX28: 0 | EY28: 0 | FQ28: 0 | FR28: 0 | FS28: 2 | FX28: 91 | FY28: 47 | GD28: 1 | GF28: 2029985936 | GG28: 2 | GH28: 1 | GI28: 2 | GJ28: 0 | GK28: 0 | GL28: =ROUND(IF(AND(BH28=3,BI28=3,FS28<>0),P28,0),2) -> 0 | GM28: =ROUND(O28+X28+Y28,2)+GX28 -> 1960.8 | GN28: =IF(OR(BI28=0,BI28=1),GM28-GX28,0) -> 0 | GO28: =IF(BI28=2,GM28-GX28,0) -> 1960.8 | GP28: =IF(BI28=4,GM28-GX28,0) -> 0 | GR28: 0 | GS28: 3 | GT28: 0 | GV28: =ROUND((GT28),6) -> 0 | GW28: 1 | GX28: =ROUND(HC28*I28,2) -> 0 | HA28: 0 | HB28: 0 | HC28: =GV28*GW28 -> 0 | HS28: 0 | IK28: 0
A29: 17 | B29: 1 | C29: =ROW(SmtRes!A20) -> 20 | D29: =ROW(EtalonRes!A22) -> 22 | F29: 4.7-21-3 | G29: Монтаж насосного агрегата лопастного центробежного одноступенчатого, многоступенчатого объемного, вихревого, поршневого, приводного, роторного на общей фундаментной плите или моноблочный массой 0,425 т | H29: 1 ШТ. | I29: 2 | J29: 0 | K29: 2 | O29: =ROUND(CP29,2) -> 44699.5 | P29: =ROUND((ROUND((AC29*AW29*I29),2)*BC29),2) -> 841.12 | Q29: =(ROUND((ROUND(((((ET29*0.75)*1.2))*AV29*I29),2)*BB29),2)+ROUND((ROUND(((AE29-(((EU29*0.75)*1.2)))*AV29*I29),2)*BS29),2)) -> 1191.29 | R29: =(ROUND((ROUND(((((EU29*0.75)*1.2))*AV29*I29),2)*BS29),2)+ROUND((ROUND(((AE29-(((EU29*0.75)*1.2)))*AV29*I29),2)*BS29),2)) -> 313.87 | S29: =ROUND((ROUND((AF29*AV29*I29),2)*BA29),2) -> 42667.09 | T29: =ROUND(CU29*I29,2) -> 0 | U29: =CV29*I29 -> 61.4592 | V29: =CW29*I29 -> 0 | W29: =ROUND(CX29*I29,2) -> 0 | X29: =(ROUND((((S29+ROUND((ROUND(((((EU29*0.75)*1.2))*AV29*I29),2)*BS29),2))*AT29)/100),2)+ROUND(((ROUND((ROUND(((AE29-(((EU29*0.75)*1.2)))*AV29*I29),2)*BS29),2)*AT29)/100),2)) -> 39112.67 | Y29: =(ROUND((((S29+ROUND((ROUND(((((EU29*0.75)*1.2))*AV29*I29),2)*BS29),2))*AU29)/100),2)+ROUND(((ROUND((ROUND(((AE29-(((EU29*0.75)*1.2)))*AV29*I29),2)*BS29),2)*AU29)/100),2)) -> 20201.05 | AA29: -1 | AB29: =ROUND((AC29+AD29+AF29),6) -> 426.8355 | AC29: =ROUND((((ES29*0.75)*1)),6) -> 34.1475 | AD29: =ROUND((((((ET29*0.75)*1.2))-(((EU29*0.75)*1.2)))+AE29),6) -> 37.872 | AE29: =ROUND((((EU29*0.75)*1.2)),6) -> 2.61 | AF29: =ROUND((((EV29*0.75)*1.2)),6) -> 354.816 | AG29: =ROUND((AP29),6) -> 0 | AH29: =(((EW29*0.75)*1.2)) -> 28.8 | AI29: =(((EX29*0.75)*1.2)) -> 0 | AJ29: =(AS29) -> 0 | AK29: 481.85 | AL29: 45.53 | AM29: 42.08 | AN29: 2.9 | AO29: 394.24 | AP29: 0 | AQ29: 32 | AR29: 0 | AS29: 0 | AT29: 91 | AU29: 47 | AV29: 1.067 | AW29: 1.028 | AZ29: 1 | BA29: 56.35 | BB29: 14.74 | BC29: 11.98 | BH29: 0 | BI29: 2 | BJ29: ТСН-2001.4 Доп. 80, Сб. 7, т. 21, поз. 3 | BM29: 66 | BN29: 0 | BO29: 4.7-21-3 | BP29: 1 | BQ29: 40 | BR29: 0 | BS29: 56.35 | BT29: 1 | BU29: 1 | BV29: 1 | BW29: 1 | BX29: 1 | BZ29: 91 | CA29: 47 | CE29: 1566 | CF29: 0 | CG29: 0 | CM29: 0 | CN29: Поправка: Гл.4.Прил.2.2.п.2.2.17_04.00.01.24.001 Наименование: При разнице в массе оборудования более 10% к норме и расценке ближайшего по массе оборудования при коэффициенте изменения массы оборудования до 0,5 т Поправка: Гл.12.Прил.8.п.8. 3_12.00.01.11.001 Наименование: При наличии напряженных и стесненных условий производства работ (стесненность, сложность складирования и транспортной логистики и т.п.) для объектов, расположенных в пределах круговой магистральной системы улиц "Садовое кольцо" города Москвы | CO29: 0 | CP29: =(P29+Q29+S29) -> 44699.5 | CQ29: =ROUND((ROUND((AC29*AW29*1),2)*BC29),2) -> 420.5 | CR29: =(ROUND((ROUND(((((ET29*0.75)*1.2))*AV29*1),2)*BB29),2)+ROUND((ROUND(((AE29-(((EU29*0.75)*1.2)))*AV29*1),2)*BS29),2)) -> 595.64 | CS29: =(ROUND((ROUND(((((EU29*0.75)*1.2))*AV29*1),2)*BS29),2)+ROUND((ROUND(((AE29-(((EU29*0.75)*1.2)))*AV29*1),2)*BS29),2)) -> 156.65 | CT29: =ROUND((ROUND((AF29*AV29*1),2)*BA29),2) -> 21333.55 | CU29: =AG29 -> 0 | CV29: =(AH29*AV29) -> 30.7296 | CW29: =AI29 -> 0 | CX29: =AJ29 -> 0 | CY29: =(ROUND((((S29+ROUND((ROUND(((((EU29*0.75)*1.2))*AV29*1),2)*BS29),2))*AT29)/100),2)+ROUND(((ROUND((ROUND(((AE29-(((EU29*0.75)*1.2)))*AV29*1),2)*BS29),2)*AT29)/100),2)) -> 38969.6 | CZ29: =(ROUND((((S29+ROUND((ROUND(((((EU29*0.75)*1.2))*AV29*1),2)*BS29),2))*AU29)/100),2)+ROUND(((ROUND((ROUND(((AE29-(((EU29*0.75)*1.2)))*AV29*1),2)*BS29),2)*AU29)/100),2)) -> 20127.16 | DB29: 3 | DD29: *0,75)*1 | DE29: *0,75)*1,2 | DF29: *0,75)*1,2 | DG29: *0,75)*1,2 | DI29: *0,75)*1,2 | DJ29: *0,75)*1,2 | DN29: 0 | DO29: 0 | DP29: 1 | DQ29: 1 | DU29: 1013 | DV29: 1 ШТ. | DW29: 1 ШТ. | DX29: 1 | EE29: 56938733 | EF29: 40 | EG29: Монтаж оборудования | EH29: 0 | EJ29: 2 | EK29: 66 | EL29: ТСН-2001.4-7. Компрессорные машины, насосы, вентиляторы | EM29: ТСН-2001.4-7-1 | EO29: Поправка: Гл.4.Прил.2.2.п.2.2.17_04.00.01.24.001 Поправка: Гл.12.Прил.8.п.8. 3_12.00.01.11.001 | EQ29: 132096 | ER29: 481.85 | ES29: 45.53 | ET29: 42.08 | EU29: 2.9 | EV29: 394.24 | EW29: 32 | EX29: 0 | EY29: 0 | FQ29: 0 | FR29: 0 | FS29: 2 | FX29: 91 | FY29: 47 | GD29: 1 | GF29: 2029985936 | GG29: 2 | GH29: 1 | GI29: 2 | GJ29: 0 | GK29: 0 | GL29: =ROUND(IF(AND(BH29=3,BI29=3,FS29<>0),P29,0),2) -> 0 | GM29: =ROUND(O29+X29+Y29,2)+GX29 -> 104013.22 | GN29: =IF(OR(BI29=0,BI29=1),GM29-GX29,0) -> 0 | GO29: =IF(BI29=2,GM29-GX29,0) -> 104013.22 | GP29: =IF(BI29=4,GM29-GX29,0) -> 0 | GR29: 0 | GS29: 3 | GT29: 0 | GV29: =ROUND((GT29),6) -> 0 | GW29: 1 | GX29: =ROUND(HC29*I29,2) -> 0 | HA29: 0 | HB29: 0 | HC29: =GV29*GW29 -> 0 | HS29: 0 | IK29: 0
A30: 17 | B30: 1 | C30: =ROW(SmtRes!A29) -> 29 | D30: =ROW(EtalonRes!A34) -> 34 | E30: 1 | F30: 3.18-11-2 | G30: Установка насосов центробежных с электродвигателем массой агрегата до 0,2 т | H30: 1 насос | I30: 1 | J30: 0 | K30: 1 | O30: =ROUND(CP30,2) -> 490.07 | P30: =ROUND((ROUND((AC30*AW30*I30),2)*BC30),2) -> 172.01 | Q30: =(ROUND((ROUND(((((ET30*1.2)*1.25))*AV30*I30),2)*BB30),2)+ROUND((ROUND(((AE30-(((EU30*1.2)*1.25)))*AV30*I30),2)*BS30),2)) -> 25.48 | R30: =(ROUND((ROUND(((((EU30*1.2)*1.25))*AV30*I30),2)*BS30),2)+ROUND((ROUND(((AE30-(((EU30*1.2)*1.25)))*AV30*I30),2)*BS30),2)) -> 2.29 | S30: =ROUND((ROUND((AF30*AV30*I30),2)*BA30),2) -> 292.58 | T30: =ROUND(CU30*I30,2) -> 0 | U30: =CV30*I30 -> 24.001098 | V30: =CW30*I30 -> 0 | W30: =ROUND(CX30*I30,2) -> 0 | X30: =(ROUND((((S30+ROUND((ROUND(((((EU30*1.2)*1.25))*AV30*I30),2)*BS30),2))*AT30)/100),2)+ROUND(((ROUND((ROUND(((AE30-(((EU30*1.2)*1.25)))*AV30*I30),2)*BS30),2)*AT30)/100),2)) -> 356.79 | Y30: =(ROUND((((S30+ROUND((ROUND(((((EU30*1.2)*1.25))*AV30*I30),2)*BS30),2))*AU30)/100),2)+ROUND(((ROUND((ROUND(((AE30-(((EU30*1.2)*1.25)))*AV30*I30),2)*BS30),2)*AU30)/100),2)) -> 212.31 | AA30: 55747649 | AB30: =ROUND((AC30+AD30+AF30),6) -> 470.096 | AC30: =ROUND((((ES30*1)*1)),6) -> 172.01 | AD30: =ROUND((((((ET30*1.2)*1.25))-(((EU30*1.2)*1.25)))+AE30),6) -> 23.88 | AE30: =ROUND((((EU30*1.2)*1.25)),6) -> 2.145 | AF30: =ROUND((((EV30*1.2)*1.15)),6) -> 274.206 | AG30: =ROUND((AP30),6) -> 0 | AH30: =(((EW30*1.2)*1.15)) -> 22.494 | AI30: =(((EX30*1.2)*1.25)) -> 0 | AJ30: =(AS30) -> 0 | AK30: 386.63 | AL30: 172.01 | AM30: 15.92 | AN30: 1.43 | AO30: 198.7 | AP30: 0 | AQ30: 16.3 | AR30: 0 | AS30: 0 | AT30: 121 | AU30: 72 | AV30: 1.067 | AW30: 1 | AZ30: 1 | BA30: 1 | BB30: 1 | BC30: 1 | BH30: 0 | BI30: 1 | BJ30: ТСН-2001.3 Доп. 79, Сб. 18, т. 11, поз. 2 | BM30: 23 | BN30: 0 | BO30: 3.18-11-2 | BP30: 1 | BQ30: 30 | BR30: 0 | BS30: 1 | BT30: 1 | BU30: 1 | BV30: 1 | BW30: 1 | BX30: 1 | BZ30: 121 | CA30: 72 | CE30: 1566 | CF30: 0 | CG30: 0 | CM30: 0 | CN30: Поправка: Гл.12.Прил.8.п.8. 3_12.00.01.11.001 Наименование: При наличии напряженных и стесненных условий производства работ (стесненность, сложность складирования и транспортной логистики и т.п.) для объектов, расположенных в пределах круговой магистральной системы улиц "Садовое кольцо" города Москвы Поправка: Гл.6.Прил.2.2.п.2.2.6_06.00.01.07.001 Наименование: При выполнении при капитальном ремонте и реконструкции работ, аналогичных технологическим процессам, характерным для нового строительства, и отсутствующих в сборниках на ремонтно-строительные работы ТСН-2001.6 | CO30: 0 | CP30: =(P30+Q30+S30) -> 490.07 | CQ30: =ROUND((ROUND((AC30*AW30*1),2)*BC30),2) -> 172.01 | CR30: =(ROUND((ROUND(((((ET30*1.2)*1.25))*AV30*1),2)*BB30),2)+ROUND((ROUND(((AE30-(((EU30*1.2)*1.25)))*AV30*1),2)*BS30),2)) -> 25.48 | CS30: =(ROUND((ROUND(((((EU30*1.2)*1.25))*AV30*1),2)*BS30),2)+ROUND((ROUND(((AE30-(((EU30*1.2)*1.25)))*AV30*1),2)*BS30),2)) -> 2.29 | CT30: =ROUND((ROUND((AF30*AV30*1),2)*BA30),2) -> 292.58 | CU30: =AG30 -> 0 | CV30: =(AH30*AV30) -> 24.001098 | CW30: =AI30 -> 0 | CX30: =AJ30 -> 0 | CY30: =(ROUND((((S30+ROUND((ROUND(((((EU30*1.2)*1.25))*AV30*1),2)*BS30),2))*AT30)/100),2)+ROUND(((ROUND((ROUND(((AE30-(((EU30*1.2)*1.25)))*AV30*1),2)*BS30),2)*AT30)/100),2)) -> 356.79 | CZ30: =(ROUND((((S30+ROUND((ROUND(((((EU30*1.2)*1.25))*AV30*1),2)*BS30),2))*AU30)/100),2)+ROUND(((ROUND((ROUND(((AE30-(((EU30*1.2)*1.25)))*AV30*1),2)*BS30),2)*AU30)/100),2)) -> 212.31 | DB30: 5 | DD30: *1)*1 | DE30: *1,2)*1,25 | DF30: *1,2)*1,25 | DG30: *1,2)*1,15 | DI30: *1,2)*1,15 | DJ30: *1,2)*1,25 | DN30: 0 | DO30: 0 | DP30: 1 | DQ30: 1 | DU30: 1013 | DV30: 1 насос | DW30: 1 насос | DX30: 1 | EE30: 56938689 | EF30: 30 | EG30: Строительные работы | EH30: 0 | EJ30: 1 | EK30: 23 | EL30: ТСН-2001.3-18. Отопление - внутренние устройства | EM30: ТСН-2001.3-18-1 | EO30: Поправка: Гл.12.Прил.8.п.8. 3_12.00.01.11.001 Поправка: Гл.6.Прил.2.2.п.2.2.6_06.00.01.07.001 | EQ30: 0 | ER30: 386.63 | ES30: 172.01 | ET30: 15.92 | EU30: 1.43 | EV30: 198.7 | EW30: 16.3 | EX30: 0 | EY30: 0 | FQ30: 0 | FR30: 0 | FS30: 0 | FX30: 121 | FY30: 72 | GD30: 1 | GF30: 1996820590 | GG30: 2 | GH30: 1 | GI30: 2 | GJ30: 0 | GK30: 0 | GL30: =ROUND(IF(AND(BH30=3,BI30=3,FS30<>0),P30,0),2) -> 0 | GM30: =ROUND(O30+X30+Y30,2)+GX30 -> 1059.17 | GN30: =IF(OR(BI30=0,BI30=1),GM30-GX30,0) -> 1059.17 | GO30: =IF(BI30=2,GM30-GX30,0) -> 0 | GP30: =IF(BI30=4,GM30-GX30,0) -> 0 | GR30: 0 | GS30: 3 | GT30: 0 | GV30: =ROUND((GT30),6) -> 0 | GW30: 1 | GX30: =ROUND(HC30*I30,2) -> 0 | HA30: 0 | HB30: 0 | HC30: =GV30*GW30 -> 0 | HS30: 0 | IK30: 0
A31: 17 | B31: 1 | C31: =ROW(SmtRes!A38) -> 38 | D31: =ROW(EtalonRes!A46) -> 46 | E31: 1 | F31: 3.18-11-2 | G31: Установка насосов центробежных с электродвигателем массой агрегата до 0,2 т | H31: 1 насос | I31: 1 | J31: 0 | K31: 1 | O31: =ROUND(CP31,2) -> 18120.35 | P31: =ROUND((ROUND((AC31*AW31*I31),2)*BC31),2) -> 1250.51 | Q31: =(ROUND((ROUND(((((ET31*1.2)*1.25))*AV31*I31),2)*BB31),2)+ROUND((ROUND(((AE31-(((EU31*1.2)*1.25)))*AV31*I31),2)*BS31),2)) -> 382.96 | R31: =(ROUND((ROUND(((((EU31*1.2)*1.25))*AV31*I31),2)*BS31),2)+ROUND((ROUND(((AE31-(((EU31*1.2)*1.25)))*AV31*I31),2)*BS31),2)) -> 129.04 | S31: =ROUND((ROUND((AF31*AV31*I31),2)*BA31),2) -> 16486.88 | T31: =ROUND(CU31*I31,2) -> 0 | U31: =CV31*I31 -> 24.001098 | V31: =CW31*I31 -> 0 | W31: =ROUND(CX31*I31,2) -> 0 | X31: =(ROUND((((S31+ROUND((ROUND(((((EU31*1.2)*1.25))*AV31*I31),2)*BS31),2))*AT31)/100),2)+ROUND(((ROUND((ROUND(((AE31-(((EU31*1.2)*1.25)))*AV31*I31),2)*BS31),2)*AT31)/100),2)) -> 20105.26 | Y31: =(ROUND((((S31+ROUND((ROUND(((((EU31*1.2)*1.25))*AV31*I31),2)*BS31),2))*AU31)/100),2)+ROUND(((ROUND((ROUND(((AE31-(((EU31*1.2)*1.25)))*AV31*I31),2)*BS31),2)*AU31)/100),2)) -> 11963.46 | AA31: 55747651 | AB31: =ROUND((AC31+AD31+AF31),6) -> 470.096 | AC31: =ROUND((((ES31*1)*1)),6) -> 172.01 | AD31: =ROUND((((((ET31*1.2)*1.25))-(((EU31*1.2)*1.25)))+AE31),6) -> 23.88 | AE31: =ROUND((((EU31*1.2)*1.25)),6) -> 2.145 | AF31: =ROUND((((EV31*1.2)*1.15)),6) -> 274.206 | AG31: =ROUND((AP31),6) -> 0 | AH31: =(((EW31*1.2)*1.15)) -> 22.494 | AI31: =(((EX31*1.2)*1.25)) -> 0 | AJ31: =(AS31) -> 0 | AK31: 386.63 | AL31: 172.01 | AM31: 15.92 | AN31: 1.43 | AO31: 198.7 | AP31: 0 | AQ31: 16.3 | AR31: 0 | AS31: 0 | AT31: 121 | AU31: 72 | AV31: 1.067 | AW31: 1 | AZ31: 1 | BA31: 56.35 | BB31: 15.03 | BC31: 7.27 | BH31: 0 | BI31: 1 | BJ31: ТСН-2001.3 Доп. 79, Сб. 18, т. 11, поз. 2 | BM31: 23 | BN31: 0 | BO31: 3.18-11-2 | BP31: 1 | BQ31: 30 | BR31: 0 | BS31: 56.35 | BT31: 1 | BU31: 1 | BV31: 1 | BW31: 1 | BX31: 1 | BZ31: 121 | CA31: 72 | CE31: 1566 | CF31: 0 | CG31: 0 | CM31: 0 | CN31: Поправка: Гл.12.Прил.8.п.8. 3_12.00.01.11.001 Наименование: При наличии напряженных и стесненных условий производства работ (стесненность, сложность складирования и транспортной логистики и т.п.) для объектов, расположенных в пределах круговой магистральной системы улиц "Садовое кольцо" города Москвы Поправка: Гл.6.Прил.2.2.п.2.2.6_06.00.01.07.001 Наименование: При выполнении при капитальном ремонте и реконструкции работ, аналогичных технологическим процессам, характерным для нового строительства, и отсутствующих в сборниках на ремонтно-строительные работы ТСН-2001.6 | CO31: 0 | CP31: =(P31+Q31+S31) -> 18120.35 | CQ31: =ROUND((ROUND((AC31*AW31*1),2)*BC31),2) -> 1250.51 | CR31: =(ROUND((ROUND(((((ET31*1.2)*1.25))*AV31*1),2)*BB31),2)+ROUND((ROUND(((AE31-(((EU31*1.2)*1.25)))*AV31*1),2)*BS31),2)) -> 382.96 | CS31: =(ROUND((ROUND(((((EU31*1.2)*1.25))*AV31*1),2)*BS31),2)+ROUND((ROUND(((AE31-(((EU31*1.2)*1.25)))*AV31*1),2)*BS31),2)) -> 129.04 | CT31: =ROUND((ROUND((AF31*AV31*1),2)*BA31),2) -> 16486.88 | CU31: =AG31 -> 0 | CV31: =(AH31*AV31) -> 24.001098 | CW31: =AI31 -> 0 | CX31: =AJ31 -> 0 | CY31: =(ROUND((((S31+ROUND((ROUND(((((EU31*1.2)*1.25))*AV31*1),2)*BS31),2))*AT31)/100),2)+ROUND(((ROUND((ROUND(((AE31-(((EU31*1.2)*1.25)))*AV31*1),2)*BS31),2)*AT31)/100),2)) -> 20105.26 | CZ31: =(ROUND((((S31+ROUND((ROUND(((((EU31*1.2)*1.25))*AV31*1),2)*BS31),2))*AU31)/100),2)+ROUND(((ROUND((ROUND(((AE31-(((EU31*1.2)*1.25)))*AV31*1),2)*BS31),2)*AU31)/100),2)) -> 11963.46 | DB31: 7 | DD31: *1)*1 | DE31: *1,2)*1,25 | DF31: *1,2)*1,25 | DG31: *1,2)*1,15 | DI31: *1,2)*1,15 | DJ31: *1,2)*1,25 | DN31: 0 | DO31: 0 | DP31: 1 | DQ31: 1 | DU31: 1013 | DV31: 1 насос | DW31: 1 насос | DX31: 1 | EE31: 56938689 | EF31: 30 | EG31: Строительные работы | EH31: 0 | EJ31: 1 | EK31: 23 | EL31: ТСН-2001.3-18. Отопление - внутренние устройства | EM31: ТСН-2001.3-18-1 | EO31: Поправка: Гл.12.Прил.8.п.8. 3_12.00.01.11.001 Поправка: Гл.6.Прил.2.2.п.2.2.6_06.00.01.07.001 | EQ31: 0 | ER31: 386.63 | ES31: 172.01 | ET31: 15.92 | EU31: 1.43 | EV31: 198.7 | EW31: 16.3 | EX31: 0 | EY31: 0 | FQ31: 0 | FR31: 0 | FS31: 0 | FX31: 121 | FY31: 72 | GD31: 1 | GF31: 1996820590 | GG31: 2 | GH31: 1 | GI31: 2 | GJ31: 0 | GK31: 0 | GL31: =ROUND(IF(AND(BH31=3,BI31=3,FS31<>0),P31,0),2) -> 0 | GM31: =ROUND(O31+X31+Y31,2)+GX31 -> 50189.07 | GN31: =IF(OR(BI31=0,BI31=1),GM31-GX31,0) -> 50189.07 | GO31: =IF(BI31=2,GM31-GX31,0) -> 0 | GP31: =IF(BI31=4,GM31-GX31,0) -> 0 | GR31: 0 | GS31: 3 | GT31: 0 | GV31: =ROUND((GT31),6) -> 0 | GW31: 1 | GX31: =ROUND(HC31*I31,2) -> 0 | HA31: 0 | HB31: 0 | HC31: =GV31*GW31 -> 0 | HS31: 0 | IK31: 0
A32: 17 | B32: 1 | C32: =ROW(SmtRes!A48) -> 48 | D32: =ROW(EtalonRes!A57) -> 57 | F32: 4.7-21-1 | G32: Монтаж насосного агрегата лопастного центробежного одноступенчатого, многоступенчатого объемного, вихревого, поршневого, приводного, роторного на общей фундаментной плите или моноблочный массой 0,064 т | H32: 1 ШТ. | I32: =ROUND(1,9) -> 1 | J32: 0 | K32: =ROUND(1,9) -> 1 | O32: =ROUND(CP32,2) -> 513.44 | P32: =ROUND((ROUND((AC32*AW32*I32),2)*BC32),2) -> 43.53 | Q32: =(ROUND((ROUND((((ET32*1.2))*AV32*I32),2)*BB32),2)+ROUND((ROUND(((AE32-((EU32*1.2)))*AV32*I32),2)*BS32),2)) -> 31.37 | R32: =(ROUND((ROUND((((EU32*1.2))*AV32*I32),2)*BS32),2)+ROUND((ROUND(((AE32-((EU32*1.2)))*AV32*I32),2)*BS32),2)) -> 0.49 | S32: =ROUND((ROUND((AF32*AV32*I32),2)*BA32),2) -> 438.54 | T32: =ROUND(CU32*I32,2) -> 0 | U32: =CV32*I32 -> 35.59512 | V32: =CW32*I32 -> 0 | W32: =ROUND(CX32*I32,2) -> 0 | X32: =(ROUND((((S32+ROUND((ROUND((((EU32*1.2))*AV32*I32),2)*BS32),2))*AT32)/100),2)+ROUND(((ROUND((ROUND(((AE32-((EU32*1.2)))*AV32*I32),2)*BS32),2)*AT32)/100),2)) -> 399.52 | Y32: =(ROUND((((S32+ROUND((ROUND((((EU32*1.2))*AV32*I32),2)*BS32),2))*AU32)/100),2)+ROUND(((ROUND((ROUND(((AE32-((EU32*1.2)))*AV32*I32),2)*BS32),2)*AU32)/100),2)) -> 206.34 | AA32: -1 | AB32: =ROUND((AC32+AD32+AF32),6) -> 482.74 | AC32: =ROUND(((ES32*1)),6) -> 42.34 | AD32: =ROUND(((((ET32*1.2))-((EU32*1.2)))+AE32),6) -> 29.4 | AE32: =ROUND(((EU32*1.2)),6) -> 0.456 | AF32: =ROUND(((EV32*1.2)),6) -> 411 | AG32: =ROUND((AP32),6) -> 0 | AH32: =((EW32*1.2)) -> 33.36 | AI32: =((EX32*1.2)) -> 0 | AJ32: =(AS32) -> 0 | AK32: 409.34 | AL32: 42.34 | AM32: 24.5 | AN32: 0.38 | AO32: 342.5 | AP32: 0 | AQ32: 27.8 | AR32: 0 | AS32: 0 | AT32: 91 | AU32: 47 | AV32: 1.067 | AW32: 1.028 | AZ32: 1 | BA32: 1 | BB32: 1 | BC32: 1 | BH32: 0 | BI32: 2 | BJ32: ТСН-2001.4 Доп. 80, Сб. 7, т. 21, поз. 1 | BM32: 66 | BN32: 0 | BO32: 4.7-21-1 | BP32: 1 | BQ32: 40 | BR32: 0 | BS32: 1 | BT32: 1 | BU32: 1 | BV32: 1 | BW32: 1 | BX32: 1 | BZ32: 91 | CA32: 47 | CE32: 1566 | CF32: 0 | CG32: 0 | CM32: 0 | CN32: Поправка: Гл.12.Прил.8.п.8. 3_12.00.01.11.001 Наименование: При наличии напряженных и стесненных условий производства работ (стесненность, сложность складирования и транспортной логистики и т.п.) для объектов, расположенных в пределах круговой магистральной системы улиц "Садовое кольцо" города Москвы | CO32: 0 | CP32: =(P32+Q32+S32) -> 513.44 | CQ32: =ROUND((ROUND((AC32*AW32*1),2)*BC32),2) -> 43.53 | CR32: =(ROUND((ROUND((((ET32*1.2))*AV32*1),2)*BB32),2)+ROUND((ROUND(((AE32-((EU32*1.2)))*AV32*1),2)*BS32),2)) -> 31.37 | CS32: =(ROUND((ROUND((((EU32*1.2))*AV32*1),2)*BS32),2)+ROUND((ROUND(((AE32-((EU32*1.2)))*AV32*1),2)*BS32),2)) -> 0.49 | CT32: =ROUND((ROUND((AF32*AV32*1),2)*BA32),2) -> 438.54 | CU32: =AG32 -> 0 | CV32: =(AH32*AV32) -> 35.59512 | CW32: =AI32 -> 0 | CX32: =AJ32 -> 0 | CY32: =(ROUND((((S32+ROUND((ROUND((((EU32*1.2))*AV32*1),2)*BS32),2))*AT32)/100),2)+ROUND(((ROUND((ROUND(((AE32-((EU32*1.2)))*AV32*1),2)*BS32),2)*AT32)/100),2)) -> 399.52 | CZ32: =(ROUND((((S32+ROUND((ROUND((((EU32*1.2))*AV32*1),2)*BS32),2))*AU32)/100),2)+ROUND(((ROUND((ROUND(((AE32-((EU32*1.2)))*AV32*1),2)*BS32),2)*AU32)/100),2)) -> 206.34 | DB32: 9 | DD32: *1 | DE32: *1,2 | DF32: *1,2 | DG32: *1,2 | DI32: *1,2 | DJ32: *1,2 | DN32: 0 | DO32: 0 | DP32: 1 | DQ32: 1 | DU32: 1013 | DV32: 1 ШТ. | DW32: 1 ШТ. | DX32: 1 | EE32: 56938733 | EF32: 40 | EG32: Монтаж оборудования | EH32: 0 | EJ32: 2 | EK32: 66 | EL32: ТСН-2001.4-7. Компрессорные машины, насосы, вентиляторы | EM32: ТСН-2001.4-7-1 | EO32: Поправка: Гл.12.Прил.8.п.8. 3_12.00.01.11.001 | EQ32: 132096 | ER32: 409.34 | ES32: 42.34 | ET32: 24.5 | EU32: 0.38 | EV32: 342.5 | EW32: 27.8 | EX32: 0 | EY32: 0 | FQ32: 0 | FR32: 0 | FS32: 2 | FX32: 91 | FY32: 47 | GD32: 1 | GF32: -1722888311 | GG32: 2 | GH32: 1 | GI32: 2 | GJ32: 0 | GK32: 0 | GL32: =ROUND(IF(AND(BH32=3,BI32=3,FS32<>0),P32,0),2) -> 0 | GM32: =ROUND(O32+X32+Y32,2)+GX32 -> 1119.3 | GN32: =IF(OR(BI32=0,BI32=1),GM32-GX32,0) -> 0 | GO32: =IF(BI32=2,GM32-GX32,0) -> 1119.3 | GP32: =IF(BI32=4,GM32-GX32,0) -> 0 | GR32: 0 | GS32: 3 | GT32: 0 | GV32: =ROUND((GT32),6) -> 0 | GW32: 1 | GX32: =ROUND(HC32*I32,2) -> 0 | HA32: 0 | HB32: 0 | HC32: =GV32*GW32 -> 0 | HS32: 0 | IK32: 0
A33: 17 | B33: 1 | C33: =ROW(SmtRes!A58) -> 58 | D33: =ROW(EtalonRes!A68) -> 68 | F33: 4.7-21-1 | G33: Монтаж насосного агрегата лопастного центробежного одноступенчатого, многоступенчатого объемного, вихревого, поршневого, приводного, роторного на общей фундаментной плите или моноблочный массой 0,064 т | H33: 1 ШТ. | I33: =ROUND(1,9) -> 1 | J33: 0 | K33: =ROUND(1,9) -> 1 | O33: =ROUND(CP33,2) -> 25637.77 | P33: =ROUND((ROUND((AC33*AW33*I33),2)*BC33),2) -> 507.56 | Q33: =(ROUND((ROUND((((ET33*1.2))*AV33*I33),2)*BB33),2)+ROUND((ROUND(((AE33-((EU33*1.2)))*AV33*I33),2)*BS33),2)) -> 418.48 | R33: =(ROUND((ROUND((((EU33*1.2))*AV33*I33),2)*BS33),2)+ROUND((ROUND(((AE33-((EU33*1.2)))*AV33*I33),2)*BS33),2)) -> 27.61 | S33: =ROUND((ROUND((AF33*AV33*I33),2)*BA33),2) -> 24711.73 | T33: =ROUND(CU33*I33,2) -> 0 | U33: =CV33*I33 -> 35.59512 | V33: =CW33*I33 -> 0 | W33: =ROUND(CX33*I33,2) -> 0 | X33: =(ROUND((((S33+ROUND((ROUND((((EU33*1.2))*AV33*I33),2)*BS33),2))*AT33)/100),2)+ROUND(((ROUND((ROUND(((AE33-((EU33*1.2)))*AV33*I33),2)*BS33),2)*AT33)/100),2)) -> 22512.8 | Y33: =(ROUND((((S33+ROUND((ROUND((((EU33*1.2))*AV33*I33),2)*BS33),2))*AU33)/100),2)+ROUND(((ROUND((ROUND(((AE33-((EU33*1.2)))*AV33*I33),2)*BS33),2)*AU33)/100),2)) -> 11627.49 | AA33: -1 | AB33: =ROUND((AC33+AD33+AF33),6) -> 482.74 | AC33: =ROUND(((ES33*1)),6) -> 42.34 | AD33: =ROUND(((((ET33*1.2))-((EU33*1.2)))+AE33),6) -> 29.4 | AE33: =ROUND(((EU33*1.2)),6) -> 0.456 | AF33: =ROUND(((EV33*1.2)),6) -> 411 | AG33: =ROUND((AP33),6) -> 0 | AH33: =((EW33*1.2)) -> 33.36 | AI33: =((EX33*1.2)) -> 0 | AJ33: =(AS33) -> 0 | AK33: 409.34 | AL33: 42.34 | AM33: 24.5 | AN33: 0.38 | AO33: 342.5 | AP33: 0 | AQ33: 27.8 | AR33: 0 | AS33: 0 | AT33: 91 | AU33: 47 | AV33: 1.067 | AW33: 1.028 | AZ33: 1 | BA33: 56.35 | BB33: 13.34 | BC33: 11.66 | BH33: 0 | BI33: 2 | BJ33: ТСН-2001.4 Доп. 80, Сб. 7, т. 21, поз. 1 | BM33: 66 | BN33: 0 | BO33: 4.7-21-1 | BP33: 1 | BQ33: 40 | BR33: 0 | BS33: 56.35 | BT33: 1 | BU33: 1 | BV33: 1 | BW33: 1 | BX33: 1 | BZ33: 91 | CA33: 47 | CE33: 1566 | CF33: 0 | CG33: 0 | CM33: 0 | CN33: Поправка: Гл.12.Прил.8.п.8. 3_12.00.01.11.001 Наименование: При наличии напряженных и стесненных условий производства работ (стесненность, сложность складирования и транспортной логистики и т.п.) для объектов, расположенных в пределах круговой магистральной системы улиц "Садовое кольцо" города Москвы | CO33: 0 | CP33: =(P33+Q33+S33) -> 25637.77 | CQ33: =ROUND((ROUND((AC33*AW33*1),2)*BC33),2) -> 507.56 | CR33: =(ROUND((ROUND((((ET33*1.2))*AV33*1),2)*BB33),2)+ROUND((ROUND(((AE33-((EU33*1.2)))*AV33*1),2)*BS33),2)) -> 418.48 | CS33: =(ROUND((ROUND((((EU33*1.2))*AV33*1),2)*BS33),2)+ROUND((ROUND(((AE33-((EU33*1.2)))*AV33*1),2)*BS33),2)) -> 27.61 | CT33: =ROUND((ROUND((AF33*AV33*1),2)*BA33),2) -> 24711.73 | CU33: =AG33 -> 0 | CV33: =(AH33*AV33) -> 35.59512 | CW33: =AI33 -> 0 | CX33: =AJ33 -> 0 | CY33: =(ROUND((((S33+ROUND((ROUND((((EU33*1.2))*AV33*1),2)*BS33),2))*AT33)/100),2)+ROUND(((ROUND((ROUND(((AE33-((EU33*1.2)))*AV33*1),2)*BS33),2)*AT33)/100),2)) -> 22512.8 | CZ33: =(ROUND((((S33+ROUND((ROUND((((EU33*1.2))*AV33*1),2)*BS33),2))*AU33)/100),2)+ROUND(((ROUND((ROUND(((AE33-((EU33*1.2)))*AV33*1),2)*BS33),2)*AU33)/100),2)) -> 11627.49 | DB33: 10 | DD33: *1 | DE33: *1,2 | DF33: *1,2 | DG33: *1,2 | DI33: *1,2 | DJ33: *1,2 | DN33: 0 | DO33: 0 | DP33: 1 | DQ33: 1 | DU33: 1013 | DV33: 1 ШТ. | DW33: 1 ШТ. | DX33: 1 | EE33: 56938733 | EF33: 40 | EG33: Монтаж оборудования | EH33: 0 | EJ33: 2 | EK33: 66 | EL33: ТСН-2001.4-7. Компрессорные машины, насосы, вентиляторы | EM33: ТСН-2001.4-7-1 | EO33: Поправка: Гл.12.Прил.8.п.8. 3_12.00.01.11.001 | EQ33: 132096 | ER33: 409.34 | ES33: 42.34 | ET33: 24.5 | EU33: 0.38 | EV33: 342.5 | EW33: 27.8 | EX33: 0 | EY33: 0 | FQ33: 0 | FR33: 0 | FS33: 2 | FX33: 91 | FY33: 47 | GD33: 1 | GF33: -1722888311 | GG33: 2 | GH33: 1 | GI33: 2 | GJ33: 0 | GK33: 0 | GL33: =ROUND(IF(AND(BH33=3,BI33=3,FS33<>0),P33,0),2) -> 0 | GM33: =ROUND(O33+X33+Y33,2)+GX33 -> 59778.06 | GN33: =IF(OR(BI33=0,BI33=1),GM33-GX33,0) -> 0 | GO33: =IF(BI33=2,GM33-GX33,0) -> 59778.06 | GP33: =IF(BI33=4,GM33-GX33,0) -> 0 | GR33: 0 | GS33: 3 | GT33: 0 | GV33: =ROUND((GT33),6) -> 0 | GW33: 1 | GX33: =ROUND(HC33*I33,2) -> 0 | HA33: 0 | HB33: 0 | HC33: =GV33*GW33 -> 0 | HS33: 0 | IK33: 0
A34: 17 | B34: 1 | C34: =ROW(SmtRes!A67) -> 67 | D34: =ROW(EtalonRes!A78) -> 78 | E34: 2 | F34: 3.17-10-1 | G34: Установка насосов погружных центробежных фекальных с электродвигателем производительностью 10 м3/час | H34: 1 ШТ. | I34: 1 | J34: 0 | K34: 1 | O34: =ROUND(CP34,2) -> 358.38 | P34: =ROUND((ROUND((AC34*AW34*I34),2)*BC34),2) -> 109.65 | Q34: =(ROUND((ROUND(((((ET34*1.2)*1.25))*AV34*I34),2)*BB34),2)+ROUND((ROUND(((AE34-(((EU34*1.2)*1.25)))*AV34*I34),2)*BS34),2)) -> 10 | R34: =(ROUND((ROUND(((((EU34*1.2)*1.25))*AV34*I34),2)*BS34),2)+ROUND((ROUND(((AE34-(((EU34*1.2)*1.25)))*AV34*I34),2)*BS34),2)) -> 0.48 | S34: =ROUND((ROUND((AF34*AV34*I34),2)*BA34),2) -> 238.73 | T34: =ROUND(CU34*I34,2) -> 0 | U34: =CV34*I34 -> 19.583718 | V34: =CW34*I34 -> 0 | W34: =ROUND(CX34*I34,2) -> 0 | X34: =(ROUND((((S34+ROUND((ROUND(((((EU34*1.2)*1.25))*AV34*I34),2)*BS34),2))*AT34)/100),2)+ROUND(((ROUND((ROUND(((AE34-(((EU34*1.2)*1.25)))*AV34*I34),2)*BS34),2)*AT34)/100),2)) -> 289.44 | Y34: =(ROUND((((S34+ROUND((ROUND(((((EU34*1.2)*1.25))*AV34*I34),2)*BS34),2))*AU34)/100),2)+ROUND(((ROUND((ROUND(((AE34-(((EU34*1.2)*1.25)))*AV34*I34),2)*BS34),2)*AU34)/100),2)) -> 172.23 | AA34: 55747649 | AB34: =ROUND((AC34+AD34+AF34),6) -> 342.7644 | AC34: =ROUND((((ES34*1)*1)),6) -> 109.65 | AD34: =ROUND((((((ET34*1.2)*1.25))-(((EU34*1.2)*1.25)))+AE34),6) -> 9.375 | AE34: =ROUND((((EU34*1.2)*1.25)),6) -> 0.45 | AF34: =ROUND((((EV34*1.2)*1.15)),6) -> 223.7394 | AG34: =ROUND((AP34),6) -> 0 | AH34: =(((EW34*1.2)*1.15)) -> 18.354 | AI34: =(((EX34*1.2)*1.25)) -> 0 | AJ34: =(AS34) -> 0 | AK34: 278.03 | AL34: 109.65 | AM34: 6.25 | AN34: 0.3 | AO34: 162.13 | AP34: 0 | AQ34: 13.3 | AR34: 0 | AS34: 0 | AT34: 121 | AU34: 72 | AV34: 1.067 | AW34: 1 | AZ34: 1 | BA34: 1 | BB34: 1 | BC34: 1 | BH34: 0 | BI34: 1 | BJ34: ТСН-2001.3 Доп. 79, Сб. 17, т. 10, поз. 1 | BM34: 22 | BN34: 0 | BO34: 3.17-10-1 | BP34: 1 | BQ34: 30 | BR34: 0 | BS34: 1 | BT34: 1 | BU34: 1 | BV34: 1 | BW34: 1 | BX34: 1 | BZ34: 121 | CA34: 72 | CE34: 1566 | CF34: 0 | CG34: 0 | CM34: 0 | CN34: Поправка: Гл.12.Прил.8.п.8. 3_12.00.01.11.001 Наименование: При наличии напряженных и стесненных условий производства работ (стесненность, сложность складирования и транспортной логистики и т.п.) для объектов, расположенных в пределах круговой магистральной системы улиц "Садовое кольцо" города Москвы Поправка: Гл.6.Прил.2.2.п.2.2.6_06.00.01.07.001 Наименование: При выполнении при капитальном ремонте и реконструкции работ, аналогичных технологическим процессам, характерным для нового строительства, и отсутствующих в сборниках на ремонтно-строительные работы ТСН-2001.6 | CO34: 0 | CP34: =(P34+Q34+S34) -> 358.38 | CQ34: =ROUND((ROUND((AC34*AW34*1),2)*BC34),2) -> 109.65 | CR34: =(ROUND((ROUND(((((ET34*1.2)*1.25))*AV34*1),2)*BB34),2)+ROUND((ROUND(((AE34-(((EU34*1.2)*1.25)))*AV34*1),2)*BS34),2)) -> 10 | CS34: =(ROUND((ROUND(((((EU34*1.2)*1.25))*AV34*1),2)*BS34),2)+ROUND((ROUND(((AE34-(((EU34*1.2)*1.25)))*AV34*1),2)*BS34),2)) -> 0.48 | CT34: =ROUND((ROUND((AF34*AV34*1),2)*BA34),2) -> 238.73 | CU34: =AG34 -> 0 | CV34: =(AH34*AV34) -> 19.583718 | CW34: =AI34 -> 0 | CX34: =AJ34 -> 0 | CY34: =(ROUND((((S34+ROUND((ROUND(((((EU34*1.2)*1.25))*AV34*1),2)*BS34),2))*AT34)/100),2)+ROUND(((ROUND((ROUND(((AE34-(((EU34*1.2)*1.25)))*AV34*1),2)*BS34),2)*AT34)/100),2)) -> 289.44 | CZ34: =(ROUND((((S34+ROUND((ROUND(((((EU34*1.2)*1.25))*AV34*1),2)*BS34),2))*AU34)/100),2)+ROUND(((ROUND((ROUND(((AE34-(((EU34*1.2)*1.25)))*AV34*1),2)*BS34),2)*AU34)/100),2)) -> 172.23 | DB34: 11 | DD34: *1)*1 | DE34: *1,2)*1,25 | DF34: *1,2)*1,25 | DG34: *1,2)*1,15 | DI34: *1,2)*1,15 | DJ34: *1,2)*1,25 | DN34: 0 | DO34: 0 | DP34: 1 | DQ34: 1 | DU34: 1013 | DV34: 1 ШТ. | DW34: 1 ШТ. | DX34: 1 | EE34: 56938688 | EF34: 30 | EG34: Строительные работы | EH34: 0 | EJ34: 1 | EK34: 22 | EL34: ТСН-2001.3-17. Водопровод и канализация - внутренние устройства | EM34: ТСН-2001.3-17-1 | EO34: Поправка: Гл.12.Прил.8.п.8. 3_12.00.01.11.001 Поправка: Гл.6.Прил.2.2.п.2.2.6_06.00.01.07.001 | EQ34: 0 | ER34: 278.03 | ES34: 109.65 | ET34: 6.25 | EU34: 0.3 | EV34: 162.13 | EW34: 13.3 | EX34: 0 | EY34: 0 | FQ34: 0 | FR34: 0 | FS34: 0 | FX34: 121 | FY34: 72 | GD34: 1 | GF34: -257018826 | GG34: 2 | GH34: 1 | GI34: 2 | GJ34: 0 | GK34: 0 | GL34: =ROUND(IF(AND(BH34=3,BI34=3,FS34<>0),P34,0),2) -> 0 | GM34: =ROUND(O34+X34+Y34,2)+GX34 -> 820.05 | GN34: =IF(OR(BI34=0,BI34=1),GM34-GX34,0) -> 820.05 | GO34: =IF(BI34=2,GM34-GX34,0) -> 0 | GP34: =IF(BI34=4,GM34-GX34,0) -> 0 | GR34: 0 | GS34: 3 | GT34: 0 | GV34: =ROUND((GT34),6) -> 0 | GW34: 1 | GX34: =ROUND(HC34*I34,2) -> 0 | HA34: 0 | HB34: 0 | HC34: =GV34*GW34 -> 0 | HS34: 0 | IK34: 0
A35: 17 | B35: 1 | C35: =ROW(SmtRes!A76) -> 76 | D35: =ROW(EtalonRes!A88) -> 88 | E35: 2 | F35: 3.17-10-1 | G35: Установка насосов погружных центробежных фекальных с электродвигателем производительностью 10 м3/час | H35: 1 ШТ. | I35: 1 | J35: 0 | K35: 1 | O35: =ROUND(CP35,2) -> 14385.22 | P35: =ROUND((ROUND((AC35*AW35*I35),2)*BC35),2) -> 790.58 | Q35: =(ROUND((ROUND(((((ET35*1.2)*1.25))*AV35*I35),2)*BB35),2)+ROUND((ROUND(((AE35-(((EU35*1.2)*1.25)))*AV35*I35),2)*BS35),2)) -> 142.2 | R35: =(ROUND((ROUND(((((EU35*1.2)*1.25))*AV35*I35),2)*BS35),2)+ROUND((ROUND(((AE35-(((EU35*1.2)*1.25)))*AV35*I35),2)*BS35),2)) -> 27.05 | S35: =ROUND((ROUND((AF35*AV35*I35),2)*BA35),2) -> 13452.44 | T35: =ROUND(CU35*I35,2) -> 0 | U35: =CV35*I35 -> 19.583718 | V35: =CW35*I35 -> 0 | W35: =ROUND(CX35*I35,2) -> 0 | X35: =(ROUND((((S35+ROUND((ROUND(((((EU35*1.2)*1.25))*AV35*I35),2)*BS35),2))*AT35)/100),2)+ROUND(((ROUND((ROUND(((AE35-(((EU35*1.2)*1.25)))*AV35*I35),2)*BS35),2)*AT35)/100),2)) -> 16310.18 | Y35: =(ROUND((((S35+ROUND((ROUND(((((EU35*1.2)*1.25))*AV35*I35),2)*BS35),2))*AU35)/100),2)+ROUND(((ROUND((ROUND(((AE35-(((EU35*1.2)*1.25)))*AV35*I35),2)*BS35),2)*AU35)/100),2)) -> 9705.23 | AA35: 55747651 | AB35: =ROUND((AC35+AD35+AF35),6) -> 342.7644 | AC35: =ROUND((((ES35*1)*1)),6) -> 109.65 | AD35: =ROUND((((((ET35*1.2)*1.25))-(((EU35*1.2)*1.25)))+AE35),6) -> 9.375 | AE35: =ROUND((((EU35*1.2)*1.25)),6) -> 0.45 | AF35: =ROUND((((EV35*1.2)*1.15)),6) -> 223.7394 | AG35: =ROUND((AP35),6) -> 0 | AH35: =(((EW35*1.2)*1.15)) -> 18.354 | AI35: =(((EX35*1.2)*1.25)) -> 0 | AJ35: =(AS35) -> 0 | AK35: 278.03 | AL35: 109.65 | AM35: 6.25 | AN35: 0.3 | AO35: 162.13 | AP35: 0 | AQ35: 13.3 | AR35: 0 | AS35: 0 | AT35: 121 | AU35: 72 | AV35: 1.067 | AW35: 1 | AZ35: 1 | BA35: 56.35 | BB35: 14.22 | BC35: 7.21 | BH35: 0 | BI35: 1 | BJ35: ТСН-2001.3 Доп. 79, Сб. 17, т. 10, поз. 1 | BM35: 22 | BN35: 0 | BO35: 3.17-10-1 | BP35: 1 | BQ35: 30 | BR35: 0 | BS35: 56.35 | BT35: 1 | BU35: 1 | BV35: 1 | BW35: 1 | BX35: 1 | BZ35: 121 | CA35: 72 | CE35: 1566 | CF35: 0 | CG35: 0 | CM35: 0 | CN35: Поправка: Гл.12.Прил.8.п.8. 3_12.00.01.11.001 Наименование: При наличии напряженных и стесненных условий производства работ (стесненность, сложность складирования и транспортной логистики и т.п.) для объектов, расположенных в пределах круговой магистральной системы улиц "Садовое кольцо" города Москвы Поправка: Гл.6.Прил.2.2.п.2.2.6_06.00.01.07.001 Наименование: При выполнении при капитальном ремонте и реконструкции работ, аналогичных технологическим процессам, характерным для нового строительства, и отсутствующих в сборниках на ремонтно-строительные работы ТСН-2001.6 | CO35: 0 | CP35: =(P35+Q35+S35) -> 14385.22 | CQ35: =ROUND((ROUND((AC35*AW35*1),2)*BC35),2) -> 790.58 | CR35: =(ROUND((ROUND(((((ET35*1.2)*1.25))*AV35*1),2)*BB35),2)+ROUND((ROUND(((AE35-(((EU35*1.2)*1.25)))*AV35*1),2)*BS35),2)) -> 142.2 | CS35: =(ROUND((ROUND(((((EU35*1.2)*1.25))*AV35*1),2)*BS35),2)+ROUND((ROUND(((AE35-(((EU35*1.2)*1.25)))*AV35*1),2)*BS35),2)) -> 27.05 | CT35: =ROUND((ROUND((AF35*AV35*1),2)*BA35),2) -> 13452.44 | CU35: =AG35 -> 0 | CV35: =(AH35*AV35) -> 19.583718 | CW35: =AI35 -> 0 | CX35: =AJ35 -> 0 | CY35: =(ROUND((((S35+ROUND((ROUND(((((EU35*1.2)*1.25))*AV35*1),2)*BS35),2))*AT35)/100),2)+ROUND(((ROUND((ROUND(((AE35-(((EU35*1.2)*1.25)))*AV35*1),2)*BS35),2)*AT35)/100),2)) -> 16310.18 | CZ35: =(ROUND((((S35+ROUND((ROUND(((((EU35*1.2)*1.25))*AV35*1),2)*BS35),2))*AU35)/100),2)+ROUND(((ROUND((ROUND(((AE35-(((EU35*1.2)*1.25)))*AV35*1),2)*BS35),2)*AU35)/100),2)) -> 9705.23 | DB35: 13 | DD35: *1)*1 | DE35: *1,2)*1,25 | DF35: *1,2)*1,25 | DG35: *1,2)*1,15 | DI35: *1,2)*1,15 | DJ35: *1,2)*1,25 | DN35: 0 | DO35: 0 | DP35: 1 | DQ35: 1 | DU35: 1013 | DV35: 1 ШТ. | DW35: 1 ШТ. | DX35: 1 | EE35: 56938688 | EF35: 30 | EG35: Строительные работы | EH35: 0 | EJ35: 1 | EK35: 22 | EL35: ТСН-2001.3-17. Водопровод и канализация - внутренние устройства | EM35: ТСН-2001.3-17-1 | EO35: Поправка: Гл.12.Прил.8.п.8. 3_12.00.01.11.001 Поправка: Гл.6.Прил.2.2.п.2.2.6_06.00.01.07.001 | EQ35: 0 | ER35: 278.03 | ES35: 109.65 | ET35: 6.25 | EU35: 0.3 | EV35: 162.13 | EW35: 13.3 | EX35: 0 | EY35: 0 | FQ35: 0 | FR35: 0 | FS35: 0 | FX35: 121 | FY35: 72 | GD35: 1 | GF35: -257018826 | GG35: 2 | GH35: 1 | GI35: 2 | GJ35: 0 | GK35: 0 | GL35: =ROUND(IF(AND(BH35=3,BI35=3,FS35<>0),P35,0),2) -> 0 | GM35: =ROUND(O35+X35+Y35,2)+GX35 -> 40400.63 | GN35: =IF(OR(BI35=0,BI35=1),GM35-GX35,0) -> 40400.63 | GO35: =IF(BI35=2,GM35-GX35,0) -> 0 | GP35: =IF(BI35=4,GM35-GX35,0) -> 0 | GR35: 0 | GS35: 3 | GT35: 0 | GV35: =ROUND((GT35),6) -> 0 | GW35: 1 | GX35: =ROUND(HC35*I35,2) -> 0 | HA35: 0 | HB35: 0 | HC35: =GV35*GW35 -> 0 | HS35: 0 | IK35: 0
A36: 17 | B36: 1 | C36: =ROW(SmtRes!A77) -> 77 | D36: =ROW(EtalonRes!A89) -> 89 | F36: 4.6-48-4 | G36: Бак внутренней установки без давления цилиндрический вертикальный, вместимость 1,0 м3 (60 л.) | H36: 1 Т | I36: 0.009 | J36: 0 | K36: 0.009 | O36: =ROUND(CP36,2) -> 100.94 | P36: =ROUND((ROUND((AC36*AW36*I36),2)*BC36),2) -> 1.23 | Q36: =(ROUND((ROUND((((ET36*1.2))*AV36*I36),2)*BB36),2)+ROUND((ROUND(((AE36-((EU36*1.2)))*AV36*I36),2)*BS36),2)) -> 35.34 | R36: =(ROUND((ROUND((((EU36*1.2))*AV36*I36),2)*BS36),2)+ROUND((ROUND(((AE36-((EU36*1.2)))*AV36*I36),2)*BS36),2)) -> 10.63 | S36: =ROUND((ROUND((AF36*AV36*I36),2)*BA36),2) -> 64.37 | T36: =ROUND(CU36*I36,2) -> 0 | U36: =CV36*I36 -> 5.6119932 | V36: =CW36*I36 -> 0 | W36: =ROUND(CX36*I36,2) -> 0 | X36: =(ROUND((((S36+ROUND((ROUND((((EU36*1.2))*AV36*I36),2)*BS36),2))*AT36)/100),2)+ROUND(((ROUND((ROUND(((AE36-((EU36*1.2)))*AV36*I36),2)*BS36),2)*AT36)/100),2)) -> 66.75 | Y36: =(ROUND((((S36+ROUND((ROUND((((EU36*1.2))*AV36*I36),2)*BS36),2))*AU36)/100),2)+ROUND(((ROUND((ROUND(((AE36-((EU36*1.2)))*AV36*I36),2)*BS36),2)*AU36)/100),2)) -> 33.75 | AA36: -1 | AB36: =ROUND((AC36+AD36+AF36),6) -> 10515.652 | AC36: =ROUND(((ES36*1)),6) -> 133 | AD36: =ROUND(((((ET36*1.2))-((EU36*1.2)))+AE36),6) -> 3679.584 | AE36: =ROUND(((EU36*1.2)),6) -> 1107.072 | AF36: =ROUND(((EV36*1.2)),6) -> 6703.068 | AG36: =ROUND((AP36),6) -> 0 | AH36: =((EW36*1.2)) -> 584.4 | AI36: =((EX36*1.2)) -> 0 | AJ36: =(AS36) -> 0 | AK36: 8785.21 | AL36: 133 | AM36: 3066.32 | AN36: 922.56 | AO36: 5585.89 | AP36: 0 | AQ36: 487 | AR36: 0 | AS36: 0 | AT36: 89 | AU36: 45 | AV36: 1.067 | AW36: 1.028 | AZ36: 1 | BA36: 1 | BB36: 1 | BC36: 1 | BH36: 0 | BI36: 2 | BJ36: ТСН-2001.4. Доп. 1-42. Сб. 6, т. 48, поз. 4 | BM36: 65 | BN36: 0 | BO36: 4.6-48-4 | BP36: 1 | BQ36: 40 | BR36: 0 | BS36: 1 | BT36: 1 | BU36: 1 | BV36: 1 | BW36: 1 | BX36: 1 | BZ36: 89 | CA36: 45 | CE36: 1566 | CF36: 0 | CG36: 0 | CM36: 0 | CN36: Поправка: Гл.12.Прил.8.п.8. 3_12.00.01.11.001 Наименование: При наличии напряженных и стесненных условий производства работ (стесненность, сложность складирования и транспортной логистики и т.п.) для объектов, расположенных в пределах круговой магистральной системы улиц "Садовое кольцо" города Москвы | CO36: 0 | CP36: =(P36+Q36+S36) -> 100.94 | CQ36: =ROUND((ROUND((AC36*AW36*1),2)*BC36),2) -> 136.72 | CR36: =(ROUND((ROUND((((ET36*1.2))*AV36*1),2)*BB36),2)+ROUND((ROUND(((AE36-((EU36*1.2)))*AV36*1),2)*BS36),2)) -> 3926.12 | CS36: =(ROUND((ROUND((((EU36*1.2))*AV36*1),2)*BS36),2)+ROUND((ROUND(((AE36-((EU36*1.2)))*AV36*1),2)*BS36),2)) -> 1181.25 | CT36: =ROUND((ROUND((AF36*AV36*1),2)*BA36),2) -> 7152.17 | CU36: =AG36 -> 0 | CV36: =(AH36*AV36) -> 623.5548 | CW36: =AI36 -> 0 | CX36: =AJ36 -> 0 | CY36: =(ROUND((((S36+ROUND((ROUND((((EU36*1.2))*AV36*1),2)*BS36),2))*AT36)/100),2)+ROUND(((ROUND((ROUND(((AE36-((EU36*1.2)))*AV36*1),2)*BS36),2)*AT36)/100),2)) -> 1108.6 | CZ36: =(ROUND((((S36+ROUND((ROUND((((EU36*1.2))*AV36*1),2)*BS36),2))*AU36)/100),2)+ROUND(((ROUND((ROUND(((AE36-((EU36*1.2)))*AV36*1),2)*BS36),2)*AU36)/100),2)) -> 560.53 | DB36: 15 | DD36: *1 | DE36: *1,2 | DF36: *1,2 | DG36: *1,2 | DI36: *1,2 | DJ36: *1,2 | DN36: 0 | DO36: 0 | DP36: 1 | DQ36: 1 | DU36: 1013 | DV36: 1 Т | DW36: 1 Т | DX36: 1 | EE36: 56938732 | EF36: 40 | EG36: Монтаж оборудования | EH36: 0 | EJ36: 2 | EK36: 65 | EL36: ТСН-2001.4-6. Теплосиловое оборудование | EM36: ТСН-2001.4-6-1 | EO36: Поправка: Гл.12.Прил.8.п.8. 3_12.00.01.11.001 | EQ36: 132096 | ER36: 8785.21 | ES36: 133 | ET36: 3066.32 | EU36: 922.56 | EV36: 5585.89 | EW36: 487 | EX36: 0 | EY36: 0 | FQ36: 0 | FR36: 0 | FS36: 2 | FX36: 89 | FY36: 45 | GD36: 1 | GF36: -966979253 | GG36: 2 | GH36: 1 | GI36: 2 | GJ36: 0 | GK36: 0 | GL36: =ROUND(IF(AND(BH36=3,BI36=3,FS36<>0),P36,0),2) -> 0 | GM36: =ROUND(O36+X36+Y36,2)+GX36 -> 201.44 | GN36: =IF(OR(BI36=0,BI36=1),GM36-GX36,0) -> 0 | GO36: =IF(BI36=2,GM36-GX36,0) -> 201.44 | GP36: =IF(BI36=4,GM36-GX36,0) -> 0 | GR36: 0 | GS36: 3 | GT36: 0 | GV36: =ROUND((GT36),6) -> 0 | GW36: 1 | GX36: =ROUND(HC36*I36,2) -> 0 | HA36: 0 | HB36: 0 | HC36: =GV36*GW36 -> 0 | HS36: 0 | IK36: 0
A37: 17 | B37: 1 | C37: =ROW(SmtRes!A78) -> 78 | D37: =ROW(EtalonRes!A90) -> 90 | F37: 4.6-48-4 | G37: Бак внутренней установки без давления цилиндрический вертикальный, вместимость 1,0 м3 (60 л.) | H37: 1 Т | I37: 0.009 | J37: 0 | K37: 0.009 | O37: =ROUND(CP37,2) -> 4509.42 | P37: =ROUND((ROUND((AC37*AW37*I37),2)*BC37),2) -> 12.1 | Q37: =(ROUND((ROUND((((ET37*1.2))*AV37*I37),2)*BB37),2)+ROUND((ROUND(((AE37-((EU37*1.2)))*AV37*I37),2)*BS37),2)) -> 870.07 | R37: =(ROUND((ROUND((((EU37*1.2))*AV37*I37),2)*BS37),2)+ROUND((ROUND(((AE37-((EU37*1.2)))*AV37*I37),2)*BS37),2)) -> 599 | S37: =ROUND((ROUND((AF37*AV37*I37),2)*BA37),2) -> 3627.25 | T37: =ROUND(CU37*I37,2) -> 0 | U37: =CV37*I37 -> 5.6119932 | V37: =CW37*I37 -> 0 | W37: =ROUND(CX37*I37,2) -> 0 | X37: =(ROUND((((S37+ROUND((ROUND((((EU37*1.2))*AV37*I37),2)*BS37),2))*AT37)/100),2)+ROUND(((ROUND((ROUND(((AE37-((EU37*1.2)))*AV37*I37),2)*BS37),2)*AT37)/100),2)) -> 3761.36 | Y37: =(ROUND((((S37+ROUND((ROUND((((EU37*1.2))*AV37*I37),2)*BS37),2))*AU37)/100),2)+ROUND(((ROUND((ROUND(((AE37-((EU37*1.2)))*AV37*I37),2)*BS37),2)*AU37)/100),2)) -> 1901.81 | AA37: -1 | AB37: =ROUND((AC37+AD37+AF37),6) -> 10515.652 | AC37: =ROUND(((ES37*1)),6) -> 133 | AD37: =ROUND(((((ET37*1.2))-((EU37*1.2)))+AE37),6) -> 3679.584 | AE37: =ROUND(((EU37*1.2)),6) -> 1107.072 | AF37: =ROUND(((EV37*1.2)),6) -> 6703.068 | AG37: =ROUND((AP37),6) -> 0 | AH37: =((EW37*1.2)) -> 584.4 | AI37: =((EX37*1.2)) -> 0 | AJ37: =(AS37) -> 0 | AK37: 8785.21 | AL37: 133 | AM37: 3066.32 | AN37: 922.56 | AO37: 5585.89 | AP37: 0 | AQ37: 487 | AR37: 0 | AS37: 0 | AT37: 89 | AU37: 45 | AV37: 1.067 | AW37: 1.028 | AZ37: 1 | BA37: 56.35 | BB37: 24.62 | BC37: 9.84 | BH37: 0 | BI37: 2 | BJ37: ТСН-2001.4. Доп. 1-42. Сб. 6, т. 48, поз. 4 | BM37: 65 | BN37: 0 | BO37: 4.6-48-4 | BP37: 1 | BQ37: 40 | BR37: 0 | BS37: 56.35 | BT37: 1 | BU37: 1 | BV37: 1 | BW37: 1 | BX37: 1 | BZ37: 89 | CA37: 45 | CE37: 1566 | CF37: 0 | CG37: 0 | CM37: 0 | CN37: Поправка: Гл.12.Прил.8.п.8. 3_12.00.01.11.001 Наименование: При наличии напряженных и стесненных условий производства работ (стесненность, сложность складирования и транспортной логистики и т.п.) для объектов, расположенных в пределах круговой магистральной системы улиц "Садовое кольцо" города Москвы | CO37: 0 | CP37: =(P37+Q37+S37) -> 4509.42 | CQ37: =ROUND((ROUND((AC37*AW37*1),2)*BC37),2) -> 1345.32 | CR37: =(ROUND((ROUND((((ET37*1.2))*AV37*1),2)*BB37),2)+ROUND((ROUND(((AE37-((EU37*1.2)))*AV37*1),2)*BS37),2)) -> 96661.07 | CS37: =(ROUND((ROUND((((EU37*1.2))*AV37*1),2)*BS37),2)+ROUND((ROUND(((AE37-((EU37*1.2)))*AV37*1),2)*BS37),2)) -> 66563.44 | CT37: =ROUND((ROUND((AF37*AV37*1),2)*BA37),2) -> 403024.78 | CU37: =AG37 -> 0 | CV37: =(AH37*AV37) -> 623.5548 | CW37: =AI37 -> 0 | CX37: =AJ37 -> 0 | CY37: =(ROUND((((S37+ROUND((ROUND((((EU37*1.2))*AV37*1),2)*BS37),2))*AT37)/100),2)+ROUND(((ROUND((ROUND(((AE37-((EU37*1.2)))*AV37*1),2)*BS37),2)*AT37)/100),2)) -> 62469.71 | CZ37: =(ROUND((((S37+ROUND((ROUND((((EU37*1.2))*AV37*1),2)*BS37),2))*AU37)/100),2)+ROUND(((ROUND((ROUND(((AE37-((EU37*1.2)))*AV37*1),2)*BS37),2)*AU37)/100),2)) -> 31585.81 | DB37: 16 | DD37: *1 | DE37: *1,2 | DF37: *1,2 | DG37: *1,2 | DI37: *1,2 | DJ37: *1,2 | DN37: 0 | DO37: 0 | DP37: 1 | DQ37: 1 | DU37: 1013 | DV37: 1 Т | DW37: 1 Т | DX37: 1 | EE37: 56938732 | EF37: 40 | EG37: Монтаж оборудования | EH37: 0 | EJ37: 2 | EK37: 65 | EL37: ТСН-2001.4-6. Теплосиловое оборудование | EM37: ТСН-2001.4-6-1 | EO37: Поправка: Гл.12.Прил.8.п.8. 3_12.00.01.11.001 | EQ37: 132096 | ER37: 8785.21 | ES37: 133 | ET37: 3066.32 | EU37: 922.56 | EV37: 5585.89 | EW37: 487 | EX37: 0 | EY37: 0 | FQ37: 0 | FR37: 0 | FS37: 2 | FX37: 89 | FY37: 45 | GD37: 1 | GF37: -966979253 | GG37: 2 | GH37: 1 | GI37: 2 | GJ37: 0 | GK37: 0 | GL37: =ROUND(IF(AND(BH37=3,BI37=3,FS37<>0),P37,0),2) -> 0 | GM37: =ROUND(O37+X37+Y37,2)+GX37 -> 10172.59 | GN37: =IF(OR(BI37=0,BI37=1),GM37-GX37,0) -> 0 | GO37: =IF(BI37=2,GM37-GX37,0) -> 10172.59 | GP37: =IF(BI37=4,GM37-GX37,0) -> 0 | GR37: 0 | GS37: 3 | GT37: 0 | GV37: =ROUND((GT37),6) -> 0 | GW37: 1 | GX37: =ROUND(HC37*I37,2) -> 0 | HA37: 0 | HB37: 0 | HC37: =GV37*GW37 -> 0 | HS37: 0 | IK37: 0
A38: 17 | B38: 1 | C38: =ROW(SmtRes!A86) -> 86 | D38: =ROW(EtalonRes!A99) -> 99 | F38: 3.18-8-1 | G38: Установка баков расширительных круглых и прямоугольных вместимостью до 0,1 м3 (60 л.) | H38: 1 бак | I38: 1 | J38: 0 | K38: 1 | O38: =ROUND(CP38,2) -> 57.22 | P38: =ROUND((ROUND((AC38*AW38*I38),2)*BC38),2) -> 4.19 | Q38: =(ROUND((ROUND(((ET38)*AV38*I38),2)*BB38),2)+ROUND((ROUND(((AE38-(EU38))*AV38*I38),2)*BS38),2)) -> 8.07 | R38: =(ROUND((ROUND(((EU38)*AV38*I38),2)*BS38),2)+ROUND((ROUND(((AE38-(EU38))*AV38*I38),2)*BS38),2)) -> 0.63 | S38: =ROUND((ROUND((AF38*AV38*I38),2)*BA38),2) -> 44.96 | T38: =ROUND(CU38*I38,2) -> 0 | U38: =CV38*I38 -> 3.87321 | V38: =CW38*I38 -> 0 | W38: =ROUND(CX38*I38,2) -> 0 | X38: =(ROUND((((S38+ROUND((ROUND(((EU38)*AV38*I38),2)*BS38),2))*AT38)/100),2)+ROUND(((ROUND((ROUND(((AE38-(EU38))*AV38*I38),2)*BS38),2)*AT38)/100),2)) -> 55.16 | Y38: =(ROUND((((S38+ROUND((ROUND(((EU38)*AV38*I38),2)*BS38),2))*AU38)/100),2)+ROUND(((ROUND((ROUND(((AE38-(EU38))*AV38*I38),2)*BS38),2)*AU38)/100),2)) -> 32.82 | AA38: -1 | AB38: =ROUND((AC38+AD38+AF38),6) -> 53.89 | AC38: =ROUND((ES38),6) -> 4.19 | AD38: =ROUND((((ET38)-(EU38))+AE38),6) -> 7.56 | AE38: =ROUND((EU38),6) -> 0.59 | AF38: =ROUND((EV38),6) -> 42.14 | AG38: =ROUND((AP38),6) -> 0 | AH38: =(EW38) -> 3.63 | AI38: =(EX38) -> 0 | AJ38: =(AS38) -> 0 | AK38: 53.89 | AL38: 4.19 | AM38: 7.56 | AN38: 0.59 | AO38: 42.14 | AP38: 0 | AQ38: 3.63 | AR38: 0 | AS38: 0 | AT38: 121 | AU38: 72 | AV38: 1.067 | AW38: 1 | AZ38: 1 | BA38: 1 | BB38: 1 | BC38: 1 | BH38: 0 | BI38: 1 | BJ38: ТСН-2001.3 Доп. 72, Сб. 18, т. 8, поз. 1 | BM38: 23 | BN38: 0 | BO38: 3.18-8-1 | BP38: 1 | BQ38: 30 | BR38: 0 | BS38: 1 | BT38: 1 | BU38: 1 | BV38: 1 | BW38: 1 | BX38: 1 | BZ38: 121 | CA38: 72 | CE38: 1566 | CF38: 0 | CG38: 0 | CM38: 0 | CO38: 0 | CP38: =(P38+Q38+S38) -> 57.22 | CQ38: =ROUND((ROUND((AC38*AW38*1),2)*BC38),2) -> 4.19 | CR38: =(ROUND((ROUND(((ET38)*AV38*1),2)*BB38),2)+ROUND((ROUND(((AE38-(EU38))*AV38*1),2)*BS38),2)) -> 8.07 | CS38: =(ROUND((ROUND(((EU38)*AV38*1),2)*BS38),2)+ROUND((ROUND(((AE38-(EU38))*AV38*1),2)*BS38),2)) -> 0.63 | CT38: =ROUND((ROUND((AF38*AV38*1),2)*BA38),2) -> 44.96 | CU38: =AG38 -> 0 | CV38: =(AH38*AV38) -> 3.87321 | CW38: =AI38 -> 0 | CX38: =AJ38 -> 0 | CY38: =(ROUND((((S38+ROUND((ROUND(((EU38)*AV38*1),2)*BS38),2))*AT38)/100),2)+ROUND(((ROUND((ROUND(((AE38-(EU38))*AV38*1),2)*BS38),2)*AT38)/100),2)) -> 55.16 | CZ38: =(ROUND((((S38+ROUND((ROUND(((EU38)*AV38*1),2)*BS38),2))*AU38)/100),2)+ROUND(((ROUND((ROUND(((AE38-(EU38))*AV38*1),2)*BS38),2)*AU38)/100),2)) -> 32.82 | DN38: 0 | DO38: 0 | DP38: 1 | DQ38: 1 | DU38: 1013 | DV38: 1 бак | DW38: 1 бак | DX38: 1 | EE38: 56938689 | EF38: 30 | EG38: Строительные работы | EH38: 0 | EJ38: 1 | EK38: 23 | EL38: ТСН-2001.3-18. Отопление - внутренние устройства | EM38: ТСН-2001.3-18-1 | EQ38: 132096 | ER38: 53.89 | ES38: 4.19 | ET38: 7.56 | EU38: 0.59 | EV38: 42.14 | EW38: 3.63 | EX38: 0 | EY38: 0 | FQ38: 0 | FR38: 0 | FS38: 0 | FX38: 121 | FY38: 72 | GD38: 1 | GF38: 1630609332 | GG38: 2 | GH38: 1 | GI38: 2 | GJ38: 0 | GK38: 0 | GL38: =ROUND(IF(AND(BH38=3,BI38=3,FS38<>0),P38,0),2) -> 0 | GM38: =ROUND(O38+X38+Y38,2)+GX38 -> 145.2 | GN38: =IF(OR(BI38=0,BI38=1),GM38-GX38,0) -> 145.2 | GO38: =IF(BI38=2,GM38-GX38,0) -> 0 | GP38: =IF(BI38=4,GM38-GX38,0) -> 0 | GR38: 0 | GS38: 3 | GT38: 0 | GV38: =ROUND((GT38),6) -> 0 | GW38: 1 | GX38: =ROUND(HC38*I38,2) -> 0 | HA38: 0 | HB38: 0 | HC38: =GV38*GW38 -> 0 | HS38: 0 | IK38: 0
