Workbook

Sheet Смета по ТСН-2001(с доп.67
A1: =Source!B1 -> Smeta.RU (495) 974-1589
J2: Форма № 4б
A3: Капитальный ремонт здания Государственного бюджетного общеобразовательного учреждения города Москвы «Школа №1574», расположенного по адресу: г. Москва, Старопименовский переулок, д. 5. 1 этап. | AP3: Капитальный ремонт здания Государственного бюджетного общеобразовательного учреждения города Москвы «Школа №1574», расположенного по адресу: г. Москва, Старопименовский переулок, д. 5. 1 этап.
A4: (наименование стройки и/или объекта)
A6: =CONCATENATE( "ЛОКАЛЬНАЯ СМЕТА № ",IF(Source!F12<>"Новый объект", Source!F12, "")) -> ЛОКАЛЬНАЯ СМЕТА № 02-01-06.
A8: Отопление.
A9: (наименование работ и затрат)
A11: =CONCATENATE( "Основание: чертежи № ", Source!J12) -> Основание: чертежи № 2024-00375-01-0-ИОС4.1
I13: В базисном уровне цен | J13: В текущем уровне цен
E14: Сметная стоимость | I14: =I15+I16+I17+I18 -> 1411.49 | J14: =J15+J16+J17+J18 -> 19902.93 | K14: тыс.руб.
E15: Строительные работы | I15: =ROUND((Source!F675)/1000, 2) -> 1379.86 | J15: =ROUND((Source!P675)/1000, 2) -> 19683.43 | K15: тыс.руб.
E16: Работы по монтажу оборудования | I16: =ROUND((Source!F676)/1000, 2) -> 0.17 | J16: =ROUND((Source!P676)/1000, 2) -> 9.46 | K16: тыс.руб.
E17: Оборудование | I17: =ROUND((Source!F667)/1000, 2) -> 31.46 | J17: =ROUND((Source!P667)/1000, 2) -> 210.04 | K17: тыс.руб.
E18: Прочие работы и затраты | I18: =ROUND((Source!F677+Source!F678)/1000, 2) -> 0 | J18: =ROUND((Source!P677+Source!P678)/1000, 2) -> 0 | K18: тыс.руб.
E19: Средства на оплату труда | I19: =(Source!F673+ Source!F672)/1000 -> 57.03786 | J19: =((Source!P673 + Source!P672)/1000) -> 3214.0835 | K19: тыс.руб.
E20: Затраты труда | I20: =Source!F680 -> 4400.9578 | K20: чел.-ч.
E21: Кроме того:
E22: Возврат материалов | I22: =SUM(Y1:Y842)/1000 -> 0 | J22: =SUM(Z1:Z842)/1000 -> 0 | K22: тыс.руб.
A24: Составлен(а) по ТСН-2001 с учетом Дополнения №: 81
A25: № и период сборника коэффициентов (индексов) пересчета: Коэффициенты к ТСН-2001 МГЭ Дополнение 81, ремонт №219/81 I квартал 2026 года и Коэффициенты к ТСН-2001.13-2 Дополнение 47 №64/47 I квартал 2026 года | AP25: № и период сборника коэффициентов (индексов) пересчета: Коэффициенты к ТСН-2001 МГЭ Дополнение 81, ремонт №219/81 I квартал 2026 года и Коэффициенты к ТСН-2001.13-2 Дополнение 47 №64/47 I квартал 2026 года
A26: № п/п | B26: Шифр расценки и коды ресурсов | C26: Наименование работ и затрат | D26: Ед. изм. | E26: Кол-во единиц | F26: Цена на ед. изм., руб. | G26: Попра- вочные коэффи- циенты | H26: Коэффи- циенты зимних удорожа- ний | I26: Всего в ценах на январь 2000 года, руб. | J26: Коэффи- циенты (индек- сы) пере- счета, нормы НР и СП | K26: ВСЕГО затрат в текущем уровне цен, руб.
A27: 1 | B27: 2 | C27: 3 | D27: 4 | E27: 5 | F27: 6 | G27: 7 | H27: 8 | I27: 9 | J27: 10 | K27: 11
A29: =CONCATENATE("Локальная смета: ",IF(Source!G20<>"Новая локальная смета", Source!G20, "")) -> Локальная смета: Отопление.
A31: =CONCATENATE("Раздел: ",IF(Source!G24<>"Новый раздел", Source!G24, "")) -> Раздел: Отопительные приборы.
A32: 1 | B32: =Source!F28 -> 3.18-25-1 | C32: Установка радиаторов стальных панельных однорядных с креплением к стене длиной до 1600 мм (вентиль справа) | D32: =Source!H28 -> 100 шт. | E32: =Source!I28 -> 1.33 | Q32: =Source!X28 -> 2039.9 | R32: =Source!X29 -> 114948.49 | S32: =Source!Y28 -> 1141.6 | T32: =Source!Y29 -> 64328.97 | U32: =ROUND((175/100)*ROUND(Source!R28, 2), 2) -> 39.52 | V32: =ROUND((0/100)*ROUND(Source!R29, 2), 2) -> 0 | AC32: 0
C33: ="Объем: "&Source!I28&"=(1+"&"9+"&"11+"&"13+"&"23+"&"2+"&"10+"&"13+"&"18+"&"6+"&"17+"&"2+"&"8)/"&"100" -> Объем: 1,33=(1+9+11+13+23+2+10+13+18+6+17+2+8)/100
C34: ЗП | F34: =Source!AO28 -> 916.6 | G34: 1,03*1,15*1,2 | H34: =Source!AV29 -> 1.067 | I34: =Source!S28 -> 1848.89 | J34: =IF(Source!BA29<> 0, Source!BA29, 1) -> 56.35 | K34: =Source!S29 -> 104184.95
C35: ЭМ | F35: =Source!AM28 -> 95.35 | G35: 1,03*1,25*1,2 | H35: =Source!AV29 -> 1.067 | I35: =Source!Q28 -> 209.06 | J35: =IF(Source!BB29<> 0, Source!BB29, 1) -> 15.04 | K35: =Source!Q29 -> 3144.26
C36: в т.ч. ЗПМ | F36: =Source!AN28 -> 10.3 | G36: 1,03*1,25*1,2 | H36: =Source!AV29 -> 1.067 | I36: =Source!R28 -> 22.58 | J36: =IF(Source!BS29<> 0, Source!BS29, 1) -> 56.35 | K36: =Source!R29 -> 1272.38
C37: МР | F37: =Source!AL28 -> 2078.86 | H37: =Source!AW29 -> 1 | I37: =Source!P28 -> 2764.88 | J37: =IF(Source!BC29<> 0, Source!BC29, 1) -> 20.83 | K37: =Source!P29 -> 57592.45
A38: 1,1 | B38: =Source!F30 -> КА. п. 1 | C38: Сmальной nанельный paguamop PRADO Classic, mun 20, Bыcoma Н = 500 мм, PRADO Classic-20-500-400 373,26 = [4 393 / 1,22 / 9,84] + 2% Заг.скл | D38: =Source!H30 -> шт. | E38: =Source!I30 -> 1 | F38: =Source!AK30 -> 373.26 | H38: =Source!AW31 -> 1 | I38: =Source!O30 -> 373.26 | J38: =IF(Source!BC31<> 0, Source!BC31, 1) -> 9.84 | K38: =Source!O31 -> 3672.88 | Q38: =Source!X30 -> 0 | R38: =Source!X31 -> 0 | S38: =Source!Y30 -> 0 | T38: =Source!Y31 -> 0 | U38: =ROUND((175/100)*ROUND(Source!R30, 2), 2) -> 0 | V38: =ROUND((0/100)*ROUND(Source!R31, 2), 2) -> 0 | AC38: 3
A39: 1,2 | B39: =Source!F32 -> КА. п. 2 | C39: Сmальной nанельный paguamop PRADO Classic, mun 20, Bыcoma Н = 500 мм, PRADO Classic-20-500-500 431,97 = [5 084 / 1,22 / 9,84] + 2% Заг.скл | D39: =Source!H32 | E39: =Source!I32 -> 9 | F39: =Source!AK32 -> 431.97 | H39: =Source!AW33 -> 1 | I39: =Source!O32 -> 3887.73 | J39: =IF(Source!BC33<> 0, Source!BC33, 1) -> 9.84 | K39: =Source!O33 -> 38255.26 | Q39: =Source!X32 -> 0 | R39: =Source!X33 -> 0 | S39: =Source!Y32 -> 0 | T39: =Source!Y33 -> 0 | U39: =ROUND((175/100)*ROUND(Source!R32, 2), 2) -> 0 | V39: =ROUND((0/100)*ROUND(Source!R33, 2), 2) -> 0 | AC39: 3
A40: 1,3 | B40: =Source!F34 -> КА. п. 3 | C40: Сmальной nанельный paguamop PRADO Classic, mun 20, Bыcoma Н = 500 мм, PRADO Classic-20-500-600 494,25 = [5 817 / 1,22 / 9,84] + 2% Заг.скл | D40: =Source!H34 | E40: =Source!I34 -> 11 | F40: =Source!AK34 -> 494.25 | H40: =Source!AW35 -> 1 | I40: =Source!O34 -> 5436.75 | J40: =IF(Source!BC35<> 0, Source!BC35, 1) -> 9.84 | K40: =Source!O35 -> 53497.62 | Q40: =Source!X34 -> 0 | R40: =Source!X35 -> 0 | S40: =Source!Y34 -> 0 | T40: =Source!Y35 -> 0 | U40: =ROUND((175/100)*ROUND(Source!R34, 2), 2) -> 0 | V40: =ROUND((0/100)*ROUND(Source!R35, 2), 2) -> 0 | AC40: 3
A41: 1,4 | B41: =Source!F36 -> КА. п. 4 | C41: Сmальной nанельный paguamop PRADO Classic, mun 20, Bыcoma Н = 500 мм, PRADO Classic-20-500-700 545,65 = [6 422 / 1,22 / 9,84] + 2% Заг.скл | D41: =Source!H36 | E41: =Source!I36 -> 13 | F41: =Source!AK36 -> 545.65 | H41: =Source!AW37 -> 1 | I41: =Source!O36 -> 7093.45 | J41: =IF(Source!BC37<> 0, Source!BC37, 1) -> 9.84 | K41: =Source!O37 -> 69799.55 | Q41: =Source!X36 -> 0 | R41: =Source!X37 -> 0 | S41: =Source!Y36 -> 0 | T41: =Source!Y37 -> 0 | U41: =ROUND((175/100)*ROUND(Source!R36, 2), 2) -> 0 | V41: =ROUND((0/100)*ROUND(Source!R37, 2), 2) -> 0 | AC41: 3
A42: 1,5 | B42: =Source!F38 -> КА. п. 5 | C42: Сmальной nанельный paguamop PRADO Classic, mun 20, Bыcoma Н = 500 мм, PRADO Classic-20-500-800 601,47 = [7 079 / 1,22 / 9,84] + 2% Заг.скл | D42: =Source!H38 | E42: =Source!I38 -> 23 | F42: =Source!AK38 -> 601.47 | H42: =Source!AW39 -> 1 | I42: =Source!O38 -> 13833.81 | J42: =IF(Source!BC39<> 0, Source!BC39, 1) -> 9.84 | K42: =Source!O39 -> 136124.69 | Q42: =Source!X38 -> 0 | R42: =Source!X39 -> 0 | S42: =Source!Y38 -> 0 | T42: =Source!Y39 -> 0 | U42: =ROUND((175/100)*ROUND(Source!R38, 2), 2) -> 0 | V42: =ROUND((0/100)*ROUND(Source!R39, 2), 2) -> 0 | AC42: 3
A43: 1,6 | B43: =Source!F40 -> КА. п. 6 | C43: Сmальной nанельный paguamop PRADO Classic, mun 20, Bыcoma Н = 500 мм, PRADO Classic-20-500-900 660,10 = [7 769 / 1,22 / 9,84] + 2% Заг.скл | D43: =Source!H40 | E43: =Source!I40 -> 2 | F43: =Source!AK40 -> 660.1 | H43: =Source!AW41 -> 1 | I43: =Source!O40 -> 1320.2 | J43: =IF(Source!BC41<> 0, Source!BC41, 1) -> 9.84 | K43: =Source!O41 -> 12990.77 | Q43: =Source!X40 -> 0 | R43: =Source!X41 -> 0 | S43: =Source!Y40 -> 0 | T43: =Source!Y41 -> 0 | U43: =ROUND((175/100)*ROUND(Source!R40, 2), 2) -> 0 | V43: =ROUND((0/100)*ROUND(Source!R41, 2), 2) -> 0 | AC43: 3
A44: 1,7 | B44: =Source!F42 -> КА. п. 7 | C44: Сmальной nанельный paguamop PRADO Classic, mun 20, Bыcoma Н = 500 мм, PRADO Classic-20-500-1000 726,04 = [8 545 / 1,22 / 9,84] + 2% Заг.скл | D44: =Source!H42 | E44: =Source!I42 -> 10 | F44: =Source!AK42 -> 726.04 | H44: =Source!AW43 -> 1 | I44: =Source!O42 -> 7260.4 | J44: =IF(Source!BC43<> 0, Source!BC43, 1) -> 9.84 | K44: =Source!O43 -> 71442.34 | Q44: =Source!X42 -> 0 | R44: =Source!X43 -> 0 | S44: =Source!Y42 -> 0 | T44: =Source!Y43 -> 0 | U44: =ROUND((175/100)*ROUND(Source!R42, 2), 2) -> 0 | V44: =ROUND((0/100)*ROUND(Source!R43, 2), 2) -> 0 | AC44: 3
A45: 1,8 | B45: =Source!F44 -> КА. п. 8 | C45: Сmальной nанельный paguamop PRADO Classic, mun 20, Bыcoma Н = 500 мм, PRADO Classic-20-500-1100 781,86 = [9 202 / 1,22 / 9,84] + 2% Заг.скл | D45: =Source!H44 | E45: =Source!I44 -> 13 | F45: =Source!AK44 -> 781.86 | H45: =Source!AW45 -> 1 | I45: =Source!O44 -> 10164.18 | J45: =IF(Source!BC45<> 0, Source!BC45, 1) -> 9.84 | K45: =Source!O45 -> 100015.53 | Q45: =Source!X44 -> 0 | R45: =Source!X45 -> 0 | S45: =Source!Y44 -> 0 | T45: =Source!Y45 -> 0 | U45: =ROUND((175/100)*ROUND(Source!R44, 2), 2) -> 0 | V45: =ROUND((0/100)*ROUND(Source!R45, 2), 2) -> 0 | AC45: 3
A46: 1,9 | B46: =Source!F46 -> КА. п. 9 | C46: Сmальной nанельный paguamop PRADO Classic, mun 20, Bыcoma Н = 500 мм, PRADO Classic-20-500-1200 837,85 = [9 861 / 1,22 / 9,84] + 2% Заг.скл | D46: =Source!H46 | E46: =Source!I46 -> 18 | F46: =Source!AK46 -> 837.85 | H46: =Source!AW47 -> 1 | I46: =Source!O46 -> 15081.3 | J46: =IF(Source!BC47<> 0, Source!BC47, 1) -> 9.84 | K46: =Source!O47 -> 148399.99 | Q46: =Source!X46 -> 0 | R46: =Source!X47 -> 0 | S46: =Source!Y46 -> 0 | T46: =Source!Y47 -> 0 | U46: =ROUND((175/100)*ROUND(Source!R46, 2), 2) -> 0 | V46: =ROUND((0/100)*ROUND(Source!R47, 2), 2) -> 0 | AC46: 3
A47: 1,10 | B47: =Source!F48 -> КА. п. 10 | C47: Сmальной nанельный paguamop PRADO Classic, mun 20, Bыcoma Н = 500 мм, PRADO Classic-20-500-1300 848,72 = [9 989 / 1,22 / 9,84] + 2% Заг.скл | D47: =Source!H48 | E47: =Source!I48 -> 6 | F47: =Source!AK48 -> 848.72 | H47: =Source!AW49 -> 1 | I47: =Source!O48 -> 5092.32 | J47: =IF(Source!BC49<> 0, Source!BC49, 1) -> 9.84 | K47: =Source!O49 -> 50108.43 | Q47: =Source!X48 -> 0 | R47: =Source!X49 -> 0 | S47: =Source!Y48 -> 0 | T47: =Source!Y49 -> 0 | U47: =ROUND((175/100)*ROUND(Source!R48, 2), 2) -> 0 | V47: =ROUND((0/100)*ROUND(Source!R49, 2), 2) -> 0 | AC47: 3
...

Sheet Source
A1: 0 | B1: Smeta.RU (495) 974-1589 | D1: _PS_ | F1: 0 | G1: 0 | H1: 0 | I1: Smeta.RU | K1: 1 | L1: 74603 | M1: 10 | N1: 12 | O1: 1 | P1: 0 | Q1: 4
A4: 8 | B4: 1 | C4: -1 | F4: Новый проект | G4: Капитальный ремонт здания Государственного бюджетного общеобразовательного учреждения города Москвы «Школа №1574», расположенного по адресу: г. Москва, Старопименовский переулок, д. 5. 1 этап | EC4: 0
A12: 1 | B12: 699 | C12: 0 | D12: =ROW(A658) -> 658 | E12: 0 | F12: 02-01-06. | I12: 0 | J12: 2024-00375-01-0-ИОС4.1 | K12: 0 | L12: 0 | M12: 4098 | O12: 0 | P12: 0 | Q12: 0 | R12: 0 | S12: 0 | T12: 1 | V12: 2 | BB12: 0 | BH12: Сметные нормы списания | BI12: Коды ОКП для ТСН-2001 МГЭ Дополнение 81 | BJ12: 1 | BK12: 1 | BL12: 0 | BM12: 0 | BN12: 1 | BO12: 0 | BP12: 6 | BQ12: 2 | BR12: 1 | BS12: 1 | BT12: 0 | BU12: 0 | BV12: 0 | BW12: 0 | BX12: 0 | BY12: ТСН-2001 (МГЭ) Доп 81 - Ремонт | BZ12: Типовой расчет для ТСН-2001 МГЭ, Дополнение 81, ремонт | CA12: Территориальные сметные нормативы для Москвы ТСН-2001 (МГЭ), дополнение 81 | CB12: Территориальные сметные нормативы для Москвы ТСН-2001 (МГЭ), дополнение 81 | CC12: Территориальные сметные нормативы для Москвы ТСН-2001 (МГЭ), дополнение 81 | CD12: Территориальные сметные нормативы для Москвы ТСН-2001 (МГЭ), дополнение 81 | CE12: Поправки для ТСН-2001 от 07.04.2026 г. доп.81 | CF12: 0 | CG12: 0 | CH12: 8200 | CK12: 81 | CQ12: Территориальные сметные нормативы для Москвы (ТСН-2001) | CR12: ТЕР | CS12: 41660 | CT12: 1 | CU12: 81 | CY12: 0 | EC12: 0
A15: 15 | B15: 1
A18: 52 | B18: =B658 -> 699 | C18: =C658 -> 1 | D18: =D658 -> 12 | E18: =E658 -> 0 | F18: =F658 -> 02-01-06. | G18: =G658 | O18: =O658 -> 1320813.7 | P18: =P658 -> 1259642.9 | Q18: =Q658 -> 4678.66 | R18: =R658 -> 545.75 | S18: =S658 -> 56492.11 | T18: =T658 -> 0 | U18: =U658 -> 4400.9578 | V18: =V658 -> 0 | ... GX18: =GX658 -> 0
A20: 3 | B20: 1 | D20: =ROW(A625) -> 625 | F20: 02-01-06 | G20: Отопление. | I20: 0 | J20: 2024-00375-01-0-ИОС4.1 | K20: -1 | L20: 02-01-06 | S20: 0 | T20: 0 | V20: 2 | BX20: 0 | CF20: 0 | CG20: 0
A22: 52 | B22: =B625 -> 1 | C22: =C625 -> 3 | D22: =D625 -> 20 | E22: =E625 -> 0 | F22: =F625 -> 02-01-06 | G22: =G625 -> Отопление. | O22: =O625 -> 1320813.7 | P22: =P625 -> 1259642.9 | Q22: =Q625 -> 4678.66 | R22: =R625 -> 545.75 | S22: =S625 -> 56492.11 | T22: =T625 -> 0 | U22: =U625 -> 4400.9578 | V22: =V625 -> 0 | ... GX22: =GX625 -> 0
A24: 4 | B24: 1 | D24: =ROW(A261) -> 261 | F24: Новый раздел | G24: Отопительные приборы. | I24: 0 | K24: 0 | S24: 0 | T24: 0 | V24: 2 | BX24: 0 | CJ24: 0
A26: 52 | B26: =B261 -> 1 | C26: =C261 -> 4 | D26: =D261 -> 24 | E26: =E261 -> 0 | F26: =F261 -> Новый раздел | G26: =G261 -> Отопительные приборы. | O26: =O261 -> 832307.31 | P26: =P261 -> 821022.42 | Q26: =Q261 -> 707.04 | R26: =R261 -> 74.21 | S26: =S261 -> 10577.85 | T26: =T261 -> 0 | U26: =U261 -> 873.42104 | V26: =V261 -> 0 | ... GX26: =GX261 -> 0
A28: 17 | B28: 1 | C28: =ROW(SmtRes!A22) -> 22 | D28: =ROW(EtalonRes!A10) -> 10 | E28: 1 | F28: 3.18-25-1 | G28: Установка радиаторов стальных панельных однорядных с креплением к стене длиной до 1600 мм (вентиль справа) | H28: 100 шт. | I28: =ROUND((1+9+11+13+23+2+10+13+18+6+17+2+8)/100,9) -> 1.33 | J28: 0 | K28: =ROUND((1+9+11+13+23+2+10+13+18+6+17+2+8)/100,9) -> 1.33 | O28: =ROUND(CP28,2) -> 4822.83 | P28: =ROUND((ROUND((AC28*AW28*I28),2)*BC28),2) -> 2764.88 | Q28: =(ROUND((ROUND((((((ET28*1.03)*1.25)*1.2))*AV28*I28),2)*BB28),2)+ROUND((ROUND(((AE28-((((EU28*1.03)*1.25)*1.2)))*AV28*I28),2)*BS28),2)) -> 209.06 | R28: =(ROUND((ROUND((((((EU28*1.03)*1.25)*1.2))*AV28*I28),2)*BS28),2)+ROUND((ROUND(((AE28-((((EU28*1.03)*1.25)*1.2)))*AV28*I28),2)*BS28),2)) -> 22.58 | S28: =ROUND((ROUND((AF28*AV28*I28),2)*BA28),2) -> 1848.89 | T28: =ROUND(CU28*I28,2) -> 0 | U28: =CV28*I28 -> 150.67908 | V28: =CW28*I28 -> 0 | W28: =ROUND(CX28*I28,2) -> 0 | X28: =(ROUND((((S28+ROUND((ROUND((((((EU28*1.03)*1.25)*1.2))*AV28*I28),2)*BS28),2))*AT28)/100),2)+ROUND(((ROUND((ROUND(((AE28-((((EU28*1.03)*1.25)*1.2)))*AV28*I28),2)*BS28),2)*AT28)/100),2)) -> 2039.9 | Y28: =(ROUND((((S28+ROUND((ROUND((((((EU28*1.03)*1.25)*1.2))*AV28*I28),2)*BS28),2))*AU28)/100),2)+ROUND(((ROUND((ROUND(((AE28-((((EU28*1.03)*1.25)*1.2)))*AV28*I28),2)*BS28),2)*AU28)/100),2)) -> 1141.6 | AA28: 86551701 | AB28: =ROUND((AC28+AD28+AF28),6) -> 3529.031 | AC28: =ROUND(((((ES28*1)*1)*1)),6) -> 2078.86 | AD28: =ROUND(((((((ET28*1.03)*1.25)*1.2))-((((EU28*1.03)*1.25)*1.2)))+AE28),6) -> 147.31575 | AE28: =ROUND(((((EU28*1.03)*1.25)*1.2)),6) -> 15.9135 | AF28: =ROUND(((((EV28*1.03)*1.15)*1.2)),6) -> 1302.8552 | AG28: =ROUND((AP28),6) -> 0 | AH28: =((((EW28*1.03)*1.15)*1.2)) -> 106.17858 | AI28: =((((EX28*1.03)*1.25)*1.2)) -> 0 | AJ28: =(AS28) -> 0 | AK28: 3090.81 | AL28: 2078.86 | AM28: 95.35 | AN28: 10.3 | AO28: 916.6 | AP28: 0 | AQ28: 74.7 | AR28: 0 | AS28: 0 | AT28: 109 | AU28: 61 | AV28: 1.067 | AW28: 1 | AZ28: 1 | BA28: 1 | BB28: 1 | BC28: 1 | BH28: 0 | BI28: 1 | BJ28: ТСН-2001.3 Доп. 81, Сб. 18, т. 25, поз. 1 | BM28: 23 | BN28: 0 | BO28: 3.18-25-1 | BP28: 1 | BQ28: 30 | BR28: 0 | BS28: 1 | BT28: 1 | BU28: 1 | BV28: 1 | BW28: 1 | BX28: 1 | BZ28: 109 | CA28: 61 | CE28: 1566 | CF28: 0 | CG28: 0 | CM28: 0 | CN28: Поправка: 3-18. О.П. п.1.8 Наименование: Затраты на тепловое испытание систем отопления с проверкой равномерности прогрева отопительных приборов Поправка: Гл.6.Прил.2.2.п.2.2.6_06.00.01.07.001 Наименование: При выполнении при капитальном ремонте и реконструкции работ, аналогичных технологическим процессам, характерным для нового строительства, и отсутствующих в сборниках на ремонтно-строительные работы ТСН-2001.6 Поправка: Гл.12.Прил.8.п.8. 3_12.00.01.11.001 Наименование: При наличии напряженных и стесненных условий производства работ (стесненность, сложность складирования и транспортной логистики и т.п.) для объектов, расположенных в пределах круговой магистральной системы улиц "Садовое кольцо" города Москвы | CO28: 0 | CP28: =(P28+Q28+S28) -> 4822.83 | CQ28: =ROUND((ROUND((AC28*AW28*1),2)*BC28),2) -> 2078.86 | CR28: =(ROUND((ROUND((((((ET28*1.03)*1.25)*1.2))*AV28*1),2)*BB28),2)+ROUND((ROUND(((AE28-((((EU28*1.03)*1.25)*1.2)))*AV28*1),2)*BS28),2)) -> 157.19 | CS28: =(ROUND((ROUND((((((EU28*1.03)*1.25)*1.2))*AV28*1),2)*BS28),2)+ROUND((ROUND(((AE28-((((EU28*1.03)*1.25)*1.2)))*AV28*1),2)*BS28),2)) -> 16.98 | CT28: =ROUND((ROUND((AF28*AV28*1),2)*BA28),2) -> 1390.15 | CU28: =AG28 -> 0 | CV28: =(AH28*AV28) -> 113.29254 | CW28: =AI28 -> 0 | CX28: =AJ28 -> 0 | CY28: =(ROUND((((S28+ROUND((ROUND((((((EU28*1.03)*1.25)*1.2))*AV28*1),2)*BS28),2))*AT28)/100),2)+ROUND(((ROUND((ROUND(((AE28-((((EU28*1.03)*1.25)*1.2)))*AV28*1),2)*BS28),2)*AT28)/100),2)) -> 2033.8 | CZ28: =(ROUND((((S28+ROUND((ROUND((((((EU28*1.03)*1.25)*1.2))*AV28*1),2)*BS28),2))*AU28)/100),2)+ROUND(((ROUND((ROUND(((AE28-((((EU28*1.03)*1.25)*1.2)))*AV28*1),2)*BS28),2)*AU28)/100),2)) -> 1138.18 | DB28: 1 | DD28: *1)*1)*1 | DE28: *1,03)*1,25)*1,2 | DF28: *1,03)*1,25)*1,2 | DG28: *1,03)*1,15)*1,2 | DI28: *1,03)*1,15)*1,2 | DJ28: *1,03)*1,25)*1,2 | DN28: 0 | DO28: 0 | DP28: 1 | DQ28: 1 | DU28: 1010 | DV28: 100 шт. | DW28: 100 шт. | DX28: 100 | EE28: 85635395 | EF28: 30 | EG28: Строительные работы | EH28: 0 | EJ28: 1 | EK28: 23 | EL28: ТСН-2001.3-18. Отопление - внутренние устройства | EM28: ТСН-2001.3-18-1 | EO28: Поправка: 3-18. О.П. п.1.8 Поправка: Гл.6.Прил.2.2.п.2.2.6_06.00.01.07.001 Поправка: Гл.12.Прил.8.п.8. 3_12.00.01.11.001 | EQ28: 131072 | ER28: 3090.81 | ES28: 2078.86 | ET28: 95.35 | EU28: 10.3 | EV28: 916.6 | EW28: 74.7 | EX28: 0 | EY28: 0 | FQ28: 0 | FR28: 0 | FS28: 0 | FX28: 109 | FY28: 61 | GD28: 1 | GF28: -468095277 | GG28: 2 | GH28: 1 | GI28: 2 | GJ28: 0 | GK28: 0 | GL28: =ROUND(IF(AND(BH28=3,BI28=3,FS28<>0),P28,0),2) -> 0 | GM28: =ROUND(O28+X28+Y28,2)+GX28 -> 8004.33 | GN28: =IF(OR(BI28=0,BI28=1),GM28-GX28,0) -> 8004.33 | GO28: =IF(BI28=2,GM28-GX28,0) -> 0 | GP28: =IF(BI28=4,GM28-GX28,0) -> 0 | GR28: 0 | GS28: 3 | GT28: 0 | GV28: =ROUND((GT28),6) -> 0 | GW28: 1 | GX28: =ROUND(HC28*I28,2) -> 0 | HA28: 0 | HB28: 0 | HC28: =GV28*GW28 -> 0 | HS28: 0 | IK28: 0
A29: 17 | B29: 1 | C29: =ROW(SmtRes!A44) -> 44 | D29: =ROW(EtalonRes!A20) -> 20 | E29: 1 | F29: 3.18-25-1 | G29: Установка радиаторов стальных панельных однорядных с креплением к стене длиной до 1600 мм (вентиль справа) | H29: 100 шт. | I29: =ROUND((1+9+11+13+23+2+10+13+18+6+17+2+8)/100,9) -> 1.33 | J29: 0 | K29: =ROUND((1+9+11+13+23+2+10+13+18+6+17+2+8)/100,9) -> 1.33 | O29: =ROUND(CP29,2) -> 164921.66 | P29: =ROUND((ROUND((AC29*AW29*I29),2)*BC29),2) -> 57592.45 | Q29: =(ROUND((ROUND((((((ET29*1.03)*1.25)*1.2))*AV29*I29),2)*BB29),2)+ROUND((ROUND(((AE29-((((EU29*1.03)*1.25)*1.2)))*AV29*I29),2)*BS29),2)) -> 3144.26 | R29: =(ROUND((ROUND((((((EU29*1.03)*1.25)*1.2))*AV29*I29),2)*BS29),2)+ROUND((ROUND(((AE29-((((EU29*1.03)*1.25)*1.2)))*AV29*I29),2)*BS29),2)) -> 1272.38 | S29: =ROUND((ROUND((AF29*AV29*I29),2)*BA29),2) -> 104184.95 | T29: =ROUND(CU29*I29,2) -> 0 | U29: =CV29*I29 -> 150.67908 | V29: =CW29*I29 -> 0 | W29: =ROUND(CX29*I29,2) -> 0 | X29: =(ROUND((((S29+ROUND((ROUND((((((EU29*1.03)*1.25)*1.2))*AV29*I29),2)*BS29),2))*AT29)/100),2)+ROUND(((ROUND((ROUND(((AE29-((((EU29*1.03)*1.25)*1.2)))*AV29*I29),2)*BS29),2)*AT29)/100),2)) -> 114948.49 | Y29: =(ROUND((((S29+ROUND((ROUND((((((EU29*1.03)*1.25)*1.2))*AV29*I29),2)*BS29),2))*AU29)/100),2)+ROUND(((ROUND((ROUND(((AE29-((((EU29*1.03)*1.25)*1.2)))*AV29*I29),2)*BS29),2)*AU29)/100),2)) -> 64328.97 | AA29: 86551703 | AB29: =ROUND((AC29+AD29+AF29),6) -> 3529.031 | AC29: =ROUND(((((ES29*1)*1)*1)),6) -> 2078.86 | AD29: =ROUND(((((((ET29*1.03)*1.25)*1.2))-((((EU29*1.03)*1.25)*1.2)))+AE29),6) -> 147.31575 | AE29: =ROUND(((((EU29*1.03)*1.25)*1.2)),6) -> 15.9135 | AF29: =ROUND(((((EV29*1.03)*1.15)*1.2)),6) -> 1302.8552 | AG29: =ROUND((AP29),6) -> 0 | AH29: =((((EW29*1.03)*1.15)*1.2)) -> 106.17858 | AI29: =((((EX29*1.03)*1.25)*1.2)) -> 0 | AJ29: =(AS29) -> 0 | AK29: 3090.81 | AL29: 2078.86 | AM29: 95.35 | AN29: 10.3 | AO29: 916.6 | AP29: 0 | AQ29: 74.7 | AR29: 0 | AS29: 0 | AT29: 109 | AU29: 61 | AV29: 1.067 | AW29: 1 | AZ29: 1 | BA29: 56.35 | BB29: 15.04 | BC29: 20.83 | BH29: 0 | BI29: 1 | BJ29: ТСН-2001.3 Доп. 81, Сб. 18, т. 25, поз. 1 | BM29: 23 | BN29: 0 | BO29: 3.18-25-1 | BP29: 1 | BQ29: 30 | BR29: 0 | BS29: 56.35 | BT29: 1 | BU29: 1 | BV29: 1 | BW29: 1 | BX29: 1 | BZ29: 109 | CA29: 61 | CE29: 1566 | CF29: 0 | CG29: 0 | CM29: 0 | CN29: Поправка: 3-18. О.П. п.1.8 Наименование: Затраты на тепловое испытание систем отопления с проверкой равномерности прогрева отопительных приборов Поправка: Гл.6.Прил.2.2.п.2.2.6_06.00.01.07.001 Наименование: При выполнении при капитальном ремонте и реконструкции работ, аналогичных технологическим процессам, характерным для нового строительства, и отсутствующих в сборниках на ремонтно-строительные работы ТСН-2001.6 Поправка: Гл.12.Прил.8.п.8. 3_12.00.01.11.001 Наименование: При наличии напряженных и стесненных условий производства работ (стесненность, сложность складирования и транспортной логистики и т.п.) для объектов, расположенных в пределах круговой магистральной системы улиц "Садовое кольцо" города Москвы | CO29: 0 | CP29: =(P29+Q29+S29) -> 164921.66 | CQ29: =ROUND((ROUND((AC29*AW29*1),2)*BC29),2) -> 43302.65 | CR29: =(ROUND((ROUND((((((ET29*1.03)*1.25)*1.2))*AV29*1),2)*BB29),2)+ROUND((ROUND(((AE29-((((EU29*1.03)*1.25)*1.2)))*AV29*1),2)*BS29),2)) -> 2364.14 | CS29: =(ROUND((ROUND((((((EU29*1.03)*1.25)*1.2))*AV29*1),2)*BS29),2)+ROUND((ROUND(((AE29-((((EU29*1.03)*1.25)*1.2)))*AV29*1),2)*BS29),2)) -> 956.82 | CT29: =ROUND((ROUND((AF29*AV29*1),2)*BA29),2) -> 78334.95 | CU29: =AG29 -> 0 | CV29: =(AH29*AV29) -> 113.29254 | CW29: =AI29 -> 0 | CX29: =AJ29 -> 0 | CY29: =(ROUND((((S29+ROUND((ROUND((((((EU29*1.03)*1.25)*1.2))*AV29*1),2)*BS29),2))*AT29)/100),2)+ROUND(((ROUND((ROUND(((AE29-((((EU29*1.03)*1.25)*1.2)))*AV29*1),2)*BS29),2)*AT29)/100),2)) -> 114604.53 | CZ29: =(ROUND((((S29+ROUND((ROUND((((((EU29*1.03)*1.25)*1.2))*AV29*1),2)*BS29),2))*AU29)/100),2)+ROUND(((ROUND((ROUND(((AE29-((((EU29*1.03)*1.25)*1.2)))*AV29*1),2)*BS29),2)*AU29)/100),2)) -> 64136.48 | DB29: 4 | DD29: *1)*1)*1 | DE29: *1,03)*1,25)*1,2 | DF29: *1,03)*1,25)*1,2 | DG29: *1,03)*1,15)*1,2 | DI29: *1,03)*1,15)*1,2 | DJ29: *1,03)*1,25)*1,2 | DN29: 0 | DO29: 0 | DP29: 1 | DQ29: 1 | DU29: 1010 | DV29: 100 шт. | DW29: 100 шт. | DX29: 100 | EE29: 85635395 | EF29: 30 | EG29: Строительные работы | EH29: 0 | EJ29: 1 | EK29: 23 | EL29: ТСН-2001.3-18. Отопление - внутренние устройства | EM29: ТСН-2001.3-18-1 | EO29: Поправка: 3-18. О.П. п.1.8 Поправка: Гл.6.Прил.2.2.п.2.2.6_06.00.01.07.001 Поправка: Гл.12.Прил.8.п.8. 3_12.00.01.11.001 | EQ29: 131072 | ER29: 3090.81 | ES29: 2078.86 | ET29: 95.35 | EU29: 10.3 | EV29: 916.6 | EW29: 74.7 | EX29: 0 | EY29: 0 | FQ29: 0 | FR29: 0 | FS29: 0 | FX29: 109 | FY29: 61 | GD29: 1 | GF29: -468095277 | GG29: 2 | GH29: 1 | GI29: 2 | GJ29: 0 | GK29: 0 | GL29: =ROUND(IF(AND(BH29=3,BI29=3,FS29<>0),P29,0),2) -> 0 | GM29: =ROUND(O29+X29+Y29,2)+GX29 -> 344199.12 | GN29: =IF(OR(BI29=0,BI29=1),GM29-GX29,0) -> 344199.12 | GO29: =IF(BI29=2,GM29-GX29,0) -> 0 | GP29: =IF(BI29=4,GM29-GX29,0) -> 0 | GR29: 0 | GS29: 3 | GT29: 0 | GV29: =ROUND((GT29),6) -> 0 | GW29: 1 | GX29: =ROUND(HC29*I29,2) -> 0 | HA29: 0 | HB29: 0 | HC29: =GV29*GW29 -> 0 | HS29: 0 | IK29: 0
A30: 18 | B30: 1 | C30: 10 | E30: 1,1 | F30: КА. п. 1 | G30: Сmальной nанельный paguamop PRADO Classic, mun 20, Bыcoma Н = 500 мм, PRADO Classic-20-500-400 | H30: шт. | I30: =I28*J30 -> 1 | J30: 0.7518797 | K30: 0.75188 | O30: =ROUND(CP30,2) -> 373.26 | P30: =ROUND((ROUND((AC30*AW30*I30),2)*BC30),2) -> 373.26 | Q30: =(ROUND((ROUND(((ET30)*AV30*I30),2)*BB30),2)+ROUND((ROUND(((AE30-(EU30))*AV30*I30),2)*BS30),2)) -> 0 | R30: =(ROUND((ROUND(((EU30)*AV30*I30),2)*BS30),2)+ROUND((ROUND(((AE30-(EU30))*AV30*I30),2)*BS30),2)) -> 0 | S30: =ROUND((ROUND((AF30*AV30*I30),2)*BA30),2) -> 0 | T30: =ROUND(CU30*I30,2) -> 0 | U30: =CV30*I30 -> 0 | V30: =CW30*I30 -> 0 | W30: =ROUND(CX30*I30,2) -> 0 | X30: =(ROUND((((S30+ROUND((ROUND(((EU30)*AV30*I30),2)*BS30),2))*AT30)/100),2)+ROUND(((ROUND((ROUND(((AE30-(EU30))*AV30*I30),2)*BS30),2)*AT30)/100),2)) -> 0 | Y30: =(ROUND((((S30+ROUND((ROUND(((EU30)*AV30*I30),2)*BS30),2))*AU30)/100),2)+ROUND(((ROUND((ROUND(((AE30-(EU30))*AV30*I30),2)*BS30),2)*AU30)/100),2)) -> 0 | AA30: 86551701 | AB30: =ROUND((AC30+AD30+AF30),6) -> 373.26 | AC30: =ROUND((ES30),6) -> 373.26 | AD30: =ROUND((((ET30)-(EU30))+AE30),6) -> 0 | AE30: =ROUND((EU30),6) -> 0 | AF30: =ROUND((EV30),6) -> 0 | AG30: =ROUND((AP30),6) -> 0 | AH30: =(EW30) -> 0 | AI30: =(EX30) -> 0 | AJ30: =(AS30) -> 0 | AK30: 373.26 | AL30: 373.26 | AM30: 0 | AN30: 0 | AO30: 0 | AP30: 0 | AQ30: 0 | AR30: 0 | AS30: 0 | AT30: 109 | AU30: 61 | AV30: 1 | AW30: 1 | AZ30: 1 | BA30: 1 | BB30: 1 | BC30: 1 | BH30: 3 | BI30: 1 | BM30: 23 | BN30: 0 | BP30: 0 | BQ30: 30 | BR30: 0 | BS30: 1 | BT30: 1 | BU30: 1 | BV30: 1 | BW30: 1 | BX30: 1 | BZ30: 109 | CA30: 61 | CE30: 1566 | CF30: 0 | CG30: 0 | CM30: 0 | CO30: 0 | CP30: =(P30+Q30+S30) -> 373.26 | CQ30: =ROUND((ROUND((AC30*AW30*1),2)*BC30),2) -> 373.26 | CR30: =(ROUND((ROUND(((ET30)*AV30*1),2)*BB30),2)+ROUND((ROUND(((AE30-(EU30))*AV30*1),2)*BS30),2)) -> 0 | CS30: =(ROUND((ROUND(((EU30)*AV30*1),2)*BS30),2)+ROUND((ROUND(((AE30-(EU30))*AV30*1),2)*BS30),2)) -> 0 | CT30: =ROUND((ROUND((AF30*AV30*1),2)*BA30),2) -> 0 | CU30: =AG30 -> 0 | CV30: =(AH30*AV30) -> 0 | CW30: =AI30 -> 0 | CX30: =AJ30 -> 0 | CY30: =(ROUND((((S30+ROUND((ROUND(((EU30)*AV30*1),2)*BS30),2))*AT30)/100),2)+ROUND(((ROUND((ROUND(((AE30-(EU30))*AV30*1),2)*BS30),2)*AT30)/100),2)) -> 0 | CZ30: =(ROUND((((S30+ROUND((ROUND(((EU30)*AV30*1),2)*BS30),2))*AU30)/100),2)+ROUND(((ROUND((ROUND(((AE30-(EU30))*AV30*1),2)*BS30),2)*AU30)/100),2)) -> 0 | DN30: 0 | DO30: 0 | DP30: 1 | DQ30: 1 | DU30: 1010 | DV30: шт. | DW30: шт. | DX30: 1 | EE30: 85635395 | EF30: 30 | EG30: Строительные работы | EH30: 0 | EJ30: 1 | EK30: 23 | EL30: ТСН-2001.3-18. Отопление - внутренние устройства | EM30: ТСН-2001.3-18-1 | EQ30: 0 | ER30: 0 | ES30: 373.26 | ET30: 0 | EU30: 0 | EV30: 0 | EW30: 0 | EX30: 0 | FQ30: 0 | FR30: 0 | FS30: 0 | FX30: 109 | FY30: 61 | GA30: [4 393 / 1,22 / 9,84] + 2% Заг.скл | GD30: 1 | GF30: 2083950908 | GG30: 2 | GH30: 4 | GI30: -2 | GJ30: 0 | GK30: 0 | GL30: =ROUND(IF(AND(BH30=3,BI30=3,FS30<>0),P30,0),2) -> 0 | GM30: =ROUND(O30+X30+Y30,2)+GX30 -> 373.26 | GN30: =IF(OR(BI30=0,BI30=1),GM30-GX30,0) -> 373.26 | GO30: =IF(BI30=2,GM30-GX30,0) -> 0 | GP30: =IF(BI30=4,GM30-GX30,0) -> 0 | GR30: 0 | GS30: 2 | GT30: 0 | GV30: =ROUND((GT30),6) -> 0 | GW30: 1 | GX30: =ROUND(HC30*I30,2) -> 0 | HA30: 0 | HB30: 0 | HC30: =GV30*GW30 -> 0 | HE30: 0 | HF30: 2 | HS30: 0 | IK30: 0
A31: 18 | B31: 1 | C31: 32 | E31: 1,1 | F31: КА. п. 1 | G31: Сmальной nанельный paguamop PRADO Classic, mun 20, Bыcoma Н = 500 мм, PRADO Classic-20-500-400 | H31: шт. | I31: =I29*J31 -> 1 | J31: 0.7518797 | K31: 0.75188 | O31: =ROUND(CP31,2) -> 3672.88 | P31: =ROUND((ROUND((AC31*AW31*I31),2)*BC31),2) -> 3672.88 | Q31: =(ROUND((ROUND(((ET31)*AV31*I31),2)*BB31),2)+ROUND((ROUND(((AE31-(EU31))*AV31*I31),2)*BS31),2)) -> 0 | R31: =(ROUND((ROUND(((EU31)*AV31*I31),2)*BS31),2)+ROUND((ROUND(((AE31-(EU31))*AV31*I31),2)*BS31),2)) -> 0 | S31: =ROUND((ROUND((AF31*AV31*I31),2)*BA31),2) -> 0 | T31: =ROUND(CU31*I31,2) -> 0 | U31: =CV31*I31 -> 0 | V31: =CW31*I31 -> 0 | W31: =ROUND(CX31*I31,2) -> 0 | X31: =(ROUND((((S31+ROUND((ROUND(((EU31)*AV31*I31),2)*BS31),2))*AT31)/100),2)+ROUND(((ROUND((ROUND(((AE31-(EU31))*AV31*I31),2)*BS31),2)*AT31)/100),2)) -> 0 | Y31: =(ROUND((((S31+ROUND((ROUND(((EU31)*AV31*I31),2)*BS31),2))*AU31)/100),2)+ROUND(((ROUND((ROUND(((AE31-(EU31))*AV31*I31),2)*BS31),2)*AU31)/100),2)) -> 0 | AA31: 86551703 | AB31: =ROUND((AC31+AD31+AF31),6) -> 373.26 | AC31: =ROUND((ES31),6) -> 373.26 | AD31: =ROUND((((ET31)-(EU31))+AE31),6) -> 0 | AE31: =ROUND((EU31),6) -> 0 | AF31: =ROUND((EV31),6) -> 0 | AG31: =ROUND((AP31),6) -> 0 | AH31: =(EW31) -> 0 | AI31: =(EX31) -> 0 | AJ31: =(AS31) -> 0 | AK31: 373.26 | AL31: 373.26 | AM31: 0 | AN31: 0 | AO31: 0 | AP31: 0 | AQ31: 0 | AR31: 0 | AS31: 0 | AT31: 109 | AU31: 61 | AV31: 1 | AW31: 1 | AZ31: 1 | BA31: 1 | BB31: 1 | BC31: 9.84 | BH31: 3 | BI31: 1 | BM31: 23 | BN31: 0 | BP31: 0 | BQ31: 30 | BR31: 0 | BS31: 1 | BT31: 1 | BU31: 1 | BV31: 1 | BW31: 1 | BX31: 1 | BZ31: 109 | CA31: 61 | CE31: 1566 | CF31: 0 | CG31: 0 | CM31: 0 | CO31: 0 | CP31: =(P31+Q31+S31) -> 3672.88 | CQ31: =ROUND((ROUND((AC31*AW31*1),2)*BC31),2) -> 3672.88 | CR31: =(ROUND((ROUND(((ET31)*AV31*1),2)*BB31),2)+ROUND((ROUND(((AE31-(EU31))*AV31*1),2)*BS31),2)) -> 0 | CS31: =(ROUND((ROUND(((EU31)*AV31*1),2)*BS31),2)+ROUND((ROUND(((AE31-(EU31))*AV31*1),2)*BS31),2)) -> 0 | CT31: =ROUND((ROUND((AF31*AV31*1),2)*BA31),2) -> 0 | CU31: =AG31 -> 0 | CV31: =(AH31*AV31) -> 0 | CW31: =AI31 -> 0 | CX31: =AJ31 -> 0 | CY31: =(ROUND((((S31+ROUND((ROUND(((EU31)*AV31*1),2)*BS31),2))*AT31)/100),2)+ROUND(((ROUND((ROUND(((AE31-(EU31))*AV31*1),2)*BS31),2)*AT31)/100),2)) -> 0 | CZ31: =(ROUND((((S31+ROUND((ROUND(((EU31)*AV31*1),2)*BS31),2))*AU31)/100),2)+ROUND(((ROUND((ROUND(((AE31-(EU31))*AV31*1),2)*BS31),2)*AU31)/100),2)) -> 0 | DN31: 0 | DO31: 0 | DP31: 1 | DQ31: 1 | DU31: 1010 | DV31: шт. | DW31: шт. | DX31: 1 | EE31: 85635395 | EF31: 30 | EG31: Строительные работы | EH31: 0 | EJ31: 1 | EK31: 23 | EL31: ТСН-2001.3-18. Отопление - внутренние устройства | EM31: ТСН-2001.3-18-1 | EQ31: 0 | ER31: 373.26 | ES31: 373.26 | ET31: 0 | EU31: 0 | EV31: 0 | EW31: 0 | EX31: 0 | EZ31: 5 | FC31: 1 | FD31: 18 | FF31: 4393 | FQ31: 0 | FR31: 0 | FS31: 0 | FX31: 109 | FY31: 61 | GA31: [4 393 / 1,22 / 9,84] + 2% Заг.скл | GD31: 1 | GF31: 2083950908 | GG31: 2 | GH31: 3 | GI31: 5 | GJ31: 0 | GK31: 0 | GL31: =ROUND(IF(AND(BH31=3,BI31=3,FS31<>0),P31,0),2) -> 0 | GM31: =ROUND(O31+X31+Y31,2)+GX31 -> 3672.88 | GN31: =IF(OR(BI31=0,BI31=1),GM31-GX31,0) -> 3672.88 | GO31: =IF(BI31=2,GM31-GX31,0) -> 0 | GP31: =IF(BI31=4,GM31-GX31,0) -> 0 | GR31: 1 | GS31: 1 | GT31: 0 | GV31: =ROUND((GT31),6) -> 0 | GW31: 1 | GX31: =ROUND(HC31*I31,2) -> 0 | HA31: 0 | HB31: 0 | HC31: =GV31*GW31 -> 0 | HE31: 0 | HF31: 2 | HS31: 0 | IK31: 0
A32: 18 | B32: 1 | C32: 15 | E32: 1,2 | F32: КА. п. 2 | G32: Сmальной nанельный paguamop PRADO Classic, mun 20, Bыcoma Н = 500 мм, PRADO Classic-20-500-500 | I32: =I28*J32 -> 9 | J32: 6.7669173 | K32: 6.766917 | O32: =ROUND(CP32,2) -> 3887.73 | P32: =ROUND((ROUND((AC32*AW32*I32),2)*BC32),2) -> 3887.73 | Q32: =(ROUND((ROUND(((ET32)*AV32*I32),2)*BB32),2)+ROUND((ROUND(((AE32-(EU32))*AV32*I32),2)*BS32),2)) -> 0 | R32: =(ROUND((ROUND(((EU32)*AV32*I32),2)*BS32),2)+ROUND((ROUND(((AE32-(EU32))*AV32*I32),2)*BS32),2)) -> 0 | S32: =ROUND((ROUND((AF32*AV32*I32),2)*BA32),2) -> 0 | T32: =ROUND(CU32*I32,2) -> 0 | U32: =CV32*I32 -> 0 | V32: =CW32*I32 -> 0 | W32: =ROUND(CX32*I32,2) -> 0 | X32: =(ROUND((((S32+ROUND((ROUND(((EU32)*AV32*I32),2)*BS32),2))*AT32)/100),2)+ROUND(((ROUND((ROUND(((AE32-(EU32))*AV32*I32),2)*BS32),2)*AT32)/100),2)) -> 0 | Y32: =(ROUND((((S32+ROUND((ROUND(((EU32)*AV32*I32),2)*BS32),2))*AU32)/100),2)+ROUND(((ROUND((ROUND(((AE32-(EU32))*AV32*I32),2)*BS32),2)*AU32)/100),2)) -> 0 | AA32: 86551701 | AB32: =ROUND((AC32+AD32+AF32),6) -> 431.97 | AC32: =ROUND((ES32),6) -> 431.97 | AD32: =ROUND((((ET32)-(EU32))+AE32),6) -> 0 | AE32: =ROUND((EU32),6) -> 0 | AF32: =ROUND((EV32),6) -> 0 | AG32: =ROUND((AP32),6) -> 0 | AH32: =(EW32) -> 0 | AI32: =(EX32) -> 0 | AJ32: =(AS32) -> 0 | AK32: 431.97 | AL32: 431.97 | AM32: 0 | AN32: 0 | AO32: 0 | AP32: 0 | AQ32: 0 | AR32: 0 | AS32: 0 | AT32: 109 | AU32: 61 | AV32: 1 | AW32: 1 | AZ32: 1 | BA32: 1 | BB32: 1 | BC32: 1 | BH32: 3 | BI32: 1 | BM32: 23 | BN32: 0 | BP32: 0 | BQ32: 30 | BR32: 0 | BS32: 1 | BT32: 1 | BU32: 1 | BV32: 1 | BW32: 1 | BX32: 1 | BZ32: 109 | CA32: 61 | CE32: 1566 | CF32: 0 | CG32: 0 | CM32: 0 | CO32: 0 | CP32: =(P32+Q32+S32) -> 3887.73 | CQ32: =ROUND((ROUND((AC32*AW32*1),2)*BC32),2) -> 431.97 | CR32: =(ROUND((ROUND(((ET32)*AV32*1),2)*BB32),2)+ROUND((ROUND(((AE32-(EU32))*AV32*1),2)*BS32),2)) -> 0 | CS32: =(ROUND((ROUND(((EU32)*AV32*1),2)*BS32),2)+ROUND((ROUND(((AE32-(EU32))*AV32*1),2)*BS32),2)) -> 0 | CT32: =ROUND((ROUND((AF32*AV32*1),2)*BA32),2) -> 0 | CU32: =AG32 -> 0 | CV32: =(AH32*AV32) -> 0 | CW32: =AI32 -> 0 | CX32: =AJ32 -> 0 | CY32: =(ROUND((((S32+ROUND((ROUND(((EU32)*AV32*1),2)*BS32),2))*AT32)/100),2)+ROUND(((ROUND((ROUND(((AE32-(EU32))*AV32*1),2)*BS32),2)*AT32)/100),2)) -> 0 | CZ32: =(ROUND((((S32+ROUND((ROUND(((EU32)*AV32*1),2)*BS32),2))*AU32)/100),2)+ROUND(((ROUND((ROUND(((AE32-(EU32))*AV32*1),2)*BS32),2)*AU32)/100),2)) -> 0 | DN32: 0 | DO32: 0 | DP32: 1 | DQ32: 1 | EE32: 85635395 | EF32: 30 | EG32: Строительные работы | EH32: 0 | EJ32: 1 | EK32: 23 | EL32: ТСН-2001.3-18. Отопление - внутренние устройства | EM32: ТСН-2001.3-18-1 | EQ32: 0 | ER32: 0 | ES32: 431.97 | ET32: 0 | EU32: 0 | EV32: 0 | EW32: 0 | EX32: 0 | FQ32: 0 | FR32: 0 | FS32: 0 | FX32: 109 | FY32: 61 | GA32: [5 084 / 1,22 / 9,84] + 2% Заг.скл | GD32: 1 | GF32: -401967197 | GG32: 2 | GH32: 4 | GI32: -2 | GJ32: 0 | GK32: 0 | GL32: =ROUND(IF(AND(BH32=3,BI32=3,FS32<>0),P32,0),2) -> 0 | GM32: =ROUND(O32+X32+Y32,2)+GX32 -> 3887.73 | GN32: =IF(OR(BI32=0,BI32=1),GM32-GX32,0) -> 3887.73 | GO32: =IF(BI32=2,GM32-GX32,0) -> 0 | GP32: =IF(BI32=4,GM32-GX32,0) -> 0 | GR32: 0 | GS32: 2 | GT32: 0 | GV32: =ROUND((GT32),6) -> 0 | GW32: 1 | GX32: =ROUND(HC32*I32,2) -> 0 | HA32: 0 | HB32: 0 | HC32: =GV32*GW32 -> 0 | HE32: 0 | HF32: 2 | HS32: 0 | IK32: 0
A33: 18 | B33: 1 | C33: 37 | E33: 1,2 | F33: КА. п. 2 | G33: Сmальной nанельный paguamop PRADO Classic, mun 20, Bыcoma Н = 500 мм, PRADO Classic-20-500-500 | I33: =I29*J33 -> 9 | J33: 6.7669173 | K33: 6.766917 | O33: =ROUND(CP33,2) -> 38255.26 | P33: =ROUND((ROUND((AC33*AW33*I33),2)*BC33),2) -> 38255.26 | Q33: =(ROUND((ROUND(((ET33)*AV33*I33),2)*BB33),2)+ROUND((ROUND(((AE33-(EU33))*AV33*I33),2)*BS33),2)) -> 0 | R33: =(ROUND((ROUND(((EU33)*AV33*I33),2)*BS33),2)+ROUND((ROUND(((AE33-(EU33))*AV33*I33),2)*BS33),2)) -> 0 | S33: =ROUND((ROUND((AF33*AV33*I33),2)*BA33),2) -> 0 | T33: =ROUND(CU33*I33,2) -> 0 | U33: =CV33*I33 -> 0 | V33: =CW33*I33 -> 0 | W33: =ROUND(CX33*I33,2) -> 0 | X33: =(ROUND((((S33+ROUND((ROUND(((EU33)*AV33*I33),2)*BS33),2))*AT33)/100),2)+ROUND(((ROUND((ROUND(((AE33-(EU33))*AV33*I33),2)*BS33),2)*AT33)/100),2)) -> 0 | Y33: =(ROUND((((S33+ROUND((ROUND(((EU33)*AV33*I33),2)*BS33),2))*AU33)/100),2)+ROUND(((ROUND((ROUND(((AE33-(EU33))*AV33*I33),2)*BS33),2)*AU33)/100),2)) -> 0 | AA33: 86551703 | AB33: =ROUND((AC33+AD33+AF33),6) -> 431.97 | AC33: =ROUND((ES33),6) -> 431.97 | AD33: =ROUND((((ET33)-(EU33))+AE33),6) -> 0 | AE33: =ROUND((EU33),6) -> 0 | AF33: =ROUND((EV33),6) -> 0 | AG33: =ROUND((AP33),6) -> 0 | AH33: =(EW33) -> 0 | AI33: =(EX33) -> 0 | AJ33: =(AS33) -> 0 | AK33: 431.97 | AL33: 431.97 | AM33: 0 | AN33: 0 | AO33: 0 | AP33: 0 | AQ33: 0 | AR33: 0 | AS33: 0 | AT33: 109 | AU33: 61 | AV33: 1 | AW33: 1 | AZ33: 1 | BA33: 1 | BB33: 1 | BC33: 9.84 | BH33: 3 | BI33: 1 | BM33: 23 | BN33: 0 | BP33: 0 | BQ33: 30 | BR33: 0 | BS33: 1 | BT33: 1 | BU33: 1 | BV33: 1 | BW33: 1 | BX33: 1 | BZ33: 109 | CA33: 61 | CE33: 1566 | CF33: 0 | CG33: 0 | CM33: 0 | CO33: 0 | CP33: =(P33+Q33+S33) -> 38255.26 | CQ33: =ROUND((ROUND((AC33*AW33*1),2)*BC33),2) -> 4250.58 | CR33: =(ROUND((ROUND(((ET33)*AV33*1),2)*BB33),2)+ROUND((ROUND(((AE33-(EU33))*AV33*1),2)*BS33),2)) -> 0 | CS33: =(ROUND((ROUND(((EU33)*AV33*1),2)*BS33),2)+ROUND((ROUND(((AE33-(EU33))*AV33*1),2)*BS33),2)) -> 0 | CT33: =ROUND((ROUND((AF33*AV33*1),2)*BA33),2) -> 0 | CU33: =AG33 -> 0 | CV33: =(AH33*AV33) -> 0 | CW33: =AI33 -> 0 | CX33: =AJ33 -> 0 | CY33: =(ROUND((((S33+ROUND((ROUND(((EU33)*AV33*1),2)*BS33),2))*AT33)/100),2)+ROUND(((ROUND((ROUND(((AE33-(EU33))*AV33*1),2)*BS33),2)*AT33)/100),2)) -> 0 | CZ33: =(ROUND((((S33+ROUND((ROUND(((EU33)*AV33*1),2)*BS33),2))*AU33)/100),2)+ROUND(((ROUND((ROUND(((AE33-(EU33))*AV33*1),2)*BS33),2)*AU33)/100),2)) -> 0 | DN33: 0 | DO33: 0 | DP33: 1 | DQ33: 1 | EE33: 85635395 | EF33: 30 | EG33: Строительные работы | EH33: 0 | EJ33: 1 | EK33: 23 | EL33: ТСН-2001.3-18. Отопление - внутренние устройства | EM33: ТСН-2001.3-18-1 | EQ33: 0 | ER33: 431.97 | ES33: 431.97 | ET33: 0 | EU33: 0 | EV33: 0 | EW33: 0 | EX33: 0 | EZ33: 5 | FC33: 1 | FD33: 18 | FF33: 5084 | FQ33: 0 | FR33: 0 | FS33: 0 | FX33: 109 | FY33: 61 | GA33: [5 084 / 1,22 / 9,84] + 2% Заг.скл | GD33: 1 | GF33: -401967197 | GG33: 2 | GH33: 3 | GI33: 5 | GJ33: 0 | GK33: 0 | GL33: =ROUND(IF(AND(BH33=3,BI33=3,FS33<>0),P33,0),2) -> 0 | GM33: =ROUND(O33+X33+Y33,2)+GX33 -> 38255.26 | GN33: =IF(OR(BI33=0,BI33=1),GM33-GX33,0) -> 38255.26 | GO33: =IF(BI33=2,GM33-GX33,0) -> 0 | GP33: =IF(BI33=4,GM33-GX33,0) -> 0 | GR33: 1 | GS33: 1 | GT33: 0 | GV33: =ROUND((GT33),6) -> 0 | GW33: 1 | GX33: =ROUND(HC33*I33,2) -> 0 | HA33: 0 | HB33: 0 | HC33: =GV33*GW33 -> 0 | HE33: 0 | HF33: 2 | HS33: 0 | IK33: 0
A34: 18 | B34: 1 | C34: 16 | E34: 1,3 | F34: КА. п. 3 | G34: Сmальной nанельный paguamop PRADO Classic, mun 20, Bыcoma Н = 500 мм, PRADO Classic-20-500-600 | I34: =I28*J34 -> 11 | J34: 8.2706767 | K34: 8.270677 | O34: =ROUND(CP34,2) -> 5436.75 | P34: =ROUND((ROUND((AC34*AW34*I34),2)*BC34),2) -> 5436.75 | Q34: =(ROUND((ROUND(((ET34)*AV34*I34),2)*BB34),2)+ROUND((ROUND(((AE34-(EU34))*AV34*I34),2)*BS34),2)) -> 0 | R34: =(ROUND((ROUND(((EU34)*AV34*I34),2)*BS34),2)+ROUND((ROUND(((AE34-(EU34))*AV34*I34),2)*BS34),2)) -> 0 | S34: =ROUND((ROUND((AF34*AV34*I34),2)*BA34),2) -> 0 | T34: =ROUND(CU34*I34,2) -> 0 | U34: =CV34*I34 -> 0 | V34: =CW34*I34 -> 0 | W34: =ROUND(CX34*I34,2) -> 0 | X34: =(ROUND((((S34+ROUND((ROUND(((EU34)*AV34*I34),2)*BS34),2))*AT34)/100),2)+ROUND(((ROUND((ROUND(((AE34-(EU34))*AV34*I34),2)*BS34),2)*AT34)/100),2)) -> 0 | Y34: =(ROUND((((S34+ROUND((ROUND(((EU34)*AV34*I34),2)*BS34),2))*AU34)/100),2)+ROUND(((ROUND((ROUND(((AE34-(EU34))*AV34*I34),2)*BS34),2)*AU34)/100),2)) -> 0 | AA34: 86551701 | AB34: =ROUND((AC34+AD34+AF34),6) -> 494.25 | AC34: =ROUND((ES34),6) -> 494.25 | AD34: =ROUND((((ET34)-(EU34))+AE34),6) -> 0 | AE34: =ROUND((EU34),6) -> 0 | AF34: =ROUND((EV34),6) -> 0 | AG34: =ROUND((AP34),6) -> 0 | AH34: =(EW34) -> 0 | AI34: =(EX34) -> 0 | AJ34: =(AS34) -> 0 | AK34: 494.25 | AL34: 494.25 | AM34: 0 | AN34: 0 | AO34: 0 | AP34: 0 | AQ34: 0 | AR34: 0 | AS34: 0 | AT34: 109 | AU34: 61 | AV34: 1 | AW34: 1 | AZ34: 1 | BA34: 1 | BB34: 1 | BC34: 1 | BH34: 3 | BI34: 1 | BM34: 23 | BN34: 0 | BP34: 0 | BQ34: 30 | BR34: 0 | BS34: 1 | BT34: 1 | BU34: 1 | BV34: 1 | BW34: 1 | BX34: 1 | BZ34: 109 | CA34: 61 | CE34: 1566 | CF34: 0 | CG34: 0 | CM34: 0 | CO34: 0 | CP34: =(P34+Q34+S34) -> 5436.75 | CQ34: =ROUND((ROUND((AC34*AW34*1),2)*BC34),2) -> 494.25 | CR34: =(ROUND((ROUND(((ET34)*AV34*1),2)*BB34),2)+ROUND((ROUND(((AE34-(EU34))*AV34*1),2)*BS34),2)) -> 0 | CS34: =(ROUND((ROUND(((EU34)*AV34*1),2)*BS34),2)+ROUND((ROUND(((AE34-(EU34))*AV34*1),2)*BS34),2)) -> 0 | CT34: =ROUND((ROUND((AF34*AV34*1),2)*BA34),2) -> 0 | CU34: =AG34 -> 0 | CV34: =(AH34*AV34) -> 0 | CW34: =AI34 -> 0 | CX34: =AJ34 -> 0 | CY34: =(ROUND((((S34+ROUND((ROUND(((EU34)*AV34*1),2)*BS34),2))*AT34)/100),2)+ROUND(((ROUND((ROUND(((AE34-(EU34))*AV34*1),2)*BS34),2)*AT34)/100),2)) -> 0 | CZ34: =(ROUND((((S34+ROUND((ROUND(((EU34)*AV34*1),2)*BS34),2))*AU34)/100),2)+ROUND(((ROUND((ROUND(((AE34-(EU34))*AV34*1),2)*BS34),2)*AU34)/100),2)) -> 0 | DN34: 0 | DO34: 0 | DP34: 1 | DQ34: 1 | EE34: 85635395 | EF34: 30 | EG34: Строительные работы | EH34: 0 | EJ34: 1 | EK34: 23 | EL34: ТСН-2001.3-18. Отопление - внутренние устройства | EM34: ТСН-2001.3-18-1 | EQ34: 0 | ER34: 0 | ES34: 494.25 | ET34: 0 | EU34: 0 | EV34: 0 | EW34: 0 | EX34: 0 | FQ34: 0 | FR34: 0 | FS34: 0 | FX34: 109 | FY34: 61 | GA34: [5 817 / 1,22 / 9,84] + 2% Заг.скл | GD34: 1 | GF34: 1290624388 | GG34: 2 | GH34: 4 | GI34: -2 | GJ34: 0 | GK34: 0 | GL34: =ROUND(IF(AND(BH34=3,BI34=3,FS34<>0),P34,0),2) -> 0 | GM34: =ROUND(O34+X34+Y34,2)+GX34 -> 5436.75 | GN34: =IF(OR(BI34=0,BI34=1),GM34-GX34,0) -> 5436.75 | GO34: =IF(BI34=2,GM34-GX34,0) -> 0 | GP34: =IF(BI34=4,GM34-GX34,0) -> 0 | GR34: 0 | GS34: 2 | GT34: 0 | GV34: =ROUND((GT34),6) -> 0 | GW34: 1 | GX34: =ROUND(HC34*I34,2) -> 0 | HA34: 0 | HB34: 0 | HC34: =GV34*GW34 -> 0 | HE34: 0 | HF34: 2 | HS34: 0 | IK34: 0
A35: 18 | B35: 1 | C35: 38 | E35: 1,3 | F35: КА. п. 3 | G35: Сmальной nанельный paguamop PRADO Classic, mun 20, Bыcoma Н = 500 мм, PRADO Classic-20-500-600 | I35: =I29*J35 -> 11 | J35: 8.2706767 | K35: 8.270677 | O35: =ROUND(CP35,2) -> 53497.62 | P35: =ROUND((ROUND((AC35*AW35*I35),2)*BC35),2) -> 53497.62 | Q35: =(ROUND((ROUND(((ET35)*AV35*I35),2)*BB35),2)+ROUND((ROUND(((AE35-(EU35))*AV35*I35),2)*BS35),2)) -> 0 | R35: =(ROUND((ROUND(((EU35)*AV35*I35),2)*BS35),2)+ROUND((ROUND(((AE35-(EU35))*AV35*I35),2)*BS35),2)) -> 0 | S35: =ROUND((ROUND((AF35*AV35*I35),2)*BA35),2) -> 0 | T35: =ROUND(CU35*I35,2) -> 0 | U35: =CV35*I35 -> 0 | V35: =CW35*I35 -> 0 | W35: =ROUND(CX35*I35,2) -> 0 | X35: =(ROUND((((S35+ROUND((ROUND(((EU35)*AV35*I35),2)*BS35),2))*AT35)/100),2)+ROUND(((ROUND((ROUND(((AE35-(EU35))*AV35*I35),2)*BS35),2)*AT35)/100),2)) -> 0 | Y35: =(ROUND((((S35+ROUND((ROUND(((EU35)*AV35*I35),2)*BS35),2))*AU35)/100),2)+ROUND(((ROUND((ROUND(((AE35-(EU35))*AV35*I35),2)*BS35),2)*AU35)/100),2)) -> 0 | AA35: 86551703 | AB35: =ROUND((AC35+AD35+AF35),6) -> 494.25 | AC35: =ROUND((ES35),6) -> 494.25 | AD35: =ROUND((((ET35)-(EU35))+AE35),6) -> 0 | AE35: =ROUND((EU35),6) -> 0 | AF35: =ROUND((EV35),6) -> 0 | AG35: =ROUND((AP35),6) -> 0 | AH35: =(EW35) -> 0 | AI35: =(EX35) -> 0 | AJ35: =(AS35) -> 0 | AK35: 494.25 | AL35: 494.25 | AM35: 0 | AN35: 0 | AO35: 0 | AP35: 0 | AQ35: 0 | AR35: 0 | AS35: 0 | AT35: 109 | AU35: 61 | AV35: 1 | AW35: 1 | AZ35: 1 | BA35: 1 | BB35: 1 | BC35: 9.84 | BH35: 3 | BI35: 1 | BM35: 23 | BN35: 0 | BP35: 0 | BQ35: 30 | BR35: 0 | BS35: 1 | BT35: 1 | BU35: 1 | BV35: 1 | BW35: 1 | BX35: 1 | BZ35: 109 | CA35: 61 | CE35: 1566 | CF35: 0 | CG35: 0 | CM35: 0 | CO35: 0 | CP35: =(P35+Q35+S35) -> 53497.62 | CQ35: =ROUND((ROUND((AC35*AW35*1),2)*BC35),2) -> 4863.42 | CR35: =(ROUND((ROUND(((ET35)*AV35*1),2)*BB35),2)+ROUND((ROUND(((AE35-(EU35))*AV35*1),2)*BS35),2)) -> 0 | CS35: =(ROUND((ROUND(((EU35)*AV35*1),2)*BS35),2)+ROUND((ROUND(((AE35-(EU35))*AV35*1),2)*BS35),2)) -> 0 | CT35: =ROUND((ROUND((AF35*AV35*1),2)*BA35),2) -> 0 | CU35: =AG35 -> 0 | CV35: =(AH35*AV35) -> 0 | CW35: =AI35 -> 0 | CX35: =AJ35 -> 0 | CY35: =(ROUND((((S35+ROUND((ROUND(((EU35)*AV35*1),2)*BS35),2))*AT35)/100),2)+ROUND(((ROUND((ROUND(((AE35-(EU35))*AV35*1),2)*BS35),2)*AT35)/100),2)) -> 0 | CZ35: =(ROUND((((S35+ROUND((ROUND(((EU35)*AV35*1),2)*BS35),2))*AU35)/100),2)+ROUND(((ROUND((ROUND(((AE35-(EU35))*AV35*1),2)*BS35),2)*AU35)/100),2)) -> 0 | DN35: 0 | DO35: 0 | DP35: 1 | DQ35: 1 | EE35: 85635395 | EF35: 30 | EG35: Строительные работы | EH35: 0 | EJ35: 1 | EK35: 23 | EL35: ТСН-2001.3-18. Отопление - внутренние устройства | EM35: ТСН-2001.3-18-1 | EQ35: 0 | ER35: 494.25 | ES35: 494.25 | ET35: 0 | EU35: 0 | EV35: 0 | EW35: 0 | EX35: 0 | EZ35: 5 | FC35: 1 | FD35: 18 | FF35: 5817 | FQ35: 0 | FR35: 0 | FS35: 0 | FX35: 109 | FY35: 61 | GA35: [5 817 / 1,22 / 9,84] + 2% Заг.скл | GD35: 1 | GF35: 1290624388 | GG35: 2 | GH35: 3 | GI35: 5 | GJ35: 0 | GK35: 0 | GL35: =ROUND(IF(AND(BH35=3,BI35=3,FS35<>0),P35,0),2) -> 0 | GM35: =ROUND(O35+X35+Y35,2)+GX35 -> 53497.62 | GN35: =IF(OR(BI35=0,BI35=1),GM35-GX35,0) -> 53497.62 | GO35: =IF(BI35=2,GM35-GX35,0) -> 0 | GP35: =IF(BI35=4,GM35-GX35,0) -> 0 | GR35: 1 | GS35: 1 | GT35: 0 | GV35: =ROUND((GT35),6) -> 0 | GW35: 1 | GX35: =ROUND(HC35*I35,2) -> 0 | HA35: 0 | HB35: 0 | HC35: =GV35*GW35 -> 0 | HE35: 0 | HF35: 2 | HS35: 0 | IK35: 0
A36: 18 | B36: 1 | C36: 17 | E36: 1,4 | F36: КА. п. 4 | G36: Сmальной nанельный paguamop PRADO Classic, mun 20, Bыcoma Н = 500 мм, PRADO Classic-20-500-700 | I36: =I28*J36 -> 13 | J36: 9.7744361 | K36: 9.774436 | O36: =ROUND(CP36,2) -> 7093.45 | P36: =ROUND((ROUND((AC36*AW36*I36),2)*BC36),2) -> 7093.45 | Q36: =(ROUND((ROUND(((ET36)*AV36*I36),2)*BB36),2)+ROUND((ROUND(((AE36-(EU36))*AV36*I36),2)*BS36),2)) -> 0 | R36: =(ROUND((ROUND(((EU36)*AV36*I36),2)*BS36),2)+ROUND((ROUND(((AE36-(EU36))*AV36*I36),2)*BS36),2)) -> 0 | S36: =ROUND((ROUND((AF36*AV36*I36),2)*BA36),2) -> 0 | T36: =ROUND(CU36*I36,2) -> 0 | U36: =CV36*I36 -> 0 | V36: =CW36*I36 -> 0 | W36: =ROUND(CX36*I36,2) -> 0 | X36: =(ROUND((((S36+ROUND((ROUND(((EU36)*AV36*I36),2)*BS36),2))*AT36)/100),2)+ROUND(((ROUND((ROUND(((AE36-(EU36))*AV36*I36),2)*BS36),2)*AT36)/100),2)) -> 0 | Y36: =(ROUND((((S36+ROUND((ROUND(((EU36)*AV36*I36),2)*BS36),2))*AU36)/100),2)+ROUND(((ROUND((ROUND(((AE36-(EU36))*AV36*I36),2)*BS36),2)*AU36)/100),2)) -> 0 | AA36: 86551701 | AB36: =ROUND((AC36+AD36+AF36),6) -> 545.65 | AC36: =ROUND((ES36),6) -> 545.65 | AD36: =ROUND((((ET36)-(EU36))+AE36),6) -> 0 | AE36: =ROUND((EU36),6) -> 0 | AF36: =ROUND((EV36),6) -> 0 | AG36: =ROUND((AP36),6) -> 0 | AH36: =(EW36) -> 0 | AI36: =(EX36) -> 0 | AJ36: =(AS36) -> 0 | AK36: 545.65 | AL36: 545.65 | AM36: 0 | AN36: 0 | AO36: 0 | AP36: 0 | AQ36: 0 | AR36: 0 | AS36: 0 | AT36: 109 | AU36: 61 | AV36: 1 | AW36: 1 | AZ36: 1 | BA36: 1 | BB36: 1 | BC36: 1 | BH36: 3 | BI36: 1 | BM36: 23 | BN36: 0 | BP36: 0 | BQ36: 30 | BR36: 0 | BS36: 1 | BT36: 1 | BU36: 1 | BV36: 1 | BW36: 1 | BX36: 1 | BZ36: 109 | CA36: 61 | CE36: 1566 | CF36: 0 | CG36: 0 | CM36: 0 | CO36: 0 | CP36: =(P36+Q36+S36) -> 7093.45 | CQ36: =ROUND((ROUND((AC36*AW36*1),2)*BC36),2) -> 545.65 | CR36: =(ROUND((ROUND(((ET36)*AV36*1),2)*BB36),2)+ROUND((ROUND(((AE36-(EU36))*AV36*1),2)*BS36),2)) -> 0 | CS36: =(ROUND((ROUND(((EU36)*AV36*1),2)*BS36),2)+ROUND((ROUND(((AE36-(EU36))*AV36*1),2)*BS36),2)) -> 0 | CT36: =ROUND((ROUND((AF36*AV36*1),2)*BA36),2) -> 0 | CU36: =AG36 -> 0 | CV36: =(AH36*AV36) -> 0 | CW36: =AI36 -> 0 | CX36: =AJ36 -> 0 | CY36: =(ROUND((((S36+ROUND((ROUND(((EU36)*AV36*1),2)*BS36),2))*AT36)/100),2)+ROUND(((ROUND((ROUND(((AE36-(EU36))*AV36*1),2)*BS36),2)*AT36)/100),2)) -> 0 | CZ36: =(ROUND((((S36+ROUND((ROUND(((EU36)*AV36*1),2)*BS36),2))*AU36)/100),2)+ROUND(((ROUND((ROUND(((AE36-(EU36))*AV36*1),2)*BS36),2)*AU36)/100),2)) -> 0 | DN36: 0 | DO36: 0 | DP36: 1 | DQ36: 1 | EE36: 85635395 | EF36: 30 | EG36: Строительные работы | EH36: 0 | EJ36: 1 | EK36: 23 | EL36: ТСН-2001.3-18. Отопление - внутренние устройства | EM36: ТСН-2001.3-18-1 | EQ36: 0 | ER36: 0 | ES36: 545.65 | ET36: 0 | EU36: 0 | EV36: 0 | EW36: 0 | EX36: 0 | FQ36: 0 | FR36: 0 | FS36: 0 | FX36: 109 | FY36: 61 | GA36: [6 422 / 1,22 / 9,84] + 2% Заг.скл | GD36: 1 | GF36: 752976982 | GG36: 2 | GH36: 4 | GI36: -2 | GJ36: 0 | GK36: 0 | GL36: =ROUND(IF(AND(BH36=3,BI36=3,FS36<>0),P36,0),2) -> 0 | GM36: =ROUND(O36+X36+Y36,2)+GX36 -> 7093.45 | GN36: =IF(OR(BI36=0,BI36=1),GM36-GX36,0) -> 7093.45 | GO36: =IF(BI36=2,GM36-GX36,0) -> 0 | GP36: =IF(BI36=4,GM36-GX36,0) -> 0 | GR36: 0 | GS36: 2 | GT36: 0 | GV36: =ROUND((GT36),6) -> 0 | GW36: 1 | GX36: =ROUND(HC36*I36,2) -> 0 | HA36: 0 | HB36: 0 | HC36: =GV36*GW36 -> 0 | HE36: 0 | HF36: 2 | HS36: 0 | IK36: 0
A37: 18 | B37: 1 | C37: 39 | E37: 1,4 | F37: КА. п. 4 | G37: Сmальной nанельный paguamop PRADO Classic, mun 20, Bыcoma Н = 500 мм, PRADO Classic-20-500-700 | I37: =I29*J37 -> 13 | J37: 9.7744361 | K37: 9.774436 | O37: =ROUND(CP37,2) -> 69799.55 | P37: =ROUND((ROUND((AC37*AW37*I37),2)*BC37),2) -> 69799.55 | Q37: =(ROUND((ROUND(((ET37)*AV37*I37),2)*BB37),2)+ROUND((ROUND(((AE37-(EU37))*AV37*I37),2)*BS37),2)) -> 0 | R37: =(ROUND((ROUND(((EU37)*AV37*I37),2)*BS37),2)+ROUND((ROUND(((AE37-(EU37))*AV37*I37),2)*BS37),2)) -> 0 | S37: =ROUND((ROUND((AF37*AV37*I37),2)*BA37),2) -> 0 | T37: =ROUND(CU37*I37,2) -> 0 | U37: =CV37*I37 -> 0 | V37: =CW37*I37 -> 0 | W37: =ROUND(CX37*I37,2) -> 0 | X37: =(ROUND((((S37+ROUND((ROUND(((EU37)*AV37*I37),2)*BS37),2))*AT37)/100),2)+ROUND(((ROUND((ROUND(((AE37-(EU37))*AV37*I37),2)*BS37),2)*AT37)/100),2)) -> 0 | Y37: =(ROUND((((S37+ROUND((ROUND(((EU37)*AV37*I37),2)*BS37),2))*AU37)/100),2)+ROUND(((ROUND((ROUND(((AE37-(EU37))*AV37*I37),2)*BS37),2)*AU37)/100),2)) -> 0 | AA37: 86551703 | AB37: =ROUND((AC37+AD37+AF37),6) -> 545.65 | AC37: =ROUND((ES37),6) -> 545.65 | AD37: =ROUND((((ET37)-(EU37))+AE37),6) -> 0 | AE37: =ROUND((EU37),6) -> 0 | AF37: =ROUND((EV37),6) -> 0 | AG37: =ROUND((AP37),6) -> 0 | AH37: =(EW37) -> 0 | AI37: =(EX37) -> 0 | AJ37: =(AS37) -> 0 | AK37: 545.65 | AL37: 545.65 | AM37: 0 | AN37: 0 | AO37: 0 | AP37: 0 | AQ37: 0 | AR37: 0 | AS37: 0 | AT37: 109 | AU37: 61 | AV37: 1 | AW37: 1 | AZ37: 1 | BA37: 1 | BB37: 1 | BC37: 9.84 | BH37: 3 | BI37: 1 | BM37: 23 | BN37: 0 | BP37: 0 | BQ37: 30 | BR37: 0 | BS37: 1 | BT37: 1 | BU37: 1 | BV37: 1 | BW37: 1 | BX37: 1 | BZ37: 109 | CA37: 61 | CE37: 1566 | CF37: 0 | CG37: 0 | CM37: 0 | CO37: 0 | CP37: =(P37+Q37+S37) -> 69799.55 | CQ37: =ROUND((ROUND((AC37*AW37*1),2)*BC37),2) -> 5369.2 | CR37: =(ROUND((ROUND(((ET37)*AV37*1),2)*BB37),2)+ROUND((ROUND(((AE37-(EU37))*AV37*1),2)*BS37),2)) -> 0 | CS37: =(ROUND((ROUND(((EU37)*AV37*1),2)*BS37),2)+ROUND((ROUND(((AE37-(EU37))*AV37*1),2)*BS37),2)) -> 0 | CT37: =ROUND((ROUND((AF37*AV37*1),2)*BA37),2) -> 0 | CU37: =AG37 -> 0 | CV37: =(AH37*AV37) -> 0 | CW37: =AI37 -> 0 | CX37: =AJ37 -> 0 | CY37: =(ROUND((((S37+ROUND((ROUND(((EU37)*AV37*1),2)*BS37),2))*AT37)/100),2)+ROUND(((ROUND((ROUND(((AE37-(EU37))*AV37*1),2)*BS37),2)*AT37)/100),2)) -> 0 | CZ37: =(ROUND((((S37+ROUND((ROUND(((EU37)*AV37*1),2)*BS37),2))*AU37)/100),2)+ROUND(((ROUND((ROUND(((AE37-(EU37))*AV37*1),2)*BS37),2)*AU37)/100),2)) -> 0 | DN37: 0 | DO37: 0 | DP37: 1 | DQ37: 1 | EE37: 85635395 | EF37: 30 | EG37: Строительные работы | EH37: 0 | EJ37: 1 | EK37: 23 | EL37: ТСН-2001.3-18. Отопление - внутренние устройства | EM37: ТСН-2001.3-18-1 | EQ37: 0 | ER37: 545.65 | ES37: 545.65 | ET37: 0 | EU37: 0 | EV37: 0 | EW37: 0 | EX37: 0 | EZ37: 5 | FC37: 1 | FD37: 18 | FF37: 6422 | FQ37: 0 | FR37: 0 | FS37: 0 | FX37: 109 | FY37: 61 | GA37: [6 422 / 1,22 / 9,84] + 2% Заг.скл | GD37: 1 | GF37: 752976982 | GG37: 2 | GH37: 3 | GI37: 5 | GJ37: 0 | GK37: 0 | GL37: =ROUND(IF(AND(BH37=3,BI37=3,FS37<>0),P37,0),2) -> 0 | GM37: =ROUND(O37+X37+Y37,2)+GX37 -> 69799.55 | GN37: =IF(OR(BI37=0,BI37=1),GM37-GX37,0) -> 69799.55 | GO37: =IF(BI37=2,GM37-GX37,0) -> 0 | GP37: =IF(BI37=4,GM37-GX37,0) -> 0 | GR37: 1 | GS37: 1 | GT37: 0 | GV37: =ROUND((GT37),6) -> 0 | GW37: 1 | GX37: =ROUND(HC37*I37,2) -> 0 | HA37: 0 | HB37: 0 | HC37: =GV37*GW37 -> 0 | HE37: 0 | HF37: 2 | HS37: 0 | IK37: 0
A38: 18 | B38: 1 | C38: 18 | E38: 1,5 | F38: КА. п. 5 | G38: Сmальной nанельный paguamop PRADO Classic, mun 20, Bыcoma Н = 500 мм, PRADO Classic-20-500-800 | I38: =I28*J38 -> 23 | J38: 17.293233 | K38: 17.293233 | O38: =ROUND(CP38,2) -> 13833.81 | P38: =ROUND((ROUND((AC38*AW38*I38),2)*BC38),2) -> 13833.81 | Q38: =(ROUND((ROUND(((ET38)*AV38*I38),2)*BB38),2)+ROUND((ROUND(((AE38-(EU38))*AV38*I38),2)*BS38),2)) -> 0 | R38: =(ROUND((ROUND(((EU38)*AV38*I38),2)*BS38),2)+ROUND((ROUND(((AE38-(EU38))*AV38*I38),2)*BS38),2)) -> 0 | S38: =ROUND((ROUND((AF38*AV38*I38),2)*BA38),2) -> 0 | T38: =ROUND(CU38*I38,2) -> 0 | U38: =CV38*I38 -> 0 | V38: =CW38*I38 -> 0 | W38: =ROUND(CX38*I38,2) -> 0 | X38: =(ROUND((((S38+ROUND((ROUND(((EU38)*AV38*I38),2)*BS38),2))*AT38)/100),2)+ROUND(((ROUND((ROUND(((AE38-(EU38))*AV38*I38),2)*BS38),2)*AT38)/100),2)) -> 0 | Y38: =(ROUND((((S38+ROUND((ROUND(((EU38)*AV38*I38),2)*BS38),2))*AU38)/100),2)+ROUND(((ROUND((ROUND(((AE38-(EU38))*AV38*I38),2)*BS38),2)*AU38)/100),2)) -> 0 | AA38: 86551701 | AB38: =ROUND((AC38+AD38+AF38),6) -> 601.47 | AC38: =ROUND((ES38),6) -> 601.47 | AD38: =ROUND((((ET38)-(EU38))+AE38),6) -> 0 | AE38: =ROUND((EU38),6) -> 0 | AF38: =ROUND((EV38),6) -> 0 | AG38: =ROUND((AP38),6) -> 0 | AH38: =(EW38) -> 0 | AI38: =(EX38) -> 0 | AJ38: =(AS38) -> 0 | AK38: 601.47 | AL38: 601.47 | AM38: 0 | AN38: 0 | AO38: 0 | AP38: 0 | AQ38: 0 | AR38: 0 | AS38: 0 | AT38: 109 | AU38: 61 | AV38: 1 | AW38: 1 | AZ38: 1 | BA38: 1 | BB38: 1 | BC38: 1 | BH38: 3 | BI38: 1 | BM38: 23 | BN38: 0 | BP38: 0 | BQ38: 30 | BR38: 0 | BS38: 1 | BT38: 1 | BU38: 1 | BV38: 1 | BW38: 1 | BX38: 1 | BZ38: 109 | CA38: 61 | CE38: 1566 | CF38: 0 | CG38: 0 | CM38: 0 | CO38: 0 | CP38: =(P38+Q38+S38) -> 13833.81 | CQ38: =ROUND((ROUND((AC38*AW38*1),2)*BC38),2) -> 601.47 | CR38: =(ROUND((ROUND(((ET38)*AV38*1),2)*BB38),2)+ROUND((ROUND(((AE38-(EU38))*AV38*1),2)*BS38),2)) -> 0 | CS38: =(ROUND((ROUND(((EU38)*AV38*1),2)*BS38),2)+ROUND((ROUND(((AE38-(EU38))*AV38*1),2)*BS38),2)) -> 0 | CT38: =ROUND((ROUND((AF38*AV38*1),2)*BA38),2) -> 0 | CU38: =AG38 -> 0 | CV38: =(AH38*AV38) -> 0 | CW38: =AI38 -> 0 | CX38: =AJ38 -> 0 | CY38: =(ROUND((((S38+ROUND((ROUND(((EU38)*AV38*1),2)*BS38),2))*AT38)/100),2)+ROUND(((ROUND((ROUND(((AE38-(EU38))*AV38*1),2)*BS38),2)*AT38)/100),2)) -> 0 | CZ38: =(ROUND((((S38+ROUND((ROUND(((EU38)*AV38*1),2)*BS38),2))*AU38)/100),2)+ROUND(((ROUND((ROUND(((AE38-(EU38))*AV38*1),2)*BS38),2)*AU38)/100),2)) -> 0 | DN38: 0 | DO38: 0 | DP38: 1 | DQ38: 1 | EE38: 85635395 | EF38: 30 | EG38: Строительные работы | EH38: 0 | EJ38: 1 | EK38: 23 | EL38: ТСН-2001.3-18. Отопление - внутренние устройства | EM38: ТСН-2001.3-18-1 | EQ38: 0 | ER38: 0 | ES38: 601.47 | ET38: 0 | EU38: 0 | EV38: 0 | EW38: 0 | EX38: 0 | FQ38: 0 | FR38: 0 | FS38: 0 | FX38: 109 | FY38: 61 | GA38: [7 079 / 1,22 / 9,84] + 2% Заг.скл | GD38: 1 | GF38: 566747535 | GG38: 2 | GH38: 4 | GI38: -2 | GJ38: 0 | GK38: 0 | GL38: =ROUND(IF(AND(BH38=3,BI38=3,FS38<>0),P38,0),2) -> 0 | GM38: =ROUND(O38+X38+Y38,2)+GX38 -> 13833.81 | GN38: =IF(OR(BI38=0,BI38=1),GM38-GX38,0) -> 13833.81 | GO38: =IF(BI38=2,GM38-GX38,0) -> 0 | GP38: =IF(BI38=4,GM38-GX38,0) -> 0 | GR38: 0 | GS38: 2 | GT38: 0 | GV38: =ROUND((GT38),6) -> 0 | GW38: 1 | GX38: =ROUND(HC38*I38,2) -> 0 | HA38: 0 | HB38: 0 | HC38: =GV38*GW38 -> 0 | HE38: 0 | HF38: 2 | HS38: 0 | IK38: 0
A39: 18 | B39: 1 | C39: 40 | E39: 1,5 | F39: КА. п. 5 | G39: Сmальной nанельный paguamop PRADO Classic, mun 20, Bыcoma Н = 500 мм, PRADO Classic-20-500-800 | I39: =I29*J39 -> 23 | J39: 17.293233 | K39: 17.293233 | O39: =ROUND(CP39,2) -> 136124.69 | P39: =ROUND((ROUND((AC39*AW39*I39),2)*BC39),2) -> 136124.69 | Q39: =(ROUND((ROUND(((ET39)*AV39*I39),2)*BB39),2)+ROUND((ROUND(((AE39-(EU39))*AV39*I39),2)*BS39),2)) -> 0 | R39: =(ROUND((ROUND(((EU39)*AV39*I39),2)*BS39),2)+ROUND((ROUND(((AE39-(EU39))*AV39*I39),2)*BS39),2)) -> 0 | S39: =ROUND((ROUND((AF39*AV39*I39),2)*BA39),2) -> 0 | T39: =ROUND(CU39*I39,2) -> 0 | U39: =CV39*I39 -> 0 | V39: =CW39*I39 -> 0 | W39: =ROUND(CX39*I39,2) -> 0 | X39: =(ROUND((((S39+ROUND((ROUND(((EU39)*AV39*I39),2)*BS39),2))*AT39)/100),2)+ROUND(((ROUND((ROUND(((AE39-(EU39))*AV39*I39),2)*BS39),2)*AT39)/100),2)) -> 0 | Y39: =(ROUND((((S39+ROUND((ROUND(((EU39)*AV39*I39),2)*BS39),2))*AU39)/100),2)+ROUND(((ROUND((ROUND(((AE39-(EU39))*AV39*I39),2)*BS39),2)*AU39)/100),2)) -> 0 | AA39: 86551703 | AB39: =ROUND((AC39+AD39+AF39),6) -> 601.47 | AC39: =ROUND((ES39),6) -> 601.47 | AD39: =ROUND((((ET39)-(EU39))+AE39),6) -> 0 | AE39: =ROUND((EU39),6) -> 0 | AF39: =ROUND((EV39),6) -> 0 | AG39: =ROUND((AP39),6) -> 0 | AH39: =(EW39) -> 0 | AI39: =(EX39) -> 0 | AJ39: =(AS39) -> 0 | AK39: 601.47 | AL39: 601.47 | AM39: 0 | AN39: 0 | AO39: 0 | AP39: 0 | AQ39: 0 | AR39: 0 | AS39: 0 | AT39: 109 | AU39: 61 | AV39: 1 | AW39: 1 | AZ39: 1 | BA39: 1 | BB39: 1 | BC39: 9.84 | BH39: 3 | BI39: 1 | BM39: 23 | BN39: 0 | BP39: 0 | BQ39: 30 | BR39: 0 | BS39: 1 | BT39: 1 | BU39: 1 | BV39: 1 | BW39: 1 | BX39: 1 | BZ39: 109 | CA39: 61 | CE39: 1566 | CF39: 0 | CG39: 0 | CM39: 0 | CO39: 0 | CP39: =(P39+Q39+S39) -> 136124.69 | CQ39: =ROUND((ROUND((AC39*AW39*1),2)*BC39),2) -> 5918.46 | CR39: =(ROUND((ROUND(((ET39)*AV39*1),2)*BB39),2)+ROUND((ROUND(((AE39-(EU39))*AV39*1),2)*BS39),2)) -> 0 | CS39: =(ROUND((ROUND(((EU39)*AV39*1),2)*BS39),2)+ROUND((ROUND(((AE39-(EU39))*AV39*1),2)*BS39),2)) -> 0 | CT39: =ROUND((ROUND((AF39*AV39*1),2)*BA39),2) -> 0 | CU39: =AG39 -> 0 | CV39: =(AH39*AV39) -> 0 | CW39: =AI39 -> 0 | CX39: =AJ39 -> 0 | CY39: =(ROUND((((S39+ROUND((ROUND(((EU39)*AV39*1),2)*BS39),2))*AT39)/100),2)+ROUND(((ROUND((ROUND(((AE39-(EU39))*AV39*1),2)*BS39),2)*AT39)/100),2)) -> 0 | CZ39: =(ROUND((((S39+ROUND((ROUND(((EU39)*AV39*1),2)*BS39),2))*AU39)/100),2)+ROUND(((ROUND((ROUND(((AE39-(EU39))*AV39*1),2)*BS39),2)*AU39)/100),2)) -> 0 | DN39: 0 | DO39: 0 | DP39: 1 | DQ39: 1 | EE39: 85635395 | EF39: 30 | EG39: Строительные работы | EH39: 0 | EJ39: 1 | EK39: 23 | EL39: ТСН-2001.3-18. Отопление - внутренние устройства | EM39: ТСН-2001.3-18-1 | EQ39: 0 | ER39: 601.47 | ES39: 601.47 | ET39: 0 | EU39: 0 | EV39: 0 | EW39: 0 | EX39: 0 | EZ39: 5 | FC39: 1 | FD39: 18 | FF39: 7079 | FQ39: 0 | FR39: 0 | FS39: 0 | FX39: 109 | FY39: 61 | GA39: [7 079 / 1,22 / 9,84] + 2% Заг.скл | GD39: 1 | GF39: 566747535 | GG39: 2 | GH39: 3 | GI39: 5 | GJ39: 0 | GK39: 0 | GL39: =ROUND(IF(AND(BH39=3,BI39=3,FS39<>0),P39,0),2) -> 0 | GM39: =ROUND(O39+X39+Y39,2)+GX39 -> 136124.69 | GN39: =IF(OR(BI39=0,BI39=1),GM39-GX39,0) -> 136124.69 | GO39: =IF(BI39=2,GM39-GX39,0) -> 0 | GP39: =IF(BI39=4,GM39-GX39,0) -> 0 | GR39: 1 | GS39: 1 | GT39: 0 | GV39: =ROUND((GT39),6) -> 0 | GW39: 1 | GX39: =ROUND(HC39*I39,2) -> 0 | HA39: 0 | HB39: 0 | HC39: =GV39*GW39 -> 0 | HE39: 0 | HF39: 2 | HS39: 0 | IK39: 0
