Workbook

Sheet Смета по ТСН-2001(с доп.67
A1: =Source!B1 -> Smeta.RU (495) 974-1589
J2: Форма № 4б
B3: "СОГЛАСОВАНО" | G3: "УТВЕРЖДАЮ"
B6: =CONCATENATE("______________________ ", IF(Source!AL12<>"", Source!AL12, "")) -> ______________________ | G6: =CONCATENATE("______________________ ", IF(Source!AH12<>"", Source!AH12, "")) -> ______________________
B7: "_____"________________ 2026 г. | G7: "_____"________________ 2026 г.
A10: Капитальный ремонт здания Государственного бюджетного общеобразовательного учреждения города Москвы «Школа №1574», расположенного по адресу: г. Москва, Старопименовский переулок, д. 5. 1 этап. 02-01-03 ЭОМ_27.07.26 | AP10: Капитальный ремонт здания Государственного бюджетного общеобразовательного учреждения города Москвы «Школа №1574», расположенного по адресу: г. Москва, Старопименовский переулок, д. 5. 1 этап. 02-01-03 ЭОМ_27.07.26
A11: (наименование стройки и/или объекта)
A13: =CONCATENATE( "ЛОКАЛЬНАЯ СМЕТА № ",IF(Source!F12<>"Новый объект", Source!F12, "")) -> ЛОКАЛЬНАЯ СМЕТА № 02-01-03
A16: (наименование работ и затрат)
A18: =CONCATENATE( "Основание: чертежи № ", Source!J12) -> Основание: чертежи № 2024-00375-01-0-ИОС1, 2024-00375-01-0-ООС2
I20: В базисном уровне цен | J20: В текущем уровне цен
E21: Сметная стоимость | I21: =I22+I23+I24+I25 -> 5734.48 | J21: =J22+J23+J24+J25 -> 78658.44 | K21: тыс.руб.
E22: Строительные работы | I22: =ROUND((Source!F1478)/1000, 2) -> 261.16 | J22: =ROUND((Source!P1478)/1000, 2) -> 14439.08 | K22: тыс.руб.
E23: Работы по монтажу оборудования | I23: =ROUND((Source!F1479)/1000, 2) -> 4377.25 | J23: =ROUND((Source!P1479)/1000, 2) -> 55954.02 | K23: тыс.руб.
E24: Оборудование | I24: =ROUND((Source!F1470)/1000, 2) -> 1096.07 | J24: =ROUND((Source!P1470)/1000, 2) -> 8265.34 | K24: тыс.руб.
E25: Прочие работы и затраты | I25: =ROUND((Source!F1480+Source!F1481)/1000, 2) -> 0 | J25: =ROUND((Source!P1480+Source!P1481)/1000, 2) -> 0 | K25: тыс.руб.
E26: Средства на оплату труда | I26: =(Source!F1476+ Source!F1475)/1000 -> 275.98458 | J26: =((Source!P1476 + Source!P1475)/1000) -> 15551.731 | K26: тыс.руб.
E27: Затраты труда | I27: =Source!F1483 -> 23259.425 | K27: чел.-ч.
E28: Кроме того:
E29: Возврат материалов | I29: =SUM(Y1:Y2291)/1000 -> 0 | J29: =SUM(Z1:Z2291)/1000 -> 0 | K29: тыс.руб.
A31: Составлен(а) по ТСН-2001 с учетом Дополнения №: 81
A32: № и период сборника коэффициентов (индексов) пересчета: Коэффициенты к ТСН-2001 МГЭ Дополнение 81, строительство №219/81 I квартал 2026 года и Коэффициенты к ТСН-2001.13-2 Дополнение 47 №64/47 I квартал 2026 года | AP32: № и период сборника коэффициентов (индексов) пересчета: Коэффициенты к ТСН-2001 МГЭ Дополнение 81, строительство №219/81 I квартал 2026 года и Коэффициенты к ТСН-2001.13-2 Дополнение 47 №64/47 I квартал 2026 года
A33: № п/п | B33: Шифр расценки и коды ресурсов | C33: Наименование работ и затрат | D33: Ед. изм. | E33: Кол-во единиц | F33: Цена на ед. изм., руб. | G33: Попра- вочные коэффи- циенты | H33: Коэффи- циенты зимних удорожа- ний | I33: Всего в ценах на январь 2000 года, руб. | J33: Коэффи- циенты (индек- сы) пере- счета, нормы НР и СП | K33: ВСЕГО затрат в текущем уровне цен, руб.
A34: 1 | B34: 2 | C34: 3 | D34: 4 | E34: 5 | F34: 6 | G34: 7 | H34: 8 | I34: 9 | J34: 10 | K34: 11
A36: =CONCATENATE("Локальная смета: ",IF(Source!G20<>"Новая локальная смета", Source!G20, "")) -> Локальная смета: Система электроснабжения
A38: =CONCATENATE("Раздел: ",IF(Source!G24<>"Новый раздел", Source!G24, "")) -> Раздел: Демонтажные работы (2024-00375-01-0-ООС2)
A39: 1 | B39: =Source!F28 -> 4.8-251-9 | C39: Монтаж щитка осветительного, устанавливаемого на стене распорными дюбелями, масса щитка до 6 кг / демонтаж | D39: =Source!H28 -> 1 ШТ. | E39: =Source!I28 -> 58 | Q39: =Source!X28 -> 801.57 | R39: =Source!X29 -> 45168.42 | S39: =Source!Y28 -> 421.44 | T39: =Source!Y29 -> 23748.34 | U39: =ROUND((175/100)*ROUND(Source!R28, 2), 2) -> 4.97 | V39: =ROUND((0/100)*ROUND(Source!R29, 2), 2) -> 0 | AC39: 0
C40: ЗП | F40: =Source!AO28 -> 37.67 | G40: 1,2*0,3 | H40: =Source!AV29 -> 1.047 | I40: =Source!S28 -> 823.52 | J40: =IF(Source!BA29<> 0, Source!BA29, 1) -> 56.35 | K40: =Source!S29 -> 46405.35
C41: ЭМ | F41: =Source!AM28 -> 1.32 | G41: 1,2*0,3 | H41: =Source!AV29 -> 1.047 | I41: =Source!Q28 -> 28.86 | J41: =IF(Source!BB29<> 0, Source!BB29, 1) -> 14.27 | K41: =Source!Q29 -> 411.83
C42: в т.ч. ЗПМ | F42: =Source!AN28 -> 0.13 | G42: 1,2*0,3 | H42: =Source!AV29 -> 1.047 | I42: =Source!R28 -> 2.84 | J42: =IF(Source!BS29<> 0, Source!BS29, 1) -> 56.35 | K42: =Source!R29 -> 160.03
C43: НР от ФОТ | D43: % | E43: =Source!BZ29 -> 97 | I43: =SUM(Q39:Q42) -> 801.57 | J43: =Source!AT29 -> 97 | K43: =SUM(R39:R42) -> 45168.42
C44: СП от ФОТ | D44: % | E44: =Source!CA29 -> 51 | I44: =SUM(S39:S43) -> 421.44 | J44: =Source!AU29 -> 51 | K44: =SUM(T39:T43) -> 23748.34
C45: ЗТР | D45: чел-ч | E45: =Source!AQ28 -> 2.9 | G45: 1,2*0,3 | H45: =Source!AV29 -> 1.047 | I45: =Source!U28 -> 63.397944
C46: ВСЕГО работ по позиции: | H46: =I40+I41+I43+I44+0-0-0 -> 2075.39 | J46: =K40+K41+K43+K44+0-0-0 -> 115733.94
C47: ВСЕГО оборудование по позиции: | H47: =0+0 -> 0 | J47: =0+0 -> 0
C48: ВСЕГО по позиции: | H48: =I40+I41+I43+I44+0 -> 2075.39 | J48: =K40+K41+K43+K44+0 -> 115733.94 | O48: =I40+I41+I43+I44+0 -> 2075.39 | P48: =K40+K41+K43+K44+0 -> 115733.94
A50: 2 | B50: =Source!F30 -> 6.67-7-5 | C50: Демонтаж осветительных приборов, светильник для люминесцентных ламп | D50: =Source!H30 -> 100 шт. | E50: =Source!I30 -> 12.44 | Q50: =Source!X30 -> 2676.76 | R50: =Source!X31 -> 150835.19 | S50: =Source!Y30 -> 1411.92 | T50: =Source!Y31 -> 79561.42 | U50: =ROUND((175/100)*ROUND(Source!R30, 2), 2) -> 0 | V50: =ROUND((0/100)*ROUND(Source!R31, 2), 2) -> 0 | AC50: 0
C51: ="Объем: "&Source!I30&"=1244/"&"100" -> Объем: 12,44=1244/100
C52: ЗП | F52: =Source!AO30 -> 188.2 | G52: 1,2 | H52: =Source!AV31 -> 1.047 | I52: =Source!S30 -> 2941.49 | J52: =IF(Source!BA31<> 0, Source!BA31, 1) -> 56.35 | K52: =Source!S31 -> 165752.96
C53: НР от ФОТ | D53: % | E53: =Source!BZ31 -> 91 | I53: =SUM(Q50:Q52) -> 2676.76 | J53: =Source!AT31 -> 91 | K53: =SUM(R50:R52) -> 150835.19
...

Sheet Source
A1: 0 | B1: Smeta.RU (495) 974-1589 | D1: _PS_ | F1: 0 | G1: 0 | H1: 0 | I1: Smeta.RU | K1: 1 | L1: 74599 | M1: 10 | N1: 12 | O1: 1 | P1: 0 | Q1: 5
A4: 1 | B4: 1 | C4: -1 | G4: Капитальный ремонт здания Государственного бюджетного общеобразовательного учреждения города Москвы «Школа №1574», расположенного по адресу: г. Москва, Старопименовский переулок, д. 5. 1 этап | EC4: 0
A5: 8 | B5: 1 | C5: -1 | G5: Капитальный ремонт здания Государственного бюджетного общеобразовательного учреждения города Москвы «Школа №1574», расположенного по адресу: г. Москва, Старопименовский переулок, д. 5. 1 этап | EC5: 0
A12: 1 | B12: 1500 | C12: 0 | D12: =ROW(A1461) -> 1461 | E12: 0 | F12: 02-01-03 | G12: 02-01-03 ЭОМ_27.07.26 | I12: 0 | J12: 2024-00375-01-0-ИОС1, 2024-00375-01-0-ООС2 | K12: 0 | L12: 0 | M12: 4098 | O12: 0 | P12: 0 | Q12: 0 | R12: 0 | S12: 0 | T12: 1 | V12: 2 | AB12: О.А.Гришечкина | AC12: Ведущий инженер-сметччик | AD12: И.В.Феденко | AE12: Начальник отдела | BB12: 0 | BH12: Сметные нормы списания | BI12: Коды ОКП для ТСН-2001 МГЭ Дополнение 81 | BJ12: 1 | BK12: 1 | BL12: 0 | BM12: 0 | BN12: 1 | BO12: 0 | BP12: 6 | BQ12: 2 | BR12: 1 | BS12: 1 | BT12: 0 | BU12: 0 | BV12: 0 | BW12: 0 | BX12: 0 | BY12: ТСН-2001 (МГЭ) Доп 81 - Новое строительство | BZ12: Типовой расчет для ТСН-2001 МГЭ, Дополнение 81, строительство | CA12: Территориальные сметные нормативы для Москвы ТСН-2001 (МГЭ), дополнение 81 | CB12: Территориальные сметные нормативы для Москвы ТСН-2001 (МГЭ), дополнение 81 | CC12: Территориальные сметные нормативы для Москвы ТСН-2001 (МГЭ), дополнение 81 | CD12: Территориальные сметные нормативы для Москвы ТСН-2001 (МГЭ), дополнение 81 | CE12: Поправки для ТСН-2001 от 07.04.2026 г. доп.81 | CF12: 0 | CG12: 0 | CH12: 8200 | CK12: 82 | CQ12: Территориальные сметные нормативы для Москвы (ТСН-2001) | CR12: ТЕР | CS12: 41660 | CT12: 1 | CU12: 81 | CY12: 0 | EC12: 0
A15: 15 | B15: 1
A18: 52 | B18: =B1461 -> 1500 | C18: =C1461 -> 1 | D18: =D1461 -> 12 | E18: =E1461 -> 0 | F18: =F1461 -> 02-01-03 | G18: =G1461 -> 02-01-03 ЭОМ_27.07.26 | O18: =O1461 -> 5335739.8 | P18: =P1461 -> 5030939 | Q18: =Q1461 -> 34810 | R18: =R1461 -> 5993.71 | S18: =S1461 -> 269990.87 | T18: =T1461 -> 0 | U18: =U1461 -> 23259.425 | V18: =V1461 -> 0 | ... GX18: =GX1461 -> 0
A20: 3 | B20: 1 | D20: =ROW(A1431) -> 1431 | F20: 02-01-03 | G20: Система электроснабжения | I20: 0 | J20: 2024-00375-01-0-ИОС1, 2024-00375-01-0-ООС2 | K20: -1 | L20: 02-01-03 | S20: 0 | T20: 0 | V20: 2 | AB20: О.А.Гритшечкина | AD20: И.В.Феденко | AE20: Начальник отдела | BC20: *1 | BD20: *1,1 | BE20: *1,1 | BF20: *1,1 | BH20: *1,1 | BI20: *1,1 | BM20: *1 | BN20: *1,1 | BO20: Поправка: Гл.12.Прил.8.п.8. 5_12.00.01.11.003 Наименование: При наличии усложненных условий производства работ (стесненность, сложность складирования и транспортной логистики, наличие в зоне производства работ действующего технологического оборудования или движения технологического транспорта и т.п.) для объектов, расположенных за пределами территории круговой магистральной системы улиц "Садовое кольцо" и за пределами Третьего транспортного кольца города Москвы пунктов "а" и "б", но в пределах Московской кольцевой автомобильной дороги | BP20: Поправка: Гл.12.Прил.8.п.8. 5_12.00.01.11.003 | BX20: 0 | CF20: 0 | CG20: 0
A22: 52 | B22: =B1431 -> 1 | C22: =C1431 -> 3 | D22: =D1431 -> 20 | E22: =E1431 -> 0 | F22: =F1431 -> 02-01-03 | G22: =G1431 -> Система электроснабжения | O22: =O1431 -> 5335739.8 | P22: =P1431 -> 5030939 | Q22: =Q1431 -> 34810 | R22: =R1431 -> 5993.71 | S22: =S1431 -> 269990.87 | T22: =T1431 -> 0 | U22: =U1431 -> 23259.425 | V22: =V1431 -> 0 | ... GX22: =GX1431 -> 0
A24: 4 | B24: 1 | D24: =ROW(A93) -> 93 | F24: 1 | G24: Демонтажные работы (2024-00375-01-0-ООС2) | I24: 0 | K24: -1 | S24: 0 | T24: 0 | V24: 2 | BC24: *1 | BD24: *1,1 | BE24: *1,1 | BF24: *1,1 | BH24: *1,1 | BI24: *1,1 | BM24: *1 | BN24: *1,1 | BO24: Поправка: Гл.12.Прил.8.п.8. 5_12.00.01.11.003 Наименование: При наличии усложненных условий производства работ (стесненность, сложность складирования и транспортной логистики, наличие в зоне производства работ действующего технологического оборудования или движения технологического транспорта и т.п.) для объектов, расположенных за пределами территории круговой магистральной системы улиц "Садовое кольцо" и за пределами Третьего транспортного кольца города Москвы пунктов "а" и "б", но в пределах Московской кольцевой автомобильной дороги | BP24: Поправка: Гл.12.Прил.8.п.8. 5_12.00.01.11.003 | BX24: 0 | CJ24: 0
A26: 52 | B26: =B93 -> 1 | C26: =C93 -> 4 | D26: =D93 -> 24 | E26: =E93 -> 0 | F26: =F93 -> 1 | G26: =G93 -> Демонтажные работы (2024-00375-01-0-ООС2) | O26: =O93 -> 115163.54 | P26: =P93 -> 4.29 | Q26: =Q93 -> 857.45 | R26: =R93 -> 71.34 | S26: =S93 -> 114301.8 | T26: =T93 -> 0 | U26: =U93 -> 10822.647 | V26: =V93 -> 0 | ... GX26: =GX93 -> 0
A28: 17 | B28: 1 | C28: =ROW(SmtRes!A9) -> 9 | D28: =ROW(EtalonRes!A12) -> 12 | E28: 1 | F28: 4.8-251-9 | G28: Монтаж щитка осветительного, устанавливаемого на стене распорными дюбелями, масса щитка до 6 кг / демонтаж | H28: 1 ШТ. | I28: 58 | J28: 0 | K28: 58 | O28: =ROUND(CP28,2) -> 852.38 | P28: =ROUND((ROUND((AC28*AW28*I28),2)*BC28),2) -> 0 | Q28: =(ROUND((ROUND(((((ET28*1.2)*0.3))*AV28*I28),2)*BB28),2)+ROUND((ROUND(((AE28-(((EU28*1.2)*0.3)))*AV28*I28),2)*BS28),2)) -> 28.86 | R28: =(ROUND((ROUND(((((EU28*1.2)*0.3))*AV28*I28),2)*BS28),2)+ROUND((ROUND(((AE28-(((EU28*1.2)*0.3)))*AV28*I28),2)*BS28),2)) -> 2.84 | S28: =ROUND((ROUND((AF28*AV28*I28),2)*BA28),2) -> 823.52 | T28: =ROUND(CU28*I28,2) -> 0 | U28: =CV28*I28 -> 63.397944 | V28: =CW28*I28 -> 0 | W28: =ROUND(CX28*I28,2) -> 0 | X28: =(ROUND((((S28+ROUND((ROUND(((((EU28*1.2)*0.3))*AV28*I28),2)*BS28),2))*AT28)/100),2)+ROUND(((ROUND((ROUND(((AE28-(((EU28*1.2)*0.3)))*AV28*I28),2)*BS28),2)*AT28)/100),2)) -> 801.57 | Y28: =(ROUND((((S28+ROUND((ROUND(((((EU28*1.2)*0.3))*AV28*I28),2)*BS28),2))*AU28)/100),2)+ROUND(((ROUND((ROUND(((AE28-(((EU28*1.2)*0.3)))*AV28*I28),2)*BS28),2)*AU28)/100),2)) -> 421.44 | AA28: 54971259 | AB28: =ROUND((AC28+AD28+AF28),6) -> 14.0364 | AC28: =ROUND((((ES28*1)*0)),6) -> 0 | AD28: =ROUND((((((ET28*1.2)*0.3))-(((EU28*1.2)*0.3)))+AE28),6) -> 0.4752 | AE28: =ROUND((((EU28*1.2)*0.3)),6) -> 0.0468 | AF28: =ROUND((((EV28*1.2)*0.3)),6) -> 13.5612 | AG28: =ROUND((AP28),6) -> 0 | AH28: =(((EW28*1.2)*0.3)) -> 1.044 | AI28: =(((EX28*1.2)*0.3)) -> 0 | AJ28: =(AS28) -> 0 | AK28: 69.2 | AL28: 30.21 | AM28: 1.32 | AN28: 0.13 | AO28: 37.67 | AP28: 0 | AQ28: 2.9 | AR28: 0 | AS28: 0 | AT28: 97 | AU28: 51 | AV28: 1.047 | AW28: 1 | AZ28: 1 | BA28: 1 | BB28: 1 | BC28: 1 | BH28: 0 | BI28: 2 | BJ28: ТСН-2001.4 Доп. 80, Сб. 8, т. 251, поз. 9 | BM28: 67 | BN28: 0 | BO28: 4.8-251-9 | BP28: 1 | BQ28: 40 | BR28: 0 | BS28: 1 | BT28: 1 | BU28: 1 | BV28: 1 | BW28: 1 | BX28: 1 | BZ28: 97 | CA28: 51 | CE28: 1566 | CF28: 0 | CG28: 0 | CM28: 0 | CN28: Поправка: Гл.12.Прил.8.п.8. 3_12.00.01.11.001 Наименование: При наличии напряженных и стесненных условий производства работ (стесненность, сложность складирования и транспортной логистики и т.п.) для объектов, расположенных в пределах круговой магистральной системы улиц "Садовое кольцо" города Москвы Поправка: Гл.4.Прил.2.2.п.2.2.29_04.00.01.35.003 Наименование: При демонтаже оборудования, предназначенного в лом | CO28: 0 | CP28: =(P28+Q28+S28) -> 852.38 | CQ28: =ROUND((ROUND((AC28*AW28*1),2)*BC28),2) -> 0 | CR28: =(ROUND((ROUND(((((ET28*1.2)*0.3))*AV28*1),2)*BB28),2)+ROUND((ROUND(((AE28-(((EU28*1.2)*0.3)))*AV28*1),2)*BS28),2)) -> 0.5 | CS28: =(ROUND((ROUND(((((EU28*1.2)*0.3))*AV28*1),2)*BS28),2)+ROUND((ROUND(((AE28-(((EU28*1.2)*0.3)))*AV28*1),2)*BS28),2)) -> 0.05 | CT28: =ROUND((ROUND((AF28*AV28*1),2)*BA28),2) -> 14.2 | CU28: =AG28 -> 0 | CV28: =(AH28*AV28) -> 1.093068 | CW28: =AI28 -> 0 | CX28: =AJ28 -> 0 | CY28: =(ROUND((((S28+ROUND((ROUND(((((EU28*1.2)*0.3))*AV28*1),2)*BS28),2))*AT28)/100),2)+ROUND(((ROUND((ROUND(((AE28-(((EU28*1.2)*0.3)))*AV28*1),2)*BS28),2)*AT28)/100),2)) -> 798.86 | CZ28: =(ROUND((((S28+ROUND((ROUND(((((EU28*1.2)*0.3))*AV28*1),2)*BS28),2))*AU28)/100),2)+ROUND(((ROUND((ROUND(((AE28-(((EU28*1.2)*0.3)))*AV28*1),2)*BS28),2)*AU28)/100),2)) -> 420.02 | DB28: 1 | DD28: *1)*0 | DE28: *1,2)*0,3 | DF28: *1,2)*0,3 | DG28: *1,2)*0,3 | DI28: *1,2)*0,3 | DJ28: *1,2)*0,3 | DN28: 0 | DO28: 0 | DP28: 1 | DQ28: 1 | DU28: 1013 | DV28: 1 ШТ. | DW28: 1 ШТ. | DX28: 1 | EE28: 57042957 | EF28: 40 | EG28: Монтаж оборудования | EH28: 0 | EJ28: 2 | EK28: 67 | EL28: ТСН-2001.4-8. Электротехнические установки | EM28: ТСН-2001.4-8-1 | EO28: Поправка: Гл.12.Прил.8.п.8. 3_12.00.01.11.001 Поправка: Гл.4.Прил.2.2.п.2.2.29_04.00.01.35.003 | EQ28: 0 | ER28: 69.2 | ES28: 30.21 | ET28: 1.32 | EU28: 0.13 | EV28: 37.67 | EW28: 2.9 | EX28: 0 | EY28: 0 | FQ28: 0 | FR28: 0 | FS28: 0 | FX28: 97 | FY28: 51 | GD28: 1 | GF28: 1021264723 | GG28: 2 | GH28: 1 | GI28: 2 | GJ28: 0 | GK28: 0 | GL28: =ROUND(IF(AND(BH28=3,BI28=3,FS28<>0),P28,0),2) -> 0 | GM28: =ROUND(O28+X28+Y28,2)+GX28 -> 2075.39 | GN28: =IF(OR(BI28=0,BI28=1),GM28-GX28,0) -> 0 | GO28: =IF(BI28=2,GM28-GX28,0) -> 2075.39 | GP28: =IF(BI28=4,GM28-GX28,0) -> 0 | GR28: 0 | GS28: 3 | GT28: 0 | GV28: =ROUND((GT28),6) -> 0 | GW28: 1 | GX28: =ROUND(HC28*I28,2) -> 0 | HA28: 0 | HB28: 0 | HC28: =GV28*GW28 -> 0 | HS28: 0 | IK28: 0
A29: 17 | B29: 1 | C29: =ROW(SmtRes!A18) -> 18 | D29: =ROW(EtalonRes!A24) -> 24 | E29: 1 | F29: 4.8-251-9 | G29: Монтаж щитка осветительного, устанавливаемого на стене распорными дюбелями, масса щитка до 6 кг / демонтаж | H29: 1 ШТ. | I29: 58 | J29: 0 | K29: 58 | O29: =ROUND(CP29,2) -> 46817.18 | P29: =ROUND((ROUND((AC29*AW29*I29),2)*BC29),2) -> 0 | Q29: =(ROUND((ROUND(((((ET29*1.2)*0.3))*AV29*I29),2)*BB29),2)+ROUND((ROUND(((AE29-(((EU29*1.2)*0.3)))*AV29*I29),2)*BS29),2)) -> 411.83 | R29: =(ROUND((ROUND(((((EU29*1.2)*0.3))*AV29*I29),2)*BS29),2)+ROUND((ROUND(((AE29-(((EU29*1.2)*0.3)))*AV29*I29),2)*BS29),2)) -> 160.03 | S29: =ROUND((ROUND((AF29*AV29*I29),2)*BA29),2) -> 46405.35 | T29: =ROUND(CU29*I29,2) -> 0 | U29: =CV29*I29 -> 63.397944 | V29: =CW29*I29 -> 0 | W29: =ROUND(CX29*I29,2) -> 0 | X29: =(ROUND((((S29+ROUND((ROUND(((((EU29*1.2)*0.3))*AV29*I29),2)*BS29),2))*AT29)/100),2)+ROUND(((ROUND((ROUND(((AE29-(((EU29*1.2)*0.3)))*AV29*I29),2)*BS29),2)*AT29)/100),2)) -> 45168.42 | Y29: =(ROUND((((S29+ROUND((ROUND(((((EU29*1.2)*0.3))*AV29*I29),2)*BS29),2))*AU29)/100),2)+ROUND(((ROUND((ROUND(((AE29-(((EU29*1.2)*0.3)))*AV29*I29),2)*BS29),2)*AU29)/100),2)) -> 23748.34 | AA29: 55890823 | AB29: =ROUND((AC29+AD29+AF29),6) -> 14.0364 | AC29: =ROUND((((ES29*1)*0)),6) -> 0 | AD29: =ROUND((((((ET29*1.2)*0.3))-(((EU29*1.2)*0.3)))+AE29),6) -> 0.4752 | AE29: =ROUND((((EU29*1.2)*0.3)),6) -> 0.0468 | AF29: =ROUND((((EV29*1.2)*0.3)),6) -> 13.5612 | AG29: =ROUND((AP29),6) -> 0 | AH29: =(((EW29*1.2)*0.3)) -> 1.044 | AI29: =(((EX29*1.2)*0.3)) -> 0 | AJ29: =(AS29) -> 0 | AK29: 69.2 | AL29: 30.21 | AM29: 1.32 | AN29: 0.13 | AO29: 37.67 | AP29: 0 | AQ29: 2.9 | AR29: 0 | AS29: 0 | AT29: 97 | AU29: 51 | AV29: 1.047 | AW29: 1 | AZ29: 1 | BA29: 56.35 | BB29: 14.27 | BC29: 6.19 | BH29: 0 | BI29: 2 | BJ29: ТСН-2001.4 Доп. 80, Сб. 8, т. 251, поз. 9 | BM29: 67 | BN29: 0 | BO29: 4.8-251-9 | BP29: 1 | BQ29: 40 | BR29: 0 | BS29: 56.35 | BT29: 1 | BU29: 1 | BV29: 1 | BW29: 1 | BX29: 1 | BZ29: 97 | CA29: 51 | CE29: 1566 | CF29: 0 | CG29: 0 | CM29: 0 | CN29: Поправка: Гл.12.Прил.8.п.8. 3_12.00.01.11.001 Наименование: При наличии напряженных и стесненных условий производства работ (стесненность, сложность складирования и транспортной логистики и т.п.) для объектов, расположенных в пределах круговой магистральной системы улиц "Садовое кольцо" города Москвы Поправка: Гл.4.Прил.2.2.п.2.2.29_04.00.01.35.003 Наименование: При демонтаже оборудования, предназначенного в лом | CO29: 0 | CP29: =(P29+Q29+S29) -> 46817.18 | CQ29: =ROUND((ROUND((AC29*AW29*1),2)*BC29),2) -> 0 | CR29: =(ROUND((ROUND(((((ET29*1.2)*0.3))*AV29*1),2)*BB29),2)+ROUND((ROUND(((AE29-(((EU29*1.2)*0.3)))*AV29*1),2)*BS29),2)) -> 7.14 | CS29: =(ROUND((ROUND(((((EU29*1.2)*0.3))*AV29*1),2)*BS29),2)+ROUND((ROUND(((AE29-(((EU29*1.2)*0.3)))*AV29*1),2)*BS29),2)) -> 2.82 | CT29: =ROUND((ROUND((AF29*AV29*1),2)*BA29),2) -> 800.17 | CU29: =AG29 -> 0 | CV29: =(AH29*AV29) -> 1.093068 | CW29: =AI29 -> 0 | CX29: =AJ29 -> 0 | CY29: =(ROUND((((S29+ROUND((ROUND(((((EU29*1.2)*0.3))*AV29*1),2)*BS29),2))*AT29)/100),2)+ROUND(((ROUND((ROUND(((AE29-(((EU29*1.2)*0.3)))*AV29*1),2)*BS29),2)*AT29)/100),2)) -> 45015.92 | CZ29: =(ROUND((((S29+ROUND((ROUND(((((EU29*1.2)*0.3))*AV29*1),2)*BS29),2))*AU29)/100),2)+ROUND(((ROUND((ROUND(((AE29-(((EU29*1.2)*0.3)))*AV29*1),2)*BS29),2)*AU29)/100),2)) -> 23668.17 | DB29: 3 | DD29: *1)*0 | DE29: *1,2)*0,3 | DF29: *1,2)*0,3 | DG29: *1,2)*0,3 | DI29: *1,2)*0,3 | DJ29: *1,2)*0,3 | DN29: 0 | DO29: 0 | DP29: 1 | DQ29: 1 | DU29: 1013 | DV29: 1 ШТ. | DW29: 1 ШТ. | DX29: 1 | EE29: 57042957 | EF29: 40 | EG29: Монтаж оборудования | EH29: 0 | EJ29: 2 | EK29: 67 | EL29: ТСН-2001.4-8. Электротехнические установки | EM29: ТСН-2001.4-8-1 | EO29: Поправка: Гл.12.Прил.8.п.8. 3_12.00.01.11.001 Поправка: Гл.4.Прил.2.2.п.2.2.29_04.00.01.35.003 | EQ29: 0 | ER29: 69.2 | ES29: 30.21 | ET29: 1.32 | EU29: 0.13 | EV29: 37.67 | EW29: 2.9 | EX29: 0 | EY29: 0 | FQ29: 0 | FR29: 0 | FS29: 0 | FX29: 97 | FY29: 51 | GD29: 1 | GF29: 1021264723 | GG29: 2 | GH29: 1 | GI29: 2 | GJ29: 0 | GK29: 0 | GL29: =ROUND(IF(AND(BH29=3,BI29=3,FS29<>0),P29,0),2) -> 0 | GM29: =ROUND(O29+X29+Y29,2)+GX29 -> 115733.94 | GN29: =IF(OR(BI29=0,BI29=1),GM29-GX29,0) -> 0 | GO29: =IF(BI29=2,GM29-GX29,0) -> 115733.94 | GP29: =IF(BI29=4,GM29-GX29,0) -> 0 | GR29: 0 | GS29: 3 | GT29: 0 | GV29: =ROUND((GT29),6) -> 0 | GW29: 1 | GX29: =ROUND(HC29*I29,2) -> 0 | HA29: 0 | HB29: 0 | HC29: =GV29*GW29 -> 0 | HS29: 0 | IK29: 0
A30: 17 | B30: 1 | C30: =ROW(SmtRes!A19) -> 19 | D30: =ROW(EtalonRes!A25) -> 25 | E30: 2 | F30: 6.67-7-5 | G30: Демонтаж осветительных приборов, светильник для люминесцентных ламп | H30: 100 шт. | I30: =ROUND(1244/100,9) -> 12.44 | J30: 0 | K30: =ROUND(1244/100,9) -> 12.44 | O30: =ROUND(CP30,2) -> 2941.49 | P30: =ROUND((ROUND((AC30*AW30*I30),2)*BC30),2) -> 0 | Q30: =(ROUND((ROUND((((ET30*1.2))*AV30*I30),2)*BB30),2)+ROUND((ROUND(((AE30-((EU30*1.2)))*AV30*I30),2)*BS30),2)) -> 0 | R30: =(ROUND((ROUND((((EU30*1.2))*AV30*I30),2)*BS30),2)+ROUND((ROUND(((AE30-((EU30*1.2)))*AV30*I30),2)*BS30),2)) -> 0 | S30: =ROUND((ROUND((AF30*AV30*I30),2)*BA30),2) -> 2941.49 | T30: =ROUND(CU30*I30,2) -> 0 | U30: =CV30*I30 -> 279.61383 | V30: =CW30*I30 -> 0 | W30: =ROUND(CX30*I30,2) -> 0 | X30: =(ROUND((((S30+ROUND((ROUND((((EU30*1.2))*AV30*I30),2)*BS30),2))*AT30)/100),2)+ROUND(((ROUND((ROUND(((AE30-((EU30*1.2)))*AV30*I30),2)*BS30),2)*AT30)/100),2)) -> 2676.76 | Y30: =(ROUND((((S30+ROUND((ROUND((((EU30*1.2))*AV30*I30),2)*BS30),2))*AU30)/100),2)+ROUND(((ROUND((ROUND(((AE30-((EU30*1.2)))*AV30*I30),2)*BS30),2)*AU30)/100),2)) -> 1411.92 | AA30: 54971259 | AB30: =ROUND((AC30+AD30+AF30),6) -> 225.84 | AC30: =ROUND(((ES30*1)),6) -> 0 | AD30: =ROUND(((((ET30*1.2))-((EU30*1.2)))+AE30),6) -> 0 | AE30: =ROUND(((EU30*1.2)),6) -> 0 | AF30: =ROUND(((EV30*1.2)),6) -> 225.84 | AG30: =ROUND((AP30),6) -> 0 | AH30: =((EW30*1.2)) -> 21.468 | AI30: =((EX30*1.2)) -> 0 | AJ30: =(AS30) -> 0 | AK30: 188.2 | AL30: 0 | AM30: 0 | AN30: 0 | AO30: 188.2 | AP30: 0 | AQ30: 17.89 | AR30: 0 | AS30: 0 | AT30: 91 | AU30: 48 | AV30: 1.047 | AW30: 1 | AZ30: 1 | BA30: 1 | BB30: 1 | BC30: 1 | BH30: 0 | BI30: 1 | BJ30: ТСН-2001.6. Доп. 1-42. Сб. 67, т. 7, поз. 5 | BM30: 106 | BN30: 0 | BO30: 6.67-7-5 | BP30: 1 | BQ30: 60 | BR30: 0 | BS30: 1 | BT30: 1 | BU30: 1 | BV30: 1 | BW30: 1 | BX30: 1 | BZ30: 91 | CA30: 48 | CE30: 1566 | CF30: 0 | CG30: 0 | CM30: 0 | CN30: Поправка: Гл.12.Прил.8.п.8. 3_12.00.01.11.001 Наименование: При наличии напряженных и стесненных условий производства работ (стесненность, сложность складирования и транспортной логистики и т.п.) для объектов, расположенных в пределах круговой магистральной системы улиц "Садовое кольцо" города Москвы | CO30: 0 | CP30: =(P30+Q30+S30) -> 2941.49 | CQ30: =ROUND((ROUND((AC30*AW30*1),2)*BC30),2) -> 0 | CR30: =(ROUND((ROUND((((ET30*1.2))*AV30*1),2)*BB30),2)+ROUND((ROUND(((AE30-((EU30*1.2)))*AV30*1),2)*BS30),2)) -> 0 | CS30: =(ROUND((ROUND((((EU30*1.2))*AV30*1),2)*BS30),2)+ROUND((ROUND(((AE30-((EU30*1.2)))*AV30*1),2)*BS30),2)) -> 0 | CT30: =ROUND((ROUND((AF30*AV30*1),2)*BA30),2) -> 236.45 | CU30: =AG30 -> 0 | CV30: =(AH30*AV30) -> 22.476996 | CW30: =AI30 -> 0 | CX30: =AJ30 -> 0 | CY30: =(ROUND((((S30+ROUND((ROUND((((EU30*1.2))*AV30*1),2)*BS30),2))*AT30)/100),2)+ROUND(((ROUND((ROUND(((AE30-((EU30*1.2)))*AV30*1),2)*BS30),2)*AT30)/100),2)) -> 2676.76 | CZ30: =(ROUND((((S30+ROUND((ROUND((((EU30*1.2))*AV30*1),2)*BS30),2))*AU30)/100),2)+ROUND(((ROUND((ROUND(((AE30-((EU30*1.2)))*AV30*1),2)*BS30),2)*AU30)/100),2)) -> 1411.92 | DB30: 5 | DD30: *1 | DE30: *1,2 | DF30: *1,2 | DG30: *1,2 | DI30: *1,2 | DJ30: *1,2 | DN30: 0 | DO30: 0 | DP30: 1 | DQ30: 1 | DU30: 1010 | DV30: 100 шт. | DW30: 100 шт. | DX30: 100 | EE30: 57042996 | EF30: 60 | EG30: Ремонтно-строительные работы | EH30: 0 | EJ30: 1 | EK30: 106 | EL30: ТСН-2001.6-67. Электромонтажные работы | EM30: ТСН-2001.6-67-1 | EO30: Поправка: Гл.12.Прил.8.п.8. 3_12.00.01.11.001 | EQ30: 0 | ER30: 188.2 | ES30: 0 | ET30: 0 | EU30: 0 | EV30: 188.2 | EW30: 17.89 | EX30: 0 | EY30: 0 | FQ30: 0 | FR30: 0 | FS30: 0 | FX30: 91 | FY30: 48 | GD30: 1 | GF30: -651826134 | GG30: 2 | GH30: 1 | GI30: 2 | GJ30: 0 | GK30: 0 | GL30: =ROUND(IF(AND(BH30=3,BI30=3,FS30<>0),P30,0),2) -> 0 | GM30: =ROUND(O30+X30+Y30,2)+GX30 -> 7030.17 | GN30: =IF(OR(BI30=0,BI30=1),GM30-GX30,0) -> 7030.17 | GO30: =IF(BI30=2,GM30-GX30,0) -> 0 | GP30: =IF(BI30=4,GM30-GX30,0) -> 0 | GR30: 0 | GS30: 3 | GT30: 0 | GV30: =ROUND((GT30),6) -> 0 | GW30: 1 | GX30: =ROUND(HC30*I30,2) -> 0 | HA30: 0 | HB30: 0 | HC30: =GV30*GW30 -> 0 | HS30: 0 | IK30: 0
A31: 17 | B31: 1 | C31: =ROW(SmtRes!A20) -> 20 | D31: =ROW(EtalonRes!A26) -> 26 | E31: 2 | F31: 6.67-7-5 | G31: Демонтаж осветительных приборов, светильник для люминесцентных ламп | H31: 100 шт. | I31: =ROUND(1244/100,9) -> 12.44 | J31: 0 | K31: =ROUND(1244/100,9) -> 12.44 | O31: =ROUND(CP31,2) -> 165752.96 | P31: =ROUND((ROUND((AC31*AW31*I31),2)*BC31),2) -> 0 | Q31: =(ROUND((ROUND((((ET31*1.2))*AV31*I31),2)*BB31),2)+ROUND((ROUND(((AE31-((EU31*1.2)))*AV31*I31),2)*BS31),2)) -> 0 | R31: =(ROUND((ROUND((((EU31*1.2))*AV31*I31),2)*BS31),2)+ROUND((ROUND(((AE31-((EU31*1.2)))*AV31*I31),2)*BS31),2)) -> 0 | S31: =ROUND((ROUND((AF31*AV31*I31),2)*BA31),2) -> 165752.96 | T31: =ROUND(CU31*I31,2) -> 0 | U31: =CV31*I31 -> 279.61383 | V31: =CW31*I31 -> 0 | W31: =ROUND(CX31*I31,2) -> 0 | X31: =(ROUND((((S31+ROUND((ROUND((((EU31*1.2))*AV31*I31),2)*BS31),2))*AT31)/100),2)+ROUND(((ROUND((ROUND(((AE31-((EU31*1.2)))*AV31*I31),2)*BS31),2)*AT31)/100),2)) -> 150835.19 | Y31: =(ROUND((((S31+ROUND((ROUND((((EU31*1.2))*AV31*I31),2)*BS31),2))*AU31)/100),2)+ROUND(((ROUND((ROUND(((AE31-((EU31*1.2)))*AV31*I31),2)*BS31),2)*AU31)/100),2)) -> 79561.42 | AA31: 55890823 | AB31: =ROUND((AC31+AD31+AF31),6) -> 225.84 | AC31: =ROUND(((ES31*1)),6) -> 0 | AD31: =ROUND(((((ET31*1.2))-((EU31*1.2)))+AE31),6) -> 0 | AE31: =ROUND(((EU31*1.2)),6) -> 0 | AF31: =ROUND(((EV31*1.2)),6) -> 225.84 | AG31: =ROUND((AP31),6) -> 0 | AH31: =((EW31*1.2)) -> 21.468 | AI31: =((EX31*1.2)) -> 0 | AJ31: =(AS31) -> 0 | AK31: 188.2 | AL31: 0 | AM31: 0 | AN31: 0 | AO31: 188.2 | AP31: 0 | AQ31: 17.89 | AR31: 0 | AS31: 0 | AT31: 91 | AU31: 48 | AV31: 1.047 | AW31: 1 | AZ31: 1 | BA31: 56.35 | BB31: 1 | BC31: 1 | BH31: 0 | BI31: 1 | BJ31: ТСН-2001.6. Доп. 1-42. Сб. 67, т. 7, поз. 5 | BM31: 106 | BN31: 0 | BO31: 6.67-7-5 | BP31: 1 | BQ31: 60 | BR31: 0 | BS31: 56.35 | BT31: 1 | BU31: 1 | BV31: 1 | BW31: 1 | BX31: 1 | BZ31: 91 | CA31: 48 | CE31: 1566 | CF31: 0 | CG31: 0 | CM31: 0 | CN31: Поправка: Гл.12.Прил.8.п.8. 3_12.00.01.11.001 Наименование: При наличии напряженных и стесненных условий производства работ (стесненность, сложность складирования и транспортной логистики и т.п.) для объектов, расположенных в пределах круговой магистральной системы улиц "Садовое кольцо" города Москвы | CO31: 0 | CP31: =(P31+Q31+S31) -> 165752.96 | CQ31: =ROUND((ROUND((AC31*AW31*1),2)*BC31),2) -> 0 | CR31: =(ROUND((ROUND((((ET31*1.2))*AV31*1),2)*BB31),2)+ROUND((ROUND(((AE31-((EU31*1.2)))*AV31*1),2)*BS31),2)) -> 0 | CS31: =(ROUND((ROUND((((EU31*1.2))*AV31*1),2)*BS31),2)+ROUND((ROUND(((AE31-((EU31*1.2)))*AV31*1),2)*BS31),2)) -> 0 | CT31: =ROUND((ROUND((AF31*AV31*1),2)*BA31),2) -> 13323.96 | CU31: =AG31 -> 0 | CV31: =(AH31*AV31) -> 22.476996 | CW31: =AI31 -> 0 | CX31: =AJ31 -> 0 | CY31: =(ROUND((((S31+ROUND((ROUND((((EU31*1.2))*AV31*1),2)*BS31),2))*AT31)/100),2)+ROUND(((ROUND((ROUND(((AE31-((EU31*1.2)))*AV31*1),2)*BS31),2)*AT31)/100),2)) -> 150835.19 | CZ31: =(ROUND((((S31+ROUND((ROUND((((EU31*1.2))*AV31*1),2)*BS31),2))*AU31)/100),2)+ROUND(((ROUND((ROUND(((AE31-((EU31*1.2)))*AV31*1),2)*BS31),2)*AU31)/100),2)) -> 79561.42 | DB31: 6 | DD31: *1 | DE31: *1,2 | DF31: *1,2 | DG31: *1,2 | DI31: *1,2 | DJ31: *1,2 | DN31: 0 | DO31: 0 | DP31: 1 | DQ31: 1 | DU31: 1010 | DV31: 100 шт. | DW31: 100 шт. | DX31: 100 | EE31: 57042996 | EF31: 60 | EG31: Ремонтно-строительные работы | EH31: 0 | EJ31: 1 | EK31: 106 | EL31: ТСН-2001.6-67. Электромонтажные работы | EM31: ТСН-2001.6-67-1 | EO31: Поправка: Гл.12.Прил.8.п.8. 3_12.00.01.11.001 | EQ31: 0 | ER31: 188.2 | ES31: 0 | ET31: 0 | EU31: 0 | EV31: 188.2 | EW31: 17.89 | EX31: 0 | EY31: 0 | FQ31: 0 | FR31: 0 | FS31: 0 | FX31: 91 | FY31: 48 | GD31: 1 | GF31: -651826134 | GG31: 2 | GH31: 1 | GI31: 2 | GJ31: 0 | GK31: 0 | GL31: =ROUND(IF(AND(BH31=3,BI31=3,FS31<>0),P31,0),2) -> 0 | GM31: =ROUND(O31+X31+Y31,2)+GX31 -> 396149.57 | GN31: =IF(OR(BI31=0,BI31=1),GM31-GX31,0) -> 396149.57 | GO31: =IF(BI31=2,GM31-GX31,0) -> 0 | GP31: =IF(BI31=4,GM31-GX31,0) -> 0 | GR31: 0 | GS31: 3 | GT31: 0 | GV31: =ROUND((GT31),6) -> 0 | GW31: 1 | GX31: =ROUND(HC31*I31,2) -> 0 | HA31: 0 | HB31: 0 | HC31: =GV31*GW31 -> 0 | HS31: 0 | IK31: 0
A32: 17 | B32: 1 | C32: =ROW(SmtRes!A21) -> 21 | D32: =ROW(EtalonRes!A27) -> 27 | F32: 6.67-7-3 | G32: Демонтаж осветительных приборов, светильники с лампами накаливания | H32: 100 шт. | I32: =ROUND(1244/100,9) -> 12.44 | J32: 0 | K32: =ROUND(1244/100,9) -> 12.44 | O32: =ROUND(CP32,2) -> 1009.52 | P32: =ROUND((ROUND((AC32*AW32*I32),2)*BC32),2) -> 0 | Q32: =(ROUND((ROUND((((ET32*1.2))*AV32*I32),2)*BB32),2)+ROUND((ROUND(((AE32-((EU32*1.2)))*AV32*I32),2)*BS32),2)) -> 0 | R32: =(ROUND((ROUND((((EU32*1.2))*AV32*I32),2)*BS32),2)+ROUND((ROUND(((AE32-((EU32*1.2)))*AV32*I32),2)*BS32),2)) -> 0 | S32: =ROUND((ROUND((AF32*AV32*I32),2)*BA32),2) -> 1009.52 | T32: =ROUND(CU32*I32,2) -> 0 | U32: =CV32*I32 -> 98.779173 | V32: =CW32*I32 -> 0 | W32: =ROUND(CX32*I32,2) -> 0 | X32: =(ROUND((((S32+ROUND((ROUND((((EU32*1.2))*AV32*I32),2)*BS32),2))*AT32)/100),2)+ROUND(((ROUND((ROUND(((AE32-((EU32*1.2)))*AV32*I32),2)*BS32),2)*AT32)/100),2)) -> 918.66 | Y32: =(ROUND((((S32+ROUND((ROUND((((EU32*1.2))*AV32*I32),2)*BS32),2))*AU32)/100),2)+ROUND(((ROUND((ROUND(((AE32-((EU32*1.2)))*AV32*I32),2)*BS32),2)*AU32)/100),2)) -> 484.57 | AA32: -1 | AB32: =ROUND((AC32+AD32+AF32),6) -> 77.508 | AC32: =ROUND(((ES32*1)),6) -> 0 | AD32: =ROUND(((((ET32*1.2))-((EU32*1.2)))+AE32),6) -> 0 | AE32: =ROUND(((EU32*1.2)),6) -> 0 | AF32: =ROUND(((EV32*1.2)),6) -> 77.508 | AG32: =ROUND((AP32),6) -> 0 | AH32: =((EW32*1.2)) -> 7.584 | AI32: =((EX32*1.2)) -> 0 | AJ32: =(AS32) -> 0 | AK32: 64.59 | AL32: 0 | AM32: 0 | AN32: 0 | AO32: 64.59 | AP32: 0 | AQ32: 6.32 | AR32: 0 | AS32: 0 | AT32: 91 | AU32: 48 | AV32: 1.047 | AW32: 1 | AZ32: 1 | BA32: 1 | BB32: 1 | BC32: 1 | BH32: 0 | BI32: 1 | BJ32: ТСН-2001.6. Доп. 1-42. Сб. 67, т. 7, поз. 3 | BM32: 106 | BN32: 0 | BO32: 6.67-7-3 | BP32: 1 | BQ32: 60 | BR32: 0 | BS32: 1 | BT32: 1 | BU32: 1 | BV32: 1 | BW32: 1 | BX32: 1 | BZ32: 91 | CA32: 48 | CE32: 1566 | CF32: 0 | CG32: 0 | CM32: 0 | CN32: Поправка: Гл.12.Прил.8.п.8. 3_12.00.01.11.001 Наименование: При наличии напряженных и стесненных условий производства работ (стесненность, сложность складирования и транспортной логистики и т.п.) для объектов, расположенных в пределах круговой магистральной системы улиц "Садовое кольцо" города Москвы | CO32: 0 | CP32: =(P32+Q32+S32) -> 1009.52 | CQ32: =ROUND((ROUND((AC32*AW32*1),2)*BC32),2) -> 0 | CR32: =(ROUND((ROUND((((ET32*1.2))*AV32*1),2)*BB32),2)+ROUND((ROUND(((AE32-((EU32*1.2)))*AV32*1),2)*BS32),2)) -> 0 | CS32: =(ROUND((ROUND((((EU32*1.2))*AV32*1),2)*BS32),2)+ROUND((ROUND(((AE32-((EU32*1.2)))*AV32*1),2)*BS32),2)) -> 0 | CT32: =ROUND((ROUND((AF32*AV32*1),2)*BA32),2) -> 81.15 | CU32: =AG32 -> 0 | CV32: =(AH32*AV32) -> 7.940448 | CW32: =AI32 -> 0 | CX32: =AJ32 -> 0 | CY32: =(ROUND((((S32+ROUND((ROUND((((EU32*1.2))*AV32*1),2)*BS32),2))*AT32)/100),2)+ROUND(((ROUND((ROUND(((AE32-((EU32*1.2)))*AV32*1),2)*BS32),2)*AT32)/100),2)) -> 918.66 | CZ32: =(ROUND((((S32+ROUND((ROUND((((EU32*1.2))*AV32*1),2)*BS32),2))*AU32)/100),2)+ROUND(((ROUND((ROUND(((AE32-((EU32*1.2)))*AV32*1),2)*BS32),2)*AU32)/100),2)) -> 484.57 | DB32: 7 | DD32: *1 | DE32: *1,2 | DF32: *1,2 | DG32: *1,2 | DI32: *1,2 | DJ32: *1,2 | DN32: 0 | DO32: 0 | DP32: 1 | DQ32: 1 | DU32: 1010 | DV32: 100 шт. | DW32: 100 шт. | DX32: 100 | EE32: 57042996 | EF32: 60 | EG32: Ремонтно-строительные работы | EH32: 0 | EJ32: 1 | EK32: 106 | EL32: ТСН-2001.6-67. Электромонтажные работы | EM32: ТСН-2001.6-67-1 | EO32: Поправка: Гл.12.Прил.8.п.8. 3_12.00.01.11.001 | EQ32: 1024 | ER32: 64.59 | ES32: 0 | ET32: 0 | EU32: 0 | EV32: 64.59 | EW32: 6.32 | EX32: 0 | EY32: 0 | FQ32: 0 | FR32: 0 | FS32: 0 | FX32: 91 | FY32: 48 | GD32: 1 | GF32: 1397822307 | GG32: 2 | GH32: 1 | GI32: 2 | GJ32: 0 | GK32: 0 | GL32: =ROUND(IF(AND(BH32=3,BI32=3,FS32<>0),P32,0),2) -> 0 | GM32: =ROUND(O32+X32+Y32,2)+GX32 -> 2412.75 | GN32: =IF(OR(BI32=0,BI32=1),GM32-GX32,0) -> 2412.75 | GO32: =IF(BI32=2,GM32-GX32,0) -> 0 | GP32: =IF(BI32=4,GM32-GX32,0) -> 0 | GR32: 0 | GS32: 3 | GT32: 0 | GV32: =ROUND((GT32),6) -> 0 | GW32: 1 | GX32: =ROUND(HC32*I32,2) -> 0 | HA32: 0 | HB32: 0 | HC32: =GV32*GW32 -> 0 | HS32: 0 | IK32: 0
A33: 17 | B33: 1 | C33: =ROW(SmtRes!A22) -> 22 | D33: =ROW(EtalonRes!A28) -> 28 | F33: 6.67-7-3 | G33: Демонтаж осветительных приборов, светильники с лампами накаливания | H33: 100 шт. | I33: =ROUND(1244/100,9) -> 12.44 | J33: 0 | K33: =ROUND(1244/100,9) -> 12.44 | O33: =ROUND(CP33,2) -> 56886.45 | P33: =ROUND((ROUND((AC33*AW33*I33),2)*BC33),2) -> 0 | Q33: =(ROUND((ROUND((((ET33*1.2))*AV33*I33),2)*BB33),2)+ROUND((ROUND(((AE33-((EU33*1.2)))*AV33*I33),2)*BS33),2)) -> 0 | R33: =(ROUND((ROUND((((EU33*1.2))*AV33*I33),2)*BS33),2)+ROUND((ROUND(((AE33-((EU33*1.2)))*AV33*I33),2)*BS33),2)) -> 0 | S33: =ROUND((ROUND((AF33*AV33*I33),2)*BA33),2) -> 56886.45 | T33: =ROUND(CU33*I33,2) -> 0 | U33: =CV33*I33 -> 98.779173 | V33: =CW33*I33 -> 0 | W33: =ROUND(CX33*I33,2) -> 0 | X33: =(ROUND((((S33+ROUND((ROUND((((EU33*1.2))*AV33*I33),2)*BS33),2))*AT33)/100),2)+ROUND(((ROUND((ROUND(((AE33-((EU33*1.2)))*AV33*I33),2)*BS33),2)*AT33)/100),2)) -> 51766.67 | Y33: =(ROUND((((S33+ROUND((ROUND((((EU33*1.2))*AV33*I33),2)*BS33),2))*AU33)/100),2)+ROUND(((ROUND((ROUND(((AE33-((EU33*1.2)))*AV33*I33),2)*BS33),2)*AU33)/100),2)) -> 27305.5 | AA33: -1 | AB33: =ROUND((AC33+AD33+AF33),6) -> 77.508 | AC33: =ROUND(((ES33*1)),6) -> 0 | AD33: =ROUND(((((ET33*1.2))-((EU33*1.2)))+AE33),6) -> 0 | AE33: =ROUND(((EU33*1.2)),6) -> 0 | AF33: =ROUND(((EV33*1.2)),6) -> 77.508 | AG33: =ROUND((AP33),6) -> 0 | AH33: =((EW33*1.2)) -> 7.584 | AI33: =((EX33*1.2)) -> 0 | AJ33: =(AS33) -> 0 | AK33: 64.59 | AL33: 0 | AM33: 0 | AN33: 0 | AO33: 64.59 | AP33: 0 | AQ33: 6.32 | AR33: 0 | AS33: 0 | AT33: 91 | AU33: 48 | AV33: 1.047 | AW33: 1 | AZ33: 1 | BA33: 56.35 | BB33: 1 | BC33: 1 | BH33: 0 | BI33: 1 | BJ33: ТСН-2001.6. Доп. 1-42. Сб. 67, т. 7, поз. 3 | BM33: 106 | BN33: 0 | BO33: 6.67-7-3 | BP33: 1 | BQ33: 60 | BR33: 0 | BS33: 56.35 | BT33: 1 | BU33: 1 | BV33: 1 | BW33: 1 | BX33: 1 | BZ33: 91 | CA33: 48 | CE33: 1566 | CF33: 0 | CG33: 0 | CM33: 0 | CN33: Поправка: Гл.12.Прил.8.п.8. 3_12.00.01.11.001 Наименование: При наличии напряженных и стесненных условий производства работ (стесненность, сложность складирования и транспортной логистики и т.п.) для объектов, расположенных в пределах круговой магистральной системы улиц "Садовое кольцо" города Москвы | CO33: 0 | CP33: =(P33+Q33+S33) -> 56886.45 | CQ33: =ROUND((ROUND((AC33*AW33*1),2)*BC33),2) -> 0 | CR33: =(ROUND((ROUND((((ET33*1.2))*AV33*1),2)*BB33),2)+ROUND((ROUND(((AE33-((EU33*1.2)))*AV33*1),2)*BS33),2)) -> 0 | CS33: =(ROUND((ROUND((((EU33*1.2))*AV33*1),2)*BS33),2)+ROUND((ROUND(((AE33-((EU33*1.2)))*AV33*1),2)*BS33),2)) -> 0 | CT33: =ROUND((ROUND((AF33*AV33*1),2)*BA33),2) -> 4572.8 | CU33: =AG33 -> 0 | CV33: =(AH33*AV33) -> 7.940448 | CW33: =AI33 -> 0 | CX33: =AJ33 -> 0 | CY33: =(ROUND((((S33+ROUND((ROUND((((EU33*1.2))*AV33*1),2)*BS33),2))*AT33)/100),2)+ROUND(((ROUND((ROUND(((AE33-((EU33*1.2)))*AV33*1),2)*BS33),2)*AT33)/100),2)) -> 51766.67 | CZ33: =(ROUND((((S33+ROUND((ROUND((((EU33*1.2))*AV33*1),2)*BS33),2))*AU33)/100),2)+ROUND(((ROUND((ROUND(((AE33-((EU33*1.2)))*AV33*1),2)*BS33),2)*AU33)/100),2)) -> 27305.5 | DB33: 8 | DD33: *1 | DE33: *1,2 | DF33: *1,2 | DG33: *1,2 | DI33: *1,2 | DJ33: *1,2 | DN33: 0 | DO33: 0 | DP33: 1 | DQ33: 1 | DU33: 1010 | DV33: 100 шт. | DW33: 100 шт. | DX33: 100 | EE33: 57042996 | EF33: 60 | EG33: Ремонтно-строительные работы | EH33: 0 | EJ33: 1 | EK33: 106 | EL33: ТСН-2001.6-67. Электромонтажные работы | EM33: ТСН-2001.6-67-1 | EO33: Поправка: Гл.12.Прил.8.п.8. 3_12.00.01.11.001 | EQ33: 1024 | ER33: 64.59 | ES33: 0 | ET33: 0 | EU33: 0 | EV33: 64.59 | EW33: 6.32 | EX33: 0 | EY33: 0 | FQ33: 0 | FR33: 0 | FS33: 0 | FX33: 91 | FY33: 48 | GD33: 1 | GF33: 1397822307 | GG33: 2 | GH33: 1 | GI33: 2 | GJ33: 0 | GK33: 0 | GL33: =ROUND(IF(AND(BH33=3,BI33=3,FS33<>0),P33,0),2) -> 0 | GM33: =ROUND(O33+X33+Y33,2)+GX33 -> 135958.62 | GN33: =IF(OR(BI33=0,BI33=1),GM33-GX33,0) -> 135958.62 | GO33: =IF(BI33=2,GM33-GX33,0) -> 0 | GP33: =IF(BI33=4,GM33-GX33,0) -> 0 | GR33: 0 | GS33: 3 | GT33: 0 | GV33: =ROUND((GT33),6) -> 0 | GW33: 1 | GX33: =ROUND(HC33*I33,2) -> 0 | HA33: 0 | HB33: 0 | HC33: =GV33*GW33 -> 0 | HS33: 0 | IK33: 0
A34: 17 | B34: 1 | C34: =ROW(SmtRes!A23) -> 23 | D34: =ROW(EtalonRes!A29) -> 29 | E34: 3 | F34: 6.67-7-1 | G34: Демонтаж осветительных приборов, выключатели, розетки | H34: 100 шт. | I34: =ROUND(972/100,9) -> 9.72 | J34: 0 | K34: =ROUND(972/100,9) -> 9.72 | O34: =ROUND(CP34,2) -> 728.82 | P34: =ROUND((ROUND((AC34*AW34*I34),2)*BC34),2) -> 0 | Q34: =(ROUND((ROUND((((ET34*1.2))*AV34*I34),2)*BB34),2)+ROUND((ROUND(((AE34-((EU34*1.2)))*AV34*I34),2)*BS34),2)) -> 0 | R34: =(ROUND((ROUND((((EU34*1.2))*AV34*I34),2)*BS34),2)+ROUND((ROUND(((AE34-((EU34*1.2)))*AV34*I34),2)*BS34),2)) -> 0 | S34: =ROUND((ROUND((AF34*AV34*I34),2)*BA34),2) -> 728.82 | T34: =ROUND(CU34*I34,2) -> 0 | U34: =CV34*I34 -> 71.319295 | V34: =CW34*I34 -> 0 | W34: =ROUND(CX34*I34,2) -> 0 | X34: =(ROUND((((S34+ROUND((ROUND((((EU34*1.2))*AV34*I34),2)*BS34),2))*AT34)/100),2)+ROUND(((ROUND((ROUND(((AE34-((EU34*1.2)))*AV34*I34),2)*BS34),2)*AT34)/100),2)) -> 663.23 | Y34: =(ROUND((((S34+ROUND((ROUND((((EU34*1.2))*AV34*I34),2)*BS34),2))*AU34)/100),2)+ROUND(((ROUND((ROUND(((AE34-((EU34*1.2)))*AV34*I34),2)*BS34),2)*AU34)/100),2)) -> 349.83 | AA34: 54971259 | AB34: =ROUND((AC34+AD34+AF34),6) -> 71.616 | AC34: =ROUND(((ES34*1)),6) -> 0 | AD34: =ROUND(((((ET34*1.2))-((EU34*1.2)))+AE34),6) -> 0 | AE34: =ROUND(((EU34*1.2)),6) -> 0 | AF34: =ROUND(((EV34*1.2)),6) -> 71.616 | AG34: =ROUND((AP34),6) -> 0 | AH34: =((EW34*1.2)) -> 7.008 | AI34: =((EX34*1.2)) -> 0 | AJ34: =(AS34) -> 0 | AK34: 59.68 | AL34: 0 | AM34: 0 | AN34: 0 | AO34: 59.68 | AP34: 0 | AQ34: 5.84 | AR34: 0 | AS34: 0 | AT34: 91 | AU34: 48 | AV34: 1.047 | AW34: 1 | AZ34: 1 | BA34: 1 | BB34: 1 | BC34: 1 | BH34: 0 | BI34: 1 | BJ34: ТСН-2001.6. Доп. 1-42. Сб. 67, т. 7, поз. 1 | BM34: 106 | BN34: 0 | BO34: 6.67-7-1 | BP34: 1 | BQ34: 60 | BR34: 0 | BS34: 1 | BT34: 1 | BU34: 1 | BV34: 1 | BW34: 1 | BX34: 1 | BZ34: 91 | CA34: 48 | CE34: 1566 | CF34: 0 | CG34: 0 | CM34: 0 | CN34: Поправка: Гл.12.Прил.8.п.8. 3_12.00.01.11.001 Наименование: При наличии напряженных и стесненных условий производства работ (стесненность, сложность складирования и транспортной логистики и т.п.) для объектов, расположенных в пределах круговой магистральной системы улиц "Садовое кольцо" города Москвы | CO34: 0 | CP34: =(P34+Q34+S34) -> 728.82 | CQ34: =ROUND((ROUND((AC34*AW34*1),2)*BC34),2) -> 0 | CR34: =(ROUND((ROUND((((ET34*1.2))*AV34*1),2)*BB34),2)+ROUND((ROUND(((AE34-((EU34*1.2)))*AV34*1),2)*BS34),2)) -> 0 | CS34: =(ROUND((ROUND((((EU34*1.2))*AV34*1),2)*BS34),2)+ROUND((ROUND(((AE34-((EU34*1.2)))*AV34*1),2)*BS34),2)) -> 0 | CT34: =ROUND((ROUND((AF34*AV34*1),2)*BA34),2) -> 74.98 | CU34: =AG34 -> 0 | CV34: =(AH34*AV34) -> 7.337376 | CW34: =AI34 -> 0 | CX34: =AJ34 -> 0 | CY34: =(ROUND((((S34+ROUND((ROUND((((EU34*1.2))*AV34*1),2)*BS34),2))*AT34)/100),2)+ROUND(((ROUND((ROUND(((AE34-((EU34*1.2)))*AV34*1),2)*BS34),2)*AT34)/100),2)) -> 663.23 | CZ34: =(ROUND((((S34+ROUND((ROUND((((EU34*1.2))*AV34*1),2)*BS34),2))*AU34)/100),2)+ROUND(((ROUND((ROUND(((AE34-((EU34*1.2)))*AV34*1),2)*BS34),2)*AU34)/100),2)) -> 349.83 | DB34: 9 | DD34: *1 | DE34: *1,2 | DF34: *1,2 | DG34: *1,2 | DI34: *1,2 | DJ34: *1,2 | DN34: 0 | DO34: 0 | DP34: 1 | DQ34: 1 | DU34: 1010 | DV34: 100 шт. | DW34: 100 шт. | DX34: 100 | EE34: 57042996 | EF34: 60 | EG34: Ремонтно-строительные работы | EH34: 0 | EJ34: 1 | EK34: 106 | EL34: ТСН-2001.6-67. Электромонтажные работы | EM34: ТСН-2001.6-67-1 | EO34: Поправка: Гл.12.Прил.8.п.8. 3_12.00.01.11.001 | EQ34: 0 | ER34: 59.68 | ES34: 0 | ET34: 0 | EU34: 0 | EV34: 59.68 | EW34: 5.84 | EX34: 0 | EY34: 0 | FQ34: 0 | FR34: 0 | FS34: 0 | FX34: 91 | FY34: 48 | GD34: 1 | GF34: 1478850760 | GG34: 2 | GH34: 1 | GI34: 2 | GJ34: 0 | GK34: 0 | GL34: =ROUND(IF(AND(BH34=3,BI34=3,FS34<>0),P34,0),2) -> 0 | GM34: =ROUND(O34+X34+Y34,2)+GX34 -> 1741.88 | GN34: =IF(OR(BI34=0,BI34=1),GM34-GX34,0) -> 1741.88 | GO34: =IF(BI34=2,GM34-GX34,0) -> 0 | GP34: =IF(BI34=4,GM34-GX34,0) -> 0 | GR34: 0 | GS34: 3 | GT34: 0 | GV34: =ROUND((GT34),6) -> 0 | GW34: 1 | GX34: =ROUND(HC34*I34,2) -> 0 | HA34: 0 | HB34: 0 | HC34: =GV34*GW34 -> 0 | HS34: 0 | IK34: 0
A35: 17 | B35: 1 | C35: =ROW(SmtRes!A24) -> 24 | D35: =ROW(EtalonRes!A30) -> 30 | E35: 3 | F35: 6.67-7-1 | G35: Демонтаж осветительных приборов, выключатели, розетки | H35: 100 шт. | I35: =ROUND(972/100,9) -> 9.72 | J35: 0 | K35: =ROUND(972/100,9) -> 9.72 | O35: =ROUND(CP35,2) -> 41069.01 | P35: =ROUND((ROUND((AC35*AW35*I35),2)*BC35),2) -> 0 | Q35: =(ROUND((ROUND((((ET35*1.2))*AV35*I35),2)*BB35),2)+ROUND((ROUND(((AE35-((EU35*1.2)))*AV35*I35),2)*BS35),2)) -> 0 | R35: =(ROUND((ROUND((((EU35*1.2))*AV35*I35),2)*BS35),2)+ROUND((ROUND(((AE35-((EU35*1.2)))*AV35*I35),2)*BS35),2)) -> 0 | S35: =ROUND((ROUND((AF35*AV35*I35),2)*BA35),2) -> 41069.01 | T35: =ROUND(CU35*I35,2) -> 0 | U35: =CV35*I35 -> 71.319295 | V35: =CW35*I35 -> 0 | W35: =ROUND(CX35*I35,2) -> 0 | X35: =(ROUND((((S35+ROUND((ROUND((((EU35*1.2))*AV35*I35),2)*BS35),2))*AT35)/100),2)+ROUND(((ROUND((ROUND(((AE35-((EU35*1.2)))*AV35*I35),2)*BS35),2)*AT35)/100),2)) -> 37372.8 | Y35: =(ROUND((((S35+ROUND((ROUND((((EU35*1.2))*AV35*I35),2)*BS35),2))*AU35)/100),2)+ROUND(((ROUND((ROUND(((AE35-((EU35*1.2)))*AV35*I35),2)*BS35),2)*AU35)/100),2)) -> 19713.12 | AA35: 55890823 | AB35: =ROUND((AC35+AD35+AF35),6) -> 71.616 | AC35: =ROUND(((ES35*1)),6) -> 0 | AD35: =ROUND(((((ET35*1.2))-((EU35*1.2)))+AE35),6) -> 0 | AE35: =ROUND(((EU35*1.2)),6) -> 0 | AF35: =ROUND(((EV35*1.2)),6) -> 71.616 | AG35: =ROUND((AP35),6) -> 0 | AH35: =((EW35*1.2)) -> 7.008 | AI35: =((EX35*1.2)) -> 0 | AJ35: =(AS35) -> 0 | AK35: 59.68 | AL35: 0 | AM35: 0 | AN35: 0 | AO35: 59.68 | AP35: 0 | AQ35: 5.84 | AR35: 0 | AS35: 0 | AT35: 91 | AU35: 48 | AV35: 1.047 | AW35: 1 | AZ35: 1 | BA35: 56.35 | BB35: 1 | BC35: 1 | BH35: 0 | BI35: 1 | BJ35: ТСН-2001.6. Доп. 1-42. Сб. 67, т. 7, поз. 1 | BM35: 106 | BN35: 0 | BO35: 6.67-7-1 | BP35: 1 | BQ35: 60 | BR35: 0 | BS35: 56.35 | BT35: 1 | BU35: 1 | BV35: 1 | BW35: 1 | BX35: 1 | BZ35: 91 | CA35: 48 | CE35: 1566 | CF35: 0 | CG35: 0 | CM35: 0 | CN35: Поправка: Гл.12.Прил.8.п.8. 3_12.00.01.11.001 Наименование: При наличии напряженных и стесненных условий производства работ (стесненность, сложность складирования и транспортной логистики и т.п.) для объектов, расположенных в пределах круговой магистральной системы улиц "Садовое кольцо" города Москвы | CO35: 0 | CP35: =(P35+Q35+S35) -> 41069.01 | CQ35: =ROUND((ROUND((AC35*AW35*1),2)*BC35),2) -> 0 | CR35: =(ROUND((ROUND((((ET35*1.2))*AV35*1),2)*BB35),2)+ROUND((ROUND(((AE35-((EU35*1.2)))*AV35*1),2)*BS35),2)) -> 0 | CS35: =(ROUND((ROUND((((EU35*1.2))*AV35*1),2)*BS35),2)+ROUND((ROUND(((AE35-((EU35*1.2)))*AV35*1),2)*BS35),2)) -> 0 | CT35: =ROUND((ROUND((AF35*AV35*1),2)*BA35),2) -> 4225.12 | CU35: =AG35 -> 0 | CV35: =(AH35*AV35) -> 7.337376 | CW35: =AI35 -> 0 | CX35: =AJ35 -> 0 | CY35: =(ROUND((((S35+ROUND((ROUND((((EU35*1.2))*AV35*1),2)*BS35),2))*AT35)/100),2)+ROUND(((ROUND((ROUND(((AE35-((EU35*1.2)))*AV35*1),2)*BS35),2)*AT35)/100),2)) -> 37372.8 | CZ35: =(ROUND((((S35+ROUND((ROUND((((EU35*1.2))*AV35*1),2)*BS35),2))*AU35)/100),2)+ROUND(((ROUND((ROUND(((AE35-((EU35*1.2)))*AV35*1),2)*BS35),2)*AU35)/100),2)) -> 19713.12 | DB35: 10 | DD35: *1 | DE35: *1,2 | DF35: *1,2 | DG35: *1,2 | DI35: *1,2 | DJ35: *1,2 | DN35: 0 | DO35: 0 | DP35: 1 | DQ35: 1 | DU35: 1010 | DV35: 100 шт. | DW35: 100 шт. | DX35: 100 | EE35: 57042996 | EF35: 60 | EG35: Ремонтно-строительные работы | EH35: 0 | EJ35: 1 | EK35: 106 | EL35: ТСН-2001.6-67. Электромонтажные работы | EM35: ТСН-2001.6-67-1 | EO35: Поправка: Гл.12.Прил.8.п.8. 3_12.00.01.11.001 | EQ35: 0 | ER35: 59.68 | ES35: 0 | ET35: 0 | EU35: 0 | EV35: 59.68 | EW35: 5.84 | EX35: 0 | EY35: 0 | FQ35: 0 | FR35: 0 | FS35: 0 | FX35: 91 | FY35: 48 | GD35: 1 | GF35: 1478850760 | GG35: 2 | GH35: 1 | GI35: 2 | GJ35: 0 | GK35: 0 | GL35: =ROUND(IF(AND(BH35=3,BI35=3,FS35<>0),P35,0),2) -> 0 | GM35: =ROUND(O35+X35+Y35,2)+GX35 -> 98154.93 | GN35: =IF(OR(BI35=0,BI35=1),GM35-GX35,0) -> 98154.93 | GO35: =IF(BI35=2,GM35-GX35,0) -> 0 | GP35: =IF(BI35=4,GM35-GX35,0) -> 0 | GR35: 0 | GS35: 3 | GT35: 0 | GV35: =ROUND((GT35),6) -> 0 | GW35: 1 | GX35: =ROUND(HC35*I35,2) -> 0 | HA35: 0 | HB35: 0 | HC35: =GV35*GW35 -> 0 | HS35: 0 | IK35: 0
A36: 17 | B36: 1 | C36: =ROW(SmtRes!A25) -> 25 | D36: =ROW(EtalonRes!A31) -> 31 | E36: 4 | F36: 6.67-6-1 | G36: Демонтаж кабеля | H36: 100 м | I36: =ROUND(30359/100,9) -> 303.59 | J36: 0 | K36: =ROUND(30359/100,9) -> 303.59 | O36: =ROUND(CP36,2) -> 37578.53 | P36: =ROUND((ROUND((AC36*AW36*I36),2)*BC36),2) -> 0 | Q36: =(ROUND((ROUND((((ET36*1.2))*AV36*I36),2)*BB36),2)+ROUND((ROUND(((AE36-((EU36*1.2)))*AV36*I36),2)*BS36),2)) -> 0 | R36: =(ROUND((ROUND((((EU36*1.2))*AV36*I36),2)*BS36),2)+ROUND((ROUND(((AE36-((EU36*1.2)))*AV36*I36),2)*BS36),2)) -> 0 | S36: =ROUND((ROUND((AF36*AV36*I36),2)*BA36),2) -> 37578.53 | T36: =ROUND(CU36*I36,2) -> 0 | U36: =CV36*I36 -> 3676.9898 | V36: =CW36*I36 -> 0 | W36: =ROUND(CX36*I36,2) -> 0 | X36: =(ROUND((((S36+ROUND((ROUND((((EU36*1.2))*AV36*I36),2)*BS36),2))*AT36)/100),2)+ROUND(((ROUND((ROUND(((AE36-((EU36*1.2)))*AV36*I36),2)*BS36),2)*AT36)/100),2)) -> 34196.46 | Y36: =(ROUND((((S36+ROUND((ROUND((((EU36*1.2))*AV36*I36),2)*BS36),2))*AU36)/100),2)+ROUND(((ROUND((ROUND(((AE36-((EU36*1.2)))*AV36*I36),2)*BS36),2)*AU36)/100),2)) -> 18037.69 | AA36: 54971259 | AB36: =ROUND((AC36+AD36+AF36),6) -> 118.224 | AC36: =ROUND(((ES36*1)),6) -> 0 | AD36: =ROUND(((((ET36*1.2))-((EU36*1.2)))+AE36),6) -> 0 | AE36: =ROUND(((EU36*1.2)),6) -> 0 | AF36: =ROUND(((EV36*1.2)),6) -> 118.224 | AG36: =ROUND((AP36),6) -> 0 | AH36: =((EW36*1.2)) -> 11.568 | AI36: =((EX36*1.2)) -> 0 | AJ36: =(AS36) -> 0 | AK36: 98.52 | AL36: 0 | AM36: 0 | AN36: 0 | AO36: 98.52 | AP36: 0 | AQ36: 9.64 | AR36: 0 | AS36: 0 | AT36: 91 | AU36: 48 | AV36: 1.047 | AW36: 1 | AZ36: 1 | BA36: 1 | BB36: 1 | BC36: 1 | BH36: 0 | BI36: 1 | BJ36: ТСН-2001.6. Доп. 1-42. Сб. 67, т. 6, поз. 1 | BM36: 106 | BN36: 0 | BO36: 6.67-6-1 | BP36: 1 | BQ36: 60 | BR36: 0 | BS36: 1 | BT36: 1 | BU36: 1 | BV36: 1 | BW36: 1 | BX36: 1 | BZ36: 91 | CA36: 48 | CE36: 1566 | CF36: 0 | CG36: 0 | CM36: 0 | CN36: Поправка: Гл.12.Прил.8.п.8. 3_12.00.01.11.001 Наименование: При наличии напряженных и стесненных условий производства работ (стесненность, сложность складирования и транспортной логистики и т.п.) для объектов, расположенных в пределах круговой магистральной системы улиц "Садовое кольцо" города Москвы | CO36: 0 | CP36: =(P36+Q36+S36) -> 37578.53 | CQ36: =ROUND((ROUND((AC36*AW36*1),2)*BC36),2) -> 0 | CR36: =(ROUND((ROUND((((ET36*1.2))*AV36*1),2)*BB36),2)+ROUND((ROUND(((AE36-((EU36*1.2)))*AV36*1),2)*BS36),2)) -> 0 | CS36: =(ROUND((ROUND((((EU36*1.2))*AV36*1),2)*BS36),2)+ROUND((ROUND(((AE36-((EU36*1.2)))*AV36*1),2)*BS36),2)) -> 0 | CT36: =ROUND((ROUND((AF36*AV36*1),2)*BA36),2) -> 123.78 | CU36: =AG36 -> 0 | CV36: =(AH36*AV36) -> 12.111696 | CW36: =AI36 -> 0 | CX36: =AJ36 -> 0 | CY36: =(ROUND((((S36+ROUND((ROUND((((EU36*1.2))*AV36*1),2)*BS36),2))*AT36)/100),2)+ROUND(((ROUND((ROUND(((AE36-((EU36*1.2)))*AV36*1),2)*BS36),2)*AT36)/100),2)) -> 34196.46 | CZ36: =(ROUND((((S36+ROUND((ROUND((((EU36*1.2))*AV36*1),2)*BS36),2))*AU36)/100),2)+ROUND(((ROUND((ROUND(((AE36-((EU36*1.2)))*AV36*1),2)*BS36),2)*AU36)/100),2)) -> 18037.69 | DB36: 11 | DD36: *1 | DE36: *1,2 | DF36: *1,2 | DG36: *1,2 | DI36: *1,2 | DJ36: *1,2 | DN36: 0 | DO36: 0 | DP36: 1 | DQ36: 1 | DU36: 1003 | DV36: 100 м | DW36: 100 м | DX36: 100 | EE36: 57042996 | EF36: 60 | EG36: Ремонтно-строительные работы | EH36: 0 | EJ36: 1 | EK36: 106 | EL36: ТСН-2001.6-67. Электромонтажные работы | EM36: ТСН-2001.6-67-1 | EO36: Поправка: Гл.12.Прил.8.п.8. 3_12.00.01.11.001 | EQ36: 0 | ER36: 98.52 | ES36: 0 | ET36: 0 | EU36: 0 | EV36: 98.52 | EW36: 9.64 | EX36: 0 | EY36: 0 | FQ36: 0 | FR36: 0 | FS36: 0 | FX36: 91 | FY36: 48 | GD36: 1 | GF36: 1114236003 | GG36: 2 | GH36: 1 | GI36: 2 | GJ36: 0 | GK36: 0 | GL36: =ROUND(IF(AND(BH36=3,BI36=3,FS36<>0),P36,0),2) -> 0 | GM36: =ROUND(O36+X36+Y36,2)+GX36 -> 89812.68 | GN36: =IF(OR(BI36=0,BI36=1),GM36-GX36,0) -> 89812.68 | GO36: =IF(BI36=2,GM36-GX36,0) -> 0 | GP36: =IF(BI36=4,GM36-GX36,0) -> 0 | GR36: 0 | GS36: 3 | GT36: 0 | GV36: =ROUND((GT36),6) -> 0 | GW36: 1 | GX36: =ROUND(HC36*I36,2) -> 0 | HA36: 0 | HB36: 0 | HC36: =GV36*GW36 -> 0 | HS36: 0 | IK36: 0
A37: 17 | B37: 1 | C37: =ROW(SmtRes!A26) -> 26 | D37: =ROW(EtalonRes!A32) -> 32 | E37: 4 | F37: 6.67-6-1 | G37: Демонтаж кабеля | H37: 100 м | I37: =ROUND(30359/100,9) -> 303.59 | J37: 0 | K37: =ROUND(30359/100,9) -> 303.59 | O37: =ROUND(CP37,2) -> 2117550.2 | P37: =ROUND((ROUND((AC37*AW37*I37),2)*BC37),2) -> 0 | Q37: =(ROUND((ROUND((((ET37*1.2))*AV37*I37),2)*BB37),2)+ROUND((ROUND(((AE37-((EU37*1.2)))*AV37*I37),2)*BS37),2)) -> 0 | R37: =(ROUND((ROUND((((EU37*1.2))*AV37*I37),2)*BS37),2)+ROUND((ROUND(((AE37-((EU37*1.2)))*AV37*I37),2)*BS37),2)) -> 0 | S37: =ROUND((ROUND((AF37*AV37*I37),2)*BA37),2) -> 2117550.2 | T37: =ROUND(CU37*I37,2) -> 0 | U37: =CV37*I37 -> 3676.9898 | V37: =CW37*I37 -> 0 | W37: =ROUND(CX37*I37,2) -> 0 | X37: =(ROUND((((S37+ROUND((ROUND((((EU37*1.2))*AV37*I37),2)*BS37),2))*AT37)/100),2)+ROUND(((ROUND((ROUND(((AE37-((EU37*1.2)))*AV37*I37),2)*BS37),2)*AT37)/100),2)) -> 1926970.6 | Y37: =(ROUND((((S37+ROUND((ROUND((((EU37*1.2))*AV37*I37),2)*BS37),2))*AU37)/100),2)+ROUND(((ROUND((ROUND(((AE37-((EU37*1.2)))*AV37*I37),2)*BS37),2)*AU37)/100),2)) -> 1016424.1 | AA37: 55890823 | AB37: =ROUND((AC37+AD37+AF37),6) -> 118.224 | AC37: =ROUND(((ES37*1)),6) -> 0 | AD37: =ROUND(((((ET37*1.2))-((EU37*1.2)))+AE37),6) -> 0 | AE37: =ROUND(((EU37*1.2)),6) -> 0 | AF37: =ROUND(((EV37*1.2)),6) -> 118.224 | AG37: =ROUND((AP37),6) -> 0 | AH37: =((EW37*1.2)) -> 11.568 | AI37: =((EX37*1.2)) -> 0 | AJ37: =(AS37) -> 0 | AK37: 98.52 | AL37: 0 | AM37: 0 | AN37: 0 | AO37: 98.52 | AP37: 0 | AQ37: 9.64 | AR37: 0 | AS37: 0 | AT37: 91 | AU37: 48 | AV37: 1.047 | AW37: 1 | AZ37: 1 | BA37: 56.35 | BB37: 1 | BC37: 1 | BH37: 0 | BI37: 1 | BJ37: ТСН-2001.6. Доп. 1-42. Сб. 67, т. 6, поз. 1 | BM37: 106 | BN37: 0 | BO37: 6.67-6-1 | BP37: 1 | BQ37: 60 | BR37: 0 | BS37: 56.35 | BT37: 1 | BU37: 1 | BV37: 1 | BW37: 1 | BX37: 1 | BZ37: 91 | CA37: 48 | CE37: 1566 | CF37: 0 | CG37: 0 | CM37: 0 | CN37: Поправка: Гл.12.Прил.8.п.8. 3_12.00.01.11.001 Наименование: При наличии напряженных и стесненных условий производства работ (стесненность, сложность складирования и транспортной логистики и т.п.) для объектов, расположенных в пределах круговой магистральной системы улиц "Садовое кольцо" города Москвы | CO37: 0 | CP37: =(P37+Q37+S37) -> 2117550.2 | CQ37: =ROUND((ROUND((AC37*AW37*1),2)*BC37),2) -> 0 | CR37: =(ROUND((ROUND((((ET37*1.2))*AV37*1),2)*BB37),2)+ROUND((ROUND(((AE37-((EU37*1.2)))*AV37*1),2)*BS37),2)) -> 0 | CS37: =(ROUND((ROUND((((EU37*1.2))*AV37*1),2)*BS37),2)+ROUND((ROUND(((AE37-((EU37*1.2)))*AV37*1),2)*BS37),2)) -> 0 | CT37: =ROUND((ROUND((AF37*AV37*1),2)*BA37),2) -> 6975 | CU37: =AG37 -> 0 | CV37: =(AH37*AV37) -> 12.111696 | CW37: =AI37 -> 0 | CX37: =AJ37 -> 0 | CY37: =(ROUND((((S37+ROUND((ROUND((((EU37*1.2))*AV37*1),2)*BS37),2))*AT37)/100),2)+ROUND(((ROUND((ROUND(((AE37-((EU37*1.2)))*AV37*1),2)*BS37),2)*AT37)/100),2)) -> 1926970.6 | CZ37: =(ROUND((((S37+ROUND((ROUND((((EU37*1.2))*AV37*1),2)*BS37),2))*AU37)/100),2)+ROUND(((ROUND((ROUND(((AE37-((EU37*1.2)))*AV37*1),2)*BS37),2)*AU37)/100),2)) -> 1016424.1 | DB37: 12 | DD37: *1 | DE37: *1,2 | DF37: *1,2 | DG37: *1,2 | DI37: *1,2 | DJ37: *1,2 | DN37: 0 | DO37: 0 | DP37: 1 | DQ37: 1 | DU37: 1003 | DV37: 100 м | DW37: 100 м | DX37: 100 | EE37: 57042996 | EF37: 60 | EG37: Ремонтно-строительные работы | EH37: 0 | EJ37: 1 | EK37: 106 | EL37: ТСН-2001.6-67. Электромонтажные работы | EM37: ТСН-2001.6-67-1 | EO37: Поправка: Гл.12.Прил.8.п.8. 3_12.00.01.11.001 | EQ37: 0 | ER37: 98.52 | ES37: 0 | ET37: 0 | EU37: 0 | EV37: 98.52 | EW37: 9.64 | EX37: 0 | EY37: 0 | FQ37: 0 | FR37: 0 | FS37: 0 | FX37: 91 | FY37: 48 | GD37: 1 | GF37: 1114236003 | GG37: 2 | GH37: 1 | GI37: 2 | GJ37: 0 | GK37: 0 | GL37: =ROUND(IF(AND(BH37=3,BI37=3,FS37<>0),P37,0),2) -> 0 | GM37: =ROUND(O37+X37+Y37,2)+GX37 -> 5060944.9 | GN37: =IF(OR(BI37=0,BI37=1),GM37-GX37,0) -> 5060944.9 | GO37: =IF(BI37=2,GM37-GX37,0) -> 0 | GP37: =IF(BI37=4,GM37-GX37,0) -> 0 | GR37: 0 | GS37: 3 | GT37: 0 | GV37: =ROUND((GT37),6) -> 0 | GW37: 1 | GX37: =ROUND(HC37*I37,2) -> 0 | HA37: 0 | HB37: 0 | HC37: =GV37*GW37 -> 0 | HS37: 0 | IK37: 0
A38: 17 | B38: 1 | C38: =ROW(SmtRes!A28) -> 28 | D38: =ROW(EtalonRes!A34) -> 34 | E38: 5 | F38: 6.67-5-13 | G38: Демонтаж трубных проводок, трубы в борозде диаметром 40 мм / стальных | H38: 100 м | I38: =ROUND((550)/100,9) -> 5.5 | J38: 0 | K38: =ROUND((550)/100,9) -> 5.5 | O38: =ROUND(CP38,2) -> 3791.97 | P38: =ROUND((ROUND((AC38*AW38*I38),2)*BC38),2) -> 0 | Q38: =(ROUND((ROUND((((ET38*1.2))*AV38*I38),2)*BB38),2)+ROUND((ROUND(((AE38-((EU38*1.2)))*AV38*I38),2)*BS38),2)) -> 0 | R38: =(ROUND((ROUND((((EU38*1.2))*AV38*I38),2)*BS38),2)+ROUND((ROUND(((AE38-((EU38*1.2)))*AV38*I38),2)*BS38),2)) -> 0 | S38: =ROUND((ROUND((AF38*AV38*I38),2)*BA38),2) -> 3791.97 | T38: =ROUND(CU38*I38,2) -> 0 | U38: =CV38*I38 -> 348.20498 | V38: =CW38*I38 -> 0 | W38: =ROUND(CX38*I38,2) -> 0 | X38: =(ROUND((((S38+ROUND((ROUND((((EU38*1.2))*AV38*I38),2)*BS38),2))*AT38)/100),2)+ROUND(((ROUND((ROUND(((AE38-((EU38*1.2)))*AV38*I38),2)*BS38),2)*AT38)/100),2)) -> 3450.69 | Y38: =(ROUND((((S38+ROUND((ROUND((((EU38*1.2))*AV38*I38),2)*BS38),2))*AU38)/100),2)+ROUND(((ROUND((ROUND(((AE38-((EU38*1.2)))*AV38*I38),2)*BS38),2)*AU38)/100),2)) -> 1820.15 | AA38: 54971259 | AB38: =ROUND((AC38+AD38+AF38),6) -> 658.5 | AC38: =ROUND(((ES38*1)),6) -> 0 | AD38: =ROUND(((((ET38*1.2))-((EU38*1.2)))+AE38),6) -> 0 | AE38: =ROUND(((EU38*1.2)),6) -> 0 | AF38: =ROUND(((EV38*1.2)),6) -> 658.5 | AG38: =ROUND((AP38),6) -> 0 | AH38: =((EW38*1.2)) -> 60.468 | AI38: =((EX38*1.2)) -> 0 | AJ38: =(AS38) -> 0 | AK38: 548.75 | AL38: 0 | AM38: 0 | AN38: 0 | AO38: 548.75 | AP38: 0 | AQ38: 50.39 | AR38: 0 | AS38: 0 | AT38: 91 | AU38: 48 | AV38: 1.047 | AW38: 1 | AZ38: 1 | BA38: 1 | BB38: 1 | BC38: 1 | BH38: 0 | BI38: 1 | BJ38: ТСН-2001.6. Доп. 1-42. Сб. 67, т. 5, поз. 13 | BM38: 106 | BN38: 0 | BO38: 6.67-5-13 | BP38: 1 | BQ38: 60 | BR38: 0 | BS38: 1 | BT38: 1 | BU38: 1 | BV38: 1 | BW38: 1 | BX38: 1 | BZ38: 91 | CA38: 48 | CE38: 1566 | CF38: 0 | CG38: 0 | CM38: 0 | CN38: Поправка: Гл.12.Прил.8.п.8. 3_12.00.01.11.001 Наименование: При наличии напряженных и стесненных условий производства работ (стесненность, сложность складирования и транспортной логистики и т.п.) для объектов, расположенных в пределах круговой магистральной системы улиц "Садовое кольцо" города Москвы | CO38: 0 | CP38: =(P38+Q38+S38) -> 3791.97 | CQ38: =ROUND((ROUND((AC38*AW38*1),2)*BC38),2) -> 0 | CR38: =(ROUND((ROUND((((ET38*1.2))*AV38*1),2)*BB38),2)+ROUND((ROUND(((AE38-((EU38*1.2)))*AV38*1),2)*BS38),2)) -> 0 | CS38: =(ROUND((ROUND((((EU38*1.2))*AV38*1),2)*BS38),2)+ROUND((ROUND(((AE38-((EU38*1.2)))*AV38*1),2)*BS38),2)) -> 0 | CT38: =ROUND((ROUND((AF38*AV38*1),2)*BA38),2) -> 689.45 | CU38: =AG38 -> 0 | CV38: =(AH38*AV38) -> 63.309996 | CW38: =AI38 -> 0 | CX38: =AJ38 -> 0 | CY38: =(ROUND((((S38+ROUND((ROUND((((EU38*1.2))*AV38*1),2)*BS38),2))*AT38)/100),2)+ROUND(((ROUND((ROUND(((AE38-((EU38*1.2)))*AV38*1),2)*BS38),2)*AT38)/100),2)) -> 3450.69 | CZ38: =(ROUND((((S38+ROUND((ROUND((((EU38*1.2))*AV38*1),2)*BS38),2))*AU38)/100),2)+ROUND(((ROUND((ROUND(((AE38-((EU38*1.2)))*AV38*1),2)*BS38),2)*AU38)/100),2)) -> 1820.15 | DB38: 13 | DD38: *1 | DE38: *1,2 | DF38: *1,2 | DG38: *1,2 | DI38: *1,2 | DJ38: *1,2 | DN38: 0 | DO38: 0 | DP38: 1 | DQ38: 1 | DU38: 1003 | DV38: 100 м | DW38: 100 м | DX38: 100 | EE38: 57042996 | EF38: 60 | EG38: Ремонтно-строительные работы | EH38: 0 | EJ38: 1 | EK38: 106 | EL38: ТСН-2001.6-67. Электромонтажные работы | EM38: ТСН-2001.6-67-1 | EO38: Поправка: Гл.12.Прил.8.п.8. 3_12.00.01.11.001 | EQ38: 0 | ER38: 548.75 | ES38: 0 | ET38: 0 | EU38: 0 | EV38: 548.75 | EW38: 50.39 | EX38: 0 | EY38: 0 | FQ38: 0 | FR38: 0 | FS38: 0 | FX38: 91 | FY38: 48 | GD38: 1 | GF38: -1102157239 | GG38: 2 | GH38: 1 | GI38: 2 | GJ38: 0 | GK38: 0 | GL38: =ROUND(IF(AND(BH38=3,BI38=3,FS38<>0),P38,0),2) -> 0 | GM38: =ROUND(O38+X38+Y38,2)+GX38 -> 9062.81 | GN38: =IF(OR(BI38=0,BI38=1),GM38-GX38,0) -> 9062.81 | GO38: =IF(BI38=2,GM38-GX38,0) -> 0 | GP38: =IF(BI38=4,GM38-GX38,0) -> 0 | GR38: 0 | GS38: 3 | GT38: 0 | GV38: =ROUND((GT38),6) -> 0 | GW38: 1 | GX38: =ROUND(HC38*I38,2) -> 0 | HA38: 0 | HB38: 0 | HC38: =GV38*GW38 -> 0 | HS38: 0 | IK38: 0
