Workbook

Sheet 02-01-02
A1: =Source!B1 -> Smeta.RU (495) 974-1589
J2: Форма № 4б
B3: "СОГЛАСОВАНО" | G3: "УТВЕРЖДАЮ"
B6: =CONCATENATE("______________________ ", IF(Source!AL12<>"", Source!AL12, "")) -> ______________________ | G6: =CONCATENATE("______________________ ", IF(Source!AH12<>"", Source!AH12, "")) -> ______________________
B7: "_____"________________ 2025 г. | G7: "_____"________________ 2025 г.
A10: Капитальный ремонт здания Государственного бюджетного общеобразовательного учреждения города Москвы «Школа № 236» по адресу: г. Москва, ул. Клязьминская, д. 7, к. 4. I этап | AP10: Капитальный ремонт здания Государственного бюджетного общеобразовательного учреждения города Москвы «Школа № 236» по адресу: г. Москва, ул. Клязьминская, д. 7, к. 4. I этап. 02-01-02 Конструктивные решения
A11: (наименование стройки и/или объекта)
A13: ЛОКАЛЬНАЯ СМЕТА № 02-01-02
A15: =IF(Source!G20<>"Новая локальная смета", Source!G20, "") -> Конструктивные решения
A16: (наименование работ и затрат)
A18: =CONCATENATE( "Основание: чертежи № ", Source!J20) -> Основание: чертежи № 2024-00272-01-0-КР.ВОР
I20: В базисном уровне цен | J20: В текущем уровне цен
E21: Сметная стоимость | I21: =I22+I23+I24+I25 -> 4298.49 | J21: =J22+J23+J24+J25 -> 68645.51 | K21: тыс.руб.
E22: Строительные работы | I22: =ROUND((Source!F1544)/1000, 2) -> 4298.49 | J22: =ROUND((Source!P1544)/1000, 2) -> 68645.51 | K22: тыс.руб.
E23: Работы по монтажу оборудования | I23: =ROUND((Source!F1545)/1000, 2) -> 0 | J23: =ROUND((Source!P1545)/1000, 2) -> 0 | K23: тыс.руб.
E24: Оборудование | I24: =ROUND((Source!F1536)/1000, 2) -> 0 | J24: =ROUND((Source!P1536)/1000, 2) -> 0 | K24: тыс.руб.
E25: Прочие работы и затраты | I25: =ROUND((Source!F1546+Source!F1547)/1000, 2) -> 0 | J25: =ROUND((Source!P1546+Source!P1547)/1000, 2) -> 0 | K25: тыс.руб.
E26: Средства на оплату труда | I26: =(Source!F1542+ Source!F1541)/1000 -> 364.80192 | J26: =((Source!P1542 + Source!P1541)/1000) -> 17451.356 | K26: тыс.руб.
E27: Затраты труда | I27: =Source!F1549 -> 27400.046 | K27: чел.-ч.
E28: Кроме того:
E29: Возврат материалов | I29: =SUM(Y35:Y1500)/1000 -> 0 | J29: =SUM(Z35:Z1500)/1000 -> 0 | K29: тыс.руб.
A31: Составлен(а) по ТСН-2001 с учетом Дополнения №: 79
A32: № и период сборника коэффициентов (индексов) пересчета: Коэффициенты к ТСН-2001 МГЭ Дополнение 79, ремонт №216/79 III квартал 2025 года и Коэффициенты к ТСН-2001.13-2 Дополнение 45 №62/45 III квартал 2025 года | M32: Пересчитать в Доп. 79, 3 квартал сентябрь | AP32: № и период сборника коэффициентов (индексов) пересчета: Коэффициенты к ТСН-2001 МГЭ Дополнение 79, ремонт №216/79 III квартал 2025 года и Коэффициенты к ТСН-2001.13-2 Дополнение 45 №62/45 III квартал 2025 года
A33: № п/п | B33: Шифр расценки и коды ресурсов | C33: Наименование работ и затрат | D33: Ед. изм. | E33: Кол-во единиц | F33: Цена на ед. изм., руб. | G33: Попра- вочные коэффи- циенты | H33: Коэффи- циенты зимних удорожа- ний | I33: Всего в ценах на январь 2000 года, руб. | J33: Коэффи- циенты (индек- сы) пере- счета, нормы НР и СП | K33: ВСЕГО затрат в текущем уровне цен, руб.
A34: 1 | B34: 2 | C34: 3 | D34: 4 | E34: 5 | F34: 6 | G34: 7 | H34: 8 | I34: 9 | J34: 10 | K34: 11
A36: =CONCATENATE("Раздел: ",IF(Source!G24<>"Новый раздел", Source!G24, "")) -> Раздел: Усиление внутренних и наружных стен в зоне расширяемых проемов в подвале и в надземной части здания. Рама РС-1, 105 шт. (КР-5,6) | AP36: =CONCATENATE("Раздел: ",IF(Source!G24<>"Новый раздел", Source!G24, "")) -> Раздел: Усиление внутренних и наружных стен в зоне расширяемых проемов в подвале и в надземной части здания. Рама РС-1, 105 шт. (КР-5,6)
A37: 1 | B37: 6.53-25-1 Поправка: Гл.12.Прил.8.п.8. 5_12.00.01.11.003 | C37: Усиление кирпичных стен металлическим каркасом | D37: =Source!H28 -> 1 Т | E37: =Source!I28 -> 25.5045 | M37: откорректировать объемы и виды работ в соответствии с КР.ВОР | Q37: =Source!X28 -> 68224.72 | R37: =Source!X29 -> 3262505.9 | S37: =Source!Y28 -> 38561.8 | T37: =Source!Y29 -> 1844025.1 | U37: =ROUND((175/100)*ROUND(Source!R28, 2), 2) -> 116.69 | V37: =ROUND((0/100)*ROUND(Source!R29, 2), 2) -> 0 | AC37: 0
C38: ="Объем: "&Source!I28&"=(70,9+"&"38,5+"&"109,3+"&"7,4+"&"7,2+"&"2,7+"&"6,9)/"&"1000*"&"105" -> Объем: 25,5045=(70,9+38,5+109,3+7,4+7,2+2,7+6,9)/1000*105
C39: ЗП | F39: =Source!AO28 -> 2522.36 | G39: =Source!DG28 -> *1,1 | H39: =Source!AV29 -> 1.047 | I39: =Source!S28 -> 74090.62 | J39: =IF(Source!BA29<> 0, Source!BA29, 1) -> 47.82 | K39: =Source!S29 -> 3543013.5
C40: ЭМ | F40: =Source!AM28 -> 36.08 | G40: =Source!DE28 -> *1,1 | H40: =Source!AV29 -> 1.047 | I40: =Source!Q28 -> 1059.8 | J40: =IF(Source!BB29<> 0, Source!BB29, 1) -> 13.74 | K40: =Source!Q29 -> 14561.65
C41: в т.ч. ЗПМ | F41: =Source!AN28 -> 2.27 | G41: =Source!DF28 -> *1,1 | H41: =Source!AV29 -> 1.047 | I41: =Source!R28 -> 66.68 | J41: =IF(Source!BS29<> 0, Source!BS29, 1) -> 47.82 | K41: =Source!R29 -> 3188.64
C42: МР | F42: =Source!AL28 -> 28.74 | G42: =Source!DD28 | H42: =Source!AW29 -> 1.002 | I42: =Source!P28 -> 734.47 | J42: =IF(Source!BC29<> 0, Source!BC29, 1) -> 13.02 | K42: =Source!P29 -> 9562.8
A43: 1,1 | B43: =Source!F30 -> 1.1-1-1121 | C43: Уголок равнополочный, для строительных стальных конструкций, ширина полки более 70 мм, сталь С235, С245 | D43: =Source!H30 -> т | E43: =Source!I30 -> 24.465 | F43: =Source!AK30 -> 9844.31 | H43: =Source!AW31 -> 1.002 | I43: =Source!O30 -> 241322.73 | J43: =IF(Source!BC31<> 0, Source!BC31, 1) -> 7.54 | K43: =Source!O31 -> 1819573.4 | Q43: =Source!X30 -> 0 | R43: =Source!X31 -> 0 | S43: =Source!Y30 -> 0 | T43: =Source!Y31 -> 0 | U43: =ROUND((175/100)*ROUND(Source!R30, 2), 2) -> 0 | V43: =ROUND((0/100)*ROUND(Source!R31, 2), 2) -> 0 | AC43: 3
A44: 1,2 | B44: =Source!F32 -> 1.1-1-1105 | C44: Прокат листовой из стали С235, С245 для строительных стальных конструкций, толщина более 3 мм | D44: =Source!H32 -> т | E44: =Source!I32 -> 1.0395 | F44: =Source!AK32 -> 6519.2 | H44: =Source!AW33 -> 1.002 | I44: =Source!O32 -> 6790.26 | J44: =IF(Source!BC33<> 0, Source!BC33, 1) -> 10.12 | K44: =Source!O33 -> 68717.43 | Q44: =Source!X32 -> 0 | R44: =Source!X33 -> 0 | S44: =Source!Y32 -> 0 | T44: =Source!Y33 -> 0 | U44: =ROUND((175/100)*ROUND(Source!R32, 2), 2) -> 0 | V44: =ROUND((0/100)*ROUND(Source!R33, 2), 2) -> 0 | AC44: 3
A45: 1,3 | B45: =Source!F34 -> 1.7-5-220 | C45: Шпилька резьбовая, стальная, оцинкованная, с заостренным концом, в комплекте с шайбой и гайкой, М16x190 мм | D45: =Source!H34 -> шт. | E45: =Source!I34 -> 1470 | F45: =Source!AK34 -> 29.8 | H45: =Source!AW35 -> 1.002 | I45: =Source!O34 -> 43893.61 | J45: =IF(Source!BC35<> 0, Source!BC35, 1) -> 11.97 | K45: =Source!O35 -> 525406.51 | Q45: =Source!X34 -> 0 | R45: =Source!X35 -> 0 | S45: =Source!Y34 -> 0 | T45: =Source!Y35 -> 0 | U45: =ROUND((175/100)*ROUND(Source!R34, 2), 2) -> 0 | V45: =ROUND((0/100)*ROUND(Source!R35, 2), 2) -> 0 | AC45: 3
C46: НР от ЗП | D46: % | E46: =Source!BZ29 -> 92 | I46: =SUM(Q37:Q45) -> 68224.72 | J46: =Source!AT29 -> 92 | K46: =SUM(R37:R45) -> 3262505.9
C47: СП от ЗП | D47: % | E47: =Source!CA29 -> 52 | I47: =SUM(S37:S46) -> 38561.8 | J47: =Source!AU29 -> 52 | K47: =SUM(T37:T46) -> 1844025.1
C48: ЗТР | D48: чел-ч | E48: =Source!AQ28 -> 201.95 | G48: =Source!DI28 -> *1,1 | H48: =Source!AV29 -> 1.047 | I48: =Source!U28 -> 5931.9849
C49: ВСЕГО работ по позиции: | H49: =I39+I40+I42+I46+I47+SUM(I43:I45)-SUMIF(AC43:AC45, 5, I43:I45)-SUMIF(AC43:AC45, 6, I43:I45) -> 474678.01 | J49: =K39+K40+K42+K46+K47+SUM(K43:K45)-SUMIF(AC43:AC45, 5, K43:K45)-SUMIF(AC43:AC45, 6, K43:K45) -> 11087366
C50: ВСЕГО оборудование по позиции: | H50: =SUMIF(AC43:AC45, 5, I43:I45)+SUMIF(AC43:AC45, 6, I43:I45) -> 0 | J50: =SUMIF(AC43:AC45, 5, K43:K45)+SUMIF(AC43:AC45, 6, K43:K45) -> 0
...

Sheet Ведомость объемов работ
A1: =Source!B1 -> Smeta.RU (495) 974-1589
E3: "УТВЕРЖДАЮ"
D5: ___________________________
D7: ___________________________
D9: " ___ " ___________ 20 ___ г.
B12: =CONCATENATE("Ведомость объемов работ ", IF(Source!AN15<>"", Source!AN15," ")) -> Ведомость объемов работ
B13: =CONCATENATE(Source!F12, " ", Source!G12) -> 02-01-02 02-01-02 Конструктивные решения
A16: № п/п | B16: № в ЛСР | C16: Наименование работ и затрат | D16: Единица измерения | E16: Количество | F16: Ссылка на чертежи, спецификации | G16: Формула расчета, расчет объемов работ и расхода материалов | H16: Примечание
A17: 1 | B17: 2 | C17: 3 | D17: 4 | E17: 5 | F17: 6 | G17: 7 | H17: 8
A18: =CONCATENATE("Локальная смета: ", Source!G20) -> Локальная смета: Конструктивные решения
A19: =CONCATENATE("Раздел: ", Source!G24) -> Раздел: Усиление внутренних и наружных стен в зоне расширяемых проемов в подвале и в надземной части здания. Рама РС-1, 105 шт. (КР-5,6) | AF19: =CONCATENATE("Раздел: ", Source!G24) -> Раздел: Усиление внутренних и наружных стен в зоне расширяемых проемов в подвале и в надземной части здания. Рама РС-1, 105 шт. (КР-5,6)
A20: 1 | B20: =Source!E28 -> 1 | C20: =Source!G28 -> Усиление кирпичных стен металлическим каркасом | D20: 1 Т | E20: =Source!I28 -> 25.5045 | F20: =Source!U24 | G20: ="=(70,9+"&"38,5+"&"109,3+"&"7,4+"&"7,2+"&"2,7+"&"6,9)/"&"1000*"&"105" -> =(70,9+38,5+109,3+7,4+7,2+2,7+6,9)/1000*105
A21: 1.1 | B21: =Source!E30 -> 1,1 | C21: =Source!G30 -> Уголок равнополочный, для строительных стальных конструкций, ширина полки более 70 мм, сталь С235, С245 | D21: т | E21: =Source!I30 -> 24.465 | F21: =Source!U24
A22: 1.2 | B22: =Source!E32 -> 1,2 | C22: =Source!G32 -> Прокат листовой из стали С235, С245 для строительных стальных конструкций, толщина более 3 мм | D22: т | E22: =Source!I32 -> 1.0395 | F22: =Source!U24
A23: 1.3 | B23: =Source!E34 -> 1,3 | C23: =Source!G34 -> Шпилька резьбовая, стальная, оцинкованная, с заостренным концом, в комплекте с шайбой и гайкой, М16x190 мм | D23: шт. | E23: =Source!I34 -> 1470 | F23: =Source!U24
A24: 2 | B24: =Source!E36 -> 2 | C24: =Source!G36 -> Огрунтовка металлических поверхностей грунтовкой ГФ-021 за один раз | D24: 100 м2 | E24: =Source!I36 -> 7.6375005 | F24: =Source!U24 | G24: ="=(70,9*"&"26,3+"&"38,5*"&"26,3+"&"109,3*"&"33+"&"7,4*"&"33+"&"7,2*"&"32,1+"&"2,7*"&"32,1+"&"6,9*"&"33)/"&"1000/"&"100*"&"105" -> =(70,9*26,3+38,5*26,3+109,3*33+7,4*33+7,2*32,1+2,7*32,1+6,9*33)/1000/100*105
A25: 2.1 | B25: =Source!E38 -> 2,1 | C25: =Source!G38 -> Грунтовка глифталевая, типа ГФ-021 | D25: т | E25: =Source!I38 -> 0.068738 | F25: =Source!U24
A26: =CONCATENATE("Раздел: ", Source!G71) -> Раздел: Усиление внутренних и наружных стен в зоне расширяемых проемов в подвале и в надземной части здания. Рама РС-2, 22 шт. (КР-5,6) | AF26: =CONCATENATE("Раздел: ", Source!G71) -> Раздел: Усиление внутренних и наружных стен в зоне расширяемых проемов в подвале и в надземной части здания. Рама РС-2, 22 шт. (КР-5,6)
A27: 3 | B27: =Source!E75 -> 3 | C27: =Source!G75 -> Усиление кирпичных стен металлическим каркасом | D27: 1 Т | E27: =Source!I75 -> 4.7322 | F27: =Source!U71 | G27: ="=(67,6+"&"106,3+"&"4,2+"&"6,9+"&"7,2+"&"11,3+"&"0,9+"&"1,4+"&"9,3)/"&"1000*"&"22" -> =(67,6+106,3+4,2+6,9+7,2+11,3+0,9+1,4+9,3)/1000*22
A28: 3.1 | B28: =Source!E77 -> 3,1 | C28: =Source!G77 -> Швеллер №№ 12-40, из стали углеродистой обыкновенного качества, спокойной | D28: т | E28: =Source!I77 -> 1.4872 | F28: =Source!U71
A29: 3.2 | B29: =Source!E79 -> 3,2 | C29: =Source!G79 -> Уголок равнополочный, для строительных стальных конструкций, ширина полки более 70 мм, сталь С235, С245 | D29: т | E29: =Source!I79 -> 2.5828 | F29: =Source!U71
A30: 3.3 | B30: =Source!E81 -> 3,3 | C30: =Source!G81 -> Прокат листовой из стали С235, С245 для строительных стальных конструкций, толщина более 3 мм | D30: т | E30: =Source!I81 -> 0.6622 | F30: =Source!U71
A31: 3.4 | B31: =Source!E83 -> 3,4 | C31: =Source!G83 -> Шпилька резьбовая, стальная, оцинкованная, с заостренным концом, в комплекте с шайбой и гайкой, М16x190 мм | D31: шт. | E31: =Source!I83 -> 176 | F31: =Source!U71
A32: 3.5 | B32: =Source!E85 -> 3,5 | C32: =Source!G85 -> Анкер-болт забивной, распорный, стальной, оцинкованный, с широкой шайбой M12х110 | D32: 100 шт. | E32: =Source!I85 -> 0.88 | F32: =Source!U71
A33: 4 | B33: =Source!E87 -> 4 | C33: =Source!G87 -> Огрунтовка металлических поверхностей грунтовкой ГФ-021 за один раз | D33: 100 м2 | E33: =Source!I87 -> 1.4266978 | F33: =Source!U71 | G33: ="=(67,6*"&"26,1+"&"106,3*"&"33+"&"4,2*"&"33+"&"6,9*"&"33+"&"7,2*"&"32,1+"&"11,3*"&"21,5+"&"0,9*"&"32,1+"&"1,4*"&"32,1+"&"9,3*"&"32,1)/"&"1000/"&"100*"&"22" -> =(67,6*26,1+106,3*33+4,2*33+6,9*33+7,2*32,1+11,3*21,5+0,9*32,1+1,4*32,1+9,3*32,1)/1000/100*22
A34: 4.1 | B34: =Source!E89 -> 4,1 | C34: =Source!G89 -> Грунтовка глифталевая, типа ГФ-021 | D34: т | E34: =Source!I89 -> 0.01284 | F34: =Source!U71
A35: =CONCATENATE("Раздел: ", Source!G122) -> Раздел: Усиление внутренних и наружных стен в зоне расширяемых проемов в подвале и в надземной части здания. Рама РС-3, 5 шт. (КР-5,6) | AF35: =CONCATENATE("Раздел: ", Source!G122) -> Раздел: Усиление внутренних и наружных стен в зоне расширяемых проемов в подвале и в надземной части здания. Рама РС-3, 5 шт. (КР-5,6)
A36: 5 | B36: =Source!E126 -> 5 | C36: =Source!G126 -> Усиление кирпичных стен металлическим каркасом | D36: 1 Т | E36: =Source!I126 -> 1.473 | F36: =Source!U122 | G36: ="=(146,3+"&"108,5+"&"15,7+"&"7,2+"&"16,9)/"&"1000*"&"5" -> =(146,3+108,5+15,7+7,2+16,9)/1000*5
A37: 5.1 | B37: =Source!E128 -> 5,1 | C37: =Source!G128 -> Уголок равнополочный, для строительных стальных конструкций, ширина полки более 70 мм, сталь С235, С245 | D37: т | E37: =Source!I128 -> 1.3525 | F37: =Source!U122
A38: 5.2 | B38: =Source!E130 -> 5,2 | C38: =Source!G130 -> Прокат листовой из стали С235, С245 для строительных стальных конструкций, толщина более 3 мм | D38: т | E38: =Source!I130 -> 0.1205 | F38: =Source!U122
A39: 5.3 | B39: =Source!E132 -> 5,3 | C39: =Source!G132 -> Шпилька резьбовая, стальная, оцинкованная, с заостренным концом, в комплекте с шайбой и гайкой, М16x190 мм | D39: шт. | E39: =Source!I132 -> 90 | F39: =Source!U122
A40: 6 | B40: =Source!E134 -> 6 | C40: =Source!G134 -> Огрунтовка металлических поверхностей грунтовкой ГФ-021 за один раз | D40: 100 м2 | E40: =Source!I134 -> 0.435995 | F40: =Source!U122 | G40: ="=(146,3*"&"26,3+"&"108,5*"&"33+"&"15,7*"&"33+"&"7,2*"&"32,1+"&"16,9*"&"32,1)/"&"1000/"&"100*"&"5" -> =(146,3*26,3+108,5*33+15,7*33+7,2*32,1+16,9*32,1)/1000/100*5
A41: 6.1 | B41: =Source!E136 -> 6,1 | C41: =Source!G136 -> Грунтовка глифталевая, типа ГФ-021 | D41: т | E41: =Source!I136 -> 0.003924 | F41: =Source!U122
A42: =CONCATENATE("Раздел: ", Source!G169) -> Раздел: Усиление внутренних и наружных стен в зоне расширяемых проемов в подвале и в надземной части здания. Рама РС-6, 2 шт. (КР-5,6) | AF42: =CONCATENATE("Раздел: ", Source!G169) -> Раздел: Усиление внутренних и наружных стен в зоне расширяемых проемов в подвале и в надземной части здания. Рама РС-6, 2 шт. (КР-5,6)
A43: 7 | B43: =Source!E173 -> 7 | C43: =Source!G173 -> Усиление кирпичных стен металлическим каркасом | D43: 1 Т | E43: =Source!I173 -> 0.676 | F43: =Source!U169 | G43: ="=(182,6+"&"50,5+"&"55,4+"&"31,4+"&"3,6+"&"14,5)/"&"1000*"&"2" -> =(182,6+50,5+55,4+31,4+3,6+14,5)/1000*2
A44: 7.1 | B44: =Source!E175 -> 7,1 | C44: =Source!G175 -> Уголок равнополочный, для строительных стальных конструкций, ширина полки более 70 мм, сталь С235, С245 | D44: т | E44: =Source!I175 -> 0.5388 | F44: =Source!U169
A45: 7.2 | B45: =Source!E177 -> 7,2 | C45: =Source!G177 -> Профили стальные электросварные квадратного сечения трубчатые, размер стороны 100 мм, толщина стенки от 3 до 6 мм | D45: т | E45: =Source!I177 -> 0.101 | F45: =Source!U169
A46: 7.3 | B46: =Source!E179 -> 7,3 | C46: =Source!G179 -> Прокат листовой из стали С235, С245 для строительных стальных конструкций, толщина более 3 мм | D46: т | E46: =Source!I179 -> 0.0362 | F46: =Source!U169
A47: 7.4 | B47: =Source!E181 -> 7,4 | C47: =Source!G181 -> Шпилька резьбовая, стальная, оцинкованная, с заостренным концом, в комплекте с шайбой и гайкой, М16x190 мм | D47: шт. | E47: =Source!I181 -> 36 | F47: =Source!U169
A48: 8 | B48: =Source!E183 -> 8 | C48: =Source!G183 -> Огрунтовка металлических поверхностей грунтовкой ГФ-021 за один раз | D48: 100 м2 | E48: =Source!I183 -> 0.1817218 | F48: =Source!U169 | G48: ="=(182,6*"&"26,3+"&"50,5*"&"16,6+"&"55,4*"&"33+"&"31,4*"&"33+"&"3,6*"&"32,1+"&"14,5*"&"32,1)/"&"1000/"&"100*"&"2" -> =(182,6*26,3+50,5*16,6+55,4*33+31,4*33+3,6*32,1+14,5*32,1)/1000/100*2
...

Sheet Source
A1: 0 | B1: Smeta.RU (495) 974-1589 | D1: _PS_ | F1: 0 | G1: 0 | H1: 0 | I1: Smeta.RU | K1: 1 | L1: 74562 | M1: 10 | N1: 11 | O1: 14 | P1: 0 | Q1: 0
A4: 1 | B4: 1 | C4: -1 | G4: Капитальный ремонт здания Государственного бюджетного общеобразовательного учреждения города Москвы «Школа № 236» по адресу: г. Москва, ул. Клязьминская, д. 7, к. 4. I этап | EC4: 0
A12: 1 | B12: 1597 | C12: 0 | D12: =ROW(A1557) -> 1557 | E12: 0 | F12: 02-01-02 | G12: 02-01-02 Конструктивные решения | I12: 0 | J12: 2024-00272-01-0-КР.ВОР | K12: 0 | L12: 0 | M12: 4098 | O12: 0 | P12: 0 | Q12: 0 | R12: 0 | S12: 0 | T12: 1 | V12: 0 | AB12: Лукьянова А.Л. | BB12: 0 | BH12: Сметные нормы списания | BI12: Коды ОКП для ТСН-2001 МГЭ Дополнение 79 | BJ12: 1 | BK12: 1 | BL12: 0 | BM12: 0 | BN12: 1 | BO12: 0 | BP12: 6 | BQ12: 2 | BR12: 1 | BS12: 1 | BT12: 0 | BU12: 0 | BV12: 0 | BW12: 0 | BX12: 0 | BY12: ТСН-2001 (МГЭ) Доп 79 - Ремонт | BZ12: Типовой расчет для ТСН-2001 МГЭ, Дополнение 79, ремонт | CA12: Территориальные сметные нормативы для Москвы ТСН-2001 (МГЭ), дополнение 79 | CB12: Территориальные сметные нормативы для Москвы ТСН-2001 (МГЭ), дополнение 79 | CC12: Территориальные сметные нормативы для Москвы ТСН-2001 (МГЭ), дополнение 79 | CD12: Территориальные сметные нормативы для Москвы ТСН-2001 (МГЭ), дополнение 79 | CE12: Поправки для ТСН-2001 от 03.10.2025 г. доп.79 | CF12: 0 | CG12: 0 | CH12: 8200 | CK12: 79 | CQ12: Территориальные сметные нормативы для Москвы (ТСН-2001) | CR12: ТЕР | CS12: 41660 | CT12: 1 | CU12: 79 | CY12: 0 | EC12: 0
A15: 15 | B15: 1
A18: 52 | B18: =B1557 -> 1597 | C18: =C1557 -> 1 | D18: =D1557 -> 12 | E18: =E1557 -> 0 | F18: =F1557 -> 02-01-02 | G18: =G1557 -> 02-01-02 Конструктивные решения | O18: =O1557 -> 3772771 | P18: =P1557 -> 3378093.4 | Q18: =Q1557 -> 32771.56 | R18: =R1557 -> 2895.88 | S18: =S1557 -> 361906.04 | T18: =T1557 -> 0 | U18: =U1557 -> 27400.046 | V18: =V1557 -> 0 | ... GX18: =GX1557 -> 0
A20: 3 | B20: 1 | D20: =ROW(A1527) -> 1527 | G20: Конструктивные решения | I20: 0 | J20: 2024-00272-01-0-КР.ВОР | K20: -1 | L20: 02-01-02 | S20: 0 | T20: 0 | V20: 0 | AB20: Лукьянова А.Л. | BX20: 0 | CF20: 0 | CG20: 0
A22: 52 | B22: =B1527 -> 1 | C22: =C1527 -> 3 | D22: =D1527 -> 20 | E22: =E1527 -> 0 | F22: =F1527 | G22: =G1527 -> Конструктивные решения | O22: =O1527 -> 3772771 | P22: =P1527 -> 3378093.4 | Q22: =Q1527 -> 32771.56 | R22: =R1527 -> 2895.88 | S22: =S1527 -> 361906.04 | T22: =T1527 -> 0 | U22: =U1527 -> 27400.046 | V22: =V1527 -> 0 | ... GX22: =GX1527 -> 0
A24: 4 | B24: 1 | D24: =ROW(A41) -> 41 | G24: Усиление внутренних и наружных стен в зоне расширяемых проемов в подвале и в надземной части здания. Рама РС-1, 105 шт. (КР-5,6) | I24: 0 | K24: -1 | S24: 0 | T24: 0 | V24: 0 | BX24: 0 | CJ24: 0
A26: 52 | B26: =B41 -> 1 | C26: =C41 -> 4 | D26: =D41 -> 24 | E26: =E41 -> 0 | F26: =F41 | G26: =G41 -> Усиление внутренних и наружных стен в зоне расширяемых проемов в подвале и в надземной части здания. Рама РС-1, 105 шт. (КР-5,6) | O26: =O41 -> 370105.87 | P26: =P41 -> 294096.01 | Q26: =Q41 -> 1203.04 | R26: =R41 -> 69.31 | S26: =S41 -> 74806.82 | T26: =T41 -> 0 | U26: =U41 -> 5983.2872 | V26: =V41 -> 0 | ... GX26: =GX41 -> 0
A28: 17 | B28: 1 | C28: =ROW(SmtRes!A3) -> 3 | D28: =ROW(EtalonRes!A8) -> 8 | E28: 1 | F28: 6.53-25-1 | G28: Усиление кирпичных стен металлическим каркасом | H28: 1 Т | I28: =ROUND((70.9+38.5+109.3+7.4+7.2+2.7+6.9)/1000*105,9) -> 25.5045 | J28: 0 | K28: =ROUND((70.9+38.5+109.3+7.4+7.2+2.7+6.9)/1000*105,9) -> 25.5045 | O28: =ROUND(CP28,2) -> 75884.89 | P28: =ROUND((ROUND((AC28*AW28*I28),2)*BC28),2) -> 734.47 | Q28: =(ROUND((ROUND((((ET28*1.1))*AV28*I28),2)*BB28),2)+ROUND((ROUND(((AE28-((EU28*1.1)))*AV28*I28),2)*BS28),2)) -> 1059.8 | R28: =ROUND((ROUND((AE28*AV28*I28),2)*BS28),2) -> 66.68 | S28: =ROUND((ROUND((AF28*AV28*I28),2)*BA28),2) -> 74090.62 | T28: =ROUND(CU28*I28,2) -> 0 | U28: =CV28*I28 -> 5931.9849 | V28: =CW28*I28 -> 0 | W28: =ROUND(CX28*I28,2) -> 0 | X28: =ROUND(CY28,2) -> 68224.72 | Y28: =ROUND(CZ28,2) -> 38561.8 | AA28: 56481265 | AB28: =ROUND((AC28+AD28+AF28),6) -> 2843.024 | AC28: =ROUND((ES28),6) -> 28.74 | AD28: =ROUND(((((ET28*1.1))-((EU28*1.1)))+AE28),6) -> 39.688 | AE28: =ROUND(((EU28*1.1)),6) -> 2.497 | AF28: =ROUND(((EV28*1.1)),6) -> 2774.596 | AG28: =ROUND((AP28),6) -> 0 | AH28: =((EW28*1.1)) -> 222.145 | AI28: =((EX28*1.1)) -> 0 | AJ28: =(AS28) -> 0 | AK28: 2587.18 | AL28: 28.74 | AM28: 36.08 | AN28: 2.27 | AO28: 2522.36 | AP28: 0 | AQ28: 201.95 | AR28: 0 | AS28: 0 | AT28: 92 | AU28: 52 | AV28: 1.047 | AW28: 1.002 | AZ28: 1 | BA28: 1 | BB28: 1 | BC28: 1 | BH28: 0 | BI28: 1 | BJ28: ТСН-2001.6 Доп. 79, Сб. 53, т. 25, поз. 1 | BM28: 90 | BN28: 0 | BO28: 6.53-25-1 | BP28: 1 | BQ28: 60 | BR28: 0 | BS28: 1 | BT28: 1 | BU28: 1 | BV28: 1 | BW28: 1 | BX28: 1 | BZ28: 92 | CA28: 52 | CE28: 30 | CF28: 0 | CG28: 0 | CM28: 0 | CO28: 0 | CP28: =(P28+Q28+S28) -> 75884.89 | CQ28: =ROUND((ROUND((AC28*AW28*1),2)*BC28),2) -> 28.8 | CR28: =(ROUND((ROUND((((ET28*1.1))*AV28*1),2)*BB28),2)+ROUND((ROUND(((AE28-((EU28*1.1)))*AV28*1),2)*BS28),2)) -> 41.55 | CS28: =ROUND((ROUND((AE28*AV28*1),2)*BS28),2) -> 2.61 | CT28: =ROUND((ROUND((AF28*AV28*1),2)*BA28),2) -> 2905 | CU28: =AG28 -> 0 | CV28: =(AH28*AV28) -> 232.58581 | CW28: =AI28 -> 0 | CX28: =AJ28 -> 0 | CY28: =(((S28+R28)*AT28)/100) -> 68224.716 | CZ28: =(((S28+R28)*AU28)/100) -> 38561.796 | DE28: *1,1 | DF28: *1,1 | DG28: *1,1 | DI28: *1,1 | DJ28: *1,1 | DN28: 0 | DO28: 0 | DP28: 1 | DQ28: 1 | DU28: 1013 | DV28: 1 Т | DW28: 1 Т | DX28: 1 | EE28: 55586525 | EF28: 60 | EG28: Ремонтно-строительные работы | EH28: 0 | EJ28: 1 | EK28: 90 | EL28: ТСН-2001.6-53. Стены | EM28: ТСН-2001.6-53-1 | EO28: Поправка: Гл.12.Прил.8.п.8. 5_12.00.01.11.003 | EQ28: 0 | ER28: 2587.18 | ES28: 28.74 | ET28: 36.08 | EU28: 2.27 | EV28: 2522.36 | EW28: 201.95 | EX28: 0 | EY28: 0 | FQ28: 0 | FR28: 0 | FS28: 0 | FX28: 92 | FY28: 52 | GD28: 1 | GF28: -811884377 | GG28: 2 | GH28: 1 | GI28: 2 | GJ28: 0 | GK28: 0 | GL28: =ROUND(IF(AND(BH28=3,BI28=3,FS28<>0),P28,0),2) -> 0 | GM28: =ROUND(O28+X28+Y28,2)+GX28 -> 182671.41 | GN28: =IF(OR(BI28=0,BI28=1),GM28-GX28,0) -> 182671.41 | GO28: =IF(BI28=2,GM28-GX28,0) -> 0 | GP28: =IF(BI28=4,GM28-GX28,0) -> 0 | GR28: 0 | GS28: 3 | GT28: 0 | GV28: =ROUND((GT28),6) -> 0 | GW28: 1 | GX28: =ROUND(HC28*I28,2) -> 0 | HA28: 0 | HB28: 0 | HC28: =GV28*GW28 -> 0 | HS28: 0 | IK28: 0
A29: 17 | B29: 1 | C29: =ROW(SmtRes!A6) -> 6 | D29: =ROW(EtalonRes!A16) -> 16 | E29: 1 | F29: 6.53-25-1 | G29: Усиление кирпичных стен металлическим каркасом | H29: 1 Т | I29: =ROUND((70.9+38.5+109.3+7.4+7.2+2.7+6.9)/1000*105,9) -> 25.5045 | J29: 0 | K29: =ROUND((70.9+38.5+109.3+7.4+7.2+2.7+6.9)/1000*105,9) -> 25.5045 | O29: =ROUND(CP29,2) -> 3567137.9 | P29: =ROUND((ROUND((AC29*AW29*I29),2)*BC29),2) -> 9562.8 | Q29: =(ROUND((ROUND((((ET29*1.1))*AV29*I29),2)*BB29),2)+ROUND((ROUND(((AE29-((EU29*1.1)))*AV29*I29),2)*BS29),2)) -> 14561.65 | R29: =ROUND((ROUND((AE29*AV29*I29),2)*BS29),2) -> 3188.64 | S29: =ROUND((ROUND((AF29*AV29*I29),2)*BA29),2) -> 3543013.5 | T29: =ROUND(CU29*I29,2) -> 0 | U29: =CV29*I29 -> 5931.9849 | V29: =CW29*I29 -> 0 | W29: =ROUND(CX29*I29,2) -> 0 | X29: =ROUND(CY29,2) -> 3262505.9 | Y29: =ROUND(CZ29,2) -> 1844025.1 | AA29: 56481267 | AB29: =ROUND((AC29+AD29+AF29),6) -> 2843.024 | AC29: =ROUND((ES29),6) -> 28.74 | AD29: =ROUND(((((ET29*1.1))-((EU29*1.1)))+AE29),6) -> 39.688 | AE29: =ROUND(((EU29*1.1)),6) -> 2.497 | AF29: =ROUND(((EV29*1.1)),6) -> 2774.596 | AG29: =ROUND((AP29),6) -> 0 | AH29: =((EW29*1.1)) -> 222.145 | AI29: =((EX29*1.1)) -> 0 | AJ29: =(AS29) -> 0 | AK29: 2587.18 | AL29: 28.74 | AM29: 36.08 | AN29: 2.27 | AO29: 2522.36 | AP29: 0 | AQ29: 201.95 | AR29: 0 | AS29: 0 | AT29: 92 | AU29: 52 | AV29: 1.047 | AW29: 1.002 | AZ29: 1 | BA29: 47.82 | BB29: 13.74 | BC29: 13.02 | BH29: 0 | BI29: 1 | BJ29: ТСН-2001.6 Доп. 79, Сб. 53, т. 25, поз. 1 | BM29: 90 | BN29: 0 | BO29: 6.53-25-1 | BP29: 1 | BQ29: 60 | BR29: 0 | BS29: 47.82 | BT29: 1 | BU29: 1 | BV29: 1 | BW29: 1 | BX29: 1 | BZ29: 92 | CA29: 52 | CE29: 30 | CF29: 0 | CG29: 0 | CM29: 0 | CO29: 0 | CP29: =(P29+Q29+S29) -> 3567137.9 | CQ29: =ROUND((ROUND((AC29*AW29*1),2)*BC29),2) -> 374.98 | CR29: =(ROUND((ROUND((((ET29*1.1))*AV29*1),2)*BB29),2)+ROUND((ROUND(((AE29-((EU29*1.1)))*AV29*1),2)*BS29),2)) -> 570.9 | CS29: =ROUND((ROUND((AE29*AV29*1),2)*BS29),2) -> 124.81 | CT29: =ROUND((ROUND((AF29*AV29*1),2)*BA29),2) -> 138917.1 | CU29: =AG29 -> 0 | CV29: =(AH29*AV29) -> 232.58581 | CW29: =AI29 -> 0 | CX29: =AJ29 -> 0 | CY29: =(((S29+R29)*AT29)/100) -> 3262505.9 | CZ29: =(((S29+R29)*AU29)/100) -> 1844025.1 | DE29: *1,1 | DF29: *1,1 | DG29: *1,1 | DI29: *1,1 | DJ29: *1,1 | DN29: 0 | DO29: 0 | DP29: 1 | DQ29: 1 | DU29: 1013 | DV29: 1 Т | DW29: 1 Т | DX29: 1 | EE29: 55586525 | EF29: 60 | EG29: Ремонтно-строительные работы | EH29: 0 | EJ29: 1 | EK29: 90 | EL29: ТСН-2001.6-53. Стены | EM29: ТСН-2001.6-53-1 | EO29: Поправка: Гл.12.Прил.8.п.8. 5_12.00.01.11.003 | EQ29: 0 | ER29: 2587.18 | ES29: 28.74 | ET29: 36.08 | EU29: 2.27 | EV29: 2522.36 | EW29: 201.95 | EX29: 0 | EY29: 0 | FQ29: 0 | FR29: 0 | FS29: 0 | FX29: 92 | FY29: 52 | GD29: 1 | GF29: -811884377 | GG29: 2 | GH29: 1 | GI29: 2 | GJ29: 0 | GK29: 0 | GL29: =ROUND(IF(AND(BH29=3,BI29=3,FS29<>0),P29,0),2) -> 0 | GM29: =ROUND(O29+X29+Y29,2)+GX29 -> 8673668.9 | GN29: =IF(OR(BI29=0,BI29=1),GM29-GX29,0) -> 8673668.9 | GO29: =IF(BI29=2,GM29-GX29,0) -> 0 | GP29: =IF(BI29=4,GM29-GX29,0) -> 0 | GR29: 0 | GS29: 3 | GT29: 0 | GV29: =ROUND((GT29),6) -> 0 | GW29: 1 | GX29: =ROUND(HC29*I29,2) -> 0 | HA29: 0 | HB29: 0 | HC29: =GV29*GW29 -> 0 | HS29: 0 | IK29: 0
A30: 18 | B30: 1 | C30: 2 | E30: 1,1 | F30: 1.1-1-1121 | G30: Уголок равнополочный, для строительных стальных конструкций, ширина полки более 70 мм, сталь С235, С245 | H30: т | I30: =I28*J30 -> 24.465 | J30: 0.95924249 | K30: 0.9592425 | O30: =ROUND(CP30,2) -> 241322.73 | P30: =ROUND((ROUND((AC30*AW30*I30),2)*BC30),2) -> 241322.73 | Q30: =(ROUND((ROUND(((ET30)*AV30*I30),2)*BB30),2)+ROUND((ROUND(((AE30-(EU30))*AV30*I30),2)*BS30),2)) -> 0 | R30: =ROUND((ROUND((AE30*AV30*I30),2)*BS30),2) -> 0 | S30: =ROUND((ROUND((AF30*AV30*I30),2)*BA30),2) -> 0 | T30: =ROUND(CU30*I30,2) -> 0 | U30: =CV30*I30 -> 0 | V30: =CW30*I30 -> 0 | W30: =ROUND(CX30*I30,2) -> 0 | X30: =ROUND(CY30,2) -> 0 | Y30: =ROUND(CZ30,2) -> 0 | AA30: 56481265 | AB30: =ROUND((AC30+AD30+AF30),6) -> 9844.31 | AC30: =ROUND((ES30),6) -> 9844.31 | AD30: =ROUND((((ET30)-(EU30))+AE30),6) -> 0 | AE30: =ROUND((EU30),6) -> 0 | AF30: =ROUND((EV30),6) -> 0 | AG30: =ROUND((AP30),6) -> 0 | AH30: =(EW30) -> 0 | AI30: =(EX30) -> 0 | AJ30: =(AS30) -> 0 | AK30: 9844.31 | AL30: 9844.31 | AM30: 0 | AN30: 0 | AO30: 0 | AP30: 0 | AQ30: 0 | AR30: 0 | AS30: 0 | AT30: 92 | AU30: 52 | AV30: 1 | AW30: 1.002 | AZ30: 1 | BA30: 1 | BB30: 1 | BC30: 1 | BH30: 3 | BI30: 1 | BJ30: ТСН-2001.1 Доп. 79, Р. 1, о. 1, поз. 1121 | BM30: 90 | BN30: 0 | BP30: 0 | BQ30: 60 | BR30: 0 | BS30: 1 | BT30: 1 | BU30: 1 | BV30: 1 | BW30: 1 | BX30: 1 | BZ30: 92 | CA30: 52 | CE30: 30 | CF30: 0 | CG30: 0 | CM30: 0 | CO30: 0 | CP30: =(P30+Q30+S30) -> 241322.73 | CQ30: =ROUND((ROUND((AC30*AW30*1),2)*BC30),2) -> 9864 | CR30: =(ROUND((ROUND(((ET30)*AV30*1),2)*BB30),2)+ROUND((ROUND(((AE30-(EU30))*AV30*1),2)*BS30),2)) -> 0 | CS30: =ROUND((ROUND((AE30*AV30*1),2)*BS30),2) -> 0 | CT30: =ROUND((ROUND((AF30*AV30*1),2)*BA30),2) -> 0 | CU30: =AG30 -> 0 | CV30: =(AH30*AV30) -> 0 | CW30: =AI30 -> 0 | CX30: =AJ30 -> 0 | CY30: =(((S30+R30)*AT30)/100) -> 0 | CZ30: =(((S30+R30)*AU30)/100) -> 0 | DN30: 0 | DO30: 0 | DP30: 1 | DQ30: 1 | DU30: 1009 | DV30: т | DW30: т | DX30: 1000 | EE30: 55586525 | EF30: 60 | EG30: Ремонтно-строительные работы | EH30: 0 | EJ30: 1 | EK30: 90 | EL30: ТСН-2001.6-53. Стены | EM30: ТСН-2001.6-53-1 | EQ30: 0 | ER30: 9844.31 | ES30: 9844.31 | ET30: 0 | EU30: 0 | EV30: 0 | EW30: 0 | EX30: 0 | FQ30: 0 | FR30: 0 | FS30: 0 | FX30: 92 | FY30: 52 | GD30: 1 | GF30: 981881691 | GG30: 2 | GH30: 1 | GI30: -2 | GJ30: 0 | GK30: 0 | GL30: =ROUND(IF(AND(BH30=3,BI30=3,FS30<>0),P30,0),2) -> 0 | GM30: =ROUND(O30+X30+Y30,2)+GX30 -> 241322.73 | GN30: =IF(OR(BI30=0,BI30=1),GM30-GX30,0) -> 241322.73 | GO30: =IF(BI30=2,GM30-GX30,0) -> 0 | GP30: =IF(BI30=4,GM30-GX30,0) -> 0 | GR30: 0 | GS30: 3 | GT30: 0 | GV30: =ROUND((GT30),6) -> 0 | GW30: 1 | GX30: =ROUND(HC30*I30,2) -> 0 | HA30: 0 | HB30: 0 | HC30: =GV30*GW30 -> 0 | HS30: 0 | IK30: 0
A31: 18 | B31: 1 | C31: 5 | E31: 1,1 | F31: 1.1-1-1121 | G31: Уголок равнополочный, для строительных стальных конструкций, ширина полки более 70 мм, сталь С235, С245 | H31: т | I31: =I29*J31 -> 24.465 | J31: 0.95924249 | K31: 0.9592425 | O31: =ROUND(CP31,2) -> 1819573.4 | P31: =ROUND((ROUND((AC31*AW31*I31),2)*BC31),2) -> 1819573.4 | Q31: =(ROUND((ROUND(((ET31)*AV31*I31),2)*BB31),2)+ROUND((ROUND(((AE31-(EU31))*AV31*I31),2)*BS31),2)) -> 0 | R31: =ROUND((ROUND((AE31*AV31*I31),2)*BS31),2) -> 0 | S31: =ROUND((ROUND((AF31*AV31*I31),2)*BA31),2) -> 0 | T31: =ROUND(CU31*I31,2) -> 0 | U31: =CV31*I31 -> 0 | V31: =CW31*I31 -> 0 | W31: =ROUND(CX31*I31,2) -> 0 | X31: =ROUND(CY31,2) -> 0 | Y31: =ROUND(CZ31,2) -> 0 | AA31: 56481267 | AB31: =ROUND((AC31+AD31+AF31),6) -> 9844.31 | AC31: =ROUND((ES31),6) -> 9844.31 | AD31: =ROUND((((ET31)-(EU31))+AE31),6) -> 0 | AE31: =ROUND((EU31),6) -> 0 | AF31: =ROUND((EV31),6) -> 0 | AG31: =ROUND((AP31),6) -> 0 | AH31: =(EW31) -> 0 | AI31: =(EX31) -> 0 | AJ31: =(AS31) -> 0 | AK31: 9844.31 | AL31: 9844.31 | AM31: 0 | AN31: 0 | AO31: 0 | AP31: 0 | AQ31: 0 | AR31: 0 | AS31: 0 | AT31: 92 | AU31: 52 | AV31: 1 | AW31: 1.002 | AZ31: 1 | BA31: 1 | BB31: 1 | BC31: 7.54 | BH31: 3 | BI31: 1 | BJ31: ТСН-2001.1 Доп. 79, Р. 1, о. 1, поз. 1121 | BM31: 90 | BN31: 0 | BO31: 1.1-1-1121 | BP31: 1 | BQ31: 60 | BR31: 0 | BS31: 1 | BT31: 1 | BU31: 1 | BV31: 1 | BW31: 1 | BX31: 1 | BZ31: 92 | CA31: 52 | CE31: 30 | CF31: 0 | CG31: 0 | CM31: 0 | CO31: 0 | CP31: =(P31+Q31+S31) -> 1819573.4 | CQ31: =ROUND((ROUND((AC31*AW31*1),2)*BC31),2) -> 74374.56 | CR31: =(ROUND((ROUND(((ET31)*AV31*1),2)*BB31),2)+ROUND((ROUND(((AE31-(EU31))*AV31*1),2)*BS31),2)) -> 0 | CS31: =ROUND((ROUND((AE31*AV31*1),2)*BS31),2) -> 0 | CT31: =ROUND((ROUND((AF31*AV31*1),2)*BA31),2) -> 0 | CU31: =AG31 -> 0 | CV31: =(AH31*AV31) -> 0 | CW31: =AI31 -> 0 | CX31: =AJ31 -> 0 | CY31: =(((S31+R31)*AT31)/100) -> 0 | CZ31: =(((S31+R31)*AU31)/100) -> 0 | DN31: 0 | DO31: 0 | DP31: 1 | DQ31: 1 | DU31: 1009 | DV31: т | DW31: т | DX31: 1000 | EE31: 55586525 | EF31: 60 | EG31: Ремонтно-строительные работы | EH31: 0 | EJ31: 1 | EK31: 90 | EL31: ТСН-2001.6-53. Стены | EM31: ТСН-2001.6-53-1 | EQ31: 0 | ER31: 9844.31 | ES31: 9844.31 | ET31: 0 | EU31: 0 | EV31: 0 | EW31: 0 | EX31: 0 | FQ31: 0 | FR31: 0 | FS31: 0 | FX31: 92 | FY31: 52 | GD31: 1 | GF31: 981881691 | GG31: 2 | GH31: 1 | GI31: 2 | GJ31: 0 | GK31: 0 | GL31: =ROUND(IF(AND(BH31=3,BI31=3,FS31<>0),P31,0),2) -> 0 | GM31: =ROUND(O31+X31+Y31,2)+GX31 -> 1819573.4 | GN31: =IF(OR(BI31=0,BI31=1),GM31-GX31,0) -> 1819573.4 | GO31: =IF(BI31=2,GM31-GX31,0) -> 0 | GP31: =IF(BI31=4,GM31-GX31,0) -> 0 | GR31: 0 | GS31: 3 | GT31: 0 | GV31: =ROUND((GT31),6) -> 0 | GW31: 1 | GX31: =ROUND(HC31*I31,2) -> 0 | HA31: 0 | HB31: 0 | HC31: =GV31*GW31 -> 0 | HS31: 0 | IK31: 0
A32: 18 | B32: 1 | C32: 1 | E32: 1,2 | F32: 1.1-1-1105 | G32: Прокат листовой из стали С235, С245 для строительных стальных конструкций, толщина более 3 мм | H32: т | I32: =I28*J32 -> 1.0395 | J32: 0.040757513 | K32: 0.0407575 | O32: =ROUND(CP32,2) -> 6790.26 | P32: =ROUND((ROUND((AC32*AW32*I32),2)*BC32),2) -> 6790.26 | Q32: =(ROUND((ROUND(((ET32)*AV32*I32),2)*BB32),2)+ROUND((ROUND(((AE32-(EU32))*AV32*I32),2)*BS32),2)) -> 0 | R32: =ROUND((ROUND((AE32*AV32*I32),2)*BS32),2) -> 0 | S32: =ROUND((ROUND((AF32*AV32*I32),2)*BA32),2) -> 0 | T32: =ROUND(CU32*I32,2) -> 0 | U32: =CV32*I32 -> 0 | V32: =CW32*I32 -> 0 | W32: =ROUND(CX32*I32,2) -> 0 | X32: =ROUND(CY32,2) -> 0 | Y32: =ROUND(CZ32,2) -> 0 | AA32: 56481265 | AB32: =ROUND((AC32+AD32+AF32),6) -> 6519.2 | AC32: =ROUND((ES32),6) -> 6519.2 | AD32: =ROUND((((ET32)-(EU32))+AE32),6) -> 0 | AE32: =ROUND((EU32),6) -> 0 | AF32: =ROUND((EV32),6) -> 0 | AG32: =ROUND((AP32),6) -> 0 | AH32: =(EW32) -> 0 | AI32: =(EX32) -> 0 | AJ32: =(AS32) -> 0 | AK32: 6519.2 | AL32: 6519.2 | AM32: 0 | AN32: 0 | AO32: 0 | AP32: 0 | AQ32: 0 | AR32: 0 | AS32: 0 | AT32: 92 | AU32: 52 | AV32: 1 | AW32: 1.002 | AZ32: 1 | BA32: 1 | BB32: 1 | BC32: 1 | BH32: 3 | BI32: 1 | BJ32: ТСН-2001.1 Доп. 79, Р. 1, о. 1, поз. 1105 | BM32: 90 | BN32: 0 | BP32: 0 | BQ32: 60 | BR32: 0 | BS32: 1 | BT32: 1 | BU32: 1 | BV32: 1 | BW32: 1 | BX32: 1 | BZ32: 92 | CA32: 52 | CE32: 30 | CF32: 0 | CG32: 0 | CM32: 0 | CO32: 0 | CP32: =(P32+Q32+S32) -> 6790.26 | CQ32: =ROUND((ROUND((AC32*AW32*1),2)*BC32),2) -> 6532.24 | CR32: =(ROUND((ROUND(((ET32)*AV32*1),2)*BB32),2)+ROUND((ROUND(((AE32-(EU32))*AV32*1),2)*BS32),2)) -> 0 | CS32: =ROUND((ROUND((AE32*AV32*1),2)*BS32),2) -> 0 | CT32: =ROUND((ROUND((AF32*AV32*1),2)*BA32),2) -> 0 | CU32: =AG32 -> 0 | CV32: =(AH32*AV32) -> 0 | CW32: =AI32 -> 0 | CX32: =AJ32 -> 0 | CY32: =(((S32+R32)*AT32)/100) -> 0 | CZ32: =(((S32+R32)*AU32)/100) -> 0 | DN32: 0 | DO32: 0 | DP32: 1 | DQ32: 1 | DU32: 1009 | DV32: т | DW32: т | DX32: 1000 | EE32: 55586525 | EF32: 60 | EG32: Ремонтно-строительные работы | EH32: 0 | EJ32: 1 | EK32: 90 | EL32: ТСН-2001.6-53. Стены | EM32: ТСН-2001.6-53-1 | EQ32: 0 | ER32: 6519.2 | ES32: 6519.2 | ET32: 0 | EU32: 0 | EV32: 0 | EW32: 0 | EX32: 0 | FQ32: 0 | FR32: 0 | FS32: 0 | FX32: 92 | FY32: 52 | GD32: 1 | GF32: -1891961884 | GG32: 2 | GH32: 1 | GI32: -2 | GJ32: 0 | GK32: 0 | GL32: =ROUND(IF(AND(BH32=3,BI32=3,FS32<>0),P32,0),2) -> 0 | GM32: =ROUND(O32+X32+Y32,2)+GX32 -> 6790.26 | GN32: =IF(OR(BI32=0,BI32=1),GM32-GX32,0) -> 6790.26 | GO32: =IF(BI32=2,GM32-GX32,0) -> 0 | GP32: =IF(BI32=4,GM32-GX32,0) -> 0 | GR32: 0 | GS32: 3 | GT32: 0 | GV32: =ROUND((GT32),6) -> 0 | GW32: 1 | GX32: =ROUND(HC32*I32,2) -> 0 | HA32: 0 | HB32: 0 | HC32: =GV32*GW32 -> 0 | HS32: 0 | IK32: 0
A33: 18 | B33: 1 | C33: 4 | E33: 1,2 | F33: 1.1-1-1105 | G33: Прокат листовой из стали С235, С245 для строительных стальных конструкций, толщина более 3 мм | H33: т | I33: =I29*J33 -> 1.0395 | J33: 0.040757513 | K33: 0.0407575 | O33: =ROUND(CP33,2) -> 68717.43 | P33: =ROUND((ROUND((AC33*AW33*I33),2)*BC33),2) -> 68717.43 | Q33: =(ROUND((ROUND(((ET33)*AV33*I33),2)*BB33),2)+ROUND((ROUND(((AE33-(EU33))*AV33*I33),2)*BS33),2)) -> 0 | R33: =ROUND((ROUND((AE33*AV33*I33),2)*BS33),2) -> 0 | S33: =ROUND((ROUND((AF33*AV33*I33),2)*BA33),2) -> 0 | T33: =ROUND(CU33*I33,2) -> 0 | U33: =CV33*I33 -> 0 | V33: =CW33*I33 -> 0 | W33: =ROUND(CX33*I33,2) -> 0 | X33: =ROUND(CY33,2) -> 0 | Y33: =ROUND(CZ33,2) -> 0 | AA33: 56481267 | AB33: =ROUND((AC33+AD33+AF33),6) -> 6519.2 | AC33: =ROUND((ES33),6) -> 6519.2 | AD33: =ROUND((((ET33)-(EU33))+AE33),6) -> 0 | AE33: =ROUND((EU33),6) -> 0 | AF33: =ROUND((EV33),6) -> 0 | AG33: =ROUND((AP33),6) -> 0 | AH33: =(EW33) -> 0 | AI33: =(EX33) -> 0 | AJ33: =(AS33) -> 0 | AK33: 6519.2 | AL33: 6519.2 | AM33: 0 | AN33: 0 | AO33: 0 | AP33: 0 | AQ33: 0 | AR33: 0 | AS33: 0 | AT33: 92 | AU33: 52 | AV33: 1 | AW33: 1.002 | AZ33: 1 | BA33: 1 | BB33: 1 | BC33: 10.12 | BH33: 3 | BI33: 1 | BJ33: ТСН-2001.1 Доп. 79, Р. 1, о. 1, поз. 1105 | BM33: 90 | BN33: 0 | BO33: 1.1-1-1105 | BP33: 1 | BQ33: 60 | BR33: 0 | BS33: 1 | BT33: 1 | BU33: 1 | BV33: 1 | BW33: 1 | BX33: 1 | BZ33: 92 | CA33: 52 | CE33: 30 | CF33: 0 | CG33: 0 | CM33: 0 | CO33: 0 | CP33: =(P33+Q33+S33) -> 68717.43 | CQ33: =ROUND((ROUND((AC33*AW33*1),2)*BC33),2) -> 66106.27 | CR33: =(ROUND((ROUND(((ET33)*AV33*1),2)*BB33),2)+ROUND((ROUND(((AE33-(EU33))*AV33*1),2)*BS33),2)) -> 0 | CS33: =ROUND((ROUND((AE33*AV33*1),2)*BS33),2) -> 0 | CT33: =ROUND((ROUND((AF33*AV33*1),2)*BA33),2) -> 0 | CU33: =AG33 -> 0 | CV33: =(AH33*AV33) -> 0 | CW33: =AI33 -> 0 | CX33: =AJ33 -> 0 | CY33: =(((S33+R33)*AT33)/100) -> 0 | CZ33: =(((S33+R33)*AU33)/100) -> 0 | DN33: 0 | DO33: 0 | DP33: 1 | DQ33: 1 | DU33: 1009 | DV33: т | DW33: т | DX33: 1000 | EE33: 55586525 | EF33: 60 | EG33: Ремонтно-строительные работы | EH33: 0 | EJ33: 1 | EK33: 90 | EL33: ТСН-2001.6-53. Стены | EM33: ТСН-2001.6-53-1 | EQ33: 0 | ER33: 6519.2 | ES33: 6519.2 | ET33: 0 | EU33: 0 | EV33: 0 | EW33: 0 | EX33: 0 | FQ33: 0 | FR33: 0 | FS33: 0 | FX33: 92 | FY33: 52 | GD33: 1 | GF33: -1891961884 | GG33: 2 | GH33: 1 | GI33: 2 | GJ33: 0 | GK33: 0 | GL33: =ROUND(IF(AND(BH33=3,BI33=3,FS33<>0),P33,0),2) -> 0 | GM33: =ROUND(O33+X33+Y33,2)+GX33 -> 68717.43 | GN33: =IF(OR(BI33=0,BI33=1),GM33-GX33,0) -> 68717.43 | GO33: =IF(BI33=2,GM33-GX33,0) -> 0 | GP33: =IF(BI33=4,GM33-GX33,0) -> 0 | GR33: 0 | GS33: 3 | GT33: 0 | GV33: =ROUND((GT33),6) -> 0 | GW33: 1 | GX33: =ROUND(HC33*I33,2) -> 0 | HA33: 0 | HB33: 0 | HC33: =GV33*GW33 -> 0 | HS33: 0 | IK33: 0
A34: 18 | B34: 1 | C34: 3 | E34: 1,3 | F34: 1.7-5-220 | G34: Шпилька резьбовая, стальная, оцинкованная, с заостренным концом, в комплекте с шайбой и гайкой, М16x190 мм | H34: шт. | I34: =I28*J34 -> 1470 | J34: 57.636888 | K34: 57.636888 | O34: =ROUND(CP34,2) -> 43893.61 | P34: =ROUND((ROUND((AC34*AW34*I34),2)*BC34),2) -> 43893.61 | Q34: =(ROUND((ROUND(((ET34)*AV34*I34),2)*BB34),2)+ROUND((ROUND(((AE34-(EU34))*AV34*I34),2)*BS34),2)) -> 0 | R34: =ROUND((ROUND((AE34*AV34*I34),2)*BS34),2) -> 0 | S34: =ROUND((ROUND((AF34*AV34*I34),2)*BA34),2) -> 0 | T34: =ROUND(CU34*I34,2) -> 0 | U34: =CV34*I34 -> 0 | V34: =CW34*I34 -> 0 | W34: =ROUND(CX34*I34,2) -> 0 | X34: =ROUND(CY34,2) -> 0 | Y34: =ROUND(CZ34,2) -> 0 | AA34: 56481265 | AB34: =ROUND((AC34+AD34+AF34),6) -> 29.8 | AC34: =ROUND((ES34),6) -> 29.8 | AD34: =ROUND((((ET34)-(EU34))+AE34),6) -> 0 | AE34: =ROUND((EU34),6) -> 0 | AF34: =ROUND((EV34),6) -> 0 | AG34: =ROUND((AP34),6) -> 0 | AH34: =(EW34) -> 0 | AI34: =(EX34) -> 0 | AJ34: =(AS34) -> 0 | AK34: 29.8 | AL34: 29.8 | AM34: 0 | AN34: 0 | AO34: 0 | AP34: 0 | AQ34: 0 | AR34: 0 | AS34: 0 | AT34: 92 | AU34: 52 | AV34: 1 | AW34: 1.002 | AZ34: 1 | BA34: 1 | BB34: 1 | BC34: 1 | BH34: 3 | BI34: 1 | BJ34: ТСН-2001.1 Доп. 53, Р. 7, о. 5, поз. 220 | BM34: 90 | BN34: 0 | BP34: 0 | BQ34: 60 | BR34: 0 | BS34: 1 | BT34: 1 | BU34: 1 | BV34: 1 | BW34: 1 | BX34: 1 | BZ34: 92 | CA34: 52 | CE34: 30 | CF34: 0 | CG34: 0 | CM34: 0 | CO34: 0 | CP34: =(P34+Q34+S34) -> 43893.61 | CQ34: =ROUND((ROUND((AC34*AW34*1),2)*BC34),2) -> 29.86 | CR34: =(ROUND((ROUND(((ET34)*AV34*1),2)*BB34),2)+ROUND((ROUND(((AE34-(EU34))*AV34*1),2)*BS34),2)) -> 0 | CS34: =ROUND((ROUND((AE34*AV34*1),2)*BS34),2) -> 0 | CT34: =ROUND((ROUND((AF34*AV34*1),2)*BA34),2) -> 0 | CU34: =AG34 -> 0 | CV34: =(AH34*AV34) -> 0 | CW34: =AI34 -> 0 | CX34: =AJ34 -> 0 | CY34: =(((S34+R34)*AT34)/100) -> 0 | CZ34: =(((S34+R34)*AU34)/100) -> 0 | DN34: 0 | DO34: 0 | DP34: 1 | DQ34: 1 | DU34: 1010 | DV34: шт. | DW34: шт. | DX34: 1 | EE34: 55586525 | EF34: 60 | EG34: Ремонтно-строительные работы | EH34: 0 | EJ34: 1 | EK34: 90 | EL34: ТСН-2001.6-53. Стены | EM34: ТСН-2001.6-53-1 | EQ34: 0 | ER34: 29.8 | ES34: 29.8 | ET34: 0 | EU34: 0 | EV34: 0 | EW34: 0 | EX34: 0 | FQ34: 0 | FR34: 0 | FS34: 0 | FX34: 92 | FY34: 52 | GD34: 1 | GF34: 2014927073 | GG34: 2 | GH34: 1 | GI34: -2 | GJ34: 0 | GK34: 0 | GL34: =ROUND(IF(AND(BH34=3,BI34=3,FS34<>0),P34,0),2) -> 0 | GM34: =ROUND(O34+X34+Y34,2)+GX34 -> 43893.61 | GN34: =IF(OR(BI34=0,BI34=1),GM34-GX34,0) -> 43893.61 | GO34: =IF(BI34=2,GM34-GX34,0) -> 0 | GP34: =IF(BI34=4,GM34-GX34,0) -> 0 | GR34: 0 | GS34: 3 | GT34: 0 | GV34: =ROUND((GT34),6) -> 0 | GW34: 1 | GX34: =ROUND(HC34*I34,2) -> 0 | HA34: 0 | HB34: 0 | HC34: =GV34*GW34 -> 0 | HS34: 0 | IK34: 0
A35: 18 | B35: 1 | C35: 6 | E35: 1,3 | F35: 1.7-5-220 | G35: Шпилька резьбовая, стальная, оцинкованная, с заостренным концом, в комплекте с шайбой и гайкой, М16x190 мм | H35: шт. | I35: =I29*J35 -> 1470 | J35: 57.636888 | K35: 57.636888 | O35: =ROUND(CP35,2) -> 525406.51 | P35: =ROUND((ROUND((AC35*AW35*I35),2)*BC35),2) -> 525406.51 | Q35: =(ROUND((ROUND(((ET35)*AV35*I35),2)*BB35),2)+ROUND((ROUND(((AE35-(EU35))*AV35*I35),2)*BS35),2)) -> 0 | R35: =ROUND((ROUND((AE35*AV35*I35),2)*BS35),2) -> 0 | S35: =ROUND((ROUND((AF35*AV35*I35),2)*BA35),2) -> 0 | T35: =ROUND(CU35*I35,2) -> 0 | U35: =CV35*I35 -> 0 | V35: =CW35*I35 -> 0 | W35: =ROUND(CX35*I35,2) -> 0 | X35: =ROUND(CY35,2) -> 0 | Y35: =ROUND(CZ35,2) -> 0 | AA35: 56481267 | AB35: =ROUND((AC35+AD35+AF35),6) -> 29.8 | AC35: =ROUND((ES35),6) -> 29.8 | AD35: =ROUND((((ET35)-(EU35))+AE35),6) -> 0 | AE35: =ROUND((EU35),6) -> 0 | AF35: =ROUND((EV35),6) -> 0 | AG35: =ROUND((AP35),6) -> 0 | AH35: =(EW35) -> 0 | AI35: =(EX35) -> 0 | AJ35: =(AS35) -> 0 | AK35: 29.8 | AL35: 29.8 | AM35: 0 | AN35: 0 | AO35: 0 | AP35: 0 | AQ35: 0 | AR35: 0 | AS35: 0 | AT35: 92 | AU35: 52 | AV35: 1 | AW35: 1.002 | AZ35: 1 | BA35: 1 | BB35: 1 | BC35: 11.97 | BH35: 3 | BI35: 1 | BJ35: ТСН-2001.1 Доп. 53, Р. 7, о. 5, поз. 220 | BM35: 90 | BN35: 0 | BO35: 1.7-5-220 | BP35: 1 | BQ35: 60 | BR35: 0 | BS35: 1 | BT35: 1 | BU35: 1 | BV35: 1 | BW35: 1 | BX35: 1 | BZ35: 92 | CA35: 52 | CE35: 30 | CF35: 0 | CG35: 0 | CM35: 0 | CO35: 0 | CP35: =(P35+Q35+S35) -> 525406.51 | CQ35: =ROUND((ROUND((AC35*AW35*1),2)*BC35),2) -> 357.42 | CR35: =(ROUND((ROUND(((ET35)*AV35*1),2)*BB35),2)+ROUND((ROUND(((AE35-(EU35))*AV35*1),2)*BS35),2)) -> 0 | CS35: =ROUND((ROUND((AE35*AV35*1),2)*BS35),2) -> 0 | CT35: =ROUND((ROUND((AF35*AV35*1),2)*BA35),2) -> 0 | CU35: =AG35 -> 0 | CV35: =(AH35*AV35) -> 0 | CW35: =AI35 -> 0 | CX35: =AJ35 -> 0 | CY35: =(((S35+R35)*AT35)/100) -> 0 | CZ35: =(((S35+R35)*AU35)/100) -> 0 | DN35: 0 | DO35: 0 | DP35: 1 | DQ35: 1 | DU35: 1010 | DV35: шт. | DW35: шт. | DX35: 1 | EE35: 55586525 | EF35: 60 | EG35: Ремонтно-строительные работы | EH35: 0 | EJ35: 1 | EK35: 90 | EL35: ТСН-2001.6-53. Стены | EM35: ТСН-2001.6-53-1 | EQ35: 0 | ER35: 29.8 | ES35: 29.8 | ET35: 0 | EU35: 0 | EV35: 0 | EW35: 0 | EX35: 0 | FQ35: 0 | FR35: 0 | FS35: 0 | FX35: 92 | FY35: 52 | GD35: 1 | GF35: 2014927073 | GG35: 2 | GH35: 1 | GI35: 2 | GJ35: 0 | GK35: 0 | GL35: =ROUND(IF(AND(BH35=3,BI35=3,FS35<>0),P35,0),2) -> 0 | GM35: =ROUND(O35+X35+Y35,2)+GX35 -> 525406.51 | GN35: =IF(OR(BI35=0,BI35=1),GM35-GX35,0) -> 525406.51 | GO35: =IF(BI35=2,GM35-GX35,0) -> 0 | GP35: =IF(BI35=4,GM35-GX35,0) -> 0 | GR35: 0 | GS35: 3 | GT35: 0 | GV35: =ROUND((GT35),6) -> 0 | GW35: 1 | GX35: =ROUND(HC35*I35,2) -> 0 | HA35: 0 | HB35: 0 | HC35: =GV35*GW35 -> 0 | HS35: 0 | IK35: 0
A36: 17 | B36: 1 | C36: =ROW(SmtRes!A7) -> 7 | E36: 2 | F36: 3.13-9-2 | G36: Огрунтовка металлических поверхностей грунтовкой ГФ-021 за один раз | H36: 100 м2 | I36: =ROUND((70.9*26.3+38.5*26.3+109.3*33+7.4*33+7.2*32.1+2.7*32.1+6.9*33)/1000/100*105,9) -> 7.6375005 | J36: 0 | K36: =ROUND((70.9*26.3+38.5*26.3+109.3*33+7.4*33+7.2*32.1+2.7*32.1+6.9*33)/1000/100*105,9) -> 7.6375005 | O36: =ROUND(CP36,2) -> 931.69 | P36: =ROUND((ROUND((AC36*AW36*I36),2)*BC36),2) -> 72.25 | Q36: =(ROUND((ROUND(((((ET36*1.25)*1.1))*AV36*I36),2)*BB36),2)+ROUND((ROUND(((AE36-(((EU36*1.25)*1.1)))*AV36*I36),2)*BS36),2)) -> 143.24 | R36: =ROUND((ROUND((AE36*AV36*I36),2)*BS36),2) -> 2.63 | S36: =ROUND((ROUND((AF36*AV36*I36),2)*BA36),2) -> 716.2 | T36: =ROUND(CU36*I36,2) -> 0 | U36: =CV36*I36 -> 51.302236 | V36: =CW36*I36 -> 0 | W36: =ROUND(CX36*I36,2) -> 0 | X36: =ROUND(CY36,2) -> 718.83 | Y36: =ROUND(CZ36,2) -> 460.05 | AA36: 56481265 | AB36: =ROUND((AC36+AD36+AF36),6) -> 121.98945 | AC36: =ROUND((ES36),6) -> 9.46 | AD36: =ROUND((((((ET36*1.25)*1.1))-(((EU36*1.25)*1.1)))+AE36),6) -> 18.755 | AE36: =ROUND((((EU36*1.25)*1.1)),6) -> 0.34375 | AF36: =ROUND((((EV36*1.15)*1.1)),6) -> 93.77445 | AG36: =ROUND((AP36),6) -> 0 | AH36: =(((EW36*1.15)*1.1)) -> 6.71715 | AI36: =(((EX36*1.25)*1.1)) -> 0 | AJ36: =(AS36) -> 0 | AK36: 97.23 | AL36: 9.46 | AM36: 13.64 | AN36: 0.25 | AO36: 74.13 | AP36: 0 | AQ36: 5.31 | AR36: 0 | AS36: 0 | AT36: 100 | AU36: 64 | AV36: 1 | AW36: 1 | AZ36: 1 | BA36: 1 | BB36: 1 | BC36: 1 | BH36: 0 | BI36: 1 | BJ36: ТСН-2001.3 Доп. 71, Сб. 13, т. 9, поз. 2 | BM36: 97 | BN36: 0 | BP36: 0 | BQ36: 60 | BR36: 0 | BS36: 1 | BT36: 1 | BU36: 1 | BV36: 1 | BW36: 1 | BX36: 1 | BZ36: 100 | CA36: 64 | CE36: 30 | CF36: 0 | CG36: 0 | CM36: 0 | CO36: 0 | CP36: =(P36+Q36+S36) -> 931.69 | CQ36: =ROUND((ROUND((AC36*AW36*1),2)*BC36),2) -> 9.46 | CR36: =(ROUND((ROUND(((((ET36*1.25)*1.1))*AV36*1),2)*BB36),2)+ROUND((ROUND(((AE36-(((EU36*1.25)*1.1)))*AV36*1),2)*BS36),2)) -> 18.76 | CS36: =ROUND((ROUND((AE36*AV36*1),2)*BS36),2) -> 0.34 | CT36: =ROUND((ROUND((AF36*AV36*1),2)*BA36),2) -> 93.77 | CU36: =AG36 -> 0 | CV36: =(AH36*AV36) -> 6.71715 | CW36: =AI36 -> 0 | CX36: =AJ36 -> 0 | CY36: =(((S36+R36)*AT36)/100) -> 718.83 | CZ36: =(((S36+R36)*AU36)/100) -> 460.0512 | DE36: *1,25)*1,1 | DF36: *1,25)*1,1 | DG36: *1,15)*1,1 | DI36: *1,15)*1,1 | DJ36: *1,25)*1,1 | DN36: 0 | DO36: 0 | DP36: 1.047 | DQ36: 1 | DU36: 1005 | DV36: 100 м2 | DW36: 100 м2 | DX36: 100 | EE36: 55586532 | EF36: 60 | EG36: Ремонтно-строительные работы | EH36: 0 | EJ36: 1 | EK36: 97 | EL36: ТСН-2001.6-60. Печные работы | EM36: ТСН-2001.6-60-1 | EO36: Поправка: О.П. п.3.4. 6 Поправка: О.П. п.3.4.30.в | EQ36: 0 | ER36: 97.23 | ES36: 9.46 | ET36: 13.64 | EU36: 0.25 | EV36: 74.13 | EW36: 5.31 | EX36: 0 | EY36: 0 | FQ36: 0 | FR36: 0 | FS36: 0 | FX36: 100 | FY36: 64 | GD36: 1 | GF36: -673576059 | GG36: 2 | GH36: 1 | GI36: -2 | GJ36: 0 | GK36: 0 | GL36: =ROUND(IF(AND(BH36=3,BI36=3,FS36<>0),P36,0),2) -> 0 | GM36: =ROUND(O36+X36+Y36,2)+GX36 -> 2110.57 | GN36: =IF(OR(BI36=0,BI36=1),GM36-GX36,0) -> 2110.57 | GO36: =IF(BI36=2,GM36-GX36,0) -> 0 | GP36: =IF(BI36=4,GM36-GX36,0) -> 0 | GR36: 0 | GS36: 3 | GT36: 0 | GV36: =ROUND((GT36),6) -> 0 | GW36: 1 | GX36: =ROUND(HC36*I36,2) -> 0 | HA36: 0 | HB36: 0 | HC36: =GV36*GW36 -> 0 | HS36: 0 | IK36: 0
A37: 17 | B37: 1 | C37: =ROW(SmtRes!A8) -> 8 | E37: 2 | F37: 3.13-9-2 | G37: Огрунтовка металлических поверхностей грунтовкой ГФ-021 за один раз | H37: 100 м2 | I37: =ROUND((70.9*26.3+38.5*26.3+109.3*33+7.4*33+7.2*32.1+2.7*32.1+6.9*33)/1000/100*105,9) -> 7.6375005 | J37: 0 | K37: =ROUND((70.9*26.3+38.5*26.3+109.3*33+7.4*33+7.2*32.1+2.7*32.1+6.9*33)/1000/100*105,9) -> 7.6375005 | O37: =ROUND(CP37,2) -> 39764.55 | P37: =ROUND((ROUND((AC37*AW37*I37),2)*BC37),2) -> 2330.06 | Q37: =(ROUND((ROUND(((((ET37*1.25)*1.1))*AV37*I37),2)*BB37),2)+ROUND((ROUND(((AE37-(((EU37*1.25)*1.1)))*AV37*I37),2)*BS37),2)) -> 1576.18 | R37: =ROUND((ROUND((AE37*AV37*I37),2)*BS37),2) -> 131.51 | S37: =ROUND((ROUND((AF37*AV37*I37),2)*BA37),2) -> 35858.31 | T37: =ROUND(CU37*I37,2) -> 0 | U37: =CV37*I37 -> 53.713442 | V37: =CW37*I37 -> 0 | W37: =ROUND(CX37*I37,2) -> 0 | X37: =ROUND(CY37,2) -> 32030.94 | Y37: =ROUND(CZ37,2) -> 15835.52 | AA37: 56481267 | AB37: =ROUND((AC37+AD37+AF37),6) -> 121.98945 | AC37: =ROUND((ES37),6) -> 9.46 | AD37: =ROUND((((((ET37*1.25)*1.1))-(((EU37*1.25)*1.1)))+AE37),6) -> 18.755 | AE37: =ROUND((((EU37*1.25)*1.1)),6) -> 0.34375 | AF37: =ROUND((((EV37*1.15)*1.1)),6) -> 93.77445 | AG37: =ROUND((AP37),6) -> 0 | AH37: =(((EW37*1.15)*1.1)) -> 6.71715 | AI37: =(((EX37*1.25)*1.1)) -> 0 | AJ37: =(AS37) -> 0 | AK37: 97.23 | AL37: 9.46 | AM37: 13.64 | AN37: 0.25 | AO37: 74.13 | AP37: 0 | AQ37: 5.31 | AR37: 0 | AS37: 0 | AT37: 89 | AU37: 44 | AV37: 1.047 | AW37: 1 | AZ37: 1 | BA37: 47.82 | BB37: 10.51 | BC37: 32.25 | BH37: 0 | BI37: 1 | BJ37: ТСН-2001.3 Доп. 71, Сб. 13, т. 9, поз. 2 | BM37: 97 | BN37: 0 | BO37: 3.13-9-2 | BP37: 1 | BQ37: 60 | BR37: 0 | BS37: 47.82 | BT37: 1 | BU37: 1 | BV37: 1 | BW37: 1 | BX37: 1 | BZ37: 89 | CA37: 44 | CE37: 30 | CF37: 0 | CG37: 0 | CM37: 0 | CO37: 0 | CP37: =(P37+Q37+S37) -> 39764.55 | CQ37: =ROUND((ROUND((AC37*AW37*1),2)*BC37),2) -> 305.09 | CR37: =(ROUND((ROUND(((((ET37*1.25)*1.1))*AV37*1),2)*BB37),2)+ROUND((ROUND(((AE37-(((EU37*1.25)*1.1)))*AV37*1),2)*BS37),2)) -> 206.42 | CS37: =ROUND((ROUND((AE37*AV37*1),2)*BS37),2) -> 17.22 | CT37: =ROUND((ROUND((AF37*AV37*1),2)*BA37),2) -> 4694.97 | CU37: =AG37 -> 0 | CV37: =(AH37*AV37) -> 7.032856 | CW37: =AI37 -> 0 | CX37: =AJ37 -> 0 | CY37: =(((S37+R37)*AT37)/100) -> 32030.94 | CZ37: =(((S37+R37)*AU37)/100) -> 15835.521 | DE37: *1,25)*1,1 | DF37: *1,25)*1,1 | DG37: *1,15)*1,1 | DI37: *1,15)*1,1 | DJ37: *1,25)*1,1 | DN37: 0 | DO37: 0 | DP37: 1 | DQ37: 1 | DU37: 1005 | DV37: 100 м2 | DW37: 100 м2 | DX37: 100 | EE37: 55586532 | EF37: 60 | EG37: Ремонтно-строительные работы | EH37: 0 | EJ37: 1 | EK37: 97 | EL37: ТСН-2001.6-60. Печные работы | EM37: ТСН-2001.6-60-1 | EO37: Поправка: О.П. п.3.4. 6 Поправка: О.П. п.3.4.30.в | EQ37: 0 | ER37: 97.23 | ES37: 9.46 | ET37: 13.64 | EU37: 0.25 | EV37: 74.13 | EW37: 5.31 | EX37: 0 | EY37: 0 | FQ37: 0 | FR37: 0 | FS37: 0 | FX37: 89 | FY37: 44 | GD37: 1 | GF37: -673576059 | GG37: 2 | GH37: 1 | GI37: 2 | GJ37: 0 | GK37: 0 | GL37: =ROUND(IF(AND(BH37=3,BI37=3,FS37<>0),P37,0),2) -> 0 | GM37: =ROUND(O37+X37+Y37,2)+GX37 -> 87631.01 | GN37: =IF(OR(BI37=0,BI37=1),GM37-GX37,0) -> 87631.01 | GO37: =IF(BI37=2,GM37-GX37,0) -> 0 | GP37: =IF(BI37=4,GM37-GX37,0) -> 0 | GR37: 0 | GS37: 0 | GT37: 0 | GV37: =ROUND((GT37),6) -> 0 | GW37: 1 | GX37: =ROUND(HC37*I37,2) -> 0 | HA37: 0 | HB37: 0 | HC37: =GV37*GW37 -> 0 | HS37: 0 | IK37: 0
A38: 18 | B38: 1 | C38: 7 | E38: 2,1 | F38: 1.1-1-165 | G38: Грунтовка глифталевая, типа ГФ-021 | H38: т | I38: =I36*J38 -> 0.068738 | J38: 0.0090000649 | K38: 0.009 | O38: =ROUND(CP38,2) -> 1282.69 | P38: =ROUND((ROUND((AC38*AW38*I38),2)*BC38),2) -> 1282.69 | Q38: =(ROUND((ROUND(((ET38)*AV38*I38),2)*BB38),2)+ROUND((ROUND(((AE38-(EU38))*AV38*I38),2)*BS38),2)) -> 0 | R38: =ROUND((ROUND((AE38*AV38*I38),2)*BS38),2) -> 0 | S38: =ROUND((ROUND((AF38*AV38*I38),2)*BA38),2) -> 0 | T38: =ROUND(CU38*I38,2) -> 0 | U38: =CV38*I38 -> 0 | V38: =CW38*I38 -> 0 | W38: =ROUND(CX38*I38,2) -> 0 | X38: =ROUND(CY38,2) -> 0 | Y38: =ROUND(CZ38,2) -> 0 | AA38: 56481265 | AB38: =ROUND((AC38+AD38+AF38),6) -> 18660.61 | AC38: =ROUND((ES38),6) -> 18660.61 | AD38: =ROUND((((ET38)-(EU38))+AE38),6) -> 0 | AE38: =ROUND((EU38),6) -> 0 | AF38: =ROUND((EV38),6) -> 0 | AG38: =ROUND((AP38),6) -> 0 | AH38: =(EW38) -> 0 | AI38: =(EX38) -> 0 | AJ38: =(AS38) -> 0 | AK38: 18660.61 | AL38: 18660.61 | AM38: 0 | AN38: 0 | AO38: 0 | AP38: 0 | AQ38: 0 | AR38: 0 | AS38: 0 | AT38: 100 | AU38: 64 | AV38: 1 | AW38: 1 | AZ38: 1 | BA38: 1 | BB38: 1 | BC38: 1 | BH38: 3 | BI38: 1 | BJ38: ТСН-2001.1 Доп. 67, Р. 1, о. 1, поз. 165 | BM38: 97 | BN38: 0 | BP38: 0 | BQ38: 60 | BR38: 0 | BS38: 1 | BT38: 1 | BU38: 1 | BV38: 1 | BW38: 1 | BX38: 1 | BZ38: 100 | CA38: 64 | CE38: 30 | CF38: 0 | CG38: 0 | CM38: 0 | CO38: 0 | CP38: =(P38+Q38+S38) -> 1282.69 | CQ38: =ROUND((ROUND((AC38*AW38*1),2)*BC38),2) -> 18660.61 | CR38: =(ROUND((ROUND(((ET38)*AV38*1),2)*BB38),2)+ROUND((ROUND(((AE38-(EU38))*AV38*1),2)*BS38),2)) -> 0 | CS38: =ROUND((ROUND((AE38*AV38*1),2)*BS38),2) -> 0 | CT38: =ROUND((ROUND((AF38*AV38*1),2)*BA38),2) -> 0 | CU38: =AG38 -> 0 | CV38: =(AH38*AV38) -> 0 | CW38: =AI38 -> 0 | CX38: =AJ38 -> 0 | CY38: =(((S38+R38)*AT38)/100) -> 0 | CZ38: =(((S38+R38)*AU38)/100) -> 0 | DN38: 0 | DO38: 0 | DP38: 1.047 | DQ38: 1 | DU38: 1009 | DV38: т | DW38: т | DX38: 1000 | EE38: 55586532 | EF38: 60 | EG38: Ремонтно-строительные работы | EH38: 0 | EJ38: 1 | EK38: 97 | EL38: ТСН-2001.6-60. Печные работы | EM38: ТСН-2001.6-60-1 | EQ38: 0 | ER38: 18660.61 | ES38: 18660.61 | ET38: 0 | EU38: 0 | EV38: 0 | EW38: 0 | EX38: 0 | FQ38: 0 | FR38: 0 | FS38: 0 | FX38: 100 | FY38: 64 | GD38: 1 | GF38: 667244177 | GG38: 2 | GH38: 1 | GI38: -2 | GJ38: 0 | GK38: 0 | GL38: =ROUND(IF(AND(BH38=3,BI38=3,FS38<>0),P38,0),2) -> 0 | GM38: =ROUND(O38+X38+Y38,2)+GX38 -> 1282.69 | GN38: =IF(OR(BI38=0,BI38=1),GM38-GX38,0) -> 1282.69 | GO38: =IF(BI38=2,GM38-GX38,0) -> 0 | GP38: =IF(BI38=4,GM38-GX38,0) -> 0 | GR38: 0 | GS38: 3 | GT38: 0 | GV38: =ROUND((GT38),6) -> 0 | GW38: 1 | GX38: =ROUND(HC38*I38,2) -> 0 | HA38: 0 | HB38: 0 | HC38: =GV38*GW38 -> 0 | HS38: 0 | IK38: 0
A39: 18 | B39: 1 | C39: 8 | E39: 2,1 | F39: 1.1-1-165 | G39: Грунтовка глифталевая, типа ГФ-021 | H39: т | I39: =I37*J39 -> 0.068738 | J39: 0.0090000649 | K39: 0.009 | O39: =ROUND(CP39,2) -> 4592.03 | P39: =ROUND((ROUND((AC39*AW39*I39),2)*BC39),2) -> 4592.03 | Q39: =(ROUND((ROUND(((ET39)*AV39*I39),2)*BB39),2)+ROUND((ROUND(((AE39-(EU39))*AV39*I39),2)*BS39),2)) -> 0 | R39: =ROUND((ROUND((AE39*AV39*I39),2)*BS39),2) -> 0 | S39: =ROUND((ROUND((AF39*AV39*I39),2)*BA39),2) -> 0 | T39: =ROUND(CU39*I39,2) -> 0 | U39: =CV39*I39 -> 0 | V39: =CW39*I39 -> 0 | W39: =ROUND(CX39*I39,2) -> 0 | X39: =ROUND(CY39,2) -> 0 | Y39: =ROUND(CZ39,2) -> 0 | AA39: 56481267 | AB39: =ROUND((AC39+AD39+AF39),6) -> 18660.61 | AC39: =ROUND((ES39),6) -> 18660.61 | AD39: =ROUND((((ET39)-(EU39))+AE39),6) -> 0 | AE39: =ROUND((EU39),6) -> 0 | AF39: =ROUND((EV39),6) -> 0 | AG39: =ROUND((AP39),6) -> 0 | AH39: =(EW39) -> 0 | AI39: =(EX39) -> 0 | AJ39: =(AS39) -> 0 | AK39: 18660.61 | AL39: 18660.61 | AM39: 0 | AN39: 0 | AO39: 0 | AP39: 0 | AQ39: 0 | AR39: 0 | AS39: 0 | AT39: 89 | AU39: 44 | AV39: 1 | AW39: 1 | AZ39: 1 | BA39: 1 | BB39: 1 | BC39: 3.58 | BH39: 3 | BI39: 1 | BJ39: ТСН-2001.1 Доп. 67, Р. 1, о. 1, поз. 165 | BM39: 97 | BN39: 0 | BO39: 1.1-1-165 | BP39: 1 | BQ39: 60 | BR39: 0 | BS39: 1 | BT39: 1 | BU39: 1 | BV39: 1 | BW39: 1 | BX39: 1 | BZ39: 89 | CA39: 44 | CE39: 30 | CF39: 0 | CG39: 0 | CM39: 0 | CO39: 0 | CP39: =(P39+Q39+S39) -> 4592.03 | CQ39: =ROUND((ROUND((AC39*AW39*1),2)*BC39),2) -> 66804.98 | CR39: =(ROUND((ROUND(((ET39)*AV39*1),2)*BB39),2)+ROUND((ROUND(((AE39-(EU39))*AV39*1),2)*BS39),2)) -> 0 | CS39: =ROUND((ROUND((AE39*AV39*1),2)*BS39),2) -> 0 | CT39: =ROUND((ROUND((AF39*AV39*1),2)*BA39),2) -> 0 | CU39: =AG39 -> 0 | CV39: =(AH39*AV39) -> 0 | CW39: =AI39 -> 0 | CX39: =AJ39 -> 0 | CY39: =(((S39+R39)*AT39)/100) -> 0 | CZ39: =(((S39+R39)*AU39)/100) -> 0 | DN39: 0 | DO39: 0 | DP39: 1 | DQ39: 1 | DU39: 1009 | DV39: т | DW39: т | DX39: 1000 | EE39: 55586532 | EF39: 60 | EG39: Ремонтно-строительные работы | EH39: 0 | EJ39: 1 | EK39: 97 | EL39: ТСН-2001.6-60. Печные работы | EM39: ТСН-2001.6-60-1 | EQ39: 0 | ER39: 18660.61 | ES39: 18660.61 | ET39: 0 | EU39: 0 | EV39: 0 | EW39: 0 | EX39: 0 | FQ39: 0 | FR39: 0 | FS39: 0 | FX39: 89 | FY39: 44 | GD39: 1 | GF39: 667244177 | GG39: 2 | GH39: 1 | GI39: 2 | GJ39: 0 | GK39: 0 | GL39: =ROUND(IF(AND(BH39=3,BI39=3,FS39<>0),P39,0),2) -> 0 | GM39: =ROUND(O39+X39+Y39,2)+GX39 -> 4592.03 | GN39: =IF(OR(BI39=0,BI39=1),GM39-GX39,0) -> 4592.03 | GO39: =IF(BI39=2,GM39-GX39,0) -> 0 | GP39: =IF(BI39=4,GM39-GX39,0) -> 0 | GR39: 0 | GS39: 0 | GT39: 0 | GV39: =ROUND((GT39),6) -> 0 | GW39: 1 | GX39: =ROUND(HC39*I39,2) -> 0 | HA39: 0 | HB39: 0 | HC39: =GV39*GW39 -> 0 | HS39: 0 | IK39: 0
A41: 51 | B41: =B24 -> 1 | C41: =A24 -> 4 | D41: =ROW(A24) -> 24 | F41: =IF(F24<>"",F24,"") | G41: =IF(G24<>"",G24,"") -> Усиление внутренних и наружных стен в зоне расширяемых проемов в подвале и в надземной части здания. Рама РС-1, 105 шт. (КР-5,6) | H41: 0 | O41: =ROUND(AB41,2) -> 370105.87 | P41: =ROUND(AC41,2) -> 294096.01 | Q41: =ROUND(AD41,2) -> 1203.04 | R41: =ROUND(AE41,2) -> 69.31 | S41: =ROUND(AF41,2) -> 74806.82 | T41: =ROUND(AG41,2) -> 0 | U41: =AH41 -> 5983.2872 | V41: =AI41 -> 0 | W41: =ROUND(AJ41,2) -> 0 | X41: =ROUND(AK41,2) -> 68943.55 | Y41: =ROUND(AL41,2) -> 39021.85 | AB41: =ROUND(SUMIF(AA28:AA39,"=56481265",O28:O39),2) -> 370105.87 | AC41: =ROUND(SUMIF(AA28:AA39,"=56481265",P28:P39),2) -> 294096.01 | AD41: =ROUND(SUMIF(AA28:AA39,"=56481265",Q28:Q39),2) -> 1203.04 | AE41: =ROUND(SUMIF(AA28:AA39,"=56481265",R28:R39),2) -> 69.31 | AF41: =ROUND(SUMIF(AA28:AA39,"=56481265",S28:S39),2) -> 74806.82 | AG41: =ROUND(SUMIF(AA28:AA39,"=56481265",T28:T39),2) -> 0 | AH41: =SUMIF(AA28:AA39,"=56481265",U28:U39) -> 5983.2872 | AI41: =SUMIF(AA28:AA39,"=56481265",V28:V39) -> 0 | AJ41: =ROUND(SUMIF(AA28:AA39,"=56481265",W28:W39),2) -> 0 | AK41: =ROUND(SUMIF(AA28:AA39,"=56481265",X28:X39),2) -> 68943.55 | AL41: =ROUND(SUMIF(AA28:AA39,"=56481265",Y28:Y39),2) -> 39021.85 | AO41: =ROUND(BX41,2) -> 0 | AP41: =ROUND(BY41,2) -> 0 | AQ41: =ROUND(BZ41,2) -> 0 | AR41: =ROUND(CA41,2) -> 478071.27 | AS41: =ROUND(CB41,2) -> 478071.27 | AT41: =ROUND(CC41,2) -> 0 | AU41: =ROUND(CD41,2) -> 0 | AV41: =ROUND(CE41,2) -> 294096.01 | ... BD41: =ROUND(CM41,2) -> 0 | BX41: =ROUND(SUMIF(AA28:AA39,"=56481265",FQ28:FQ39),2) -> 0 | BY41: =ROUND(SUMIF(AA28:AA39,"=56481265",FR28:FR39),2) -> 0 | BZ41: =ROUND(SUMIF(AA28:AA39,"=56481265",GL28:GL39),2) -> 0 | CA41: =ROUND(SUMIF(AA28:AA39,"=56481265",GM28:GM39),2) -> 478071.27 | CB41: =ROUND(SUMIF(AA28:AA39,"=56481265",GN28:GN39),2) -> 478071.27 | CC41: =ROUND(SUMIF(AA28:AA39,"=56481265",GO28:GO39),2) -> 0 | CD41: =ROUND(SUMIF(AA28:AA39,"=56481265",GP28:GP39),2) -> 0 | CE41: =AC41-BX41 -> 294096.01 | CF41: =AC41-BY41 -> 294096.01 | CG41: =BX41-BZ41 -> 0 | CH41: =AC41-BX41-BY41+BZ41 -> 294096.01 | CI41: =BY41-BZ41 -> 0 | CJ41: =ROUND(SUMIF(AA28:AA39,"=56481265",GX28:GX39),2) -> 0 | CK41: =ROUND(SUMIF(AA28:AA39,"=56481265",GY28:GY39),2) -> 0 | CL41: =ROUND(SUMIF(AA28:AA39,"=56481265",GZ28:GZ39),2) -> 0 | CM41: =ROUND(SUMIF(AA28:AA39,"=56481265",HD28:HD39),2) -> 0 | DG41: =ROUND(DT41,2) -> 6025191.8 | DH41: =ROUND(DU41,2) -> 2430182.2 | DI41: =ROUND(DV41,2) -> 16137.83 | DJ41: =ROUND(DW41,2) -> 3320.15 | DK41: =ROUND(DX41,2) -> 3578871.8 | DL41: =ROUND(DY41,2) -> 0 | DM41: =DZ41 -> 5985.6984 | DN41: =EA41 -> 0 | DO41: =ROUND(EB41,2) -> 0 | DP41: =ROUND(EC41,2) -> 3294536.9 | DQ41: =ROUND(ED41,2) -> 1859860.6 | DT41: =ROUND(SUMIF(AA28:AA39,"=56481267",O28:O39),2) -> 6025191.8 | DU41: =ROUND(SUMIF(AA28:AA39,"=56481267",P28:P39),2) -> 2430182.2 | DV41: =ROUND(SUMIF(AA28:AA39,"=56481267",Q28:Q39),2) -> 16137.83 | DW41: =ROUND(SUMIF(AA28:AA39,"=56481267",R28:R39),2) -> 3320.15 | DX41: =ROUND(SUMIF(AA28:AA39,"=56481267",S28:S39),2) -> 3578871.8 | DY41: =ROUND(SUMIF(AA28:AA39,"=56481267",T28:T39),2) -> 0 | DZ41: =SUMIF(AA28:AA39,"=56481267",U28:U39) -> 5985.6984 | EA41: =SUMIF(AA28:AA39,"=56481267",V28:V39) -> 0 | EB41: =ROUND(SUMIF(AA28:AA39,"=56481267",W28:W39),2) -> 0 | EC41: =ROUND(SUMIF(AA28:AA39,"=56481267",X28:X39),2) -> 3294536.9 | ED41: =ROUND(SUMIF(AA28:AA39,"=56481267",Y28:Y39),2) -> 1859860.6 | EG41: =ROUND(FP41,2) -> 0 | EH41: =ROUND(FQ41,2) -> 0 | EI41: =ROUND(FR41,2) -> 0 | EJ41: =ROUND(FS41,2) -> 11179589 | EK41: =ROUND(FT41,2) -> 11179589 | EL41: =ROUND(FU41,2) -> 0 | EM41: =ROUND(FV41,2) -> 0 | EN41: =ROUND(FW41,2) -> 2430182.2 | ... EV41: =ROUND(GE41,2) -> 0 | FP41: =ROUND(SUMIF(AA28:AA39,"=56481267",FQ28:FQ39),2) -> 0 | FQ41: =ROUND(SUMIF(AA28:AA39,"=56481267",FR28:FR39),2) -> 0 | FR41: =ROUND(SUMIF(AA28:AA39,"=56481267",GL28:GL39),2) -> 0 | FS41: =ROUND(SUMIF(AA28:AA39,"=56481267",GM28:GM39),2) -> 11179589 | FT41: =ROUND(SUMIF(AA28:AA39,"=56481267",GN28:GN39),2) -> 11179589 | FU41: =ROUND(SUMIF(AA28:AA39,"=56481267",GO28:GO39),2) -> 0 | FV41: =ROUND(SUMIF(AA28:AA39,"=56481267",GP28:GP39),2) -> 0 | FW41: =DU41-FP41 -> 2430182.2 | FX41: =DU41-FQ41 -> 2430182.2 | FY41: =FP41-FR41 -> 0 | FZ41: =DU41-FP41-FQ41+FR41 -> 2430182.2 | GA41: =FQ41-FR41 -> 0 | GB41: =ROUND(SUMIF(AA28:AA39,"=56481267",GX28:GX39),2) -> 0 | GC41: =ROUND(SUMIF(AA28:AA39,"=56481267",GY28:GY39),2) -> 0 | GD41: =ROUND(SUMIF(AA28:AA39,"=56481267",GZ28:GZ39),2) -> 0 | GE41: =ROUND(SUMIF(AA28:AA39,"=56481267",HD28:HD39),2) -> 0 | GX41: 0
A43: 50 | B43: 0 | C43: 0 | D43: 1 | E43: 201 | F43: =ROUND(Source!O41,O43) -> 370105.87 | G43: ПЗ | H43: Прямые затраты | K43: 201 | L43: 1 | M43: 3 | O43: 2 | P43: =ROUND(Source!DG41,O43) -> 6025191.8 | W43: 370105.87 | X43: 1 | Y43: 370105.87 | Z43: 6025191.8 | AA43: 1 | AB43: 6025191.8
A44: 50 | B44: 0 | C44: 0 | D44: 1 | E44: 202 | F44: =ROUND(Source!P41,O44) -> 294096.01 | G44: СтМатОб | H44: Стоимость материальных ресурсов (всего) | K44: 202 | L44: 2 | M44: 3 | O44: 2 | P44: =ROUND(Source!DH41,O44) -> 2430182.2 | W44: 294096.01 | X44: 1 | Y44: 294096.01 | Z44: 2430182.2 | AA44: 1 | AB44: 2430182.2
