Workbook

Sheet 09-01-02
A1: =Source!B1 -> Smeta.RU (495) 974-1589
J2: Форма № 4б
B3: "СОГЛАСОВАНО" | G3: "УТВЕРЖДАЮ"
B6: =CONCATENATE("______________________ ", IF(Source!AL12<>"", Source!AL12, "")) -> ______________________ | G6: =CONCATENATE("______________________ ", IF(Source!AH12<>"", Source!AH12, "")) -> ______________________
B7: "_____"________________ 2025 г. | G7: "_____"________________ 2025 г.
A10: Капитальный ремонт здания Государственного бюджетного общеобразовательного учреждения города Москвы «Школа № 236» по адресу: г. Москва, ул. Клязьминская, д. 7, к. 4. I этап | AP10: Капитальный ремонт здания Государственного бюджетного общеобразовательного учреждения города Москвы «Школа № 236» по адресу: г. Москва, ул. Клязьминская, д. 7, к. 4. I этап. 09-01-02 Перевозка мусора
A11: (наименование стройки и/или объекта)
A13: =CONCATENATE( "ЛОКАЛЬНАЯ СМЕТА № ",IF(Source!F20<>"Новая локальная смета", Source!F20, "")) -> ЛОКАЛЬНАЯ СМЕТА № 09-01-02
A15: =IF(Source!G20<>"Новая локальная смета", Source!G20, "") -> Перевозка мусора
A16: (наименование работ и затрат)
A18: =CONCATENATE( "Основание: чертежи № ", Source!J20) -> Основание: чертежи № 0224-00272-01-0-ООС2
I20: В базисном уровне цен | J20: В текущем уровне цен
E21: Сметная стоимость | I21: =I22+I23+I24+I25 -> 188.2 | J21: =J22+J23+J24+J25 -> 2900.21 | K21: тыс.руб.
E22: Строительные работы | I22: =ROUND((Source!F78)/1000, 2) -> 0 | J22: =ROUND((Source!P78)/1000, 2) -> 0 | K22: тыс.руб.
E23: Работы по монтажу оборудования | I23: =ROUND((Source!F79)/1000, 2) -> 0 | J23: =ROUND((Source!P79)/1000, 2) -> 0 | K23: тыс.руб.
E24: Оборудование | I24: =ROUND((Source!F70)/1000, 2) -> 0 | J24: =ROUND((Source!P70)/1000, 2) -> 0 | K24: тыс.руб.
E25: Прочие работы и затраты | I25: =ROUND((Source!F80+Source!F81)/1000, 2) -> 188.2 | J25: =ROUND((Source!P80+Source!P81)/1000, 2) -> 2900.21 | K25: тыс.руб.
E26: Средства на оплату труда | I26: =(Source!F76+ Source!F75)/1000 -> 0 | J26: =((Source!P76 + Source!P75)/1000) -> 0 | K26: тыс.руб.
E27: Затраты труда | I27: =Source!F83 -> 0 | K27: чел.-ч.
E28: Кроме того:
E29: Возврат материалов | I29: =SUM(Y35:Y50)/1000 -> 0 | J29: =SUM(Z35:Z50)/1000 -> 0 | K29: тыс.руб.
A31: Составлен(а) по ТСН-2001 с учетом Дополнения №: 79
A32: № и период сборника коэффициентов (индексов) пересчета: Коэффициенты к ТСН-2001 МГЭ Дополнение 79, строительство №216/79 III квартал 2025 года и Коэффициенты к ТСН-2001.13-2 Дополнение 45 №62/45 III квартал 2025 года | M32: 3 кв-л сентябрь | AP32: № и период сборника коэффициентов (индексов) пересчета: Коэффициенты к ТСН-2001 МГЭ Дополнение 79, строительство №216/79 III квартал 2025 года и Коэффициенты к ТСН-2001.13-2 Дополнение 45 №62/45 III квартал 2025 года
A33: № п/п | B33: Шифр расценки и коды ресурсов | C33: Наименование работ и затрат | D33: Ед. изм. | E33: Кол-во единиц | F33: Цена на ед. изм., руб. | G33: Попра- вочные коэффи- циенты | H33: Коэффи- циенты зимних удорожа- ний | I33: Всего в ценах на январь 2000 года, руб. | J33: Коэффи- циенты (индек- сы) пере- счета, нормы НР и СП | K33: ВСЕГО затрат в текущем уровне цен, руб.
A34: 1 | B34: 2 | C34: 3 | D34: 4 | E34: 5 | F34: 6 | G34: 7 | H34: 8 | I34: 9 | J34: 10 | K34: 11
A36: =CONCATENATE("Раздел: ",IF(Source!G24<>"Новый раздел", Source!G24, "")) -> Раздел: Перевозка мусора
A37: 1 | B37: =Source!F28 -> 15.2-45-42 | C37: Перевозка строительного мусора на расстояние до 45 км автосамосвалами грузоподъемностью до 10 т | D37: =Source!H28 -> т | E37: =Source!I28 -> 3219.898 | M37: исключить лом металла, у него свой путь | Q37: =Source!X28 -> 0 | R37: =Source!X29 -> 0 | S37: =Source!Y28 -> 0 | T37: =Source!Y29 -> 0 | U37: =ROUND((175/100)*ROUND(Source!R28, 2), 2) -> 0 | V37: =ROUND((0/100)*ROUND(Source!R29, 2), 2) -> 0 | AC37: 0
C38: ЭМ | F38: =Source!AM28 -> 58.45 | G38: =Source!DE28 | H38: =Source!AV29 -> 1 | I38: =Source!Q28 -> 188203.04 | J38: =IF(Source!BB29<> 0, Source!BB29, 1) -> 15.41 | K38: =Source!Q29 -> 2900208.9
C39: ВСЕГО работ по позиции: | H39: =I38+0-0-0 -> 188203.04 | J39: =K38+0-0-0 -> 2900208.9
C40: ВСЕГО оборудование по позиции: | H40: =0+0 -> 0 | J40: =0+0 -> 0
C41: ВСЕГО по позиции: | H41: =I38+0 -> 188203.04 | J41: =K38+0 -> 2900208.9 | O41: =I38+0 -> 188203.04 | P41: =K38+0 -> 2900208.9
A44: =CONCATENATE("Итого по разделу: ",IF(Source!G31<>"Новый раздел", Source!G31, "")) -> Итого по разделу: Перевозка мусора | H44: =SUM(O36:O43) -> 188203.04 | J44: =SUM(P36:P43) -> 2900208.9
A45: Итого по ТСН-2001.16 | I45: =SUM(W36:W44) -> 0 | J45: =SUM(X36:X44) -> 0
A46: Итого возвратных сумм | I46: =SUM(Y36:Y45) -> 0 | J46: =SUM(Z36:Z45) -> 0
A48: =CONCATENATE("Итого по локальной смете: ",IF(Source!G61<>"Новая локальная смета", Source!G61, "")) -> Итого по локальной смете: Перевозка мусора | H48: =SUM(O35:O47) -> 188203.04 | J48: =SUM(P35:P47) -> 2900208.9
A49: Итого по ТСН-2001.16 | I49: =SUM(W35:W48) -> 0 | J49: =SUM(X35:X48) -> 0
A50: Итого возвратных сумм | I50: =SUM(Y35:Y49) -> 0 | J50: =SUM(Z35:Z49) -> 0
A53: Составил | C53: =IF(Source!AC12<>"", Source!AC12," ") | H53: =IF(Source!AB12<>"", Source!AB12," ") -> Лукьянова А.Л.
C54: (должность, подпись, инициалы, фамилия)
A56: Проверил | C56: =IF(Source!AE12<>"", Source!AE12," ") | H56: =IF(Source!AD12<>"", Source!AD12," ")
...

Sheet Ведомость объемов работ
A1: =Source!B1 -> Smeta.RU (495) 974-1589
E3: "УТВЕРЖДАЮ"
D5: ___________________________
D7: ___________________________
D9: " ___ " ___________ 20 ___ г.
B12: =CONCATENATE("Ведомость объемов работ ", IF(Source!AN15<>"", Source!AN15," ")) -> Ведомость объемов работ
B13: =CONCATENATE(Source!F12, " ", Source!G12) -> 09-01-02 09-01-02 Перевозка мусора
A16: № п/п | B16: № в ЛСР | C16: Наименование работ и затрат | D16: Единица измерения | E16: Количество | F16: Ссылка на чертежи, спецификации | G16: Формула расчета, расчет объемов работ и расхода материалов | H16: Примечание
A17: 1 | B17: 2 | C17: 3 | D17: 4 | E17: 5 | F17: 6 | G17: 7 | H17: 8
A18: =CONCATENATE("Локальная смета: ", Source!G20) -> Локальная смета: Перевозка мусора
A19: =CONCATENATE("Раздел: ", Source!G24) -> Раздел: Перевозка мусора
A20: 1 | B20: =Source!E28 -> 1 | C20: =Source!G28 -> Перевозка строительного мусора на расстояние до 45 км автосамосвалами грузоподъемностью до 10 т | D20: т | E20: =Source!I28 -> 3219.898 | F20: =Source!U24 | G20: =Source!I28 -> 3219.898
C23: Главный инженер проекта _________________ | D23: =IF(Source!X12<>"", Source!X12," ")
C25: Составил _________________ | D25: =IF(Source!AB12<>"", Source!AB12," ") -> Лукьянова А.Л.

Sheet Source
A1: 0 | B1: Smeta.RU (495) 974-1589 | D1: _PS_ | F1: 0 | G1: 0 | H1: 0 | I1: Smeta.RU | K1: 1 | L1: 74562 | M1: 10 | N1: 11 | O1: 14 | P1: 0 | Q1: 0
A4: 1 | B4: 1 | C4: -1 | G4: Капитальный ремонт здания Государственного бюджетного общеобразовательного учреждения города Москвы «Школа № 236» по адресу: г. Москва, ул. Клязьминская, д. 7, к. 4. I этап | EC4: 0
A12: 1 | B12: 131 | C12: 0 | D12: =ROW(A91) -> 91 | E12: 0 | F12: 09-01-02 | G12: 09-01-02 Перевозка мусора | I12: 0 | J12: 0224-00272-01-0-ООС2 | K12: 0 | L12: 0 | M12: 4098 | O12: 0 | P12: 0 | Q12: 0 | R12: 0 | S12: 0 | T12: 1 | V12: 0 | AB12: Лукьянова А.Л. | BB12: 0 | BH12: Сметные нормы списания | BI12: Коды ОКП для ТСН-2001 МГЭ Дополнение 79 | BJ12: 1 | BK12: 1 | BL12: 0 | BM12: 0 | BN12: 1 | BO12: 0 | BP12: 6 | BQ12: 2 | BR12: 1 | BS12: 1 | BT12: 0 | BU12: 0 | BV12: 0 | BW12: 0 | BX12: 0 | BY12: ТСН-2001 (МГЭ) Доп 79 - Новое строительство | BZ12: Типовой расчет для ТСН-2001 МГЭ, Дополнение 79, строительство | CA12: Территориальные сметные нормативы для Москвы ТСН-2001 (МГЭ), дополнение 79 | CB12: Территориальные сметные нормативы для Москвы ТСН-2001 (МГЭ), дополнение 79 | CC12: Территориальные сметные нормативы для Москвы ТСН-2001 (МГЭ), дополнение 79 | CD12: Территориальные сметные нормативы для Москвы ТСН-2001 (МГЭ), дополнение 79 | CE12: Поправки для ТСН-2001 от 03.10.2025 г. доп.79 | CF12: 0 | CG12: 0 | CH12: 8200 | CK12: 79 | CQ12: Территориальные сметные нормативы для Москвы (ТСН-2001) | CR12: ТЕР | CS12: 41660 | CT12: 1 | CU12: 79 | CY12: 0 | EC12: 0
A15: 15 | B15: 1
A18: 52 | B18: =B91 -> 131 | C18: =C91 -> 1 | D18: =D91 -> 12 | E18: =E91 -> 0 | F18: =F91 -> 09-01-02 | G18: =G91 -> 09-01-02 Перевозка мусора | O18: =O91 -> 188203.04 | P18: =P91 -> 0 | Q18: =Q91 -> 188203.04 | R18: =R91 -> 0 | S18: =S91 -> 0 | T18: =T91 -> 0 | U18: =U91 -> 0 | V18: =V91 -> 0 | ... GX18: =GX91 -> 0
A20: 3 | B20: 1 | D20: =ROW(A61) -> 61 | F20: 09-01-02 | G20: Перевозка мусора | I20: 0 | J20: 0224-00272-01-0-ООС2 | K20: -1 | L20: 09-01-02 | S20: 0 | T20: 0 | V20: 0 | AB20: Лукьянова А.Л. | BX20: 0 | CF20: 0 | CG20: 0
A22: 52 | B22: =B61 -> 1 | C22: =C61 -> 3 | D22: =D61 -> 20 | E22: =E61 -> 0 | F22: =F61 -> 09-01-02 | G22: =G61 -> Перевозка мусора | O22: =O61 -> 188203.04 | P22: =P61 -> 0 | Q22: =Q61 -> 188203.04 | R22: =R61 -> 0 | S22: =S61 -> 0 | T22: =T61 -> 0 | U22: =U61 -> 0 | V22: =V61 -> 0 | ... GX22: =GX61 -> 0
A24: 4 | B24: 1 | D24: =ROW(A31) -> 31 | F24: Новый раздел | G24: Перевозка мусора | I24: 0 | K24: 0 | S24: 0 | T24: 0 | V24: 0 | BX24: 0 | CJ24: 0
A26: 52 | B26: =B31 -> 1 | C26: =C31 -> 4 | D26: =D31 -> 24 | E26: =E31 -> 0 | F26: =F31 -> Новый раздел | G26: =G31 -> Перевозка мусора | O26: =O31 -> 188203.04 | P26: =P31 -> 0 | Q26: =Q31 -> 188203.04 | R26: =R31 -> 0 | S26: =S31 -> 0 | T26: =T31 -> 0 | U26: =U31 -> 0 | V26: =V31 -> 0 | ... GX26: =GX31 -> 0
A28: 17 | B28: 1 | C28: =ROW(SmtRes!A1) -> 1 | D28: =ROW(EtalonRes!A1) -> 1 | E28: 1 | F28: 15.2-45-42 | G28: Перевозка строительного мусора на расстояние до 45 км автосамосвалами грузоподъемностью до 10 т | H28: т | I28: 3219.898 | J28: 0 | K28: 3219.898 | O28: =ROUND(CP28,2) -> 188203.04 | P28: =ROUND((ROUND((AC28*AW28*I28),2)*BC28),2) -> 0 | Q28: =(ROUND((ROUND(((ET28)*AV28*I28),2)*BB28),2)+ROUND((ROUND(((AE28-(EU28))*AV28*I28),2)*BS28),2)) -> 188203.04 | R28: =ROUND((ROUND((AE28*AV28*I28),2)*BS28),2) -> 0 | S28: =ROUND((ROUND((AF28*AV28*I28),2)*BA28),2) -> 0 | T28: =ROUND(CU28*I28,2) -> 0 | U28: =CV28*I28 -> 0 | V28: =CW28*I28 -> 0 | W28: =ROUND(CX28*I28,2) -> 0 | X28: =ROUND(CY28,2) -> 0 | Y28: =ROUND(CZ28,2) -> 0 | AA28: 56526069 | AB28: =ROUND((AC28+AD28+AF28),6) -> 58.45 | AC28: =ROUND((ES28),6) -> 0 | AD28: =ROUND((((ET28)-(EU28))+AE28),6) -> 58.45 | AE28: =ROUND((EU28),6) -> 0 | AF28: =ROUND((EV28),6) -> 0 | AG28: =ROUND((AP28),6) -> 0 | AH28: =(EW28) -> 0 | AI28: =(EX28) -> 0 | AJ28: =(AS28) -> 0 | AK28: 58.45 | AL28: 0 | AM28: 58.45 | AN28: 0 | AO28: 0 | AP28: 0 | AQ28: 0 | AR28: 0 | AS28: 0 | AT28: 94 | AU28: 61 | AV28: 1 | AW28: 1 | AZ28: 1 | BA28: 1 | BB28: 1 | BC28: 1 | BH28: 0 | BI28: 4 | BJ28: ТСН-2001.15 Доп. 79, Сб. 2, т. 45, поз. 42 | BM28: 188 | BN28: 0 | BO28: 15.2-45-42 | BP28: 1 | BQ28: 150 | BR28: 0 | BS28: 1 | BT28: 1 | BU28: 1 | BV28: 1 | BW28: 1 | BX28: 1 | BZ28: 94 | CA28: 61 | CE28: 30 | CF28: 0 | CG28: 0 | CM28: 0 | CO28: 0 | CP28: =(P28+Q28+S28) -> 188203.04 | CQ28: =ROUND((ROUND((AC28*AW28*1),2)*BC28),2) -> 0 | CR28: =(ROUND((ROUND(((ET28)*AV28*1),2)*BB28),2)+ROUND((ROUND(((AE28-(EU28))*AV28*1),2)*BS28),2)) -> 58.45 | CS28: =ROUND((ROUND((AE28*AV28*1),2)*BS28),2) -> 0 | CT28: =ROUND((ROUND((AF28*AV28*1),2)*BA28),2) -> 0 | CU28: =AG28 -> 0 | CV28: =(AH28*AV28) -> 0 | CW28: =AI28 -> 0 | CX28: =AJ28 -> 0 | CY28: =(((S28+R28)*AT28)/100) -> 0 | CZ28: =(((S28+R28)*AU28)/100) -> 0 | DN28: 0 | DO28: 0 | DP28: 1 | DQ28: 1 | DU28: 1009 | DV28: т | DW28: т | DX28: 1000 | EE28: 55586142 | EF28: 150 | EG28: Транспортные затраты | EH28: 0 | EJ28: 4 | EK28: 188 | EL28: ТСН-2001.15. Перевозка строительных грузов автомобильным транспортом | EM28: ТСН-2001.15. | EQ28: 0 | ER28: 58.45 | ES28: 0 | ET28: 58.45 | EU28: 0 | EV28: 0 | EW28: 0 | EX28: 0 | EY28: 0 | FQ28: 0 | FR28: 0 | FS28: 0 | FX28: 94 | FY28: 61 | GD28: 1 | GF28: 767338782 | GG28: 2 | GH28: 1 | GI28: 2 | GJ28: 0 | GK28: 0 | GL28: =ROUND(IF(AND(BH28=3,BI28=3,FS28<>0),P28,0),2) -> 0 | GM28: =ROUND(O28+X28+Y28,2)+GX28 -> 188203.04 | GN28: =IF(OR(BI28=0,BI28=1),GM28-GX28,0) -> 0 | GO28: =IF(BI28=2,GM28-GX28,0) -> 0 | GP28: =IF(BI28=4,GM28-GX28,0) -> 188203.04 | GR28: 0 | GS28: 3 | GT28: 0 | GV28: =ROUND((GT28),6) -> 0 | GW28: 1 | GX28: =ROUND(HC28*I28,2) -> 0 | HA28: 0 | HB28: 0 | HC28: =GV28*GW28 -> 0 | HS28: 0 | IK28: 0
A29: 17 | B29: 1 | C29: =ROW(SmtRes!A2) -> 2 | D29: =ROW(EtalonRes!A2) -> 2 | E29: 1 | F29: 15.2-45-42 | G29: Перевозка строительного мусора на расстояние до 45 км автосамосвалами грузоподъемностью до 10 т | H29: т | I29: 3219.898 | J29: 0 | K29: 3219.898 | O29: =ROUND(CP29,2) -> 2900208.9 | P29: =ROUND((ROUND((AC29*AW29*I29),2)*BC29),2) -> 0 | Q29: =(ROUND((ROUND(((ET29)*AV29*I29),2)*BB29),2)+ROUND((ROUND(((AE29-(EU29))*AV29*I29),2)*BS29),2)) -> 2900208.9 | R29: =ROUND((ROUND((AE29*AV29*I29),2)*BS29),2) -> 0 | S29: =ROUND((ROUND((AF29*AV29*I29),2)*BA29),2) -> 0 | T29: =ROUND(CU29*I29,2) -> 0 | U29: =CV29*I29 -> 0 | V29: =CW29*I29 -> 0 | W29: =ROUND(CX29*I29,2) -> 0 | X29: =ROUND(CY29,2) -> 0 | Y29: =ROUND(CZ29,2) -> 0 | AA29: 56526071 | AB29: =ROUND((AC29+AD29+AF29),6) -> 58.45 | AC29: =ROUND((ES29),6) -> 0 | AD29: =ROUND((((ET29)-(EU29))+AE29),6) -> 58.45 | AE29: =ROUND((EU29),6) -> 0 | AF29: =ROUND((EV29),6) -> 0 | AG29: =ROUND((AP29),6) -> 0 | AH29: =(EW29) -> 0 | AI29: =(EX29) -> 0 | AJ29: =(AS29) -> 0 | AK29: 58.45 | AL29: 0 | AM29: 58.45 | AN29: 0 | AO29: 0 | AP29: 0 | AQ29: 0 | AR29: 0 | AS29: 0 | AT29: 94 | AU29: 61 | AV29: 1 | AW29: 1 | AZ29: 1 | BA29: 1 | BB29: 15.41 | BC29: 1 | BH29: 0 | BI29: 4 | BJ29: ТСН-2001.15 Доп. 79, Сб. 2, т. 45, поз. 42 | BM29: 188 | BN29: 0 | BO29: 15.2-45-42 | BP29: 1 | BQ29: 150 | BR29: 0 | BS29: 1 | BT29: 1 | BU29: 1 | BV29: 1 | BW29: 1 | BX29: 1 | BZ29: 94 | CA29: 61 | CE29: 30 | CF29: 0 | CG29: 0 | CM29: 0 | CO29: 0 | CP29: =(P29+Q29+S29) -> 2900208.9 | CQ29: =ROUND((ROUND((AC29*AW29*1),2)*BC29),2) -> 0 | CR29: =(ROUND((ROUND(((ET29)*AV29*1),2)*BB29),2)+ROUND((ROUND(((AE29-(EU29))*AV29*1),2)*BS29),2)) -> 900.71 | CS29: =ROUND((ROUND((AE29*AV29*1),2)*BS29),2) -> 0 | CT29: =ROUND((ROUND((AF29*AV29*1),2)*BA29),2) -> 0 | CU29: =AG29 -> 0 | CV29: =(AH29*AV29) -> 0 | CW29: =AI29 -> 0 | CX29: =AJ29 -> 0 | CY29: =(((S29+R29)*AT29)/100) -> 0 | CZ29: =(((S29+R29)*AU29)/100) -> 0 | DN29: 0 | DO29: 0 | DP29: 1 | DQ29: 1 | DU29: 1009 | DV29: т | DW29: т | DX29: 1000 | EE29: 55586142 | EF29: 150 | EG29: Транспортные затраты | EH29: 0 | EJ29: 4 | EK29: 188 | EL29: ТСН-2001.15. Перевозка строительных грузов автомобильным транспортом | EM29: ТСН-2001.15. | EQ29: 0 | ER29: 58.45 | ES29: 0 | ET29: 58.45 | EU29: 0 | EV29: 0 | EW29: 0 | EX29: 0 | EY29: 0 | FQ29: 0 | FR29: 0 | FS29: 0 | FX29: 94 | FY29: 61 | GD29: 1 | GF29: 767338782 | GG29: 2 | GH29: 1 | GI29: 2 | GJ29: 0 | GK29: 0 | GL29: =ROUND(IF(AND(BH29=3,BI29=3,FS29<>0),P29,0),2) -> 0 | GM29: =ROUND(O29+X29+Y29,2)+GX29 -> 2900208.9 | GN29: =IF(OR(BI29=0,BI29=1),GM29-GX29,0) -> 0 | GO29: =IF(BI29=2,GM29-GX29,0) -> 0 | GP29: =IF(BI29=4,GM29-GX29,0) -> 2900208.9 | GR29: 0 | GS29: 3 | GT29: 0 | GV29: =ROUND((GT29),6) -> 0 | GW29: 1 | GX29: =ROUND(HC29*I29,2) -> 0 | HA29: 0 | HB29: 0 | HC29: =GV29*GW29 -> 0 | HS29: 0 | IK29: 0
A31: 51 | B31: =B24 -> 1 | C31: =A24 -> 4 | D31: =ROW(A24) -> 24 | F31: =IF(F24<>"",F24,"") -> Новый раздел | G31: =IF(G24<>"",G24,"") -> Перевозка мусора | H31: 0 | O31: =ROUND(AB31,2) -> 188203.04 | P31: =ROUND(AC31,2) -> 0 | Q31: =ROUND(AD31,2) -> 188203.04 | R31: =ROUND(AE31,2) -> 0 | S31: =ROUND(AF31,2) -> 0 | T31: =ROUND(AG31,2) -> 0 | U31: =AH31 -> 0 | V31: =AI31 -> 0 | W31: =ROUND(AJ31,2) -> 0 | X31: =ROUND(AK31,2) -> 0 | Y31: =ROUND(AL31,2) -> 0 | AB31: =ROUND(SUMIF(AA28:AA29,"=56526069",O28:O29),2) -> 188203.04 | AC31: =ROUND(SUMIF(AA28:AA29,"=56526069",P28:P29),2) -> 0 | AD31: =ROUND(SUMIF(AA28:AA29,"=56526069",Q28:Q29),2) -> 188203.04 | AE31: =ROUND(SUMIF(AA28:AA29,"=56526069",R28:R29),2) -> 0 | AF31: =ROUND(SUMIF(AA28:AA29,"=56526069",S28:S29),2) -> 0 | AG31: =ROUND(SUMIF(AA28:AA29,"=56526069",T28:T29),2) -> 0 | AH31: =SUMIF(AA28:AA29,"=56526069",U28:U29) -> 0 | AI31: =SUMIF(AA28:AA29,"=56526069",V28:V29) -> 0 | AJ31: =ROUND(SUMIF(AA28:AA29,"=56526069",W28:W29),2) -> 0 | AK31: =ROUND(SUMIF(AA28:AA29,"=56526069",X28:X29),2) -> 0 | AL31: =ROUND(SUMIF(AA28:AA29,"=56526069",Y28:Y29),2) -> 0 | AO31: =ROUND(BX31,2) -> 0 | AP31: =ROUND(BY31,2) -> 0 | AQ31: =ROUND(BZ31,2) -> 0 | AR31: =ROUND(CA31,2) -> 188203.04 | AS31: =ROUND(CB31,2) -> 0 | AT31: =ROUND(CC31,2) -> 0 | AU31: =ROUND(CD31,2) -> 188203.04 | AV31: =ROUND(CE31,2) -> 0 | ... BD31: =ROUND(CM31,2) -> 0 | BX31: =ROUND(SUMIF(AA28:AA29,"=56526069",FQ28:FQ29),2) -> 0 | BY31: =ROUND(SUMIF(AA28:AA29,"=56526069",FR28:FR29),2) -> 0 | BZ31: =ROUND(SUMIF(AA28:AA29,"=56526069",GL28:GL29),2) -> 0 | CA31: =ROUND(SUMIF(AA28:AA29,"=56526069",GM28:GM29),2) -> 188203.04 | CB31: =ROUND(SUMIF(AA28:AA29,"=56526069",GN28:GN29),2) -> 0 | CC31: =ROUND(SUMIF(AA28:AA29,"=56526069",GO28:GO29),2) -> 0 | CD31: =ROUND(SUMIF(AA28:AA29,"=56526069",GP28:GP29),2) -> 188203.04 | CE31: =AC31-BX31 -> 0 | CF31: =AC31-BY31 -> 0 | CG31: =BX31-BZ31 -> 0 | CH31: =AC31-BX31-BY31+BZ31 -> 0 | CI31: =BY31-BZ31 -> 0 | CJ31: =ROUND(SUMIF(AA28:AA29,"=56526069",GX28:GX29),2) -> 0 | CK31: =ROUND(SUMIF(AA28:AA29,"=56526069",GY28:GY29),2) -> 0 | CL31: =ROUND(SUMIF(AA28:AA29,"=56526069",GZ28:GZ29),2) -> 0 | CM31: =ROUND(SUMIF(AA28:AA29,"=56526069",HD28:HD29),2) -> 0 | DG31: =ROUND(DT31,2) -> 2900208.9 | DH31: =ROUND(DU31,2) -> 0 | DI31: =ROUND(DV31,2) -> 2900208.9 | DJ31: =ROUND(DW31,2) -> 0 | DK31: =ROUND(DX31,2) -> 0 | DL31: =ROUND(DY31,2) -> 0 | DM31: =DZ31 -> 0 | DN31: =EA31 -> 0 | DO31: =ROUND(EB31,2) -> 0 | DP31: =ROUND(EC31,2) -> 0 | DQ31: =ROUND(ED31,2) -> 0 | DT31: =ROUND(SUMIF(AA28:AA29,"=56526071",O28:O29),2) -> 2900208.9 | DU31: =ROUND(SUMIF(AA28:AA29,"=56526071",P28:P29),2) -> 0 | DV31: =ROUND(SUMIF(AA28:AA29,"=56526071",Q28:Q29),2) -> 2900208.9 | DW31: =ROUND(SUMIF(AA28:AA29,"=56526071",R28:R29),2) -> 0 | DX31: =ROUND(SUMIF(AA28:AA29,"=56526071",S28:S29),2) -> 0 | DY31: =ROUND(SUMIF(AA28:AA29,"=56526071",T28:T29),2) -> 0 | DZ31: =SUMIF(AA28:AA29,"=56526071",U28:U29) -> 0 | EA31: =SUMIF(AA28:AA29,"=56526071",V28:V29) -> 0 | EB31: =ROUND(SUMIF(AA28:AA29,"=56526071",W28:W29),2) -> 0 | EC31: =ROUND(SUMIF(AA28:AA29,"=56526071",X28:X29),2) -> 0 | ED31: =ROUND(SUMIF(AA28:AA29,"=56526071",Y28:Y29),2) -> 0 | EG31: =ROUND(FP31,2) -> 0 | EH31: =ROUND(FQ31,2) -> 0 | EI31: =ROUND(FR31,2) -> 0 | EJ31: =ROUND(FS31,2) -> 2900208.9 | EK31: =ROUND(FT31,2) -> 0 | EL31: =ROUND(FU31,2) -> 0 | EM31: =ROUND(FV31,2) -> 2900208.9 | EN31: =ROUND(FW31,2) -> 0 | ... EV31: =ROUND(GE31,2) -> 0 | FP31: =ROUND(SUMIF(AA28:AA29,"=56526071",FQ28:FQ29),2) -> 0 | FQ31: =ROUND(SUMIF(AA28:AA29,"=56526071",FR28:FR29),2) -> 0 | FR31: =ROUND(SUMIF(AA28:AA29,"=56526071",GL28:GL29),2) -> 0 | FS31: =ROUND(SUMIF(AA28:AA29,"=56526071",GM28:GM29),2) -> 2900208.9 | FT31: =ROUND(SUMIF(AA28:AA29,"=56526071",GN28:GN29),2) -> 0 | FU31: =ROUND(SUMIF(AA28:AA29,"=56526071",GO28:GO29),2) -> 0 | FV31: =ROUND(SUMIF(AA28:AA29,"=56526071",GP28:GP29),2) -> 2900208.9 | FW31: =DU31-FP31 -> 0 | FX31: =DU31-FQ31 -> 0 | FY31: =FP31-FR31 -> 0 | FZ31: =DU31-FP31-FQ31+FR31 -> 0 | GA31: =FQ31-FR31 -> 0 | GB31: =ROUND(SUMIF(AA28:AA29,"=56526071",GX28:GX29),2) -> 0 | GC31: =ROUND(SUMIF(AA28:AA29,"=56526071",GY28:GY29),2) -> 0 | GD31: =ROUND(SUMIF(AA28:AA29,"=56526071",GZ28:GZ29),2) -> 0 | GE31: =ROUND(SUMIF(AA28:AA29,"=56526071",HD28:HD29),2) -> 0 | GX31: 0
A33: 50 | B33: 0 | C33: 0 | D33: 1 | E33: 201 | F33: =ROUND(Source!O31,O33) -> 188203.04 | G33: ПЗ | H33: Прямые затраты | K33: 201 | L33: 1 | M33: 3 | O33: 2 | P33: =ROUND(Source!DG31,O33) -> 2900208.9 | W33: 188203.04 | X33: 1 | Y33: 188203.04 | Z33: 2900208.9 | AA33: 1 | AB33: 2900208.9
A34: 50 | B34: 0 | C34: 0 | D34: 1 | E34: 202 | F34: =ROUND(Source!P31,O34) -> 0 | G34: СтМатОб | H34: Стоимость материальных ресурсов (всего) | K34: 202 | L34: 2 | M34: 3 | O34: 2 | P34: =ROUND(Source!DH31,O34) -> 0 | W34: 0 | X34: 1 | Y34: 0 | Z34: 0 | AA34: 1 | AB34: 0
A35: 50 | B35: 0 | C35: 0 | D35: 1 | E35: 222 | F35: =ROUND(Source!AO31,O35) -> 0 | G35: СтМатОбЗак | H35: Стоимость материалов и оборудования заказчика | K35: 222 | L35: 3 | M35: 3 | O35: 2 | P35: =ROUND(Source!EG31,O35) -> 0 | W35: 0 | X35: 1 | Y35: 0 | Z35: 0 | AA35: 1 | AB35: 0
A36: 50 | B36: 0 | C36: 0 | D36: 1 | E36: 225 | F36: =ROUND(Source!AV31,O36) -> 0 | G36: СтМатОбПод | H36: Стоимость материалов и оборудования подрядчика | K36: 225 | L36: 4 | M36: 3 | O36: 2 | P36: =ROUND(Source!EN31,O36) -> 0 | W36: 0 | X36: 1 | Y36: 0 | Z36: 0 | AA36: 1 | AB36: 0
A37: 50 | B37: 0 | C37: 0 | D37: 1 | E37: 226 | F37: =ROUND(Source!AW31,O37) -> 0 | G37: СтМат | H37: Стоимость материалов (всего) | K37: 226 | L37: 5 | M37: 3 | O37: 2 | P37: =ROUND(Source!EO31,O37) -> 0 | W37: 0 | X37: 1 | Y37: 0 | Z37: 0 | AA37: 1 | AB37: 0
A38: 50 | B38: 0 | C38: 0 | D38: 1 | E38: 227 | F38: =ROUND(Source!AX31,O38) -> 0 | G38: СтМатЗак | H38: Стоимость материалов заказчика | K38: 227 | L38: 6 | M38: 3 | O38: 2 | P38: =ROUND(Source!EP31,O38) -> 0 | W38: 0 | X38: 1 | Y38: 0 | Z38: 0 | AA38: 1 | AB38: 0
A39: 50 | B39: 0 | C39: 0 | D39: 1 | E39: 228 | F39: =ROUND(Source!AY31,O39) -> 0 | G39: СтМатПод | H39: Стоимость материалов подрядчика | K39: 228 | L39: 7 | M39: 3 | O39: 2 | P39: =ROUND(Source!EQ31,O39) -> 0 | W39: 0 | X39: 1 | Y39: 0 | Z39: 0 | AA39: 1 | AB39: 0
A40: 50 | B40: 0 | C40: 0 | D40: 1 | E40: 216 | F40: =ROUND(Source!AP31,O40) -> 0 | G40: Оборуд | H40: Стоимость оборудования (всего) | K40: 216 | L40: 8 | M40: 3 | O40: 2 | P40: =ROUND(Source!EH31,O40) -> 0 | W40: 0 | X40: 1 | Y40: 0 | Z40: 0 | AA40: 1 | AB40: 0
A41: 50 | B41: 0 | C41: 0 | D41: 1 | E41: 223 | F41: =ROUND(Source!AQ31,O41) -> 0 | G41: ОборудЗак | H41: Стоимость оборудования заказчика | K41: 223 | L41: 9 | M41: 3 | O41: 2 | P41: =ROUND(Source!EI31,O41) -> 0 | W41: 0 | X41: 1 | Y41: 0 | Z41: 0 | AA41: 1 | AB41: 0
A42: 50 | B42: 0 | C42: 0 | D42: 1 | E42: 229 | F42: =ROUND(Source!AZ31,O42) -> 0 | G42: ОборудПод | H42: Стоимость оборудования подрядчика | K42: 229 | L42: 10 | M42: 3 | O42: 2 | P42: =ROUND(Source!ER31,O42) -> 0 | W42: 0 | X42: 1 | Y42: 0 | Z42: 0 | AA42: 1 | AB42: 0
A43: 50 | B43: 0 | C43: 0 | D43: 1 | E43: 203 | F43: =ROUND(Source!Q31,O43) -> 188203.04 | G43: ЭММ | H43: Эксплуатация машин | K43: 203 | L43: 11 | M43: 3 | O43: 2 | P43: =ROUND(Source!DI31,O43) -> 2900208.9 | W43: 188203.04 | X43: 1 | Y43: 188203.04 | Z43: 2900208.9 | AA43: 1 | AB43: 2900208.9
A44: 50 | B44: 0 | C44: 0 | D44: 1 | E44: 231 | F44: =ROUND(Source!BB31,O44) -> 0 | G44: ЭММсНРиСП | H44: Эксплуатация машин по ТСН-2001.16 | K44: 231 | L44: 12 | M44: 3 | O44: 2 | P44: =ROUND(Source!ET31,O44) -> 0 | W44: 0 | X44: 1 | Y44: 0 | Z44: 0 | AA44: 1 | AB44: 0
A45: 50 | B45: 0 | C45: 0 | D45: 1 | E45: 204 | F45: =ROUND(Source!R31,O45) -> 0 | G45: ЗПМ | H45: ЗП машинистов | K45: 204 | L45: 13 | M45: 3 | O45: 2 | P45: =ROUND(Source!DJ31,O45) -> 0 | W45: 0 | X45: 1 | Y45: 0 | Z45: 0 | AA45: 1 | AB45: 0
A46: 50 | B46: 0 | C46: 0 | D46: 1 | E46: 205 | F46: =ROUND(Source!S31,O46) -> 0 | G46: ОЗП | H46: Основная ЗП рабочих | K46: 205 | L46: 14 | M46: 3 | O46: 2 | P46: =ROUND(Source!DK31,O46) -> 0 | W46: 0 | X46: 1 | Y46: 0 | Z46: 0 | AA46: 1 | AB46: 0
A47: 50 | B47: 0 | C47: 0 | D47: 1 | E47: 232 | F47: =ROUND(Source!BC31,O47) -> 0 | G47: ОЗПсНРиСП | H47: Основная ЗП рабочих по ТСН-2001.16 | K47: 232 | L47: 15 | M47: 3 | O47: 2 | P47: =ROUND(Source!EU31,O47) -> 0 | W47: 0 | X47: 1 | Y47: 0 | Z47: 0 | AA47: 1 | AB47: 0
A48: 50 | B48: 0 | C48: 0 | D48: 1 | E48: 214 | F48: =ROUND(Source!AS31,O48) -> 0 | G48: Строит | H48: Строительные работы с НР и СП | K48: 214 | L48: 16 | M48: 3 | O48: 2 | P48: =ROUND(Source!EK31,O48) -> 0 | W48: 0 | X48: 1 | Y48: 0 | Z48: 0 | AA48: 1 | AB48: 0
A49: 50 | B49: 0 | C49: 0 | D49: 1 | E49: 215 | F49: =ROUND(Source!AT31,O49) -> 0 | G49: Монтаж | H49: Монтажные работы с НР и СП | K49: 215 | L49: 17 | M49: 3 | O49: 2 | P49: =ROUND(Source!EL31,O49) -> 0 | W49: 0 | X49: 1 | Y49: 0 | Z49: 0 | AA49: 1 | AB49: 0
A50: 50 | B50: 0 | C50: 0 | D50: 1 | E50: 217 | F50: =ROUND(Source!AU31,O50) -> 188203.04 | G50: Прочие | H50: Прочие работы с НР и СП | K50: 217 | L50: 18 | M50: 3 | O50: 2 | P50: =ROUND(Source!EM31,O50) -> 2900208.9 | W50: 188203.04 | X50: 1 | Y50: 188203.04 | Z50: 2900208.9 | AA50: 1 | AB50: 2900208.9
A51: 50 | B51: 0 | C51: 0 | D51: 1 | E51: 230 | F51: =ROUND(Source!BA31,O51) -> 0 | G51: ПрочиеЗатр | H51: Прочие затраты по ТСН-2001.16 | K51: 230 | L51: 19 | M51: 3 | O51: 2 | P51: =ROUND(Source!ES31,O51) -> 0 | W51: 0 | X51: 1 | Y51: 0 | Z51: 0 | AA51: 1 | AB51: 0
A52: 50 | B52: 0 | C52: 0 | D52: 1 | E52: 206 | F52: =ROUND(Source!T31,O52) -> 0 | G52: ВозврМат | H52: Возврат материалов | K52: 206 | L52: 20 | M52: 3 | O52: 2 | P52: =ROUND(Source!DL31,O52) -> 0 | W52: 0 | X52: 1 | Y52: 0 | Z52: 0 | AA52: 1 | AB52: 0
A53: 50 | B53: 0 | C53: 0 | D53: 1 | E53: 207 | F53: =Source!U31 -> 0 | G53: ТрудСтр | H53: Трудозатраты строителей | K53: 207 | L53: 21 | M53: 3 | O53: -1 | P53: =Source!DM31 -> 0 | W53: 0 | X53: 1 | Y53: 0 | Z53: 0 | AA53: 1 | AB53: 0
A54: 50 | B54: 0 | C54: 0 | D54: 1 | E54: 208 | F54: =Source!V31 -> 0 | G54: ТрудМаш | H54: Трудозатраты машинистов | K54: 208 | L54: 22 | M54: 3 | O54: -1 | P54: =Source!DN31 -> 0 | W54: 0 | X54: 1 | Y54: 0 | Z54: 0 | AA54: 1 | AB54: 0
A55: 50 | B55: 0 | C55: 0 | D55: 1 | E55: 209 | F55: =ROUND(Source!W31,O55) -> 0 | G55: ТранспМат | H55: Транспорт материалов | K55: 209 | L55: 23 | M55: 3 | O55: 2 | P55: =ROUND(Source!DO31,O55) -> 0 | W55: 0 | X55: 1 | Y55: 0 | Z55: 0 | AA55: 1 | AB55: 0
A56: 50 | B56: 0 | C56: 0 | D56: 1 | E56: 233 | F56: =ROUND(Source!BD31,O56) -> 0 | G56: Перевозка | H56: Перевозка грузов | K56: 233 | L56: 24 | M56: 3 | O56: 2 | P56: =ROUND(Source!EV31,O56) -> 0 | W56: 0 | X56: 1 | Y56: 0 | Z56: 0 | AA56: 1 | AB56: 0
A57: 50 | B57: 0 | C57: 0 | D57: 1 | E57: 210 | F57: =ROUND(Source!X31,O57) -> 0 | G57: НР | H57: Накладные расходы | K57: 210 | L57: 25 | M57: 3 | O57: 2 | P57: =ROUND(Source!DP31,O57) -> 0 | W57: 0 | X57: 1 | Y57: 0 | Z57: 0 | AA57: 1 | AB57: 0
A58: 50 | B58: 0 | C58: 0 | D58: 1 | E58: 211 | F58: =ROUND(Source!Y31,O58) -> 0 | G58: СмПриб | H58: Сметная прибыль | K58: 211 | L58: 26 | M58: 3 | O58: 2 | P58: =ROUND(Source!DQ31,O58) -> 0 | W58: 0 | X58: 1 | Y58: 0 | Z58: 0 | AA58: 1 | AB58: 0
A59: 50 | B59: 0 | C59: 0 | D59: 1 | E59: 224 | F59: =ROUND(Source!AR31,O59) -> 188203.04 | G59: Всего | H59: Всего с НР и СП | K59: 224 | L59: 27 | M59: 3 | O59: 2 | P59: =ROUND(Source!EJ31,O59) -> 2900208.9 | W59: 188203.04 | X59: 1 | Y59: 188203.04 | Z59: 2900208.9 | AA59: 1 | AB59: 2900208.9
A61: 51 | B61: =B20 -> 1 | C61: =A20 -> 3 | D61: =ROW(A20) -> 20 | F61: =IF(F20<>"",F20,"") -> 09-01-02 | G61: =IF(G20<>"",G20,"") -> Перевозка мусора | H61: 0 | O61: =ROUND(O31+AB61,2) -> 188203.04 | P61: =ROUND(P31+AC61,2) -> 0 | Q61: =ROUND(Q31+AD61,2) -> 188203.04 | R61: =ROUND(R31+AE61,2) -> 0 | S61: =ROUND(S31+AF61,2) -> 0 | T61: =ROUND(T31+AG61,2) -> 0 | U61: =U31+AH61 -> 0 | V61: =V31+AI61 -> 0 | W61: =ROUND(W31+AJ61,2) -> 0 | X61: =ROUND(X31+AK61,2) -> 0 | Y61: =ROUND(Y31+AL61,2) -> 0 | AO61: =ROUND(AO31+BX61,2) -> 0 | AP61: =ROUND(AP31+BY61,2) -> 0 | AQ61: =ROUND(AQ31+BZ61,2) -> 0 | AR61: =ROUND(AR31+CA61,2) -> 188203.04 | AS61: =ROUND(AS31+CB61,2) -> 0 | AT61: =ROUND(AT31+CC61,2) -> 0 | AU61: =ROUND(AU31+CD61,2) -> 188203.04 | AV61: =ROUND(AV31+CE61,2) -> 0 | ... BD61: =ROUND(BD31+CM61,2) -> 0 | DG61: =ROUND(DG31+DT61,2) -> 2900208.9 | DH61: =ROUND(DH31+DU61,2) -> 0 | DI61: =ROUND(DI31+DV61,2) -> 2900208.9 | DJ61: =ROUND(DJ31+DW61,2) -> 0 | DK61: =ROUND(DK31+DX61,2) -> 0 | DL61: =ROUND(DL31+DY61,2) -> 0 | DM61: =DM31+DZ61 -> 0 | DN61: =DN31+EA61 -> 0 | DO61: =ROUND(DO31+EB61,2) -> 0 | DP61: =ROUND(DP31+EC61,2) -> 0 | DQ61: =ROUND(DQ31+ED61,2) -> 0 | EG61: =ROUND(EG31+FP61,2) -> 0 | EH61: =ROUND(EH31+FQ61,2) -> 0 | EI61: =ROUND(EI31+FR61,2) -> 0 | EJ61: =ROUND(EJ31+FS61,2) -> 2900208.9 | EK61: =ROUND(EK31+FT61,2) -> 0 | EL61: =ROUND(EL31+FU61,2) -> 0 | EM61: =ROUND(EM31+FV61,2) -> 2900208.9 | EN61: =ROUND(EN31+FW61,2) -> 0 | ... EV61: =ROUND(EV31+GE61,2) -> 0 | GX61: 0
...

Sheet SourceObSm
A1: 0 | B1: Smeta.RU (495) 974-1589 | D1: _OBSM_ | F1: 0 | G1: 0 | H1: 0 | I1: Smeta.RU | K1: 1 | L1: 74562 | M1: 10 | N1: 11 | O1: 14 | P1: 0 | Q1: 0
A4: 1 | B4: 1 | C4: -1 | G4: Капитальный ремонт здания Государственного бюджетного общеобразовательного учреждения города Москвы «Школа № 236» по адресу: г. Москва, ул. Клязьминская, д. 7, к. 4. I этап | EC4: 0
A12: 1 | B12: 51 | C12: 0 | E12: 0 | F12: 09-01-02 | G12: 09-01-02 Перевозка мусора | I12: 0 | J12: 0224-00272-01-0-ООС2 | K12: 0 | L12: 0 | M12: 4098 | O12: 0 | P12: 0 | Q12: 0 | R12: 0 | S12: 0 | T12: 1 | V12: 0 | AB12: Лукьянова А.Л. | BB12: 0 | BH12: Сметные нормы списания | BI12: Коды ОКП для ТСН-2001 МГЭ Дополнение 79 | BJ12: 1 | BK12: 1 | BL12: 0 | BM12: 0 | BN12: 1 | BO12: 0 | BP12: 6 | BQ12: 2 | BR12: 1 | BS12: 1 | BT12: 0 | BU12: 0 | BV12: 0 | BW12: 0 | BX12: 0 | BY12: ТСН-2001 (МГЭ) Доп 79 - Новое строительство | BZ12: Типовой расчет для ТСН-2001 МГЭ, Дополнение 79, строительство | CA12: Территориальные сметные нормативы для Москвы ТСН-2001 (МГЭ), дополнение 79 | CB12: Территориальные сметные нормативы для Москвы ТСН-2001 (МГЭ), дополнение 79 | CC12: Территориальные сметные нормативы для Москвы ТСН-2001 (МГЭ), дополнение 79 | CD12: Территориальные сметные нормативы для Москвы ТСН-2001 (МГЭ), дополнение 79 | CE12: Поправки для ТСН-2001 от 03.10.2025 г. доп.79 | CF12: 0 | CG12: 0 | CH12: 8200 | CK12: 79 | CQ12: Территориальные сметные нормативы для Москвы (ТСН-2001) | CR12: ТЕР | CS12: 41660 | CT12: 1 | CU12: 79 | CY12: 0 | EC12: 0
A14: 22 | B14: 1 | C14: 0 | D14: 56526071 | E14: 56526069 | F14: 2 | G14: 1
A16: 3 | B16: 1 | C16: 09-01-02 | D16: Перевозка мусора | E16: =ROUND((Source!P78)/1000,2) -> 0 | F16: =ROUND((Source!P79)/1000,2) -> 0 | G16: =ROUND((Source!P70)/1000,2) -> 0 | H16: =ROUND((Source!P80)/1000+(Source!P81)/1000,2) -> 2900.21 | I16: =E16+F16+G16+H16 -> 2900.21 | J16: =ROUND((Source!P76+Source!P75)/1000,2) -> 0 | K16: 2900.21 | L16: 0 | M16: 0 | N16: =I16+L16+M16 -> 2900.21 | T16: =ROUND((Source!F78)/1000,2) -> 0 | U16: =ROUND((Source!F79)/1000,2) -> 0 | V16: =ROUND((Source!F70)/1000,2) -> 0 | W16: =ROUND((Source!F80)/1000+(Source!F81)/1000,2) -> 188.2 | X16: =T16+U16+V16+W16 -> 188.2 | Y16: =ROUND((Source!F76+Source!F75)/1000,2) -> 0 | Z16: 188.2 | AA16: 0 | AB16: 0 | AC16: =X16+AA16+AB16 -> 188.2 | AI16: 0 | AJ16: -1 | AN16: 0 | AT16: 2900208.9 | AU16: 0 | AV16: 0 | AW16: 0 | AX16: 0 | AY16: 2900208.9 | AZ16: 0 | BA16: 0 | BB16: 0 | BC16: 0 | BD16: 2900208.9 | BE16: 0 | BF16: 0 | BG16: 0 | BH16: 0 | BI16: 0 | BJ16: 0 | BK16: 2900208.9 | BR16: 188203.04 | BS16: 0 | BT16: 0 | BU16: 0 | BV16: 0 | BW16: 188203.04 | BX16: 0 | BY16: 0 | BZ16: 0 | CA16: 0 | CB16: 188203.04 | CC16: 0 | CD16: 0 | CE16: 0 | CF16: 0 | CG16: 0 | CH16: 0 | CI16: 188203.04
A18: 51 | E18: 0 | F18: 0 | G18: 0 | H18: 2900.21 | I18: 2900.21 | J18: 0 | K18: 2900.21 | L18: 0 | M18: 0 | N18: 2900.21 | T18: 0 | U18: 0 | V18: 0 | W18: 188.2 | X18: 188.2 | Y18: 0 | Z18: 188.2 | AA18: 0 | AB18: 0 | AC18: 188.2
A20: 50 | B20: 0 | C20: 0 | D20: 1 | E20: 201 | F20: 2900208.9 | G20: ПЗ | H20: Прямые затраты | K20: 201 | L20: 1 | M20: 3 | O20: 2 | P20: 188203.04
A21: 50 | B21: 0 | C21: 0 | D21: 1 | E21: 202 | F21: 0 | G21: СтМатОб | H21: Стоимость материальных ресурсов (всего) | K21: 202 | L21: 2 | M21: 3 | O21: 2 | P21: 0
A22: 50 | B22: 0 | C22: 0 | D22: 1 | E22: 222 | F22: 0 | G22: СтМатОбЗак | H22: Стоимость материалов и оборудования заказчика | K22: 222 | L22: 3 | M22: 3 | O22: 2 | P22: 0
A23: 50 | B23: 0 | C23: 0 | D23: 1 | E23: 225 | F23: 0 | G23: СтМатОбПод | H23: Стоимость материалов и оборудования подрядчика | K23: 225 | L23: 4 | M23: 3 | O23: 2 | P23: 0
A24: 50 | B24: 0 | C24: 0 | D24: 1 | E24: 226 | F24: 0 | G24: СтМат | H24: Стоимость материалов (всего) | K24: 226 | L24: 5 | M24: 3 | O24: 2 | P24: 0
A25: 50 | B25: 0 | C25: 0 | D25: 1 | E25: 227 | F25: 0 | G25: СтМатЗак | H25: Стоимость материалов заказчика | K25: 227 | L25: 6 | M25: 3 | O25: 2 | P25: 0
A26: 50 | B26: 0 | C26: 0 | D26: 1 | E26: 228 | F26: 0 | G26: СтМатПод | H26: Стоимость материалов подрядчика | K26: 228 | L26: 7 | M26: 3 | O26: 2 | P26: 0
A27: 50 | B27: 0 | C27: 0 | D27: 1 | E27: 216 | F27: 0 | G27: Оборуд | H27: Стоимость оборудования (всего) | K27: 216 | L27: 8 | M27: 3 | O27: 2 | P27: 0
A28: 50 | B28: 0 | C28: 0 | D28: 1 | E28: 223 | F28: 0 | G28: ОборудЗак | H28: Стоимость оборудования заказчика | K28: 223 | L28: 9 | M28: 3 | O28: 2 | P28: 0
A29: 50 | B29: 0 | C29: 0 | D29: 1 | E29: 229 | F29: 0 | G29: ОборудПод | H29: Стоимость оборудования подрядчика | K29: 229 | L29: 10 | M29: 3 | O29: 2 | P29: 0
A30: 50 | B30: 0 | C30: 0 | D30: 1 | E30: 203 | F30: 2900208.9 | G30: ЭММ | H30: Эксплуатация машин | K30: 203 | L30: 11 | M30: 3 | O30: 2 | P30: 188203.04
A31: 50 | B31: 0 | C31: 0 | D31: 1 | E31: 231 | F31: 0 | G31: ЭММсНРиСП | H31: Эксплуатация машин по ТСН-2001.16 | K31: 231 | L31: 12 | M31: 3 | O31: 2 | P31: 0
... A46: 50 | B46: 0 | C46: 0 | D46: 1 | E46: 224 | F46: 2900208.9 | G46: Всего | H46: Всего с НР и СП | K46: 224 | L46: 27 | M46: 3 | O46: 2 | P46: 188203.04
A48: -1
A51: 75 | B51: Текущий уровень цен | C51: 2025 | D51: 0 | E51: 7 | G51: 0 | H51: 1 | I51: 1 | J51: 3 | K51: 0 | L51: 0 | M51: 1 | N51: 56526071 | O51: 1
A52: 1 | B52: Сборник индексов | C52: Коэффициенты к ТСН-2001 МГЭ Дополнение 79, строительство | D52: 2025 | E52: 7 | F52: 1 | G52: 1 | H52: 0 | I52: 2 | J52: 1 | K52: 1 | L52: 1 | M52: 1 | N52: 1 | O52: 1 | P52: 1 | Q52: 1 | AA52: 216/79 | AN52: 56526072
A53: 1 | B53: Сборник индексов | C53: Коэффициенты к ТСН-2001.13-2 Дополнение 45 | D53: 2025 | E53: 7 | F53: 1 | G53: 1 | H53: 0 | I53: 2 | J53: 1 | K53: 1 | L53: 1 | M53: 1 | N53: 1 | O53: 1 | P53: 1 | Q53: 1 | AA53: 62/45 | AN53: 56526073
A54: 75 | B54: Базовый уровень цен | C54: 2000 | D54: 0 | E54: 1 | F54: 0 | G54: 0 | H54: 1 | I54: 1 | J54: 3 | K54: 0 | L54: 0 | M54: 0 | N54: 56526069 | O54: 2
A55: 1 | B55: Сборник индексов | C55: Коэффициенты к ТСН-2001 МГЭ Дополнение 79, строительство | D55: 2000 | E55: 1 | F55: 1 | G55: 1 | H55: 0 | I55: 2 | J55: 1 | K55: 1 | L55: 1 | M55: 1 | N55: 1 | O55: 1 | P55: 1 | Q55: 1 | AN55: 56526070

Sheet SmtRes
A1: =ROW(Source!A28) -> 28 | B1: 56526069 | C1: 56526703 | D1: 54836954 | E1: 1079 | F1: 1 | G1: 1079 | H1: 2 | I1: 9999990007 | K1: Стоимость прочих машин (ЭСН) | L1: 1344 | N1: 1008 | O1: руб. | P1: руб. | Q1: 1 | W1: 0 | X1: -1180195794 | Y1: =AT1 -> 58.45 | AA1: 0 | AB1: 1 | AC1: 0 | AD1: 0 | AE1: 0 | AF1: 1 | AG1: 0 | AH1: 0 | AI1: 1 | AJ1: 1 | AK1: 1 | AL1: 1 | AM1: -2 | AN1: 0 | AO1: 1 | AP1: 1 | AQ1: 0 | AR1: 0 | AT1: 58.45 | AV1: 0 | AW1: 2 | AX1: 56526706 | AY1: 1 | AZ1: 0 | BA1: 1 | BB1: 0 | BC1: 0 | BD1: 0 | BE1: 0 | BF1: 0 | BG1: 0 | BH1: 0 | BI1: 0 | BJ1: 0 | BK1: 0 | BL1: 0 | BM1: 0 | BN1: 0 | BO1: 0 | BP1: 0 | BQ1: 0 | BR1: 0 | BS1: 0 | BT1: 0 | BU1: 0 | BV1: 0 | BW1: 0 | CV1: 0 | CW1: =ROUND(Y1*Source!I28*DO1,9) -> 0 | CX1: =ROUND(Y1*Source!I28,9) -> 188203.04 | CY1: =AB1 -> 1 | CZ1: =AF1 -> 1 | DA1: =AJ1 -> 1 | DB1: =ROUND(ROUND(AT1*CZ1,2),6) -> 58.45 | DC1: =ROUND(ROUND(AT1*AG1,2),6) -> 0 | DF1: =ROUND(ROUND(AE1,2)*CX1,2) -> 0 | DG1: =ROUND(ROUND(AF1,2)*CX1,2) -> 188203.04 | DH1: =ROUND(ROUND(AG1,2)*CX1,2) -> 0 | DI1: =ROUND(ROUND(AH1,2)*CX1,2) -> 0 | DJ1: =DG1 -> 188203.04 | DK1: 0 | DM1: 0 | DO1: 0
A2: =ROW(Source!A29) -> 29 | B2: 56526071 | C2: 56526703 | D2: 54836954 | E2: 1079 | F2: 1 | G2: 1079 | H2: 2 | I2: 9999990007 | K2: Стоимость прочих машин (ЭСН) | L2: 1344 | N2: 1008 | O2: руб. | P2: руб. | Q2: 1 | W2: 0 | X2: -1180195794 | Y2: =AT2 -> 58.45 | AA2: 0 | AB2: 1 | AC2: 0 | AD2: 0 | AE2: 0 | AF2: 1 | AG2: 0 | AH2: 0 | AI2: 1 | AJ2: 1 | AK2: 1 | AL2: 1 | AM2: -2 | AN2: 0 | AO2: 1 | AP2: 1 | AQ2: 0 | AR2: 0 | AT2: 58.45 | AV2: 0 | AW2: 2 | AX2: 56526706 | AY2: 1 | AZ2: 0 | BA2: 2 | BB2: 0 | BC2: 0 | BD2: 0 | BE2: 0 | BF2: 0 | BG2: 0 | BH2: 0 | BI2: 0 | BJ2: 0 | BK2: 0 | BL2: 0 | BM2: 0 | BN2: 0 | BO2: 0 | BP2: 0 | BQ2: 0 | BR2: 0 | BS2: 0 | BT2: 0 | BU2: 0 | BV2: 0 | BW2: 0 | CV2: 0 | CW2: =ROUND(Y2*Source!I29*DO2,9) -> 0 | CX2: =ROUND(Y2*Source!I29,9) -> 188203.04 | CY2: =AB2 -> 1 | CZ2: =AF2 -> 1 | DA2: =AJ2 -> 1 | DB2: =ROUND(ROUND(AT2*CZ2,2),6) -> 58.45 | DC2: =ROUND(ROUND(AT2*AG2,2),6) -> 0 | DF2: =ROUND(ROUND(AE2,2)*CX2,2) -> 0 | DG2: =ROUND(ROUND(AF2,2)*CX2,2) -> 188203.04 | DH2: =ROUND(ROUND(AG2,2)*CX2,2) -> 0 | DI2: =ROUND(ROUND(AH2,2)*CX2,2) -> 0 | DJ2: =DG2 -> 188203.04 | DK2: 0 | DM2: 0 | DO2: 0

Sheet EtalonRes
A1: =ROW(Source!A28) -> 28 | B1: 56526706 | C1: 56526703 | D1: 54836954 | E1: 1079 | F1: 1 | G1: 1079 | H1: 2 | I1: 9999990007 | K1: Стоимость прочих машин (ЭСН) | L1: 1344 | N1: 1008 | O1: руб. | P1: руб. | Q1: 1 | X1: 58.45 | Y1: 0 | Z1: 1 | AA1: 0 | AB1: 0 | AC1: 0 | AD1: 1 | AE1: 0 | AG1: 58.45 | AH1: 2 | AI1: 56526706 | AJ1: 1 | AK1: 0 | AL1: 0 | AM1: 0 | AN1: 0 | AO1: 0 | AP1: 0 | AQ1: 0 | AR1: 0
A2: =ROW(Source!A29) -> 29 | B2: 56526706 | C2: 56526703 | D2: 54836954 | E2: 1079 | F2: 1 | G2: 1079 | H2: 2 | I2: 9999990007 | K2: Стоимость прочих машин (ЭСН) | L2: 1344 | N2: 1008 | O2: руб. | P2: руб. | Q2: 1 | X2: 58.45 | Y2: 0 | Z2: 1 | AA2: 0 | AB2: 0 | AC2: 0 | AD2: 1 | AE2: 0 | AG2: 58.45 | AH2: 2 | AI2: 56526706 | AJ2: 2 | AK2: 0 | AL2: 0 | AM2: 0 | AN2: 0 | AO2: 0 | AP2: 0 | AQ2: 0 | AR2: 0

Sheet SrcPoprs

Sheet SrcKA
A1: 0 | B1: Smeta.RU (495) 974-1589 | D1: _PS_ | F1: 0 | G1: 0 | H1: 0 | I1: Smeta.RU | K1: 1 | L1: 74562 | M1: 10 | N1: 11 | O1: 14 | P1: 0 | Q1: 0
F12: =Source!F12 -> 09-01-02 | G12: =Source!G12 -> 09-01-02 Перевозка мусора | CY12: =Source!CY12 -> 0
