Workbook

Sheet 09-01-03
A1: =Source!B1 -> Smeta.RU (495) 974-1589
J2: Форма № 4б
B3: "СОГЛАСОВАНО" | G3: "УТВЕРЖДАЮ"
B6: =CONCATENATE("______________________ ", IF(Source!AL12<>"", Source!AL12, "")) -> ______________________ | G6: =CONCATENATE("______________________ ", IF(Source!AH12<>"", Source!AH12, "")) -> ______________________
B7: "_____"________________ 2025 г. | G7: "_____"________________ 2025 г.
A10: Капитальный ремонт здания Государственного бюджетного общеобразовательного учреждения города Москвы «Школа № 236» по адресу: г. Москва, ул. Клязьминская, д. 7, к. 4. I этап | AP10: Капитальный ремонт здания Государственного бюджетного общеобразовательного учреждения города Москвы «Школа № 236» по адресу: г. Москва, ул. Клязьминская, д. 7, к. 4. I этап. 09-01-03 Размещение и содержание строительного мусора
A11: (наименование стройки и/или объекта)
A13: ЛОКАЛЬНАЯ СМЕТА № 09-01-03
A15: =IF(Source!G20<>"Новая локальная смета", Source!G20, "") -> Размещение и содержание строительного мусора
A16: (наименование работ и затрат)
A18: =CONCATENATE( "Основание: чертежи № ", Source!J20) -> Основание: чертежи № 0224-00272-01-0-ООС2
I20: В базисном уровне цен | J20: В текущем уровне цен
E21: Сметная стоимость | I21: =I22+I23+I24+I25 -> 96.54 | J21: =J22+J23+J24+J25 -> 961.16 | K21: тыс.руб.
E22: Строительные работы | I22: =ROUND((Source!F112)/1000, 2) -> 0 | J22: =ROUND((Source!P112)/1000, 2) -> 0 | K22: тыс.руб.
E23: Работы по монтажу оборудования | I23: =ROUND((Source!F113)/1000, 2) -> 0 | J23: =ROUND((Source!P113)/1000, 2) -> 0 | K23: тыс.руб.
E24: Оборудование | I24: =ROUND((Source!F104)/1000, 2) -> 0 | J24: =ROUND((Source!P104)/1000, 2) -> 0 | K24: тыс.руб.
E25: Прочие работы и затраты | I25: =ROUND((Source!F114+Source!F115)/1000, 2) -> 96.54 | J25: =ROUND((Source!P114+Source!P115)/1000, 2) -> 961.16 | K25: тыс.руб.
E26: Средства на оплату труда | I26: =(Source!F110+ Source!F109)/1000 -> 0 | J26: =((Source!P110 + Source!P109)/1000) -> 0 | K26: тыс.руб.
E27: Затраты труда | I27: =Source!F117 -> 0 | K27: чел.-ч.
E28: Кроме того:
E29: Возврат материалов | I29: =SUM(Y35:Y152)/1000 -> 0 | J29: =SUM(Z35:Z152)/1000 -> 0 | K29: тыс.руб.
A31: Составлен(а) по ТСН-2001 с учетом Дополнения №: 79
A32: № и период сборника коэффициентов (индексов) пересчета: Коэффициенты к ТСН-2001 МГЭ Дополнение 79, ремонт №216/79 III квартал 2025 года и Коэффициенты к ТСН-2001.13-2 Дополнение 45 №62/45 III квартал 2025 года | M32: 3 кв-л сентябрь | AP32: № и период сборника коэффициентов (индексов) пересчета: Коэффициенты к ТСН-2001 МГЭ Дополнение 79, ремонт №216/79 III квартал 2025 года и Коэффициенты к ТСН-2001.13-2 Дополнение 45 №62/45 III квартал 2025 года
A33: № п/п | B33: Шифр расценки и коды ресурсов | C33: Наименование работ и затрат | D33: Ед. изм. | E33: Кол-во единиц | F33: Цена на ед. изм., руб. | G33: Попра- вочные коэффи- циенты | H33: Коэффи- циенты зимних удорожа- ний | I33: Всего в ценах на январь 2000 года, руб. | J33: Коэффи- циенты (индек- сы) пере- счета, нормы НР и СП | K33: ВСЕГО затрат в текущем уровне цен, руб.
A34: 1 | B34: 2 | C34: 3 | D34: 4 | E34: 5 | F34: 6 | G34: 7 | H34: 8 | I34: 9 | J34: 10 | K34: 11
A36: =CONCATENATE("Раздел: ",IF(Source!G24<>"Новый раздел", Source!G24, "")) -> Раздел: Размещение и содержание строительного мусора
A37: 1 | B37: =Source!F28 -> 15.1-1500-01 | C37: Отходы (мусор) от строительных и ремонтных работ малоопасные | D37: =Source!H28 -> 1 Т | E37: =Source!I28 -> 74.973 | Q37: =Source!X28 -> 0 | R37: =Source!X29 -> 0 | S37: =Source!Y28 -> 0 | T37: =Source!Y29 -> 0 | U37: =ROUND((175/100)*ROUND(Source!R28, 2), 2) -> 0 | V37: =ROUND((0/100)*ROUND(Source!R29, 2), 2) -> 0 | AC37: 0
C38: ЭМ | F38: =Source!AM28 -> 31.67 | G38: =Source!DE28 | H38: =Source!AV29 -> 1 | I38: =Source!Q28 -> 2374.39 | J38: =IF(Source!BB29<> 0, Source!BB29, 1) -> 43.37 | K38: =Source!Q29 -> 102977.29
C39: ВСЕГО работ по позиции: | H39: =I38+0-0-0 -> 2374.39 | J39: =K38+0-0-0 -> 102977.29
C40: ВСЕГО оборудование по позиции: | H40: =0+0 -> 0 | J40: =0+0 -> 0
C41: ВСЕГО по позиции: | H41: =I38+0 -> 2374.39 | J41: =K38+0 -> 102977.29 | O41: =I38+0 -> 2374.39 | P41: =K38+0 -> 102977.29
A43: 2 | B43: =Source!F30 -> 15.1-1201-10 | C43: Отходы затвердевшего строительного раствора в кусковой форме, малоопасные | D43: =Source!H30 -> 1 Т | E43: =Source!I30 -> 1545.61 | Q43: =Source!X30 -> 0 | R43: =Source!X31 -> 0 | S43: =Source!Y30 -> 0 | T43: =Source!Y31 -> 0 | U43: =ROUND((175/100)*ROUND(Source!R30, 2), 2) -> 0 | V43: =ROUND((0/100)*ROUND(Source!R31, 2), 2) -> 0 | AC43: 0
C44: ЭМ | F44: =Source!AM30 -> 31.13 | G44: =Source!DE30 | H44: =Source!AV31 -> 1 | I44: =Source!Q30 -> 48114.84 | J44: =IF(Source!BB31<> 0, Source!BB31, 1) -> 9.33 | K44: =Source!Q31 -> 448911.46
C45: ВСЕГО работ по позиции: | H45: =I44+0-0-0 -> 48114.84 | J45: =K44+0-0-0 -> 448911.46
C46: ВСЕГО оборудование по позиции: | H46: =0+0 -> 0 | J46: =0+0 -> 0
C47: ВСЕГО по позиции: | H47: =I44+0 -> 48114.84 | J47: =K44+0 -> 448911.46 | O47: =I44+0 -> 48114.84 | P47: =K44+0 -> 448911.46
A49: 3 | B49: =Source!F32 -> 15.1-1203-06 | C49: Отходы штукатурки затвердевшей малоопасные | D49: =Source!H32 -> 1 Т | E49: =Source!I32 -> 195.77 | Q49: =Source!X32 -> 0 | R49: =Source!X33 -> 0 | S49: =Source!Y32 -> 0 | T49: =Source!Y33 -> 0 | U49: =ROUND((175/100)*ROUND(Source!R32, 2), 2) -> 0 | V49: =ROUND((0/100)*ROUND(Source!R33, 2), 2) -> 0 | AC49: 0
C50: ЭМ | F50: =Source!AM32 -> 36.59 | G50: =Source!DE32 | H50: =Source!AV33 -> 1 | I50: =Source!Q32 -> 7163.22 | J50: =IF(Source!BB33<> 0, Source!BB33, 1) -> 9.57 | K50: =Source!Q33 -> 68552.02
C51: ВСЕГО работ по позиции: | H51: =I50+0-0-0 -> 7163.22 | J51: =K50+0-0-0 -> 68552.02
C52: ВСЕГО оборудование по позиции: | H52: =0+0 -> 0 | J52: =0+0 -> 0
...

Sheet Ведомость объемов работ
A1: =Source!B1 -> Smeta.RU (495) 974-1589
E3: "УТВЕРЖДАЮ"
D5: ___________________________
D7: ___________________________
D9: " ___ " ___________ 20 ___ г.
B12: =CONCATENATE("Ведомость объемов работ ", IF(Source!AN15<>"", Source!AN15," ")) -> Ведомость объемов работ
B13: =CONCATENATE(Source!F12, " ", Source!G12) -> 09-01-03 09-01-03 Размещение и содержание строительного мусора
A16: № п/п | B16: № в ЛСР | C16: Наименование работ и затрат | D16: Единица измерения | E16: Количество | F16: Ссылка на чертежи, спецификации | G16: Формула расчета, расчет объемов работ и расхода материалов | H16: Примечание
A17: 1 | B17: 2 | C17: 3 | D17: 4 | E17: 5 | F17: 6 | G17: 7 | H17: 8
A18: =CONCATENATE("Локальная смета: ", Source!G20) -> Локальная смета: Размещение и содержание строительного мусора
A19: =CONCATENATE("Раздел: ", Source!G24) -> Раздел: Размещение и содержание строительного мусора
A20: 1 | B20: =Source!E28 -> 1 | C20: =Source!G28 -> Отходы (мусор) от строительных и ремонтных работ малоопасные | D20: 1 Т | E20: =Source!I28 -> 74.973 | F20: =Source!U24 | G20: =Source!I28 -> 74.973
A21: 2 | B21: =Source!E30 -> 2 | C21: =Source!G30 -> Отходы затвердевшего строительного раствора в кусковой форме, малоопасные | D21: 1 Т | E21: =Source!I30 -> 1545.61 | F21: =Source!U24 | G21: =Source!I30 -> 1545.61
A22: 3 | B22: =Source!E32 -> 3 | C22: =Source!G32 -> Отходы штукатурки затвердевшей малоопасные | D22: 1 Т | E22: =Source!I32 -> 195.77 | F22: =Source!U24 | G22: =Source!I32 -> 195.77
A23: 4 | B23: =Source!E34 -> 4 | C23: =Source!G34 -> Отходы прочих теплоизоляционных материалов на основе минерального волокна незагрязненные, практически неопасные | D23: 1 Т | E23: =Source!I34 -> 4.248 | F23: =Source!U24 | G23: =Source!I34 -> 4.248
A24: 5 | B24: =Source!E36 -> 5 | C24: =Source!G36 -> Обрезь и лом гипсокартонных листов малоопасные | D24: 1 Т | E24: =Source!I36 -> 0.035 | F24: =Source!U24 | G24: =Source!I36 -> 0.035
A25: 6 | B25: =Source!E38 -> 6 | C25: =Source!G38 -> Отходы линолеума незагрязненные малоопасные | D25: 1 Т | E25: =Source!I38 -> 3.487 | F25: =Source!U24 | G25: =Source!I38 -> 3.487
A26: 7 | B26: =Source!E40 -> 7 | C26: =Source!G40 -> Отходы фанеры и изделий из нее незагрязненные | D26: 1 Т | E26: =Source!I40 -> 0.027 | F26: =Source!U24 | G26: =Source!I40 -> 0.027
A27: 8 | B27: =Source!E42 -> 8 | C27: =Source!G42 -> Отходы (мусор) от строительных и ремонтных работ малоопасные / светильники со светодиодными элементами в сборе | D27: 1 Т | E27: =Source!I42 -> 0.653 | F27: =Source!U24 | G27: =Source!I42 -> 0.653
A28: 9 | B28: =Source!E44 -> 9 | C28: =Source!G44 -> Смесь незагрязненных строительных материалов на основе полимеров, содержащая поливинилхлорид малоопасная | D28: 1 Т | E28: =Source!I44 -> 3.873 | F28: =Source!U24 | G28: =Source!I44 -> 3.873
A29: 10 | B29: =Source!E46 -> 10 | C29: =Source!G46 -> Лом бетонных изделий, отходы бетона в кусковой форме, практически неопасные | D29: 1 Т | E29: =Source!I46 -> 666.679 | F29: =Source!U24 | G29: =Source!I46 -> 666.679
A30: 11 | B30: =Source!E48 -> 11 | C30: =Source!G48 -> Лом черепицы, керамики незагрязненный практически неопасный | D30: 1 Т | E30: =Source!I48 -> 146.251 | F30: =Source!U24 | G30: =Source!I48 -> 146.251
A31: 12 | B31: =Source!E50 -> 12 | C31: =Source!G50 -> Лом строительного кирпича незагрязненный практически неопасный | D31: 1 Т | E31: =Source!I50 -> 0.309 | F31: =Source!U24 | G31: =Source!I50 -> 0.309
A32: 13 | B32: =Source!E52 -> 13 | C32: =Source!G52 -> Лом кирпичной кладки от сноса и разборки зданий практически неопасный | D32: 1 Т | E32: =Source!I52 -> 206.091 | F32: =Source!U24 | G32: =Source!I52 -> 206.091
A33: 14 | B33: =Source!E54 -> 14 | C33: =Source!G54 -> Лом бортовых камней, брусчатки, булыжных камней и прочие отходы изделий из природного камня, практически неопасный | D33: 1 Т | E33: =Source!I54 -> 4.628 | F33: =Source!U24 | G33: =Source!I54 -> 4.628
A34: 15 | B34: =Source!E56 -> 15 | C34: =Source!G56 -> Отходы изолированных проводов и кабелей | D34: 1 Т | E34: =Source!I56 -> 3.611 | F34: =Source!U24 | G34: =Source!I56 -> 3.611
A35: 16 | B35: =Source!E58 -> 16 | C35: =Source!G58 -> Лом и отходы изделий из полипропилена незагрязненные (кроме тары) | D35: 1 Т | E35: =Source!I58 -> 1.685 | F35: =Source!U24 | G35: =Source!I58 -> 1.685
A36: 17 | B36: =Source!E60 -> 17 | C36: =Source!G60 -> Прочая продукция из натуральной древесины, утратившая потребительские свойства, незагрязненная | D36: 1 Т | E36: =Source!I60 -> 2.6 | F36: =Source!U24 | G36: =Source!I60 -> 2.6
A37: 18 | B37: =Source!E62 -> 18 | C37: =Source!G62 -> Керамзит, утративший потребительские свойства, незагрязненный, практически неопасный | D37: 1 Т | E37: =Source!I62 -> 318.564 | F37: =Source!U24 | G37: =Source!I62 -> 318.564
C40: Главный инженер проекта _________________ | D40: =IF(Source!X12<>"", Source!X12," ")
C42: Составил _________________ | D42: =IF(Source!AB12<>"", Source!AB12," ") -> Лукьянова А.Л.

Sheet Source
A1: 0 | B1: Smeta.RU (495) 974-1589 | D1: _PS_ | F1: 0 | G1: 0 | H1: 0 | I1: Smeta.RU | K1: 1 | L1: 74562 | M1: 10 | N1: 11 | O1: 14 | P1: 0 | Q1: 0
A4: 1 | B4: 1 | C4: -1 | G4: Капитальный ремонт здания Государственного бюджетного общеобразовательного учреждения города Москвы «Школа № 236» по адресу: г. Москва, ул. Клязьминская, д. 7, к. 4. I этап | EC4: 0
A12: 1 | B12: 165 | C12: 0 | D12: =ROW(A125) -> 125 | E12: 0 | F12: 09-01-03 | G12: 09-01-03 Размещение и содержание строительного мусора | I12: 0 | J12: 0224-00272-01-0-ООС2 | K12: 0 | L12: 0 | M12: 4098 | O12: 0 | P12: 0 | Q12: 0 | R12: 0 | S12: 0 | T12: 1 | V12: 0 | AB12: Лукьянова А.Л. | BB12: 0 | BH12: Сметные нормы списания | BI12: Коды ОКП для ТСН-2001 МГЭ Дополнение 79 | BJ12: 1 | BK12: 1 | BL12: 0 | BM12: 0 | BN12: 1 | BO12: 0 | BP12: 6 | BQ12: 2 | BR12: 1 | BS12: 1 | BT12: 0 | BU12: 0 | BV12: 0 | BW12: 0 | BX12: 0 | BY12: ТСН-2001 (МГЭ) Доп 79 - Ремонт | BZ12: Типовой расчет для ТСН-2001 МГЭ, Дополнение 79, ремонт | CA12: Территориальные сметные нормативы для Москвы ТСН-2001 (МГЭ), дополнение 79 | CB12: Территориальные сметные нормативы для Москвы ТСН-2001 (МГЭ), дополнение 79 | CC12: Территориальные сметные нормативы для Москвы ТСН-2001 (МГЭ), дополнение 79 | CD12: Территориальные сметные нормативы для Москвы ТСН-2001 (МГЭ), дополнение 79 | CE12: Поправки для ТСН-2001 от 03.10.2025 г. доп.79 | CF12: 0 | CG12: 0 | CH12: 8200 | CK12: 79 | CQ12: Территориальные сметные нормативы для Москвы (ТСН-2001) | CR12: ТЕР | CS12: 41660 | CT12: 1 | CU12: 79 | CY12: 0 | EC12: 0
A15: 15 | B15: 1
A18: 52 | B18: =B125 -> 165 | C18: =C125 -> 1 | D18: =D125 -> 12 | E18: =E125 -> 0 | F18: =F125 -> 09-01-03 | G18: =G125 -> 09-01-03 Размещение и содержание строительного мусора | O18: =O125 -> 96538.04 | P18: =P125 -> 0 | Q18: =Q125 -> 96538.04 | R18: =R125 -> 0 | S18: =S125 -> 0 | T18: =T125 -> 0 | U18: =U125 -> 0 | V18: =V125 -> 0 | ... GX18: =GX125 -> 0
A20: 3 | B20: 1 | D20: =ROW(A95) -> 95 | G20: Размещение и содержание строительного мусора | I20: 0 | J20: 0224-00272-01-0-ООС2 | K20: -1 | L20: 09-01-03 | S20: 0 | T20: 0 | V20: 0 | AB20: Лукьянова А.Л. | BX20: 0 | CF20: 0 | CG20: 0
A22: 52 | B22: =B95 -> 1 | C22: =C95 -> 3 | D22: =D95 -> 20 | E22: =E95 -> 0 | F22: =F95 | G22: =G95 -> Размещение и содержание строительного мусора | O22: =O95 -> 96538.04 | P22: =P95 -> 0 | Q22: =Q95 -> 96538.04 | R22: =R95 -> 0 | S22: =S95 -> 0 | T22: =T95 -> 0 | U22: =U95 -> 0 | V22: =V95 -> 0 | ... GX22: =GX95 -> 0
A24: 4 | B24: 1 | D24: =ROW(A65) -> 65 | G24: Размещение и содержание строительного мусора | I24: 0 | K24: -1 | S24: 0 | T24: 0 | V24: 0 | BX24: 0 | CJ24: 0
A26: 52 | B26: =B65 -> 1 | C26: =C65 -> 4 | D26: =D65 -> 24 | E26: =E65 -> 0 | F26: =F65 | G26: =G65 -> Размещение и содержание строительного мусора | O26: =O65 -> 96538.04 | P26: =P65 -> 0 | Q26: =Q65 -> 96538.04 | R26: =R65 -> 0 | S26: =S65 -> 0 | T26: =T65 -> 0 | U26: =U65 -> 0 | V26: =V65 -> 0 | ... GX26: =GX65 -> 0
A28: 17 | B28: 1 | C28: =ROW(SmtRes!A1) -> 1 | D28: =ROW(EtalonRes!A1) -> 1 | E28: 1 | F28: 15.1-1500-01 | G28: Отходы (мусор) от строительных и ремонтных работ малоопасные | H28: 1 Т | I28: 74.973 | J28: 0 | K28: 74.973 | O28: =ROUND(CP28,2) -> 2374.39 | P28: =ROUND((ROUND((AC28*AW28*I28),2)*BC28),2) -> 0 | Q28: =(ROUND((ROUND(((ET28)*AV28*I28),2)*BB28),2)+ROUND((ROUND(((AE28-(EU28))*AV28*I28),2)*BS28),2)) -> 2374.39 | R28: =ROUND((ROUND((AE28*AV28*I28),2)*BS28),2) -> 0 | S28: =ROUND((ROUND((AF28*AV28*I28),2)*BA28),2) -> 0 | T28: =ROUND(CU28*I28,2) -> 0 | U28: =CV28*I28 -> 0 | V28: =CW28*I28 -> 0 | W28: =ROUND(CX28*I28,2) -> 0 | X28: =ROUND(CY28,2) -> 0 | Y28: =ROUND(CZ28,2) -> 0 | AA28: 56526439 | AB28: =ROUND((AC28+AD28+AF28),6) -> 31.67 | AC28: =ROUND((ES28),6) -> 0 | AD28: =ROUND((((ET28)-(EU28))+AE28),6) -> 31.67 | AE28: =ROUND((EU28),6) -> 0 | AF28: =ROUND((EV28),6) -> 0 | AG28: =ROUND((AP28),6) -> 0 | AH28: =(EW28) -> 0 | AI28: =(EX28) -> 0 | AJ28: =(AS28) -> 0 | AK28: 31.67 | AL28: 0 | AM28: 31.67 | AN28: 0 | AO28: 0 | AP28: 0 | AQ28: 0 | AR28: 0 | AS28: 0 | AT28: 94 | AU28: 61 | AV28: 1 | AW28: 1 | AZ28: 1 | BA28: 1 | BB28: 1 | BC28: 1 | BH28: 0 | BI28: 4 | BJ28: ТСН-2001.15 Доп. 56, Сб. 1, т. 1500, поз. 1 | BM28: 188 | BN28: 0 | BO28: 15.1-1500-01 | BP28: 1 | BQ28: 150 | BR28: 0 | BS28: 1 | BT28: 1 | BU28: 1 | BV28: 1 | BW28: 1 | BX28: 1 | BZ28: 94 | CA28: 61 | CE28: 30 | CF28: 0 | CG28: 0 | CM28: 0 | CO28: 0 | CP28: =(P28+Q28+S28) -> 2374.39 | CQ28: =ROUND((ROUND((AC28*AW28*1),2)*BC28),2) -> 0 | CR28: =(ROUND((ROUND(((ET28)*AV28*1),2)*BB28),2)+ROUND((ROUND(((AE28-(EU28))*AV28*1),2)*BS28),2)) -> 31.67 | CS28: =ROUND((ROUND((AE28*AV28*1),2)*BS28),2) -> 0 | CT28: =ROUND((ROUND((AF28*AV28*1),2)*BA28),2) -> 0 | CU28: =AG28 -> 0 | CV28: =(AH28*AV28) -> 0 | CW28: =AI28 -> 0 | CX28: =AJ28 -> 0 | CY28: =(((S28+R28)*AT28)/100) -> 0 | CZ28: =(((S28+R28)*AU28)/100) -> 0 | DN28: 0 | DO28: 0 | DP28: 1 | DQ28: 1 | DU28: 1013 | DV28: 1 Т | DW28: 1 Т | DX28: 1 | EE28: 55586412 | EF28: 150 | EG28: Транспортные затраты | EH28: 0 | EJ28: 4 | EK28: 188 | EL28: ТСН-2001.15. Перевозка строительных грузов автомобильным транспортом | EM28: ТСН-2001.15. | EQ28: 0 | ER28: 31.67 | ES28: 0 | ET28: 31.67 | EU28: 0 | EV28: 0 | EW28: 0 | EX28: 0 | EY28: 0 | FQ28: 0 | FR28: 0 | FS28: 0 | FX28: 94 | FY28: 61 | GD28: 1 | GF28: 247349083 | GG28: 2 | GH28: 1 | GI28: 2 | GJ28: 0 | GK28: 0 | GL28: =ROUND(IF(AND(BH28=3,BI28=3,FS28<>0),P28,0),2) -> 0 | GM28: =ROUND(O28+X28+Y28,2)+GX28 -> 2374.39 | GN28: =IF(OR(BI28=0,BI28=1),GM28-GX28,0) -> 0 | GO28: =IF(BI28=2,GM28-GX28,0) -> 0 | GP28: =IF(BI28=4,GM28-GX28,0) -> 2374.39 | GR28: 0 | GS28: 3 | GT28: 0 | GV28: =ROUND((GT28),6) -> 0 | GW28: 1 | GX28: =ROUND(HC28*I28,2) -> 0 | HA28: 0 | HB28: 0 | HC28: =GV28*GW28 -> 0 | HS28: 0 | IK28: 0
A29: 17 | B29: 1 | C29: =ROW(SmtRes!A2) -> 2 | D29: =ROW(EtalonRes!A2) -> 2 | E29: 1 | F29: 15.1-1500-01 | G29: Отходы (мусор) от строительных и ремонтных работ малоопасные | H29: 1 Т | I29: 74.973 | J29: 0 | K29: 74.973 | O29: =ROUND(CP29,2) -> 102977.29 | P29: =ROUND((ROUND((AC29*AW29*I29),2)*BC29),2) -> 0 | Q29: =(ROUND((ROUND(((ET29)*AV29*I29),2)*BB29),2)+ROUND((ROUND(((AE29-(EU29))*AV29*I29),2)*BS29),2)) -> 102977.29 | R29: =ROUND((ROUND((AE29*AV29*I29),2)*BS29),2) -> 0 | S29: =ROUND((ROUND((AF29*AV29*I29),2)*BA29),2) -> 0 | T29: =ROUND(CU29*I29,2) -> 0 | U29: =CV29*I29 -> 0 | V29: =CW29*I29 -> 0 | W29: =ROUND(CX29*I29,2) -> 0 | X29: =ROUND(CY29,2) -> 0 | Y29: =ROUND(CZ29,2) -> 0 | AA29: 56526441 | AB29: =ROUND((AC29+AD29+AF29),6) -> 31.67 | AC29: =ROUND((ES29),6) -> 0 | AD29: =ROUND((((ET29)-(EU29))+AE29),6) -> 31.67 | AE29: =ROUND((EU29),6) -> 0 | AF29: =ROUND((EV29),6) -> 0 | AG29: =ROUND((AP29),6) -> 0 | AH29: =(EW29) -> 0 | AI29: =(EX29) -> 0 | AJ29: =(AS29) -> 0 | AK29: 31.67 | AL29: 0 | AM29: 31.67 | AN29: 0 | AO29: 0 | AP29: 0 | AQ29: 0 | AR29: 0 | AS29: 0 | AT29: 94 | AU29: 61 | AV29: 1 | AW29: 1 | AZ29: 1 | BA29: 1 | BB29: 43.37 | BC29: 1 | BH29: 0 | BI29: 4 | BJ29: ТСН-2001.15 Доп. 56, Сб. 1, т. 1500, поз. 1 | BM29: 188 | BN29: 0 | BO29: 15.1-1500-01 | BP29: 1 | BQ29: 150 | BR29: 0 | BS29: 1 | BT29: 1 | BU29: 1 | BV29: 1 | BW29: 1 | BX29: 1 | BZ29: 94 | CA29: 61 | CE29: 30 | CF29: 0 | CG29: 0 | CM29: 0 | CO29: 0 | CP29: =(P29+Q29+S29) -> 102977.29 | CQ29: =ROUND((ROUND((AC29*AW29*1),2)*BC29),2) -> 0 | CR29: =(ROUND((ROUND(((ET29)*AV29*1),2)*BB29),2)+ROUND((ROUND(((AE29-(EU29))*AV29*1),2)*BS29),2)) -> 1373.53 | CS29: =ROUND((ROUND((AE29*AV29*1),2)*BS29),2) -> 0 | CT29: =ROUND((ROUND((AF29*AV29*1),2)*BA29),2) -> 0 | CU29: =AG29 -> 0 | CV29: =(AH29*AV29) -> 0 | CW29: =AI29 -> 0 | CX29: =AJ29 -> 0 | CY29: =(((S29+R29)*AT29)/100) -> 0 | CZ29: =(((S29+R29)*AU29)/100) -> 0 | DN29: 0 | DO29: 0 | DP29: 1 | DQ29: 1 | DU29: 1013 | DV29: 1 Т | DW29: 1 Т | DX29: 1 | EE29: 55586412 | EF29: 150 | EG29: Транспортные затраты | EH29: 0 | EJ29: 4 | EK29: 188 | EL29: ТСН-2001.15. Перевозка строительных грузов автомобильным транспортом | EM29: ТСН-2001.15. | EQ29: 0 | ER29: 31.67 | ES29: 0 | ET29: 31.67 | EU29: 0 | EV29: 0 | EW29: 0 | EX29: 0 | EY29: 0 | FQ29: 0 | FR29: 0 | FS29: 0 | FX29: 94 | FY29: 61 | GD29: 1 | GF29: 247349083 | GG29: 2 | GH29: 1 | GI29: 2 | GJ29: 0 | GK29: 0 | GL29: =ROUND(IF(AND(BH29=3,BI29=3,FS29<>0),P29,0),2) -> 0 | GM29: =ROUND(O29+X29+Y29,2)+GX29 -> 102977.29 | GN29: =IF(OR(BI29=0,BI29=1),GM29-GX29,0) -> 0 | GO29: =IF(BI29=2,GM29-GX29,0) -> 0 | GP29: =IF(BI29=4,GM29-GX29,0) -> 102977.29 | GR29: 0 | GS29: 3 | GT29: 0 | GV29: =ROUND((GT29),6) -> 0 | GW29: 1 | GX29: =ROUND(HC29*I29,2) -> 0 | HA29: 0 | HB29: 0 | HC29: =GV29*GW29 -> 0 | HS29: 0 | IK29: 0
A30: 17 | B30: 1 | C30: =ROW(SmtRes!A3) -> 3 | D30: =ROW(EtalonRes!A3) -> 3 | E30: 2 | F30: 15.1-1201-10 | G30: Отходы затвердевшего строительного раствора в кусковой форме, малоопасные | H30: 1 Т | I30: 1545.61 | J30: 0 | K30: 1545.61 | O30: =ROUND(CP30,2) -> 48114.84 | P30: =ROUND((ROUND((AC30*AW30*I30),2)*BC30),2) -> 0 | Q30: =(ROUND((ROUND(((ET30)*AV30*I30),2)*BB30),2)+ROUND((ROUND(((AE30-(EU30))*AV30*I30),2)*BS30),2)) -> 48114.84 | R30: =ROUND((ROUND((AE30*AV30*I30),2)*BS30),2) -> 0 | S30: =ROUND((ROUND((AF30*AV30*I30),2)*BA30),2) -> 0 | T30: =ROUND(CU30*I30,2) -> 0 | U30: =CV30*I30 -> 0 | V30: =CW30*I30 -> 0 | W30: =ROUND(CX30*I30,2) -> 0 | X30: =ROUND(CY30,2) -> 0 | Y30: =ROUND(CZ30,2) -> 0 | AA30: 56526439 | AB30: =ROUND((AC30+AD30+AF30),6) -> 31.13 | AC30: =ROUND((ES30),6) -> 0 | AD30: =ROUND((((ET30)-(EU30))+AE30),6) -> 31.13 | AE30: =ROUND((EU30),6) -> 0 | AF30: =ROUND((EV30),6) -> 0 | AG30: =ROUND((AP30),6) -> 0 | AH30: =(EW30) -> 0 | AI30: =(EX30) -> 0 | AJ30: =(AS30) -> 0 | AK30: 31.13 | AL30: 0 | AM30: 31.13 | AN30: 0 | AO30: 0 | AP30: 0 | AQ30: 0 | AR30: 0 | AS30: 0 | AT30: 94 | AU30: 61 | AV30: 1 | AW30: 1 | AZ30: 1 | BA30: 1 | BB30: 1 | BC30: 1 | BH30: 0 | BI30: 4 | BJ30: ТСН-2001.15 Доп. 56, Сб. 1, т. 1201, поз. 10 | BM30: 188 | BN30: 0 | BO30: 15.1-1201-10 | BP30: 1 | BQ30: 150 | BR30: 0 | BS30: 1 | BT30: 1 | BU30: 1 | BV30: 1 | BW30: 1 | BX30: 1 | BZ30: 94 | CA30: 61 | CE30: 30 | CF30: 0 | CG30: 0 | CM30: 0 | CO30: 0 | CP30: =(P30+Q30+S30) -> 48114.84 | CQ30: =ROUND((ROUND((AC30*AW30*1),2)*BC30),2) -> 0 | CR30: =(ROUND((ROUND(((ET30)*AV30*1),2)*BB30),2)+ROUND((ROUND(((AE30-(EU30))*AV30*1),2)*BS30),2)) -> 31.13 | CS30: =ROUND((ROUND((AE30*AV30*1),2)*BS30),2) -> 0 | CT30: =ROUND((ROUND((AF30*AV30*1),2)*BA30),2) -> 0 | CU30: =AG30 -> 0 | CV30: =(AH30*AV30) -> 0 | CW30: =AI30 -> 0 | CX30: =AJ30 -> 0 | CY30: =(((S30+R30)*AT30)/100) -> 0 | CZ30: =(((S30+R30)*AU30)/100) -> 0 | DN30: 0 | DO30: 0 | DP30: 1 | DQ30: 1 | DU30: 1013 | DV30: 1 Т | DW30: 1 Т | DX30: 1 | EE30: 55586412 | EF30: 150 | EG30: Транспортные затраты | EH30: 0 | EJ30: 4 | EK30: 188 | EL30: ТСН-2001.15. Перевозка строительных грузов автомобильным транспортом | EM30: ТСН-2001.15. | EQ30: 0 | ER30: 31.13 | ES30: 0 | ET30: 31.13 | EU30: 0 | EV30: 0 | EW30: 0 | EX30: 0 | EY30: 0 | FQ30: 0 | FR30: 0 | FS30: 0 | FX30: 94 | FY30: 61 | GD30: 1 | GF30: 1826450107 | GG30: 2 | GH30: 1 | GI30: 2 | GJ30: 0 | GK30: 0 | GL30: =ROUND(IF(AND(BH30=3,BI30=3,FS30<>0),P30,0),2) -> 0 | GM30: =ROUND(O30+X30+Y30,2)+GX30 -> 48114.84 | GN30: =IF(OR(BI30=0,BI30=1),GM30-GX30,0) -> 0 | GO30: =IF(BI30=2,GM30-GX30,0) -> 0 | GP30: =IF(BI30=4,GM30-GX30,0) -> 48114.84 | GR30: 0 | GS30: 3 | GT30: 0 | GV30: =ROUND((GT30),6) -> 0 | GW30: 1 | GX30: =ROUND(HC30*I30,2) -> 0 | HA30: 0 | HB30: 0 | HC30: =GV30*GW30 -> 0 | HS30: 0 | IK30: 0
A31: 17 | B31: 1 | C31: =ROW(SmtRes!A4) -> 4 | D31: =ROW(EtalonRes!A4) -> 4 | E31: 2 | F31: 15.1-1201-10 | G31: Отходы затвердевшего строительного раствора в кусковой форме, малоопасные | H31: 1 Т | I31: 1545.61 | J31: 0 | K31: 1545.61 | O31: =ROUND(CP31,2) -> 448911.46 | P31: =ROUND((ROUND((AC31*AW31*I31),2)*BC31),2) -> 0 | Q31: =(ROUND((ROUND(((ET31)*AV31*I31),2)*BB31),2)+ROUND((ROUND(((AE31-(EU31))*AV31*I31),2)*BS31),2)) -> 448911.46 | R31: =ROUND((ROUND((AE31*AV31*I31),2)*BS31),2) -> 0 | S31: =ROUND((ROUND((AF31*AV31*I31),2)*BA31),2) -> 0 | T31: =ROUND(CU31*I31,2) -> 0 | U31: =CV31*I31 -> 0 | V31: =CW31*I31 -> 0 | W31: =ROUND(CX31*I31,2) -> 0 | X31: =ROUND(CY31,2) -> 0 | Y31: =ROUND(CZ31,2) -> 0 | AA31: 56526441 | AB31: =ROUND((AC31+AD31+AF31),6) -> 31.13 | AC31: =ROUND((ES31),6) -> 0 | AD31: =ROUND((((ET31)-(EU31))+AE31),6) -> 31.13 | AE31: =ROUND((EU31),6) -> 0 | AF31: =ROUND((EV31),6) -> 0 | AG31: =ROUND((AP31),6) -> 0 | AH31: =(EW31) -> 0 | AI31: =(EX31) -> 0 | AJ31: =(AS31) -> 0 | AK31: 31.13 | AL31: 0 | AM31: 31.13 | AN31: 0 | AO31: 0 | AP31: 0 | AQ31: 0 | AR31: 0 | AS31: 0 | AT31: 94 | AU31: 61 | AV31: 1 | AW31: 1 | AZ31: 1 | BA31: 1 | BB31: 9.33 | BC31: 1 | BH31: 0 | BI31: 4 | BJ31: ТСН-2001.15 Доп. 56, Сб. 1, т. 1201, поз. 10 | BM31: 188 | BN31: 0 | BO31: 15.1-1201-10 | BP31: 1 | BQ31: 150 | BR31: 0 | BS31: 1 | BT31: 1 | BU31: 1 | BV31: 1 | BW31: 1 | BX31: 1 | BZ31: 94 | CA31: 61 | CE31: 30 | CF31: 0 | CG31: 0 | CM31: 0 | CO31: 0 | CP31: =(P31+Q31+S31) -> 448911.46 | CQ31: =ROUND((ROUND((AC31*AW31*1),2)*BC31),2) -> 0 | CR31: =(ROUND((ROUND(((ET31)*AV31*1),2)*BB31),2)+ROUND((ROUND(((AE31-(EU31))*AV31*1),2)*BS31),2)) -> 290.44 | CS31: =ROUND((ROUND((AE31*AV31*1),2)*BS31),2) -> 0 | CT31: =ROUND((ROUND((AF31*AV31*1),2)*BA31),2) -> 0 | CU31: =AG31 -> 0 | CV31: =(AH31*AV31) -> 0 | CW31: =AI31 -> 0 | CX31: =AJ31 -> 0 | CY31: =(((S31+R31)*AT31)/100) -> 0 | CZ31: =(((S31+R31)*AU31)/100) -> 0 | DN31: 0 | DO31: 0 | DP31: 1 | DQ31: 1 | DU31: 1013 | DV31: 1 Т | DW31: 1 Т | DX31: 1 | EE31: 55586412 | EF31: 150 | EG31: Транспортные затраты | EH31: 0 | EJ31: 4 | EK31: 188 | EL31: ТСН-2001.15. Перевозка строительных грузов автомобильным транспортом | EM31: ТСН-2001.15. | EQ31: 0 | ER31: 31.13 | ES31: 0 | ET31: 31.13 | EU31: 0 | EV31: 0 | EW31: 0 | EX31: 0 | EY31: 0 | FQ31: 0 | FR31: 0 | FS31: 0 | FX31: 94 | FY31: 61 | GD31: 1 | GF31: 1826450107 | GG31: 2 | GH31: 1 | GI31: 2 | GJ31: 0 | GK31: 0 | GL31: =ROUND(IF(AND(BH31=3,BI31=3,FS31<>0),P31,0),2) -> 0 | GM31: =ROUND(O31+X31+Y31,2)+GX31 -> 448911.46 | GN31: =IF(OR(BI31=0,BI31=1),GM31-GX31,0) -> 0 | GO31: =IF(BI31=2,GM31-GX31,0) -> 0 | GP31: =IF(BI31=4,GM31-GX31,0) -> 448911.46 | GR31: 0 | GS31: 3 | GT31: 0 | GV31: =ROUND((GT31),6) -> 0 | GW31: 1 | GX31: =ROUND(HC31*I31,2) -> 0 | HA31: 0 | HB31: 0 | HC31: =GV31*GW31 -> 0 | HS31: 0 | IK31: 0
A32: 17 | B32: 1 | C32: =ROW(SmtRes!A5) -> 5 | D32: =ROW(EtalonRes!A5) -> 5 | E32: 3 | F32: 15.1-1203-06 | G32: Отходы штукатурки затвердевшей малоопасные | H32: 1 Т | I32: 195.77 | J32: 0 | K32: 195.77 | O32: =ROUND(CP32,2) -> 7163.22 | P32: =ROUND((ROUND((AC32*AW32*I32),2)*BC32),2) -> 0 | Q32: =(ROUND((ROUND(((ET32)*AV32*I32),2)*BB32),2)+ROUND((ROUND(((AE32-(EU32))*AV32*I32),2)*BS32),2)) -> 7163.22 | R32: =ROUND((ROUND((AE32*AV32*I32),2)*BS32),2) -> 0 | S32: =ROUND((ROUND((AF32*AV32*I32),2)*BA32),2) -> 0 | T32: =ROUND(CU32*I32,2) -> 0 | U32: =CV32*I32 -> 0 | V32: =CW32*I32 -> 0 | W32: =ROUND(CX32*I32,2) -> 0 | X32: =ROUND(CY32,2) -> 0 | Y32: =ROUND(CZ32,2) -> 0 | AA32: 56526439 | AB32: =ROUND((AC32+AD32+AF32),6) -> 36.59 | AC32: =ROUND((ES32),6) -> 0 | AD32: =ROUND((((ET32)-(EU32))+AE32),6) -> 36.59 | AE32: =ROUND((EU32),6) -> 0 | AF32: =ROUND((EV32),6) -> 0 | AG32: =ROUND((AP32),6) -> 0 | AH32: =(EW32) -> 0 | AI32: =(EX32) -> 0 | AJ32: =(AS32) -> 0 | AK32: 36.59 | AL32: 0 | AM32: 36.59 | AN32: 0 | AO32: 0 | AP32: 0 | AQ32: 0 | AR32: 0 | AS32: 0 | AT32: 94 | AU32: 61 | AV32: 1 | AW32: 1 | AZ32: 1 | BA32: 1 | BB32: 1 | BC32: 1 | BH32: 0 | BI32: 4 | BJ32: ТСН-2001.15 Доп. 56, Сб. 1, т. 1203, поз. 6 | BM32: 188 | BN32: 0 | BO32: 15.1-1203-06 | BP32: 1 | BQ32: 150 | BR32: 0 | BS32: 1 | BT32: 1 | BU32: 1 | BV32: 1 | BW32: 1 | BX32: 1 | BZ32: 94 | CA32: 61 | CE32: 30 | CF32: 0 | CG32: 0 | CM32: 0 | CO32: 0 | CP32: =(P32+Q32+S32) -> 7163.22 | CQ32: =ROUND((ROUND((AC32*AW32*1),2)*BC32),2) -> 0 | CR32: =(ROUND((ROUND(((ET32)*AV32*1),2)*BB32),2)+ROUND((ROUND(((AE32-(EU32))*AV32*1),2)*BS32),2)) -> 36.59 | CS32: =ROUND((ROUND((AE32*AV32*1),2)*BS32),2) -> 0 | CT32: =ROUND((ROUND((AF32*AV32*1),2)*BA32),2) -> 0 | CU32: =AG32 -> 0 | CV32: =(AH32*AV32) -> 0 | CW32: =AI32 -> 0 | CX32: =AJ32 -> 0 | CY32: =(((S32+R32)*AT32)/100) -> 0 | CZ32: =(((S32+R32)*AU32)/100) -> 0 | DN32: 0 | DO32: 0 | DP32: 1 | DQ32: 1 | DU32: 1013 | DV32: 1 Т | DW32: 1 Т | DX32: 1 | EE32: 55586412 | EF32: 150 | EG32: Транспортные затраты | EH32: 0 | EJ32: 4 | EK32: 188 | EL32: ТСН-2001.15. Перевозка строительных грузов автомобильным транспортом | EM32: ТСН-2001.15. | EQ32: 0 | ER32: 36.59 | ES32: 0 | ET32: 36.59 | EU32: 0 | EV32: 0 | EW32: 0 | EX32: 0 | EY32: 0 | FQ32: 0 | FR32: 0 | FS32: 0 | FX32: 94 | FY32: 61 | GD32: 1 | GF32: -1232021766 | GG32: 2 | GH32: 1 | GI32: 2 | GJ32: 0 | GK32: 0 | GL32: =ROUND(IF(AND(BH32=3,BI32=3,FS32<>0),P32,0),2) -> 0 | GM32: =ROUND(O32+X32+Y32,2)+GX32 -> 7163.22 | GN32: =IF(OR(BI32=0,BI32=1),GM32-GX32,0) -> 0 | GO32: =IF(BI32=2,GM32-GX32,0) -> 0 | GP32: =IF(BI32=4,GM32-GX32,0) -> 7163.22 | GR32: 0 | GS32: 3 | GT32: 0 | GV32: =ROUND((GT32),6) -> 0 | GW32: 1 | GX32: =ROUND(HC32*I32,2) -> 0 | HA32: 0 | HB32: 0 | HC32: =GV32*GW32 -> 0 | HS32: 0 | IK32: 0
A33: 17 | B33: 1 | C33: =ROW(SmtRes!A6) -> 6 | D33: =ROW(EtalonRes!A6) -> 6 | E33: 3 | F33: 15.1-1203-06 | G33: Отходы штукатурки затвердевшей малоопасные | H33: 1 Т | I33: 195.77 | J33: 0 | K33: 195.77 | O33: =ROUND(CP33,2) -> 68552.02 | P33: =ROUND((ROUND((AC33*AW33*I33),2)*BC33),2) -> 0 | Q33: =(ROUND((ROUND(((ET33)*AV33*I33),2)*BB33),2)+ROUND((ROUND(((AE33-(EU33))*AV33*I33),2)*BS33),2)) -> 68552.02 | R33: =ROUND((ROUND((AE33*AV33*I33),2)*BS33),2) -> 0 | S33: =ROUND((ROUND((AF33*AV33*I33),2)*BA33),2) -> 0 | T33: =ROUND(CU33*I33,2) -> 0 | U33: =CV33*I33 -> 0 | V33: =CW33*I33 -> 0 | W33: =ROUND(CX33*I33,2) -> 0 | X33: =ROUND(CY33,2) -> 0 | Y33: =ROUND(CZ33,2) -> 0 | AA33: 56526441 | AB33: =ROUND((AC33+AD33+AF33),6) -> 36.59 | AC33: =ROUND((ES33),6) -> 0 | AD33: =ROUND((((ET33)-(EU33))+AE33),6) -> 36.59 | AE33: =ROUND((EU33),6) -> 0 | AF33: =ROUND((EV33),6) -> 0 | AG33: =ROUND((AP33),6) -> 0 | AH33: =(EW33) -> 0 | AI33: =(EX33) -> 0 | AJ33: =(AS33) -> 0 | AK33: 36.59 | AL33: 0 | AM33: 36.59 | AN33: 0 | AO33: 0 | AP33: 0 | AQ33: 0 | AR33: 0 | AS33: 0 | AT33: 94 | AU33: 61 | AV33: 1 | AW33: 1 | AZ33: 1 | BA33: 1 | BB33: 9.57 | BC33: 1 | BH33: 0 | BI33: 4 | BJ33: ТСН-2001.15 Доп. 56, Сб. 1, т. 1203, поз. 6 | BM33: 188 | BN33: 0 | BO33: 15.1-1203-06 | BP33: 1 | BQ33: 150 | BR33: 0 | BS33: 1 | BT33: 1 | BU33: 1 | BV33: 1 | BW33: 1 | BX33: 1 | BZ33: 94 | CA33: 61 | CE33: 30 | CF33: 0 | CG33: 0 | CM33: 0 | CO33: 0 | CP33: =(P33+Q33+S33) -> 68552.02 | CQ33: =ROUND((ROUND((AC33*AW33*1),2)*BC33),2) -> 0 | CR33: =(ROUND((ROUND(((ET33)*AV33*1),2)*BB33),2)+ROUND((ROUND(((AE33-(EU33))*AV33*1),2)*BS33),2)) -> 350.17 | CS33: =ROUND((ROUND((AE33*AV33*1),2)*BS33),2) -> 0 | CT33: =ROUND((ROUND((AF33*AV33*1),2)*BA33),2) -> 0 | CU33: =AG33 -> 0 | CV33: =(AH33*AV33) -> 0 | CW33: =AI33 -> 0 | CX33: =AJ33 -> 0 | CY33: =(((S33+R33)*AT33)/100) -> 0 | CZ33: =(((S33+R33)*AU33)/100) -> 0 | DN33: 0 | DO33: 0 | DP33: 1 | DQ33: 1 | DU33: 1013 | DV33: 1 Т | DW33: 1 Т | DX33: 1 | EE33: 55586412 | EF33: 150 | EG33: Транспортные затраты | EH33: 0 | EJ33: 4 | EK33: 188 | EL33: ТСН-2001.15. Перевозка строительных грузов автомобильным транспортом | EM33: ТСН-2001.15. | EQ33: 0 | ER33: 36.59 | ES33: 0 | ET33: 36.59 | EU33: 0 | EV33: 0 | EW33: 0 | EX33: 0 | EY33: 0 | FQ33: 0 | FR33: 0 | FS33: 0 | FX33: 94 | FY33: 61 | GD33: 1 | GF33: -1232021766 | GG33: 2 | GH33: 1 | GI33: 2 | GJ33: 0 | GK33: 0 | GL33: =ROUND(IF(AND(BH33=3,BI33=3,FS33<>0),P33,0),2) -> 0 | GM33: =ROUND(O33+X33+Y33,2)+GX33 -> 68552.02 | GN33: =IF(OR(BI33=0,BI33=1),GM33-GX33,0) -> 0 | GO33: =IF(BI33=2,GM33-GX33,0) -> 0 | GP33: =IF(BI33=4,GM33-GX33,0) -> 68552.02 | GR33: 0 | GS33: 3 | GT33: 0 | GV33: =ROUND((GT33),6) -> 0 | GW33: 1 | GX33: =ROUND(HC33*I33,2) -> 0 | HA33: 0 | HB33: 0 | HC33: =GV33*GW33 -> 0 | HS33: 0 | IK33: 0
A34: 17 | B34: 1 | C34: =ROW(SmtRes!A7) -> 7 | D34: =ROW(EtalonRes!A7) -> 7 | E34: 4 | F34: 15.1-1505-04 | G34: Отходы прочих теплоизоляционных материалов на основе минерального волокна незагрязненные, практически неопасные | H34: 1 Т | I34: 4.248 | J34: 0 | K34: 4.248 | O34: =ROUND(CP34,2) -> 417.58 | P34: =ROUND((ROUND((AC34*AW34*I34),2)*BC34),2) -> 0 | Q34: =(ROUND((ROUND(((ET34)*AV34*I34),2)*BB34),2)+ROUND((ROUND(((AE34-(EU34))*AV34*I34),2)*BS34),2)) -> 417.58 | R34: =ROUND((ROUND((AE34*AV34*I34),2)*BS34),2) -> 0 | S34: =ROUND((ROUND((AF34*AV34*I34),2)*BA34),2) -> 0 | T34: =ROUND(CU34*I34,2) -> 0 | U34: =CV34*I34 -> 0 | V34: =CW34*I34 -> 0 | W34: =ROUND(CX34*I34,2) -> 0 | X34: =ROUND(CY34,2) -> 0 | Y34: =ROUND(CZ34,2) -> 0 | AA34: 56526439 | AB34: =ROUND((AC34+AD34+AF34),6) -> 98.3 | AC34: =ROUND((ES34),6) -> 0 | AD34: =ROUND((((ET34)-(EU34))+AE34),6) -> 98.3 | AE34: =ROUND((EU34),6) -> 0 | AF34: =ROUND((EV34),6) -> 0 | AG34: =ROUND((AP34),6) -> 0 | AH34: =(EW34) -> 0 | AI34: =(EX34) -> 0 | AJ34: =(AS34) -> 0 | AK34: 98.3 | AL34: 0 | AM34: 98.3 | AN34: 0 | AO34: 0 | AP34: 0 | AQ34: 0 | AR34: 0 | AS34: 0 | AT34: 94 | AU34: 61 | AV34: 1 | AW34: 1 | AZ34: 1 | BA34: 1 | BB34: 1 | BC34: 1 | BH34: 0 | BI34: 4 | BJ34: ТСН-2001.15 Доп. 56, Сб. 1, т. 1505, поз. 4 | BM34: 188 | BN34: 0 | BO34: 15.1-1505-04 | BP34: 1 | BQ34: 150 | BR34: 0 | BS34: 1 | BT34: 1 | BU34: 1 | BV34: 1 | BW34: 1 | BX34: 1 | BZ34: 94 | CA34: 61 | CE34: 30 | CF34: 0 | CG34: 0 | CM34: 0 | CO34: 0 | CP34: =(P34+Q34+S34) -> 417.58 | CQ34: =ROUND((ROUND((AC34*AW34*1),2)*BC34),2) -> 0 | CR34: =(ROUND((ROUND(((ET34)*AV34*1),2)*BB34),2)+ROUND((ROUND(((AE34-(EU34))*AV34*1),2)*BS34),2)) -> 98.3 | CS34: =ROUND((ROUND((AE34*AV34*1),2)*BS34),2) -> 0 | CT34: =ROUND((ROUND((AF34*AV34*1),2)*BA34),2) -> 0 | CU34: =AG34 -> 0 | CV34: =(AH34*AV34) -> 0 | CW34: =AI34 -> 0 | CX34: =AJ34 -> 0 | CY34: =(((S34+R34)*AT34)/100) -> 0 | CZ34: =(((S34+R34)*AU34)/100) -> 0 | DN34: 0 | DO34: 0 | DP34: 1 | DQ34: 1 | DU34: 1013 | DV34: 1 Т | DW34: 1 Т | DX34: 1 | EE34: 55586412 | EF34: 150 | EG34: Транспортные затраты | EH34: 0 | EJ34: 4 | EK34: 188 | EL34: ТСН-2001.15. Перевозка строительных грузов автомобильным транспортом | EM34: ТСН-2001.15. | EQ34: 0 | ER34: 98.3 | ES34: 0 | ET34: 98.3 | EU34: 0 | EV34: 0 | EW34: 0 | EX34: 0 | EY34: 0 | FQ34: 0 | FR34: 0 | FS34: 0 | FX34: 94 | FY34: 61 | GD34: 1 | GF34: 151177787 | GG34: 2 | GH34: 1 | GI34: 2 | GJ34: 0 | GK34: 0 | GL34: =ROUND(IF(AND(BH34=3,BI34=3,FS34<>0),P34,0),2) -> 0 | GM34: =ROUND(O34+X34+Y34,2)+GX34 -> 417.58 | GN34: =IF(OR(BI34=0,BI34=1),GM34-GX34,0) -> 0 | GO34: =IF(BI34=2,GM34-GX34,0) -> 0 | GP34: =IF(BI34=4,GM34-GX34,0) -> 417.58 | GR34: 0 | GS34: 3 | GT34: 0 | GV34: =ROUND((GT34),6) -> 0 | GW34: 1 | GX34: =ROUND(HC34*I34,2) -> 0 | HA34: 0 | HB34: 0 | HC34: =GV34*GW34 -> 0 | HS34: 0 | IK34: 0
A35: 17 | B35: 1 | C35: =ROW(SmtRes!A8) -> 8 | D35: =ROW(EtalonRes!A8) -> 8 | E35: 4 | F35: 15.1-1505-04 | G35: Отходы прочих теплоизоляционных материалов на основе минерального волокна незагрязненные, практически неопасные | H35: 1 Т | I35: 4.248 | J35: 0 | K35: 4.248 | O35: =ROUND(CP35,2) -> 4601.73 | P35: =ROUND((ROUND((AC35*AW35*I35),2)*BC35),2) -> 0 | Q35: =(ROUND((ROUND(((ET35)*AV35*I35),2)*BB35),2)+ROUND((ROUND(((AE35-(EU35))*AV35*I35),2)*BS35),2)) -> 4601.73 | R35: =ROUND((ROUND((AE35*AV35*I35),2)*BS35),2) -> 0 | S35: =ROUND((ROUND((AF35*AV35*I35),2)*BA35),2) -> 0 | T35: =ROUND(CU35*I35,2) -> 0 | U35: =CV35*I35 -> 0 | V35: =CW35*I35 -> 0 | W35: =ROUND(CX35*I35,2) -> 0 | X35: =ROUND(CY35,2) -> 0 | Y35: =ROUND(CZ35,2) -> 0 | AA35: 56526441 | AB35: =ROUND((AC35+AD35+AF35),6) -> 98.3 | AC35: =ROUND((ES35),6) -> 0 | AD35: =ROUND((((ET35)-(EU35))+AE35),6) -> 98.3 | AE35: =ROUND((EU35),6) -> 0 | AF35: =ROUND((EV35),6) -> 0 | AG35: =ROUND((AP35),6) -> 0 | AH35: =(EW35) -> 0 | AI35: =(EX35) -> 0 | AJ35: =(AS35) -> 0 | AK35: 98.3 | AL35: 0 | AM35: 98.3 | AN35: 0 | AO35: 0 | AP35: 0 | AQ35: 0 | AR35: 0 | AS35: 0 | AT35: 94 | AU35: 61 | AV35: 1 | AW35: 1 | AZ35: 1 | BA35: 1 | BB35: 11.02 | BC35: 1 | BH35: 0 | BI35: 4 | BJ35: ТСН-2001.15 Доп. 56, Сб. 1, т. 1505, поз. 4 | BM35: 188 | BN35: 0 | BO35: 15.1-1505-04 | BP35: 1 | BQ35: 150 | BR35: 0 | BS35: 1 | BT35: 1 | BU35: 1 | BV35: 1 | BW35: 1 | BX35: 1 | BZ35: 94 | CA35: 61 | CE35: 30 | CF35: 0 | CG35: 0 | CM35: 0 | CO35: 0 | CP35: =(P35+Q35+S35) -> 4601.73 | CQ35: =ROUND((ROUND((AC35*AW35*1),2)*BC35),2) -> 0 | CR35: =(ROUND((ROUND(((ET35)*AV35*1),2)*BB35),2)+ROUND((ROUND(((AE35-(EU35))*AV35*1),2)*BS35),2)) -> 1083.27 | CS35: =ROUND((ROUND((AE35*AV35*1),2)*BS35),2) -> 0 | CT35: =ROUND((ROUND((AF35*AV35*1),2)*BA35),2) -> 0 | CU35: =AG35 -> 0 | CV35: =(AH35*AV35) -> 0 | CW35: =AI35 -> 0 | CX35: =AJ35 -> 0 | CY35: =(((S35+R35)*AT35)/100) -> 0 | CZ35: =(((S35+R35)*AU35)/100) -> 0 | DN35: 0 | DO35: 0 | DP35: 1 | DQ35: 1 | DU35: 1013 | DV35: 1 Т | DW35: 1 Т | DX35: 1 | EE35: 55586412 | EF35: 150 | EG35: Транспортные затраты | EH35: 0 | EJ35: 4 | EK35: 188 | EL35: ТСН-2001.15. Перевозка строительных грузов автомобильным транспортом | EM35: ТСН-2001.15. | EQ35: 0 | ER35: 98.3 | ES35: 0 | ET35: 98.3 | EU35: 0 | EV35: 0 | EW35: 0 | EX35: 0 | EY35: 0 | FQ35: 0 | FR35: 0 | FS35: 0 | FX35: 94 | FY35: 61 | GD35: 1 | GF35: 151177787 | GG35: 2 | GH35: 1 | GI35: 2 | GJ35: 0 | GK35: 0 | GL35: =ROUND(IF(AND(BH35=3,BI35=3,FS35<>0),P35,0),2) -> 0 | GM35: =ROUND(O35+X35+Y35,2)+GX35 -> 4601.73 | GN35: =IF(OR(BI35=0,BI35=1),GM35-GX35,0) -> 0 | GO35: =IF(BI35=2,GM35-GX35,0) -> 0 | GP35: =IF(BI35=4,GM35-GX35,0) -> 4601.73 | GR35: 0 | GS35: 3 | GT35: 0 | GV35: =ROUND((GT35),6) -> 0 | GW35: 1 | GX35: =ROUND(HC35*I35,2) -> 0 | HA35: 0 | HB35: 0 | HC35: =GV35*GW35 -> 0 | HS35: 0 | IK35: 0
A36: 17 | B36: 1 | C36: =ROW(SmtRes!A9) -> 9 | D36: =ROW(EtalonRes!A9) -> 9 | E36: 5 | F36: 15.1-1203-02 | G36: Обрезь и лом гипсокартонных листов малоопасные | H36: 1 Т | I36: 0.035 | J36: 0 | K36: 0.035 | O36: =ROUND(CP36,2) -> 1.36 | P36: =ROUND((ROUND((AC36*AW36*I36),2)*BC36),2) -> 0 | Q36: =(ROUND((ROUND(((ET36)*AV36*I36),2)*BB36),2)+ROUND((ROUND(((AE36-(EU36))*AV36*I36),2)*BS36),2)) -> 1.36 | R36: =ROUND((ROUND((AE36*AV36*I36),2)*BS36),2) -> 0 | S36: =ROUND((ROUND((AF36*AV36*I36),2)*BA36),2) -> 0 | T36: =ROUND(CU36*I36,2) -> 0 | U36: =CV36*I36 -> 0 | V36: =CW36*I36 -> 0 | W36: =ROUND(CX36*I36,2) -> 0 | X36: =ROUND(CY36,2) -> 0 | Y36: =ROUND(CZ36,2) -> 0 | AA36: 56526439 | AB36: =ROUND((AC36+AD36+AF36),6) -> 38.77 | AC36: =ROUND((ES36),6) -> 0 | AD36: =ROUND((((ET36)-(EU36))+AE36),6) -> 38.77 | AE36: =ROUND((EU36),6) -> 0 | AF36: =ROUND((EV36),6) -> 0 | AG36: =ROUND((AP36),6) -> 0 | AH36: =(EW36) -> 0 | AI36: =(EX36) -> 0 | AJ36: =(AS36) -> 0 | AK36: 38.77 | AL36: 0 | AM36: 38.77 | AN36: 0 | AO36: 0 | AP36: 0 | AQ36: 0 | AR36: 0 | AS36: 0 | AT36: 94 | AU36: 61 | AV36: 1 | AW36: 1 | AZ36: 1 | BA36: 1 | BB36: 1 | BC36: 1 | BH36: 0 | BI36: 4 | BJ36: ТСН-2001.15 Доп. 56, Сб. 1, т. 1203, поз. 2 | BM36: 188 | BN36: 0 | BO36: 15.1-1203-02 | BP36: 1 | BQ36: 150 | BR36: 0 | BS36: 1 | BT36: 1 | BU36: 1 | BV36: 1 | BW36: 1 | BX36: 1 | BZ36: 94 | CA36: 61 | CE36: 30 | CF36: 0 | CG36: 0 | CM36: 0 | CO36: 0 | CP36: =(P36+Q36+S36) -> 1.36 | CQ36: =ROUND((ROUND((AC36*AW36*1),2)*BC36),2) -> 0 | CR36: =(ROUND((ROUND(((ET36)*AV36*1),2)*BB36),2)+ROUND((ROUND(((AE36-(EU36))*AV36*1),2)*BS36),2)) -> 38.77 | CS36: =ROUND((ROUND((AE36*AV36*1),2)*BS36),2) -> 0 | CT36: =ROUND((ROUND((AF36*AV36*1),2)*BA36),2) -> 0 | CU36: =AG36 -> 0 | CV36: =(AH36*AV36) -> 0 | CW36: =AI36 -> 0 | CX36: =AJ36 -> 0 | CY36: =(((S36+R36)*AT36)/100) -> 0 | CZ36: =(((S36+R36)*AU36)/100) -> 0 | DN36: 0 | DO36: 0 | DP36: 1 | DQ36: 1 | DU36: 1013 | DV36: 1 Т | DW36: 1 Т | DX36: 1 | EE36: 55586412 | EF36: 150 | EG36: Транспортные затраты | EH36: 0 | EJ36: 4 | EK36: 188 | EL36: ТСН-2001.15. Перевозка строительных грузов автомобильным транспортом | EM36: ТСН-2001.15. | EQ36: 0 | ER36: 38.77 | ES36: 0 | ET36: 38.77 | EU36: 0 | EV36: 0 | EW36: 0 | EX36: 0 | EY36: 0 | FQ36: 0 | FR36: 0 | FS36: 0 | FX36: 94 | FY36: 61 | GD36: 1 | GF36: 725869249 | GG36: 2 | GH36: 1 | GI36: 2 | GJ36: 0 | GK36: 0 | GL36: =ROUND(IF(AND(BH36=3,BI36=3,FS36<>0),P36,0),2) -> 0 | GM36: =ROUND(O36+X36+Y36,2)+GX36 -> 1.36 | GN36: =IF(OR(BI36=0,BI36=1),GM36-GX36,0) -> 0 | GO36: =IF(BI36=2,GM36-GX36,0) -> 0 | GP36: =IF(BI36=4,GM36-GX36,0) -> 1.36 | GR36: 0 | GS36: 3 | GT36: 0 | GV36: =ROUND((GT36),6) -> 0 | GW36: 1 | GX36: =ROUND(HC36*I36,2) -> 0 | HA36: 0 | HB36: 0 | HC36: =GV36*GW36 -> 0 | HS36: 0 | IK36: 0
A37: 17 | B37: 1 | C37: =ROW(SmtRes!A10) -> 10 | D37: =ROW(EtalonRes!A10) -> 10 | E37: 5 | F37: 15.1-1203-02 | G37: Обрезь и лом гипсокартонных листов малоопасные | H37: 1 Т | I37: 0.035 | J37: 0 | K37: 0.035 | O37: =ROUND(CP37,2) -> 14.32 | P37: =ROUND((ROUND((AC37*AW37*I37),2)*BC37),2) -> 0 | Q37: =(ROUND((ROUND(((ET37)*AV37*I37),2)*BB37),2)+ROUND((ROUND(((AE37-(EU37))*AV37*I37),2)*BS37),2)) -> 14.32 | R37: =ROUND((ROUND((AE37*AV37*I37),2)*BS37),2) -> 0 | S37: =ROUND((ROUND((AF37*AV37*I37),2)*BA37),2) -> 0 | T37: =ROUND(CU37*I37,2) -> 0 | U37: =CV37*I37 -> 0 | V37: =CW37*I37 -> 0 | W37: =ROUND(CX37*I37,2) -> 0 | X37: =ROUND(CY37,2) -> 0 | Y37: =ROUND(CZ37,2) -> 0 | AA37: 56526441 | AB37: =ROUND((AC37+AD37+AF37),6) -> 38.77 | AC37: =ROUND((ES37),6) -> 0 | AD37: =ROUND((((ET37)-(EU37))+AE37),6) -> 38.77 | AE37: =ROUND((EU37),6) -> 0 | AF37: =ROUND((EV37),6) -> 0 | AG37: =ROUND((AP37),6) -> 0 | AH37: =(EW37) -> 0 | AI37: =(EX37) -> 0 | AJ37: =(AS37) -> 0 | AK37: 38.77 | AL37: 0 | AM37: 38.77 | AN37: 0 | AO37: 0 | AP37: 0 | AQ37: 0 | AR37: 0 | AS37: 0 | AT37: 94 | AU37: 61 | AV37: 1 | AW37: 1 | AZ37: 1 | BA37: 1 | BB37: 10.53 | BC37: 1 | BH37: 0 | BI37: 4 | BJ37: ТСН-2001.15 Доп. 56, Сб. 1, т. 1203, поз. 2 | BM37: 188 | BN37: 0 | BO37: 15.1-1203-02 | BP37: 1 | BQ37: 150 | BR37: 0 | BS37: 1 | BT37: 1 | BU37: 1 | BV37: 1 | BW37: 1 | BX37: 1 | BZ37: 94 | CA37: 61 | CE37: 30 | CF37: 0 | CG37: 0 | CM37: 0 | CO37: 0 | CP37: =(P37+Q37+S37) -> 14.32 | CQ37: =ROUND((ROUND((AC37*AW37*1),2)*BC37),2) -> 0 | CR37: =(ROUND((ROUND(((ET37)*AV37*1),2)*BB37),2)+ROUND((ROUND(((AE37-(EU37))*AV37*1),2)*BS37),2)) -> 408.25 | CS37: =ROUND((ROUND((AE37*AV37*1),2)*BS37),2) -> 0 | CT37: =ROUND((ROUND((AF37*AV37*1),2)*BA37),2) -> 0 | CU37: =AG37 -> 0 | CV37: =(AH37*AV37) -> 0 | CW37: =AI37 -> 0 | CX37: =AJ37 -> 0 | CY37: =(((S37+R37)*AT37)/100) -> 0 | CZ37: =(((S37+R37)*AU37)/100) -> 0 | DN37: 0 | DO37: 0 | DP37: 1 | DQ37: 1 | DU37: 1013 | DV37: 1 Т | DW37: 1 Т | DX37: 1 | EE37: 55586412 | EF37: 150 | EG37: Транспортные затраты | EH37: 0 | EJ37: 4 | EK37: 188 | EL37: ТСН-2001.15. Перевозка строительных грузов автомобильным транспортом | EM37: ТСН-2001.15. | EQ37: 0 | ER37: 38.77 | ES37: 0 | ET37: 38.77 | EU37: 0 | EV37: 0 | EW37: 0 | EX37: 0 | EY37: 0 | FQ37: 0 | FR37: 0 | FS37: 0 | FX37: 94 | FY37: 61 | GD37: 1 | GF37: 725869249 | GG37: 2 | GH37: 1 | GI37: 2 | GJ37: 0 | GK37: 0 | GL37: =ROUND(IF(AND(BH37=3,BI37=3,FS37<>0),P37,0),2) -> 0 | GM37: =ROUND(O37+X37+Y37,2)+GX37 -> 14.32 | GN37: =IF(OR(BI37=0,BI37=1),GM37-GX37,0) -> 0 | GO37: =IF(BI37=2,GM37-GX37,0) -> 0 | GP37: =IF(BI37=4,GM37-GX37,0) -> 14.32 | GR37: 0 | GS37: 3 | GT37: 0 | GV37: =ROUND((GT37),6) -> 0 | GW37: 1 | GX37: =ROUND(HC37*I37,2) -> 0 | HA37: 0 | HB37: 0 | HC37: =GV37*GW37 -> 0 | HS37: 0 | IK37: 0
A38: 17 | B38: 1 | C38: =ROW(SmtRes!A11) -> 11 | D38: =ROW(EtalonRes!A11) -> 11 | E38: 6 | F38: 15.1-1207-01 | G38: Отходы линолеума незагрязненные малоопасные | H38: 1 Т | I38: 3.487 | J38: 0 | K38: 3.487 | O38: =ROUND(CP38,2) -> 135.19 | P38: =ROUND((ROUND((AC38*AW38*I38),2)*BC38),2) -> 0 | Q38: =(ROUND((ROUND(((ET38)*AV38*I38),2)*BB38),2)+ROUND((ROUND(((AE38-(EU38))*AV38*I38),2)*BS38),2)) -> 135.19 | R38: =ROUND((ROUND((AE38*AV38*I38),2)*BS38),2) -> 0 | S38: =ROUND((ROUND((AF38*AV38*I38),2)*BA38),2) -> 0 | T38: =ROUND(CU38*I38,2) -> 0 | U38: =CV38*I38 -> 0 | V38: =CW38*I38 -> 0 | W38: =ROUND(CX38*I38,2) -> 0 | X38: =ROUND(CY38,2) -> 0 | Y38: =ROUND(CZ38,2) -> 0 | AA38: 56526439 | AB38: =ROUND((AC38+AD38+AF38),6) -> 38.77 | AC38: =ROUND((ES38),6) -> 0 | AD38: =ROUND((((ET38)-(EU38))+AE38),6) -> 38.77 | AE38: =ROUND((EU38),6) -> 0 | AF38: =ROUND((EV38),6) -> 0 | AG38: =ROUND((AP38),6) -> 0 | AH38: =(EW38) -> 0 | AI38: =(EX38) -> 0 | AJ38: =(AS38) -> 0 | AK38: 38.77 | AL38: 0 | AM38: 38.77 | AN38: 0 | AO38: 0 | AP38: 0 | AQ38: 0 | AR38: 0 | AS38: 0 | AT38: 94 | AU38: 61 | AV38: 1 | AW38: 1 | AZ38: 1 | BA38: 1 | BB38: 1 | BC38: 1 | BH38: 0 | BI38: 4 | BJ38: ТСН-2001.15 Доп. 56, Сб. 1, т. 1207, поз. 1 | BM38: 188 | BN38: 0 | BO38: 15.1-1207-01 | BP38: 1 | BQ38: 150 | BR38: 0 | BS38: 1 | BT38: 1 | BU38: 1 | BV38: 1 | BW38: 1 | BX38: 1 | BZ38: 94 | CA38: 61 | CE38: 30 | CF38: 0 | CG38: 0 | CM38: 0 | CO38: 0 | CP38: =(P38+Q38+S38) -> 135.19 | CQ38: =ROUND((ROUND((AC38*AW38*1),2)*BC38),2) -> 0 | CR38: =(ROUND((ROUND(((ET38)*AV38*1),2)*BB38),2)+ROUND((ROUND(((AE38-(EU38))*AV38*1),2)*BS38),2)) -> 38.77 | CS38: =ROUND((ROUND((AE38*AV38*1),2)*BS38),2) -> 0 | CT38: =ROUND((ROUND((AF38*AV38*1),2)*BA38),2) -> 0 | CU38: =AG38 -> 0 | CV38: =(AH38*AV38) -> 0 | CW38: =AI38 -> 0 | CX38: =AJ38 -> 0 | CY38: =(((S38+R38)*AT38)/100) -> 0 | CZ38: =(((S38+R38)*AU38)/100) -> 0 | DN38: 0 | DO38: 0 | DP38: 1 | DQ38: 1 | DU38: 1013 | DV38: 1 Т | DW38: 1 Т | DX38: 1 | EE38: 55586412 | EF38: 150 | EG38: Транспортные затраты | EH38: 0 | EJ38: 4 | EK38: 188 | EL38: ТСН-2001.15. Перевозка строительных грузов автомобильным транспортом | EM38: ТСН-2001.15. | EQ38: 0 | ER38: 38.77 | ES38: 0 | ET38: 38.77 | EU38: 0 | EV38: 0 | EW38: 0 | EX38: 0 | EY38: 0 | FQ38: 0 | FR38: 0 | FS38: 0 | FX38: 94 | FY38: 61 | GD38: 1 | GF38: 345636752 | GG38: 2 | GH38: 1 | GI38: 2 | GJ38: 0 | GK38: 0 | GL38: =ROUND(IF(AND(BH38=3,BI38=3,FS38<>0),P38,0),2) -> 0 | GM38: =ROUND(O38+X38+Y38,2)+GX38 -> 135.19 | GN38: =IF(OR(BI38=0,BI38=1),GM38-GX38,0) -> 0 | GO38: =IF(BI38=2,GM38-GX38,0) -> 0 | GP38: =IF(BI38=4,GM38-GX38,0) -> 135.19 | GR38: 0 | GS38: 3 | GT38: 0 | GV38: =ROUND((GT38),6) -> 0 | GW38: 1 | GX38: =ROUND(HC38*I38,2) -> 0 | HA38: 0 | HB38: 0 | HC38: =GV38*GW38 -> 0 | HS38: 0 | IK38: 0
A39: 17 | B39: 1 | C39: =ROW(SmtRes!A12) -> 12 | D39: =ROW(EtalonRes!A12) -> 12 | E39: 6 | F39: 15.1-1207-01 | G39: Отходы линолеума незагрязненные малоопасные | H39: 1 Т | I39: 3.487 | J39: 0 | K39: 3.487 | O39: =ROUND(CP39,2) -> 6685.15 | P39: =ROUND((ROUND((AC39*AW39*I39),2)*BC39),2) -> 0 | Q39: =(ROUND((ROUND(((ET39)*AV39*I39),2)*BB39),2)+ROUND((ROUND(((AE39-(EU39))*AV39*I39),2)*BS39),2)) -> 6685.15 | R39: =ROUND((ROUND((AE39*AV39*I39),2)*BS39),2) -> 0 | S39: =ROUND((ROUND((AF39*AV39*I39),2)*BA39),2) -> 0 | T39: =ROUND(CU39*I39,2) -> 0 | U39: =CV39*I39 -> 0 | V39: =CW39*I39 -> 0 | W39: =ROUND(CX39*I39,2) -> 0 | X39: =ROUND(CY39,2) -> 0 | Y39: =ROUND(CZ39,2) -> 0 | AA39: 56526441 | AB39: =ROUND((AC39+AD39+AF39),6) -> 38.77 | AC39: =ROUND((ES39),6) -> 0 | AD39: =ROUND((((ET39)-(EU39))+AE39),6) -> 38.77 | AE39: =ROUND((EU39),6) -> 0 | AF39: =ROUND((EV39),6) -> 0 | AG39: =ROUND((AP39),6) -> 0 | AH39: =(EW39) -> 0 | AI39: =(EX39) -> 0 | AJ39: =(AS39) -> 0 | AK39: 38.77 | AL39: 0 | AM39: 38.77 | AN39: 0 | AO39: 0 | AP39: 0 | AQ39: 0 | AR39: 0 | AS39: 0 | AT39: 94 | AU39: 61 | AV39: 1 | AW39: 1 | AZ39: 1 | BA39: 1 | BB39: 49.45 | BC39: 1 | BH39: 0 | BI39: 4 | BJ39: ТСН-2001.15 Доп. 56, Сб. 1, т. 1207, поз. 1 | BM39: 188 | BN39: 0 | BO39: 15.1-1207-01 | BP39: 1 | BQ39: 150 | BR39: 0 | BS39: 1 | BT39: 1 | BU39: 1 | BV39: 1 | BW39: 1 | BX39: 1 | BZ39: 94 | CA39: 61 | CE39: 30 | CF39: 0 | CG39: 0 | CM39: 0 | CO39: 0 | CP39: =(P39+Q39+S39) -> 6685.15 | CQ39: =ROUND((ROUND((AC39*AW39*1),2)*BC39),2) -> 0 | CR39: =(ROUND((ROUND(((ET39)*AV39*1),2)*BB39),2)+ROUND((ROUND(((AE39-(EU39))*AV39*1),2)*BS39),2)) -> 1917.18 | CS39: =ROUND((ROUND((AE39*AV39*1),2)*BS39),2) -> 0 | CT39: =ROUND((ROUND((AF39*AV39*1),2)*BA39),2) -> 0 | CU39: =AG39 -> 0 | CV39: =(AH39*AV39) -> 0 | CW39: =AI39 -> 0 | CX39: =AJ39 -> 0 | CY39: =(((S39+R39)*AT39)/100) -> 0 | CZ39: =(((S39+R39)*AU39)/100) -> 0 | DN39: 0 | DO39: 0 | DP39: 1 | DQ39: 1 | DU39: 1013 | DV39: 1 Т | DW39: 1 Т | DX39: 1 | EE39: 55586412 | EF39: 150 | EG39: Транспортные затраты | EH39: 0 | EJ39: 4 | EK39: 188 | EL39: ТСН-2001.15. Перевозка строительных грузов автомобильным транспортом | EM39: ТСН-2001.15. | EQ39: 0 | ER39: 38.77 | ES39: 0 | ET39: 38.77 | EU39: 0 | EV39: 0 | EW39: 0 | EX39: 0 | EY39: 0 | FQ39: 0 | FR39: 0 | FS39: 0 | FX39: 94 | FY39: 61 | GD39: 1 | GF39: 345636752 | GG39: 2 | GH39: 1 | GI39: 2 | GJ39: 0 | GK39: 0 | GL39: =ROUND(IF(AND(BH39=3,BI39=3,FS39<>0),P39,0),2) -> 0 | GM39: =ROUND(O39+X39+Y39,2)+GX39 -> 6685.15 | GN39: =IF(OR(BI39=0,BI39=1),GM39-GX39,0) -> 0 | GO39: =IF(BI39=2,GM39-GX39,0) -> 0 | GP39: =IF(BI39=4,GM39-GX39,0) -> 6685.15 | GR39: 0 | GS39: 3 | GT39: 0 | GV39: =ROUND((GT39),6) -> 0 | GW39: 1 | GX39: =ROUND(HC39*I39,2) -> 0 | HA39: 0 | HB39: 0 | HC39: =GV39*GW39 -> 0 | HS39: 0 | IK39: 0
... A63: 17 | B63: 1 | C63: =ROW(SmtRes!A36) -> 36 | D63: =ROW(EtalonRes!A36) -> 36 | E63: 18 | F63: 15.1-1505-07 | G63: Керамзит, утративший потребительские свойства, незагрязненный, практически неопасный | H63: 1 Т | I63: 318.564 | J63: 0 | K63: 318.564 | O63: =ROUND(CP63,2) -> 123955.49 | P63: =ROUND((ROUND((AC63*AW63*I63),2)*BC63),2) -> 0 | Q63: =(ROUND((ROUND(((ET63)*AV63*I63),2)*BB63),2)+ROUND((ROUND(((AE63-(EU63))*AV63*I63),2)*BS63),2)) -> 123955.49 | R63: =ROUND((ROUND((AE63*AV63*I63),2)*BS63),2) -> 0 | S63: =ROUND((ROUND((AF63*AV63*I63),2)*BA63),2) -> 0 | T63: =ROUND(CU63*I63,2) -> 0 | U63: =CV63*I63 -> 0 | V63: =CW63*I63 -> 0 | W63: =ROUND(CX63*I63,2) -> 0 | X63: =ROUND(CY63,2) -> 0 | Y63: =ROUND(CZ63,2) -> 0 | AA63: 56526441 | AB63: =ROUND((AC63+AD63+AF63),6) -> 47.51 | AC63: =ROUND((ES63),6) -> 0 | AD63: =ROUND((((ET63)-(EU63))+AE63),6) -> 47.51 | AE63: =ROUND((EU63),6) -> 0 | AF63: =ROUND((EV63),6) -> 0 | AG63: =ROUND((AP63),6) -> 0 | AH63: =(EW63) -> 0 | AI63: =(EX63) -> 0 | AJ63: =(AS63) -> 0 | AK63: 47.51 | AL63: 0 | AM63: 47.51 | AN63: 0 | AO63: 0 | AP63: 0 | AQ63: 0 | AR63: 0 | AS63: 0 | AT63: 94 | AU63: 61 | AV63: 1 | AW63: 1 | AZ63: 1 | BA63: 1 | BB63: 8.19 | BC63: 1 | BH63: 0 | BI63: 4 | BJ63: ТСН-2001.15 Доп. 56, Сб. 1, т. 1505, поз. 7 | BM63: 188 | BN63: 0 | BO63: 15.1-1505-07 | BP63: 1 | BQ63: 150 | BR63: 0 | BS63: 1 | BT63: 1 | BU63: 1 | BV63: 1 | BW63: 1 | BX63: 1 | BZ63: 94 | CA63: 61 | CE63: 30 | CF63: 0 | CG63: 0 | CM63: 0 | CO63: 0 | CP63: =(P63+Q63+S63) -> 123955.49 | CQ63: =ROUND((ROUND((AC63*AW63*1),2)*BC63),2) -> 0 | CR63: =(ROUND((ROUND(((ET63)*AV63*1),2)*BB63),2)+ROUND((ROUND(((AE63-(EU63))*AV63*1),2)*BS63),2)) -> 389.11 | CS63: =ROUND((ROUND((AE63*AV63*1),2)*BS63),2) -> 0 | CT63: =ROUND((ROUND((AF63*AV63*1),2)*BA63),2) -> 0 | CU63: =AG63 -> 0 | CV63: =(AH63*AV63) -> 0 | CW63: =AI63 -> 0 | CX63: =AJ63 -> 0 | CY63: =(((S63+R63)*AT63)/100) -> 0 | CZ63: =(((S63+R63)*AU63)/100) -> 0 | DN63: 0 | DO63: 0 | DP63: 1 | DQ63: 1 | DU63: 1013 | DV63: 1 Т | DW63: 1 Т | DX63: 1 | EE63: 55586412 | EF63: 150 | EG63: Транспортные затраты | EH63: 0 | EJ63: 4 | EK63: 188 | EL63: ТСН-2001.15. Перевозка строительных грузов автомобильным транспортом | EM63: ТСН-2001.15. | EQ63: 0 | ER63: 47.51 | ES63: 0 | ET63: 47.51 | EU63: 0 | EV63: 0 | EW63: 0 | EX63: 0 | EY63: 0 | FQ63: 0 | FR63: 0 | FS63: 0 | FX63: 94 | FY63: 61 | GD63: 1 | GF63: -1557990163 | GG63: 2 | GH63: 1 | GI63: 2 | GJ63: 0 | GK63: 0 | GL63: =ROUND(IF(AND(BH63=3,BI63=3,FS63<>0),P63,0),2) -> 0 | GM63: =ROUND(O63+X63+Y63,2)+GX63 -> 123955.49 | GN63: =IF(OR(BI63=0,BI63=1),GM63-GX63,0) -> 0 | GO63: =IF(BI63=2,GM63-GX63,0) -> 0 | GP63: =IF(BI63=4,GM63-GX63,0) -> 123955.49 | GR63: 0 | GS63: 3 | GT63: 0 | GV63: =ROUND((GT63),6) -> 0 | GW63: 1 | GX63: =ROUND(HC63*I63,2) -> 0 | HA63: 0 | HB63: 0 | HC63: =GV63*GW63 -> 0 | HS63: 0 | IK63: 0
A65: 51 | B65: =B24 -> 1 | C65: =A24 -> 4 | D65: =ROW(A24) -> 24 | F65: =IF(F24<>"",F24,"") | G65: =IF(G24<>"",G24,"") -> Размещение и содержание строительного мусора | H65: 0 | O65: =ROUND(AB65,2) -> 96538.04 | P65: =ROUND(AC65,2) -> 0 | Q65: =ROUND(AD65,2) -> 96538.04 | R65: =ROUND(AE65,2) -> 0 | S65: =ROUND(AF65,2) -> 0 | T65: =ROUND(AG65,2) -> 0 | U65: =AH65 -> 0 | V65: =AI65 -> 0 | W65: =ROUND(AJ65,2) -> 0 | X65: =ROUND(AK65,2) -> 0 | Y65: =ROUND(AL65,2) -> 0 | AB65: =ROUND(SUMIF(AA28:AA63,"=56526439",O28:O63),2) -> 96538.04 | AC65: =ROUND(SUMIF(AA28:AA63,"=56526439",P28:P63),2) -> 0 | AD65: =ROUND(SUMIF(AA28:AA63,"=56526439",Q28:Q63),2) -> 96538.04 | AE65: =ROUND(SUMIF(AA28:AA63,"=56526439",R28:R63),2) -> 0 | AF65: =ROUND(SUMIF(AA28:AA63,"=56526439",S28:S63),2) -> 0 | AG65: =ROUND(SUMIF(AA28:AA63,"=56526439",T28:T63),2) -> 0 | AH65: =SUMIF(AA28:AA63,"=56526439",U28:U63) -> 0 | AI65: =SUMIF(AA28:AA63,"=56526439",V28:V63) -> 0 | AJ65: =ROUND(SUMIF(AA28:AA63,"=56526439",W28:W63),2) -> 0 | AK65: =ROUND(SUMIF(AA28:AA63,"=56526439",X28:X63),2) -> 0 | AL65: =ROUND(SUMIF(AA28:AA63,"=56526439",Y28:Y63),2) -> 0 | AO65: =ROUND(BX65,2) -> 0 | AP65: =ROUND(BY65,2) -> 0 | AQ65: =ROUND(BZ65,2) -> 0 | AR65: =ROUND(CA65,2) -> 96538.04 | AS65: =ROUND(CB65,2) -> 0 | AT65: =ROUND(CC65,2) -> 0 | AU65: =ROUND(CD65,2) -> 96538.04 | AV65: =ROUND(CE65,2) -> 0 | ... BD65: =ROUND(CM65,2) -> 0 | BX65: =ROUND(SUMIF(AA28:AA63,"=56526439",FQ28:FQ63),2) -> 0 | BY65: =ROUND(SUMIF(AA28:AA63,"=56526439",FR28:FR63),2) -> 0 | BZ65: =ROUND(SUMIF(AA28:AA63,"=56526439",GL28:GL63),2) -> 0 | CA65: =ROUND(SUMIF(AA28:AA63,"=56526439",GM28:GM63),2) -> 96538.04 | CB65: =ROUND(SUMIF(AA28:AA63,"=56526439",GN28:GN63),2) -> 0 | CC65: =ROUND(SUMIF(AA28:AA63,"=56526439",GO28:GO63),2) -> 0 | CD65: =ROUND(SUMIF(AA28:AA63,"=56526439",GP28:GP63),2) -> 96538.04 | CE65: =AC65-BX65 -> 0 | CF65: =AC65-BY65 -> 0 | CG65: =BX65-BZ65 -> 0 | CH65: =AC65-BX65-BY65+BZ65 -> 0 | CI65: =BY65-BZ65 -> 0 | CJ65: =ROUND(SUMIF(AA28:AA63,"=56526439",GX28:GX63),2) -> 0 | CK65: =ROUND(SUMIF(AA28:AA63,"=56526439",GY28:GY63),2) -> 0 | CL65: =ROUND(SUMIF(AA28:AA63,"=56526439",GZ28:GZ63),2) -> 0 | CM65: =ROUND(SUMIF(AA28:AA63,"=56526439",HD28:HD63),2) -> 0 | DG65: =ROUND(DT65,2) -> 961161.92 | DH65: =ROUND(DU65,2) -> 0 | DI65: =ROUND(DV65,2) -> 961161.92 | DJ65: =ROUND(DW65,2) -> 0 | DK65: =ROUND(DX65,2) -> 0 | DL65: =ROUND(DY65,2) -> 0 | DM65: =DZ65 -> 0 | DN65: =EA65 -> 0 | DO65: =ROUND(EB65,2) -> 0 | DP65: =ROUND(EC65,2) -> 0 | DQ65: =ROUND(ED65,2) -> 0 | DT65: =ROUND(SUMIF(AA28:AA63,"=56526441",O28:O63),2) -> 961161.92 | DU65: =ROUND(SUMIF(AA28:AA63,"=56526441",P28:P63),2) -> 0 | DV65: =ROUND(SUMIF(AA28:AA63,"=56526441",Q28:Q63),2) -> 961161.92 | DW65: =ROUND(SUMIF(AA28:AA63,"=56526441",R28:R63),2) -> 0 | DX65: =ROUND(SUMIF(AA28:AA63,"=56526441",S28:S63),2) -> 0 | DY65: =ROUND(SUMIF(AA28:AA63,"=56526441",T28:T63),2) -> 0 | DZ65: =SUMIF(AA28:AA63,"=56526441",U28:U63) -> 0 | EA65: =SUMIF(AA28:AA63,"=56526441",V28:V63) -> 0 | EB65: =ROUND(SUMIF(AA28:AA63,"=56526441",W28:W63),2) -> 0 | EC65: =ROUND(SUMIF(AA28:AA63,"=56526441",X28:X63),2) -> 0 | ED65: =ROUND(SUMIF(AA28:AA63,"=56526441",Y28:Y63),2) -> 0 | EG65: =ROUND(FP65,2) -> 0 | EH65: =ROUND(FQ65,2) -> 0 | EI65: =ROUND(FR65,2) -> 0 | EJ65: =ROUND(FS65,2) -> 961161.92 | EK65: =ROUND(FT65,2) -> 0 | EL65: =ROUND(FU65,2) -> 0 | EM65: =ROUND(FV65,2) -> 961161.92 | EN65: =ROUND(FW65,2) -> 0 | ... EV65: =ROUND(GE65,2) -> 0 | FP65: =ROUND(SUMIF(AA28:AA63,"=56526441",FQ28:FQ63),2) -> 0 | FQ65: =ROUND(SUMIF(AA28:AA63,"=56526441",FR28:FR63),2) -> 0 | FR65: =ROUND(SUMIF(AA28:AA63,"=56526441",GL28:GL63),2) -> 0 | FS65: =ROUND(SUMIF(AA28:AA63,"=56526441",GM28:GM63),2) -> 961161.92 | FT65: =ROUND(SUMIF(AA28:AA63,"=56526441",GN28:GN63),2) -> 0 | FU65: =ROUND(SUMIF(AA28:AA63,"=56526441",GO28:GO63),2) -> 0 | FV65: =ROUND(SUMIF(AA28:AA63,"=56526441",GP28:GP63),2) -> 961161.92 | FW65: =DU65-FP65 -> 0 | FX65: =DU65-FQ65 -> 0 | FY65: =FP65-FR65 -> 0 | FZ65: =DU65-FP65-FQ65+FR65 -> 0 | GA65: =FQ65-FR65 -> 0 | GB65: =ROUND(SUMIF(AA28:AA63,"=56526441",GX28:GX63),2) -> 0 | GC65: =ROUND(SUMIF(AA28:AA63,"=56526441",GY28:GY63),2) -> 0 | GD65: =ROUND(SUMIF(AA28:AA63,"=56526441",GZ28:GZ63),2) -> 0 | GE65: =ROUND(SUMIF(AA28:AA63,"=56526441",HD28:HD63),2) -> 0 | GX65: 0
A67: 50 | B67: 0 | C67: 0 | D67: 1 | E67: 201 | F67: =ROUND(Source!O65,O67) -> 96538.04 | G67: ПЗ | H67: Прямые затраты | K67: 201 | L67: 1 | M67: 3 | O67: 2 | P67: =ROUND(Source!DG65,O67) -> 961161.92 | W67: 96538.04 | X67: 1 | Y67: 96538.04 | Z67: 961161.92 | AA67: 1 | AB67: 961161.92
A68: 50 | B68: 0 | C68: 0 | D68: 1 | E68: 202 | F68: =ROUND(Source!P65,O68) -> 0 | G68: СтМатОб | H68: Стоимость материальных ресурсов (всего) | K68: 202 | L68: 2 | M68: 3 | O68: 2 | P68: =ROUND(Source!DH65,O68) -> 0 | W68: 0 | X68: 1 | Y68: 0 | Z68: 0 | AA68: 1 | AB68: 0
A69: 50 | B69: 0 | C69: 0 | D69: 1 | E69: 222 | F69: =ROUND(Source!AO65,O69) -> 0 | G69: СтМатОбЗак | H69: Стоимость материалов и оборудования заказчика | K69: 222 | L69: 3 | M69: 3 | O69: 2 | P69: =ROUND(Source!EG65,O69) -> 0 | W69: 0 | X69: 1 | Y69: 0 | Z69: 0 | AA69: 1 | AB69: 0
A70: 50 | B70: 0 | C70: 0 | D70: 1 | E70: 225 | F70: =ROUND(Source!AV65,O70) -> 0 | G70: СтМатОбПод | H70: Стоимость материалов и оборудования подрядчика | K70: 225 | L70: 4 | M70: 3 | O70: 2 | P70: =ROUND(Source!EN65,O70) -> 0 | W70: 0 | X70: 1 | Y70: 0 | Z70: 0 | AA70: 1 | AB70: 0
A71: 50 | B71: 0 | C71: 0 | D71: 1 | E71: 226 | F71: =ROUND(Source!AW65,O71) -> 0 | G71: СтМат | H71: Стоимость материалов (всего) | K71: 226 | L71: 5 | M71: 3 | O71: 2 | P71: =ROUND(Source!EO65,O71) -> 0 | W71: 0 | X71: 1 | Y71: 0 | Z71: 0 | AA71: 1 | AB71: 0
A72: 50 | B72: 0 | C72: 0 | D72: 1 | E72: 227 | F72: =ROUND(Source!AX65,O72) -> 0 | G72: СтМатЗак | H72: Стоимость материалов заказчика | K72: 227 | L72: 6 | M72: 3 | O72: 2 | P72: =ROUND(Source!EP65,O72) -> 0 | W72: 0 | X72: 1 | Y72: 0 | Z72: 0 | AA72: 1 | AB72: 0
A73: 50 | B73: 0 | C73: 0 | D73: 1 | E73: 228 | F73: =ROUND(Source!AY65,O73) -> 0 | G73: СтМатПод | H73: Стоимость материалов подрядчика | K73: 228 | L73: 7 | M73: 3 | O73: 2 | P73: =ROUND(Source!EQ65,O73) -> 0 | W73: 0 | X73: 1 | Y73: 0 | Z73: 0 | AA73: 1 | AB73: 0
A74: 50 | B74: 0 | C74: 0 | D74: 1 | E74: 216 | F74: =ROUND(Source!AP65,O74) -> 0 | G74: Оборуд | H74: Стоимость оборудования (всего) | K74: 216 | L74: 8 | M74: 3 | O74: 2 | P74: =ROUND(Source!EH65,O74) -> 0 | W74: 0 | X74: 1 | Y74: 0 | Z74: 0 | AA74: 1 | AB74: 0
A75: 50 | B75: 0 | C75: 0 | D75: 1 | E75: 223 | F75: =ROUND(Source!AQ65,O75) -> 0 | G75: ОборудЗак | H75: Стоимость оборудования заказчика | K75: 223 | L75: 9 | M75: 3 | O75: 2 | P75: =ROUND(Source!EI65,O75) -> 0 | W75: 0 | X75: 1 | Y75: 0 | Z75: 0 | AA75: 1 | AB75: 0
A76: 50 | B76: 0 | C76: 0 | D76: 1 | E76: 229 | F76: =ROUND(Source!AZ65,O76) -> 0 | G76: ОборудПод | H76: Стоимость оборудования подрядчика | K76: 229 | L76: 10 | M76: 3 | O76: 2 | P76: =ROUND(Source!ER65,O76) -> 0 | W76: 0 | X76: 1 | Y76: 0 | Z76: 0 | AA76: 1 | AB76: 0
A77: 50 | B77: 0 | C77: 0 | D77: 1 | E77: 203 | F77: =ROUND(Source!Q65,O77) -> 96538.04 | G77: ЭММ | H77: Эксплуатация машин | K77: 203 | L77: 11 | M77: 3 | O77: 2 | P77: =ROUND(Source!DI65,O77) -> 961161.92 | W77: 96538.04 | X77: 1 | Y77: 96538.04 | Z77: 961161.92 | AA77: 1 | AB77: 961161.92
A78: 50 | B78: 0 | C78: 0 | D78: 1 | E78: 231 | F78: =ROUND(Source!BB65,O78) -> 0 | G78: ЭММсНРиСП | H78: Эксплуатация машин по ТСН-2001.16 | K78: 231 | L78: 12 | M78: 3 | O78: 2 | P78: =ROUND(Source!ET65,O78) -> 0 | W78: 0 | X78: 1 | Y78: 0 | Z78: 0 | AA78: 1 | AB78: 0
A79: 50 | B79: 0 | C79: 0 | D79: 1 | E79: 204 | F79: =ROUND(Source!R65,O79) -> 0 | G79: ЗПМ | H79: ЗП машинистов | K79: 204 | L79: 13 | M79: 3 | O79: 2 | P79: =ROUND(Source!DJ65,O79) -> 0 | W79: 0 | X79: 1 | Y79: 0 | Z79: 0 | AA79: 1 | AB79: 0
A80: 50 | B80: 0 | C80: 0 | D80: 1 | E80: 205 | F80: =ROUND(Source!S65,O80) -> 0 | G80: ОЗП | H80: Основная ЗП рабочих | K80: 205 | L80: 14 | M80: 3 | O80: 2 | P80: =ROUND(Source!DK65,O80) -> 0 | W80: 0 | X80: 1 | Y80: 0 | Z80: 0 | AA80: 1 | AB80: 0
A81: 50 | B81: 0 | C81: 0 | D81: 1 | E81: 232 | F81: =ROUND(Source!BC65,O81) -> 0 | G81: ОЗПсНРиСП | H81: Основная ЗП рабочих по ТСН-2001.16 | K81: 232 | L81: 15 | M81: 3 | O81: 2 | P81: =ROUND(Source!EU65,O81) -> 0 | W81: 0 | X81: 1 | Y81: 0 | Z81: 0 | AA81: 1 | AB81: 0
A82: 50 | B82: 0 | C82: 0 | D82: 1 | E82: 214 | F82: =ROUND(Source!AS65,O82) -> 0 | G82: Строит | H82: Строительные работы с НР и СП | K82: 214 | L82: 16 | M82: 3 | O82: 2 | P82: =ROUND(Source!EK65,O82) -> 0 | W82: 0 | X82: 1 | Y82: 0 | Z82: 0 | AA82: 1 | AB82: 0
A83: 50 | B83: 0 | C83: 0 | D83: 1 | E83: 215 | F83: =ROUND(Source!AT65,O83) -> 0 | G83: Монтаж | H83: Монтажные работы с НР и СП | K83: 215 | L83: 17 | M83: 3 | O83: 2 | P83: =ROUND(Source!EL65,O83) -> 0 | W83: 0 | X83: 1 | Y83: 0 | Z83: 0 | AA83: 1 | AB83: 0
...

Sheet SourceObSm
A1: 0 | B1: Smeta.RU (495) 974-1589 | D1: _OBSM_ | F1: 0 | G1: 0 | H1: 0 | I1: Smeta.RU | K1: 1 | L1: 74562 | M1: 10 | N1: 11 | O1: 14 | P1: 0 | Q1: 0
A4: 1 | B4: 1 | C4: -1 | G4: Капитальный ремонт здания Государственного бюджетного общеобразовательного учреждения города Москвы «Школа № 236» по адресу: г. Москва, ул. Клязьминская, д. 7, к. 4. I этап | EC4: 0
