Workbook

Sheet 02-01-20
A1: =Source!B1 -> Smeta.RU (495) 974-1589
J2: Форма № 4б
A3: Капитальный ремонт здания Государственного бюджетного общеобразовательного учреждения города Москвы "Школа № 236" по адресу: г. Москва ул. Клязьминская, д. 7 к. 4. 1 этап. | AP3: Капитальный ремонт здания Государственного бюджетного общеобразовательного учреждения города Москвы "Школа № 236" по адресу: г. Москва ул. Клязьминская, д. 7 к. 4. 1 этап. 02-01-20 ПТА
A4: (наименование стройки и/или объекта)
A6: =CONCATENATE( "ЛОКАЛЬНАЯ СМЕТА № ",IF(Source!F20<>"Новая локальная смета", Source!F20, "")) -> ЛОКАЛЬНАЯ СМЕТА № 02-01-20
A8: =IF(Source!G20<>"Новая локальная смета", Source!G20, "") -> Мероприятия по противодействию террористическим актам
A9: (наименование работ и затрат)
A11: =CONCATENATE( "Основание: чертежи № ", Source!J20) -> Основание: чертежи № 2024-00272-01-0-ПТА
I13: В базисном уровне цен | J13: В текущем уровне цен
E14: Сметная стоимость | I14: =I15+I16+I17+I18 -> 376.17 | J14: =J15+J16+J17+J18 -> 2977.26 | K14: тыс.руб.
E15: Строительные работы | I15: =ROUND((Source!F98)/1000, 2) -> 26.42 | J15: =ROUND((Source!P98)/1000, 2) -> 266.61 | K15: тыс.руб.
E16: Работы по монтажу оборудования | I16: =ROUND((Source!F99)/1000, 2) -> 0.13 | J16: =ROUND((Source!P99)/1000, 2) -> 7.19 | K16: тыс.руб.
E17: Оборудование | I17: =ROUND((Source!F90)/1000, 2) -> 349.62 | J17: =ROUND((Source!P90)/1000, 2) -> 2703.46 | K17: тыс.руб.
E18: Прочие работы и затраты | I18: =ROUND((Source!F100+Source!F101)/1000, 2) -> 0 | J18: =ROUND((Source!P100+Source!P101)/1000, 2) -> 0 | K18: тыс.руб.
E19: Средства на оплату труда | I19: =(Source!F96+ Source!F95)/1000 -> 0.10155 | J19: =((Source!P96 + Source!P95)/1000) -> 5.58424 | K19: тыс.руб.
E20: Затраты труда | I20: =Source!F103 -> 8.0418206 | K20: чел.-ч.
E21: Кроме того:
E22: Возврат материалов | I22: =SUM(Y28:Y86)/1000 -> 0 | J22: =SUM(Z28:Z86)/1000 -> 0 | K22: тыс.руб.
A24: Составлен(а) по ТСН-2001 с учетом Дополнения №: 80
A25: № и период сборника коэффициентов (индексов) пересчета: Коэффициенты к ТСН-2001 МГЭ Дополнение 80, строительство №217/80 III квартал 2025 года и Коэффициенты к ТСН-2001.13-2 Дополнение 46 №62/46 III квартал 2025 года | AP25: № и период сборника коэффициентов (индексов) пересчета: Коэффициенты к ТСН-2001 МГЭ Дополнение 80, строительство №217/80 III квартал 2025 года и Коэффициенты к ТСН-2001.13-2 Дополнение 46 №62/46 III квартал 2025 года
A26: № п/п | B26: Шифр расценки и коды ресурсов | C26: Наименование работ и затрат | D26: Ед. изм. | E26: Кол-во единиц | F26: Цена на ед. изм., руб. | G26: Попра- вочные коэффи- циенты | H26: Коэффи- циенты зимних удорожа- ний | I26: Всего в ценах на январь 2000 года, руб. | J26: Коэффи- циенты (индек- сы) пере- счета, нормы НР и СП | K26: ВСЕГО затрат в текущем уровне цен, руб.
A27: 1 | B27: 2 | C27: 3 | D27: 4 | E27: 5 | F27: 6 | G27: 7 | H27: 8 | I27: 9 | J27: 10 | K27: 11
A29: =CONCATENATE("Раздел: ",IF(Source!G24<>"Новый раздел", Source!G24, "")) -> Раздел: Оборудование
A30: 1 | B30: 4.10-161-1 Поправка: Гл.12.Прил.8.п.8. 5_12.00.01.11.003 | C30: Монтаж стационарного металлодетектора арочного типа | D30: =Source!H28 -> 1 ШТ. | E30: =Source!I28 -> 2 | Q30: =Source!X28 -> 49.82 | R30: =Source!X29 -> 2739.33 | S30: =Source!Y28 -> 25.46 | T30: =Source!Y29 -> 1400.1 | U30: =ROUND((175/100)*ROUND(Source!R28, 2), 2) -> 0 | V30: =ROUND((0/100)*ROUND(Source!R29, 2), 2) -> 0 | AC30: 0
C31: ЗП | F31: =Source!AO28 -> 23.58 | G31: =Source!DG28 -> *1,1 | H31: =Source!AV29 -> 1.067 | I31: =Source!S28 -> 55.35 | J31: =IF(Source!BA29<> 0, Source!BA29, 1) -> 54.99 | K31: =Source!S29 -> 3043.7
C32: ЭМ | F32: =Source!AM28 -> 0.51 | G32: =Source!DE28 -> *1,1 | H32: =Source!AV29 -> 1.067 | I32: =Source!Q28 -> 1.2 | J32: =IF(Source!BB29<> 0, Source!BB29, 1) -> 8.63 | K32: =Source!Q29 -> 10.36
C33: НР от ФОТ | D33: % | E33: =Source!BZ29 -> 90 | I33: =SUM(Q30:Q32) -> 49.82 | J33: =Source!AT29 -> 90 | K33: =SUM(R30:R32) -> 2739.33
C34: СП от ФОТ | D34: % | E34: =Source!CA29 -> 46 | I34: =SUM(S30:S33) -> 25.46 | J34: =Source!AU29 -> 46 | K34: =SUM(T30:T33) -> 1400.1
C35: ЗТР | D35: чел-ч | E35: =Source!AQ28 -> 1.69 | G35: =Source!DI28 -> *1,1 | H35: =Source!AV29 -> 1.067 | I35: =Source!U28 -> 3.967106
C36: Всего по позиции: | H36: =I31+I32+I33+I34+0 -> 131.83 | J36: =K31+K32+K33+K34+0 -> 7193.49 | O36: =I31+I32+I33+I34+0 -> 131.83 | P36: =K31+K32+K33+K34+0 -> 7193.49
A38: 2 | B38: =Source!F30 -> КА 1 | C38: ОБОРУДОВАНИЕ:_x000D_ Металлодетектор арочный Паутина-Н2-1 33 055,69 = [291 500 / 1,2 / 7,66] + 3% Трансп + 1,2% Заг.скл | D38: =Source!H30 -> шт. | E38: =Source!I30 -> 2 | F38: =Source!AL30 -> 33055.69 | G38: =Source!DD30 | H38: =Source!AW31 -> 1 | I38: =Source!P30 -> 66111.38 | J38: =IF(Source!BC31<> 0, Source!BC31, 1) -> 7.66 | K38: =Source!P31 -> 506413.17 | Q38: =Source!X30 -> 0 | R38: =Source!X31 -> 0 | S38: =Source!Y30 -> 0 | T38: =Source!Y31 -> 0 | U38: =ROUND((175/100)*ROUND(Source!R30, 2), 2) -> 0 | V38: =ROUND((0/100)*ROUND(Source!R31, 2), 2) -> 0 | AC38: 5
C39: Всего по позиции: | H39: =I38+0 -> 66111.38 | J39: =K38+0 -> 506413.17 | O39: =I38+0 -> 66111.38 | P39: =K38+0 -> 506413.17
A41: 3 | B41: =Source!F32 -> КА 2 | C41: ОБОРУДОВАНИЕ:_x000D_ Ручной металлодетектор «СФИНКС ВМ-611 РД-2.0» 6 798,25 = [59 950 / 1,2 / 7,66] + 3% Трансп + 1,2% Заг.скл | D41: =Source!H32 -> шт. | E41: =Source!I32 -> 3 | F41: =Source!AL32 -> 6798.25 | G41: =Source!DD32 | H41: =Source!AW33 -> 1 | I41: =Source!P32 -> 20394.75 | J41: =IF(Source!BC33<> 0, Source!BC33, 1) -> 7.66 | K41: =Source!P33 -> 156223.79 | Q41: =Source!X32 -> 0 | R41: =Source!X33 -> 0 | S41: =Source!Y32 -> 0 | T41: =Source!Y33 -> 0 | U41: =ROUND((175/100)*ROUND(Source!R32, 2), 2) -> 0 | V41: =ROUND((0/100)*ROUND(Source!R33, 2), 2) -> 0 | AC41: 5
C42: Всего по позиции: | H42: =I41+0 -> 20394.75 | J42: =K41+0 -> 156223.79 | O42: =I41+0 -> 20394.75 | P42: =K41+0 -> 156223.79
A44: 4 | B44: =Source!F34 -> КА 3 | C44: ОБОРУДОВАНИЕ:_x000D_ Газоанализатор паров взрывчатых веществ «Кербер-Т» 249 476,94 = [2 200 000 / 1,2 / 7,66] + 3% Трансп + 1,2% Заг.скл | D44: =Source!H34 -> шт. | E44: =Source!I34 -> 1 | F44: =Source!AL34 -> 249476.94 | G44: =Source!DD34 | H44: =Source!AW35 -> 1 | I44: =Source!P34 -> 249476.94 | J44: =IF(Source!BC35<> 0, Source!BC35, 1) -> 7.66 | K44: =Source!P35 -> 1910993.4 | Q44: =Source!X34 -> 0 | R44: =Source!X35 -> 0 | S44: =Source!Y34 -> 0 | T44: =Source!Y35 -> 0 | U44: =ROUND((175/100)*ROUND(Source!R34, 2), 2) -> 0 | V44: =ROUND((0/100)*ROUND(Source!R35, 2), 2) -> 0 | AC44: 5
C45: Всего по позиции: | H45: =I44+0 -> 249476.94 | J45: =K44+0 -> 1910993.4 | O45: =I44+0 -> 249476.94 | P45: =K44+0 -> 1910993.4
A47: 5 | B47: =Source!F36 -> 13.3-9-180 | C47: ОБОРУДОВАНИЕ:_x000D_ Устройство для защиты от взрыва типа Фонтан-2 10У. Мобильное устройство для подавления не более 1000 г ТНТ, локализуемый объем до 15 дм3, выполнено в форме купола с двумя ручками, стенки и верх купола наполнены специальным диспенсером, поглощающим тепловую и ударную волну, габаритные размеры 610х610х365 мм | D47: =Source!H36 -> шт. | E47: =Source!I36 -> 1 | F47: =Source!AL36 -> 8188.38 | G47: =Source!DD36 | H47: =Source!AW37 -> 1 | I47: =Source!P36 -> 8188.38 | J47: =IF(Source!BC37<> 0, Source!BC37, 1) -> 10.36 | K47: =Source!P37 -> 84831.62 | Q47: =Source!X36 -> 0 | R47: =Source!X37 -> 0 | S47: =Source!Y36 -> 0 | T47: =Source!Y37 -> 0 | U47: =ROUND((175/100)*ROUND(Source!R36, 2), 2) -> 0 | V47: =ROUND((0/100)*ROUND(Source!R37, 2), 2) -> 0 | AC47: 5
C48: Всего по позиции: | H48: =I47+0 -> 8188.38 | J48: =K47+0 -> 84831.62 | O48: =I47+0 -> 8188.38 | P48: =K47+0 -> 84831.62
A50: 6 | B50: =Source!F38 -> 13.1-2-203 | C50: ОБОРУДОВАНИЕ:_x000D_ Устройство досмотровое (зеркало) для осмотра грузов, транспортных средств, неосвещенных и труднодоступных мест в помещениях. В составе: телескопическая штанга со встроенными светодиодами, с регулировкой длины от 600 до 1850 мм, набор зеркал различного размера и формы - 4 шт. Время непрерывной работы светодиодов не менее 9 часов, диапазон рабочих температур от -20 до +50°С | D50: =Source!H38 -> КОМПЛЕКТ | E50: =Source!I38 -> 1 | F50: =Source!AL38 -> 866.44 | G50: =Source!DD38 | H50: =Source!AW39 -> 1 | I50: =Source!P38 -> 866.44 | J50: =IF(Source!BC39<> 0, Source!BC39, 1) -> 11.43 | K50: =Source!P39 -> 9903.41 | Q50: =Source!X38 -> 0 | R50: =Source!X39 -> 0 | S50: =Source!Y38 -> 0 | T50: =Source!Y39 -> 0 | U50: =ROUND((175/100)*ROUND(Source!R38, 2), 2) -> 0 | V50: =ROUND((0/100)*ROUND(Source!R39, 2), 2) -> 0 | AC50: 5
C51: Всего по позиции: | H51: =I50+0 -> 866.44 | J51: =K50+0 -> 9903.41 | O51: =I50+0 -> 866.44 | P51: =K50+0 -> 9903.41
...

Sheet Ведомость объемов работ
A1: =Source!B1 -> Smeta.RU (495) 974-1589
E3: "УТВЕРЖДАЮ"
D5: ___________________________
D7: ___________________________
D9: " ___ " ___________ 20 ___ г.
B12: =CONCATENATE("Ведомость объемов работ ", IF(Source!AN15<>"", Source!AN15," ")) -> Ведомость объемов работ
B13: =CONCATENATE(Source!F12, " ", Source!G12) -> Новый объект (ТСН-2001 (Мосгосэкспертиза)) 02-01-20 ПТА
A16: № п/п | B16: № в ЛСР | C16: Наименование работ и затрат | D16: Единица измерения | E16: Количество | F16: Ссылка на чертежи, спецификации | G16: Формула расчета, расчет объемов работ и расхода материалов | H16: Примечание
A17: 1 | B17: 2 | C17: 3 | D17: 4 | E17: 5 | F17: 6 | G17: 7 | H17: 8
A18: =CONCATENATE("Локальная смета: ", Source!G20) -> Локальная смета: Мероприятия по противодействию террористическим актам
A19: =CONCATENATE("Раздел: ", Source!G24) -> Раздел: Оборудование
A20: 1 | B20: =Source!E28 -> 1 | C20: =Source!G28 -> Монтаж стационарного металлодетектора арочного типа | D20: 1 ШТ. | E20: =Source!I28 -> 2 | F20: =Source!U24 | G20: =Source!I28 -> 2
A21: 2 | B21: =Source!E30 -> 2 | C21: =Source!G30 -> Металлодетектор арочный Паутина-Н2-1 | D21: шт. | E21: =Source!I30 -> 2 | F21: =Source!U24 | G21: =Source!I30 -> 2
A22: 3 | B22: =Source!E32 -> 3 | C22: =Source!G32 -> Ручной металлодетектор «СФИНКС ВМ-611 РД-2.0» | D22: шт. | E22: =Source!I32 -> 3 | F22: =Source!U24 | G22: =Source!I32 -> 3
A23: 4 | B23: =Source!E34 -> 4 | C23: =Source!G34 -> Газоанализатор паров взрывчатых веществ «Кербер-Т» | D23: шт. | E23: =Source!I34 -> 1 | F23: =Source!U24 | G23: =Source!I34 -> 1
A24: 5 | B24: =Source!E36 -> 5 | C24: =Source!G36 -> Устройство для защиты от взрыва типа Фонтан-2 10У. Мобильное устройство для подавления не более 1000 г ТНТ, локализуемый объем до 15 дм3, выполнено в форме купола с двумя ручками, стенки и верх купола наполнены специальным диспенсером, поглощающим тепловую и ударную волну, габаритные размеры 610х610х365 мм | D24: шт. | E24: =Source!I36 -> 1 | F24: =Source!U24 | G24: =Source!I36 -> 1
A25: 6 | B25: =Source!E38 -> 6 | C25: =Source!G38 -> Устройство досмотровое (зеркало) для осмотра грузов, транспортных средств, неосвещенных и труднодоступных мест в помещениях. В составе: телескопическая штанга со встроенными светодиодами, с регулировкой длины от 600 до 1850 мм, набор зеркал различного размера и формы - 4 шт. Время непрерывной работы светодиодов не менее 9 часов, диапазон рабочих температур от -20 до +50°С | D25: КОМПЛЕКТ | E25: =Source!I38 -> 1 | F25: =Source!U24 | G25: =Source!I38 -> 1
A26: 7 | B26: =Source!E40 -> 7 | C26: =Source!G40 -> Установка штучных изделий столов, шкафов под мойки, холодильных шкафов и других | D26: 100 изделий | E26: =Source!I40 -> 0.04 | F26: =Source!U24 | G26: ="=4/"&"100" -> =4/100
A27: 8 | B27: =Source!E42 -> 8 | C27: =Source!G42 -> Стол досмотровый СД-950 (500х400х900) | D27: шт. | E27: =Source!I42 -> 4 | F27: =Source!U24 | G27: =Source!I42 -> 4
A28: 9 | B28: =Source!E44 -> 9 | C28: =Source!G44 -> Установка металлических ограждений без поручня | D28: 100 м ограждений | E28: =Source!I44 -> 0.02 | F28: =Source!U24 | G28: ="=2/"&"100" -> =2/100
A29: 9.1 | B29: =Source!E46 -> 9,1 | C29: =Source!G46 -> Ограждение полуростовое BH02 PERCo | D29: м.п. | E29: =Source!I46 -> 2 | F29: =Source!U24
A30: 9.2 | B30: =Source!E48 -> 9,2 | C30: =Source!G48 -> Калитка одностворчатая PERCo | D30: шт. | E30: =Source!I48 -> 2 | F30: =Source!U24
C33: Главный инженер проекта _________________ | D33: =IF(Source!X12<>"", Source!X12," ")
C35: Составил _________________ | D35: =IF(Source!AB12<>"", Source!AB12," ") -> Кузнецова Е.А.

Sheet Source
A1: 0 | B1: Smeta.RU (495) 974-1589 | D1: _PS_ | F1: 0 | G1: 0 | H1: 0 | I1: Smeta.RU | K1: 1 | L1: 74402 | M1: 10 | N1: 12 | O1: 0 | P1: 0 | Q1: 3
A4: 1 | B4: 1 | C4: -1 | G4: Капитальный ремонт здания Государственного бюджетного общеобразовательного учреждения города Москвы "Школа № 236" по адресу: г. Москва ул. Клязьминская, д. 7 к. 4. 1 этап | EC4: 0
A12: 1 | B12: 150 | C12: 0 | D12: =ROW(A111) -> 111 | E12: 0 | F12: Новый объект (ТСН-2001 (Мосгосэкспертиза)) | G12: 02-01-20 ПТА | I12: 0 | K12: 0 | L12: 0 | M12: 4098 | O12: 0 | P12: 0 | Q12: 0 | R12: 0 | S12: 0 | T12: 1 | V12: 0 | AB12: Кузнецова Е.А. | BB12: 0 | BH12: Сметные нормы списания | BI12: Коды ОКП для ТСН-2001 МГЭ Дополнение 80 | BJ12: 1 | BK12: 1 | BL12: 0 | BM12: 0 | BN12: 1 | BO12: 0 | BP12: 6 | BQ12: 2 | BR12: 1 | BS12: 1 | BT12: 0 | BU12: 0 | BV12: 1 | BW12: 0 | BX12: 0 | BZ12: Типовой расчет для ТСН-2001 МГЭ, Дополнение 80, строительство | CA12: Территориальные сметные нормативы для Москвы ТСН-2001 (МГЭ), дополнение 80 | CB12: Территориальные сметные нормативы для Москвы ТСН-2001 (МГЭ), дополнение 80 | CC12: Территориальные сметные нормативы для Москвы ТСН-2001 (МГЭ), дополнение 80 | CD12: Территориальные сметные нормативы для Москвы ТСН-2001 (МГЭ), дополнение 80 | CE12: Поправки для ТСН-2001 от 03.10.2025 г. доп.79 | CF12: 0 | CG12: 0 | CH12: 327688 | CK12: 80 | CQ12: Территориальные сметные нормативы для Москвы (ТСН-2001) | CR12: ТЕР | CS12: 41660 | CT12: 1 | CU12: 80 | CY12: 0 | EC12: 0
A15: 15 | B15: 1
A18: 52 | B18: =B111 -> 150 | C18: =C111 -> 1 | D18: =D111 -> 12 | E18: =E111 -> 0 | F18: =F111 -> Новый объект (ТСН-2001 (Мосгосэкспертиза)) | G18: =G111 -> 02-01-20 ПТА | O18: =O111 -> 376019.07 | P18: =P111 -> 375907.12 | Q18: =Q111 -> 12 | R18: =R111 -> 1.6 | S18: =S111 -> 99.95 | T18: =T111 -> 0 | U18: =U111 -> 8.0418206 | V18: =V111 -> 0 | ... GX18: =GX111 -> 0
A20: 3 | B20: 1 | D20: =ROW(A81) -> 81 | F20: 02-01-20 | G20: Мероприятия по противодействию террористическим актам | I20: 0 | J20: 2024-00272-01-0-ПТА | K20: -1 | L20: 02-01-20 | S20: 0 | T20: 0 | V20: 2 | BX20: 0 | CF20: 0 | CG20: 0
A22: 52 | B22: =B81 -> 1 | C22: =C81 -> 3 | D22: =D81 -> 20 | E22: =E81 -> 0 | F22: =F81 -> 02-01-20 | G22: =G81 -> Мероприятия по противодействию террористическим актам | O22: =O81 -> 376019.07 | P22: =P81 -> 375907.12 | Q22: =Q81 -> 12 | R22: =R81 -> 1.6 | S22: =S81 -> 99.95 | T22: =T81 -> 0 | U22: =U81 -> 8.0418206 | V22: =V81 -> 0 | ... GX22: =GX81 -> 0
A24: 4 | B24: 1 | D24: =ROW(A51) -> 51 | F24: Новый раздел | G24: Оборудование | I24: 0 | K24: 0 | S24: 0 | T24: 0 | V24: 2 | BX24: 0 | CJ24: 0
A26: 52 | B26: =B51 -> 1 | C26: =C51 -> 4 | D26: =D51 -> 24 | E26: =E51 -> 0 | F26: =F51 -> Новый раздел | G26: =G51 -> Оборудование | O26: =O51 -> 376019.07 | P26: =P51 -> 375907.12 | Q26: =Q51 -> 12 | R26: =R51 -> 1.6 | S26: =S51 -> 99.95 | T26: =T51 -> 0 | U26: =U51 -> 8.0418206 | V26: =V51 -> 0 | ... GX26: =GX51 -> 0
A28: 17 | B28: 1 | C28: =ROW(SmtRes!A3) -> 3 | D28: =ROW(EtalonRes!A4) -> 4 | E28: 1 | F28: 4.10-161-1 | G28: Монтаж стационарного металлодетектора арочного типа | H28: 1 ШТ. | I28: =ROUND(ROUND(2,4),9) -> 2 | J28: 0 | K28: =ROUND(ROUND(2,4),9) -> 2 | O28: =ROUND(CP28,2) -> 56.55 | P28: =ROUND((ROUND((AC28*AW28*I28),2)*BC28),2) -> 0 | Q28: =(ROUND((ROUND((((ET28*1.1))*AV28*I28),2)*BB28),2)+ROUND((ROUND(((AE28-((EU28*1.1)))*AV28*I28),2)*BS28),2)) -> 1.2 | R28: =ROUND((ROUND((AE28*AV28*I28),2)*BS28),2) -> 0 | S28: =ROUND((ROUND((AF28*AV28*I28),2)*BA28),2) -> 55.35 | T28: =ROUND(CU28*I28,2) -> 0 | U28: =CV28*I28 -> 3.967106 | V28: =CW28*I28 -> 0 | W28: =ROUND(CX28*I28,2) -> 0 | X28: =ROUND(CY28,2) -> 49.82 | Y28: =ROUND(CZ28,2) -> 25.46 | AA28: 59214062 | AB28: =ROUND((AC28+AD28+AF28),6) -> 26.499 | AC28: =ROUND(((ES28*1)),6) -> 0 | AD28: =ROUND(((((ET28*1.1))-((EU28*1.1)))+AE28),6) -> 0.561 | AE28: =ROUND(((EU28*1.1)),6) -> 0 | AF28: =ROUND(((EV28*1.1)),6) -> 25.938 | AG28: =ROUND((AP28),6) -> 0 | AH28: =((EW28*1.1)) -> 1.859 | AI28: =((EX28*1.1)) -> 0 | AJ28: =(AS28) -> 0 | AK28: 24.09 | AL28: 0 | AM28: 0.51 | AN28: 0 | AO28: 23.58 | AP28: 0 | AQ28: 1.69 | AR28: 0 | AS28: 0 | AT28: 90 | AU28: 46 | AV28: 1.067 | AW28: 1.028 | AZ28: 1 | BA28: 1 | BB28: 1 | BC28: 1 | BH28: 0 | BI28: 2 | BJ28: ТСН-2001.4 Доп. 68, Сб. 10, т. 161, поз. 1 | BM28: 68 | BN28: 58808062 | BO28: 4.10-161-1 | BP28: 1 | BQ28: 40 | BR28: 0 | BS28: 1 | BT28: 1 | BU28: 1 | BV28: 1 | BW28: 1 | BX28: 1 | BZ28: 90 | CA28: 46 | CE28: 30 | CF28: 0 | CG28: 0 | CM28: 0 | CN28: Поправка: Гл.12.Прил.8.п.8. 5_12.00.01.11.003 Наименование: При наличии усложненных условий производства работ (стесненность, сложность складирования и транспортной логистики, наличие в зоне производства работ действующего технологического оборудования или движения технологического транспорта и т.п.) для объектов, расположенных за пределами территории круговой магистральной системы улиц "Садовое кольцо" и за пределами Третьего транспортного кольца города Москвы пунктов "а" и "б", но в пределах Московской кольцевой автомобильной дороги | CO28: 0 | CP28: =(P28+Q28+S28) -> 56.55 | CQ28: =ROUND((ROUND((AC28*AW28*1),2)*BC28),2) -> 0 | CR28: =(ROUND((ROUND((((ET28*1.1))*AV28*1),2)*BB28),2)+ROUND((ROUND(((AE28-((EU28*1.1)))*AV28*1),2)*BS28),2)) -> 0.6 | CS28: =ROUND((ROUND((AE28*AV28*1),2)*BS28),2) -> 0 | CT28: =ROUND((ROUND((AF28*AV28*1),2)*BA28),2) -> 27.68 | CU28: =AG28 -> 0 | CV28: =(AH28*AV28) -> 1.983553 | CW28: =AI28 -> 0 | CX28: =AJ28 -> 0 | CY28: =(((S28+R28)*AT28)/100) -> 49.815 | CZ28: =(((S28+R28)*AU28)/100) -> 25.461 | DB28: 1 | DD28: *1 | DE28: *1,1 | DF28: *1,1 | DG28: *1,1 | DI28: *1,1 | DJ28: *1,1 | DN28: 0 | DO28: 0 | DP28: 1 | DQ28: 1 | DU28: 1013 | DV28: 1 ШТ. | DW28: 1 ШТ. | DX28: 1 | EE28: 58808178 | EF28: 40 | EG28: Монтаж оборудования | EH28: 0 | EJ28: 2 | EK28: 68 | EL28: ТСН-2001.4-10. Прокладка и монтаж сетей связи | EM28: ТСН-2001.4-10-1 | EO28: Поправка: Гл.12.Прил.8.п.8. 5_12.00.01.11.003 | EQ28: 0 | ER28: 24.09 | ES28: 0 | ET28: 0.51 | EU28: 0 | EV28: 23.58 | EW28: 1.69 | EX28: 0 | EY28: 0 | FQ28: 0 | FR28: 0 | FS28: 0 | FX28: 90 | FY28: 46 | GD28: 1 | GF28: 363374648 | GG28: 2 | GH28: 1 | GI28: 2 | GJ28: 0 | GK28: 0 | GL28: =ROUND(IF(AND(BH28=3,BI28=3,FS28<>0),P28,0),2) -> 0 | GM28: =ROUND(O28+X28+Y28,2)+GX28 -> 131.83 | GN28: =IF(OR(BI28=0,BI28=1),GM28-GX28,0) -> 0 | GO28: =IF(BI28=2,GM28-GX28,0) -> 131.83 | GP28: =IF(BI28=4,GM28-GX28,0) -> 0 | GR28: 0 | GS28: 3 | GT28: 0 | GV28: =ROUND((GT28),6) -> 0 | GW28: 1 | GX28: =ROUND(HC28*I28,2) -> 0 | HA28: 0 | HB28: 0 | HC28: =GV28*GW28 -> 0 | HS28: 0 | IK28: 0
A29: 17 | B29: 1 | C29: =ROW(SmtRes!A6) -> 6 | D29: =ROW(EtalonRes!A8) -> 8 | E29: 1 | F29: 4.10-161-1 | G29: Монтаж стационарного металлодетектора арочного типа | H29: 1 ШТ. | I29: =ROUND(ROUND(2,4),9) -> 2 | J29: 0 | K29: =ROUND(ROUND(2,4),9) -> 2 | O29: =ROUND(CP29,2) -> 3054.06 | P29: =ROUND((ROUND((AC29*AW29*I29),2)*BC29),2) -> 0 | Q29: =(ROUND((ROUND((((ET29*1.1))*AV29*I29),2)*BB29),2)+ROUND((ROUND(((AE29-((EU29*1.1)))*AV29*I29),2)*BS29),2)) -> 10.36 | R29: =ROUND((ROUND((AE29*AV29*I29),2)*BS29),2) -> 0 | S29: =ROUND((ROUND((AF29*AV29*I29),2)*BA29),2) -> 3043.7 | T29: =ROUND(CU29*I29,2) -> 0 | U29: =CV29*I29 -> 3.967106 | V29: =CW29*I29 -> 0 | W29: =ROUND(CX29*I29,2) -> 0 | X29: =ROUND(CY29,2) -> 2739.33 | Y29: =ROUND(CZ29,2) -> 1400.1 | AA29: 59214059 | AB29: =ROUND((AC29+AD29+AF29),6) -> 26.499 | AC29: =ROUND(((ES29*1)),6) -> 0 | AD29: =ROUND(((((ET29*1.1))-((EU29*1.1)))+AE29),6) -> 0.561 | AE29: =ROUND(((EU29*1.1)),6) -> 0 | AF29: =ROUND(((EV29*1.1)),6) -> 25.938 | AG29: =ROUND((AP29),6) -> 0 | AH29: =((EW29*1.1)) -> 1.859 | AI29: =((EX29*1.1)) -> 0 | AJ29: =(AS29) -> 0 | AK29: 24.09 | AL29: 0 | AM29: 0.51 | AN29: 0 | AO29: 23.58 | AP29: 0 | AQ29: 1.69 | AR29: 0 | AS29: 0 | AT29: 90 | AU29: 46 | AV29: 1.067 | AW29: 1.028 | AZ29: 1 | BA29: 54.99 | BB29: 8.63 | BC29: 1 | BH29: 0 | BI29: 2 | BJ29: ТСН-2001.4 Доп. 68, Сб. 10, т. 161, поз. 1 | BM29: 68 | BN29: 58808062 | BO29: 4.10-161-1 | BP29: 1 | BQ29: 40 | BR29: 0 | BS29: 54.99 | BT29: 1 | BU29: 1 | BV29: 1 | BW29: 1 | BX29: 1 | BZ29: 90 | CA29: 46 | CE29: 30 | CF29: 0 | CG29: 0 | CM29: 0 | CN29: Поправка: Гл.12.Прил.8.п.8. 5_12.00.01.11.003 Наименование: При наличии усложненных условий производства работ (стесненность, сложность складирования и транспортной логистики, наличие в зоне производства работ действующего технологического оборудования или движения технологического транспорта и т.п.) для объектов, расположенных за пределами территории круговой магистральной системы улиц "Садовое кольцо" и за пределами Третьего транспортного кольца города Москвы пунктов "а" и "б", но в пределах Московской кольцевой автомобильной дороги | CO29: 0 | CP29: =(P29+Q29+S29) -> 3054.06 | CQ29: =ROUND((ROUND((AC29*AW29*1),2)*BC29),2) -> 0 | CR29: =(ROUND((ROUND((((ET29*1.1))*AV29*1),2)*BB29),2)+ROUND((ROUND(((AE29-((EU29*1.1)))*AV29*1),2)*BS29),2)) -> 5.18 | CS29: =ROUND((ROUND((AE29*AV29*1),2)*BS29),2) -> 0 | CT29: =ROUND((ROUND((AF29*AV29*1),2)*BA29),2) -> 1522.12 | CU29: =AG29 -> 0 | CV29: =(AH29*AV29) -> 1.983553 | CW29: =AI29 -> 0 | CX29: =AJ29 -> 0 | CY29: =(((S29+R29)*AT29)/100) -> 2739.33 | CZ29: =(((S29+R29)*AU29)/100) -> 1400.102 | DB29: 2 | DD29: *1 | DE29: *1,1 | DF29: *1,1 | DG29: *1,1 | DI29: *1,1 | DJ29: *1,1 | DN29: 0 | DO29: 0 | DP29: 1 | DQ29: 1 | DU29: 1013 | DV29: 1 ШТ. | DW29: 1 ШТ. | DX29: 1 | EE29: 58808178 | EF29: 40 | EG29: Монтаж оборудования | EH29: 0 | EJ29: 2 | EK29: 68 | EL29: ТСН-2001.4-10. Прокладка и монтаж сетей связи | EM29: ТСН-2001.4-10-1 | EO29: Поправка: Гл.12.Прил.8.п.8. 5_12.00.01.11.003 | EQ29: 0 | ER29: 24.09 | ES29: 0 | ET29: 0.51 | EU29: 0 | EV29: 23.58 | EW29: 1.69 | EX29: 0 | EY29: 0 | FQ29: 0 | FR29: 0 | FS29: 0 | FX29: 90 | FY29: 46 | GD29: 1 | GF29: 363374648 | GG29: 2 | GH29: 1 | GI29: 2 | GJ29: 0 | GK29: 0 | GL29: =ROUND(IF(AND(BH29=3,BI29=3,FS29<>0),P29,0),2) -> 0 | GM29: =ROUND(O29+X29+Y29,2)+GX29 -> 7193.49 | GN29: =IF(OR(BI29=0,BI29=1),GM29-GX29,0) -> 0 | GO29: =IF(BI29=2,GM29-GX29,0) -> 7193.49 | GP29: =IF(BI29=4,GM29-GX29,0) -> 0 | GR29: 0 | GS29: 3 | GT29: 0 | GV29: =ROUND((GT29),6) -> 0 | GW29: 1 | GX29: =ROUND(HC29*I29,2) -> 0 | HA29: 0 | HB29: 0 | HC29: =GV29*GW29 -> 0 | HS29: 0 | IK29: 0
A30: 17 | B30: 1 | E30: 2 | F30: КА 1 | G30: Металлодетектор арочный Паутина-Н2-1 | H30: шт. | I30: =ROUND(ROUND(2,4),9) -> 2 | J30: 0 | K30: =ROUND(ROUND(2,4),9) -> 2 | O30: =ROUND(CP30,2) -> 66111.38 | P30: =ROUND((ROUND((AC30*I30),2)*BC30),2) -> 66111.38 | Q30: =(ROUND((ROUND(((ET30)*AV30*I30),2)*BB30),2)+ROUND((ROUND(((AE30-(EU30))*AV30*I30),2)*BS30),2)) -> 0 | R30: =ROUND((ROUND((AE30*AV30*I30),2)*BS30),2) -> 0 | S30: =ROUND((ROUND((AF30*AV30*I30),2)*BA30),2) -> 0 | T30: =ROUND(CU30*I30,2) -> 0 | U30: =CV30*I30 -> 0 | V30: =CW30*I30 -> 0 | W30: =ROUND(CX30*I30,2) -> 0 | X30: =ROUND(CY30,2) -> 0 | Y30: =ROUND(CZ30,2) -> 0 | AA30: 59214062 | AB30: =ROUND((AC30+AD30+AF30),6) -> 33055.69 | AC30: =ROUND((ES30),6) -> 33055.69 | AD30: =ROUND((((ET30)-(EU30))+AE30),6) -> 0 | AE30: =ROUND((EU30),6) -> 0 | AF30: =ROUND((EV30),6) -> 0 | AG30: =ROUND((AP30),6) -> 0 | AH30: =(EW30) -> 0 | AI30: =(EX30) -> 0 | AJ30: =(AS30) -> 0 | AK30: 33055.69 | AL30: 33055.69 | AM30: 0 | AN30: 0 | AO30: 0 | AP30: 0 | AQ30: 0 | AR30: 0 | AS30: 0 | AT30: 0 | AU30: 0 | AV30: 1 | AW30: 1 | AZ30: 1 | BA30: 1 | BB30: 1 | BC30: 1 | BH30: 3 | BI30: 3 | BM30: 746 | BN30: 0 | BP30: 0 | BQ30: 130 | BR30: 0 | BS30: 1 | BT30: 1 | BU30: 1 | BV30: 1 | BW30: 1 | BX30: 1 | BZ30: 0 | CA30: 0 | CE30: 30 | CF30: 0 | CG30: 0 | CM30: 0 | CO30: 0 | CP30: =(P30+Q30+S30) -> 66111.38 | CQ30: =ROUND((ROUND((AC30*1),2)*BC30),2) -> 33055.69 | CR30: =(ROUND((ROUND(((ET30)*AV30*1),2)*BB30),2)+ROUND((ROUND(((AE30-(EU30))*AV30*1),2)*BS30),2)) -> 0 | CS30: =ROUND((ROUND((AE30*AV30*1),2)*BS30),2) -> 0 | CT30: =ROUND((ROUND((AF30*AV30*1),2)*BA30),2) -> 0 | CU30: =AG30 -> 0 | CV30: =(AH30*AV30) -> 0 | CW30: =AI30 -> 0 | CX30: =AJ30 -> 0 | CY30: =(((S30+R30)*AT30)/100) -> 0 | CZ30: =(((S30+R30)*AU30)/100) -> 0 | DN30: 0 | DO30: 0 | DP30: 1 | DQ30: 1 | DU30: 1010 | DV30: шт. | DW30: шт. | DX30: 1 | EE30: 58808284 | EF30: 130 | EG30: Сметная стоимость оборудования | EH30: 0 | EJ30: 3 | EK30: 746 | EL30: ТСН-2001.13. Сметная стоимость оборудования | EM30: ТСН-2001.13 | EQ30: 0 | ER30: 0 | ES30: 33055.69 | ET30: 0 | EU30: 0 | EV30: 0 | EW30: 0 | EX30: 0 | EY30: 0 | FQ30: 0 | FR30: =P30 -> 66111.38 | FS30: 0 | FX30: 0 | FY30: 0 | GA30: [291 500 / 1,2 / 7,66] + 3% Трансп + 1,2% Заг.скл | GD30: 1 | GF30: -1911462648 | GG30: 2 | GH30: 4 | GI30: 0 | GJ30: 0 | GK30: 0 | GL30: =ROUND(IF(AND(BH30=3,BI30=3,FS30<>0),P30,0),2) -> 0 | GM30: =ROUND(O30+X30+Y30,2)+GX30 -> 66111.38 | GN30: =IF(OR(BI30=0,BI30=1),GM30-GX30,0) -> 0 | GO30: =IF(BI30=2,GM30-GX30,0) -> 0 | GP30: =IF(BI30=4,GM30-GX30,0) -> 0 | GR30: 2 | GS30: 2 | GT30: 0 | GV30: =ROUND((GT30),6) -> 0 | GW30: 1 | GX30: =ROUND(HC30*I30,2) -> 0 | HA30: 0 | HB30: 0 | HC30: =GV30*GW30 -> 0 | HE30: 3 | HF30: 1,2 | HS30: 0 | IK30: 0
A31: 17 | B31: 1 | E31: 2 | F31: КА 1 | G31: Металлодетектор арочный Паутина-Н2-1 | H31: шт. | I31: =ROUND(ROUND(2,4),9) -> 2 | J31: 0 | K31: =ROUND(ROUND(2,4),9) -> 2 | O31: =ROUND(CP31,2) -> 506413.17 | P31: =ROUND((ROUND((AC31*I31),2)*BC31),2) -> 506413.17 | Q31: =(ROUND((ROUND(((ET31)*AV31*I31),2)*BB31),2)+ROUND((ROUND(((AE31-(EU31))*AV31*I31),2)*BS31),2)) -> 0 | R31: =ROUND((ROUND((AE31*AV31*I31),2)*BS31),2) -> 0 | S31: =ROUND((ROUND((AF31*AV31*I31),2)*BA31),2) -> 0 | T31: =ROUND(CU31*I31,2) -> 0 | U31: =CV31*I31 -> 0 | V31: =CW31*I31 -> 0 | W31: =ROUND(CX31*I31,2) -> 0 | X31: =ROUND(CY31,2) -> 0 | Y31: =ROUND(CZ31,2) -> 0 | AA31: 59214059 | AB31: =ROUND((AC31+AD31+AF31),6) -> 33055.69 | AC31: =ROUND((ES31),6) -> 33055.69 | AD31: =ROUND((((ET31)-(EU31))+AE31),6) -> 0 | AE31: =ROUND((EU31),6) -> 0 | AF31: =ROUND((EV31),6) -> 0 | AG31: =ROUND((AP31),6) -> 0 | AH31: =(EW31) -> 0 | AI31: =(EX31) -> 0 | AJ31: =(AS31) -> 0 | AK31: 33055.69 | AL31: 33055.69 | AM31: 0 | AN31: 0 | AO31: 0 | AP31: 0 | AQ31: 0 | AR31: 0 | AS31: 0 | AT31: 0 | AU31: 0 | AV31: 1 | AW31: 1 | AZ31: 1 | BA31: 1 | BB31: 1 | BC31: 7.66 | BH31: 3 | BI31: 3 | BM31: 746 | BN31: 0 | BP31: 0 | BQ31: 130 | BR31: 0 | BS31: 1 | BT31: 1 | BU31: 1 | BV31: 1 | BW31: 1 | BX31: 1 | BZ31: 0 | CA31: 0 | CE31: 30 | CF31: 0 | CG31: 0 | CM31: 0 | CO31: 0 | CP31: =(P31+Q31+S31) -> 506413.17 | CQ31: =ROUND((ROUND((AC31*1),2)*BC31),2) -> 253206.59 | CR31: =(ROUND((ROUND(((ET31)*AV31*1),2)*BB31),2)+ROUND((ROUND(((AE31-(EU31))*AV31*1),2)*BS31),2)) -> 0 | CS31: =ROUND((ROUND((AE31*AV31*1),2)*BS31),2) -> 0 | CT31: =ROUND((ROUND((AF31*AV31*1),2)*BA31),2) -> 0 | CU31: =AG31 -> 0 | CV31: =(AH31*AV31) -> 0 | CW31: =AI31 -> 0 | CX31: =AJ31 -> 0 | CY31: =(((S31+R31)*AT31)/100) -> 0 | CZ31: =(((S31+R31)*AU31)/100) -> 0 | DN31: 0 | DO31: 0 | DP31: 1 | DQ31: 1 | DU31: 1010 | DV31: шт. | DW31: шт. | DX31: 1 | EE31: 58808284 | EF31: 130 | EG31: Сметная стоимость оборудования | EH31: 0 | EJ31: 3 | EK31: 746 | EL31: ТСН-2001.13. Сметная стоимость оборудования | EM31: ТСН-2001.13 | EQ31: 0 | ER31: 0 | ES31: 33055.69 | ET31: 0 | EU31: 0 | EV31: 0 | EW31: 0 | EX31: 0 | EY31: 0 | EZ31: 5 | FC31: 1 | FD31: 18 | FF31: 291500 | FQ31: 0 | FR31: =P31 -> 506413.17 | FS31: 0 | FX31: 0 | FY31: 0 | GA31: [291 500 / 1,2 / 7,66] + 3% Трансп + 1,2% Заг.скл | GD31: 1 | GF31: -1911462648 | GG31: 2 | GH31: 2 | GI31: 5 | GJ31: 0 | GK31: 0 | GL31: =ROUND(IF(AND(BH31=3,BI31=3,FS31<>0),P31,0),2) -> 0 | GM31: =ROUND(O31+X31+Y31,2)+GX31 -> 506413.17 | GN31: =IF(OR(BI31=0,BI31=1),GM31-GX31,0) -> 0 | GO31: =IF(BI31=2,GM31-GX31,0) -> 0 | GP31: =IF(BI31=4,GM31-GX31,0) -> 0 | GR31: 2 | GS31: 1 | GT31: 0 | GV31: =ROUND((GT31),6) -> 0 | GW31: 1 | GX31: =ROUND(HC31*I31,2) -> 0 | HA31: 0 | HB31: 0 | HC31: =GV31*GW31 -> 0 | HE31: 3 | HF31: 1,2 | HS31: 0 | IK31: 0
A32: 17 | B32: 1 | E32: 3 | F32: КА 2 | G32: Ручной металлодетектор «СФИНКС ВМ-611 РД-2.0» | H32: шт. | I32: =ROUND(ROUND(3,4),9) -> 3 | J32: 0 | K32: =ROUND(ROUND(3,4),9) -> 3 | O32: =ROUND(CP32,2) -> 20394.75 | P32: =ROUND((ROUND((AC32*I32),2)*BC32),2) -> 20394.75 | Q32: =(ROUND((ROUND(((ET32)*AV32*I32),2)*BB32),2)+ROUND((ROUND(((AE32-(EU32))*AV32*I32),2)*BS32),2)) -> 0 | R32: =ROUND((ROUND((AE32*AV32*I32),2)*BS32),2) -> 0 | S32: =ROUND((ROUND((AF32*AV32*I32),2)*BA32),2) -> 0 | T32: =ROUND(CU32*I32,2) -> 0 | U32: =CV32*I32 -> 0 | V32: =CW32*I32 -> 0 | W32: =ROUND(CX32*I32,2) -> 0 | X32: =ROUND(CY32,2) -> 0 | Y32: =ROUND(CZ32,2) -> 0 | AA32: 59214062 | AB32: =ROUND((AC32+AD32+AF32),6) -> 6798.25 | AC32: =ROUND((ES32),6) -> 6798.25 | AD32: =ROUND((((ET32)-(EU32))+AE32),6) -> 0 | AE32: =ROUND((EU32),6) -> 0 | AF32: =ROUND((EV32),6) -> 0 | AG32: =ROUND((AP32),6) -> 0 | AH32: =(EW32) -> 0 | AI32: =(EX32) -> 0 | AJ32: =(AS32) -> 0 | AK32: 6798.25 | AL32: 6798.25 | AM32: 0 | AN32: 0 | AO32: 0 | AP32: 0 | AQ32: 0 | AR32: 0 | AS32: 0 | AT32: 0 | AU32: 0 | AV32: 1 | AW32: 1 | AZ32: 1 | BA32: 1 | BB32: 1 | BC32: 1 | BH32: 3 | BI32: 3 | BM32: 746 | BN32: 0 | BP32: 0 | BQ32: 130 | BR32: 0 | BS32: 1 | BT32: 1 | BU32: 1 | BV32: 1 | BW32: 1 | BX32: 1 | BZ32: 0 | CA32: 0 | CE32: 30 | CF32: 0 | CG32: 0 | CM32: 0 | CO32: 0 | CP32: =(P32+Q32+S32) -> 20394.75 | CQ32: =ROUND((ROUND((AC32*1),2)*BC32),2) -> 6798.25 | CR32: =(ROUND((ROUND(((ET32)*AV32*1),2)*BB32),2)+ROUND((ROUND(((AE32-(EU32))*AV32*1),2)*BS32),2)) -> 0 | CS32: =ROUND((ROUND((AE32*AV32*1),2)*BS32),2) -> 0 | CT32: =ROUND((ROUND((AF32*AV32*1),2)*BA32),2) -> 0 | CU32: =AG32 -> 0 | CV32: =(AH32*AV32) -> 0 | CW32: =AI32 -> 0 | CX32: =AJ32 -> 0 | CY32: =(((S32+R32)*AT32)/100) -> 0 | CZ32: =(((S32+R32)*AU32)/100) -> 0 | DN32: 0 | DO32: 0 | DP32: 1 | DQ32: 1 | DU32: 1010 | DV32: шт. | DW32: шт. | DX32: 1 | EE32: 58808284 | EF32: 130 | EG32: Сметная стоимость оборудования | EH32: 0 | EJ32: 3 | EK32: 746 | EL32: ТСН-2001.13. Сметная стоимость оборудования | EM32: ТСН-2001.13 | EQ32: 0 | ER32: 0 | ES32: 6798.25 | ET32: 0 | EU32: 0 | EV32: 0 | EW32: 0 | EX32: 0 | EY32: 0 | FQ32: 0 | FR32: =P32 -> 20394.75 | FS32: 0 | FX32: 0 | FY32: 0 | GA32: [59 950 / 1,2 / 7,66] + 3% Трансп + 1,2% Заг.скл | GD32: 1 | GF32: -338370289 | GG32: 2 | GH32: 4 | GI32: 0 | GJ32: 0 | GK32: 0 | GL32: =ROUND(IF(AND(BH32=3,BI32=3,FS32<>0),P32,0),2) -> 0 | GM32: =ROUND(O32+X32+Y32,2)+GX32 -> 20394.75 | GN32: =IF(OR(BI32=0,BI32=1),GM32-GX32,0) -> 0 | GO32: =IF(BI32=2,GM32-GX32,0) -> 0 | GP32: =IF(BI32=4,GM32-GX32,0) -> 0 | GR32: 2 | GS32: 2 | GT32: 0 | GV32: =ROUND((GT32),6) -> 0 | GW32: 1 | GX32: =ROUND(HC32*I32,2) -> 0 | HA32: 0 | HB32: 0 | HC32: =GV32*GW32 -> 0 | HE32: 3 | HF32: 1,2 | HS32: 0 | IK32: 0
A33: 17 | B33: 1 | E33: 3 | F33: КА 2 | G33: Ручной металлодетектор «СФИНКС ВМ-611 РД-2.0» | H33: шт. | I33: =ROUND(ROUND(3,4),9) -> 3 | J33: 0 | K33: =ROUND(ROUND(3,4),9) -> 3 | O33: =ROUND(CP33,2) -> 156223.79 | P33: =ROUND((ROUND((AC33*I33),2)*BC33),2) -> 156223.79 | Q33: =(ROUND((ROUND(((ET33)*AV33*I33),2)*BB33),2)+ROUND((ROUND(((AE33-(EU33))*AV33*I33),2)*BS33),2)) -> 0 | R33: =ROUND((ROUND((AE33*AV33*I33),2)*BS33),2) -> 0 | S33: =ROUND((ROUND((AF33*AV33*I33),2)*BA33),2) -> 0 | T33: =ROUND(CU33*I33,2) -> 0 | U33: =CV33*I33 -> 0 | V33: =CW33*I33 -> 0 | W33: =ROUND(CX33*I33,2) -> 0 | X33: =ROUND(CY33,2) -> 0 | Y33: =ROUND(CZ33,2) -> 0 | AA33: 59214059 | AB33: =ROUND((AC33+AD33+AF33),6) -> 6798.25 | AC33: =ROUND((ES33),6) -> 6798.25 | AD33: =ROUND((((ET33)-(EU33))+AE33),6) -> 0 | AE33: =ROUND((EU33),6) -> 0 | AF33: =ROUND((EV33),6) -> 0 | AG33: =ROUND((AP33),6) -> 0 | AH33: =(EW33) -> 0 | AI33: =(EX33) -> 0 | AJ33: =(AS33) -> 0 | AK33: 6798.25 | AL33: 6798.25 | AM33: 0 | AN33: 0 | AO33: 0 | AP33: 0 | AQ33: 0 | AR33: 0 | AS33: 0 | AT33: 0 | AU33: 0 | AV33: 1 | AW33: 1 | AZ33: 1 | BA33: 1 | BB33: 1 | BC33: 7.66 | BH33: 3 | BI33: 3 | BM33: 746 | BN33: 0 | BP33: 0 | BQ33: 130 | BR33: 0 | BS33: 1 | BT33: 1 | BU33: 1 | BV33: 1 | BW33: 1 | BX33: 1 | BZ33: 0 | CA33: 0 | CE33: 30 | CF33: 0 | CG33: 0 | CM33: 0 | CO33: 0 | CP33: =(P33+Q33+S33) -> 156223.79 | CQ33: =ROUND((ROUND((AC33*1),2)*BC33),2) -> 52074.6 | CR33: =(ROUND((ROUND(((ET33)*AV33*1),2)*BB33),2)+ROUND((ROUND(((AE33-(EU33))*AV33*1),2)*BS33),2)) -> 0 | CS33: =ROUND((ROUND((AE33*AV33*1),2)*BS33),2) -> 0 | CT33: =ROUND((ROUND((AF33*AV33*1),2)*BA33),2) -> 0 | CU33: =AG33 -> 0 | CV33: =(AH33*AV33) -> 0 | CW33: =AI33 -> 0 | CX33: =AJ33 -> 0 | CY33: =(((S33+R33)*AT33)/100) -> 0 | CZ33: =(((S33+R33)*AU33)/100) -> 0 | DN33: 0 | DO33: 0 | DP33: 1 | DQ33: 1 | DU33: 1010 | DV33: шт. | DW33: шт. | DX33: 1 | EE33: 58808284 | EF33: 130 | EG33: Сметная стоимость оборудования | EH33: 0 | EJ33: 3 | EK33: 746 | EL33: ТСН-2001.13. Сметная стоимость оборудования | EM33: ТСН-2001.13 | EQ33: 0 | ER33: 0 | ES33: 6798.25 | ET33: 0 | EU33: 0 | EV33: 0 | EW33: 0 | EX33: 0 | EY33: 0 | EZ33: 5 | FC33: 1 | FD33: 18 | FF33: 59950 | FQ33: 0 | FR33: =P33 -> 156223.79 | FS33: 0 | FX33: 0 | FY33: 0 | GA33: [59 950 / 1,2 / 7,66] + 3% Трансп + 1,2% Заг.скл | GD33: 1 | GF33: -338370289 | GG33: 2 | GH33: 2 | GI33: 5 | GJ33: 0 | GK33: 0 | GL33: =ROUND(IF(AND(BH33=3,BI33=3,FS33<>0),P33,0),2) -> 0 | GM33: =ROUND(O33+X33+Y33,2)+GX33 -> 156223.79 | GN33: =IF(OR(BI33=0,BI33=1),GM33-GX33,0) -> 0 | GO33: =IF(BI33=2,GM33-GX33,0) -> 0 | GP33: =IF(BI33=4,GM33-GX33,0) -> 0 | GR33: 2 | GS33: 1 | GT33: 0 | GV33: =ROUND((GT33),6) -> 0 | GW33: 1 | GX33: =ROUND(HC33*I33,2) -> 0 | HA33: 0 | HB33: 0 | HC33: =GV33*GW33 -> 0 | HE33: 3 | HF33: 1,2 | HS33: 0 | IK33: 0
A34: 17 | B34: 1 | E34: 4 | F34: КА 3 | G34: Газоанализатор паров взрывчатых веществ «Кербер-Т» | H34: шт. | I34: =ROUND(ROUND(1,4),9) -> 1 | J34: 0 | K34: =ROUND(ROUND(1,4),9) -> 1 | O34: =ROUND(CP34,2) -> 249476.94 | P34: =ROUND((ROUND((AC34*I34),2)*BC34),2) -> 249476.94 | Q34: =(ROUND((ROUND(((ET34)*AV34*I34),2)*BB34),2)+ROUND((ROUND(((AE34-(EU34))*AV34*I34),2)*BS34),2)) -> 0 | R34: =ROUND((ROUND((AE34*AV34*I34),2)*BS34),2) -> 0 | S34: =ROUND((ROUND((AF34*AV34*I34),2)*BA34),2) -> 0 | T34: =ROUND(CU34*I34,2) -> 0 | U34: =CV34*I34 -> 0 | V34: =CW34*I34 -> 0 | W34: =ROUND(CX34*I34,2) -> 0 | X34: =ROUND(CY34,2) -> 0 | Y34: =ROUND(CZ34,2) -> 0 | AA34: 59214062 | AB34: =ROUND((AC34+AD34+AF34),6) -> 249476.94 | AC34: =ROUND((ES34),6) -> 249476.94 | AD34: =ROUND((((ET34)-(EU34))+AE34),6) -> 0 | AE34: =ROUND((EU34),6) -> 0 | AF34: =ROUND((EV34),6) -> 0 | AG34: =ROUND((AP34),6) -> 0 | AH34: =(EW34) -> 0 | AI34: =(EX34) -> 0 | AJ34: =(AS34) -> 0 | AK34: 249476.94 | AL34: 249476.94 | AM34: 0 | AN34: 0 | AO34: 0 | AP34: 0 | AQ34: 0 | AR34: 0 | AS34: 0 | AT34: 0 | AU34: 0 | AV34: 1 | AW34: 1 | AZ34: 1 | BA34: 1 | BB34: 1 | BC34: 1 | BH34: 3 | BI34: 3 | BM34: 746 | BN34: 0 | BP34: 0 | BQ34: 130 | BR34: 0 | BS34: 1 | BT34: 1 | BU34: 1 | BV34: 1 | BW34: 1 | BX34: 1 | BZ34: 0 | CA34: 0 | CE34: 30 | CF34: 0 | CG34: 0 | CM34: 0 | CO34: 0 | CP34: =(P34+Q34+S34) -> 249476.94 | CQ34: =ROUND((ROUND((AC34*1),2)*BC34),2) -> 249476.94 | CR34: =(ROUND((ROUND(((ET34)*AV34*1),2)*BB34),2)+ROUND((ROUND(((AE34-(EU34))*AV34*1),2)*BS34),2)) -> 0 | CS34: =ROUND((ROUND((AE34*AV34*1),2)*BS34),2) -> 0 | CT34: =ROUND((ROUND((AF34*AV34*1),2)*BA34),2) -> 0 | CU34: =AG34 -> 0 | CV34: =(AH34*AV34) -> 0 | CW34: =AI34 -> 0 | CX34: =AJ34 -> 0 | CY34: =(((S34+R34)*AT34)/100) -> 0 | CZ34: =(((S34+R34)*AU34)/100) -> 0 | DN34: 0 | DO34: 0 | DP34: 1 | DQ34: 1 | DU34: 1010 | DV34: шт. | DW34: шт. | DX34: 1 | EE34: 58808284 | EF34: 130 | EG34: Сметная стоимость оборудования | EH34: 0 | EJ34: 3 | EK34: 746 | EL34: ТСН-2001.13. Сметная стоимость оборудования | EM34: ТСН-2001.13 | EQ34: 0 | ER34: 0 | ES34: 249476.94 | ET34: 0 | EU34: 0 | EV34: 0 | EW34: 0 | EX34: 0 | EY34: 0 | FQ34: 0 | FR34: =P34 -> 249476.94 | FS34: 0 | FX34: 0 | FY34: 0 | GA34: [2 200 000 / 1,2 / 7,66] + 3% Трансп + 1,2% Заг.скл | GD34: 1 | GF34: -709671177 | GG34: 2 | GH34: 4 | GI34: 0 | GJ34: 0 | GK34: 0 | GL34: =ROUND(IF(AND(BH34=3,BI34=3,FS34<>0),P34,0),2) -> 0 | GM34: =ROUND(O34+X34+Y34,2)+GX34 -> 249476.94 | GN34: =IF(OR(BI34=0,BI34=1),GM34-GX34,0) -> 0 | GO34: =IF(BI34=2,GM34-GX34,0) -> 0 | GP34: =IF(BI34=4,GM34-GX34,0) -> 0 | GR34: 2 | GS34: 2 | GT34: 0 | GV34: =ROUND((GT34),6) -> 0 | GW34: 1 | GX34: =ROUND(HC34*I34,2) -> 0 | HA34: 0 | HB34: 0 | HC34: =GV34*GW34 -> 0 | HE34: 3 | HF34: 1,2 | HS34: 0 | IK34: 0
A35: 17 | B35: 1 | E35: 4 | F35: КА 3 | G35: Газоанализатор паров взрывчатых веществ «Кербер-Т» | H35: шт. | I35: =ROUND(ROUND(1,4),9) -> 1 | J35: 0 | K35: =ROUND(ROUND(1,4),9) -> 1 | O35: =ROUND(CP35,2) -> 1910993.4 | P35: =ROUND((ROUND((AC35*I35),2)*BC35),2) -> 1910993.4 | Q35: =(ROUND((ROUND(((ET35)*AV35*I35),2)*BB35),2)+ROUND((ROUND(((AE35-(EU35))*AV35*I35),2)*BS35),2)) -> 0 | R35: =ROUND((ROUND((AE35*AV35*I35),2)*BS35),2) -> 0 | S35: =ROUND((ROUND((AF35*AV35*I35),2)*BA35),2) -> 0 | T35: =ROUND(CU35*I35,2) -> 0 | U35: =CV35*I35 -> 0 | V35: =CW35*I35 -> 0 | W35: =ROUND(CX35*I35,2) -> 0 | X35: =ROUND(CY35,2) -> 0 | Y35: =ROUND(CZ35,2) -> 0 | AA35: 59214059 | AB35: =ROUND((AC35+AD35+AF35),6) -> 249476.94 | AC35: =ROUND((ES35),6) -> 249476.94 | AD35: =ROUND((((ET35)-(EU35))+AE35),6) -> 0 | AE35: =ROUND((EU35),6) -> 0 | AF35: =ROUND((EV35),6) -> 0 | AG35: =ROUND((AP35),6) -> 0 | AH35: =(EW35) -> 0 | AI35: =(EX35) -> 0 | AJ35: =(AS35) -> 0 | AK35: 249476.94 | AL35: 249476.94 | AM35: 0 | AN35: 0 | AO35: 0 | AP35: 0 | AQ35: 0 | AR35: 0 | AS35: 0 | AT35: 0 | AU35: 0 | AV35: 1 | AW35: 1 | AZ35: 1 | BA35: 1 | BB35: 1 | BC35: 7.66 | BH35: 3 | BI35: 3 | BM35: 746 | BN35: 0 | BP35: 0 | BQ35: 130 | BR35: 0 | BS35: 1 | BT35: 1 | BU35: 1 | BV35: 1 | BW35: 1 | BX35: 1 | BZ35: 0 | CA35: 0 | CE35: 30 | CF35: 0 | CG35: 0 | CM35: 0 | CO35: 0 | CP35: =(P35+Q35+S35) -> 1910993.4 | CQ35: =ROUND((ROUND((AC35*1),2)*BC35),2) -> 1910993.4 | CR35: =(ROUND((ROUND(((ET35)*AV35*1),2)*BB35),2)+ROUND((ROUND(((AE35-(EU35))*AV35*1),2)*BS35),2)) -> 0 | CS35: =ROUND((ROUND((AE35*AV35*1),2)*BS35),2) -> 0 | CT35: =ROUND((ROUND((AF35*AV35*1),2)*BA35),2) -> 0 | CU35: =AG35 -> 0 | CV35: =(AH35*AV35) -> 0 | CW35: =AI35 -> 0 | CX35: =AJ35 -> 0 | CY35: =(((S35+R35)*AT35)/100) -> 0 | CZ35: =(((S35+R35)*AU35)/100) -> 0 | DN35: 0 | DO35: 0 | DP35: 1 | DQ35: 1 | DU35: 1010 | DV35: шт. | DW35: шт. | DX35: 1 | EE35: 58808284 | EF35: 130 | EG35: Сметная стоимость оборудования | EH35: 0 | EJ35: 3 | EK35: 746 | EL35: ТСН-2001.13. Сметная стоимость оборудования | EM35: ТСН-2001.13 | EQ35: 0 | ER35: 0 | ES35: 249476.94 | ET35: 0 | EU35: 0 | EV35: 0 | EW35: 0 | EX35: 0 | EY35: 0 | EZ35: 5 | FC35: 1 | FD35: 18 | FF35: 2200000 | FQ35: 0 | FR35: =P35 -> 1910993.4 | FS35: 0 | FX35: 0 | FY35: 0 | GA35: [2 200 000 / 1,2 / 7,66] + 3% Трансп + 1,2% Заг.скл | GD35: 1 | GF35: -709671177 | GG35: 2 | GH35: 2 | GI35: 5 | GJ35: 0 | GK35: 0 | GL35: =ROUND(IF(AND(BH35=3,BI35=3,FS35<>0),P35,0),2) -> 0 | GM35: =ROUND(O35+X35+Y35,2)+GX35 -> 1910993.4 | GN35: =IF(OR(BI35=0,BI35=1),GM35-GX35,0) -> 0 | GO35: =IF(BI35=2,GM35-GX35,0) -> 0 | GP35: =IF(BI35=4,GM35-GX35,0) -> 0 | GR35: 2 | GS35: 1 | GT35: 0 | GV35: =ROUND((GT35),6) -> 0 | GW35: 1 | GX35: =ROUND(HC35*I35,2) -> 0 | HA35: 0 | HB35: 0 | HC35: =GV35*GW35 -> 0 | HE35: 3 | HF35: 1,2 | HS35: 0 | IK35: 0
A36: 17 | B36: 1 | E36: 5 | F36: 13.3-9-180 | G36: Устройство для защиты от взрыва типа Фонтан-2 10У. Мобильное устройство для подавления не более 1000 г ТНТ, локализуемый объем до 15 дм3, выполнено в форме купола с двумя ручками, стенки и верх купола наполнены специальным диспенсером, поглощающим тепловую и ударную волну, габаритные размеры 610х610х365 мм | H36: шт. | I36: =ROUND(ROUND(1,4),9) -> 1 | J36: 0 | K36: =ROUND(ROUND(1,4),9) -> 1 | O36: =ROUND(CP36,2) -> 8188.38 | P36: =ROUND((ROUND((AC36*I36),2)*BC36),2) -> 8188.38 | Q36: =(ROUND((ROUND(((ET36)*AV36*I36),2)*BB36),2)+ROUND((ROUND(((AE36-(EU36))*AV36*I36),2)*BS36),2)) -> 0 | R36: =ROUND((ROUND((AE36*AV36*I36),2)*BS36),2) -> 0 | S36: =ROUND((ROUND((AF36*AV36*I36),2)*BA36),2) -> 0 | T36: =ROUND(CU36*I36,2) -> 0 | U36: =CV36*I36 -> 0 | V36: =CW36*I36 -> 0 | W36: =ROUND(CX36*I36,2) -> 0 | X36: =ROUND(CY36,2) -> 0 | Y36: =ROUND(CZ36,2) -> 0 | AA36: 59214062 | AB36: =ROUND((AC36+AD36+AF36),6) -> 8188.38 | AC36: =ROUND((ES36),6) -> 8188.38 | AD36: =ROUND((((ET36)-(EU36))+AE36),6) -> 0 | AE36: =ROUND((EU36),6) -> 0 | AF36: =ROUND((EV36),6) -> 0 | AG36: =ROUND((AP36),6) -> 0 | AH36: =(EW36) -> 0 | AI36: =(EX36) -> 0 | AJ36: =(AS36) -> 0 | AK36: 8188.38 | AL36: 8188.38 | AM36: 0 | AN36: 0 | AO36: 0 | AP36: 0 | AQ36: 0 | AR36: 0 | AS36: 0 | AT36: 0 | AU36: 0 | AV36: 1 | AW36: 1 | AZ36: 1 | BA36: 1 | BB36: 1 | BC36: 1 | BH36: 3 | BI36: 3 | BM36: 746 | BN36: 58808062 | BP36: 0 | BQ36: 130 | BR36: 0 | BS36: 1 | BT36: 1 | BU36: 1 | BV36: 1 | BW36: 1 | BX36: 1 | BZ36: 0 | CA36: 0 | CE36: 30 | CF36: 0 | CG36: 0 | CM36: 0 | CO36: 0 | CP36: =(P36+Q36+S36) -> 8188.38 | CQ36: =ROUND((ROUND((AC36*1),2)*BC36),2) -> 8188.38 | CR36: =(ROUND((ROUND(((ET36)*AV36*1),2)*BB36),2)+ROUND((ROUND(((AE36-(EU36))*AV36*1),2)*BS36),2)) -> 0 | CS36: =ROUND((ROUND((AE36*AV36*1),2)*BS36),2) -> 0 | CT36: =ROUND((ROUND((AF36*AV36*1),2)*BA36),2) -> 0 | CU36: =AG36 -> 0 | CV36: =(AH36*AV36) -> 0 | CW36: =AI36 -> 0 | CX36: =AJ36 -> 0 | CY36: =(((S36+R36)*AT36)/100) -> 0 | CZ36: =(((S36+R36)*AU36)/100) -> 0 | DN36: 0 | DO36: 0 | DP36: 1 | DQ36: 1 | DU36: 1010 | DV36: шт. | DW36: шт. | DX36: 1 | EE36: 58808284 | EF36: 130 | EG36: Сметная стоимость оборудования | EH36: 0 | EJ36: 3 | EK36: 746 | EL36: ТСН-2001.13. Сметная стоимость оборудования | EM36: ТСН-2001.13 | EQ36: 0 | ER36: 8188.38 | ES36: 8188.38 | ET36: 0 | EU36: 0 | EV36: 0 | EW36: 0 | EX36: 0 | EY36: 0 | FQ36: 0 | FR36: =P36 -> 8188.38 | FS36: 0 | FX36: 0 | FY36: 0 | GD36: 1 | GF36: 844771149 | GG36: 2 | GH36: 1 | GI36: -2 | GJ36: 0 | GK36: 0 | GL36: =ROUND(IF(AND(BH36=3,BI36=3,FS36<>0),P36,0),2) -> 0 | GM36: =ROUND(O36+X36+Y36,2)+GX36 -> 8188.38 | GN36: =IF(OR(BI36=0,BI36=1),GM36-GX36,0) -> 0 | GO36: =IF(BI36=2,GM36-GX36,0) -> 0 | GP36: =IF(BI36=4,GM36-GX36,0) -> 0 | GR36: 0 | GS36: 3 | GT36: 0 | GV36: =ROUND((GT36),6) -> 0 | GW36: 1 | GX36: =ROUND(HC36*I36,2) -> 0 | HA36: 0 | HB36: 0 | HC36: =GV36*GW36 -> 0 | HS36: 0 | IK36: 0
A37: 17 | B37: 1 | E37: 5 | F37: 13.3-9-180 | G37: Устройство для защиты от взрыва типа Фонтан-2 10У. Мобильное устройство для подавления не более 1000 г ТНТ, локализуемый объем до 15 дм3, выполнено в форме купола с двумя ручками, стенки и верх купола наполнены специальным диспенсером, поглощающим тепловую и ударную волну, габаритные размеры 610х610х365 мм | H37: шт. | I37: =ROUND(ROUND(1,4),9) -> 1 | J37: 0 | K37: =ROUND(ROUND(1,4),9) -> 1 | O37: =ROUND(CP37,2) -> 84831.62 | P37: =ROUND((ROUND((AC37*I37),2)*BC37),2) -> 84831.62 | Q37: =(ROUND((ROUND(((ET37)*AV37*I37),2)*BB37),2)+ROUND((ROUND(((AE37-(EU37))*AV37*I37),2)*BS37),2)) -> 0 | R37: =ROUND((ROUND((AE37*AV37*I37),2)*BS37),2) -> 0 | S37: =ROUND((ROUND((AF37*AV37*I37),2)*BA37),2) -> 0 | T37: =ROUND(CU37*I37,2) -> 0 | U37: =CV37*I37 -> 0 | V37: =CW37*I37 -> 0 | W37: =ROUND(CX37*I37,2) -> 0 | X37: =ROUND(CY37,2) -> 0 | Y37: =ROUND(CZ37,2) -> 0 | AA37: 59214059 | AB37: =ROUND((AC37+AD37+AF37),6) -> 8188.38 | AC37: =ROUND((ES37),6) -> 8188.38 | AD37: =ROUND((((ET37)-(EU37))+AE37),6) -> 0 | AE37: =ROUND((EU37),6) -> 0 | AF37: =ROUND((EV37),6) -> 0 | AG37: =ROUND((AP37),6) -> 0 | AH37: =(EW37) -> 0 | AI37: =(EX37) -> 0 | AJ37: =(AS37) -> 0 | AK37: 8188.38 | AL37: 8188.38 | AM37: 0 | AN37: 0 | AO37: 0 | AP37: 0 | AQ37: 0 | AR37: 0 | AS37: 0 | AT37: 0 | AU37: 0 | AV37: 1 | AW37: 1 | AZ37: 1 | BA37: 1 | BB37: 1 | BC37: 10.36 | BH37: 3 | BI37: 3 | BM37: 746 | BN37: 58808062 | BP37: 0 | BQ37: 130 | BR37: 0 | BS37: 1 | BT37: 1 | BU37: 1 | BV37: 1 | BW37: 1 | BX37: 1 | BZ37: 0 | CA37: 0 | CE37: 30 | CF37: 0 | CG37: 0 | CM37: 0 | CO37: 0 | CP37: =(P37+Q37+S37) -> 84831.62 | CQ37: =ROUND((ROUND((AC37*1),2)*BC37),2) -> 84831.62 | CR37: =(ROUND((ROUND(((ET37)*AV37*1),2)*BB37),2)+ROUND((ROUND(((AE37-(EU37))*AV37*1),2)*BS37),2)) -> 0 | CS37: =ROUND((ROUND((AE37*AV37*1),2)*BS37),2) -> 0 | CT37: =ROUND((ROUND((AF37*AV37*1),2)*BA37),2) -> 0 | CU37: =AG37 -> 0 | CV37: =(AH37*AV37) -> 0 | CW37: =AI37 -> 0 | CX37: =AJ37 -> 0 | CY37: =(((S37+R37)*AT37)/100) -> 0 | CZ37: =(((S37+R37)*AU37)/100) -> 0 | DN37: 0 | DO37: 0 | DP37: 1 | DQ37: 1 | DU37: 1010 | DV37: шт. | DW37: шт. | DX37: 1 | EE37: 58808284 | EF37: 130 | EG37: Сметная стоимость оборудования | EH37: 0 | EJ37: 3 | EK37: 746 | EL37: ТСН-2001.13. Сметная стоимость оборудования | EM37: ТСН-2001.13 | EQ37: 0 | ER37: 8188.38 | ES37: 8188.38 | ET37: 0 | EU37: 0 | EV37: 0 | EW37: 0 | EX37: 0 | EY37: 0 | FQ37: 0 | FR37: =P37 -> 84831.62 | FS37: 0 | FX37: 0 | FY37: 0 | GD37: 1 | GF37: 844771149 | GG37: 2 | GH37: 1 | GI37: 2 | GJ37: 0 | GK37: 0 | GL37: =ROUND(IF(AND(BH37=3,BI37=3,FS37<>0),P37,0),2) -> 0 | GM37: =ROUND(O37+X37+Y37,2)+GX37 -> 84831.62 | GN37: =IF(OR(BI37=0,BI37=1),GM37-GX37,0) -> 0 | GO37: =IF(BI37=2,GM37-GX37,0) -> 0 | GP37: =IF(BI37=4,GM37-GX37,0) -> 0 | GR37: 0 | GS37: 3 | GT37: 0 | GV37: =ROUND((GT37),6) -> 0 | GW37: 1 | GX37: =ROUND(HC37*I37,2) -> 0 | HA37: 0 | HB37: 0 | HC37: =GV37*GW37 -> 0 | HS37: 0 | IK37: 0
A38: 17 | B38: 1 | E38: 6 | F38: 13.1-2-203 | G38: Устройство досмотровое (зеркало) для осмотра грузов, транспортных средств, неосвещенных и труднодоступных мест в помещениях. В составе: телескопическая штанга со встроенными светодиодами, с регулировкой длины от 600 до 1850 мм, набор зеркал различного размера и формы - 4 шт. Время непрерывной работы светодиодов не менее 9 часов, диапазон рабочих температур от -20 до +50°С | H38: КОМПЛЕКТ | I38: =ROUND(ROUND(1,4),9) -> 1 | J38: 0 | K38: =ROUND(ROUND(1,4),9) -> 1 | O38: =ROUND(CP38,2) -> 866.44 | P38: =ROUND((ROUND((AC38*I38),2)*BC38),2) -> 866.44 | Q38: =(ROUND((ROUND(((ET38)*AV38*I38),2)*BB38),2)+ROUND((ROUND(((AE38-(EU38))*AV38*I38),2)*BS38),2)) -> 0 | R38: =ROUND((ROUND((AE38*AV38*I38),2)*BS38),2) -> 0 | S38: =ROUND((ROUND((AF38*AV38*I38),2)*BA38),2) -> 0 | T38: =ROUND(CU38*I38,2) -> 0 | U38: =CV38*I38 -> 0 | V38: =CW38*I38 -> 0 | W38: =ROUND(CX38*I38,2) -> 0 | X38: =ROUND(CY38,2) -> 0 | Y38: =ROUND(CZ38,2) -> 0 | AA38: 59214062 | AB38: =ROUND((AC38+AD38+AF38),6) -> 866.44 | AC38: =ROUND((ES38),6) -> 866.44 | AD38: =ROUND((((ET38)-(EU38))+AE38),6) -> 0 | AE38: =ROUND((EU38),6) -> 0 | AF38: =ROUND((EV38),6) -> 0 | AG38: =ROUND((AP38),6) -> 0 | AH38: =(EW38) -> 0 | AI38: =(EX38) -> 0 | AJ38: =(AS38) -> 0 | AK38: 866.44 | AL38: 866.44 | AM38: 0 | AN38: 0 | AO38: 0 | AP38: 0 | AQ38: 0 | AR38: 0 | AS38: 0 | AT38: 0 | AU38: 0 | AV38: 1 | AW38: 1 | AZ38: 1 | BA38: 1 | BB38: 1 | BC38: 1 | BH38: 3 | BI38: 3 | BM38: 746 | BN38: 58808062 | BP38: 0 | BQ38: 130 | BR38: 0 | BS38: 1 | BT38: 1 | BU38: 1 | BV38: 1 | BW38: 1 | BX38: 1 | BZ38: 0 | CA38: 0 | CE38: 30 | CF38: 0 | CG38: 0 | CM38: 0 | CO38: 0 | CP38: =(P38+Q38+S38) -> 866.44 | CQ38: =ROUND((ROUND((AC38*1),2)*BC38),2) -> 866.44 | CR38: =(ROUND((ROUND(((ET38)*AV38*1),2)*BB38),2)+ROUND((ROUND(((AE38-(EU38))*AV38*1),2)*BS38),2)) -> 0 | CS38: =ROUND((ROUND((AE38*AV38*1),2)*BS38),2) -> 0 | CT38: =ROUND((ROUND((AF38*AV38*1),2)*BA38),2) -> 0 | CU38: =AG38 -> 0 | CV38: =(AH38*AV38) -> 0 | CW38: =AI38 -> 0 | CX38: =AJ38 -> 0 | CY38: =(((S38+R38)*AT38)/100) -> 0 | CZ38: =(((S38+R38)*AU38)/100) -> 0 | DN38: 0 | DO38: 0 | DP38: 1 | DQ38: 1 | DU38: 1013 | DV38: КОМПЛЕКТ | DW38: КОМПЛЕКТ | DX38: 1 | EE38: 58808284 | EF38: 130 | EG38: Сметная стоимость оборудования | EH38: 0 | EJ38: 3 | EK38: 746 | EL38: ТСН-2001.13. Сметная стоимость оборудования | EM38: ТСН-2001.13 | EQ38: 0 | ER38: 866.44 | ES38: 866.44 | ET38: 0 | EU38: 0 | EV38: 0 | EW38: 0 | EX38: 0 | EY38: 0 | FQ38: 0 | FR38: =P38 -> 866.44 | FS38: 0 | FX38: 0 | FY38: 0 | GD38: 1 | GF38: -1221268236 | GG38: 2 | GH38: 1 | GI38: -2 | GJ38: 0 | GK38: 0 | GL38: =ROUND(IF(AND(BH38=3,BI38=3,FS38<>0),P38,0),2) -> 0 | GM38: =ROUND(O38+X38+Y38,2)+GX38 -> 866.44 | GN38: =IF(OR(BI38=0,BI38=1),GM38-GX38,0) -> 0 | GO38: =IF(BI38=2,GM38-GX38,0) -> 0 | GP38: =IF(BI38=4,GM38-GX38,0) -> 0 | GR38: 0 | GS38: 3 | GT38: 0 | GV38: =ROUND((GT38),6) -> 0 | GW38: 1 | GX38: =ROUND(HC38*I38,2) -> 0 | HA38: 0 | HB38: 0 | HC38: =GV38*GW38 -> 0 | HS38: 0 | IK38: 0
A39: 17 | B39: 1 | E39: 6 | F39: 13.1-2-203 | G39: Устройство досмотровое (зеркало) для осмотра грузов, транспортных средств, неосвещенных и труднодоступных мест в помещениях. В составе: телескопическая штанга со встроенными светодиодами, с регулировкой длины от 600 до 1850 мм, набор зеркал различного размера и формы - 4 шт. Время непрерывной работы светодиодов не менее 9 часов, диапазон рабочих температур от -20 до +50°С | H39: КОМПЛЕКТ | I39: =ROUND(ROUND(1,4),9) -> 1 | J39: 0 | K39: =ROUND(ROUND(1,4),9) -> 1 | O39: =ROUND(CP39,2) -> 9903.41 | P39: =ROUND((ROUND((AC39*I39),2)*BC39),2) -> 9903.41 | Q39: =(ROUND((ROUND(((ET39)*AV39*I39),2)*BB39),2)+ROUND((ROUND(((AE39-(EU39))*AV39*I39),2)*BS39),2)) -> 0 | R39: =ROUND((ROUND((AE39*AV39*I39),2)*BS39),2) -> 0 | S39: =ROUND((ROUND((AF39*AV39*I39),2)*BA39),2) -> 0 | T39: =ROUND(CU39*I39,2) -> 0 | U39: =CV39*I39 -> 0 | V39: =CW39*I39 -> 0 | W39: =ROUND(CX39*I39,2) -> 0 | X39: =ROUND(CY39,2) -> 0 | Y39: =ROUND(CZ39,2) -> 0 | AA39: 59214059 | AB39: =ROUND((AC39+AD39+AF39),6) -> 866.44 | AC39: =ROUND((ES39),6) -> 866.44 | AD39: =ROUND((((ET39)-(EU39))+AE39),6) -> 0 | AE39: =ROUND((EU39),6) -> 0 | AF39: =ROUND((EV39),6) -> 0 | AG39: =ROUND((AP39),6) -> 0 | AH39: =(EW39) -> 0 | AI39: =(EX39) -> 0 | AJ39: =(AS39) -> 0 | AK39: 866.44 | AL39: 866.44 | AM39: 0 | AN39: 0 | AO39: 0 | AP39: 0 | AQ39: 0 | AR39: 0 | AS39: 0 | AT39: 0 | AU39: 0 | AV39: 1 | AW39: 1 | AZ39: 1 | BA39: 1 | BB39: 1 | BC39: 11.43 | BH39: 3 | BI39: 3 | BM39: 746 | BN39: 58808062 | BP39: 0 | BQ39: 130 | BR39: 0 | BS39: 1 | BT39: 1 | BU39: 1 | BV39: 1 | BW39: 1 | BX39: 1 | BZ39: 0 | CA39: 0 | CE39: 30 | CF39: 0 | CG39: 0 | CM39: 0 | CO39: 0 | CP39: =(P39+Q39+S39) -> 9903.41 | CQ39: =ROUND((ROUND((AC39*1),2)*BC39),2) -> 9903.41 | CR39: =(ROUND((ROUND(((ET39)*AV39*1),2)*BB39),2)+ROUND((ROUND(((AE39-(EU39))*AV39*1),2)*BS39),2)) -> 0 | CS39: =ROUND((ROUND((AE39*AV39*1),2)*BS39),2) -> 0 | CT39: =ROUND((ROUND((AF39*AV39*1),2)*BA39),2) -> 0 | CU39: =AG39 -> 0 | CV39: =(AH39*AV39) -> 0 | CW39: =AI39 -> 0 | CX39: =AJ39 -> 0 | CY39: =(((S39+R39)*AT39)/100) -> 0 | CZ39: =(((S39+R39)*AU39)/100) -> 0 | DN39: 0 | DO39: 0 | DP39: 1 | DQ39: 1 | DU39: 1013 | DV39: КОМПЛЕКТ | DW39: КОМПЛЕКТ | DX39: 1 | EE39: 58808284 | EF39: 130 | EG39: Сметная стоимость оборудования | EH39: 0 | EJ39: 3 | EK39: 746 | EL39: ТСН-2001.13. Сметная стоимость оборудования | EM39: ТСН-2001.13 | EQ39: 0 | ER39: 866.44 | ES39: 866.44 | ET39: 0 | EU39: 0 | EV39: 0 | EW39: 0 | EX39: 0 | EY39: 0 | FQ39: 0 | FR39: =P39 -> 9903.41 | FS39: 0 | FX39: 0 | FY39: 0 | GD39: 1 | GF39: -1221268236 | GG39: 2 | GH39: 1 | GI39: 2 | GJ39: 0 | GK39: 0 | GL39: =ROUND(IF(AND(BH39=3,BI39=3,FS39<>0),P39,0),2) -> 0 | GM39: =ROUND(O39+X39+Y39,2)+GX39 -> 9903.41 | GN39: =IF(OR(BI39=0,BI39=1),GM39-GX39,0) -> 0 | GO39: =IF(BI39=2,GM39-GX39,0) -> 0 | GP39: =IF(BI39=4,GM39-GX39,0) -> 0 | GR39: 0 | GS39: 3 | GT39: 0 | GV39: =ROUND((GT39),6) -> 0 | GW39: 1 | GX39: =ROUND(HC39*I39,2) -> 0 | HA39: 0 | HB39: 0 | HC39: =GV39*GW39 -> 0 | HS39: 0 | IK39: 0
A40: 17 | B40: 1 | C40: =ROW(SmtRes!A10) -> 10 | D40: =ROW(EtalonRes!A14) -> 14 | E40: 7 | F40: 3.10-33-1 | G40: Установка штучных изделий столов, шкафов под мойки, холодильных шкафов и других | H40: 100 изделий | I40: =ROUND(ROUND(4/100,4),9) -> 0.04 | J40: 0 | K40: =ROUND(ROUND(4/100,4),9) -> 0.04 | O40: =ROUND(CP40,2) -> 55 | P40: =ROUND((ROUND((AC40*AW40*I40),2)*BC40),2) -> 12.73 | Q40: =(ROUND((ROUND((((ET40*1.1))*AV40*I40),2)*BB40),2)+ROUND((ROUND(((AE40-((EU40*1.1)))*AV40*I40),2)*BS40),2)) -> 9.46 | R40: =ROUND((ROUND((AE40*AV40*I40),2)*BS40),2) -> 1.44 | S40: =ROUND((ROUND((AF40*AV40*I40),2)*BA40),2) -> 32.81 | T40: =ROUND(CU40*I40,2) -> 0 | U40: =CV40*I40 -> 3.1188036 | V40: =CW40*I40 -> 0 | W40: =ROUND(CX40*I40,2) -> 0 | X40: =ROUND(CY40,2) -> 36.99 | Y40: =ROUND(CZ40,2) -> 18.84 | AA40: 59214062 | AB40: =ROUND((AC40+AD40+AF40),6) -> 1327.486 | AC40: =ROUND((ES40),6) -> 318.28 | AD40: =ROUND(((((ET40*1.1))-((EU40*1.1)))+AE40),6) -> 225.786 | AE40: =ROUND(((EU40*1.1)),6) -> 34.287 | AF40: =ROUND(((EV40*1.1)),6) -> 783.42 | AG40: =ROUND((AP40),6) -> 0 | AH40: =((EW40*1.1)) -> 74.47 | AI40: =((EX40*1.1)) -> 0 | AJ40: =(AS40) -> 0 | AK40: 1235.74 | AL40: 318.28 | AM40: 205.26 | AN40: 31.17 | AO40: 712.2 | AP40: 0 | AQ40: 67.7 | AR40: 0 | AS40: 0 | AT40: 108 | AU40: 55 | AV40: 1.047 | AW40: 1 | AZ40: 1 | BA40: 1 | BB40: 1 | BC40: 1 | BH40: 0 | BI40: 1 | BJ40: ТСН-2001.3 Доп. 79, Сб. 10, т. 33, поз. 1 | BM40: 14 | BN40: 58808062 | BO40: 3.10-33-1 | BP40: 1 | BQ40: 30 | BR40: 0 | BS40: 1 | BT40: 1 | BU40: 1 | BV40: 1 | BW40: 1 | BX40: 1 | BZ40: 108 | CA40: 55 | CE40: 30 | CF40: 0 | CG40: 0 | CM40: 0 | CN40: Поправка: О.П. п.3.4.30.в Наименование: При применении территориальных сметных нормативов для города Москвы затраты, учитывающие напряженные и стесненные условия производства работ (стесненность, сложность складирования и транспортной логистики и т.п.), исчисляются с применением коэффициентов к затратам труда и заработной плате рабочих, машинистов, времени эксплуатации машин и механизмов, стоимости эксплуатации машин в размере: для объектов, расположенных за пределами Третьего транспортного кольца города Москвы, но в пределах Московской кольцевой автомобильной дороги | CO40: 0 | CP40: =(P40+Q40+S40) -> 55 | CQ40: =ROUND((ROUND((AC40*AW40*1),2)*BC40),2) -> 318.28 | CR40: =(ROUND((ROUND((((ET40*1.1))*AV40*1),2)*BB40),2)+ROUND((ROUND(((AE40-((EU40*1.1)))*AV40*1),2)*BS40),2)) -> 236.4 | CS40: =ROUND((ROUND((AE40*AV40*1),2)*BS40),2) -> 35.9 | CT40: =ROUND((ROUND((AF40*AV40*1),2)*BA40),2) -> 820.24 | CU40: =AG40 -> 0 | CV40: =(AH40*AV40) -> 77.97009 | CW40: =AI40 -> 0 | CX40: =AJ40 -> 0 | CY40: =(((S40+R40)*AT40)/100) -> 36.99 | CZ40: =(((S40+R40)*AU40)/100) -> 18.8375 | DB40: 3 | DE40: *1,1 | DF40: *1,1 | DG40: *1,1 | DI40: *1,1 | DJ40: *1,1 | DN40: 0 | DO40: 0 | DP40: 1 | DQ40: 1 | DU40: 30517203 | DV40: 100 изделий | DW40: 100 изделий | DX40: 1 | EE40: 58808123 | EF40: 30 | EG40: Строительные работы | EH40: 0 | EJ40: 1 | EK40: 14 | EL40: ТСН-2001.3-10. Элементы и конструкции из дерева и пластмасс | EM40: ТСН-2001.3-10-1 | EO40: Поправка: О.П. п.3.4.30.в | EQ40: 0 | ER40: 1235.74 | ES40: 318.28 | ET40: 205.26 | EU40: 31.17 | EV40: 712.2 | EW40: 67.7 | EX40: 0 | EY40: 0 | FQ40: 0 | FR40: 0 | FS40: 0 | FX40: 108 | FY40: 55 | GD40: 1 | GF40: -1266291315 | GG40: 2 | GH40: 1 | GI40: 2 | GJ40: 0 | GK40: 0 | GL40: =ROUND(IF(AND(BH40=3,BI40=3,FS40<>0),P40,0),2) -> 0 | GM40: =ROUND(O40+X40+Y40,2)+GX40 -> 110.83 | GN40: =IF(OR(BI40=0,BI40=1),GM40-GX40,0) -> 110.83 | GO40: =IF(BI40=2,GM40-GX40,0) -> 0 | GP40: =IF(BI40=4,GM40-GX40,0) -> 0 | GR40: 0 | GS40: 3 | GT40: 0 | GV40: =ROUND((GT40),6) -> 0 | GW40: 1 | GX40: =ROUND(HC40*I40,2) -> 0 | HA40: 0 | HB40: 0 | HC40: =GV40*GW40 -> 0 | HS40: 0 | IK40: 0
A41: 17 | B41: 1 | C41: =ROW(SmtRes!A14) -> 14 | D41: =ROW(EtalonRes!A20) -> 20 | E41: 7 | F41: 3.10-33-1 | G41: Установка штучных изделий столов, шкафов под мойки, холодильных шкафов и других | H41: 100 изделий | I41: =ROUND(ROUND(4/100,4),9) -> 0.04 | J41: 0 | K41: =ROUND(ROUND(4/100,4),9) -> 0.04 | O41: =ROUND(CP41,2) -> 2074.39 | P41: =ROUND((ROUND((AC41*AW41*I41),2)*BC41),2) -> 115.97 | Q41: =(ROUND((ROUND((((ET41*1.1))*AV41*I41),2)*BB41),2)+ROUND((ROUND(((AE41-((EU41*1.1)))*AV41*I41),2)*BS41),2)) -> 154.2 | R41: =ROUND((ROUND((AE41*AV41*I41),2)*BS41),2) -> 79.19 | S41: =ROUND((ROUND((AF41*AV41*I41),2)*BA41),2) -> 1804.22 | T41: =ROUND(CU41*I41,2) -> 0 | U41: =CV41*I41 -> 3.1188036 | V41: =CW41*I41 -> 0 | W41: =ROUND(CX41*I41,2) -> 0 | X41: =ROUND(CY41,2) -> 2034.08 | Y41: =ROUND(CZ41,2) -> 1035.88 | AA41: 59214059 | AB41: =ROUND((AC41+AD41+AF41),6) -> 1327.486 | AC41: =ROUND((ES41),6) -> 318.28 | AD41: =ROUND(((((ET41*1.1))-((EU41*1.1)))+AE41),6) -> 225.786 | AE41: =ROUND(((EU41*1.1)),6) -> 34.287 | AF41: =ROUND(((EV41*1.1)),6) -> 783.42 | AG41: =ROUND((AP41),6) -> 0 | AH41: =((EW41*1.1)) -> 74.47 | AI41: =((EX41*1.1)) -> 0 | AJ41: =(AS41) -> 0 | AK41: 1235.74 | AL41: 318.28 | AM41: 205.26 | AN41: 31.17 | AO41: 712.2 | AP41: 0 | AQ41: 67.7 | AR41: 0 | AS41: 0 | AT41: 108 | AU41: 55 | AV41: 1.047 | AW41: 1 | AZ41: 1 | BA41: 54.99 | BB41: 16.3 | BC41: 9.11 | BH41: 0 | BI41: 1 | BJ41: ТСН-2001.3 Доп. 79, Сб. 10, т. 33, поз. 1 | BM41: 14 | BN41: 58808062 | BO41: 3.10-33-1 | BP41: 1 | BQ41: 30 | BR41: 0 | BS41: 54.99 | BT41: 1 | BU41: 1 | BV41: 1 | BW41: 1 | BX41: 1 | BZ41: 108 | CA41: 55 | CE41: 30 | CF41: 0 | CG41: 0 | CM41: 0 | CN41: Поправка: О.П. п.3.4.30.в Наименование: При применении территориальных сметных нормативов для города Москвы затраты, учитывающие напряженные и стесненные условия производства работ (стесненность, сложность складирования и транспортной логистики и т.п.), исчисляются с применением коэффициентов к затратам труда и заработной плате рабочих, машинистов, времени эксплуатации машин и механизмов, стоимости эксплуатации машин в размере: для объектов, расположенных за пределами Третьего транспортного кольца города Москвы, но в пределах Московской кольцевой автомобильной дороги | CO41: 0 | CP41: =(P41+Q41+S41) -> 2074.39 | CQ41: =ROUND((ROUND((AC41*AW41*1),2)*BC41),2) -> 2899.53 | CR41: =(ROUND((ROUND((((ET41*1.1))*AV41*1),2)*BB41),2)+ROUND((ROUND(((AE41-((EU41*1.1)))*AV41*1),2)*BS41),2)) -> 3853.32 | CS41: =ROUND((ROUND((AE41*AV41*1),2)*BS41),2) -> 1974.14 | CT41: =ROUND((ROUND((AF41*AV41*1),2)*BA41),2) -> 45105 | CU41: =AG41 -> 0 | CV41: =(AH41*AV41) -> 77.97009 | CW41: =AI41 -> 0 | CX41: =AJ41 -> 0 | CY41: =(((S41+R41)*AT41)/100) -> 2034.0828 | CZ41: =(((S41+R41)*AU41)/100) -> 1035.8755 | DB41: 4 | DE41: *1,1 | DF41: *1,1 | DG41: *1,1 | DI41: *1,1 | DJ41: *1,1 | DN41: 0 | DO41: 0 | DP41: 1 | DQ41: 1 | DU41: 30517203 | DV41: 100 изделий | DW41: 100 изделий | DX41: 1 | EE41: 58808123 | EF41: 30 | EG41: Строительные работы | EH41: 0 | EJ41: 1 | EK41: 14 | EL41: ТСН-2001.3-10. Элементы и конструкции из дерева и пластмасс | EM41: ТСН-2001.3-10-1 | EO41: Поправка: О.П. п.3.4.30.в | EQ41: 0 | ER41: 1235.74 | ES41: 318.28 | ET41: 205.26 | EU41: 31.17 | EV41: 712.2 | EW41: 67.7 | EX41: 0 | EY41: 0 | FQ41: 0 | FR41: 0 | FS41: 0 | FX41: 108 | FY41: 55 | GD41: 1 | GF41: -1266291315 | GG41: 2 | GH41: 1 | GI41: 2 | GJ41: 0 | GK41: 0 | GL41: =ROUND(IF(AND(BH41=3,BI41=3,FS41<>0),P41,0),2) -> 0 | GM41: =ROUND(O41+X41+Y41,2)+GX41 -> 5144.35 | GN41: =IF(OR(BI41=0,BI41=1),GM41-GX41,0) -> 5144.35 | GO41: =IF(BI41=2,GM41-GX41,0) -> 0 | GP41: =IF(BI41=4,GM41-GX41,0) -> 0 | GR41: 0 | GS41: 3 | GT41: 0 | GV41: =ROUND((GT41),6) -> 0 | GW41: 1 | GX41: =ROUND(HC41*I41,2) -> 0 | HA41: 0 | HB41: 0 | HC41: =GV41*GW41 -> 0 | HS41: 0 | IK41: 0
