Workbook

Sheet 02-01-16
A1: =Source!B1 -> Smeta.RU (495) 974-1589
J2: Форма № 4б
A3: Капитальный ремонт здания Государственного бюджетного общеобразовательного учреждения города Москвы "Школа №236" по адресу: г. Москва, улица Клязьминская, дом 7, корпус 4. | AP3: Капитальный ремонт здания Государственного бюджетного общеобразовательного учреждения города Москвы "Школа №236" по адресу: г. Москва, улица Клязьминская, дом 7, корпус 4. 02-01-16 СОС
A4: (наименование стройки и/или объекта)
A6: =CONCATENATE( "ЛОКАЛЬНАЯ СМЕТА № ",IF(Source!F20<>"Новая локальная смета", Source!F20, "")) -> ЛОКАЛЬНАЯ СМЕТА № 02-01-16
A8: =IF(Source!G20<>"Новая локальная смета", Source!G20, "") -> Система охранно-тревожной сигнализации
A9: (наименование работ и затрат)
A11: =CONCATENATE( "Основание: чертежи № ", Source!J20) -> Основание: чертежи № 2024-00272-00-ИОС5.8
I13: В базисном уровне цен | J13: В текущем уровне цен
E14: Сметная стоимость | I14: =I15+I16+I17+I18 -> 136.25 | J14: =J15+J16+J17+J18 -> 2626.43 | K14: тыс.руб.
E15: Строительные работы | I15: =ROUND((Source!F199)/1000, 2) -> 0 | J15: =ROUND((Source!P199)/1000, 2) -> 0 | K15: тыс.руб.
E16: Работы по монтажу оборудования | I16: =ROUND((Source!F200)/1000, 2) -> 69.47 | J16: =ROUND((Source!P200)/1000, 2) -> 2114.92 | K16: тыс.руб.
E17: Оборудование | I17: =ROUND((Source!F191)/1000, 2) -> 66.78 | J17: =ROUND((Source!P191)/1000, 2) -> 511.51 | K17: тыс.руб.
E18: Прочие работы и затраты | I18: =ROUND((Source!F201+Source!F202)/1000, 2) -> 0 | J18: =ROUND((Source!P201+Source!P202)/1000, 2) -> 0 | K18: тыс.руб.
E19: Средства на оплату труда | I19: =(Source!F197+ Source!F196)/1000 -> 13.60692 | J19: =((Source!P197 + Source!P196)/1000) -> 748.24452 | K19: тыс.руб.
E20: Затраты труда | I20: =Source!F204 -> 1038.104 | K20: чел.-ч.
E21: Кроме того:
E22: Возврат материалов | I22: =SUM(Y28:Y335)/1000 -> 0 | J22: =SUM(Z28:Z335)/1000 -> 0 | K22: тыс.руб.
A24: Составлен(а) по ТСН-2001 с учетом Дополнения №: 80
A25: № и период сборника коэффициентов (индексов) пересчета: Коэффициенты к ТСН-2001 МГЭ Дополнение 80, строительство №217/80 III квартал 2025 года и Коэффициенты к ТСН-2001.13-2 Дополнение 46 №62/46 III квартал 2025 года | AP25: № и период сборника коэффициентов (индексов) пересчета: Коэффициенты к ТСН-2001 МГЭ Дополнение 80, строительство №217/80 III квартал 2025 года и Коэффициенты к ТСН-2001.13-2 Дополнение 46 №62/46 III квартал 2025 года
A26: № п/п | B26: Шифр расценки и коды ресурсов | C26: Наименование работ и затрат | D26: Ед. изм. | E26: Кол-во единиц | F26: Цена на ед. изм., руб. | G26: Попра- вочные коэффи- циенты | H26: Коэффи- циенты зимних удорожа- ний | I26: Всего в ценах на январь 2000 года, руб. | J26: Коэффи- циенты (индек- сы) пере- счета, нормы НР и СП | K26: ВСЕГО затрат в текущем уровне цен, руб.
A27: 1 | B27: 2 | C27: 3 | D27: 4 | E27: 5 | F27: 6 | G27: 7 | H27: 8 | I27: 9 | J27: 10 | K27: 11
A29: =CONCATENATE("Раздел: ",IF(Source!G24<>"Новый раздел", Source!G24, "")) -> Раздел: Оборудование
A30: 1 | B30: =Source!F28 -> 4.10-75-6 | C30: Монтаж аппаратуры настольной массой до 20 кг | D30: =Source!H28 -> 1 ШТ. | E30: =Source!I28 -> 1 | Q30: =Source!X28 -> 96.65 | R30: =Source!X29 -> 5314.95 | S30: =Source!Y28 -> 53.92 | T30: =Source!Y29 -> 2965.18 | U30: =ROUND((175/100)*ROUND(Source!R28, 2), 2) -> 0 | V30: =ROUND((0/100)*ROUND(Source!R29, 2), 2) -> 0 | AC30: 0
C31: ЗП | F31: =Source!AO28 -> 88.34 | G31: =Source!DG28 -> *1,1 | H31: =Source!AV29 -> 1.047 | I31: =Source!S28 -> 101.74 | J31: =IF(Source!BA29<> 0, Source!BA29, 1) -> 54.99 | K31: =Source!S29 -> 5594.68
C32: МР | F32: =Source!AL28 -> 34.87 | G32: =Source!DD28 -> *1 | H32: =Source!AW29 -> 1 | I32: =Source!P28 -> 34.87 | J32: =IF(Source!BC29<> 0, Source!BC29, 1) -> 11.35 | K32: =Source!P29 -> 395.77
C33: НР от ФОТ | D33: % | E33: =Source!BZ29 -> 95 | I33: =SUM(Q30:Q32) -> 96.65 | J33: =Source!AT29 -> 95 | K33: =SUM(R30:R32) -> 5314.95
C34: СП от ФОТ | D34: % | E34: =Source!CA29 -> 53 | I34: =SUM(S30:S33) -> 53.92 | J34: =Source!AU29 -> 53 | K34: =SUM(T30:T33) -> 2965.18
C35: ЗТР | D35: чел-ч | E35: =Source!AQ28 -> 7 | G35: =Source!DI28 -> *1,1 | H35: =Source!AV29 -> 1.047 | I35: =Source!U28 -> 8.0619
C36: ВСЕГО работ по позиции: | H36: =I31+I32+I33+I34+0-0-0 -> 287.18 | J36: =K31+K32+K33+K34+0-0-0 -> 14270.58
C37: ВСЕГО оборудование по позиции: | H37: =0+0 -> 0 | J37: =0+0 -> 0
C38: ВСЕГО по позиции: | H38: =I31+I32+I33+I34+0 -> 287.18 | J38: =K31+K32+K33+K34+0 -> 14270.58 | O38: =I31+I32+I33+I34+0 -> 287.18 | P38: =K31+K32+K33+K34+0 -> 14270.58
A40: 2 | B40: =Source!F30 -> КА-1 | C40: ОБОРУДОВАНИЕ:_x000D_ Компьютер персональный АРМ DEPO ПЕРЕСВЕТ 110D11 (системный блок, монитор 21,5", клавиатура, мышь) 8 561,59 = [75 500 / 1,2 / 7,66] + 3% Трансп + 1,2% Заг.скл | D40: =Source!H30 -> ШТ | E40: =Source!I30 -> 1 | F40: =Source!AL30 -> 8561.59 | G40: =Source!DD30 | H40: =Source!AW31 -> 1 | I40: =Source!P30 -> 8561.59 | J40: =IF(Source!BC31<> 0, Source!BC31, 1) -> 7.66 | K40: =Source!P31 -> 65581.78 | Q40: =Source!X30 -> 0 | R40: =Source!X31 -> 0 | S40: =Source!Y30 -> 0 | T40: =Source!Y31 -> 0 | U40: =ROUND((175/100)*ROUND(Source!R30, 2), 2) -> 0 | V40: =ROUND((0/100)*ROUND(Source!R31, 2), 2) -> 0 | AC40: 5
C41: ВСЕГО по позиции: | H41: =I40+0 -> 8561.59 | J41: =K40+0 -> 65581.78 | O41: =I40+0 -> 8561.59 | P41: =K40+0 -> 65581.78
A43: 3 | B43: =Source!F32 -> КА-2 | C43: ОБОРУДОВАНИЕ:_x000D_ Операционная система REDOS-DSP-STD-BAS-VDI 1 655,62 = [14 600 / 1,2 / 7,66] + 3% Трансп + 1,2% Заг.скл | D43: =Source!H32 -> ШТ | E43: =Source!I32 -> 1 | F43: =Source!AL32 -> 1655.62 | G43: =Source!DD32 | H43: =Source!AW33 -> 1 | I43: =Source!P32 -> 1655.62 | J43: =IF(Source!BC33<> 0, Source!BC33, 1) -> 7.66 | K43: =Source!P33 -> 12682.05 | Q43: =Source!X32 -> 0 | R43: =Source!X33 -> 0 | S43: =Source!Y32 -> 0 | T43: =Source!Y33 -> 0 | U43: =ROUND((175/100)*ROUND(Source!R32, 2), 2) -> 0 | V43: =ROUND((0/100)*ROUND(Source!R33, 2), 2) -> 0 | AC43: 5
C44: ВСЕГО по позиции: | H44: =I43+0 -> 1655.62 | J44: =K43+0 -> 12682.05 | O44: =I43+0 -> 1655.62 | P44: =K43+0 -> 12682.05
A46: 4 | B46: =Source!F34 -> 4.10-173-2 | C46: Монтаж блока бесперебойного питания (ББП) в диспетчерской | D46: =Source!H34 -> 1 ШТ. | E46: =Source!I34 -> 1 | Q46: =Source!X34 -> 41.63 | R46: =Source!X35 -> 2289.46 | S46: =Source!Y34 -> 21.28 | T46: =Source!Y35 -> 1170.17 | U46: =ROUND((175/100)*ROUND(Source!R34, 2), 2) -> 0 | V46: =ROUND((0/100)*ROUND(Source!R35, 2), 2) -> 0 | AC46: 0
C47: ЗП | F47: =Source!AO34 -> 40.17 | G47: =Source!DG34 -> *1,1 | H47: =Source!AV35 -> 1.047 | I47: =Source!S34 -> 46.26 | J47: =IF(Source!BA35<> 0, Source!BA35, 1) -> 54.99 | K47: =Source!S35 -> 2543.84
C48: МР | F48: =Source!AL34 -> 2.34 | G48: =Source!DD34 -> *1 | H48: =Source!AW35 -> 1 | I48: =Source!P34 -> 2.34 | J48: =IF(Source!BC35<> 0, Source!BC35, 1) -> 10.26 | K48: =Source!P35 -> 24.01
C49: НР от ФОТ | D49: % | E49: =Source!BZ35 -> 90 | I49: =SUM(Q46:Q48) -> 41.63 | J49: =Source!AT35 -> 90 | K49: =SUM(R46:R48) -> 2289.46
...

Sheet Ведомость объемов работ
A1: =Source!B1 -> Smeta.RU (495) 974-1589
B4: =CONCATENATE("Ведомость объемов работ ", IF(Source!AN15<>"", Source!AN15," ")) -> Ведомость объемов работ
B5: =CONCATENATE(Source!F12, " ", Source!G12) -> 02-01-16 СОС
A8: № п/п | B8: № в ЛСР | C8: Наименование работ и затрат | D8: Единица измерения | E8: Количество | F8: Ссылка на чертежи, спецификации | G8: Формула расчета, расчет объемов работ и расхода материалов | H8: Примечание
A9: 1 | B9: 2 | C9: 3 | D9: 4 | E9: 5 | F9: 6 | G9: 7 | H9: 8
A10: =CONCATENATE("Локальная смета: ", Source!G20) -> Локальная смета: Система охранно-тревожной сигнализации
A11: =CONCATENATE("Раздел: ", Source!G24) -> Раздел: Оборудование
A12: 1 | B12: =Source!E28 -> 1 | C12: =Source!G28 -> Монтаж аппаратуры настольной массой до 20 кг | D12: 1 ШТ. | E12: =Source!I28 -> 1 | F12: =Source!U24 | G12: =Source!I28 -> 1
A13: 2 | B13: =Source!E30 -> 2 | C13: =Source!G30 -> Компьютер персональный АРМ DEPO ПЕРЕСВЕТ 110D11 (системный блок, монитор 21,5", клавиатура, мышь) | D13: ШТ | E13: =Source!I30 -> 1 | F13: =Source!U24 | G13: =Source!I30 -> 1
A14: 3 | B14: =Source!E32 -> 3 | C14: =Source!G32 -> Операционная система REDOS-DSP-STD-BAS-VDI | D14: ШТ | E14: =Source!I32 -> 1 | F14: =Source!U24 | G14: =Source!I32 -> 1
A15: 4 | B15: =Source!E34 -> 4 | C15: =Source!G34 -> Монтаж блока бесперебойного питания (ББП) в диспетчерской | D15: 1 ШТ. | E15: =Source!I34 -> 1 | F15: =Source!U24 | G15: =Source!I34 -> 1
A16: 5 | B16: =Source!E36 -> 5 | C16: =Source!G36 -> Источник бесперебойного питания, 600Вт Back Basic 1050S Euro | D16: ШТ | E16: =Source!I36 -> 1 | F16: =Source!U24 | G16: =Source!I36 -> 1
A17: 6 | B17: =Source!E38 -> 6 | C17: =Source!G38 -> Аппараты приемные, приборы ПС приемно-контрольные, пусковые, концентратор, блок базовый на 10 лучей | D17: 1 ШТ. | E17: =Source!I38 -> 1 | F17: =Source!U24 | G17: =Source!I38 -> 1
A18: 7 | B18: =Source!E40 -> 7 | C18: =Source!G40 -> Прибор приемно-контрольный и управленя Рубеж-20П прот. R3 | D18: ШТ | E18: =Source!I40 -> 1 | F18: =Source!U24 | G18: =Source!I40 -> 1
A19: 8 | B19: =Source!E42 -> 8 | C19: =Source!G42 -> Аппараты приемные, устройства промежуточные на 1 луч | D19: 1 ШТ. | E19: =Source!I42 -> 1 | F19: =Source!U24 | G19: =Source!I42 -> 1
A20: 9 | B20: =Source!E44 -> 9 | C20: =Source!G44 -> Модуль сопряжения МС-Е | D20: ШТ | E20: =Source!I44 -> 1 | F20: =Source!U24 | G20: =Source!I44 -> 1
A21: 10 | B21: =Source!E46 -> 10 | C21: =Source!G46 -> Аппараты приемные, приборы приемно-контрольные объектовые на 2 луча | D21: 1 ШТ. | E21: =Source!I46 -> 1 | F21: =Source!U24 | G21: =Source!I46 -> 1
A22: 11 | B22: =Source!E48 -> 11 | C22: =Source!G48 -> Блок индикации и управления Рубеж-БИУ | D22: ШТ | E22: =Source!I48 -> 1 | F22: =Source!U24 | G22: =Source!I48 -> 1
A23: 12 | B23: =Source!E50 -> 12 | C23: =Source!G50 -> Приборы и устройства сигнализирующие объектовые, устройства ультразвуковые, блок питания и контроля | D23: 1 ШТ. | E23: =Source!I50 -> 1 | F23: =Source!U24 | G23: =Source!I50 -> 1
A24: 13 | B24: =Source!E52 -> 13 | C24: =Source!G52 -> Устройство оконечное объектовое Приток-А КОП-1 исп.1 | D24: ШТ | E24: =Source!I52 -> 1 | F24: =Source!U24 | G24: =Source!I52 -> 1
A25: 14 | B25: =Source!E54 -> 14 | C25: =Source!G54 -> Монтаж блока бесперебойного питания (ББП) в диспетчерской | D25: 1 ШТ. | E25: =Source!I54 -> 3 | F25: =Source!U24 | G25: =Source!I54 -> 3
A26: 15 | B26: =Source!E56 -> 15 | C26: =Source!G56 -> Блок питания, 12В, 2А ИВЭПР 12/2 RS-R3 | D26: ШТ | E26: =Source!I56 -> 3 | F26: =Source!U24 | G26: =Source!I56 -> 3
A27: 16 | B27: =Source!E58 -> 16 | C27: =Source!G58 -> Аккумултор 12В 7Ач DTM 1207 | D27: ШТ | E27: =Source!I58 -> 3 | F27: =Source!U24 | G27: =Source!I58 -> 3
A28: 17 | B28: =Source!E60 -> 17 | C28: =Source!G60 -> Аппараты приемные, устройства промежуточные на 1 луч | D28: 1 ШТ. | E28: =Source!I60 -> 1 | F28: =Source!U24 | G28: =Source!I60 -> 1
A29: 18 | B29: =Source!E62 -> 18 | C29: =Source!G62 -> Адресный релейный модуль РМ-1-R3 Рубеж | D29: ШТ | E29: =Source!I62 -> 1 | F29: =Source!U24 | G29: =Source!I62 -> 1
A30: 19 | B30: =Source!E64 -> 19 | C30: =Source!G64 -> Аппараты приемные, устройства промежуточные на 1 луч | D30: 1 ШТ. | E30: =Source!I64 -> 2 | F30: =Source!U24 | G30: =Source!I64 -> 2
A31: 20 | B31: =Source!E66 -> 20 | C31: =Source!G66 -> Изолятор шлейфа ИЗ-1 прот. R3 | D31: ШТ | E31: =Source!I66 -> 2 | F31: =Source!U24 | G31: =Source!I66 -> 2
A32: 21 | B32: =Source!E68 -> 21 | C32: =Source!G68 -> Приборы и устройства сигнализирующие объектовые, устройства ультразвуковые, прибор ультразвуковой в одноблочном исполнении | D32: 1 ШТ. | E32: =Source!I68 -> 30 | F32: =Source!U24 | G32: =Source!I68 -> 30
A33: 22 | B33: =Source!E70 -> 22 | C33: =Source!G70 -> Извещатель охранный объемный оптико-электронный адресный ИО 40920-2 | D33: ШТ | E33: =Source!I70 -> 30 | F33: =Source!U24 | G33: =Source!I70 -> 30
A34: 23 | B34: =Source!E72 -> 23 | C34: =Source!G72 -> Извещатели ОС автоматические, контактный, магнито-контактный на открывание окон, дверей | D34: 1 ШТ. | E34: =Source!I72 -> 86 | F34: =Source!U24 | G34: =Source!I72 -> 86
A35: 24 | B35: =Source!E74 -> 24 | C35: =Source!G74 -> Извещатель охранный поверхностный звуковой адресный ИО 32920-2 | D35: ШТ | E35: =Source!I74 -> 86 | F35: =Source!U24 | G35: =Source!I74 -> 86
A36: 25 | B36: =Source!E76 -> 25 | C36: =Source!G76 -> Извещатели ОС автоматические, контактный, магнито-контактный на открывание окон, дверей | D36: 1 ШТ. | E36: =Source!I76 -> 90 | F36: =Source!U24 | G36: =Source!I76 -> 90
A37: 26 | B37: =Source!E78 -> 26 | C37: =Source!G78 -> Извещатель охранный магнитноуправляемый адресный ИО 10220-2 | D37: ШТ | E37: =Source!I78 -> 90 | F37: =Source!U24 | G37: =Source!I78 -> 90
A38: 27 | B38: =Source!E80 -> 27 | C38: =Source!G80 -> Аппараты приемные, устройства промежуточные на 1 луч | D38: 1 ШТ. | E38: =Source!I80 -> 9 | F38: =Source!U24 | G38: =Source!I80 -> 9
A39: 28 | B39: =Source!E82 -> 28 | C39: =Source!G82 -> Адресная метка, 4 шлейфа АМ-4-R3 | D39: ШТ | E39: =Source!I82 -> 9 | F39: =Source!U24 | G39: =Source!I82 -> 9
A40: 29 | B40: =Source!E84 -> 29 | C40: =Source!G84 -> Монтаж детали на пультах и панелях - кнопка | D40: 1 ШТ. | E40: =Source!I84 -> 10 | F40: =Source!U24 | G40: =Source!I84 -> 10
A41: 30 | B41: =Source!E86 -> 30 | C41: =Source!G86 -> Извещатель охранный ручной точечный электроконтактный Астра-321 (ИО 101-7) | D41: ШТ | E41: =Source!I86 -> 10 | F41: =Source!U24 | G41: =Source!I86 -> 10
A42: 31 | B42: =Source!E88 -> 31 | C42: =Source!G88 -> Монтаж светильников с лампами накаливания, светового настенного указателя | D42: 100 шт. | E42: =Source!I88 -> 0.01 | F42: =Source!U24 | G42: ="=1/"&"100" -> =1/100
A43: 32 | B43: =Source!E90 -> 32 | C43: =Source!G90 -> Световой оповещатель "Маяк-12-С" | D43: ШТ | E43: =Source!I90 -> 1 | F43: =Source!U24 | G43: =Source!I90 -> 1
A44: =CONCATENATE("Раздел: ", Source!G123) -> Раздел: Кабельные изделия СОТС
...

Sheet Source
A1: 0 | B1: Smeta.RU (495) 974-1589 | D1: _PS_ | F1: 0 | G1: 0 | H1: 0 | I1: Smeta.RU | K1: 1 | L1: 74563 | M1: 10 | N1: 12 | O1: 0 | P1: 0 | Q1: 3
A4: 1 | B4: 1 | C4: -1 | G4: Капитальный ремонт здания Государственного бюджетного общеобразовательного учреждения города Москвы "Школа №236" по адресу: г. Москва, улица Клязьминская, дом 7, корпус 4 | EC4: 0
A12: 1 | B12: 251 | C12: 0 | D12: =ROW(A212) -> 212 | E12: 0 | G12: 02-01-16 СОС | I12: 0 | J12: 2024-00272-00-ИОС5.8 | K12: 0 | L12: 0 | M12: 4098 | O12: 0 | P12: 0 | Q12: 0 | R12: 0 | S12: 0 | T12: 1 | V12: 0 | AB12: Соколова И.Н. | BB12: 0 | BH12: Сметные нормы списания | BI12: Коды ОКП для ТСН-2001 МГЭ Дополнение 80 | BJ12: 1 | BK12: 1 | BL12: 0 | BM12: 0 | BN12: 1 | BO12: 0 | BP12: 6 | BQ12: 2 | BR12: 1 | BS12: 1 | BT12: 0 | BU12: 0 | BV12: 0 | BW12: 0 | BX12: 0 | BZ12: Типовой расчет для ТСН-2001 МГЭ, Дополнение 80, строительство (1) | CA12: Территориальные сметные нормативы для Москвы ТСН-2001 (МГЭ), дополнение 80 | CB12: Территориальные сметные нормативы для Москвы ТСН-2001 (МГЭ), дополнение 80 | CC12: Территориальные сметные нормативы для Москвы ТСН-2001 (МГЭ), дополнение 80 | CD12: Территориальные сметные нормативы для Москвы ТСН-2001 (МГЭ), дополнение 80 | CE12: Поправки для ТСН-2001 от 28.11.2025 г. доп.79 | CF12: 0 | CG12: 0 | CH12: 8200 | CK12: 80 | CQ12: Территориальные сметные нормативы для Москвы (ТСН-2001) | CR12: ТЕР | CS12: 41660 | CT12: 1 | CU12: 80 | CY12: 0 | EC12: 0
A15: 15 | B15: 1
A18: 52 | B18: =B212 -> 251 | C18: =C212 -> 1 | D18: =D212 -> 12 | E18: =E212 -> 0 | F18: =F212 | G18: =G212 -> 02-01-16 СОС | O18: =O212 -> 116647.27 | P18: =P212 -> 101836.17 | Q18: =Q212 -> 1534.51 | R18: =R212 -> 330.33 | S18: =S212 -> 13276.59 | T18: =T212 -> 0 | U18: =U212 -> 1038.104 | V18: =V212 -> 0 | ... GX18: =GX212 -> 0
A20: 3 | B20: 1 | D20: =ROW(A182) -> 182 | F20: 02-01-16 | G20: Система охранно-тревожной сигнализации | I20: 0 | J20: 2024-00272-00-ИОС5.8 | K20: -1 | L20: 02-01-16 | S20: 0 | T20: 0 | V20: 2 | BX20: 0 | CF20: 0 | CG20: 0
A22: 52 | B22: =B182 -> 1 | C22: =C182 -> 3 | D22: =D182 -> 20 | E22: =E182 -> 0 | F22: =F182 -> 02-01-16 | G22: =G182 -> Система охранно-тревожной сигнализации | O22: =O182 -> 116647.27 | P22: =P182 -> 101836.17 | Q22: =Q182 -> 1534.51 | R22: =R182 -> 330.33 | S22: =S182 -> 13276.59 | T22: =T182 -> 0 | U22: =U182 -> 1038.104 | V22: =V182 -> 0 | ... GX22: =GX182 -> 0
A24: 4 | B24: 1 | D24: =ROW(A93) -> 93 | G24: Оборудование | I24: 0 | K24: -1 | S24: 0 | T24: 0 | V24: 2 | BX24: 0 | CJ24: 0
A26: 52 | B26: =B93 -> 1 | C26: =C93 -> 4 | D26: =D93 -> 24 | E26: =E93 -> 0 | F26: =F93 | G26: =G93 -> Оборудование | O26: =O93 -> 71809.67 | P26: =P93 -> 67074.95 | Q26: =Q93 -> 3.4 | R26: =R93 -> 0.32 | S26: =S93 -> 4731.32 | T26: =T93 -> 0 | U26: =U93 -> 366.82417 | V26: =V93 -> 0 | ... GX26: =GX93 -> 0
A28: 17 | B28: 1 | C28: =ROW(SmtRes!A5) -> 5 | D28: =ROW(EtalonRes!A7) -> 7 | E28: 1 | F28: 4.10-75-6 | G28: Монтаж аппаратуры настольной массой до 20 кг | H28: 1 ШТ. | I28: 1 | J28: 0 | K28: 1 | O28: =ROUND(CP28,2) -> 136.61 | P28: =ROUND((ROUND((AC28*AW28*I28),2)*BC28),2) -> 34.87 | Q28: =(ROUND((ROUND((((ET28*1.1))*AV28*I28),2)*BB28),2)+ROUND((ROUND(((AE28-((EU28*1.1)))*AV28*I28),2)*BS28),2)) -> 0 | R28: =(ROUND((ROUND((((EU28*1.1))*AV28*I28),2)*BS28),2)+ROUND((ROUND(((AE28-((EU28*1.1)))*AV28*I28),2)*BS28),2)) -> 0 | S28: =ROUND((ROUND((AF28*AV28*I28),2)*BA28),2) -> 101.74 | T28: =ROUND(CU28*I28,2) -> 0 | U28: =CV28*I28 -> 8.0619 | V28: =CW28*I28 -> 0 | W28: =ROUND(CX28*I28,2) -> 0 | X28: =(ROUND((((S28+ROUND((ROUND((((EU28*1.1))*AV28*I28),2)*BS28),2))*AT28)/100),2)+ROUND(((ROUND((ROUND(((AE28-((EU28*1.1)))*AV28*I28),2)*BS28),2)*AT28)/100),2)) -> 96.65 | Y28: =(ROUND((((S28+ROUND((ROUND((((EU28*1.1))*AV28*I28),2)*BS28),2))*AU28)/100),2)+ROUND(((ROUND((ROUND(((AE28-((EU28*1.1)))*AV28*I28),2)*BS28),2)*AU28)/100),2)) -> 53.92 | AA28: 60258621 | AB28: =ROUND((AC28+AD28+AF28),6) -> 132.044 | AC28: =ROUND(((ES28*1)),6) -> 34.87 | AD28: =ROUND(((((ET28*1.1))-((EU28*1.1)))+AE28),6) -> 0 | AE28: =ROUND(((EU28*1.1)),6) -> 0 | AF28: =ROUND(((EV28*1.1)),6) -> 97.174 | AG28: =ROUND((AP28),6) -> 0 | AH28: =((EW28*1.1)) -> 7.7 | AI28: =((EX28*1.1)) -> 0 | AJ28: =(AS28) -> 0 | AK28: 123.21 | AL28: 34.87 | AM28: 0 | AN28: 0 | AO28: 88.34 | AP28: 0 | AQ28: 7 | AR28: 0 | AS28: 0 | AT28: 95 | AU28: 53 | AV28: 1.047 | AW28: 1 | AZ28: 1 | BA28: 1 | BB28: 1 | BC28: 1 | BH28: 0 | BI28: 2 | BJ28: ТСН-2001.4 Доп. 79, Сб. 10, т. 75, поз. 6 | BM28: 69 | BN28: 58973116 | BO28: 4.10-75-6 | BP28: 1 | BQ28: 40 | BR28: 0 | BS28: 1 | BT28: 1 | BU28: 1 | BV28: 1 | BW28: 1 | BX28: 1 | BZ28: 95 | CA28: 53 | CE28: 1566 | CF28: 0 | CG28: 0 | CM28: 0 | CN28: Поправка: Гл.12.Прил.8.п.8. 5_12.00.01.11.003 Наименование: При наличии усложненных условий производства работ (стесненность, сложность складирования и транспортной логистики, наличие в зоне производства работ действующего технологического оборудования или движения технологического транспорта и т.п.) для объектов, расположенных за пределами территории круговой магистральной системы улиц "Садовое кольцо" и за пределами Третьего транспортного кольца города Москвы пунктов "а" и "б", но в пределах Московской кольцевой автомобильной дороги | CO28: 0 | CP28: =(P28+Q28+S28) -> 136.61 | CQ28: =ROUND((ROUND((AC28*AW28*1),2)*BC28),2) -> 34.87 | CR28: =(ROUND((ROUND((((ET28*1.1))*AV28*1),2)*BB28),2)+ROUND((ROUND(((AE28-((EU28*1.1)))*AV28*1),2)*BS28),2)) -> 0 | CS28: =(ROUND((ROUND((((EU28*1.1))*AV28*1),2)*BS28),2)+ROUND((ROUND(((AE28-((EU28*1.1)))*AV28*1),2)*BS28),2)) -> 0 | CT28: =ROUND((ROUND((AF28*AV28*1),2)*BA28),2) -> 101.74 | CU28: =AG28 -> 0 | CV28: =(AH28*AV28) -> 8.0619 | CW28: =AI28 -> 0 | CX28: =AJ28 -> 0 | CY28: =(ROUND((((S28+ROUND((ROUND((((EU28*1.1))*AV28*1),2)*BS28),2))*AT28)/100),2)+ROUND(((ROUND((ROUND(((AE28-((EU28*1.1)))*AV28*1),2)*BS28),2)*AT28)/100),2)) -> 96.65 | CZ28: =(ROUND((((S28+ROUND((ROUND((((EU28*1.1))*AV28*1),2)*BS28),2))*AU28)/100),2)+ROUND(((ROUND((ROUND(((AE28-((EU28*1.1)))*AV28*1),2)*BS28),2)*AU28)/100),2)) -> 53.92 | DB28: 1 | DD28: *1 | DE28: *1,1 | DF28: *1,1 | DG28: *1,1 | DI28: *1,1 | DJ28: *1,1 | DN28: 0 | DO28: 0 | DP28: 1 | DQ28: 1 | DU28: 1013 | DV28: 1 ШТ. | DW28: 1 ШТ. | DX28: 1 | EE28: 60088533 | EF28: 40 | EG28: Монтаж оборудования | EH28: 0 | EJ28: 2 | EK28: 69 | EL28: ТСН-2001.4-10. Монтаж радиотелевизионного и электронного оборудования | EM28: ТСН-2001.4-10-2 | EO28: Поправка: Гл.12.Прил.8.п.8. 5_12.00.01.11.003 | EQ28: 0 | ER28: 123.21 | ES28: 34.87 | ET28: 0 | EU28: 0 | EV28: 88.34 | EW28: 7 | EX28: 0 | EY28: 0 | FQ28: 0 | FR28: 0 | FS28: 0 | FX28: 95 | FY28: 53 | GD28: 1 | GF28: 1652728637 | GG28: 2 | GH28: 1 | GI28: 2 | GJ28: 0 | GK28: 0 | GL28: =ROUND(IF(AND(BH28=3,BI28=3,FS28<>0),P28,0),2) -> 0 | GM28: =ROUND(O28+X28+Y28,2)+GX28 -> 287.18 | GN28: =IF(OR(BI28=0,BI28=1),GM28-GX28,0) -> 0 | GO28: =IF(BI28=2,GM28-GX28,0) -> 287.18 | GP28: =IF(BI28=4,GM28-GX28,0) -> 0 | GR28: 0 | GS28: 3 | GT28: 0 | GV28: =ROUND((GT28),6) -> 0 | GW28: 1 | GX28: =ROUND(HC28*I28,2) -> 0 | HA28: 0 | HB28: 0 | HC28: =GV28*GW28 -> 0 | HS28: 0 | IK28: 0
A29: 17 | B29: 1 | C29: =ROW(SmtRes!A10) -> 10 | D29: =ROW(EtalonRes!A14) -> 14 | E29: 1 | F29: 4.10-75-6 | G29: Монтаж аппаратуры настольной массой до 20 кг | H29: 1 ШТ. | I29: 1 | J29: 0 | K29: 1 | O29: =ROUND(CP29,2) -> 5990.45 | P29: =ROUND((ROUND((AC29*AW29*I29),2)*BC29),2) -> 395.77 | Q29: =(ROUND((ROUND((((ET29*1.1))*AV29*I29),2)*BB29),2)+ROUND((ROUND(((AE29-((EU29*1.1)))*AV29*I29),2)*BS29),2)) -> 0 | R29: =(ROUND((ROUND((((EU29*1.1))*AV29*I29),2)*BS29),2)+ROUND((ROUND(((AE29-((EU29*1.1)))*AV29*I29),2)*BS29),2)) -> 0 | S29: =ROUND((ROUND((AF29*AV29*I29),2)*BA29),2) -> 5594.68 | T29: =ROUND(CU29*I29,2) -> 0 | U29: =CV29*I29 -> 8.0619 | V29: =CW29*I29 -> 0 | W29: =ROUND(CX29*I29,2) -> 0 | X29: =(ROUND((((S29+ROUND((ROUND((((EU29*1.1))*AV29*I29),2)*BS29),2))*AT29)/100),2)+ROUND(((ROUND((ROUND(((AE29-((EU29*1.1)))*AV29*I29),2)*BS29),2)*AT29)/100),2)) -> 5314.95 | Y29: =(ROUND((((S29+ROUND((ROUND((((EU29*1.1))*AV29*I29),2)*BS29),2))*AU29)/100),2)+ROUND(((ROUND((ROUND(((AE29-((EU29*1.1)))*AV29*I29),2)*BS29),2)*AU29)/100),2)) -> 2965.18 | AA29: 60258618 | AB29: =ROUND((AC29+AD29+AF29),6) -> 132.044 | AC29: =ROUND(((ES29*1)),6) -> 34.87 | AD29: =ROUND(((((ET29*1.1))-((EU29*1.1)))+AE29),6) -> 0 | AE29: =ROUND(((EU29*1.1)),6) -> 0 | AF29: =ROUND(((EV29*1.1)),6) -> 97.174 | AG29: =ROUND((AP29),6) -> 0 | AH29: =((EW29*1.1)) -> 7.7 | AI29: =((EX29*1.1)) -> 0 | AJ29: =(AS29) -> 0 | AK29: 123.21 | AL29: 34.87 | AM29: 0 | AN29: 0 | AO29: 88.34 | AP29: 0 | AQ29: 7 | AR29: 0 | AS29: 0 | AT29: 95 | AU29: 53 | AV29: 1.047 | AW29: 1 | AZ29: 1 | BA29: 54.99 | BB29: 1 | BC29: 11.35 | BH29: 0 | BI29: 2 | BJ29: ТСН-2001.4 Доп. 79, Сб. 10, т. 75, поз. 6 | BM29: 69 | BN29: 58973116 | BO29: 4.10-75-6 | BP29: 1 | BQ29: 40 | BR29: 0 | BS29: 54.99 | BT29: 1 | BU29: 1 | BV29: 1 | BW29: 1 | BX29: 1 | BZ29: 95 | CA29: 53 | CE29: 1566 | CF29: 0 | CG29: 0 | CM29: 0 | CN29: Поправка: Гл.12.Прил.8.п.8. 5_12.00.01.11.003 Наименование: При наличии усложненных условий производства работ (стесненность, сложность складирования и транспортной логистики, наличие в зоне производства работ действующего технологического оборудования или движения технологического транспорта и т.п.) для объектов, расположенных за пределами территории круговой магистральной системы улиц "Садовое кольцо" и за пределами Третьего транспортного кольца города Москвы пунктов "а" и "б", но в пределах Московской кольцевой автомобильной дороги | CO29: 0 | CP29: =(P29+Q29+S29) -> 5990.45 | CQ29: =ROUND((ROUND((AC29*AW29*1),2)*BC29),2) -> 395.77 | CR29: =(ROUND((ROUND((((ET29*1.1))*AV29*1),2)*BB29),2)+ROUND((ROUND(((AE29-((EU29*1.1)))*AV29*1),2)*BS29),2)) -> 0 | CS29: =(ROUND((ROUND((((EU29*1.1))*AV29*1),2)*BS29),2)+ROUND((ROUND(((AE29-((EU29*1.1)))*AV29*1),2)*BS29),2)) -> 0 | CT29: =ROUND((ROUND((AF29*AV29*1),2)*BA29),2) -> 5594.68 | CU29: =AG29 -> 0 | CV29: =(AH29*AV29) -> 8.0619 | CW29: =AI29 -> 0 | CX29: =AJ29 -> 0 | CY29: =(ROUND((((S29+ROUND((ROUND((((EU29*1.1))*AV29*1),2)*BS29),2))*AT29)/100),2)+ROUND(((ROUND((ROUND(((AE29-((EU29*1.1)))*AV29*1),2)*BS29),2)*AT29)/100),2)) -> 5314.95 | CZ29: =(ROUND((((S29+ROUND((ROUND((((EU29*1.1))*AV29*1),2)*BS29),2))*AU29)/100),2)+ROUND(((ROUND((ROUND(((AE29-((EU29*1.1)))*AV29*1),2)*BS29),2)*AU29)/100),2)) -> 2965.18 | DB29: 2 | DD29: *1 | DE29: *1,1 | DF29: *1,1 | DG29: *1,1 | DI29: *1,1 | DJ29: *1,1 | DN29: 0 | DO29: 0 | DP29: 1 | DQ29: 1 | DU29: 1013 | DV29: 1 ШТ. | DW29: 1 ШТ. | DX29: 1 | EE29: 60088533 | EF29: 40 | EG29: Монтаж оборудования | EH29: 0 | EJ29: 2 | EK29: 69 | EL29: ТСН-2001.4-10. Монтаж радиотелевизионного и электронного оборудования | EM29: ТСН-2001.4-10-2 | EO29: Поправка: Гл.12.Прил.8.п.8. 5_12.00.01.11.003 | EQ29: 0 | ER29: 123.21 | ES29: 34.87 | ET29: 0 | EU29: 0 | EV29: 88.34 | EW29: 7 | EX29: 0 | EY29: 0 | FQ29: 0 | FR29: 0 | FS29: 0 | FX29: 95 | FY29: 53 | GD29: 1 | GF29: 1652728637 | GG29: 2 | GH29: 1 | GI29: 2 | GJ29: 0 | GK29: 0 | GL29: =ROUND(IF(AND(BH29=3,BI29=3,FS29<>0),P29,0),2) -> 0 | GM29: =ROUND(O29+X29+Y29,2)+GX29 -> 14270.58 | GN29: =IF(OR(BI29=0,BI29=1),GM29-GX29,0) -> 0 | GO29: =IF(BI29=2,GM29-GX29,0) -> 14270.58 | GP29: =IF(BI29=4,GM29-GX29,0) -> 0 | GR29: 0 | GS29: 3 | GT29: 0 | GV29: =ROUND((GT29),6) -> 0 | GW29: 1 | GX29: =ROUND(HC29*I29,2) -> 0 | HA29: 0 | HB29: 0 | HC29: =GV29*GW29 -> 0 | HS29: 0 | IK29: 0
A30: 17 | B30: 1 | E30: 2 | F30: КА-1 | G30: Компьютер персональный АРМ DEPO ПЕРЕСВЕТ 110D11 (системный блок, монитор 21,5", клавиатура, мышь) | H30: ШТ | I30: 1 | J30: 0 | K30: 1 | O30: =ROUND(CP30,2) -> 8561.59 | P30: =ROUND((ROUND((AC30*I30),2)*BC30),2) -> 8561.59 | Q30: =(ROUND((ROUND(((ET30)*AV30*I30),2)*BB30),2)+ROUND((ROUND(((AE30-(EU30))*AV30*I30),2)*BS30),2)) -> 0 | R30: =(ROUND((ROUND(((EU30)*AV30*I30),2)*BS30),2)+ROUND((ROUND(((AE30-(EU30))*AV30*I30),2)*BS30),2)) -> 0 | S30: =ROUND((ROUND((AF30*AV30*I30),2)*BA30),2) -> 0 | T30: =ROUND(CU30*I30,2) -> 0 | U30: =CV30*I30 -> 0 | V30: =CW30*I30 -> 0 | W30: =ROUND(CX30*I30,2) -> 0 | X30: =(ROUND((((S30+ROUND((ROUND(((EU30)*AV30*I30),2)*BS30),2))*AT30)/100),2)+ROUND(((ROUND((ROUND(((AE30-(EU30))*AV30*I30),2)*BS30),2)*AT30)/100),2)) -> 0 | Y30: =(ROUND((((S30+ROUND((ROUND(((EU30)*AV30*I30),2)*BS30),2))*AU30)/100),2)+ROUND(((ROUND((ROUND(((AE30-(EU30))*AV30*I30),2)*BS30),2)*AU30)/100),2)) -> 0 | AA30: 60258621 | AB30: =ROUND((AC30+AD30+AF30),6) -> 8561.59 | AC30: =ROUND((ES30),6) -> 8561.59 | AD30: =ROUND((((ET30)-(EU30))+AE30),6) -> 0 | AE30: =ROUND((EU30),6) -> 0 | AF30: =ROUND((EV30),6) -> 0 | AG30: =ROUND((AP30),6) -> 0 | AH30: =(EW30) -> 0 | AI30: =(EX30) -> 0 | AJ30: =(AS30) -> 0 | AK30: 8561.59 | AL30: 8561.59 | AM30: 0 | AN30: 0 | AO30: 0 | AP30: 0 | AQ30: 0 | AR30: 0 | AS30: 0 | AT30: 0 | AU30: 0 | AV30: 1 | AW30: 1 | AZ30: 1 | BA30: 1 | BB30: 1 | BC30: 1 | BH30: 3 | BI30: 3 | BM30: 746 | BN30: 0 | BP30: 0 | BQ30: 130 | BR30: 0 | BS30: 1 | BT30: 1 | BU30: 1 | BV30: 1 | BW30: 1 | BX30: 1 | BZ30: 0 | CA30: 0 | CE30: 1566 | CF30: 0 | CG30: 0 | CM30: 0 | CO30: 0 | CP30: =(P30+Q30+S30) -> 8561.59 | CQ30: =ROUND((ROUND((AC30*1),2)*BC30),2) -> 8561.59 | CR30: =(ROUND((ROUND(((ET30)*AV30*1),2)*BB30),2)+ROUND((ROUND(((AE30-(EU30))*AV30*1),2)*BS30),2)) -> 0 | CS30: =(ROUND((ROUND(((EU30)*AV30*1),2)*BS30),2)+ROUND((ROUND(((AE30-(EU30))*AV30*1),2)*BS30),2)) -> 0 | CT30: =ROUND((ROUND((AF30*AV30*1),2)*BA30),2) -> 0 | CU30: =AG30 -> 0 | CV30: =(AH30*AV30) -> 0 | CW30: =AI30 -> 0 | CX30: =AJ30 -> 0 | CY30: =(ROUND((((S30+ROUND((ROUND(((EU30)*AV30*1),2)*BS30),2))*AT30)/100),2)+ROUND(((ROUND((ROUND(((AE30-(EU30))*AV30*1),2)*BS30),2)*AT30)/100),2)) -> 0 | CZ30: =(ROUND((((S30+ROUND((ROUND(((EU30)*AV30*1),2)*BS30),2))*AU30)/100),2)+ROUND(((ROUND((ROUND(((AE30-(EU30))*AV30*1),2)*BS30),2)*AU30)/100),2)) -> 0 | DN30: 0 | DO30: 0 | DP30: 1 | DQ30: 1 | DU30: 1013 | DV30: ШТ | DW30: ШТ | DX30: 1 | EE30: 60088638 | EF30: 130 | EG30: Сметная стоимость оборудования | EH30: 0 | EJ30: 3 | EK30: 746 | EL30: ТСН-2001.13. Сметная стоимость оборудования | EM30: ТСН-2001.13 | EQ30: 0 | ER30: 0 | ES30: 8561.59 | ET30: 0 | EU30: 0 | EV30: 0 | EW30: 0 | EX30: 0 | EY30: 0 | FQ30: 0 | FR30: =P30 -> 8561.59 | FS30: 0 | FX30: 0 | FY30: 0 | GA30: [75 500 / 1,2 / 7,66] + 3% Трансп + 1,2% Заг.скл | GD30: 1 | GF30: 521336863 | GG30: 2 | GH30: 4 | GI30: -2 | GJ30: 0 | GK30: 0 | GL30: =ROUND(IF(AND(BH30=3,BI30=3,FS30<>0),P30,0),2) -> 0 | GM30: =ROUND(O30+X30+Y30,2)+GX30 -> 8561.59 | GN30: =IF(OR(BI30=0,BI30=1),GM30-GX30,0) -> 0 | GO30: =IF(BI30=2,GM30-GX30,0) -> 0 | GP30: =IF(BI30=4,GM30-GX30,0) -> 0 | GR30: 0 | GS30: 2 | GT30: 0 | GV30: =ROUND((GT30),6) -> 0 | GW30: 1 | GX30: =ROUND(HC30*I30,2) -> 0 | HA30: 0 | HB30: 0 | HC30: =GV30*GW30 -> 0 | HE30: 3 | HF30: 1,2 | HS30: 0 | IK30: 0
A31: 17 | B31: 1 | E31: 2 | F31: КА-1 | G31: Компьютер персональный АРМ DEPO ПЕРЕСВЕТ 110D11 (системный блок, монитор 21,5", клавиатура, мышь) | H31: ШТ | I31: 1 | J31: 0 | K31: 1 | O31: =ROUND(CP31,2) -> 65581.78 | P31: =ROUND((ROUND((AC31*I31),2)*BC31),2) -> 65581.78 | Q31: =(ROUND((ROUND(((ET31)*AV31*I31),2)*BB31),2)+ROUND((ROUND(((AE31-(EU31))*AV31*I31),2)*BS31),2)) -> 0 | R31: =(ROUND((ROUND(((EU31)*AV31*I31),2)*BS31),2)+ROUND((ROUND(((AE31-(EU31))*AV31*I31),2)*BS31),2)) -> 0 | S31: =ROUND((ROUND((AF31*AV31*I31),2)*BA31),2) -> 0 | T31: =ROUND(CU31*I31,2) -> 0 | U31: =CV31*I31 -> 0 | V31: =CW31*I31 -> 0 | W31: =ROUND(CX31*I31,2) -> 0 | X31: =(ROUND((((S31+ROUND((ROUND(((EU31)*AV31*I31),2)*BS31),2))*AT31)/100),2)+ROUND(((ROUND((ROUND(((AE31-(EU31))*AV31*I31),2)*BS31),2)*AT31)/100),2)) -> 0 | Y31: =(ROUND((((S31+ROUND((ROUND(((EU31)*AV31*I31),2)*BS31),2))*AU31)/100),2)+ROUND(((ROUND((ROUND(((AE31-(EU31))*AV31*I31),2)*BS31),2)*AU31)/100),2)) -> 0 | AA31: 60258618 | AB31: =ROUND((AC31+AD31+AF31),6) -> 8561.59 | AC31: =ROUND((ES31),6) -> 8561.59 | AD31: =ROUND((((ET31)-(EU31))+AE31),6) -> 0 | AE31: =ROUND((EU31),6) -> 0 | AF31: =ROUND((EV31),6) -> 0 | AG31: =ROUND((AP31),6) -> 0 | AH31: =(EW31) -> 0 | AI31: =(EX31) -> 0 | AJ31: =(AS31) -> 0 | AK31: 8561.59 | AL31: 8561.59 | AM31: 0 | AN31: 0 | AO31: 0 | AP31: 0 | AQ31: 0 | AR31: 0 | AS31: 0 | AT31: 0 | AU31: 0 | AV31: 1 | AW31: 1 | AZ31: 1 | BA31: 1 | BB31: 1 | BC31: 7.66 | BH31: 3 | BI31: 3 | BM31: 746 | BN31: 0 | BP31: 0 | BQ31: 130 | BR31: 0 | BS31: 1 | BT31: 1 | BU31: 1 | BV31: 1 | BW31: 1 | BX31: 1 | BZ31: 0 | CA31: 0 | CE31: 1566 | CF31: 0 | CG31: 0 | CM31: 0 | CO31: 0 | CP31: =(P31+Q31+S31) -> 65581.78 | CQ31: =ROUND((ROUND((AC31*1),2)*BC31),2) -> 65581.78 | CR31: =(ROUND((ROUND(((ET31)*AV31*1),2)*BB31),2)+ROUND((ROUND(((AE31-(EU31))*AV31*1),2)*BS31),2)) -> 0 | CS31: =(ROUND((ROUND(((EU31)*AV31*1),2)*BS31),2)+ROUND((ROUND(((AE31-(EU31))*AV31*1),2)*BS31),2)) -> 0 | CT31: =ROUND((ROUND((AF31*AV31*1),2)*BA31),2) -> 0 | CU31: =AG31 -> 0 | CV31: =(AH31*AV31) -> 0 | CW31: =AI31 -> 0 | CX31: =AJ31 -> 0 | CY31: =(ROUND((((S31+ROUND((ROUND(((EU31)*AV31*1),2)*BS31),2))*AT31)/100),2)+ROUND(((ROUND((ROUND(((AE31-(EU31))*AV31*1),2)*BS31),2)*AT31)/100),2)) -> 0 | CZ31: =(ROUND((((S31+ROUND((ROUND(((EU31)*AV31*1),2)*BS31),2))*AU31)/100),2)+ROUND(((ROUND((ROUND(((AE31-(EU31))*AV31*1),2)*BS31),2)*AU31)/100),2)) -> 0 | DN31: 0 | DO31: 0 | DP31: 1 | DQ31: 1 | DU31: 1013 | DV31: ШТ | DW31: ШТ | DX31: 1 | EE31: 60088638 | EF31: 130 | EG31: Сметная стоимость оборудования | EH31: 0 | EJ31: 3 | EK31: 746 | EL31: ТСН-2001.13. Сметная стоимость оборудования | EM31: ТСН-2001.13 | EQ31: 0 | ER31: 0 | ES31: 8561.59 | ET31: 0 | EU31: 0 | EV31: 0 | EW31: 0 | EX31: 0 | EY31: 0 | EZ31: 5 | FC31: 1 | FD31: 18 | FF31: 75500 | FQ31: 0 | FR31: =P31 -> 65581.78 | FS31: 0 | FX31: 0 | FY31: 0 | GA31: [75 500 / 1,2 / 7,66] + 3% Трансп + 1,2% Заг.скл | GD31: 1 | GF31: 521336863 | GG31: 2 | GH31: 3 | GI31: 5 | GJ31: 0 | GK31: 0 | GL31: =ROUND(IF(AND(BH31=3,BI31=3,FS31<>0),P31,0),2) -> 0 | GM31: =ROUND(O31+X31+Y31,2)+GX31 -> 65581.78 | GN31: =IF(OR(BI31=0,BI31=1),GM31-GX31,0) -> 0 | GO31: =IF(BI31=2,GM31-GX31,0) -> 0 | GP31: =IF(BI31=4,GM31-GX31,0) -> 0 | GR31: 1 | GS31: 1 | GT31: 0 | GV31: =ROUND((GT31),6) -> 0 | GW31: 1 | GX31: =ROUND(HC31*I31,2) -> 0 | HA31: 0 | HB31: 0 | HC31: =GV31*GW31 -> 0 | HE31: 3 | HF31: 1,2 | HS31: 0 | IK31: 0
A32: 17 | B32: 1 | E32: 3 | F32: КА-2 | G32: Операционная система REDOS-DSP-STD-BAS-VDI | H32: ШТ | I32: 1 | J32: 0 | K32: 1 | O32: =ROUND(CP32,2) -> 1655.62 | P32: =ROUND((ROUND((AC32*I32),2)*BC32),2) -> 1655.62 | Q32: =(ROUND((ROUND(((ET32)*AV32*I32),2)*BB32),2)+ROUND((ROUND(((AE32-(EU32))*AV32*I32),2)*BS32),2)) -> 0 | R32: =(ROUND((ROUND(((EU32)*AV32*I32),2)*BS32),2)+ROUND((ROUND(((AE32-(EU32))*AV32*I32),2)*BS32),2)) -> 0 | S32: =ROUND((ROUND((AF32*AV32*I32),2)*BA32),2) -> 0 | T32: =ROUND(CU32*I32,2) -> 0 | U32: =CV32*I32 -> 0 | V32: =CW32*I32 -> 0 | W32: =ROUND(CX32*I32,2) -> 0 | X32: =(ROUND((((S32+ROUND((ROUND(((EU32)*AV32*I32),2)*BS32),2))*AT32)/100),2)+ROUND(((ROUND((ROUND(((AE32-(EU32))*AV32*I32),2)*BS32),2)*AT32)/100),2)) -> 0 | Y32: =(ROUND((((S32+ROUND((ROUND(((EU32)*AV32*I32),2)*BS32),2))*AU32)/100),2)+ROUND(((ROUND((ROUND(((AE32-(EU32))*AV32*I32),2)*BS32),2)*AU32)/100),2)) -> 0 | AA32: 60258621 | AB32: =ROUND((AC32+AD32+AF32),6) -> 1655.62 | AC32: =ROUND((ES32),6) -> 1655.62 | AD32: =ROUND((((ET32)-(EU32))+AE32),6) -> 0 | AE32: =ROUND((EU32),6) -> 0 | AF32: =ROUND((EV32),6) -> 0 | AG32: =ROUND((AP32),6) -> 0 | AH32: =(EW32) -> 0 | AI32: =(EX32) -> 0 | AJ32: =(AS32) -> 0 | AK32: 1655.62 | AL32: 1655.62 | AM32: 0 | AN32: 0 | AO32: 0 | AP32: 0 | AQ32: 0 | AR32: 0 | AS32: 0 | AT32: 0 | AU32: 0 | AV32: 1 | AW32: 1 | AZ32: 1 | BA32: 1 | BB32: 1 | BC32: 1 | BH32: 3 | BI32: 3 | BM32: 746 | BN32: 0 | BP32: 0 | BQ32: 130 | BR32: 0 | BS32: 1 | BT32: 1 | BU32: 1 | BV32: 1 | BW32: 1 | BX32: 1 | BZ32: 0 | CA32: 0 | CE32: 1566 | CF32: 0 | CG32: 0 | CM32: 0 | CO32: 0 | CP32: =(P32+Q32+S32) -> 1655.62 | CQ32: =ROUND((ROUND((AC32*1),2)*BC32),2) -> 1655.62 | CR32: =(ROUND((ROUND(((ET32)*AV32*1),2)*BB32),2)+ROUND((ROUND(((AE32-(EU32))*AV32*1),2)*BS32),2)) -> 0 | CS32: =(ROUND((ROUND(((EU32)*AV32*1),2)*BS32),2)+ROUND((ROUND(((AE32-(EU32))*AV32*1),2)*BS32),2)) -> 0 | CT32: =ROUND((ROUND((AF32*AV32*1),2)*BA32),2) -> 0 | CU32: =AG32 -> 0 | CV32: =(AH32*AV32) -> 0 | CW32: =AI32 -> 0 | CX32: =AJ32 -> 0 | CY32: =(ROUND((((S32+ROUND((ROUND(((EU32)*AV32*1),2)*BS32),2))*AT32)/100),2)+ROUND(((ROUND((ROUND(((AE32-(EU32))*AV32*1),2)*BS32),2)*AT32)/100),2)) -> 0 | CZ32: =(ROUND((((S32+ROUND((ROUND(((EU32)*AV32*1),2)*BS32),2))*AU32)/100),2)+ROUND(((ROUND((ROUND(((AE32-(EU32))*AV32*1),2)*BS32),2)*AU32)/100),2)) -> 0 | DN32: 0 | DO32: 0 | DP32: 1 | DQ32: 1 | DU32: 1013 | DV32: ШТ | DW32: ШТ | DX32: 1 | EE32: 60088638 | EF32: 130 | EG32: Сметная стоимость оборудования | EH32: 0 | EJ32: 3 | EK32: 746 | EL32: ТСН-2001.13. Сметная стоимость оборудования | EM32: ТСН-2001.13 | EQ32: 0 | ER32: 0 | ES32: 1655.62 | ET32: 0 | EU32: 0 | EV32: 0 | EW32: 0 | EX32: 0 | EY32: 0 | FQ32: 0 | FR32: =P32 -> 1655.62 | FS32: 0 | FX32: 0 | FY32: 0 | GA32: [14 600 / 1,2 / 7,66] + 3% Трансп + 1,2% Заг.скл | GD32: 1 | GF32: 963458923 | GG32: 2 | GH32: 4 | GI32: -2 | GJ32: 0 | GK32: 0 | GL32: =ROUND(IF(AND(BH32=3,BI32=3,FS32<>0),P32,0),2) -> 0 | GM32: =ROUND(O32+X32+Y32,2)+GX32 -> 1655.62 | GN32: =IF(OR(BI32=0,BI32=1),GM32-GX32,0) -> 0 | GO32: =IF(BI32=2,GM32-GX32,0) -> 0 | GP32: =IF(BI32=4,GM32-GX32,0) -> 0 | GR32: 0 | GS32: 2 | GT32: 0 | GV32: =ROUND((GT32),6) -> 0 | GW32: 1 | GX32: =ROUND(HC32*I32,2) -> 0 | HA32: 0 | HB32: 0 | HC32: =GV32*GW32 -> 0 | HE32: 3 | HF32: 1,2 | HS32: 0 | IK32: 0
A33: 17 | B33: 1 | E33: 3 | F33: КА-2 | G33: Операционная система REDOS-DSP-STD-BAS-VDI | H33: ШТ | I33: 1 | J33: 0 | K33: 1 | O33: =ROUND(CP33,2) -> 12682.05 | P33: =ROUND((ROUND((AC33*I33),2)*BC33),2) -> 12682.05 | Q33: =(ROUND((ROUND(((ET33)*AV33*I33),2)*BB33),2)+ROUND((ROUND(((AE33-(EU33))*AV33*I33),2)*BS33),2)) -> 0 | R33: =(ROUND((ROUND(((EU33)*AV33*I33),2)*BS33),2)+ROUND((ROUND(((AE33-(EU33))*AV33*I33),2)*BS33),2)) -> 0 | S33: =ROUND((ROUND((AF33*AV33*I33),2)*BA33),2) -> 0 | T33: =ROUND(CU33*I33,2) -> 0 | U33: =CV33*I33 -> 0 | V33: =CW33*I33 -> 0 | W33: =ROUND(CX33*I33,2) -> 0 | X33: =(ROUND((((S33+ROUND((ROUND(((EU33)*AV33*I33),2)*BS33),2))*AT33)/100),2)+ROUND(((ROUND((ROUND(((AE33-(EU33))*AV33*I33),2)*BS33),2)*AT33)/100),2)) -> 0 | Y33: =(ROUND((((S33+ROUND((ROUND(((EU33)*AV33*I33),2)*BS33),2))*AU33)/100),2)+ROUND(((ROUND((ROUND(((AE33-(EU33))*AV33*I33),2)*BS33),2)*AU33)/100),2)) -> 0 | AA33: 60258618 | AB33: =ROUND((AC33+AD33+AF33),6) -> 1655.62 | AC33: =ROUND((ES33),6) -> 1655.62 | AD33: =ROUND((((ET33)-(EU33))+AE33),6) -> 0 | AE33: =ROUND((EU33),6) -> 0 | AF33: =ROUND((EV33),6) -> 0 | AG33: =ROUND((AP33),6) -> 0 | AH33: =(EW33) -> 0 | AI33: =(EX33) -> 0 | AJ33: =(AS33) -> 0 | AK33: 1655.62 | AL33: 1655.62 | AM33: 0 | AN33: 0 | AO33: 0 | AP33: 0 | AQ33: 0 | AR33: 0 | AS33: 0 | AT33: 0 | AU33: 0 | AV33: 1 | AW33: 1 | AZ33: 1 | BA33: 1 | BB33: 1 | BC33: 7.66 | BH33: 3 | BI33: 3 | BM33: 746 | BN33: 0 | BP33: 0 | BQ33: 130 | BR33: 0 | BS33: 1 | BT33: 1 | BU33: 1 | BV33: 1 | BW33: 1 | BX33: 1 | BZ33: 0 | CA33: 0 | CE33: 1566 | CF33: 0 | CG33: 0 | CM33: 0 | CO33: 0 | CP33: =(P33+Q33+S33) -> 12682.05 | CQ33: =ROUND((ROUND((AC33*1),2)*BC33),2) -> 12682.05 | CR33: =(ROUND((ROUND(((ET33)*AV33*1),2)*BB33),2)+ROUND((ROUND(((AE33-(EU33))*AV33*1),2)*BS33),2)) -> 0 | CS33: =(ROUND((ROUND(((EU33)*AV33*1),2)*BS33),2)+ROUND((ROUND(((AE33-(EU33))*AV33*1),2)*BS33),2)) -> 0 | CT33: =ROUND((ROUND((AF33*AV33*1),2)*BA33),2) -> 0 | CU33: =AG33 -> 0 | CV33: =(AH33*AV33) -> 0 | CW33: =AI33 -> 0 | CX33: =AJ33 -> 0 | CY33: =(ROUND((((S33+ROUND((ROUND(((EU33)*AV33*1),2)*BS33),2))*AT33)/100),2)+ROUND(((ROUND((ROUND(((AE33-(EU33))*AV33*1),2)*BS33),2)*AT33)/100),2)) -> 0 | CZ33: =(ROUND((((S33+ROUND((ROUND(((EU33)*AV33*1),2)*BS33),2))*AU33)/100),2)+ROUND(((ROUND((ROUND(((AE33-(EU33))*AV33*1),2)*BS33),2)*AU33)/100),2)) -> 0 | DN33: 0 | DO33: 0 | DP33: 1 | DQ33: 1 | DU33: 1013 | DV33: ШТ | DW33: ШТ | DX33: 1 | EE33: 60088638 | EF33: 130 | EG33: Сметная стоимость оборудования | EH33: 0 | EJ33: 3 | EK33: 746 | EL33: ТСН-2001.13. Сметная стоимость оборудования | EM33: ТСН-2001.13 | EQ33: 0 | ER33: 0 | ES33: 1655.62 | ET33: 0 | EU33: 0 | EV33: 0 | EW33: 0 | EX33: 0 | EY33: 0 | EZ33: 5 | FC33: 1 | FD33: 18 | FF33: 14600 | FQ33: 0 | FR33: =P33 -> 12682.05 | FS33: 0 | FX33: 0 | FY33: 0 | GA33: [14 600 / 1,2 / 7,66] + 3% Трансп + 1,2% Заг.скл | GD33: 1 | GF33: 963458923 | GG33: 2 | GH33: 3 | GI33: 5 | GJ33: 0 | GK33: 0 | GL33: =ROUND(IF(AND(BH33=3,BI33=3,FS33<>0),P33,0),2) -> 0 | GM33: =ROUND(O33+X33+Y33,2)+GX33 -> 12682.05 | GN33: =IF(OR(BI33=0,BI33=1),GM33-GX33,0) -> 0 | GO33: =IF(BI33=2,GM33-GX33,0) -> 0 | GP33: =IF(BI33=4,GM33-GX33,0) -> 0 | GR33: 1 | GS33: 1 | GT33: 0 | GV33: =ROUND((GT33),6) -> 0 | GW33: 1 | GX33: =ROUND(HC33*I33,2) -> 0 | HA33: 0 | HB33: 0 | HC33: =GV33*GW33 -> 0 | HE33: 3 | HF33: 1,2 | HS33: 0 | IK33: 0
A34: 17 | B34: 1 | C34: =ROW(SmtRes!A14) -> 14 | D34: =ROW(EtalonRes!A19) -> 19 | E34: 4 | F34: 4.10-173-2 | G34: Монтаж блока бесперебойного питания (ББП) в диспетчерской | H34: 1 ШТ. | I34: 1 | J34: 0 | K34: 1 | O34: =ROUND(CP34,2) -> 48.6 | P34: =ROUND((ROUND((AC34*AW34*I34),2)*BC34),2) -> 2.34 | Q34: =(ROUND((ROUND((((ET34*1.1))*AV34*I34),2)*BB34),2)+ROUND((ROUND(((AE34-((EU34*1.1)))*AV34*I34),2)*BS34),2)) -> 0 | R34: =(ROUND((ROUND((((EU34*1.1))*AV34*I34),2)*BS34),2)+ROUND((ROUND(((AE34-((EU34*1.1)))*AV34*I34),2)*BS34),2)) -> 0 | S34: =ROUND((ROUND((AF34*AV34*I34),2)*BA34),2) -> 46.26 | T34: =ROUND(CU34*I34,2) -> 0 | U34: =CV34*I34 -> 3.662406 | V34: =CW34*I34 -> 0 | W34: =ROUND(CX34*I34,2) -> 0 | X34: =(ROUND((((S34+ROUND((ROUND((((EU34*1.1))*AV34*I34),2)*BS34),2))*AT34)/100),2)+ROUND(((ROUND((ROUND(((AE34-((EU34*1.1)))*AV34*I34),2)*BS34),2)*AT34)/100),2)) -> 41.63 | Y34: =(ROUND((((S34+ROUND((ROUND((((EU34*1.1))*AV34*I34),2)*BS34),2))*AU34)/100),2)+ROUND(((ROUND((ROUND(((AE34-((EU34*1.1)))*AV34*I34),2)*BS34),2)*AU34)/100),2)) -> 21.28 | AA34: 60258621 | AB34: =ROUND((AC34+AD34+AF34),6) -> 46.527 | AC34: =ROUND(((ES34*1)),6) -> 2.34 | AD34: =ROUND(((((ET34*1.1))-((EU34*1.1)))+AE34),6) -> 0 | AE34: =ROUND(((EU34*1.1)),6) -> 0 | AF34: =ROUND(((EV34*1.1)),6) -> 44.187 | AG34: =ROUND((AP34),6) -> 0 | AH34: =((EW34*1.1)) -> 3.498 | AI34: =((EX34*1.1)) -> 0 | AJ34: =(AS34) -> 0 | AK34: 42.51 | AL34: 2.34 | AM34: 0 | AN34: 0 | AO34: 40.17 | AP34: 0 | AQ34: 3.18 | AR34: 0 | AS34: 0 | AT34: 90 | AU34: 46 | AV34: 1.047 | AW34: 1 | AZ34: 1 | BA34: 1 | BB34: 1 | BC34: 1 | BH34: 0 | BI34: 2 | BJ34: ТСН-2001.4 Доп. 67, Сб. 10, т. 173, поз. 2 | BM34: 68 | BN34: 58973116 | BO34: 4.10-173-2 | BP34: 1 | BQ34: 40 | BR34: 0 | BS34: 1 | BT34: 1 | BU34: 1 | BV34: 1 | BW34: 1 | BX34: 1 | BZ34: 90 | CA34: 46 | CE34: 1566 | CF34: 0 | CG34: 0 | CM34: 0 | CN34: Поправка: Гл.12.Прил.8.п.8. 5_12.00.01.11.003 Наименование: При наличии усложненных условий производства работ (стесненность, сложность складирования и транспортной логистики, наличие в зоне производства работ действующего технологического оборудования или движения технологического транспорта и т.п.) для объектов, расположенных за пределами территории круговой магистральной системы улиц "Садовое кольцо" и за пределами Третьего транспортного кольца города Москвы пунктов "а" и "б", но в пределах Московской кольцевой автомобильной дороги | CO34: 0 | CP34: =(P34+Q34+S34) -> 48.6 | CQ34: =ROUND((ROUND((AC34*AW34*1),2)*BC34),2) -> 2.34 | CR34: =(ROUND((ROUND((((ET34*1.1))*AV34*1),2)*BB34),2)+ROUND((ROUND(((AE34-((EU34*1.1)))*AV34*1),2)*BS34),2)) -> 0 | CS34: =(ROUND((ROUND((((EU34*1.1))*AV34*1),2)*BS34),2)+ROUND((ROUND(((AE34-((EU34*1.1)))*AV34*1),2)*BS34),2)) -> 0 | CT34: =ROUND((ROUND((AF34*AV34*1),2)*BA34),2) -> 46.26 | CU34: =AG34 -> 0 | CV34: =(AH34*AV34) -> 3.662406 | CW34: =AI34 -> 0 | CX34: =AJ34 -> 0 | CY34: =(ROUND((((S34+ROUND((ROUND((((EU34*1.1))*AV34*1),2)*BS34),2))*AT34)/100),2)+ROUND(((ROUND((ROUND(((AE34-((EU34*1.1)))*AV34*1),2)*BS34),2)*AT34)/100),2)) -> 41.63 | CZ34: =(ROUND((((S34+ROUND((ROUND((((EU34*1.1))*AV34*1),2)*BS34),2))*AU34)/100),2)+ROUND(((ROUND((ROUND(((AE34-((EU34*1.1)))*AV34*1),2)*BS34),2)*AU34)/100),2)) -> 21.28 | DB34: 3 | DD34: *1 | DE34: *1,1 | DF34: *1,1 | DG34: *1,1 | DI34: *1,1 | DJ34: *1,1 | DN34: 0 | DO34: 0 | DP34: 1 | DQ34: 1 | DU34: 1013 | DV34: 1 ШТ. | DW34: 1 ШТ. | DX34: 1 | EE34: 60088532 | EF34: 40 | EG34: Монтаж оборудования | EH34: 0 | EJ34: 2 | EK34: 68 | EL34: ТСН-2001.4-10. Прокладка и монтаж сетей связи | EM34: ТСН-2001.4-10-1 | EO34: Поправка: Гл.12.Прил.8.п.8. 5_12.00.01.11.003 | EQ34: 0 | ER34: 42.51 | ES34: 2.34 | ET34: 0 | EU34: 0 | EV34: 40.17 | EW34: 3.18 | EX34: 0 | EY34: 0 | FQ34: 0 | FR34: 0 | FS34: 0 | FX34: 90 | FY34: 46 | GD34: 1 | GF34: 1548884140 | GG34: 2 | GH34: 1 | GI34: 2 | GJ34: 0 | GK34: 0 | GL34: =ROUND(IF(AND(BH34=3,BI34=3,FS34<>0),P34,0),2) -> 0 | GM34: =ROUND(O34+X34+Y34,2)+GX34 -> 111.51 | GN34: =IF(OR(BI34=0,BI34=1),GM34-GX34,0) -> 0 | GO34: =IF(BI34=2,GM34-GX34,0) -> 111.51 | GP34: =IF(BI34=4,GM34-GX34,0) -> 0 | GR34: 0 | GS34: 3 | GT34: 0 | GV34: =ROUND((GT34),6) -> 0 | GW34: 1 | GX34: =ROUND(HC34*I34,2) -> 0 | HA34: 0 | HB34: 0 | HC34: =GV34*GW34 -> 0 | HS34: 0 | IK34: 0
A35: 17 | B35: 1 | C35: =ROW(SmtRes!A18) -> 18 | D35: =ROW(EtalonRes!A24) -> 24 | E35: 4 | F35: 4.10-173-2 | G35: Монтаж блока бесперебойного питания (ББП) в диспетчерской | H35: 1 ШТ. | I35: 1 | J35: 0 | K35: 1 | O35: =ROUND(CP35,2) -> 2567.85 | P35: =ROUND((ROUND((AC35*AW35*I35),2)*BC35),2) -> 24.01 | Q35: =(ROUND((ROUND((((ET35*1.1))*AV35*I35),2)*BB35),2)+ROUND((ROUND(((AE35-((EU35*1.1)))*AV35*I35),2)*BS35),2)) -> 0 | R35: =(ROUND((ROUND((((EU35*1.1))*AV35*I35),2)*BS35),2)+ROUND((ROUND(((AE35-((EU35*1.1)))*AV35*I35),2)*BS35),2)) -> 0 | S35: =ROUND((ROUND((AF35*AV35*I35),2)*BA35),2) -> 2543.84 | T35: =ROUND(CU35*I35,2) -> 0 | U35: =CV35*I35 -> 3.662406 | V35: =CW35*I35 -> 0 | W35: =ROUND(CX35*I35,2) -> 0 | X35: =(ROUND((((S35+ROUND((ROUND((((EU35*1.1))*AV35*I35),2)*BS35),2))*AT35)/100),2)+ROUND(((ROUND((ROUND(((AE35-((EU35*1.1)))*AV35*I35),2)*BS35),2)*AT35)/100),2)) -> 2289.46 | Y35: =(ROUND((((S35+ROUND((ROUND((((EU35*1.1))*AV35*I35),2)*BS35),2))*AU35)/100),2)+ROUND(((ROUND((ROUND(((AE35-((EU35*1.1)))*AV35*I35),2)*BS35),2)*AU35)/100),2)) -> 1170.17 | AA35: 60258618 | AB35: =ROUND((AC35+AD35+AF35),6) -> 46.527 | AC35: =ROUND(((ES35*1)),6) -> 2.34 | AD35: =ROUND(((((ET35*1.1))-((EU35*1.1)))+AE35),6) -> 0 | AE35: =ROUND(((EU35*1.1)),6) -> 0 | AF35: =ROUND(((EV35*1.1)),6) -> 44.187 | AG35: =ROUND((AP35),6) -> 0 | AH35: =((EW35*1.1)) -> 3.498 | AI35: =((EX35*1.1)) -> 0 | AJ35: =(AS35) -> 0 | AK35: 42.51 | AL35: 2.34 | AM35: 0 | AN35: 0 | AO35: 40.17 | AP35: 0 | AQ35: 3.18 | AR35: 0 | AS35: 0 | AT35: 90 | AU35: 46 | AV35: 1.047 | AW35: 1 | AZ35: 1 | BA35: 54.99 | BB35: 1 | BC35: 10.26 | BH35: 0 | BI35: 2 | BJ35: ТСН-2001.4 Доп. 67, Сб. 10, т. 173, поз. 2 | BM35: 68 | BN35: 58973116 | BO35: 4.10-173-2 | BP35: 1 | BQ35: 40 | BR35: 0 | BS35: 54.99 | BT35: 1 | BU35: 1 | BV35: 1 | BW35: 1 | BX35: 1 | BZ35: 90 | CA35: 46 | CE35: 1566 | CF35: 0 | CG35: 0 | CM35: 0 | CN35: Поправка: Гл.12.Прил.8.п.8. 5_12.00.01.11.003 Наименование: При наличии усложненных условий производства работ (стесненность, сложность складирования и транспортной логистики, наличие в зоне производства работ действующего технологического оборудования или движения технологического транспорта и т.п.) для объектов, расположенных за пределами территории круговой магистральной системы улиц "Садовое кольцо" и за пределами Третьего транспортного кольца города Москвы пунктов "а" и "б", но в пределах Московской кольцевой автомобильной дороги | CO35: 0 | CP35: =(P35+Q35+S35) -> 2567.85 | CQ35: =ROUND((ROUND((AC35*AW35*1),2)*BC35),2) -> 24.01 | CR35: =(ROUND((ROUND((((ET35*1.1))*AV35*1),2)*BB35),2)+ROUND((ROUND(((AE35-((EU35*1.1)))*AV35*1),2)*BS35),2)) -> 0 | CS35: =(ROUND((ROUND((((EU35*1.1))*AV35*1),2)*BS35),2)+ROUND((ROUND(((AE35-((EU35*1.1)))*AV35*1),2)*BS35),2)) -> 0 | CT35: =ROUND((ROUND((AF35*AV35*1),2)*BA35),2) -> 2543.84 | CU35: =AG35 -> 0 | CV35: =(AH35*AV35) -> 3.662406 | CW35: =AI35 -> 0 | CX35: =AJ35 -> 0 | CY35: =(ROUND((((S35+ROUND((ROUND((((EU35*1.1))*AV35*1),2)*BS35),2))*AT35)/100),2)+ROUND(((ROUND((ROUND(((AE35-((EU35*1.1)))*AV35*1),2)*BS35),2)*AT35)/100),2)) -> 2289.46 | CZ35: =(ROUND((((S35+ROUND((ROUND((((EU35*1.1))*AV35*1),2)*BS35),2))*AU35)/100),2)+ROUND(((ROUND((ROUND(((AE35-((EU35*1.1)))*AV35*1),2)*BS35),2)*AU35)/100),2)) -> 1170.17 | DB35: 4 | DD35: *1 | DE35: *1,1 | DF35: *1,1 | DG35: *1,1 | DI35: *1,1 | DJ35: *1,1 | DN35: 0 | DO35: 0 | DP35: 1 | DQ35: 1 | DU35: 1013 | DV35: 1 ШТ. | DW35: 1 ШТ. | DX35: 1 | EE35: 60088532 | EF35: 40 | EG35: Монтаж оборудования | EH35: 0 | EJ35: 2 | EK35: 68 | EL35: ТСН-2001.4-10. Прокладка и монтаж сетей связи | EM35: ТСН-2001.4-10-1 | EO35: Поправка: Гл.12.Прил.8.п.8. 5_12.00.01.11.003 | EQ35: 0 | ER35: 42.51 | ES35: 2.34 | ET35: 0 | EU35: 0 | EV35: 40.17 | EW35: 3.18 | EX35: 0 | EY35: 0 | FQ35: 0 | FR35: 0 | FS35: 0 | FX35: 90 | FY35: 46 | GD35: 1 | GF35: 1548884140 | GG35: 2 | GH35: 1 | GI35: 2 | GJ35: 0 | GK35: 0 | GL35: =ROUND(IF(AND(BH35=3,BI35=3,FS35<>0),P35,0),2) -> 0 | GM35: =ROUND(O35+X35+Y35,2)+GX35 -> 6027.48 | GN35: =IF(OR(BI35=0,BI35=1),GM35-GX35,0) -> 0 | GO35: =IF(BI35=2,GM35-GX35,0) -> 6027.48 | GP35: =IF(BI35=4,GM35-GX35,0) -> 0 | GR35: 0 | GS35: 3 | GT35: 0 | GV35: =ROUND((GT35),6) -> 0 | GW35: 1 | GX35: =ROUND(HC35*I35,2) -> 0 | HA35: 0 | HB35: 0 | HC35: =GV35*GW35 -> 0 | HS35: 0 | IK35: 0
A36: 17 | B36: 1 | E36: 5 | F36: КА-3 | G36: Источник бесперебойного питания, 600Вт Back Basic 1050S Euro | H36: ШТ | I36: 1 | J36: 0 | K36: 1 | O36: =ROUND(CP36,2) -> 1280.27 | P36: =ROUND((ROUND((AC36*I36),2)*BC36),2) -> 1280.27 | Q36: =(ROUND((ROUND(((ET36)*AV36*I36),2)*BB36),2)+ROUND((ROUND(((AE36-(EU36))*AV36*I36),2)*BS36),2)) -> 0 | R36: =(ROUND((ROUND(((EU36)*AV36*I36),2)*BS36),2)+ROUND((ROUND(((AE36-(EU36))*AV36*I36),2)*BS36),2)) -> 0 | S36: =ROUND((ROUND((AF36*AV36*I36),2)*BA36),2) -> 0 | T36: =ROUND(CU36*I36,2) -> 0 | U36: =CV36*I36 -> 0 | V36: =CW36*I36 -> 0 | W36: =ROUND(CX36*I36,2) -> 0 | X36: =(ROUND((((S36+ROUND((ROUND(((EU36)*AV36*I36),2)*BS36),2))*AT36)/100),2)+ROUND(((ROUND((ROUND(((AE36-(EU36))*AV36*I36),2)*BS36),2)*AT36)/100),2)) -> 0 | Y36: =(ROUND((((S36+ROUND((ROUND(((EU36)*AV36*I36),2)*BS36),2))*AU36)/100),2)+ROUND(((ROUND((ROUND(((AE36-(EU36))*AV36*I36),2)*BS36),2)*AU36)/100),2)) -> 0 | AA36: 60258621 | AB36: =ROUND((AC36+AD36+AF36),6) -> 1280.27 | AC36: =ROUND((ES36),6) -> 1280.27 | AD36: =ROUND((((ET36)-(EU36))+AE36),6) -> 0 | AE36: =ROUND((EU36),6) -> 0 | AF36: =ROUND((EV36),6) -> 0 | AG36: =ROUND((AP36),6) -> 0 | AH36: =(EW36) -> 0 | AI36: =(EX36) -> 0 | AJ36: =(AS36) -> 0 | AK36: 1280.27 | AL36: 1280.27 | AM36: 0 | AN36: 0 | AO36: 0 | AP36: 0 | AQ36: 0 | AR36: 0 | AS36: 0 | AT36: 0 | AU36: 0 | AV36: 1 | AW36: 1 | AZ36: 1 | BA36: 1 | BB36: 1 | BC36: 1 | BH36: 3 | BI36: 3 | BM36: 746 | BN36: 0 | BP36: 0 | BQ36: 130 | BR36: 0 | BS36: 1 | BT36: 1 | BU36: 1 | BV36: 1 | BW36: 1 | BX36: 1 | BZ36: 0 | CA36: 0 | CE36: 1566 | CF36: 0 | CG36: 0 | CM36: 0 | CO36: 0 | CP36: =(P36+Q36+S36) -> 1280.27 | CQ36: =ROUND((ROUND((AC36*1),2)*BC36),2) -> 1280.27 | CR36: =(ROUND((ROUND(((ET36)*AV36*1),2)*BB36),2)+ROUND((ROUND(((AE36-(EU36))*AV36*1),2)*BS36),2)) -> 0 | CS36: =(ROUND((ROUND(((EU36)*AV36*1),2)*BS36),2)+ROUND((ROUND(((AE36-(EU36))*AV36*1),2)*BS36),2)) -> 0 | CT36: =ROUND((ROUND((AF36*AV36*1),2)*BA36),2) -> 0 | CU36: =AG36 -> 0 | CV36: =(AH36*AV36) -> 0 | CW36: =AI36 -> 0 | CX36: =AJ36 -> 0 | CY36: =(ROUND((((S36+ROUND((ROUND(((EU36)*AV36*1),2)*BS36),2))*AT36)/100),2)+ROUND(((ROUND((ROUND(((AE36-(EU36))*AV36*1),2)*BS36),2)*AT36)/100),2)) -> 0 | CZ36: =(ROUND((((S36+ROUND((ROUND(((EU36)*AV36*1),2)*BS36),2))*AU36)/100),2)+ROUND(((ROUND((ROUND(((AE36-(EU36))*AV36*1),2)*BS36),2)*AU36)/100),2)) -> 0 | DN36: 0 | DO36: 0 | DP36: 1 | DQ36: 1 | DU36: 1013 | DV36: ШТ | DW36: ШТ | DX36: 1 | EE36: 60088638 | EF36: 130 | EG36: Сметная стоимость оборудования | EH36: 0 | EJ36: 3 | EK36: 746 | EL36: ТСН-2001.13. Сметная стоимость оборудования | EM36: ТСН-2001.13 | EQ36: 0 | ER36: 0 | ES36: 1280.27 | ET36: 0 | EU36: 0 | EV36: 0 | EW36: 0 | EX36: 0 | EY36: 0 | FQ36: 0 | FR36: =P36 -> 1280.27 | FS36: 0 | FX36: 0 | FY36: 0 | GA36: [11 290 / 1,2 / 7,66] + 3% Трансп + 1,2% Заг.скл | GD36: 1 | GF36: -410713413 | GG36: 2 | GH36: 4 | GI36: -2 | GJ36: 0 | GK36: 0 | GL36: =ROUND(IF(AND(BH36=3,BI36=3,FS36<>0),P36,0),2) -> 0 | GM36: =ROUND(O36+X36+Y36,2)+GX36 -> 1280.27 | GN36: =IF(OR(BI36=0,BI36=1),GM36-GX36,0) -> 0 | GO36: =IF(BI36=2,GM36-GX36,0) -> 0 | GP36: =IF(BI36=4,GM36-GX36,0) -> 0 | GR36: 0 | GS36: 2 | GT36: 0 | GV36: =ROUND((GT36),6) -> 0 | GW36: 1 | GX36: =ROUND(HC36*I36,2) -> 0 | HA36: 0 | HB36: 0 | HC36: =GV36*GW36 -> 0 | HE36: 3 | HF36: 1,2 | HS36: 0 | IK36: 0
A37: 17 | B37: 1 | E37: 5 | F37: КА-3 | G37: Источник бесперебойного питания, 600Вт Back Basic 1050S Euro | H37: ШТ | I37: 1 | J37: 0 | K37: 1 | O37: =ROUND(CP37,2) -> 9806.87 | P37: =ROUND((ROUND((AC37*I37),2)*BC37),2) -> 9806.87 | Q37: =(ROUND((ROUND(((ET37)*AV37*I37),2)*BB37),2)+ROUND((ROUND(((AE37-(EU37))*AV37*I37),2)*BS37),2)) -> 0 | R37: =(ROUND((ROUND(((EU37)*AV37*I37),2)*BS37),2)+ROUND((ROUND(((AE37-(EU37))*AV37*I37),2)*BS37),2)) -> 0 | S37: =ROUND((ROUND((AF37*AV37*I37),2)*BA37),2) -> 0 | T37: =ROUND(CU37*I37,2) -> 0 | U37: =CV37*I37 -> 0 | V37: =CW37*I37 -> 0 | W37: =ROUND(CX37*I37,2) -> 0 | X37: =(ROUND((((S37+ROUND((ROUND(((EU37)*AV37*I37),2)*BS37),2))*AT37)/100),2)+ROUND(((ROUND((ROUND(((AE37-(EU37))*AV37*I37),2)*BS37),2)*AT37)/100),2)) -> 0 | Y37: =(ROUND((((S37+ROUND((ROUND(((EU37)*AV37*I37),2)*BS37),2))*AU37)/100),2)+ROUND(((ROUND((ROUND(((AE37-(EU37))*AV37*I37),2)*BS37),2)*AU37)/100),2)) -> 0 | AA37: 60258618 | AB37: =ROUND((AC37+AD37+AF37),6) -> 1280.27 | AC37: =ROUND((ES37),6) -> 1280.27 | AD37: =ROUND((((ET37)-(EU37))+AE37),6) -> 0 | AE37: =ROUND((EU37),6) -> 0 | AF37: =ROUND((EV37),6) -> 0 | AG37: =ROUND((AP37),6) -> 0 | AH37: =(EW37) -> 0 | AI37: =(EX37) -> 0 | AJ37: =(AS37) -> 0 | AK37: 1280.27 | AL37: 1280.27 | AM37: 0 | AN37: 0 | AO37: 0 | AP37: 0 | AQ37: 0 | AR37: 0 | AS37: 0 | AT37: 0 | AU37: 0 | AV37: 1 | AW37: 1 | AZ37: 1 | BA37: 1 | BB37: 1 | BC37: 7.66 | BH37: 3 | BI37: 3 | BM37: 746 | BN37: 0 | BP37: 0 | BQ37: 130 | BR37: 0 | BS37: 1 | BT37: 1 | BU37: 1 | BV37: 1 | BW37: 1 | BX37: 1 | BZ37: 0 | CA37: 0 | CE37: 1566 | CF37: 0 | CG37: 0 | CM37: 0 | CO37: 0 | CP37: =(P37+Q37+S37) -> 9806.87 | CQ37: =ROUND((ROUND((AC37*1),2)*BC37),2) -> 9806.87 | CR37: =(ROUND((ROUND(((ET37)*AV37*1),2)*BB37),2)+ROUND((ROUND(((AE37-(EU37))*AV37*1),2)*BS37),2)) -> 0 | CS37: =(ROUND((ROUND(((EU37)*AV37*1),2)*BS37),2)+ROUND((ROUND(((AE37-(EU37))*AV37*1),2)*BS37),2)) -> 0 | CT37: =ROUND((ROUND((AF37*AV37*1),2)*BA37),2) -> 0 | CU37: =AG37 -> 0 | CV37: =(AH37*AV37) -> 0 | CW37: =AI37 -> 0 | CX37: =AJ37 -> 0 | CY37: =(ROUND((((S37+ROUND((ROUND(((EU37)*AV37*1),2)*BS37),2))*AT37)/100),2)+ROUND(((ROUND((ROUND(((AE37-(EU37))*AV37*1),2)*BS37),2)*AT37)/100),2)) -> 0 | CZ37: =(ROUND((((S37+ROUND((ROUND(((EU37)*AV37*1),2)*BS37),2))*AU37)/100),2)+ROUND(((ROUND((ROUND(((AE37-(EU37))*AV37*1),2)*BS37),2)*AU37)/100),2)) -> 0 | DN37: 0 | DO37: 0 | DP37: 1 | DQ37: 1 | DU37: 1013 | DV37: ШТ | DW37: ШТ | DX37: 1 | EE37: 60088638 | EF37: 130 | EG37: Сметная стоимость оборудования | EH37: 0 | EJ37: 3 | EK37: 746 | EL37: ТСН-2001.13. Сметная стоимость оборудования | EM37: ТСН-2001.13 | EQ37: 0 | ER37: 0 | ES37: 1280.27 | ET37: 0 | EU37: 0 | EV37: 0 | EW37: 0 | EX37: 0 | EY37: 0 | EZ37: 5 | FC37: 1 | FD37: 18 | FF37: 11290 | FQ37: 0 | FR37: =P37 -> 9806.87 | FS37: 0 | FX37: 0 | FY37: 0 | GA37: [11 290 / 1,2 / 7,66] + 3% Трансп + 1,2% Заг.скл | GD37: 1 | GF37: -410713413 | GG37: 2 | GH37: 3 | GI37: 5 | GJ37: 0 | GK37: 0 | GL37: =ROUND(IF(AND(BH37=3,BI37=3,FS37<>0),P37,0),2) -> 0 | GM37: =ROUND(O37+X37+Y37,2)+GX37 -> 9806.87 | GN37: =IF(OR(BI37=0,BI37=1),GM37-GX37,0) -> 0 | GO37: =IF(BI37=2,GM37-GX37,0) -> 0 | GP37: =IF(BI37=4,GM37-GX37,0) -> 0 | GR37: 1 | GS37: 1 | GT37: 0 | GV37: =ROUND((GT37),6) -> 0 | GW37: 1 | GX37: =ROUND(HC37*I37,2) -> 0 | HA37: 0 | HB37: 0 | HC37: =GV37*GW37 -> 0 | HE37: 3 | HF37: 1,2 | HS37: 0 | IK37: 0
A38: 17 | B38: 1 | C38: =ROW(SmtRes!A19) -> 19 | D38: =ROW(EtalonRes!A25) -> 25 | E38: 6 | F38: 4.10-80-1 | G38: Аппараты приемные, приборы ПС приемно-контрольные, пусковые, концентратор, блок базовый на 10 лучей | H38: 1 ШТ. | I38: 1 | J38: 0 | K38: 1 | O38: =ROUND(CP38,2) -> 122.06 | P38: =ROUND((ROUND((AC38*AW38*I38),2)*BC38),2) -> 12.53 | Q38: =(ROUND((ROUND((((ET38*1.1))*AV38*I38),2)*BB38),2)+ROUND((ROUND(((AE38-((EU38*1.1)))*AV38*I38),2)*BS38),2)) -> 0.07 | R38: =(ROUND((ROUND((((EU38*1.1))*AV38*I38),2)*BS38),2)+ROUND((ROUND(((AE38-((EU38*1.1)))*AV38*I38),2)*BS38),2)) -> 0.01 | S38: =ROUND((ROUND((AF38*AV38*I38),2)*BA38),2) -> 109.46 | T38: =ROUND(CU38*I38,2) -> 0 | U38: =CV38*I38 -> 8.29224 | V38: =CW38*I38 -> 0 | W38: =ROUND(CX38*I38,2) -> 0 | X38: =(ROUND((((S38+ROUND((ROUND((((EU38*1.1))*AV38*I38),2)*BS38),2))*AT38)/100),2)+ROUND(((ROUND((ROUND(((AE38-((EU38*1.1)))*AV38*I38),2)*BS38),2)*AT38)/100),2)) -> 98.52 | Y38: =(ROUND((((S38+ROUND((ROUND((((EU38*1.1))*AV38*I38),2)*BS38),2))*AU38)/100),2)+ROUND(((ROUND((ROUND(((AE38-((EU38*1.1)))*AV38*I38),2)*BS38),2)*AU38)/100),2)) -> 50.36 | AA38: 60258621 | AB38: =ROUND((AC38+AD38+AF38),6) -> 117.14 | AC38: =ROUND(((ES38*1)),6) -> 12.53 | AD38: =ROUND(((((ET38*1.1))-((EU38*1.1)))+AE38),6) -> 0.066 | AE38: =ROUND(((EU38*1.1)),6) -> 0.011 | AF38: =ROUND(((EV38*1.1)),6) -> 104.544 | AG38: =ROUND((AP38),6) -> 0 | AH38: =((EW38*1.1)) -> 7.92 | AI38: =((EX38*1.1)) -> 0 | AJ38: =(AS38) -> 0 | AK38: 107.63 | AL38: 12.53 | AM38: 0.06 | AN38: 0.01 | AO38: 95.04 | AP38: 0 | AQ38: 7.2 | AR38: 0 | AS38: 0 | AT38: 90 | AU38: 46 | AV38: 1.047 | AW38: 1 | AZ38: 1 | BA38: 1 | BB38: 1 | BC38: 1 | BH38: 0 | BI38: 2 | BJ38: ТСН-2001.4 Доп. 68, Сб. 10, т. 80, поз. 1 | BM38: 68 | BN38: 58973116 | BO38: 4.10-80-1 | BP38: 1 | BQ38: 40 | BR38: 0 | BS38: 1 | BT38: 1 | BU38: 1 | BV38: 1 | BW38: 1 | BX38: 1 | BZ38: 90 | CA38: 46 | CE38: 1566 | CF38: 0 | CG38: 0 | CM38: 0 | CN38: Поправка: Гл.12.Прил.8.п.8. 5_12.00.01.11.003 Наименование: При наличии усложненных условий производства работ (стесненность, сложность складирования и транспортной логистики, наличие в зоне производства работ действующего технологического оборудования или движения технологического транспорта и т.п.) для объектов, расположенных за пределами территории круговой магистральной системы улиц "Садовое кольцо" и за пределами Третьего транспортного кольца города Москвы пунктов "а" и "б", но в пределах Московской кольцевой автомобильной дороги | CO38: 0 | CP38: =(P38+Q38+S38) -> 122.06 | CQ38: =ROUND((ROUND((AC38*AW38*1),2)*BC38),2) -> 12.53 | CR38: =(ROUND((ROUND((((ET38*1.1))*AV38*1),2)*BB38),2)+ROUND((ROUND(((AE38-((EU38*1.1)))*AV38*1),2)*BS38),2)) -> 0.07 | CS38: =(ROUND((ROUND((((EU38*1.1))*AV38*1),2)*BS38),2)+ROUND((ROUND(((AE38-((EU38*1.1)))*AV38*1),2)*BS38),2)) -> 0.01 | CT38: =ROUND((ROUND((AF38*AV38*1),2)*BA38),2) -> 109.46 | CU38: =AG38 -> 0 | CV38: =(AH38*AV38) -> 8.29224 | CW38: =AI38 -> 0 | CX38: =AJ38 -> 0 | CY38: =(ROUND((((S38+ROUND((ROUND((((EU38*1.1))*AV38*1),2)*BS38),2))*AT38)/100),2)+ROUND(((ROUND((ROUND(((AE38-((EU38*1.1)))*AV38*1),2)*BS38),2)*AT38)/100),2)) -> 98.52 | CZ38: =(ROUND((((S38+ROUND((ROUND((((EU38*1.1))*AV38*1),2)*BS38),2))*AU38)/100),2)+ROUND(((ROUND((ROUND(((AE38-((EU38*1.1)))*AV38*1),2)*BS38),2)*AU38)/100),2)) -> 50.36 | DB38: 5 | DD38: *1 | DE38: *1,1 | DF38: *1,1 | DG38: *1,1 | DI38: *1,1 | DJ38: *1,1 | DN38: 0 | DO38: 0 | DP38: 1 | DQ38: 1 | DU38: 1013 | DV38: 1 ШТ. | DW38: 1 ШТ. | DX38: 1 | EE38: 60088532 | EF38: 40 | EG38: Монтаж оборудования | EH38: 0 | EJ38: 2 | EK38: 68 | EL38: ТСН-2001.4-10. Прокладка и монтаж сетей связи | EM38: ТСН-2001.4-10-1 | EO38: Поправка: Гл.12.Прил.8.п.8. 5_12.00.01.11.003 | EQ38: 0 | ER38: 107.63 | ES38: 12.53 | ET38: 0.06 | EU38: 0.01 | EV38: 95.04 | EW38: 7.2 | EX38: 0 | EY38: 0 | FQ38: 0 | FR38: 0 | FS38: 0 | FX38: 90 | FY38: 46 | GD38: 1 | GF38: 723018335 | GG38: 2 | GH38: 1 | GI38: 2 | GJ38: 0 | GK38: 0 | GL38: =ROUND(IF(AND(BH38=3,BI38=3,FS38<>0),P38,0),2) -> 0 | GM38: =ROUND(O38+X38+Y38,2)+GX38 -> 270.94 | GN38: =IF(OR(BI38=0,BI38=1),GM38-GX38,0) -> 0 | GO38: =IF(BI38=2,GM38-GX38,0) -> 270.94 | GP38: =IF(BI38=4,GM38-GX38,0) -> 0 | GR38: 0 | GS38: 3 | GT38: 0 | GV38: =ROUND((GT38),6) -> 0 | GW38: 1 | GX38: =ROUND(HC38*I38,2) -> 0 | HA38: 0 | HB38: 0 | HC38: =GV38*GW38 -> 0 | HS38: 0 | IK38: 0
