Workbook

Sheet 02-01-12
A1: =Source!B1 -> Smeta.RU (495) 974-1589
J2: Форма № 4б
A3: Клязьминская улица, д. 7, к. 4, Дмитровский район Северного административного округа города Москвы Капитальный ремонт здания Государственного бюджетного общеобразовательного учреждения города Москвы «Школа № 236». 1 этап | AP3: Клязьминская улица, д. 7, к. 4, Дмитровский район Северного административного округа города Москвы Капитальный ремонт здания Государственного бюджетного общеобразовательного учреждения города Москвы «Школа № 236». 1 этап. 02-01-12 СКС
A4: (наименование стройки и/или объекта)
A6: =CONCATENATE( "ЛОКАЛЬНАЯ СМЕТА № ",IF(Source!F20<>"Новая локальная смета", Source!F20, "")) -> ЛОКАЛЬНАЯ СМЕТА № 02-01-12
A8: =IF(Source!G20<>"Новая локальная смета", Source!G20, "") -> Структурированная кабельная сеть
A9: (наименование работ и затрат)
A11: =CONCATENATE( "Основание: чертежи № ", Source!J20) -> Основание: чертежи № 2024-00272-01-0-ИОС5.5
I13: В базисном уровне цен | J13: В текущем уровне цен
E14: Сметная стоимость | I14: =I15+I16+I17+I18 -> 1018.2 | J14: =J15+J16+J17+J18 -> 12126.02 | K14: тыс.руб.
E15: Строительные работы | I15: =ROUND((Source!F386)/1000, 2) -> 0 | J15: =ROUND((Source!P386)/1000, 2) -> 0 | K15: тыс.руб.
E16: Работы по монтажу оборудования | I16: =ROUND((Source!F387)/1000, 2) -> 548.47 | J16: =ROUND((Source!P387)/1000, 2) -> 8650.89 | K16: тыс.руб.
E17: Оборудование | I17: =ROUND((Source!F378)/1000, 2) -> 469.73 | J17: =ROUND((Source!P378)/1000, 2) -> 3475.13 | K17: тыс.руб.
E18: Прочие работы и затраты | I18: =ROUND((Source!F388+Source!F389)/1000, 2) -> 0 | J18: =ROUND((Source!P388+Source!P389)/1000, 2) -> 0 | K18: тыс.руб.
E19: Средства на оплату труда | I19: =(Source!F384+ Source!F383)/1000 -> 36.28346 | J19: =((Source!P384 + Source!P383)/1000) -> 1995.2275 | K19: тыс.руб.
E20: Затраты труда | I20: =Source!F391 -> 3008.2474 | K20: чел.-ч.
E21: Кроме того:
E22: Возврат материалов | I22: =SUM(Y28:Y321)/1000 -> 0 | J22: =SUM(Z28:Z321)/1000 -> 0 | K22: тыс.руб.
A24: Составлен(а) по ТСН-2001 с учетом Дополнения №: 80
A25: № и период сборника коэффициентов (индексов) пересчета: Коэффициенты к ТСН-2001 МГЭ Дополнение 80, строительство №217/80 III квартал 2025 года и Коэффициенты к ТСН-2001.13-2 Дополнение 46 №62/46 III квартал 2025 года | AP25: № и период сборника коэффициентов (индексов) пересчета: Коэффициенты к ТСН-2001 МГЭ Дополнение 80, строительство №217/80 III квартал 2025 года и Коэффициенты к ТСН-2001.13-2 Дополнение 46 №62/46 III квартал 2025 года
A26: № п/п | B26: Шифр расценки и коды ресурсов | C26: Наименование работ и затрат | D26: Ед. изм. | E26: Кол-во единиц | F26: Цена на ед. изм., руб. | G26: Попра- вочные коэффи- циенты | H26: Коэффи- циенты зимних удорожа- ний | I26: Всего в ценах на январь 2000 года, руб. | J26: Коэффи- циенты (индек- сы) пере- счета, нормы НР и СП | K26: ВСЕГО затрат в текущем уровне цен, руб.
A27: 1 | B27: 2 | C27: 3 | D27: 4 | E27: 5 | F27: 6 | G27: 7 | H27: 8 | I27: 9 | J27: 10 | K27: 11
A29: =CONCATENATE("Раздел: ",IF(Source!G24<>"Новый раздел", Source!G24, "")) -> Раздел: Телекоммуникационный шкаф 47U 19" ШТ1-01
A30: 1 | B30: 4.10-32-1 Поправка: Гл.12.Прил.8.п.8. 5_12.00.01.11.003 | C30: Монтаж стойки, полустойки, каркаса стойки или шкафа массой до 100 кг | D30: =Source!H28 -> 1 ШТ. | E30: =Source!I28 -> 1 | Q30: =Source!X28 -> 99.34 | R30: =Source!X29 -> 5462.81 | S30: =Source!Y28 -> 50.77 | T30: =Source!Y29 -> 2792.1 | U30: =ROUND((175/100)*ROUND(Source!R28, 2), 2) -> 8.38 | V30: =ROUND((0/100)*ROUND(Source!R29, 2), 2) -> 0 | AC30: 0
C31: ЗП | F31: =Source!AO28 -> 91.68 | G31: 1,1 | H31: =Source!AV29 -> 1.047 | I31: =Source!S28 -> 105.59 | J31: =IF(Source!BA29<> 0, Source!BA29, 1) -> 54.99 | K31: =Source!S29 -> 5806.39
C32: ЭМ | F32: =Source!AM28 -> 38.92 | G32: 1,1 | H32: =Source!AV29 -> 1.047 | I32: =Source!Q28 -> 44.82 | J32: =IF(Source!BB29<> 0, Source!BB29, 1) -> 15.29 | K32: =Source!Q29 -> 685.3
C33: в т.ч. ЗПМ | F33: =Source!AN28 -> 4.16 | G33: 1,1 | H33: =Source!AV29 -> 1.047 | I33: =Source!R28 -> 4.79 | J33: =IF(Source!BS29<> 0, Source!BS29, 1) -> 54.99 | K33: =Source!R29 -> 263.4
C34: МР | F34: =Source!AL28 -> 3.92 | H34: =Source!AW29 -> 1 | I34: =Source!P28 -> 3.92 | J34: =IF(Source!BC29<> 0, Source!BC29, 1) -> 8.3 | K34: =Source!P29 -> 32.54
A35: 1,1 | B35: =Source!F30 -> КА 1 | C35: Шкаф 19" серии Racknet S3000, 47U 60F-47-7C-94BL 16 818,37 = [195 488,81 / 1,2 / 9,88] + 2% Заг.скл | D35: =Source!H30 -> шт. | E35: =Source!I30 -> 1 | F35: =Source!AK30 -> 16818.37 | H35: =Source!AW31 -> 1 | I35: =Source!O30 -> 16818.37 | J35: =IF(Source!BC31<> 0, Source!BC31, 1) -> 9.88 | K35: =Source!O31 -> 166165.5 | Q35: =Source!X30 -> 0 | R35: =Source!X31 -> 0 | S35: =Source!Y30 -> 0 | T35: =Source!Y31 -> 0 | U35: =ROUND((175/100)*ROUND(Source!R30, 2), 2) -> 0 | V35: =ROUND((0/100)*ROUND(Source!R31, 2), 2) -> 0 | AC35: 3
A36: 1,2 | B36: =Source!F32 -> КА 2 | C36: Вертикальный органайзер 60А-18-47-01-31BL 3 548,41 = [41 245 / 1,2 / 9,88] + 2% Заг.скл | D36: =Source!H32 -> шт. | E36: =Source!I32 -> 1 | F36: =Source!AK32 -> 3548.41 | H36: =Source!AW33 -> 1 | I36: =Source!O32 -> 3548.41 | J36: =IF(Source!BC33<> 0, Source!BC33, 1) -> 9.88 | K36: =Source!O33 -> 35058.29 | Q36: =Source!X32 -> 0 | R36: =Source!X33 -> 0 | S36: =Source!Y32 -> 0 | T36: =Source!Y33 -> 0 | U36: =ROUND((175/100)*ROUND(Source!R32, 2), 2) -> 0 | V36: =ROUND((0/100)*ROUND(Source!R33, 2), 2) -> 0 | AC36: 3
A37: 1,3 | B37: =Source!F34 -> КА 7 | C37: Набор для креnленuя лоmков к крышке шкафов, высоmа 50мм 60А-31-08-ЗЗВL 147,62 = [1 715,95 / 1,2 / 9,88] + 2% Заг.скл | D37: =Source!H34 -> шт. | E37: =Source!I34 -> 1 | F37: =Source!AK34 -> 147.62 | H37: =Source!AW35 -> 1 | I37: =Source!O34 -> 147.62 | J37: =IF(Source!BC35<> 0, Source!BC35, 1) -> 9.88 | K37: =Source!O35 -> 1458.49 | Q37: =Source!X34 -> 0 | R37: =Source!X35 -> 0 | S37: =Source!Y34 -> 0 | T37: =Source!Y35 -> 0 | U37: =ROUND((175/100)*ROUND(Source!R34, 2), 2) -> 0 | V37: =ROUND((0/100)*ROUND(Source!R35, 2), 2) -> 0 | AC37: 3
C38: НР от ФОТ | D38: % | E38: =Source!BZ29 -> 90 | I38: =SUM(Q30:Q37) -> 99.34 | J38: =Source!AT29 -> 90 | K38: =SUM(R30:R37) -> 5462.81
C39: СП от ФОТ | D39: % | E39: =Source!CA29 -> 46 | I39: =SUM(S30:S38) -> 50.77 | J39: =Source!AU29 -> 46 | K39: =SUM(T30:T38) -> 2792.1
C40: ЗТР | D40: чел-ч | E40: =Source!AQ28 -> 8.2 | G40: 1,1 | H40: =Source!AV29 -> 1.047 | I40: =Source!U28 -> 9.44394
C41: ВСЕГО работ по позиции: | H41: =I31+I32+I34+I38+I39+SUM(I35:I37)-SUMIF(AC35:AC37, 5, I35:I37)-SUMIF(AC35:AC37, 6, I35:I37) -> 20818.84 | J41: =K31+K32+K34+K38+K39+SUM(K35:K37)-SUMIF(AC35:AC37, 5, K35:K37)-SUMIF(AC35:AC37, 6, K35:K37) -> 217461.42
C42: ВСЕГО оборудование по позиции: | H42: =SUMIF(AC35:AC37, 5, I35:I37)+SUMIF(AC35:AC37, 6, I35:I37) -> 0 | J42: =SUMIF(AC35:AC37, 5, K35:K37)+SUMIF(AC35:AC37, 6, K35:K37) -> 0
C43: ВСЕГО по позиции: | H43: =I31+I32+I34+I38+I39+SUM(I35:I37) -> 20818.84 | J43: =K31+K32+K34+K38+K39+SUM(K35:K37) -> 217461.42 | O43: =I31+I32+I34+I38+I39+SUM(I35:I37) -> 20818.84 | P43: =K31+K32+K34+K38+K39+SUM(K35:K37) -> 217461.42
A45: 2 | B45: 4.11-12-1 Поправка: Гл.12.Прил.8.п.8. 5_12.00.01.11.003 | C45: Установка съемных и выдвижных блоков (модулей, ячеек, ТЭЗ) массой до 5 кг | D45: =Source!H36 -> 1 ШТ. | E45: =Source!I36 -> 4 | Q45: =Source!X36 -> 48.64 | R45: =Source!X37 -> 2674.49 | S45: =Source!Y36 -> 24.86 | T45: =Source!Y37 -> 1366.96 | U45: =ROUND((175/100)*ROUND(Source!R36, 2), 2) -> 0.65 | V45: =ROUND((0/100)*ROUND(Source!R37, 2), 2) -> 0 | AC45: 0
C46: ="Объем: "&Source!I36&"=1+"&"1+"&"1+"&"1" -> Объем: 4=1+1+1+1
C47: ЗП | F47: =Source!AO36 -> 11.65 | G47: 1,1 | H47: =Source!AV37 -> 1.047 | I47: =Source!S36 -> 53.67 | J47: =IF(Source!BA37<> 0, Source!BA37, 1) -> 54.99 | K47: =Source!S37 -> 2951.31
...

Sheet Ведомость объемов работ
A1: =Source!B1 -> Smeta.RU (495) 974-1589
E3: "УТВЕРЖДАЮ"
D5: ___________________________
D7: ___________________________
D9: " ___ " ___________ 20 ___ г.
B12: =CONCATENATE("Ведомость объемов работ ", IF(Source!AN15<>"", Source!AN15," ")) -> Ведомость объемов работ
B13: =CONCATENATE(Source!F12, " ", Source!G12) -> 02-01-12 02-01-12 СКС
A16: № п/п | B16: № в ЛСР | C16: Наименование работ и затрат | D16: Единица измерения | E16: Количество | F16: Ссылка на чертежи, спецификации | G16: Формула расчета, расчет объемов работ и расхода материалов | H16: Примечание
A17: 1 | B17: 2 | C17: 3 | D17: 4 | E17: 5 | F17: 6 | G17: 7 | H17: 8
A18: =CONCATENATE("Локальная смета: ", Source!G20) -> Локальная смета: Структурированная кабельная сеть
A19: =CONCATENATE("Раздел: ", Source!G24) -> Раздел: Телекоммуникационный шкаф 47U 19" ШТ1-01
A20: 1 | B20: =Source!E28 -> 1 | C20: =Source!G28 -> Монтаж стойки, полустойки, каркаса стойки или шкафа массой до 100 кг | D20: 1 ШТ. | E20: =Source!I28 -> 1 | F20: =Source!U24 | G20: =Source!I28 -> 1
A21: 1.1 | B21: =Source!E30 -> 1,1 | C21: =Source!G30 -> Шкаф 19" серии Racknet S3000, 47U 60F-47-7C-94BL | D21: шт. | E21: =Source!I30 -> 1 | F21: =Source!U24
A22: 1.2 | B22: =Source!E32 -> 1,2 | C22: =Source!G32 -> Вертикальный органайзер 60А-18-47-01-31BL | D22: шт. | E22: =Source!I32 -> 1 | F22: =Source!U24
A23: 1.3 | B23: =Source!E34 -> 1,3 | C23: =Source!G34 -> Набор для креnленuя лоmков к крышке шкафов, высоmа 50мм 60А-31-08-ЗЗВL | D23: шт. | E23: =Source!I34 -> 1 | F23: =Source!U24
A24: 2 | B24: =Source!E36 -> 2 | C24: =Source!G36 -> Установка съемных и выдвижных блоков (модулей, ячеек, ТЭЗ) массой до 5 кг | D24: 1 ШТ. | E24: =Source!I36 -> 4 | F24: =Source!U24 | G24: ="=1+"&"1+"&"1+"&"1" -> =1+1+1+1
A25: 2.1 | B25: =Source!E38 -> 2,1 | C25: =Source!G38 -> Вентиляторная панель 60А-91-11-30ВL | D25: шт. | E25: =Source!I38 -> 1 | F25: =Source!U24
A26: 2.2 | B26: =Source!E40 -> 2,2 | C26: =Source!G40 -> Выдвижная полка для клавиатуры 60А-04-45-11BL | D26: шт. | E26: =Source!I40 -> 1 | F26: =Source!U24
A27: 2.3 | B27: =Source!E42 -> 2,3 | C27: =Source!G42 -> Полка сmацuонарная регулuруемая 1U до 50кг, 370мм, для 600мм | D27: шт. | E27: =Source!I42 -> 1 | F27: =Source!U24
A28: 2.4 | B28: =Source!E44 -> 2,4 | C28: =Source!G44 -> Панель освещенuя на магнumах, унuверсальная цвеm черныu 60A-05-15BL | D28: шт. | E28: =Source!I44 -> 1 | F28: =Source!U24
A29: 3 | B29: =Source!E46 -> 3 | C29: =Source!G46 -> Включение штепсельных разъемов в аппаратуру, количество контактов в разъеме до 14 | D29: 1 разъем | E29: =Source!I46 -> 1 | F29: =Source!U24 | G29: =Source!I46 -> 1
A30: 3.1 | B30: =Source!E48 -> 3,1 | C30: =Source!G48 -> Шнур питания для вент. панели IEC 320 C14 | D30: шт. | E30: =Source!I48 -> 1 | F30: =Source!U24
A31: =CONCATENATE("Раздел: ", Source!G81) -> Раздел: Телекоммуникационный шкаф 42U 19" ШТ1-2,1-3,1-4; ШТ2-5,2-6; ШТ3-7,3-8
A32: 4 | B32: =Source!E85 -> 4 | C32: =Source!G85 -> Монтаж стойки, полустойки, каркаса стойки или шкафа массой до 100 кг | D32: 1 ШТ. | E32: =Source!I85 -> 7 | F32: =Source!U81 | G32: =Source!I85 -> 7
A33: 4.1 | B33: =Source!E87 -> 4,1 | C33: =Source!G87 -> Шкаф 19" серии Racknet S3000, 42U 60F-42-88-31BL | D33: шт. | E33: =Source!I87 -> 7 | F33: =Source!U81
A34: 4.2 | B34: =Source!E89 -> 4,2 | C34: =Source!G89 -> Вертикальный органайзер 60А-18-42-01-31BL | D34: шт. | E34: =Source!I89 -> 7 | F34: =Source!U81
A35: 4.3 | B35: =Source!E91 -> 4,3 | C35: =Source!G91 -> Шuна заземленuя 19" (500мм), 20 mочек, 5х15мм 60A-14-11GR | D35: шт. | E35: =Source!I91 -> 8 | F35: =Source!U81
A36: 4.4 | B36: =Source!E93 -> 4,4 | C36: =Source!G93 -> Набор для креnленuя лоmков к крышке шкафов, высоmа 50мм 60А-31-08-ЗЗВL | D36: шт. | E36: =Source!I93 -> 7 | F36: =Source!U81
A37: 5 | B37: =Source!E95 -> 5 | C37: =Source!G95 -> Включение штепсельных разъемов в аппаратуру, количество контактов в разъеме до 14 | D37: 1 разъем | E37: =Source!I95 -> 71 | F37: =Source!U81 | G37: ="=7+"&"8*"&"8" -> =7+8*8
A38: 5.1 | B38: =Source!E97 -> 5,1 | C38: =Source!G97 -> Шнур питания для вент. панели IEC 320 C14 | D38: шт. | E38: =Source!I97 -> 7 | F38: =Source!U81
A39: 5.2 | B39: =Source!E99 -> 5,2 | C39: =Source!G99 -> Набор nроводов заземленuя, 4 nровода 250ммх4мм2, 4 nровода, 150мм х4мм2 60A-14-13GR | D39: шт. | E39: =Source!I99 -> 8 | F39: =Source!U81
A40: 6 | B40: =Source!E101 -> 6 | C40: =Source!G101 -> Установка съемных и выдвижных блоков (модулей, ячеек, ТЭЗ) массой до 5 кг | D40: 1 ШТ. | E40: =Source!I101 -> 28 | F40: =Source!U81 | G40: ="=7+"&"7+"&"7+"&"7" -> =7+7+7+7
A41: 6.1 | B41: =Source!E103 -> 6,1 | C41: =Source!G103 -> Вентиляторная панель 60А-91-11-30ВL | D41: шт. | E41: =Source!I103 -> 7 | F41: =Source!U81
A42: 6.2 | B42: =Source!E105 -> 6,2 | C42: =Source!G105 -> Выдвижная полка для клавиатуры 60А-04-45-11BL | D42: шт. | E42: =Source!I105 -> 7 | F42: =Source!U81
A43: 6.3 | B43: =Source!E107 -> 6,3 | C43: =Source!G107 -> Полка сmацuонарная регулuруемая 1U до 50кг, 370мм, для 600мм | D43: шт. | E43: =Source!I107 -> 7 | F43: =Source!U81
A44: 6.4 | B44: =Source!E109 -> 6,4 | C44: =Source!G109 -> Панель освещенuя на магнumах, унuверсальная цвеm черныu 60A-05-15BL | D44: шт. | E44: =Source!I109 -> 7 | F44: =Source!U81
A45: =CONCATENATE("Раздел: ", Source!G142) -> Раздел: Источники электропитания
A46: 7 | B46: =Source!E146 -> 7 | C46: =Source!G146 -> Монтаж отдельно устанавливаемого преобразователя или блока питания | D46: 1 ШТ. | E46: =Source!I146 -> 8 | F46: =Source!U142 | G46: =Source!I146 -> 8
A47: 7.1 | B47: =Source!E148 -> 7,1 | C47: =Source!G148 -> Болты строительные с гайками, оцинкованные, М10х100 мм | D47: т | E47: =Source!I148 -> 0.0024 | F47: =Source!U142
A48: 7.2 | B48: =Source!E150 -> 7,2 | C48: =Source!G150 -> Наконечник кабельный, латунный, кольцевой, неизолированный, для жил сечением от 1,0 до 2,5 мм2 | D48: шт. | E48: =Source!I150 -> 80 | F48: =Source!U142
...

Sheet Source
A1: 0 | B1: Smeta.RU (495) 974-1589 | D1: _PS_ | F1: 0 | G1: 0 | H1: 0 | I1: Smeta.RU | K1: 1 | L1: 74562 | M1: 10 | N1: 12 | O1: 1 | P1: 0 | Q1: 1
A4: 1 | B4: 1 | C4: -1 | G4: Клязьминская улица, д. 7, к. 4, Дмитровский район Северного административного округа города Москвы Капитальный ремонт здания Государственного бюджетного общеобразовательного учреждения города Москвы «Школа № 236». 1 этап | EC4: 0
A12: 1 | B12: 438 | C12: 0 | D12: =ROW(A399) -> 399 | E12: 0 | F12: 02-01-12 | G12: 02-01-12 СКС | I12: 0 | J12: 2024-00272-01-0-ИОС5.5 | K12: 0 | L12: 0 | M12: 4098 | O12: 0 | P12: 0 | Q12: 0 | R12: 0 | S12: 0 | T12: 1 | V12: 0 | AB12: Лукьянова А.Л. | BB12: 0 | BH12: Сметные нормы списания | BI12: Коды ОКП для ТСН-2001 МГЭ Дополнение 80 | BJ12: 1 | BK12: 1 | BL12: 0 | BM12: 0 | BN12: 1 | BO12: 0 | BP12: 6 | BQ12: 2 | BR12: 1 | BS12: 1 | BT12: 1 | BU12: 0 | BV12: 1 | BW12: 0 | BX12: 0 | BY12: ТСН-2001 (МГЭ) Доп 80 - Новое строительство | BZ12: Типовой расчет для ТСН-2001 МГЭ, Дополнение 80, строительство | CA12: Территориальные сметные нормативы для Москвы ТСН-2001 (МГЭ), дополнение 80 | CB12: Территориальные сметные нормативы для Москвы ТСН-2001 (МГЭ), дополнение 80 | CC12: Территориальные сметные нормативы для Москвы ТСН-2001 (МГЭ), дополнение 80 | CD12: Территориальные сметные нормативы для Москвы ТСН-2001 (МГЭ), дополнение 80 | CE12: Поправки для ТСН-2001 от 03.02.2026 г. доп.80 | CF12: 0 | CG12: 0 | CH12: 8202 | CK12: 81 | CQ12: Территориальные сметные нормативы для Москвы (ТСН-2001) | CR12: ТЕР | CS12: 41660 | CT12: 1 | CU12: 80 | CY12: 0 | EC12: 0
A15: 15 | B15: 1
A18: 52 | B18: =B399 -> 438 | C18: =C399 -> 1 | D18: =D399 -> 12 | E18: =E399 -> 0 | F18: =F399 -> 02-01-12 | G18: =G399 -> 02-01-12 СКС | O18: =O399 -> 968093.54 | P18: =P399 -> 929001.41 | Q18: =Q399 -> 3132.9 | R18: =R399 -> 324.23 | S18: =S399 -> 35959.23 | T18: =T399 -> 0 | U18: =U399 -> 3008.2474 | V18: =V399 -> 0 | ... GX18: =GX399 -> 0
A20: 3 | B20: 1 | D20: =ROW(A369) -> 369 | F20: 02-01-12 | G20: Структурированная кабельная сеть | I20: 0 | J20: 2024-00272-01-0-ИОС5.5 | K20: -1 | L20: 02-01-12 | S20: 0 | T20: 0 | V20: 0 | AB20: Лукьянова А.Л. | BX20: 0 | CF20: 0 | CG20: 0
A22: 52 | B22: =B369 -> 1 | C22: =C369 -> 3 | D22: =D369 -> 20 | E22: =E369 -> 0 | F22: =F369 -> 02-01-12 | G22: =G369 -> Структурированная кабельная сеть | O22: =O369 -> 968093.54 | P22: =P369 -> 929001.41 | Q22: =Q369 -> 3132.9 | R22: =R369 -> 324.23 | S22: =S369 -> 35959.23 | T22: =T369 -> 0 | U22: =U369 -> 3008.2474 | V22: =V369 -> 0 | ... GX22: =GX369 -> 0
A24: 4 | B24: 1 | D24: =ROW(A51) -> 51 | G24: Телекоммуникационный шкаф 47U 19" ШТ1-01 | I24: 0 | K24: -1 | S24: 0 | T24: 0 | V24: 0 | BX24: 0 | CJ24: 0
A26: 52 | B26: =B51 -> 1 | C26: =C51 -> 4 | D26: =D51 -> 24 | E26: =E51 -> 0 | F26: =F51 | G26: =G51 -> Телекоммуникационный шкаф 47U 19" ШТ1-01 | O26: =O51 -> 25651.89 | P26: =P51 -> 25442.61 | Q26: =Q51 -> 47.12 | R26: =R51 -> 5.16 | S26: =S51 -> 162.16 | T26: =T51 -> 0 | U26: =U51 -> 14.442318 | V26: =V51 -> 0 | ... GX26: =GX51 -> 0
A28: 17 | B28: 1 | D28: =ROW(EtalonRes!A6) -> 6 | E28: 1 | F28: 4.10-32-1 | G28: Монтаж стойки, полустойки, каркаса стойки или шкафа массой до 100 кг | H28: 1 ШТ. | I28: 1 | J28: 0 | K28: 1 | O28: =ROUND(CP28,2) -> 154.33 | P28: =ROUND((ROUND((AC28*AW28*I28),2)*BC28),2) -> 3.92 | Q28: =(ROUND((ROUND((((ET28*1.1))*AV28*I28),2)*BB28),2)+ROUND((ROUND(((AE28-((EU28*1.1)))*AV28*I28),2)*BS28),2)) -> 44.82 | R28: =ROUND((ROUND((AE28*AV28*I28),2)*BS28),2) -> 4.79 | S28: =ROUND((ROUND((AF28*AV28*I28),2)*BA28),2) -> 105.59 | T28: =ROUND(CU28*I28,2) -> 0 | U28: =CV28*I28 -> 9.44394 | V28: =CW28*I28 -> 0 | W28: =ROUND(CX28*I28,2) -> 0 | X28: =ROUND(CY28,2) -> 99.34 | Y28: =ROUND(CZ28,2) -> 50.77 | AA28: 56505403 | AB28: =ROUND((AC28+AD28+AF28),6) -> 147.58 | AC28: =ROUND((ES28),6) -> 3.92 | AD28: =ROUND(((((ET28*1.1))-((EU28*1.1)))+AE28),6) -> 42.812 | AE28: =ROUND(((EU28*1.1)),6) -> 4.576 | AF28: =ROUND(((EV28*1.1)),6) -> 100.848 | AG28: =ROUND((AP28),6) -> 0 | AH28: =((EW28*1.1)) -> 9.02 | AI28: =((EX28*1.1)) -> 0 | AJ28: =(AS28) -> 0 | AK28: 134.52 | AL28: 3.92 | AM28: 38.92 | AN28: 4.16 | AO28: 91.68 | AP28: 0 | AQ28: 8.2 | AR28: 0 | AS28: 0 | AT28: 90 | AU28: 46 | AV28: 1.047 | AW28: 1 | AZ28: 1 | BA28: 1 | BB28: 1 | BC28: 1 | BH28: 0 | BI28: 2 | BJ28: ТСН-2001.4 Доп. 80, Сб. 10, т. 32, поз. 1 | BM28: 68 | BN28: 0 | BO28: 4.10-32-1 | BP28: 1 | BQ28: 40 | BR28: 0 | BS28: 1 | BT28: 1 | BU28: 1 | BV28: 1 | BW28: 1 | BX28: 1 | BZ28: 90 | CA28: 46 | CE28: 30 | CF28: 0 | CG28: 0 | CM28: 0 | CO28: 0 | CP28: =(P28+Q28+S28) -> 154.33 | CQ28: =ROUND((ROUND((AC28*AW28*1),2)*BC28),2) -> 3.92 | CR28: =(ROUND((ROUND((((ET28*1.1))*AV28*1),2)*BB28),2)+ROUND((ROUND(((AE28-((EU28*1.1)))*AV28*1),2)*BS28),2)) -> 44.82 | CS28: =ROUND((ROUND((AE28*AV28*1),2)*BS28),2) -> 4.79 | CT28: =ROUND((ROUND((AF28*AV28*1),2)*BA28),2) -> 105.59 | CU28: =AG28 -> 0 | CV28: =(AH28*AV28) -> 9.44394 | CW28: =AI28 -> 0 | CX28: =AJ28 -> 0 | CY28: =(((S28+R28)*AT28)/100) -> 99.342 | CZ28: =(((S28+R28)*AU28)/100) -> 50.7748 | DE28: *1,1 | DF28: *1,1 | DG28: *1,1 | DI28: *1,1 | DJ28: *1,1 | DN28: 0 | DO28: 0 | DP28: 1 | DQ28: 1 | DU28: 1013 | DV28: 1 ШТ. | DW28: 1 ШТ. | DX28: 1 | EE28: 58162630 | EF28: 40 | EG28: Монтаж оборудования | EH28: 0 | EJ28: 2 | EK28: 68 | EL28: ТСН-2001.4-10. Прокладка и монтаж сетей связи | EM28: ТСН-2001.4-10-1 | EO28: Поправка: Гл.12.Прил.8.п.8. 5_12.00.01.11.003 | EQ28: 0 | ER28: 134.52 | ES28: 3.92 | ET28: 38.92 | EU28: 4.16 | EV28: 91.68 | EW28: 8.2 | EX28: 0 | EY28: 0 | FQ28: 0 | FR28: 0 | FS28: 0 | FX28: 90 | FY28: 46 | GD28: 1 | GF28: -1576476159 | GG28: 2 | GH28: 1 | GI28: 2 | GJ28: 0 | GK28: 0 | GL28: =ROUND(IF(AND(BH28=3,BI28=3,FS28<>0),P28,0),2) -> 0 | GM28: =ROUND(O28+X28+Y28,2)+GX28 -> 304.44 | GN28: =IF(OR(BI28=0,BI28=1),GM28-GX28,0) -> 0 | GO28: =IF(BI28=2,GM28-GX28,0) -> 304.44 | GP28: =IF(BI28=4,GM28-GX28,0) -> 0 | GR28: 0 | GS28: 3 | GT28: 0 | GV28: =ROUND((GT28),6) -> 0 | GW28: 1 | GX28: =ROUND(HC28*I28,2) -> 0 | HA28: 0 | HB28: 0 | HC28: =GV28*GW28 -> 0 | HS28: 0 | IK28: 0
A29: 17 | B29: 1 | D29: =ROW(EtalonRes!A12) -> 12 | E29: 1 | F29: 4.10-32-1 | G29: Монтаж стойки, полустойки, каркаса стойки или шкафа массой до 100 кг | H29: 1 ШТ. | I29: 1 | J29: 0 | K29: 1 | O29: =ROUND(CP29,2) -> 6524.23 | P29: =ROUND((ROUND((AC29*AW29*I29),2)*BC29),2) -> 32.54 | Q29: =(ROUND((ROUND((((ET29*1.1))*AV29*I29),2)*BB29),2)+ROUND((ROUND(((AE29-((EU29*1.1)))*AV29*I29),2)*BS29),2)) -> 685.3 | R29: =ROUND((ROUND((AE29*AV29*I29),2)*BS29),2) -> 263.4 | S29: =ROUND((ROUND((AF29*AV29*I29),2)*BA29),2) -> 5806.39 | T29: =ROUND(CU29*I29,2) -> 0 | U29: =CV29*I29 -> 9.44394 | V29: =CW29*I29 -> 0 | W29: =ROUND(CX29*I29,2) -> 0 | X29: =ROUND(CY29,2) -> 5462.81 | Y29: =ROUND(CZ29,2) -> 2792.1 | AA29: 56505405 | AB29: =ROUND((AC29+AD29+AF29),6) -> 147.58 | AC29: =ROUND((ES29),6) -> 3.92 | AD29: =ROUND(((((ET29*1.1))-((EU29*1.1)))+AE29),6) -> 42.812 | AE29: =ROUND(((EU29*1.1)),6) -> 4.576 | AF29: =ROUND(((EV29*1.1)),6) -> 100.848 | AG29: =ROUND((AP29),6) -> 0 | AH29: =((EW29*1.1)) -> 9.02 | AI29: =((EX29*1.1)) -> 0 | AJ29: =(AS29) -> 0 | AK29: 134.52 | AL29: 3.92 | AM29: 38.92 | AN29: 4.16 | AO29: 91.68 | AP29: 0 | AQ29: 8.2 | AR29: 0 | AS29: 0 | AT29: 90 | AU29: 46 | AV29: 1.047 | AW29: 1 | AZ29: 1 | BA29: 54.99 | BB29: 15.29 | BC29: 8.3 | BH29: 0 | BI29: 2 | BJ29: ТСН-2001.4 Доп. 80, Сб. 10, т. 32, поз. 1 | BM29: 68 | BN29: 0 | BO29: 4.10-32-1 | BP29: 1 | BQ29: 40 | BR29: 0 | BS29: 54.99 | BT29: 1 | BU29: 1 | BV29: 1 | BW29: 1 | BX29: 1 | BZ29: 90 | CA29: 46 | CE29: 30 | CF29: 0 | CG29: 0 | CM29: 0 | CO29: 0 | CP29: =(P29+Q29+S29) -> 6524.23 | CQ29: =ROUND((ROUND((AC29*AW29*1),2)*BC29),2) -> 32.54 | CR29: =(ROUND((ROUND((((ET29*1.1))*AV29*1),2)*BB29),2)+ROUND((ROUND(((AE29-((EU29*1.1)))*AV29*1),2)*BS29),2)) -> 685.3 | CS29: =ROUND((ROUND((AE29*AV29*1),2)*BS29),2) -> 263.4 | CT29: =ROUND((ROUND((AF29*AV29*1),2)*BA29),2) -> 5806.39 | CU29: =AG29 -> 0 | CV29: =(AH29*AV29) -> 9.44394 | CW29: =AI29 -> 0 | CX29: =AJ29 -> 0 | CY29: =(((S29+R29)*AT29)/100) -> 5462.811 | CZ29: =(((S29+R29)*AU29)/100) -> 2792.1034 | DE29: *1,1 | DF29: *1,1 | DG29: *1,1 | DI29: *1,1 | DJ29: *1,1 | DN29: 0 | DO29: 0 | DP29: 1 | DQ29: 1 | DU29: 1013 | DV29: 1 ШТ. | DW29: 1 ШТ. | DX29: 1 | EE29: 58162630 | EF29: 40 | EG29: Монтаж оборудования | EH29: 0 | EJ29: 2 | EK29: 68 | EL29: ТСН-2001.4-10. Прокладка и монтаж сетей связи | EM29: ТСН-2001.4-10-1 | EO29: Поправка: Гл.12.Прил.8.п.8. 5_12.00.01.11.003 | EQ29: 0 | ER29: 134.52 | ES29: 3.92 | ET29: 38.92 | EU29: 4.16 | EV29: 91.68 | EW29: 8.2 | EX29: 0 | EY29: 0 | FQ29: 0 | FR29: 0 | FS29: 0 | FX29: 90 | FY29: 46 | GD29: 1 | GF29: -1576476159 | GG29: 2 | GH29: 1 | GI29: 2 | GJ29: 0 | GK29: 0 | GL29: =ROUND(IF(AND(BH29=3,BI29=3,FS29<>0),P29,0),2) -> 0 | GM29: =ROUND(O29+X29+Y29,2)+GX29 -> 14779.14 | GN29: =IF(OR(BI29=0,BI29=1),GM29-GX29,0) -> 0 | GO29: =IF(BI29=2,GM29-GX29,0) -> 14779.14 | GP29: =IF(BI29=4,GM29-GX29,0) -> 0 | GR29: 0 | GS29: 3 | GT29: 0 | GV29: =ROUND((GT29),6) -> 0 | GW29: 1 | GX29: =ROUND(HC29*I29,2) -> 0 | HA29: 0 | HB29: 0 | HC29: =GV29*GW29 -> 0 | HS29: 0 | IK29: 0
A30: 18 | B30: 1 | E30: 1,1 | F30: КА 1 | G30: Шкаф 19" серии Racknet S3000, 47U 60F-47-7C-94BL | H30: шт. | I30: =I28*J30 -> 1 | J30: 1 | K30: 1 | O30: =ROUND(CP30,2) -> 16818.37 | P30: =ROUND((ROUND((AC30*AW30*I30),2)*BC30),2) -> 16818.37 | Q30: =(ROUND((ROUND(((ET30)*AV30*I30),2)*BB30),2)+ROUND((ROUND(((AE30-(EU30))*AV30*I30),2)*BS30),2)) -> 0 | R30: =ROUND((ROUND((AE30*AV30*I30),2)*BS30),2) -> 0 | S30: =ROUND((ROUND((AF30*AV30*I30),2)*BA30),2) -> 0 | T30: =ROUND(CU30*I30,2) -> 0 | U30: =CV30*I30 -> 0 | V30: =CW30*I30 -> 0 | W30: =ROUND(CX30*I30,2) -> 0 | X30: =ROUND(CY30,2) -> 0 | Y30: =ROUND(CZ30,2) -> 0 | AA30: 56505403 | AB30: =ROUND((AC30+AD30+AF30),6) -> 16818.37 | AC30: =ROUND((ES30),6) -> 16818.37 | AD30: =ROUND((((ET30)-(EU30))+AE30),6) -> 0 | AE30: =ROUND((EU30),6) -> 0 | AF30: =ROUND((EV30),6) -> 0 | AG30: =ROUND((AP30),6) -> 0 | AH30: =(EW30) -> 0 | AI30: =(EX30) -> 0 | AJ30: =(AS30) -> 0 | AK30: 16818.37 | AL30: 16818.37 | AM30: 0 | AN30: 0 | AO30: 0 | AP30: 0 | AQ30: 0 | AR30: 0 | AS30: 0 | AT30: 90 | AU30: 46 | AV30: 1 | AW30: 1 | AZ30: 1 | BA30: 1 | BB30: 1 | BC30: 1 | BH30: 3 | BI30: 2 | BM30: 68 | BN30: 0 | BP30: 0 | BQ30: 40 | BR30: 0 | BS30: 1 | BT30: 1 | BU30: 1 | BV30: 1 | BW30: 1 | BX30: 1 | BZ30: 90 | CA30: 46 | CE30: 30 | CF30: 0 | CG30: 0 | CM30: 0 | CO30: 0 | CP30: =(P30+Q30+S30) -> 16818.37 | CQ30: =ROUND((ROUND((AC30*AW30*1),2)*BC30),2) -> 16818.37 | CR30: =(ROUND((ROUND(((ET30)*AV30*1),2)*BB30),2)+ROUND((ROUND(((AE30-(EU30))*AV30*1),2)*BS30),2)) -> 0 | CS30: =ROUND((ROUND((AE30*AV30*1),2)*BS30),2) -> 0 | CT30: =ROUND((ROUND((AF30*AV30*1),2)*BA30),2) -> 0 | CU30: =AG30 -> 0 | CV30: =(AH30*AV30) -> 0 | CW30: =AI30 -> 0 | CX30: =AJ30 -> 0 | CY30: =(((S30+R30)*AT30)/100) -> 0 | CZ30: =(((S30+R30)*AU30)/100) -> 0 | DN30: 0 | DO30: 0 | DP30: 1 | DQ30: 1 | DU30: 1010 | DV30: шт. | DW30: шт. | DX30: 1 | EE30: 58162630 | EF30: 40 | EG30: Монтаж оборудования | EH30: 0 | EJ30: 2 | EK30: 68 | EL30: ТСН-2001.4-10. Прокладка и монтаж сетей связи | EM30: ТСН-2001.4-10-1 | EQ30: 0 | ER30: 0 | ES30: 16818.37 | ET30: 0 | EU30: 0 | EV30: 0 | EW30: 0 | EX30: 0 | FQ30: 0 | FR30: 0 | FS30: 0 | FX30: 90 | FY30: 46 | GA30: [195 488,81 / 1,2 / 9,88] + 2% Заг.скл | GD30: 1 | GF30: -199742500 | GG30: 2 | GH30: 4 | GI30: -2 | GJ30: 0 | GK30: 0 | GL30: =ROUND(IF(AND(BH30=3,BI30=3,FS30<>0),P30,0),2) -> 0 | GM30: =ROUND(O30+X30+Y30,2)+GX30 -> 16818.37 | GN30: =IF(OR(BI30=0,BI30=1),GM30-GX30,0) -> 0 | GO30: =IF(BI30=2,GM30-GX30,0) -> 16818.37 | GP30: =IF(BI30=4,GM30-GX30,0) -> 0 | GR30: 0 | GS30: 2 | GT30: 0 | GV30: =ROUND((GT30),6) -> 0 | GW30: 1 | GX30: =ROUND(HC30*I30,2) -> 0 | HA30: 0 | HB30: 0 | HC30: =GV30*GW30 -> 0 | HE30: 0 | HF30: 2 | HS30: 0 | IK30: 0
A31: 18 | B31: 1 | E31: 1,1 | F31: КА 1 | G31: Шкаф 19" серии Racknet S3000, 47U 60F-47-7C-94BL | H31: шт. | I31: =I29*J31 -> 1 | J31: 1 | K31: 1 | O31: =ROUND(CP31,2) -> 166165.5 | P31: =ROUND((ROUND((AC31*AW31*I31),2)*BC31),2) -> 166165.5 | Q31: =(ROUND((ROUND(((ET31)*AV31*I31),2)*BB31),2)+ROUND((ROUND(((AE31-(EU31))*AV31*I31),2)*BS31),2)) -> 0 | R31: =ROUND((ROUND((AE31*AV31*I31),2)*BS31),2) -> 0 | S31: =ROUND((ROUND((AF31*AV31*I31),2)*BA31),2) -> 0 | T31: =ROUND(CU31*I31,2) -> 0 | U31: =CV31*I31 -> 0 | V31: =CW31*I31 -> 0 | W31: =ROUND(CX31*I31,2) -> 0 | X31: =ROUND(CY31,2) -> 0 | Y31: =ROUND(CZ31,2) -> 0 | AA31: 56505405 | AB31: =ROUND((AC31+AD31+AF31),6) -> 16818.37 | AC31: =ROUND((ES31),6) -> 16818.37 | AD31: =ROUND((((ET31)-(EU31))+AE31),6) -> 0 | AE31: =ROUND((EU31),6) -> 0 | AF31: =ROUND((EV31),6) -> 0 | AG31: =ROUND((AP31),6) -> 0 | AH31: =(EW31) -> 0 | AI31: =(EX31) -> 0 | AJ31: =(AS31) -> 0 | AK31: 16818.37 | AL31: 16818.37 | AM31: 0 | AN31: 0 | AO31: 0 | AP31: 0 | AQ31: 0 | AR31: 0 | AS31: 0 | AT31: 90 | AU31: 46 | AV31: 1 | AW31: 1 | AZ31: 1 | BA31: 1 | BB31: 1 | BC31: 9.88 | BH31: 3 | BI31: 2 | BM31: 68 | BN31: 0 | BP31: 0 | BQ31: 40 | BR31: 0 | BS31: 1 | BT31: 1 | BU31: 1 | BV31: 1 | BW31: 1 | BX31: 1 | BZ31: 90 | CA31: 46 | CE31: 30 | CF31: 0 | CG31: 0 | CM31: 0 | CO31: 0 | CP31: =(P31+Q31+S31) -> 166165.5 | CQ31: =ROUND((ROUND((AC31*AW31*1),2)*BC31),2) -> 166165.5 | CR31: =(ROUND((ROUND(((ET31)*AV31*1),2)*BB31),2)+ROUND((ROUND(((AE31-(EU31))*AV31*1),2)*BS31),2)) -> 0 | CS31: =ROUND((ROUND((AE31*AV31*1),2)*BS31),2) -> 0 | CT31: =ROUND((ROUND((AF31*AV31*1),2)*BA31),2) -> 0 | CU31: =AG31 -> 0 | CV31: =(AH31*AV31) -> 0 | CW31: =AI31 -> 0 | CX31: =AJ31 -> 0 | CY31: =(((S31+R31)*AT31)/100) -> 0 | CZ31: =(((S31+R31)*AU31)/100) -> 0 | DN31: 0 | DO31: 0 | DP31: 1 | DQ31: 1 | DU31: 1010 | DV31: шт. | DW31: шт. | DX31: 1 | EE31: 58162630 | EF31: 40 | EG31: Монтаж оборудования | EH31: 0 | EJ31: 2 | EK31: 68 | EL31: ТСН-2001.4-10. Прокладка и монтаж сетей связи | EM31: ТСН-2001.4-10-1 | EQ31: 0 | ER31: 16818.37 | ES31: 16818.37 | ET31: 0 | EU31: 0 | EV31: 0 | EW31: 0 | EX31: 0 | EZ31: 5 | FC31: 1 | FD31: 18 | FF31: 195488.81 | FQ31: 0 | FR31: 0 | FS31: 0 | FX31: 90 | FY31: 46 | GA31: [195 488,81 / 1,2 / 9,88] + 2% Заг.скл | GD31: 1 | GF31: -199742500 | GG31: 2 | GH31: 3 | GI31: 5 | GJ31: 0 | GK31: 0 | GL31: =ROUND(IF(AND(BH31=3,BI31=3,FS31<>0),P31,0),2) -> 0 | GM31: =ROUND(O31+X31+Y31,2)+GX31 -> 166165.5 | GN31: =IF(OR(BI31=0,BI31=1),GM31-GX31,0) -> 0 | GO31: =IF(BI31=2,GM31-GX31,0) -> 166165.5 | GP31: =IF(BI31=4,GM31-GX31,0) -> 0 | GR31: 1 | GS31: 1 | GT31: 0 | GV31: =ROUND((GT31),6) -> 0 | GW31: 1 | GX31: =ROUND(HC31*I31,2) -> 0 | HA31: 0 | HB31: 0 | HC31: =GV31*GW31 -> 0 | HE31: 0 | HF31: 2 | HS31: 0 | IK31: 0
A32: 18 | B32: 1 | E32: 1,2 | F32: КА 2 | G32: Вертикальный органайзер 60А-18-47-01-31BL | H32: шт. | I32: =I28*J32 -> 1 | J32: 1 | K32: 1 | O32: =ROUND(CP32,2) -> 3548.41 | P32: =ROUND((ROUND((AC32*AW32*I32),2)*BC32),2) -> 3548.41 | Q32: =(ROUND((ROUND(((ET32)*AV32*I32),2)*BB32),2)+ROUND((ROUND(((AE32-(EU32))*AV32*I32),2)*BS32),2)) -> 0 | R32: =ROUND((ROUND((AE32*AV32*I32),2)*BS32),2) -> 0 | S32: =ROUND((ROUND((AF32*AV32*I32),2)*BA32),2) -> 0 | T32: =ROUND(CU32*I32,2) -> 0 | U32: =CV32*I32 -> 0 | V32: =CW32*I32 -> 0 | W32: =ROUND(CX32*I32,2) -> 0 | X32: =ROUND(CY32,2) -> 0 | Y32: =ROUND(CZ32,2) -> 0 | AA32: 56505403 | AB32: =ROUND((AC32+AD32+AF32),6) -> 3548.41 | AC32: =ROUND((ES32),6) -> 3548.41 | AD32: =ROUND((((ET32)-(EU32))+AE32),6) -> 0 | AE32: =ROUND((EU32),6) -> 0 | AF32: =ROUND((EV32),6) -> 0 | AG32: =ROUND((AP32),6) -> 0 | AH32: =(EW32) -> 0 | AI32: =(EX32) -> 0 | AJ32: =(AS32) -> 0 | AK32: 3548.41 | AL32: 3548.41 | AM32: 0 | AN32: 0 | AO32: 0 | AP32: 0 | AQ32: 0 | AR32: 0 | AS32: 0 | AT32: 90 | AU32: 46 | AV32: 1 | AW32: 1 | AZ32: 1 | BA32: 1 | BB32: 1 | BC32: 1 | BH32: 3 | BI32: 2 | BM32: 68 | BN32: 0 | BP32: 0 | BQ32: 40 | BR32: 0 | BS32: 1 | BT32: 1 | BU32: 1 | BV32: 1 | BW32: 1 | BX32: 1 | BZ32: 90 | CA32: 46 | CE32: 30 | CF32: 0 | CG32: 0 | CM32: 0 | CO32: 0 | CP32: =(P32+Q32+S32) -> 3548.41 | CQ32: =ROUND((ROUND((AC32*AW32*1),2)*BC32),2) -> 3548.41 | CR32: =(ROUND((ROUND(((ET32)*AV32*1),2)*BB32),2)+ROUND((ROUND(((AE32-(EU32))*AV32*1),2)*BS32),2)) -> 0 | CS32: =ROUND((ROUND((AE32*AV32*1),2)*BS32),2) -> 0 | CT32: =ROUND((ROUND((AF32*AV32*1),2)*BA32),2) -> 0 | CU32: =AG32 -> 0 | CV32: =(AH32*AV32) -> 0 | CW32: =AI32 -> 0 | CX32: =AJ32 -> 0 | CY32: =(((S32+R32)*AT32)/100) -> 0 | CZ32: =(((S32+R32)*AU32)/100) -> 0 | DN32: 0 | DO32: 0 | DP32: 1 | DQ32: 1 | DU32: 1010 | DV32: шт. | DW32: шт. | DX32: 1 | EE32: 58162630 | EF32: 40 | EG32: Монтаж оборудования | EH32: 0 | EJ32: 2 | EK32: 68 | EL32: ТСН-2001.4-10. Прокладка и монтаж сетей связи | EM32: ТСН-2001.4-10-1 | EQ32: 0 | ER32: 0 | ES32: 3548.41 | ET32: 0 | EU32: 0 | EV32: 0 | EW32: 0 | EX32: 0 | FQ32: 0 | FR32: 0 | FS32: 0 | FX32: 90 | FY32: 46 | GA32: [41 245 / 1,2 / 9,88] + 2% Заг.скл | GD32: 1 | GF32: 1007668642 | GG32: 2 | GH32: 4 | GI32: -2 | GJ32: 0 | GK32: 0 | GL32: =ROUND(IF(AND(BH32=3,BI32=3,FS32<>0),P32,0),2) -> 0 | GM32: =ROUND(O32+X32+Y32,2)+GX32 -> 3548.41 | GN32: =IF(OR(BI32=0,BI32=1),GM32-GX32,0) -> 0 | GO32: =IF(BI32=2,GM32-GX32,0) -> 3548.41 | GP32: =IF(BI32=4,GM32-GX32,0) -> 0 | GR32: 0 | GS32: 2 | GT32: 0 | GV32: =ROUND((GT32),6) -> 0 | GW32: 1 | GX32: =ROUND(HC32*I32,2) -> 0 | HA32: 0 | HB32: 0 | HC32: =GV32*GW32 -> 0 | HE32: 0 | HF32: 2 | HS32: 0 | IK32: 0
A33: 18 | B33: 1 | E33: 1,2 | F33: КА 2 | G33: Вертикальный органайзер 60А-18-47-01-31BL | H33: шт. | I33: =I29*J33 -> 1 | J33: 1 | K33: 1 | O33: =ROUND(CP33,2) -> 35058.29 | P33: =ROUND((ROUND((AC33*AW33*I33),2)*BC33),2) -> 35058.29 | Q33: =(ROUND((ROUND(((ET33)*AV33*I33),2)*BB33),2)+ROUND((ROUND(((AE33-(EU33))*AV33*I33),2)*BS33),2)) -> 0 | R33: =ROUND((ROUND((AE33*AV33*I33),2)*BS33),2) -> 0 | S33: =ROUND((ROUND((AF33*AV33*I33),2)*BA33),2) -> 0 | T33: =ROUND(CU33*I33,2) -> 0 | U33: =CV33*I33 -> 0 | V33: =CW33*I33 -> 0 | W33: =ROUND(CX33*I33,2) -> 0 | X33: =ROUND(CY33,2) -> 0 | Y33: =ROUND(CZ33,2) -> 0 | AA33: 56505405 | AB33: =ROUND((AC33+AD33+AF33),6) -> 3548.41 | AC33: =ROUND((ES33),6) -> 3548.41 | AD33: =ROUND((((ET33)-(EU33))+AE33),6) -> 0 | AE33: =ROUND((EU33),6) -> 0 | AF33: =ROUND((EV33),6) -> 0 | AG33: =ROUND((AP33),6) -> 0 | AH33: =(EW33) -> 0 | AI33: =(EX33) -> 0 | AJ33: =(AS33) -> 0 | AK33: 3548.41 | AL33: 3548.41 | AM33: 0 | AN33: 0 | AO33: 0 | AP33: 0 | AQ33: 0 | AR33: 0 | AS33: 0 | AT33: 90 | AU33: 46 | AV33: 1 | AW33: 1 | AZ33: 1 | BA33: 1 | BB33: 1 | BC33: 9.88 | BH33: 3 | BI33: 2 | BM33: 68 | BN33: 0 | BP33: 0 | BQ33: 40 | BR33: 0 | BS33: 1 | BT33: 1 | BU33: 1 | BV33: 1 | BW33: 1 | BX33: 1 | BZ33: 90 | CA33: 46 | CE33: 30 | CF33: 0 | CG33: 0 | CM33: 0 | CO33: 0 | CP33: =(P33+Q33+S33) -> 35058.29 | CQ33: =ROUND((ROUND((AC33*AW33*1),2)*BC33),2) -> 35058.29 | CR33: =(ROUND((ROUND(((ET33)*AV33*1),2)*BB33),2)+ROUND((ROUND(((AE33-(EU33))*AV33*1),2)*BS33),2)) -> 0 | CS33: =ROUND((ROUND((AE33*AV33*1),2)*BS33),2) -> 0 | CT33: =ROUND((ROUND((AF33*AV33*1),2)*BA33),2) -> 0 | CU33: =AG33 -> 0 | CV33: =(AH33*AV33) -> 0 | CW33: =AI33 -> 0 | CX33: =AJ33 -> 0 | CY33: =(((S33+R33)*AT33)/100) -> 0 | CZ33: =(((S33+R33)*AU33)/100) -> 0 | DN33: 0 | DO33: 0 | DP33: 1 | DQ33: 1 | DU33: 1010 | DV33: шт. | DW33: шт. | DX33: 1 | EE33: 58162630 | EF33: 40 | EG33: Монтаж оборудования | EH33: 0 | EJ33: 2 | EK33: 68 | EL33: ТСН-2001.4-10. Прокладка и монтаж сетей связи | EM33: ТСН-2001.4-10-1 | EQ33: 0 | ER33: 3548.41 | ES33: 3548.41 | ET33: 0 | EU33: 0 | EV33: 0 | EW33: 0 | EX33: 0 | EZ33: 5 | FC33: 1 | FD33: 18 | FF33: 41245 | FQ33: 0 | FR33: 0 | FS33: 0 | FX33: 90 | FY33: 46 | GA33: [41 245 / 1,2 / 9,88] + 2% Заг.скл | GD33: 1 | GF33: 1007668642 | GG33: 2 | GH33: 3 | GI33: 5 | GJ33: 0 | GK33: 0 | GL33: =ROUND(IF(AND(BH33=3,BI33=3,FS33<>0),P33,0),2) -> 0 | GM33: =ROUND(O33+X33+Y33,2)+GX33 -> 35058.29 | GN33: =IF(OR(BI33=0,BI33=1),GM33-GX33,0) -> 0 | GO33: =IF(BI33=2,GM33-GX33,0) -> 35058.29 | GP33: =IF(BI33=4,GM33-GX33,0) -> 0 | GR33: 1 | GS33: 1 | GT33: 0 | GV33: =ROUND((GT33),6) -> 0 | GW33: 1 | GX33: =ROUND(HC33*I33,2) -> 0 | HA33: 0 | HB33: 0 | HC33: =GV33*GW33 -> 0 | HE33: 0 | HF33: 2 | HS33: 0 | IK33: 0
A34: 18 | B34: 1 | E34: 1,3 | F34: КА 7 | G34: Набор для креnленuя лоmков к крышке шкафов, высоmа 50мм 60А-31-08-ЗЗВL | H34: шт. | I34: =I28*J34 -> 1 | J34: 1 | K34: 1 | O34: =ROUND(CP34,2) -> 147.62 | P34: =ROUND((ROUND((AC34*AW34*I34),2)*BC34),2) -> 147.62 | Q34: =(ROUND((ROUND(((ET34)*AV34*I34),2)*BB34),2)+ROUND((ROUND(((AE34-(EU34))*AV34*I34),2)*BS34),2)) -> 0 | R34: =ROUND((ROUND((AE34*AV34*I34),2)*BS34),2) -> 0 | S34: =ROUND((ROUND((AF34*AV34*I34),2)*BA34),2) -> 0 | T34: =ROUND(CU34*I34,2) -> 0 | U34: =CV34*I34 -> 0 | V34: =CW34*I34 -> 0 | W34: =ROUND(CX34*I34,2) -> 0 | X34: =ROUND(CY34,2) -> 0 | Y34: =ROUND(CZ34,2) -> 0 | AA34: 56505403 | AB34: =ROUND((AC34+AD34+AF34),6) -> 147.62 | AC34: =ROUND((ES34),6) -> 147.62 | AD34: =ROUND((((ET34)-(EU34))+AE34),6) -> 0 | AE34: =ROUND((EU34),6) -> 0 | AF34: =ROUND((EV34),6) -> 0 | AG34: =ROUND((AP34),6) -> 0 | AH34: =(EW34) -> 0 | AI34: =(EX34) -> 0 | AJ34: =(AS34) -> 0 | AK34: 147.62 | AL34: 147.62 | AM34: 0 | AN34: 0 | AO34: 0 | AP34: 0 | AQ34: 0 | AR34: 0 | AS34: 0 | AT34: 90 | AU34: 46 | AV34: 1 | AW34: 1 | AZ34: 1 | BA34: 1 | BB34: 1 | BC34: 1 | BH34: 3 | BI34: 2 | BM34: 68 | BN34: 0 | BP34: 0 | BQ34: 40 | BR34: 0 | BS34: 1 | BT34: 1 | BU34: 1 | BV34: 1 | BW34: 1 | BX34: 1 | BZ34: 90 | CA34: 46 | CE34: 30 | CF34: 0 | CG34: 0 | CM34: 0 | CO34: 0 | CP34: =(P34+Q34+S34) -> 147.62 | CQ34: =ROUND((ROUND((AC34*AW34*1),2)*BC34),2) -> 147.62 | CR34: =(ROUND((ROUND(((ET34)*AV34*1),2)*BB34),2)+ROUND((ROUND(((AE34-(EU34))*AV34*1),2)*BS34),2)) -> 0 | CS34: =ROUND((ROUND((AE34*AV34*1),2)*BS34),2) -> 0 | CT34: =ROUND((ROUND((AF34*AV34*1),2)*BA34),2) -> 0 | CU34: =AG34 -> 0 | CV34: =(AH34*AV34) -> 0 | CW34: =AI34 -> 0 | CX34: =AJ34 -> 0 | CY34: =(((S34+R34)*AT34)/100) -> 0 | CZ34: =(((S34+R34)*AU34)/100) -> 0 | DN34: 0 | DO34: 0 | DP34: 1 | DQ34: 1 | DU34: 1010 | DV34: шт. | DW34: шт. | DX34: 1 | EE34: 58162630 | EF34: 40 | EG34: Монтаж оборудования | EH34: 0 | EJ34: 2 | EK34: 68 | EL34: ТСН-2001.4-10. Прокладка и монтаж сетей связи | EM34: ТСН-2001.4-10-1 | EQ34: 0 | ER34: 0 | ES34: 147.62 | ET34: 0 | EU34: 0 | EV34: 0 | EW34: 0 | EX34: 0 | FQ34: 0 | FR34: 0 | FS34: 0 | FX34: 90 | FY34: 46 | GA34: [1 715,95 / 1,2 / 9,88] + 2% Заг.скл | GD34: 1 | GF34: -957674279 | GG34: 2 | GH34: 4 | GI34: -2 | GJ34: 0 | GK34: 0 | GL34: =ROUND(IF(AND(BH34=3,BI34=3,FS34<>0),P34,0),2) -> 0 | GM34: =ROUND(O34+X34+Y34,2)+GX34 -> 147.62 | GN34: =IF(OR(BI34=0,BI34=1),GM34-GX34,0) -> 0 | GO34: =IF(BI34=2,GM34-GX34,0) -> 147.62 | GP34: =IF(BI34=4,GM34-GX34,0) -> 0 | GR34: 0 | GS34: 2 | GT34: 0 | GV34: =ROUND((GT34),6) -> 0 | GW34: 1 | GX34: =ROUND(HC34*I34,2) -> 0 | HA34: 0 | HB34: 0 | HC34: =GV34*GW34 -> 0 | HE34: 0 | HF34: 2 | HS34: 0 | IK34: 0
A35: 18 | B35: 1 | E35: 1,3 | F35: КА 7 | G35: Набор для креnленuя лоmков к крышке шкафов, высоmа 50мм 60А-31-08-ЗЗВL | H35: шт. | I35: =I29*J35 -> 1 | J35: 1 | K35: 1 | O35: =ROUND(CP35,2) -> 1458.49 | P35: =ROUND((ROUND((AC35*AW35*I35),2)*BC35),2) -> 1458.49 | Q35: =(ROUND((ROUND(((ET35)*AV35*I35),2)*BB35),2)+ROUND((ROUND(((AE35-(EU35))*AV35*I35),2)*BS35),2)) -> 0 | R35: =ROUND((ROUND((AE35*AV35*I35),2)*BS35),2) -> 0 | S35: =ROUND((ROUND((AF35*AV35*I35),2)*BA35),2) -> 0 | T35: =ROUND(CU35*I35,2) -> 0 | U35: =CV35*I35 -> 0 | V35: =CW35*I35 -> 0 | W35: =ROUND(CX35*I35,2) -> 0 | X35: =ROUND(CY35,2) -> 0 | Y35: =ROUND(CZ35,2) -> 0 | AA35: 56505405 | AB35: =ROUND((AC35+AD35+AF35),6) -> 147.62 | AC35: =ROUND((ES35),6) -> 147.62 | AD35: =ROUND((((ET35)-(EU35))+AE35),6) -> 0 | AE35: =ROUND((EU35),6) -> 0 | AF35: =ROUND((EV35),6) -> 0 | AG35: =ROUND((AP35),6) -> 0 | AH35: =(EW35) -> 0 | AI35: =(EX35) -> 0 | AJ35: =(AS35) -> 0 | AK35: 147.62 | AL35: 147.62 | AM35: 0 | AN35: 0 | AO35: 0 | AP35: 0 | AQ35: 0 | AR35: 0 | AS35: 0 | AT35: 90 | AU35: 46 | AV35: 1 | AW35: 1 | AZ35: 1 | BA35: 1 | BB35: 1 | BC35: 9.88 | BH35: 3 | BI35: 2 | BM35: 68 | BN35: 0 | BP35: 0 | BQ35: 40 | BR35: 0 | BS35: 1 | BT35: 1 | BU35: 1 | BV35: 1 | BW35: 1 | BX35: 1 | BZ35: 90 | CA35: 46 | CE35: 30 | CF35: 0 | CG35: 0 | CM35: 0 | CO35: 0 | CP35: =(P35+Q35+S35) -> 1458.49 | CQ35: =ROUND((ROUND((AC35*AW35*1),2)*BC35),2) -> 1458.49 | CR35: =(ROUND((ROUND(((ET35)*AV35*1),2)*BB35),2)+ROUND((ROUND(((AE35-(EU35))*AV35*1),2)*BS35),2)) -> 0 | CS35: =ROUND((ROUND((AE35*AV35*1),2)*BS35),2) -> 0 | CT35: =ROUND((ROUND((AF35*AV35*1),2)*BA35),2) -> 0 | CU35: =AG35 -> 0 | CV35: =(AH35*AV35) -> 0 | CW35: =AI35 -> 0 | CX35: =AJ35 -> 0 | CY35: =(((S35+R35)*AT35)/100) -> 0 | CZ35: =(((S35+R35)*AU35)/100) -> 0 | DN35: 0 | DO35: 0 | DP35: 1 | DQ35: 1 | DU35: 1010 | DV35: шт. | DW35: шт. | DX35: 1 | EE35: 58162630 | EF35: 40 | EG35: Монтаж оборудования | EH35: 0 | EJ35: 2 | EK35: 68 | EL35: ТСН-2001.4-10. Прокладка и монтаж сетей связи | EM35: ТСН-2001.4-10-1 | EQ35: 0 | ER35: 147.62 | ES35: 147.62 | ET35: 0 | EU35: 0 | EV35: 0 | EW35: 0 | EX35: 0 | EZ35: 5 | FC35: 1 | FD35: 18 | FF35: 1715.95 | FQ35: 0 | FR35: 0 | FS35: 0 | FX35: 90 | FY35: 46 | GA35: [1 715,95 / 1,2 / 9,88] + 2% Заг.скл | GD35: 1 | GF35: -957674279 | GG35: 2 | GH35: 3 | GI35: 5 | GJ35: 0 | GK35: 0 | GL35: =ROUND(IF(AND(BH35=3,BI35=3,FS35<>0),P35,0),2) -> 0 | GM35: =ROUND(O35+X35+Y35,2)+GX35 -> 1458.49 | GN35: =IF(OR(BI35=0,BI35=1),GM35-GX35,0) -> 0 | GO35: =IF(BI35=2,GM35-GX35,0) -> 1458.49 | GP35: =IF(BI35=4,GM35-GX35,0) -> 0 | GR35: 1 | GS35: 1 | GT35: 0 | GV35: =ROUND((GT35),6) -> 0 | GW35: 1 | GX35: =ROUND(HC35*I35,2) -> 0 | HA35: 0 | HB35: 0 | HC35: =GV35*GW35 -> 0 | HE35: 0 | HF35: 2 | HS35: 0 | IK35: 0
A36: 17 | B36: 1 | D36: =ROW(EtalonRes!A15) -> 15 | E36: 2 | F36: 4.11-12-1 | G36: Установка съемных и выдвижных блоков (модулей, ячеек, ТЭЗ) массой до 5 кг | H36: 1 ШТ. | I36: =ROUND(1+1+1+1,9) -> 4 | J36: 0 | K36: =ROUND(1+1+1+1,9) -> 4 | O36: =ROUND(CP36,2) -> 55.97 | P36: =ROUND((ROUND((AC36*AW36*I36),2)*BC36),2) -> 0 | Q36: =(ROUND((ROUND((((ET36*1.1))*AV36*I36),2)*BB36),2)+ROUND((ROUND(((AE36-((EU36*1.1)))*AV36*I36),2)*BS36),2)) -> 2.3 | R36: =ROUND((ROUND((AE36*AV36*I36),2)*BS36),2) -> 0.37 | S36: =ROUND((ROUND((AF36*AV36*I36),2)*BA36),2) -> 53.67 | T36: =ROUND(CU36*I36,2) -> 0 | U36: =CV36*I36 -> 4.745004 | V36: =CW36*I36 -> 0 | W36: =ROUND(CX36*I36,2) -> 0 | X36: =ROUND(CY36,2) -> 48.64 | Y36: =ROUND(CZ36,2) -> 24.86 | AA36: 56505403 | AB36: =ROUND((AC36+AD36+AF36),6) -> 13.365 | AC36: =ROUND((ES36),6) -> 0 | AD36: =ROUND(((((ET36*1.1))-((EU36*1.1)))+AE36),6) -> 0.55 | AE36: =ROUND(((EU36*1.1)),6) -> 0.088 | AF36: =ROUND(((EV36*1.1)),6) -> 12.815 | AG36: =ROUND((AP36),6) -> 0 | AH36: =((EW36*1.1)) -> 1.133 | AI36: =((EX36*1.1)) -> 0 | AJ36: =(AS36) -> 0 | AK36: 12.15 | AL36: 0 | AM36: 0.5 | AN36: 0.08 | AO36: 11.65 | AP36: 0 | AQ36: 1.03 | AR36: 0 | AS36: 0 | AT36: 90 | AU36: 46 | AV36: 1.047 | AW36: 1 | AZ36: 1 | BA36: 1 | BB36: 1 | BC36: 1 | BH36: 0 | BI36: 2 | BJ36: ТСН-2001.4 Доп. 68, Сб. 11, т. 12, поз. 1 | BM36: 72 | BN36: 0 | BO36: 4.11-12-1 | BP36: 1 | BQ36: 40 | BR36: 0 | BS36: 1 | BT36: 1 | BU36: 1 | BV36: 1 | BW36: 1 | BX36: 1 | BZ36: 90 | CA36: 46 | CE36: 30 | CF36: 0 | CG36: 0 | CM36: 0 | CO36: 0 | CP36: =(P36+Q36+S36) -> 55.97 | CQ36: =ROUND((ROUND((AC36*AW36*1),2)*BC36),2) -> 0 | CR36: =(ROUND((ROUND((((ET36*1.1))*AV36*1),2)*BB36),2)+ROUND((ROUND(((AE36-((EU36*1.1)))*AV36*1),2)*BS36),2)) -> 0.58 | CS36: =ROUND((ROUND((AE36*AV36*1),2)*BS36),2) -> 0.09 | CT36: =ROUND((ROUND((AF36*AV36*1),2)*BA36),2) -> 13.42 | CU36: =AG36 -> 0 | CV36: =(AH36*AV36) -> 1.186251 | CW36: =AI36 -> 0 | CX36: =AJ36 -> 0 | CY36: =(((S36+R36)*AT36)/100) -> 48.636 | CZ36: =(((S36+R36)*AU36)/100) -> 24.8584 | DE36: *1,1 | DF36: *1,1 | DG36: *1,1 | DI36: *1,1 | DJ36: *1,1 | DN36: 0 | DO36: 0 | DP36: 1 | DQ36: 1 | DU36: 1013 | DV36: 1 ШТ. | DW36: 1 ШТ. | DX36: 1 | EE36: 58162634 | EF36: 40 | EG36: Монтаж оборудования | EH36: 0 | EJ36: 2 | EK36: 72 | EL36: ТСН-2001.4-11. Приборы и средства автоматизации и вычислительной техники | EM36: ТСН-2001.4-11-1 | EO36: Поправка: Гл.12.Прил.8.п.8. 5_12.00.01.11.003 | EQ36: 0 | ER36: 12.15 | ES36: 0 | ET36: 0.5 | EU36: 0.08 | EV36: 11.65 | EW36: 1.03 | EX36: 0 | EY36: 0 | FQ36: 0 | FR36: 0 | FS36: 0 | FX36: 90 | FY36: 46 | GD36: 1 | GF36: 1708693888 | GG36: 2 | GH36: 1 | GI36: 2 | GJ36: 0 | GK36: 0 | GL36: =ROUND(IF(AND(BH36=3,BI36=3,FS36<>0),P36,0),2) -> 0 | GM36: =ROUND(O36+X36+Y36,2)+GX36 -> 129.47 | GN36: =IF(OR(BI36=0,BI36=1),GM36-GX36,0) -> 0 | GO36: =IF(BI36=2,GM36-GX36,0) -> 129.47 | GP36: =IF(BI36=4,GM36-GX36,0) -> 0 | GR36: 0 | GS36: 3 | GT36: 0 | GV36: =ROUND((GT36),6) -> 0 | GW36: 1 | GX36: =ROUND(HC36*I36,2) -> 0 | HA36: 0 | HB36: 0 | HC36: =GV36*GW36 -> 0 | HS36: 0 | IK36: 0
A37: 17 | B37: 1 | D37: =ROW(EtalonRes!A18) -> 18 | E37: 2 | F37: 4.11-12-1 | G37: Установка съемных и выдвижных блоков (модулей, ячеек, ТЭЗ) массой до 5 кг | H37: 1 ШТ. | I37: =ROUND(1+1+1+1,9) -> 4 | J37: 0 | K37: =ROUND(1+1+1+1,9) -> 4 | O37: =ROUND(CP37,2) -> 2988.71 | P37: =ROUND((ROUND((AC37*AW37*I37),2)*BC37),2) -> 0 | Q37: =(ROUND((ROUND((((ET37*1.1))*AV37*I37),2)*BB37),2)+ROUND((ROUND(((AE37-((EU37*1.1)))*AV37*I37),2)*BS37),2)) -> 37.4 | R37: =ROUND((ROUND((AE37*AV37*I37),2)*BS37),2) -> 20.35 | S37: =ROUND((ROUND((AF37*AV37*I37),2)*BA37),2) -> 2951.31 | T37: =ROUND(CU37*I37,2) -> 0 | U37: =CV37*I37 -> 4.745004 | V37: =CW37*I37 -> 0 | W37: =ROUND(CX37*I37,2) -> 0 | X37: =ROUND(CY37,2) -> 2674.49 | Y37: =ROUND(CZ37,2) -> 1366.96 | AA37: 56505405 | AB37: =ROUND((AC37+AD37+AF37),6) -> 13.365 | AC37: =ROUND((ES37),6) -> 0 | AD37: =ROUND(((((ET37*1.1))-((EU37*1.1)))+AE37),6) -> 0.55 | AE37: =ROUND(((EU37*1.1)),6) -> 0.088 | AF37: =ROUND(((EV37*1.1)),6) -> 12.815 | AG37: =ROUND((AP37),6) -> 0 | AH37: =((EW37*1.1)) -> 1.133 | AI37: =((EX37*1.1)) -> 0 | AJ37: =(AS37) -> 0 | AK37: 12.15 | AL37: 0 | AM37: 0.5 | AN37: 0.08 | AO37: 11.65 | AP37: 0 | AQ37: 1.03 | AR37: 0 | AS37: 0 | AT37: 90 | AU37: 46 | AV37: 1.047 | AW37: 1 | AZ37: 1 | BA37: 54.99 | BB37: 16.26 | BC37: 1 | BH37: 0 | BI37: 2 | BJ37: ТСН-2001.4 Доп. 68, Сб. 11, т. 12, поз. 1 | BM37: 72 | BN37: 0 | BO37: 4.11-12-1 | BP37: 1 | BQ37: 40 | BR37: 0 | BS37: 54.99 | BT37: 1 | BU37: 1 | BV37: 1 | BW37: 1 | BX37: 1 | BZ37: 90 | CA37: 46 | CE37: 30 | CF37: 0 | CG37: 0 | CM37: 0 | CO37: 0 | CP37: =(P37+Q37+S37) -> 2988.71 | CQ37: =ROUND((ROUND((AC37*AW37*1),2)*BC37),2) -> 0 | CR37: =(ROUND((ROUND((((ET37*1.1))*AV37*1),2)*BB37),2)+ROUND((ROUND(((AE37-((EU37*1.1)))*AV37*1),2)*BS37),2)) -> 9.43 | CS37: =ROUND((ROUND((AE37*AV37*1),2)*BS37),2) -> 4.95 | CT37: =ROUND((ROUND((AF37*AV37*1),2)*BA37),2) -> 737.97 | CU37: =AG37 -> 0 | CV37: =(AH37*AV37) -> 1.186251 | CW37: =AI37 -> 0 | CX37: =AJ37 -> 0 | CY37: =(((S37+R37)*AT37)/100) -> 2674.494 | CZ37: =(((S37+R37)*AU37)/100) -> 1366.9636 | DE37: *1,1 | DF37: *1,1 | DG37: *1,1 | DI37: *1,1 | DJ37: *1,1 | DN37: 0 | DO37: 0 | DP37: 1 | DQ37: 1 | DU37: 1013 | DV37: 1 ШТ. | DW37: 1 ШТ. | DX37: 1 | EE37: 58162634 | EF37: 40 | EG37: Монтаж оборудования | EH37: 0 | EJ37: 2 | EK37: 72 | EL37: ТСН-2001.4-11. Приборы и средства автоматизации и вычислительной техники | EM37: ТСН-2001.4-11-1 | EO37: Поправка: Гл.12.Прил.8.п.8. 5_12.00.01.11.003 | EQ37: 0 | ER37: 12.15 | ES37: 0 | ET37: 0.5 | EU37: 0.08 | EV37: 11.65 | EW37: 1.03 | EX37: 0 | EY37: 0 | FQ37: 0 | FR37: 0 | FS37: 0 | FX37: 90 | FY37: 46 | GD37: 1 | GF37: 1708693888 | GG37: 2 | GH37: 1 | GI37: 2 | GJ37: 0 | GK37: 0 | GL37: =ROUND(IF(AND(BH37=3,BI37=3,FS37<>0),P37,0),2) -> 0 | GM37: =ROUND(O37+X37+Y37,2)+GX37 -> 7030.16 | GN37: =IF(OR(BI37=0,BI37=1),GM37-GX37,0) -> 0 | GO37: =IF(BI37=2,GM37-GX37,0) -> 7030.16 | GP37: =IF(BI37=4,GM37-GX37,0) -> 0 | GR37: 0 | GS37: 3 | GT37: 0 | GV37: =ROUND((GT37),6) -> 0 | GW37: 1 | GX37: =ROUND(HC37*I37,2) -> 0 | HA37: 0 | HB37: 0 | HC37: =GV37*GW37 -> 0 | HS37: 0 | IK37: 0
A38: 18 | B38: 1 | E38: 2,1 | F38: КА 3 | G38: Вентиляторная панель 60А-91-11-30ВL | H38: шт. | I38: =I36*J38 -> 1 | J38: 0.25 | K38: 0.25 | O38: =ROUND(CP38,2) -> 3213.03 | P38: =ROUND((ROUND((AC38*I38),2)*BC38),2) -> 3213.03 | Q38: =(ROUND((ROUND(((ET38)*AV38*I38),2)*BB38),2)+ROUND((ROUND(((AE38-(EU38))*AV38*I38),2)*BS38),2)) -> 0 | R38: =ROUND((ROUND((AE38*AV38*I38),2)*BS38),2) -> 0 | S38: =ROUND((ROUND((AF38*AV38*I38),2)*BA38),2) -> 0 | T38: =ROUND(CU38*I38,2) -> 0 | U38: =CV38*I38 -> 0 | V38: =CW38*I38 -> 0 | W38: =ROUND(CX38*I38,2) -> 0 | X38: =ROUND(CY38,2) -> 0 | Y38: =ROUND(CZ38,2) -> 0 | AA38: 56505403 | AB38: =ROUND((AC38+AD38+AF38),6) -> 3213.03 | AC38: =ROUND((ES38),6) -> 3213.03 | AD38: =ROUND((((ET38)-(EU38))+AE38),6) -> 0 | AE38: =ROUND((EU38),6) -> 0 | AF38: =ROUND((EV38),6) -> 0 | AG38: =ROUND((AP38),6) -> 0 | AH38: =(EW38) -> 0 | AI38: =(EX38) -> 0 | AJ38: =(AS38) -> 0 | AK38: 3213.03 | AL38: 3213.03 | AM38: 0 | AN38: 0 | AO38: 0 | AP38: 0 | AQ38: 0 | AR38: 0 | AS38: 0 | AT38: 0 | AU38: 0 | AV38: 1 | AW38: 1 | AZ38: 1 | BA38: 1 | BB38: 1 | BC38: 1 | BH38: 3 | BI38: 3 | BM38: 746 | BN38: 0 | BP38: 0 | BQ38: 130 | BR38: 0 | BS38: 1 | BT38: 1 | BU38: 1 | BV38: 1 | BW38: 1 | BX38: 1 | BZ38: 90 | CA38: 46 | CE38: 30 | CF38: 0 | CG38: 0 | CM38: 0 | CO38: 0 | CP38: =(P38+Q38+S38) -> 3213.03 | CQ38: =ROUND((ROUND((AC38*1),2)*BC38),2) -> 3213.03 | CR38: =(ROUND((ROUND(((ET38)*AV38*1),2)*BB38),2)+ROUND((ROUND(((AE38-(EU38))*AV38*1),2)*BS38),2)) -> 0 | CS38: =ROUND((ROUND((AE38*AV38*1),2)*BS38),2) -> 0 | CT38: =ROUND((ROUND((AF38*AV38*1),2)*BA38),2) -> 0 | CU38: =AG38 -> 0 | CV38: =(AH38*AV38) -> 0 | CW38: =AI38 -> 0 | CX38: =AJ38 -> 0 | CY38: =(((S38+R38)*AT38)/100) -> 0 | CZ38: =(((S38+R38)*AU38)/100) -> 0 | DN38: 0 | DO38: 0 | DP38: 1 | DQ38: 1 | DU38: 1010 | DV38: шт. | DW38: шт. | DX38: 1 | EE38: 58162750 | EF38: 130 | EG38: Сметная стоимость оборудования | EH38: 0 | EJ38: 3 | EK38: 746 | EL38: ТСН-2001.13. Сметная стоимость оборудования | EM38: ТСН-2001.13 | EQ38: 0 | ER38: 0 | ES38: 3213.03 | ET38: 0 | EU38: 0 | EV38: 0 | EW38: 0 | EX38: 0 | FQ38: 0 | FR38: =P38 -> 3213.03 | FS38: 0 | FX38: 90 | FY38: 46 | GA38: [28 334 / 1,2 / 7,66] + 3% Трансп + 1,2% Заг.скл | GD38: 1 | GF38: 174995452 | GG38: 2 | GH38: 4 | GI38: -2 | GJ38: 0 | GK38: 0 | GL38: =ROUND(IF(AND(BH38=3,BI38=3,FS38<>0),P38,0),2) -> 0 | GM38: =ROUND(O38+X38+Y38,2)+GX38 -> 3213.03 | GN38: =IF(OR(BI38=0,BI38=1),GM38-GX38,0) -> 0 | GO38: =IF(BI38=2,GM38-GX38,0) -> 0 | GP38: =IF(BI38=4,GM38-GX38,0) -> 0 | GR38: 0 | GS38: 2 | GT38: 0 | GV38: =ROUND((GT38),6) -> 0 | GW38: 1 | GX38: =ROUND(HC38*I38,2) -> 0 | HA38: 0 | HB38: 0 | HC38: =GV38*GW38 -> 0 | HE38: 3 | HF38: 1,2 | HS38: 0 | IK38: 0
A39: 18 | B39: 1 | E39: 2,1 | F39: КА 3 | G39: Вентиляторная панель 60А-91-11-30ВL | H39: шт. | I39: =I37*J39 -> 1 | J39: 0.25 | K39: 0.25 | O39: =ROUND(CP39,2) -> 24611.81 | P39: =ROUND((ROUND((AC39*I39),2)*BC39),2) -> 24611.81 | Q39: =(ROUND((ROUND(((ET39)*AV39*I39),2)*BB39),2)+ROUND((ROUND(((AE39-(EU39))*AV39*I39),2)*BS39),2)) -> 0 | R39: =ROUND((ROUND((AE39*AV39*I39),2)*BS39),2) -> 0 | S39: =ROUND((ROUND((AF39*AV39*I39),2)*BA39),2) -> 0 | T39: =ROUND(CU39*I39,2) -> 0 | U39: =CV39*I39 -> 0 | V39: =CW39*I39 -> 0 | W39: =ROUND(CX39*I39,2) -> 0 | X39: =ROUND(CY39,2) -> 0 | Y39: =ROUND(CZ39,2) -> 0 | AA39: 56505405 | AB39: =ROUND((AC39+AD39+AF39),6) -> 3213.03 | AC39: =ROUND((ES39),6) -> 3213.03 | AD39: =ROUND((((ET39)-(EU39))+AE39),6) -> 0 | AE39: =ROUND((EU39),6) -> 0 | AF39: =ROUND((EV39),6) -> 0 | AG39: =ROUND((AP39),6) -> 0 | AH39: =(EW39) -> 0 | AI39: =(EX39) -> 0 | AJ39: =(AS39) -> 0 | AK39: 3213.03 | AL39: 3213.03 | AM39: 0 | AN39: 0 | AO39: 0 | AP39: 0 | AQ39: 0 | AR39: 0 | AS39: 0 | AT39: 0 | AU39: 0 | AV39: 1 | AW39: 1 | AZ39: 1 | BA39: 1 | BB39: 1 | BC39: 7.66 | BH39: 3 | BI39: 3 | BM39: 746 | BN39: 0 | BP39: 0 | BQ39: 130 | BR39: 0 | BS39: 1 | BT39: 1 | BU39: 1 | BV39: 1 | BW39: 1 | BX39: 1 | BZ39: 90 | CA39: 46 | CE39: 30 | CF39: 0 | CG39: 0 | CM39: 0 | CO39: 0 | CP39: =(P39+Q39+S39) -> 24611.81 | CQ39: =ROUND((ROUND((AC39*1),2)*BC39),2) -> 24611.81 | CR39: =(ROUND((ROUND(((ET39)*AV39*1),2)*BB39),2)+ROUND((ROUND(((AE39-(EU39))*AV39*1),2)*BS39),2)) -> 0 | CS39: =ROUND((ROUND((AE39*AV39*1),2)*BS39),2) -> 0 | CT39: =ROUND((ROUND((AF39*AV39*1),2)*BA39),2) -> 0 | CU39: =AG39 -> 0 | CV39: =(AH39*AV39) -> 0 | CW39: =AI39 -> 0 | CX39: =AJ39 -> 0 | CY39: =(((S39+R39)*AT39)/100) -> 0 | CZ39: =(((S39+R39)*AU39)/100) -> 0 | DN39: 0 | DO39: 0 | DP39: 1 | DQ39: 1 | DU39: 1010 | DV39: шт. | DW39: шт. | DX39: 1 | EE39: 58162750 | EF39: 130 | EG39: Сметная стоимость оборудования | EH39: 0 | EJ39: 3 | EK39: 746 | EL39: ТСН-2001.13. Сметная стоимость оборудования | EM39: ТСН-2001.13 | EQ39: 0 | ER39: 2437.64 | ES39: 3213.03 | ET39: 0 | EU39: 0 | EV39: 0 | EW39: 0 | EX39: 0 | EZ39: 5 | FC39: 1 | FD39: 18 | FF39: 28334 | FQ39: 0 | FR39: =P39 -> 24611.81 | FS39: 0 | FX39: 90 | FY39: 46 | GA39: [28 334 / 1,2 / 7,66] + 3% Трансп + 1,2% Заг.скл | GD39: 1 | GF39: 174995452 | GG39: 2 | GH39: 3 | GI39: 5 | GJ39: 0 | GK39: 0 | GL39: =ROUND(IF(AND(BH39=3,BI39=3,FS39<>0),P39,0),2) -> 0 | GM39: =ROUND(O39+X39+Y39,2)+GX39 -> 24611.81 | GN39: =IF(OR(BI39=0,BI39=1),GM39-GX39,0) -> 0 | GO39: =IF(BI39=2,GM39-GX39,0) -> 0 | GP39: =IF(BI39=4,GM39-GX39,0) -> 0 | GR39: 1 | GS39: 1 | GT39: 0 | GV39: =ROUND((GT39),6) -> 0 | GW39: 1 | GX39: =ROUND(HC39*I39,2) -> 0 | HA39: 0 | HB39: 0 | HC39: =GV39*GW39 -> 0 | HE39: 3 | HF39: 1,2 | HS39: 0 | IK39: 0
A40: 18 | B40: 1 | E40: 2,2 | F40: КА 5 | G40: Выдвижная полка для клавиатуры 60А-04-45-11BL | H40: шт. | I40: =I36*J40 -> 1 | J40: 0.25 | K40: 0.25 | O40: =ROUND(CP40,2) -> 553.19 | P40: =ROUND((ROUND((AC40*AW40*I40),2)*BC40),2) -> 553.19 | Q40: =(ROUND((ROUND(((ET40)*AV40*I40),2)*BB40),2)+ROUND((ROUND(((AE40-(EU40))*AV40*I40),2)*BS40),2)) -> 0 | R40: =ROUND((ROUND((AE40*AV40*I40),2)*BS40),2) -> 0 | S40: =ROUND((ROUND((AF40*AV40*I40),2)*BA40),2) -> 0 | T40: =ROUND(CU40*I40,2) -> 0 | U40: =CV40*I40 -> 0 | V40: =CW40*I40 -> 0 | W40: =ROUND(CX40*I40,2) -> 0 | X40: =ROUND(CY40,2) -> 0 | Y40: =ROUND(CZ40,2) -> 0 | AA40: 56505403 | AB40: =ROUND((AC40+AD40+AF40),6) -> 553.19 | AC40: =ROUND((ES40),6) -> 553.19 | AD40: =ROUND((((ET40)-(EU40))+AE40),6) -> 0 | AE40: =ROUND((EU40),6) -> 0 | AF40: =ROUND((EV40),6) -> 0 | AG40: =ROUND((AP40),6) -> 0 | AH40: =(EW40) -> 0 | AI40: =(EX40) -> 0 | AJ40: =(AS40) -> 0 | AK40: 553.19 | AL40: 553.19 | AM40: 0 | AN40: 0 | AO40: 0 | AP40: 0 | AQ40: 0 | AR40: 0 | AS40: 0 | AT40: 90 | AU40: 46 | AV40: 1 | AW40: 1 | AZ40: 1 | BA40: 1 | BB40: 1 | BC40: 1 | BH40: 3 | BI40: 2 | BM40: 72 | BN40: 0 | BP40: 0 | BQ40: 40 | BR40: 0 | BS40: 1 | BT40: 1 | BU40: 1 | BV40: 1 | BW40: 1 | BX40: 1 | BZ40: 90 | CA40: 46 | CE40: 30 | CF40: 0 | CG40: 0 | CM40: 0 | CO40: 0 | CP40: =(P40+Q40+S40) -> 553.19 | CQ40: =ROUND((ROUND((AC40*AW40*1),2)*BC40),2) -> 553.19 | CR40: =(ROUND((ROUND(((ET40)*AV40*1),2)*BB40),2)+ROUND((ROUND(((AE40-(EU40))*AV40*1),2)*BS40),2)) -> 0 | CS40: =ROUND((ROUND((AE40*AV40*1),2)*BS40),2) -> 0 | CT40: =ROUND((ROUND((AF40*AV40*1),2)*BA40),2) -> 0 | CU40: =AG40 -> 0 | CV40: =(AH40*AV40) -> 0 | CW40: =AI40 -> 0 | CX40: =AJ40 -> 0 | CY40: =(((S40+R40)*AT40)/100) -> 0 | CZ40: =(((S40+R40)*AU40)/100) -> 0 | DN40: 0 | DO40: 0 | DP40: 1 | DQ40: 1 | DU40: 1010 | DV40: шт. | DW40: шт. | DX40: 1 | EE40: 58162634 | EF40: 40 | EG40: Монтаж оборудования | EH40: 0 | EJ40: 2 | EK40: 72 | EL40: ТСН-2001.4-11. Приборы и средства автоматизации и вычислительной техники | EM40: ТСН-2001.4-11-1 | EQ40: 0 | ER40: 0 | ES40: 553.19 | ET40: 0 | EU40: 0 | EV40: 0 | EW40: 0 | EX40: 0 | FQ40: 0 | FR40: 0 | FS40: 0 | FX40: 90 | FY40: 46 | GA40: [6 430 / 1,2 / 9,88] + 2% Заг.скл | GD40: 1 | GF40: 1122354003 | GG40: 2 | GH40: 4 | GI40: -2 | GJ40: 0 | GK40: 0 | GL40: =ROUND(IF(AND(BH40=3,BI40=3,FS40<>0),P40,0),2) -> 0 | GM40: =ROUND(O40+X40+Y40,2)+GX40 -> 553.19 | GN40: =IF(OR(BI40=0,BI40=1),GM40-GX40,0) -> 0 | GO40: =IF(BI40=2,GM40-GX40,0) -> 553.19 | GP40: =IF(BI40=4,GM40-GX40,0) -> 0 | GR40: 0 | GS40: 2 | GT40: 0 | GV40: =ROUND((GT40),6) -> 0 | GW40: 1 | GX40: =ROUND(HC40*I40,2) -> 0 | HA40: 0 | HB40: 0 | HC40: =GV40*GW40 -> 0 | HE40: 0 | HF40: 2 | HS40: 0 | IK40: 0
A41: 18 | B41: 1 | E41: 2,2 | F41: КА 5 | G41: Выдвижная полка для клавиатуры 60А-04-45-11BL | H41: шт. | I41: =I37*J41 -> 1 | J41: 0.25 | K41: 0.25 | O41: =ROUND(CP41,2) -> 5465.52 | P41: =ROUND((ROUND((AC41*AW41*I41),2)*BC41),2) -> 5465.52 | Q41: =(ROUND((ROUND(((ET41)*AV41*I41),2)*BB41),2)+ROUND((ROUND(((AE41-(EU41))*AV41*I41),2)*BS41),2)) -> 0 | R41: =ROUND((ROUND((AE41*AV41*I41),2)*BS41),2) -> 0 | S41: =ROUND((ROUND((AF41*AV41*I41),2)*BA41),2) -> 0 | T41: =ROUND(CU41*I41,2) -> 0 | U41: =CV41*I41 -> 0 | V41: =CW41*I41 -> 0 | W41: =ROUND(CX41*I41,2) -> 0 | X41: =ROUND(CY41,2) -> 0 | Y41: =ROUND(CZ41,2) -> 0 | AA41: 56505405 | AB41: =ROUND((AC41+AD41+AF41),6) -> 553.19 | AC41: =ROUND((ES41),6) -> 553.19 | AD41: =ROUND((((ET41)-(EU41))+AE41),6) -> 0 | AE41: =ROUND((EU41),6) -> 0 | AF41: =ROUND((EV41),6) -> 0 | AG41: =ROUND((AP41),6) -> 0 | AH41: =(EW41) -> 0 | AI41: =(EX41) -> 0 | AJ41: =(AS41) -> 0 | AK41: 553.19 | AL41: 553.19 | AM41: 0 | AN41: 0 | AO41: 0 | AP41: 0 | AQ41: 0 | AR41: 0 | AS41: 0 | AT41: 90 | AU41: 46 | AV41: 1 | AW41: 1 | AZ41: 1 | BA41: 1 | BB41: 1 | BC41: 9.88 | BH41: 3 | BI41: 2 | BM41: 72 | BN41: 0 | BP41: 0 | BQ41: 40 | BR41: 0 | BS41: 1 | BT41: 1 | BU41: 1 | BV41: 1 | BW41: 1 | BX41: 1 | BZ41: 90 | CA41: 46 | CE41: 30 | CF41: 0 | CG41: 0 | CM41: 0 | CO41: 0 | CP41: =(P41+Q41+S41) -> 5465.52 | CQ41: =ROUND((ROUND((AC41*AW41*1),2)*BC41),2) -> 5465.52 | CR41: =(ROUND((ROUND(((ET41)*AV41*1),2)*BB41),2)+ROUND((ROUND(((AE41-(EU41))*AV41*1),2)*BS41),2)) -> 0 | CS41: =ROUND((ROUND((AE41*AV41*1),2)*BS41),2) -> 0 | CT41: =ROUND((ROUND((AF41*AV41*1),2)*BA41),2) -> 0 | CU41: =AG41 -> 0 | CV41: =(AH41*AV41) -> 0 | CW41: =AI41 -> 0 | CX41: =AJ41 -> 0 | CY41: =(((S41+R41)*AT41)/100) -> 0 | CZ41: =(((S41+R41)*AU41)/100) -> 0 | DN41: 0 | DO41: 0 | DP41: 1 | DQ41: 1 | DU41: 1010 | DV41: шт. | DW41: шт. | DX41: 1 | EE41: 58162634 | EF41: 40 | EG41: Монтаж оборудования | EH41: 0 | EJ41: 2 | EK41: 72 | EL41: ТСН-2001.4-11. Приборы и средства автоматизации и вычислительной техники | EM41: ТСН-2001.4-11-1 | EQ41: 0 | ER41: 553.19 | ES41: 553.19 | ET41: 0 | EU41: 0 | EV41: 0 | EW41: 0 | EX41: 0 | EZ41: 5 | FC41: 1 | FD41: 18 | FF41: 6430 | FQ41: 0 | FR41: 0 | FS41: 0 | FX41: 90 | FY41: 46 | GA41: [6 430 / 1,2 / 9,88] + 2% Заг.скл | GD41: 1 | GF41: 1122354003 | GG41: 2 | GH41: 3 | GI41: 5 | GJ41: 0 | GK41: 0 | GL41: =ROUND(IF(AND(BH41=3,BI41=3,FS41<>0),P41,0),2) -> 0 | GM41: =ROUND(O41+X41+Y41,2)+GX41 -> 5465.52 | GN41: =IF(OR(BI41=0,BI41=1),GM41-GX41,0) -> 0 | GO41: =IF(BI41=2,GM41-GX41,0) -> 5465.52 | GP41: =IF(BI41=4,GM41-GX41,0) -> 0 | GR41: 1 | GS41: 1 | GT41: 0 | GV41: =ROUND((GT41),6) -> 0 | GW41: 1 | GX41: =ROUND(HC41*I41,2) -> 0 | HA41: 0 | HB41: 0 | HC41: =GV41*GW41 -> 0 | HE41: 0 | HF41: 2 | HS41: 0 | IK41: 0
A42: 18 | B42: 1 | E42: 2,3 | F42: КА 6 | G42: Полка сmацuонарная регулuруемая 1U до 50кг, 370мм, для 600мм | H42: шт. | I42: =I36*J42 -> 1 | J42: 0.25 | K42: 0.25 | O42: =ROUND(CP42,2) -> 381.47 | P42: =ROUND((ROUND((AC42*AW42*I42),2)*BC42),2) -> 381.47 | Q42: =(ROUND((ROUND(((ET42)*AV42*I42),2)*BB42),2)+ROUND((ROUND(((AE42-(EU42))*AV42*I42),2)*BS42),2)) -> 0 | R42: =ROUND((ROUND((AE42*AV42*I42),2)*BS42),2) -> 0 | S42: =ROUND((ROUND((AF42*AV42*I42),2)*BA42),2) -> 0 | T42: =ROUND(CU42*I42,2) -> 0 | U42: =CV42*I42 -> 0 | V42: =CW42*I42 -> 0 | W42: =ROUND(CX42*I42,2) -> 0 | X42: =ROUND(CY42,2) -> 0 | Y42: =ROUND(CZ42,2) -> 0 | AA42: 56505403 | AB42: =ROUND((AC42+AD42+AF42),6) -> 381.47 | AC42: =ROUND((ES42),6) -> 381.47 | AD42: =ROUND((((ET42)-(EU42))+AE42),6) -> 0 | AE42: =ROUND((EU42),6) -> 0 | AF42: =ROUND((EV42),6) -> 0 | AG42: =ROUND((AP42),6) -> 0 | AH42: =(EW42) -> 0 | AI42: =(EX42) -> 0 | AJ42: =(AS42) -> 0 | AK42: 381.47 | AL42: 381.47 | AM42: 0 | AN42: 0 | AO42: 0 | AP42: 0 | AQ42: 0 | AR42: 0 | AS42: 0 | AT42: 90 | AU42: 46 | AV42: 1 | AW42: 1 | AZ42: 1 | BA42: 1 | BB42: 1 | BC42: 1 | BH42: 3 | BI42: 2 | BM42: 72 | BN42: 0 | BP42: 0 | BQ42: 40 | BR42: 0 | BS42: 1 | BT42: 1 | BU42: 1 | BV42: 1 | BW42: 1 | BX42: 1 | BZ42: 90 | CA42: 46 | CE42: 30 | CF42: 0 | CG42: 0 | CM42: 0 | CO42: 0 | CP42: =(P42+Q42+S42) -> 381.47 | CQ42: =ROUND((ROUND((AC42*AW42*1),2)*BC42),2) -> 381.47 | CR42: =(ROUND((ROUND(((ET42)*AV42*1),2)*BB42),2)+ROUND((ROUND(((AE42-(EU42))*AV42*1),2)*BS42),2)) -> 0 | CS42: =ROUND((ROUND((AE42*AV42*1),2)*BS42),2) -> 0 | CT42: =ROUND((ROUND((AF42*AV42*1),2)*BA42),2) -> 0 | CU42: =AG42 -> 0 | CV42: =(AH42*AV42) -> 0 | CW42: =AI42 -> 0 | CX42: =AJ42 -> 0 | CY42: =(((S42+R42)*AT42)/100) -> 0 | CZ42: =(((S42+R42)*AU42)/100) -> 0 | DN42: 0 | DO42: 0 | DP42: 1 | DQ42: 1 | DU42: 1010 | DV42: шт. | DW42: шт. | DX42: 1 | EE42: 58162634 | EF42: 40 | EG42: Монтаж оборудования | EH42: 0 | EJ42: 2 | EK42: 72 | EL42: ТСН-2001.4-11. Приборы и средства автоматизации и вычислительной техники | EM42: ТСН-2001.4-11-1 | EQ42: 0 | ER42: 0 | ES42: 381.47 | ET42: 0 | EU42: 0 | EV42: 0 | EW42: 0 | EX42: 0 | FQ42: 0 | FR42: 0 | FS42: 0 | FX42: 90 | FY42: 46 | GA42: [4 434 / 1,2 / 9,88] + 2% Заг.скл | GD42: 1 | GF42: -1998996946 | GG42: 2 | GH42: 4 | GI42: -2 | GJ42: 0 | GK42: 0 | GL42: =ROUND(IF(AND(BH42=3,BI42=3,FS42<>0),P42,0),2) -> 0 | GM42: =ROUND(O42+X42+Y42,2)+GX42 -> 381.47 | GN42: =IF(OR(BI42=0,BI42=1),GM42-GX42,0) -> 0 | GO42: =IF(BI42=2,GM42-GX42,0) -> 381.47 | GP42: =IF(BI42=4,GM42-GX42,0) -> 0 | GR42: 0 | GS42: 2 | GT42: 0 | GV42: =ROUND((GT42),6) -> 0 | GW42: 1 | GX42: =ROUND(HC42*I42,2) -> 0 | HA42: 0 | HB42: 0 | HC42: =GV42*GW42 -> 0 | HE42: 0 | HF42: 2 | HS42: 0 | IK42: 0
