Workbook

Sheet 02-01-19
A1: =Source!B1 -> Smeta.RU (495) 974-1589
J2: Форма № 4б
A3: Капитальный ремонт здания Государственного бюджетного общеобразовательного учреждения города Москвы «Школа № 236» по адресу: г. Москва, ул. Клязьминская, д. 7, к. 4. I этап | AP3: Капитальный ремонт здания Государственного бюджетного общеобразовательного учреждения города Москвы «Школа № 236» по адресу: г. Москва, ул. Клязьминская, д. 7, к. 4. I этап. 02-01-19 Вертикальный транспорт
A4: (наименование стройки и/или объекта)
A6: =CONCATENATE( "ЛОКАЛЬНАЯ СМЕТА № ",IF(Source!F20<>"Новая локальная смета", Source!F20, "")) -> ЛОКАЛЬНАЯ СМЕТА № 02-01-19
A8: =IF(Source!G20<>"Новая локальная смета", Source!G20, "") -> Вертикальный транспорт
A9: (наименование работ и затрат)
A11: =CONCATENATE( "Основание: чертежи № ", Source!J20) -> Основание: чертежи № 2024-00272-01-0-ВТ
I13: В базисном уровне цен | J13: В текущем уровне цен
E14: Сметная стоимость | I14: =I15+I16+I17+I18 -> 58.02 | J14: =J15+J16+J17+J18 -> 837.05 | K14: тыс.руб.
E15: Строительные работы | I15: =ROUND((Source!F93)/1000, 2) -> 0 | J15: =ROUND((Source!P93)/1000, 2) -> 0 | K15: тыс.руб.
E16: Работы по монтажу оборудования | I16: =ROUND((Source!F94)/1000, 2) -> 9.26 | J16: =ROUND((Source!P94)/1000, 2) -> 463.54 | K16: тыс.руб.
E17: Оборудование | I17: =ROUND((Source!F85)/1000, 2) -> 48.76 | J17: =ROUND((Source!P85)/1000, 2) -> 373.51 | K17: тыс.руб.
E18: Прочие работы и затраты | I18: =ROUND((Source!F95+Source!F96)/1000, 2) -> 0 | J18: =ROUND((Source!P95+Source!P96)/1000, 2) -> 0 | K18: тыс.руб.
E19: Средства на оплату труда | I19: =(Source!F91+ Source!F90)/1000 -> 3.42149 | J19: =((Source!P91 + Source!P90)/1000) -> 188.14774 | K19: тыс.руб.
E20: Затраты труда | I20: =Source!F98 -> 252.13564 | K20: чел.-ч.
E21: Кроме того:
E22: Возврат материалов | I22: =SUM(Y28:Y112)/1000 -> 0 | J22: =SUM(Z28:Z112)/1000 -> 0 | K22: тыс.руб.
A24: Составлен(а) по ТСН-2001 с учетом Дополнения №: 80
A25: № и период сборника коэффициентов (индексов) пересчета: Коэффициенты к ТСН-2001 МГЭ Дополнение 80, строительство №217/80 III квартал 2025 года и Коэффициенты к ТСН-2001.13-2 Дополнение 46 №62/46 III квартал 2025 года | AP25: № и период сборника коэффициентов (индексов) пересчета: Коэффициенты к ТСН-2001 МГЭ Дополнение 80, строительство №217/80 III квартал 2025 года и Коэффициенты к ТСН-2001.13-2 Дополнение 46 №62/46 III квартал 2025 года
A26: № п/п | B26: Шифр расценки и коды ресурсов | C26: Наименование работ и затрат | D26: Ед. изм. | E26: Кол-во единиц | F26: Цена на ед. изм., руб. | G26: Попра- вочные коэффи- циенты | H26: Коэффи- циенты зимних удорожа- ний | I26: Всего в ценах на январь 2000 года, руб. | J26: Коэффи- циенты (индек- сы) пере- счета, нормы НР и СП | K26: ВСЕГО затрат в текущем уровне цен, руб.
A27: 1 | B27: 2 | C27: 3 | D27: 4 | E27: 5 | F27: 6 | G27: 7 | H27: 8 | I27: 9 | J27: 10 | K27: 11
A29: =CONCATENATE("Раздел: ",IF(Source!G24<>"Новый раздел", Source!G24, "")) -> Раздел: Подъемник грузовой консольный в осях «Ж-И/4-5»
C30: =Source!G28 -> Демонтажные работы
A31: 1 | B31: 4.3-32-1 Поправка: Гл.12.Прил.8.п.8. 5_12.00.01.11.003 | C31: Лифт малогрузовой со скоростью движения кабины до 0,5 м/с, грузоподъемностью 100 кг, на 6 остановок, в глухой шахте, высота 21 м (схема управления релейно-контакторная)/ грузовой подъёмник | D31: =Source!H29 -> 1 лифт | E31: =Source!I29 -> 1 | Q31: =Source!X29 -> 1487.35 | R31: =Source!X30 -> 81789.13 | S31: =Source!Y29 -> 792.17 | T31: =Source!Y30 -> 43561.6 | U31: =ROUND((175/100)*ROUND(Source!R29, 2), 2) -> 14.91 | V31: =ROUND((0/100)*ROUND(Source!R30, 2), 2) -> 0 | AC31: 0
C32: ЗП | F32: =Source!AO29 -> 4567.2 | G32: =Source!DG29 -> *0,3)*1,1 | H32: =Source!AV30 -> 1.067 | I32: =Source!S29 -> 1608.16 | J32: =IF(Source!BA30<> 0, Source!BA30, 1) -> 54.99 | K32: =Source!S30 -> 88432.72
C33: ЭМ | F33: =Source!AM29 -> 338.32 | G33: =Source!DE29 -> *0,3)*1,1 | H33: =Source!AV30 -> 1.067 | I33: =Source!Q29 -> 119.13 | J33: =IF(Source!BB30<> 0, Source!BB30, 1) -> 13.26 | K33: =Source!Q30 -> 1579.66
C34: в т.ч. ЗПМ | F34: =Source!AN29 -> 24.21 | G34: =Source!DF29 -> *0,3)*1,1 | H34: =Source!AV30 -> 1.067 | I34: =Source!R29 -> 8.52 | J34: =IF(Source!BS30<> 0, Source!BS30, 1) -> 54.99 | K34: =Source!R30 -> 468.51
C35: НР от ФОТ | D35: % | E35: =Source!BZ30 -> 92 | I35: =SUM(Q31:Q34) -> 1487.35 | J35: =Source!AT30 -> 92 | K35: =SUM(R31:R34) -> 81789.13
C36: СП от ФОТ | D36: % | E36: =Source!CA30 -> 49 | I36: =SUM(S31:S35) -> 792.17 | J36: =Source!AU30 -> 49 | K36: =SUM(T31:T35) -> 43561.6
C37: ЗТР | D37: чел-ч | E37: =Source!AQ29 -> 346 | G37: =Source!DI29 -> *0,3)*1,1 | H37: =Source!AV30 -> 1.067 | I37: =Source!U29 -> 121.83006
C38: ВСЕГО работ по позиции: | H38: =I32+I33+I35+I36+0-0-0 -> 4006.81 | J38: =K32+K33+K35+K36+0-0-0 -> 215363.11
C39: ВСЕГО оборудование по позиции: | H39: =0+0 -> 0 | J39: =0+0 -> 0
C40: ВСЕГО по позиции: | H40: =I32+I33+I35+I36+0 -> 4006.81 | J40: =K32+K33+K35+K36+0 -> 215363.11 | O40: =I32+I33+I35+I36+0 -> 4006.81 | P40: =K32+K33+K35+K36+0 -> 215363.11
A42: 2 | B42: 4.3-32-3 Поправка: Гл.12.Прил.8.п.8. 5_12.00.01.11.003 | C42: За каждую остановку, более или менее указанных в характеристике лифта грузоподъемностью 100 кг в глухой шахте добавлять или уменьшать (схема управления релейно-контакторная)/ грузовой подъёмник | D42: =Source!H31 -> 1 остановка | E42: =Source!I31 -> -4 | Q42: =Source!X31 -> -388.23 | R42: =Source!X32 -> -21348.81 | S42: =Source!Y31 -> -206.78 | T42: =Source!Y32 -> -11370.56 | U42: =ROUND((175/100)*ROUND(Source!R31, 2), 2) -> -6.44 | V42: =ROUND((0/100)*ROUND(Source!R32, 2), 2) -> 0 | AC42: 0
C43: ="Объем: "&Source!I31&"=2-"&"6" -> Объем: -4=2-6
C44: ЗП | F44: =Source!AO31 -> 297 | G44: =Source!DG31 -> *0,3)*1,1 | H44: =Source!AV32 -> 1.067 | I44: =Source!S31 -> -418.31 | J44: =IF(Source!BA32<> 0, Source!BA32, 1) -> 54.99 | K44: =Source!S32 -> -23002.87
C45: ЭМ | F45: =Source!AM31 -> 34.82 | G45: =Source!DE31 -> *0,3)*1,1 | H45: =Source!AV32 -> 1.067 | I45: =Source!Q31 -> -49.04 | J45: =IF(Source!BB32<> 0, Source!BB32, 1) -> 13.41 | K45: =Source!Q32 -> -657.63
C46: в т.ч. ЗПМ | F46: =Source!AN31 -> 2.61 | G46: =Source!DF31 -> *0,3)*1,1 | H46: =Source!AV32 -> 1.067 | I46: =Source!R31 -> -3.68 | J46: =IF(Source!BS32<> 0, Source!BS32, 1) -> 54.99 | K46: =Source!R32 -> -202.36
C47: НР от ФОТ | D47: % | E47: =Source!BZ32 -> 92 | I47: =SUM(Q42:Q46) -> -388.23 | J47: =Source!AT32 -> 92 | K47: =SUM(R42:R46) -> -21348.81
...

Sheet 02-01-19_1
A1: =Source!B1 -> Smeta.RU (495) 974-1589
E3: "УТВЕРЖДАЮ"
D5: ___________________________
D7: ___________________________
D9: " ___ " ___________ 20 ___ г.
B12: =CONCATENATE("Ведомость объемов работ ", IF(Source!AN15<>"", Source!AN15," ")) -> Ведомость объемов работ
B13: =CONCATENATE(Source!F12, " ", Source!G12) -> 02-01-19 02-01-19 Вертикальный транспорт
B14: =CONCATENATE(Source!F20, " ", Source!G20) -> 02-01-19 Вертикальный транспорт
A16: № п/п | B16: № в ЛСР | C16: Наименование работ и затрат | D16: Единица измерения | E16: Количество | F16: Ссылка на чертежи, спецификации | G16: Формула расчета, расчет объемов работ и расхода материалов | H16: Примечание
A17: 1 | B17: 2 | C17: 3 | D17: 4 | E17: 5 | F17: 6 | G17: 7 | H17: 8
A18: =CONCATENATE("Раздел: ", Source!G24) -> Раздел: Подъемник грузовой консольный в осях «Ж-И/4-5»
A19: 1 | B19: =Source!E29 -> 1 | C19: =Source!G29 -> Лифт малогрузовой со скоростью движения кабины до 0,5 м/с, грузоподъемностью 100 кг, на 6 остановок, в глухой шахте, высота 21 м (схема управления релейно-контакторная)/ грузовой подъёмник | D19: 1 лифт | E19: =Source!I29 -> 1 | F19: =Source!U24 | G19: =Source!I29 -> 1
A20: 2 | B20: =Source!E31 -> 2 | C20: =Source!G31 -> За каждую остановку, более или менее указанных в характеристике лифта грузоподъемностью 100 кг в глухой шахте добавлять или уменьшать (схема управления релейно-контакторная)/ грузовой подъёмник | D20: 1 остановка | E20: =Source!I31 -> -4 | F20: =Source!U24 | G20: ="=2-"&"6" -> =2-6
A21: 3 | B21: =Source!E33 -> 3 | C21: =Source!G33 -> За каждый 1 м высоты шахты, более или менее указанных в характеристике малогрузового лифта грузоподъемностью 100 кг в глухой шахте добавлять или уменьшать (схема управления релейно-контакторная)/ грузовой подъёмник | D21: 1 М | E21: =Source!I33 -> -14.92 | F21: =Source!U24 | G21: ="=(3,15+"&"2,93-"&"21)" -> =(3,15+2,93-21)
A22: 4 | B22: =Source!E36 -> 4 | C22: =Source!G36 -> Лифт малогрузовой со скоростью движения кабины до 0,5 м/с, грузоподъемностью 100 кг, на 6 остановок, в глухой шахте, высота 21 м (схема управления микроэлектронная и микропроцессорная)/ грузовой подъёмник | D22: 1 лифт | E22: =Source!I36 -> 1 | F22: =Source!U24 | G22: =Source!I36 -> 1
A23: 5 | B23: =Source!E38 -> 5 | C23: =Source!G38 -> За каждую остановку, более или менее указанных в характеристике лифта грузоподъемностью 100 кг в глухой шахте добавлять или уменьшать (схема управления микроэлектронная и микропроцессорная)/ грузовой подъёмник | D23: 1 остановка | E23: =Source!I38 -> -4 | F23: =Source!U24 | G23: ="=2-"&"6" -> =2-6
A24: 6 | B24: =Source!E40 -> 6 | C24: =Source!G40 -> За каждый 1 м высоты шахты, более или менее указанных в характеристике малогрузового лифта грузоподъемностью 100 кг в глухой шахте добавлять или уменьшать (схема управления микроэлектронная и микропроцессорная)/ грузовой подъёмник | D24: 1 М | E24: =Source!I40 -> -14.92 | F24: =Source!U24 | G24: ="=(3,15+"&"2,93-"&"21)" -> =(3,15+2,93-21)
A25: 7 | B25: =Source!E43 -> 7 | C25: =Source!G43 -> Подъемник грузовой консольный РЕСТО-ПГ-Ш-100-3150 ТТ | D25: шт. | E25: =Source!I43 -> 1 | F25: =Source!U24 | G25: =Source!I43 -> 1
C28: Главный инженер проекта _________________ | D28: =IF(Source!X12<>"", Source!X12," ")
C30: Составил _________________ | D30: =IF(Source!AB12<>"", Source!AB12," ") -> Борисова Е.С.

Sheet Source
A1: 0 | B1: Smeta.RU (495) 974-1589 | D1: _PS_ | F1: 0 | G1: 0 | H1: 0 | I1: Smeta.RU | K1: 1 | L1: 74561 | M1: 10 | N1: 11 | O1: 15 | P1: 0 | Q1: 2
A4: 1 | B4: 1 | C4: -1 | G4: Капитальный ремонт здания Государственного бюджетного общеобразовательного учреждения города Москвы «Школа № 236» по адресу: г. Москва, ул. Клязьминская, д. 7, к. 4. I этап | EC4: 0
A12: 1 | B12: 145 | C12: 0 | D12: =ROW(A106) -> 106 | E12: 0 | F12: 02-01-19 | G12: 02-01-19 Вертикальный транспорт | I12: 0 | J12: 2024-00272-01-0-ВТ | K12: 0 | L12: 0 | M12: 4098 | O12: 0 | P12: 0 | Q12: 0 | R12: 0 | S12: 0 | T12: 1 | V12: 2 | AB12: Борисова Е.С. | BB12: 0 | BH12: Сметные нормы списания | BI12: Коды ОКП для ТСН-2001 МГЭ Дополнение 80 | BJ12: 1 | BK12: 1 | BL12: 0 | BM12: 0 | BN12: 1 | BO12: 0 | BP12: 6 | BQ12: 2 | BR12: 1 | BS12: 1 | BT12: 1 | BU12: 0 | BV12: 1 | BW12: 0 | BX12: 0 | BZ12: Типовой расчет для ТСН-2001 МГЭ, Дополнение 80, строительство | CA12: Территориальные сметные нормативы для Москвы ТСН-2001 (МГЭ), дополнение 80 | CB12: Территориальные сметные нормативы для Москвы ТСН-2001 (МГЭ), дополнение 80 | CC12: Территориальные сметные нормативы для Москвы ТСН-2001 (МГЭ), дополнение 80 | CD12: Территориальные сметные нормативы для Москвы ТСН-2001 (МГЭ), дополнение 80 | CE12: Поправки для ТСН-2001 от 03.02.2026 г. доп.80 | CF12: 0 | CG12: 0 | CH12: 10 | CK12: 80 | CQ12: Территориальные сметные нормативы для Москвы (ТСН-2001) | CR12: ТЕР | CS12: 41660 | CT12: 1 | CU12: 80 | CY12: 0 | EC12: 0
A15: 15 | B15: 1
A18: 52 | B18: =B106 -> 145 | C18: =C106 -> 1 | D18: =D106 -> 12 | E18: =E106 -> 0 | F18: =F106 -> 02-01-19 | G18: =G106 -> 02-01-19 Вертикальный транспорт | O18: =O106 -> 53199.99 | P18: =P106 -> 49495.8 | Q18: =Q106 -> 303.71 | R18: =R106 -> 21.01 | S18: =S106 -> 3400.48 | T18: =T106 -> 0 | U18: =U106 -> 252.13564 | V18: =V106 -> 0 | ... GX18: =GX106 -> 0
A20: 3 | B20: 1 | D20: =ROW(A76) -> 76 | F20: 02-01-19 | G20: Вертикальный транспорт | I20: 0 | J20: 2024-00272-01-0-ВТ | K20: -1 | L20: 02-01-19 | S20: 0 | T20: 0 | V20: 2 | AB20: Борисова Е.С. | BX20: 0 | CF20: 0 | CG20: 0
A22: 52 | B22: =B76 -> 1 | C22: =C76 -> 3 | D22: =D76 -> 20 | E22: =E76 -> 0 | F22: =F76 -> 02-01-19 | G22: =G76 -> Вертикальный транспорт | O22: =O76 -> 53199.99 | P22: =P76 -> 49495.8 | Q22: =Q76 -> 303.71 | R22: =R76 -> 21.01 | S22: =S76 -> 3400.48 | T22: =T76 -> 0 | U22: =U76 -> 252.13564 | V22: =V76 -> 0 | ... GX22: =GX76 -> 0
A24: 4 | B24: 1 | D24: =ROW(A46) -> 46 | G24: Подъемник грузовой консольный в осях «Ж-И/4-5» | I24: 0 | K24: -1 | S24: 0 | T24: 0 | V24: 2 | BX24: 0 | CJ24: 0
A26: 52 | B26: =B46 -> 1 | C26: =C46 -> 4 | D26: =D46 -> 24 | E26: =E46 -> 0 | F26: =F46 | G26: =G46 -> Подъемник грузовой консольный в осях «Ж-И/4-5» | O26: =O46 -> 53199.99 | P26: =P46 -> 49495.8 | Q26: =Q46 -> 303.71 | R26: =R46 -> 21.01 | S26: =S46 -> 3400.48 | T26: =T46 -> 0 | U26: =U46 -> 252.13564 | V26: =V46 -> 0 | ... GX26: =GX46 -> 0
A28: 19 | B28: 1 | G28: Демонтажные работы | AA28: 1 | IK28: 0
A29: 17 | B29: 1 | C29: =ROW(SmtRes!A2) -> 2 | D29: =ROW(EtalonRes!A2) -> 2 | E29: 1 | F29: 4.3-32-1 | G29: Лифт малогрузовой со скоростью движения кабины до 0,5 м/с, грузоподъемностью 100 кг, на 6 остановок, в глухой шахте, высота 21 м (схема управления релейно-контакторная)/ грузовой подъёмник | H29: 1 лифт | I29: 1 | J29: 0 | K29: 1 | O29: =ROUND(CP29,2) -> 1727.29 | P29: =ROUND((ROUND((AC29*AW29*I29),2)*BC29),2) -> 0 | Q29: =(ROUND((ROUND(((((ET29*0.3)*1.1))*AV29*I29),2)*BB29),2)+ROUND((ROUND(((AE29-(((EU29*0.3)*1.1)))*AV29*I29),2)*BS29),2)) -> 119.13 | R29: =ROUND((ROUND((AE29*AV29*I29),2)*BS29),2) -> 8.52 | S29: =ROUND((ROUND((AF29*AV29*I29),2)*BA29),2) -> 1608.16 | T29: =ROUND(CU29*I29,2) -> 0 | U29: =CV29*I29 -> 121.83006 | V29: =CW29*I29 -> 0 | W29: =ROUND(CX29*I29,2) -> 0 | X29: =ROUND(CY29,2) -> 1487.35 | Y29: =ROUND(CZ29,2) -> 792.17 | AA29: 59499003 | AB29: =ROUND((AC29+AD29+AF29),6) -> 1618.8216 | AC29: =ROUND((((ES29*0)*1)),6) -> 0 | AD29: =ROUND((((((ET29*0.3)*1.1))-(((EU29*0.3)*1.1)))+AE29),6) -> 111.6456 | AE29: =ROUND((((EU29*0.3)*1.1)),6) -> 7.9893 | AF29: =ROUND((((EV29*0.3)*1.1)),6) -> 1507.176 | AG29: =ROUND((AP29),6) -> 0 | AH29: =(((EW29*0.3)*1.1)) -> 114.18 | AI29: =(((EX29*0.3)*1.1)) -> 0 | AJ29: =(AS29) -> 0 | AK29: 5864.52 | AL29: 959 | AM29: 338.32 | AN29: 24.21 | AO29: 4567.2 | AP29: 0 | AQ29: 346 | AR29: 0 | AS29: 0 | AT29: 92 | AU29: 49 | AV29: 1.067 | AW29: 1.028 | AZ29: 1 | BA29: 1 | BB29: 1 | BC29: 1 | BH29: 0 | BI29: 2 | BJ29: ТСН-2001.4. Доп. 1-42. Сб. 3, т. 32, поз. 1 | BM29: 64 | BN29: 59073636 | BO29: 4.3-32-1 | BP29: 1 | BQ29: 40 | BR29: 0 | BS29: 1 | BT29: 1 | BU29: 1 | BV29: 1 | BW29: 1 | BX29: 1 | BZ29: 92 | CA29: 49 | CE29: 30 | CF29: 0 | CG29: 0 | CM29: 0 | CN29: Поправка: Гл.12.Прил.8.п.8. 5_12.00.01.11.003 Наименование: При наличии усложненных условий производства работ (стесненность, сложность складирования и транспортной логистики, наличие в зоне производства работ действующего технологического оборудования или движения технологического транспорта и т.п.) для объектов, расположенных за пределами территории круговой магистральной системы улиц "Садовое кольцо" и за пределами Третьего транспортного кольца города Москвы пунктов "а" и "б", но в пределах Московской кольцевой автомобильной дороги | CO29: 0 | CP29: =(P29+Q29+S29) -> 1727.29 | CQ29: =ROUND((ROUND((AC29*AW29*1),2)*BC29),2) -> 0 | CR29: =(ROUND((ROUND(((((ET29*0.3)*1.1))*AV29*1),2)*BB29),2)+ROUND((ROUND(((AE29-(((EU29*0.3)*1.1)))*AV29*1),2)*BS29),2)) -> 119.13 | CS29: =ROUND((ROUND((AE29*AV29*1),2)*BS29),2) -> 8.52 | CT29: =ROUND((ROUND((AF29*AV29*1),2)*BA29),2) -> 1608.16 | CU29: =AG29 -> 0 | CV29: =(AH29*AV29) -> 121.83006 | CW29: =AI29 -> 0 | CX29: =AJ29 -> 0 | CY29: =(((S29+R29)*AT29)/100) -> 1487.3456 | CZ29: =(((S29+R29)*AU29)/100) -> 792.1732 | DB29: 1 | DD29: *0)*1 | DE29: *0,3)*1,1 | DF29: *0,3)*1,1 | DG29: *0,3)*1,1 | DI29: *0,3)*1,1 | DJ29: *0,3)*1,1 | DN29: 0 | DO29: 0 | DP29: 1 | DQ29: 1 | DU29: 1013 | DV29: 1 лифт | DW29: 1 лифт | DX29: 1 | EE29: 59073703 | EF29: 40 | EG29: Монтаж оборудования | EH29: 0 | EJ29: 2 | EK29: 64 | EL29: ТСН-2001.4-3. Подъемно-транспортное оборудование | EM29: ТСН-2001.4-3-1 | EO29: Поправка: Гл.12.Прил.8.п.8. 5_12.00.01.11.003 | EQ29: 0 | ER29: 5864.52 | ES29: 959 | ET29: 338.32 | EU29: 24.21 | EV29: 4567.2 | EW29: 346 | EX29: 0 | EY29: 0 | FQ29: 0 | FR29: 0 | FS29: 0 | FX29: 92 | FY29: 49 | GD29: 1 | GF29: 1437378821 | GG29: 2 | GH29: 1 | GI29: 2 | GJ29: 0 | GK29: 0 | GL29: =ROUND(IF(AND(BH29=3,BI29=3,FS29<>0),P29,0),2) -> 0 | GM29: =ROUND(O29+X29+Y29,2)+GX29 -> 4006.81 | GN29: =IF(OR(BI29=0,BI29=1),GM29-GX29,0) -> 0 | GO29: =IF(BI29=2,GM29-GX29,0) -> 4006.81 | GP29: =IF(BI29=4,GM29-GX29,0) -> 0 | GR29: 0 | GS29: 3 | GT29: 0 | GV29: =ROUND((GT29),6) -> 0 | GW29: 1 | GX29: =ROUND(HC29*I29,2) -> 0 | HA29: 0 | HB29: 0 | HC29: =GV29*GW29 -> 0 | HS29: 0 | IK29: 0
A30: 17 | B30: 1 | C30: =ROW(SmtRes!A4) -> 4 | D30: =ROW(EtalonRes!A4) -> 4 | E30: 1 | F30: 4.3-32-1 | G30: Лифт малогрузовой со скоростью движения кабины до 0,5 м/с, грузоподъемностью 100 кг, на 6 остановок, в глухой шахте, высота 21 м (схема управления релейно-контакторная)/ грузовой подъёмник | H30: 1 лифт | I30: 1 | J30: 0 | K30: 1 | O30: =ROUND(CP30,2) -> 90012.38 | P30: =ROUND((ROUND((AC30*AW30*I30),2)*BC30),2) -> 0 | Q30: =(ROUND((ROUND(((((ET30*0.3)*1.1))*AV30*I30),2)*BB30),2)+ROUND((ROUND(((AE30-(((EU30*0.3)*1.1)))*AV30*I30),2)*BS30),2)) -> 1579.66 | R30: =ROUND((ROUND((AE30*AV30*I30),2)*BS30),2) -> 468.51 | S30: =ROUND((ROUND((AF30*AV30*I30),2)*BA30),2) -> 88432.72 | T30: =ROUND(CU30*I30,2) -> 0 | U30: =CV30*I30 -> 121.83006 | V30: =CW30*I30 -> 0 | W30: =ROUND(CX30*I30,2) -> 0 | X30: =ROUND(CY30,2) -> 81789.13 | Y30: =ROUND(CZ30,2) -> 43561.6 | AA30: 59499000 | AB30: =ROUND((AC30+AD30+AF30),6) -> 1618.8216 | AC30: =ROUND((((ES30*0)*1)),6) -> 0 | AD30: =ROUND((((((ET30*0.3)*1.1))-(((EU30*0.3)*1.1)))+AE30),6) -> 111.6456 | AE30: =ROUND((((EU30*0.3)*1.1)),6) -> 7.9893 | AF30: =ROUND((((EV30*0.3)*1.1)),6) -> 1507.176 | AG30: =ROUND((AP30),6) -> 0 | AH30: =(((EW30*0.3)*1.1)) -> 114.18 | AI30: =(((EX30*0.3)*1.1)) -> 0 | AJ30: =(AS30) -> 0 | AK30: 5864.52 | AL30: 959 | AM30: 338.32 | AN30: 24.21 | AO30: 4567.2 | AP30: 0 | AQ30: 346 | AR30: 0 | AS30: 0 | AT30: 92 | AU30: 49 | AV30: 1.067 | AW30: 1.028 | AZ30: 1 | BA30: 54.99 | BB30: 13.26 | BC30: 9.89 | BH30: 0 | BI30: 2 | BJ30: ТСН-2001.4. Доп. 1-42. Сб. 3, т. 32, поз. 1 | BM30: 64 | BN30: 59073636 | BO30: 4.3-32-1 | BP30: 1 | BQ30: 40 | BR30: 0 | BS30: 54.99 | BT30: 1 | BU30: 1 | BV30: 1 | BW30: 1 | BX30: 1 | BZ30: 92 | CA30: 49 | CE30: 30 | CF30: 0 | CG30: 0 | CM30: 0 | CN30: Поправка: Гл.12.Прил.8.п.8. 5_12.00.01.11.003 Наименование: При наличии усложненных условий производства работ (стесненность, сложность складирования и транспортной логистики, наличие в зоне производства работ действующего технологического оборудования или движения технологического транспорта и т.п.) для объектов, расположенных за пределами территории круговой магистральной системы улиц "Садовое кольцо" и за пределами Третьего транспортного кольца города Москвы пунктов "а" и "б", но в пределах Московской кольцевой автомобильной дороги | CO30: 0 | CP30: =(P30+Q30+S30) -> 90012.38 | CQ30: =ROUND((ROUND((AC30*AW30*1),2)*BC30),2) -> 0 | CR30: =(ROUND((ROUND(((((ET30*0.3)*1.1))*AV30*1),2)*BB30),2)+ROUND((ROUND(((AE30-(((EU30*0.3)*1.1)))*AV30*1),2)*BS30),2)) -> 1579.66 | CS30: =ROUND((ROUND((AE30*AV30*1),2)*BS30),2) -> 468.51 | CT30: =ROUND((ROUND((AF30*AV30*1),2)*BA30),2) -> 88432.72 | CU30: =AG30 -> 0 | CV30: =(AH30*AV30) -> 121.83006 | CW30: =AI30 -> 0 | CX30: =AJ30 -> 0 | CY30: =(((S30+R30)*AT30)/100) -> 81789.132 | CZ30: =(((S30+R30)*AU30)/100) -> 43561.603 | DB30: 3 | DD30: *0)*1 | DE30: *0,3)*1,1 | DF30: *0,3)*1,1 | DG30: *0,3)*1,1 | DI30: *0,3)*1,1 | DJ30: *0,3)*1,1 | DN30: 0 | DO30: 0 | DP30: 1 | DQ30: 1 | DU30: 1013 | DV30: 1 лифт | DW30: 1 лифт | DX30: 1 | EE30: 59073703 | EF30: 40 | EG30: Монтаж оборудования | EH30: 0 | EJ30: 2 | EK30: 64 | EL30: ТСН-2001.4-3. Подъемно-транспортное оборудование | EM30: ТСН-2001.4-3-1 | EO30: Поправка: Гл.12.Прил.8.п.8. 5_12.00.01.11.003 | EQ30: 0 | ER30: 5864.52 | ES30: 959 | ET30: 338.32 | EU30: 24.21 | EV30: 4567.2 | EW30: 346 | EX30: 0 | EY30: 0 | FQ30: 0 | FR30: 0 | FS30: 0 | FX30: 92 | FY30: 49 | GD30: 1 | GF30: 1437378821 | GG30: 2 | GH30: 1 | GI30: 2 | GJ30: 0 | GK30: 0 | GL30: =ROUND(IF(AND(BH30=3,BI30=3,FS30<>0),P30,0),2) -> 0 | GM30: =ROUND(O30+X30+Y30,2)+GX30 -> 215363.11 | GN30: =IF(OR(BI30=0,BI30=1),GM30-GX30,0) -> 0 | GO30: =IF(BI30=2,GM30-GX30,0) -> 215363.11 | GP30: =IF(BI30=4,GM30-GX30,0) -> 0 | GR30: 0 | GS30: 3 | GT30: 0 | GV30: =ROUND((GT30),6) -> 0 | GW30: 1 | GX30: =ROUND(HC30*I30,2) -> 0 | HA30: 0 | HB30: 0 | HC30: =GV30*GW30 -> 0 | HS30: 0 | IK30: 0
A31: 17 | B31: 1 | C31: =ROW(SmtRes!A5) -> 5 | D31: =ROW(EtalonRes!A5) -> 5 | E31: 2 | F31: 4.3-32-3 | G31: За каждую остановку, более или менее указанных в характеристике лифта грузоподъемностью 100 кг в глухой шахте добавлять или уменьшать (схема управления релейно-контакторная)/ грузовой подъёмник | H31: 1 остановка | I31: =ROUND(2-6,9) -> -4 | J31: 0 | K31: =ROUND(2-6,9) -> -4 | O31: =ROUND(CP31,2) -> -467.35 | P31: =ROUND((ROUND((AC31*AW31*I31),2)*BC31),2) -> 0 | Q31: =(ROUND((ROUND(((((ET31*0.3)*1.1))*AV31*I31),2)*BB31),2)+ROUND((ROUND(((AE31-(((EU31*0.3)*1.1)))*AV31*I31),2)*BS31),2)) -> -49.04 | R31: =ROUND((ROUND((AE31*AV31*I31),2)*BS31),2) -> -3.68 | S31: =ROUND((ROUND((AF31*AV31*I31),2)*BA31),2) -> -418.31 | T31: =ROUND(CU31*I31,2) -> 0 | U31: =CV31*I31 -> -31.6899 | V31: =CW31*I31 -> 0 | W31: =ROUND(CX31*I31,2) -> 0 | X31: =ROUND(CY31,2) -> -388.23 | Y31: =ROUND(CZ31,2) -> -206.78 | AA31: 59499003 | AB31: =ROUND((AC31+AD31+AF31),6) -> 109.5006 | AC31: =ROUND((((ES31*0)*1)),6) -> 0 | AD31: =ROUND((((((ET31*0.3)*1.1))-(((EU31*0.3)*1.1)))+AE31),6) -> 11.4906 | AE31: =ROUND((((EU31*0.3)*1.1)),6) -> 0.8613 | AF31: =ROUND((((EV31*0.3)*1.1)),6) -> 98.01 | AG31: =ROUND((AP31),6) -> 0 | AH31: =(((EW31*0.3)*1.1)) -> 7.425 | AI31: =(((EX31*0.3)*1.1)) -> 0 | AJ31: =(AS31) -> 0 | AK31: 390.62 | AL31: 58.8 | AM31: 34.82 | AN31: 2.61 | AO31: 297 | AP31: 0 | AQ31: 22.5 | AR31: 0 | AS31: 0 | AT31: 92 | AU31: 49 | AV31: 1.067 | AW31: 1.028 | AZ31: 1 | BA31: 1 | BB31: 1 | BC31: 1 | BH31: 0 | BI31: 2 | BJ31: ТСН-2001.4. Доп. 1-42. Сб. 3, т. 32, поз. 3 | BM31: 64 | BN31: 59073636 | BO31: 4.3-32-3 | BP31: 1 | BQ31: 40 | BR31: 0 | BS31: 1 | BT31: 1 | BU31: 1 | BV31: 1 | BW31: 1 | BX31: 1 | BZ31: 92 | CA31: 49 | CE31: 30 | CF31: 0 | CG31: 0 | CM31: 0 | CN31: Поправка: Гл.12.Прил.8.п.8. 5_12.00.01.11.003 Наименование: При наличии усложненных условий производства работ (стесненность, сложность складирования и транспортной логистики, наличие в зоне производства работ действующего технологического оборудования или движения технологического транспорта и т.п.) для объектов, расположенных за пределами территории круговой магистральной системы улиц "Садовое кольцо" и за пределами Третьего транспортного кольца города Москвы пунктов "а" и "б", но в пределах Московской кольцевой автомобильной дороги | CO31: 0 | CP31: =(P31+Q31+S31) -> -467.35 | CQ31: =ROUND((ROUND((AC31*AW31*1),2)*BC31),2) -> 0 | CR31: =(ROUND((ROUND(((((ET31*0.3)*1.1))*AV31*1),2)*BB31),2)+ROUND((ROUND(((AE31-(((EU31*0.3)*1.1)))*AV31*1),2)*BS31),2)) -> 12.26 | CS31: =ROUND((ROUND((AE31*AV31*1),2)*BS31),2) -> 0.92 | CT31: =ROUND((ROUND((AF31*AV31*1),2)*BA31),2) -> 104.58 | CU31: =AG31 -> 0 | CV31: =(AH31*AV31) -> 7.922475 | CW31: =AI31 -> 0 | CX31: =AJ31 -> 0 | CY31: =(((S31+R31)*AT31)/100) -> -388.2308 | CZ31: =(((S31+R31)*AU31)/100) -> -206.7751 | DB31: 5 | DD31: *0)*1 | DE31: *0,3)*1,1 | DF31: *0,3)*1,1 | DG31: *0,3)*1,1 | DI31: *0,3)*1,1 | DJ31: *0,3)*1,1 | DN31: 0 | DO31: 0 | DP31: 1 | DQ31: 1 | DU31: 1013 | DV31: 1 остановка | DW31: 1 остановка | DX31: 1 | EE31: 59073703 | EF31: 40 | EG31: Монтаж оборудования | EH31: 0 | EJ31: 2 | EK31: 64 | EL31: ТСН-2001.4-3. Подъемно-транспортное оборудование | EM31: ТСН-2001.4-3-1 | EO31: Поправка: Гл.12.Прил.8.п.8. 5_12.00.01.11.003 | EQ31: 0 | ER31: 390.62 | ES31: 58.8 | ET31: 34.82 | EU31: 2.61 | EV31: 297 | EW31: 22.5 | EX31: 0 | EY31: 0 | FQ31: 0 | FR31: 0 | FS31: 0 | FX31: 92 | FY31: 49 | GD31: 1 | GF31: -1024034014 | GG31: 2 | GH31: 1 | GI31: 2 | GJ31: 0 | GK31: 0 | GL31: =ROUND(IF(AND(BH31=3,BI31=3,FS31<>0),P31,0),2) -> 0 | GM31: =ROUND(O31+X31+Y31,2)+GX31 -> -1062.36 | GN31: =IF(OR(BI31=0,BI31=1),GM31-GX31,0) -> 0 | GO31: =IF(BI31=2,GM31-GX31,0) -> -1062.36 | GP31: =IF(BI31=4,GM31-GX31,0) -> 0 | GR31: 0 | GS31: 3 | GT31: 0 | GV31: =ROUND((GT31),6) -> 0 | GW31: 1 | GX31: =ROUND(HC31*I31,2) -> 0 | HA31: 0 | HB31: 0 | HC31: =GV31*GW31 -> 0 | HS31: 0 | IK31: 0
A32: 17 | B32: 1 | C32: =ROW(SmtRes!A6) -> 6 | D32: =ROW(EtalonRes!A6) -> 6 | E32: 2 | F32: 4.3-32-3 | G32: За каждую остановку, более или менее указанных в характеристике лифта грузоподъемностью 100 кг в глухой шахте добавлять или уменьшать (схема управления релейно-контакторная)/ грузовой подъёмник | H32: 1 остановка | I32: =ROUND(2-6,9) -> -4 | J32: 0 | K32: =ROUND(2-6,9) -> -4 | O32: =ROUND(CP32,2) -> -23660.5 | P32: =ROUND((ROUND((AC32*AW32*I32),2)*BC32),2) -> 0 | Q32: =(ROUND((ROUND(((((ET32*0.3)*1.1))*AV32*I32),2)*BB32),2)+ROUND((ROUND(((AE32-(((EU32*0.3)*1.1)))*AV32*I32),2)*BS32),2)) -> -657.63 | R32: =ROUND((ROUND((AE32*AV32*I32),2)*BS32),2) -> -202.36 | S32: =ROUND((ROUND((AF32*AV32*I32),2)*BA32),2) -> -23002.87 | T32: =ROUND(CU32*I32,2) -> 0 | U32: =CV32*I32 -> -31.6899 | V32: =CW32*I32 -> 0 | W32: =ROUND(CX32*I32,2) -> 0 | X32: =ROUND(CY32,2) -> -21348.81 | Y32: =ROUND(CZ32,2) -> -11370.56 | AA32: 59499000 | AB32: =ROUND((AC32+AD32+AF32),6) -> 109.5006 | AC32: =ROUND((((ES32*0)*1)),6) -> 0 | AD32: =ROUND((((((ET32*0.3)*1.1))-(((EU32*0.3)*1.1)))+AE32),6) -> 11.4906 | AE32: =ROUND((((EU32*0.3)*1.1)),6) -> 0.8613 | AF32: =ROUND((((EV32*0.3)*1.1)),6) -> 98.01 | AG32: =ROUND((AP32),6) -> 0 | AH32: =(((EW32*0.3)*1.1)) -> 7.425 | AI32: =(((EX32*0.3)*1.1)) -> 0 | AJ32: =(AS32) -> 0 | AK32: 390.62 | AL32: 58.8 | AM32: 34.82 | AN32: 2.61 | AO32: 297 | AP32: 0 | AQ32: 22.5 | AR32: 0 | AS32: 0 | AT32: 92 | AU32: 49 | AV32: 1.067 | AW32: 1.028 | AZ32: 1 | BA32: 54.99 | BB32: 13.41 | BC32: 9.89 | BH32: 0 | BI32: 2 | BJ32: ТСН-2001.4. Доп. 1-42. Сб. 3, т. 32, поз. 3 | BM32: 64 | BN32: 59073636 | BO32: 4.3-32-3 | BP32: 1 | BQ32: 40 | BR32: 0 | BS32: 54.99 | BT32: 1 | BU32: 1 | BV32: 1 | BW32: 1 | BX32: 1 | BZ32: 92 | CA32: 49 | CE32: 30 | CF32: 0 | CG32: 0 | CM32: 0 | CN32: Поправка: Гл.12.Прил.8.п.8. 5_12.00.01.11.003 Наименование: При наличии усложненных условий производства работ (стесненность, сложность складирования и транспортной логистики, наличие в зоне производства работ действующего технологического оборудования или движения технологического транспорта и т.п.) для объектов, расположенных за пределами территории круговой магистральной системы улиц "Садовое кольцо" и за пределами Третьего транспортного кольца города Москвы пунктов "а" и "б", но в пределах Московской кольцевой автомобильной дороги | CO32: 0 | CP32: =(P32+Q32+S32) -> -23660.5 | CQ32: =ROUND((ROUND((AC32*AW32*1),2)*BC32),2) -> 0 | CR32: =(ROUND((ROUND(((((ET32*0.3)*1.1))*AV32*1),2)*BB32),2)+ROUND((ROUND(((AE32-(((EU32*0.3)*1.1)))*AV32*1),2)*BS32),2)) -> 164.41 | CS32: =ROUND((ROUND((AE32*AV32*1),2)*BS32),2) -> 50.59 | CT32: =ROUND((ROUND((AF32*AV32*1),2)*BA32),2) -> 5750.85 | CU32: =AG32 -> 0 | CV32: =(AH32*AV32) -> 7.922475 | CW32: =AI32 -> 0 | CX32: =AJ32 -> 0 | CY32: =(((S32+R32)*AT32)/100) -> -21348.812 | CZ32: =(((S32+R32)*AU32)/100) -> -11370.563 | DB32: 7 | DD32: *0)*1 | DE32: *0,3)*1,1 | DF32: *0,3)*1,1 | DG32: *0,3)*1,1 | DI32: *0,3)*1,1 | DJ32: *0,3)*1,1 | DN32: 0 | DO32: 0 | DP32: 1 | DQ32: 1 | DU32: 1013 | DV32: 1 остановка | DW32: 1 остановка | DX32: 1 | EE32: 59073703 | EF32: 40 | EG32: Монтаж оборудования | EH32: 0 | EJ32: 2 | EK32: 64 | EL32: ТСН-2001.4-3. Подъемно-транспортное оборудование | EM32: ТСН-2001.4-3-1 | EO32: Поправка: Гл.12.Прил.8.п.8. 5_12.00.01.11.003 | EQ32: 0 | ER32: 390.62 | ES32: 58.8 | ET32: 34.82 | EU32: 2.61 | EV32: 297 | EW32: 22.5 | EX32: 0 | EY32: 0 | FQ32: 0 | FR32: 0 | FS32: 0 | FX32: 92 | FY32: 49 | GD32: 1 | GF32: -1024034014 | GG32: 2 | GH32: 1 | GI32: 2 | GJ32: 0 | GK32: 0 | GL32: =ROUND(IF(AND(BH32=3,BI32=3,FS32<>0),P32,0),2) -> 0 | GM32: =ROUND(O32+X32+Y32,2)+GX32 -> -56379.87 | GN32: =IF(OR(BI32=0,BI32=1),GM32-GX32,0) -> 0 | GO32: =IF(BI32=2,GM32-GX32,0) -> -56379.87 | GP32: =IF(BI32=4,GM32-GX32,0) -> 0 | GR32: 0 | GS32: 3 | GT32: 0 | GV32: =ROUND((GT32),6) -> 0 | GW32: 1 | GX32: =ROUND(HC32*I32,2) -> 0 | HA32: 0 | HB32: 0 | HC32: =GV32*GW32 -> 0 | HS32: 0 | IK32: 0
A33: 17 | B33: 1 | C33: =ROW(SmtRes!A7) -> 7 | D33: =ROW(EtalonRes!A7) -> 7 | E33: 3 | F33: 4.3-32-4 | G33: За каждый 1 м высоты шахты, более или менее указанных в характеристике малогрузового лифта грузоподъемностью 100 кг в глухой шахте добавлять или уменьшать (схема управления релейно-контакторная)/ грузовой подъёмник | H33: 1 М | I33: =ROUND((3.15+2.93-21),9) -> -14.92 | J33: 0 | K33: =ROUND((3.15+2.93-21),9) -> -14.92 | O33: =ROUND(CP33,2) -> -436.88 | P33: =ROUND((ROUND((AC33*AW33*I33),2)*BC33),2) -> 0 | Q33: =(ROUND((ROUND(((((ET33*0.3)*1.1))*AV33*I33),2)*BB33),2)+ROUND((ROUND(((AE33-(((EU33*0.3)*1.1)))*AV33*I33),2)*BS33),2)) -> 0 | R33: =ROUND((ROUND((AE33*AV33*I33),2)*BS33),2) -> 0 | S33: =ROUND((ROUND((AF33*AV33*I33),2)*BA33),2) -> -436.88 | T33: =ROUND(CU33*I33,2) -> 0 | U33: =CV33*I33 -> -33.096932 | V33: =CW33*I33 -> 0 | W33: =ROUND(CX33*I33,2) -> 0 | X33: =ROUND(CY33,2) -> -401.93 | Y33: =ROUND(CZ33,2) -> -214.07 | AA33: 59499003 | AB33: =ROUND((AC33+AD33+AF33),6) -> 27.4428 | AC33: =ROUND((((ES33*0)*1)),6) -> 0 | AD33: =ROUND((((((ET33*0.3)*1.1))-(((EU33*0.3)*1.1)))+AE33),6) -> 0 | AE33: =ROUND((((EU33*0.3)*1.1)),6) -> 0 | AF33: =ROUND((((EV33*0.3)*1.1)),6) -> 27.4428 | AG33: =ROUND((AP33),6) -> 0 | AH33: =(((EW33*0.3)*1.1)) -> 2.079 | AI33: =(((EX33*0.3)*1.1)) -> 0 | AJ33: =(AS33) -> 0 | AK33: 83.79 | AL33: 0.63 | AM33: 0 | AN33: 0 | AO33: 83.16 | AP33: 0 | AQ33: 6.3 | AR33: 0 | AS33: 0 | AT33: 92 | AU33: 49 | AV33: 1.067 | AW33: 1.028 | AZ33: 1 | BA33: 1 | BB33: 1 | BC33: 1 | BH33: 0 | BI33: 2 | BJ33: ТСН-2001.4 Доп. 68, Сб. 3, т. 32, поз. 4 | BM33: 64 | BN33: 59073636 | BO33: 4.3-32-4 | BP33: 1 | BQ33: 40 | BR33: 0 | BS33: 1 | BT33: 1 | BU33: 1 | BV33: 1 | BW33: 1 | BX33: 1 | BZ33: 92 | CA33: 49 | CE33: 30 | CF33: 0 | CG33: 0 | CM33: 0 | CN33: Поправка: Гл.12.Прил.8.п.8. 5_12.00.01.11.003 Наименование: При наличии усложненных условий производства работ (стесненность, сложность складирования и транспортной логистики, наличие в зоне производства работ действующего технологического оборудования или движения технологического транспорта и т.п.) для объектов, расположенных за пределами территории круговой магистральной системы улиц "Садовое кольцо" и за пределами Третьего транспортного кольца города Москвы пунктов "а" и "б", но в пределах Московской кольцевой автомобильной дороги | CO33: 0 | CP33: =(P33+Q33+S33) -> -436.88 | CQ33: =ROUND((ROUND((AC33*AW33*1),2)*BC33),2) -> 0 | CR33: =(ROUND((ROUND(((((ET33*0.3)*1.1))*AV33*1),2)*BB33),2)+ROUND((ROUND(((AE33-(((EU33*0.3)*1.1)))*AV33*1),2)*BS33),2)) -> 0 | CS33: =ROUND((ROUND((AE33*AV33*1),2)*BS33),2) -> 0 | CT33: =ROUND((ROUND((AF33*AV33*1),2)*BA33),2) -> 29.28 | CU33: =AG33 -> 0 | CV33: =(AH33*AV33) -> 2.218293 | CW33: =AI33 -> 0 | CX33: =AJ33 -> 0 | CY33: =(((S33+R33)*AT33)/100) -> -401.9296 | CZ33: =(((S33+R33)*AU33)/100) -> -214.0712 | DB33: 9 | DD33: *0)*1 | DE33: *0,3)*1,1 | DF33: *0,3)*1,1 | DG33: *0,3)*1,1 | DI33: *0,3)*1,1 | DJ33: *0,3)*1,1 | DN33: 0 | DO33: 0 | DP33: 1 | DQ33: 1 | DU33: 1013 | DV33: 1 М | DW33: 1 М | DX33: 1 | EE33: 59073703 | EF33: 40 | EG33: Монтаж оборудования | EH33: 0 | EJ33: 2 | EK33: 64 | EL33: ТСН-2001.4-3. Подъемно-транспортное оборудование | EM33: ТСН-2001.4-3-1 | EO33: Поправка: Гл.12.Прил.8.п.8. 5_12.00.01.11.003 | EQ33: 0 | ER33: 83.79 | ES33: 0.63 | ET33: 0 | EU33: 0 | EV33: 83.16 | EW33: 6.3 | EX33: 0 | EY33: 0 | FQ33: 0 | FR33: 0 | FS33: 0 | FX33: 92 | FY33: 49 | GD33: 1 | GF33: -1760320444 | GG33: 2 | GH33: 1 | GI33: 2 | GJ33: 0 | GK33: 0 | GL33: =ROUND(IF(AND(BH33=3,BI33=3,FS33<>0),P33,0),2) -> 0 | GM33: =ROUND(O33+X33+Y33,2)+GX33 -> -1052.88 | GN33: =IF(OR(BI33=0,BI33=1),GM33-GX33,0) -> 0 | GO33: =IF(BI33=2,GM33-GX33,0) -> -1052.88 | GP33: =IF(BI33=4,GM33-GX33,0) -> 0 | GR33: 0 | GS33: 3 | GT33: 0 | GV33: =ROUND((GT33),6) -> 0 | GW33: 1 | GX33: =ROUND(HC33*I33,2) -> 0 | HA33: 0 | HB33: 0 | HC33: =GV33*GW33 -> 0 | HS33: 0 | IK33: 0
A34: 17 | B34: 1 | C34: =ROW(SmtRes!A8) -> 8 | D34: =ROW(EtalonRes!A8) -> 8 | E34: 3 | F34: 4.3-32-4 | G34: За каждый 1 м высоты шахты, более или менее указанных в характеристике малогрузового лифта грузоподъемностью 100 кг в глухой шахте добавлять или уменьшать (схема управления релейно-контакторная)/ грузовой подъёмник | H34: 1 М | I34: =ROUND((3.15+2.93-21),9) -> -14.92 | J34: 0 | K34: =ROUND((3.15+2.93-21),9) -> -14.92 | O34: =ROUND(CP34,2) -> -24024.03 | P34: =ROUND((ROUND((AC34*AW34*I34),2)*BC34),2) -> 0 | Q34: =(ROUND((ROUND(((((ET34*0.3)*1.1))*AV34*I34),2)*BB34),2)+ROUND((ROUND(((AE34-(((EU34*0.3)*1.1)))*AV34*I34),2)*BS34),2)) -> 0 | R34: =ROUND((ROUND((AE34*AV34*I34),2)*BS34),2) -> 0 | S34: =ROUND((ROUND((AF34*AV34*I34),2)*BA34),2) -> -24024.03 | T34: =ROUND(CU34*I34,2) -> 0 | U34: =CV34*I34 -> -33.096932 | V34: =CW34*I34 -> 0 | W34: =ROUND(CX34*I34,2) -> 0 | X34: =ROUND(CY34,2) -> -22102.11 | Y34: =ROUND(CZ34,2) -> -11771.77 | AA34: 59499000 | AB34: =ROUND((AC34+AD34+AF34),6) -> 27.4428 | AC34: =ROUND((((ES34*0)*1)),6) -> 0 | AD34: =ROUND((((((ET34*0.3)*1.1))-(((EU34*0.3)*1.1)))+AE34),6) -> 0 | AE34: =ROUND((((EU34*0.3)*1.1)),6) -> 0 | AF34: =ROUND((((EV34*0.3)*1.1)),6) -> 27.4428 | AG34: =ROUND((AP34),6) -> 0 | AH34: =(((EW34*0.3)*1.1)) -> 2.079 | AI34: =(((EX34*0.3)*1.1)) -> 0 | AJ34: =(AS34) -> 0 | AK34: 83.79 | AL34: 0.63 | AM34: 0 | AN34: 0 | AO34: 83.16 | AP34: 0 | AQ34: 6.3 | AR34: 0 | AS34: 0 | AT34: 92 | AU34: 49 | AV34: 1.067 | AW34: 1.028 | AZ34: 1 | BA34: 54.99 | BB34: 1 | BC34: 9.89 | BH34: 0 | BI34: 2 | BJ34: ТСН-2001.4 Доп. 68, Сб. 3, т. 32, поз. 4 | BM34: 64 | BN34: 59073636 | BO34: 4.3-32-4 | BP34: 1 | BQ34: 40 | BR34: 0 | BS34: 54.99 | BT34: 1 | BU34: 1 | BV34: 1 | BW34: 1 | BX34: 1 | BZ34: 92 | CA34: 49 | CE34: 30 | CF34: 0 | CG34: 0 | CM34: 0 | CN34: Поправка: Гл.12.Прил.8.п.8. 5_12.00.01.11.003 Наименование: При наличии усложненных условий производства работ (стесненность, сложность складирования и транспортной логистики, наличие в зоне производства работ действующего технологического оборудования или движения технологического транспорта и т.п.) для объектов, расположенных за пределами территории круговой магистральной системы улиц "Садовое кольцо" и за пределами Третьего транспортного кольца города Москвы пунктов "а" и "б", но в пределах Московской кольцевой автомобильной дороги | CO34: 0 | CP34: =(P34+Q34+S34) -> -24024.03 | CQ34: =ROUND((ROUND((AC34*AW34*1),2)*BC34),2) -> 0 | CR34: =(ROUND((ROUND(((((ET34*0.3)*1.1))*AV34*1),2)*BB34),2)+ROUND((ROUND(((AE34-(((EU34*0.3)*1.1)))*AV34*1),2)*BS34),2)) -> 0 | CS34: =ROUND((ROUND((AE34*AV34*1),2)*BS34),2) -> 0 | CT34: =ROUND((ROUND((AF34*AV34*1),2)*BA34),2) -> 1610.11 | CU34: =AG34 -> 0 | CV34: =(AH34*AV34) -> 2.218293 | CW34: =AI34 -> 0 | CX34: =AJ34 -> 0 | CY34: =(((S34+R34)*AT34)/100) -> -22102.108 | CZ34: =(((S34+R34)*AU34)/100) -> -11771.775 | DB34: 11 | DD34: *0)*1 | DE34: *0,3)*1,1 | DF34: *0,3)*1,1 | DG34: *0,3)*1,1 | DI34: *0,3)*1,1 | DJ34: *0,3)*1,1 | DN34: 0 | DO34: 0 | DP34: 1 | DQ34: 1 | DU34: 1013 | DV34: 1 М | DW34: 1 М | DX34: 1 | EE34: 59073703 | EF34: 40 | EG34: Монтаж оборудования | EH34: 0 | EJ34: 2 | EK34: 64 | EL34: ТСН-2001.4-3. Подъемно-транспортное оборудование | EM34: ТСН-2001.4-3-1 | EO34: Поправка: Гл.12.Прил.8.п.8. 5_12.00.01.11.003 | EQ34: 0 | ER34: 83.79 | ES34: 0.63 | ET34: 0 | EU34: 0 | EV34: 83.16 | EW34: 6.3 | EX34: 0 | EY34: 0 | FQ34: 0 | FR34: 0 | FS34: 0 | FX34: 92 | FY34: 49 | GD34: 1 | GF34: -1760320444 | GG34: 2 | GH34: 1 | GI34: 2 | GJ34: 0 | GK34: 0 | GL34: =ROUND(IF(AND(BH34=3,BI34=3,FS34<>0),P34,0),2) -> 0 | GM34: =ROUND(O34+X34+Y34,2)+GX34 -> -57897.91 | GN34: =IF(OR(BI34=0,BI34=1),GM34-GX34,0) -> 0 | GO34: =IF(BI34=2,GM34-GX34,0) -> -57897.91 | GP34: =IF(BI34=4,GM34-GX34,0) -> 0 | GR34: 0 | GS34: 3 | GT34: 0 | GV34: =ROUND((GT34),6) -> 0 | GW34: 1 | GX34: =ROUND(HC34*I34,2) -> 0 | HA34: 0 | HB34: 0 | HC34: =GV34*GW34 -> 0 | HS34: 0 | IK34: 0
A35: 19 | B35: 1 | G35: Монтажные работы | AA35: 1 | IK35: 0
A36: 17 | B36: 1 | C36: =ROW(SmtRes!A10) -> 10 | D36: =ROW(EtalonRes!A10) -> 10 | E36: 4 | F36: 4.3-34-1 | G36: Лифт малогрузовой со скоростью движения кабины до 0,5 м/с, грузоподъемностью 100 кг, на 6 остановок, в глухой шахте, высота 21 м (схема управления микроэлектронная и микропроцессорная)/ грузовой подъёмник | H36: 1 лифт | I36: 1 | J36: 0 | K36: 1 | O36: =ROUND(CP36,2) -> 7052.99 | P36: =ROUND((ROUND((AC36*AW36*I36),2)*BC36),2) -> 985.85 | Q36: =(ROUND((ROUND((((ET36*1.1))*AV36*I36),2)*BB36),2)+ROUND((ROUND(((AE36-((EU36*1.1)))*AV36*I36),2)*BS36),2)) -> 397.09 | R36: =ROUND((ROUND((AE36*AV36*I36),2)*BS36),2) -> 28.42 | S36: =ROUND((ROUND((AF36*AV36*I36),2)*BA36),2) -> 5670.05 | T36: =ROUND(CU36*I36,2) -> 0 | U36: =CV36*I36 -> 417.8372 | V36: =CW36*I36 -> 0 | W36: =ROUND(CX36*I36,2) -> 0 | X36: =ROUND(CY36,2) -> 5242.59 | Y36: =ROUND(CZ36,2) -> 2792.25 | AA36: 59499003 | AB36: =ROUND((AC36+AD36+AF36),6) -> 6645.164 | AC36: =ROUND(((ES36*1)),6) -> 959 | AD36: =ROUND(((((ET36*1.1))-((EU36*1.1)))+AE36),6) -> 372.152 | AE36: =ROUND(((EU36*1.1)),6) -> 26.631 | AF36: =ROUND(((EV36*1.1)),6) -> 5314.012 | AG36: =ROUND((AP36),6) -> 0 | AH36: =((EW36*1.1)) -> 391.6 | AI36: =((EX36*1.1)) -> 0 | AJ36: =(AS36) -> 0 | AK36: 6128.24 | AL36: 959 | AM36: 338.32 | AN36: 24.21 | AO36: 4830.92 | AP36: 0 | AQ36: 356 | AR36: 0 | AS36: 0 | AT36: 92 | AU36: 49 | AV36: 1.067 | AW36: 1.028 | AZ36: 1 | BA36: 1 | BB36: 1 | BC36: 1 | BH36: 0 | BI36: 2 | BJ36: ТСН-2001.4. Доп. 1-42. Сб. 3, т. 34, поз. 1 | BM36: 64 | BN36: 59073636 | BO36: 4.3-34-1 | BP36: 1 | BQ36: 40 | BR36: 0 | BS36: 1 | BT36: 1 | BU36: 1 | BV36: 1 | BW36: 1 | BX36: 1 | BZ36: 92 | CA36: 49 | CE36: 30 | CF36: 0 | CG36: 0 | CM36: 0 | CN36: Поправка: Гл.12.Прил.8.п.8. 5_12.00.01.11.003 Наименование: При наличии усложненных условий производства работ (стесненность, сложность складирования и транспортной логистики, наличие в зоне производства работ действующего технологического оборудования или движения технологического транспорта и т.п.) для объектов, расположенных за пределами территории круговой магистральной системы улиц "Садовое кольцо" и за пределами Третьего транспортного кольца города Москвы пунктов "а" и "б", но в пределах Московской кольцевой автомобильной дороги | CO36: 0 | CP36: =(P36+Q36+S36) -> 7052.99 | CQ36: =ROUND((ROUND((AC36*AW36*1),2)*BC36),2) -> 985.85 | CR36: =(ROUND((ROUND((((ET36*1.1))*AV36*1),2)*BB36),2)+ROUND((ROUND(((AE36-((EU36*1.1)))*AV36*1),2)*BS36),2)) -> 397.09 | CS36: =ROUND((ROUND((AE36*AV36*1),2)*BS36),2) -> 28.42 | CT36: =ROUND((ROUND((AF36*AV36*1),2)*BA36),2) -> 5670.05 | CU36: =AG36 -> 0 | CV36: =(AH36*AV36) -> 417.8372 | CW36: =AI36 -> 0 | CX36: =AJ36 -> 0 | CY36: =(((S36+R36)*AT36)/100) -> 5242.5924 | CZ36: =(((S36+R36)*AU36)/100) -> 2792.2503 | DB36: 13 | DD36: *1 | DE36: *1,1 | DF36: *1,1 | DG36: *1,1 | DI36: *1,1 | DJ36: *1,1 | DN36: 0 | DO36: 0 | DP36: 1 | DQ36: 1 | DU36: 1013 | DV36: 1 лифт | DW36: 1 лифт | DX36: 1 | EE36: 59073703 | EF36: 40 | EG36: Монтаж оборудования | EH36: 0 | EJ36: 2 | EK36: 64 | EL36: ТСН-2001.4-3. Подъемно-транспортное оборудование | EM36: ТСН-2001.4-3-1 | EO36: Поправка: Гл.12.Прил.8.п.8. 5_12.00.01.11.003 | EQ36: 0 | ER36: 6128.24 | ES36: 959 | ET36: 338.32 | EU36: 24.21 | EV36: 4830.92 | EW36: 356 | EX36: 0 | EY36: 0 | FQ36: 0 | FR36: 0 | FS36: 0 | FX36: 92 | FY36: 49 | GD36: 1 | GF36: 1940847450 | GG36: 2 | GH36: 1 | GI36: 2 | GJ36: 0 | GK36: 0 | GL36: =ROUND(IF(AND(BH36=3,BI36=3,FS36<>0),P36,0),2) -> 0 | GM36: =ROUND(O36+X36+Y36,2)+GX36 -> 15087.83 | GN36: =IF(OR(BI36=0,BI36=1),GM36-GX36,0) -> 0 | GO36: =IF(BI36=2,GM36-GX36,0) -> 15087.83 | GP36: =IF(BI36=4,GM36-GX36,0) -> 0 | GR36: 0 | GS36: 3 | GT36: 0 | GV36: =ROUND((GT36),6) -> 0 | GW36: 1 | GX36: =ROUND(HC36*I36,2) -> 0 | HA36: 0 | HB36: 0 | HC36: =GV36*GW36 -> 0 | HS36: 0 | IK36: 0
A37: 17 | B37: 1 | C37: =ROW(SmtRes!A12) -> 12 | D37: =ROW(EtalonRes!A12) -> 12 | E37: 4 | F37: 4.3-34-1 | G37: Лифт малогрузовой со скоростью движения кабины до 0,5 м/с, грузоподъемностью 100 кг, на 6 остановок, в глухой шахте, высота 21 м (схема управления микроэлектронная и микропроцессорная)/ грузовой подъёмник | H37: 1 лифт | I37: 1 | J37: 0 | K37: 1 | O37: =ROUND(CP37,2) -> 326811.52 | P37: =ROUND((ROUND((AC37*AW37*I37),2)*BC37),2) -> 9750.06 | Q37: =(ROUND((ROUND((((ET37*1.1))*AV37*I37),2)*BB37),2)+ROUND((ROUND(((AE37-((EU37*1.1)))*AV37*I37),2)*BS37),2)) -> 5265.41 | R37: =ROUND((ROUND((AE37*AV37*I37),2)*BS37),2) -> 1562.82 | S37: =ROUND((ROUND((AF37*AV37*I37),2)*BA37),2) -> 311796.05 | T37: =ROUND(CU37*I37,2) -> 0 | U37: =CV37*I37 -> 417.8372 | V37: =CW37*I37 -> 0 | W37: =ROUND(CX37*I37,2) -> 0 | X37: =ROUND(CY37,2) -> 288290.16 | Y37: =ROUND(CZ37,2) -> 153545.85 | AA37: 59499000 | AB37: =ROUND((AC37+AD37+AF37),6) -> 6645.164 | AC37: =ROUND(((ES37*1)),6) -> 959 | AD37: =ROUND(((((ET37*1.1))-((EU37*1.1)))+AE37),6) -> 372.152 | AE37: =ROUND(((EU37*1.1)),6) -> 26.631 | AF37: =ROUND(((EV37*1.1)),6) -> 5314.012 | AG37: =ROUND((AP37),6) -> 0 | AH37: =((EW37*1.1)) -> 391.6 | AI37: =((EX37*1.1)) -> 0 | AJ37: =(AS37) -> 0 | AK37: 6128.24 | AL37: 959 | AM37: 338.32 | AN37: 24.21 | AO37: 4830.92 | AP37: 0 | AQ37: 356 | AR37: 0 | AS37: 0 | AT37: 92 | AU37: 49 | AV37: 1.067 | AW37: 1.028 | AZ37: 1 | BA37: 54.99 | BB37: 13.26 | BC37: 9.89 | BH37: 0 | BI37: 2 | BJ37: ТСН-2001.4. Доп. 1-42. Сб. 3, т. 34, поз. 1 | BM37: 64 | BN37: 59073636 | BO37: 4.3-34-1 | BP37: 1 | BQ37: 40 | BR37: 0 | BS37: 54.99 | BT37: 1 | BU37: 1 | BV37: 1 | BW37: 1 | BX37: 1 | BZ37: 92 | CA37: 49 | CE37: 30 | CF37: 0 | CG37: 0 | CM37: 0 | CN37: Поправка: Гл.12.Прил.8.п.8. 5_12.00.01.11.003 Наименование: При наличии усложненных условий производства работ (стесненность, сложность складирования и транспортной логистики, наличие в зоне производства работ действующего технологического оборудования или движения технологического транспорта и т.п.) для объектов, расположенных за пределами территории круговой магистральной системы улиц "Садовое кольцо" и за пределами Третьего транспортного кольца города Москвы пунктов "а" и "б", но в пределах Московской кольцевой автомобильной дороги | CO37: 0 | CP37: =(P37+Q37+S37) -> 326811.52 | CQ37: =ROUND((ROUND((AC37*AW37*1),2)*BC37),2) -> 9750.06 | CR37: =(ROUND((ROUND((((ET37*1.1))*AV37*1),2)*BB37),2)+ROUND((ROUND(((AE37-((EU37*1.1)))*AV37*1),2)*BS37),2)) -> 5265.41 | CS37: =ROUND((ROUND((AE37*AV37*1),2)*BS37),2) -> 1562.82 | CT37: =ROUND((ROUND((AF37*AV37*1),2)*BA37),2) -> 311796.05 | CU37: =AG37 -> 0 | CV37: =(AH37*AV37) -> 417.8372 | CW37: =AI37 -> 0 | CX37: =AJ37 -> 0 | CY37: =(((S37+R37)*AT37)/100) -> 288290.16 | CZ37: =(((S37+R37)*AU37)/100) -> 153545.85 | DB37: 14 | DD37: *1 | DE37: *1,1 | DF37: *1,1 | DG37: *1,1 | DI37: *1,1 | DJ37: *1,1 | DN37: 0 | DO37: 0 | DP37: 1 | DQ37: 1 | DU37: 1013 | DV37: 1 лифт | DW37: 1 лифт | DX37: 1 | EE37: 59073703 | EF37: 40 | EG37: Монтаж оборудования | EH37: 0 | EJ37: 2 | EK37: 64 | EL37: ТСН-2001.4-3. Подъемно-транспортное оборудование | EM37: ТСН-2001.4-3-1 | EO37: Поправка: Гл.12.Прил.8.п.8. 5_12.00.01.11.003 | EQ37: 0 | ER37: 6128.24 | ES37: 959 | ET37: 338.32 | EU37: 24.21 | EV37: 4830.92 | EW37: 356 | EX37: 0 | EY37: 0 | FQ37: 0 | FR37: 0 | FS37: 0 | FX37: 92 | FY37: 49 | GD37: 1 | GF37: 1940847450 | GG37: 2 | GH37: 1 | GI37: 2 | GJ37: 0 | GK37: 0 | GL37: =ROUND(IF(AND(BH37=3,BI37=3,FS37<>0),P37,0),2) -> 0 | GM37: =ROUND(O37+X37+Y37,2)+GX37 -> 768647.53 | GN37: =IF(OR(BI37=0,BI37=1),GM37-GX37,0) -> 0 | GO37: =IF(BI37=2,GM37-GX37,0) -> 768647.53 | GP37: =IF(BI37=4,GM37-GX37,0) -> 0 | GR37: 0 | GS37: 3 | GT37: 0 | GV37: =ROUND((GT37),6) -> 0 | GW37: 1 | GX37: =ROUND(HC37*I37,2) -> 0 | HA37: 0 | HB37: 0 | HC37: =GV37*GW37 -> 0 | HS37: 0 | IK37: 0
A38: 17 | B38: 1 | C38: =ROW(SmtRes!A13) -> 13 | D38: =ROW(EtalonRes!A13) -> 13 | E38: 5 | F38: 4.3-34-3 | G38: За каждую остановку, более или менее указанных в характеристике лифта грузоподъемностью 100 кг в глухой шахте добавлять или уменьшать (схема управления микроэлектронная и микропроцессорная)/ грузовой подъёмник | H38: 1 остановка | I38: =ROUND(2-6,9) -> -4 | J38: 0 | K38: =ROUND(2-6,9) -> -4 | O38: =ROUND(CP38,2) -> -1883.28 | P38: =ROUND((ROUND((AC38*AW38*I38),2)*BC38),2) -> -241.79 | Q38: =(ROUND((ROUND((((ET38*1.1))*AV38*I38),2)*BB38),2)+ROUND((ROUND(((AE38-((EU38*1.1)))*AV38*I38),2)*BS38),2)) -> -163.47 | R38: =ROUND((ROUND((AE38*AV38*I38),2)*BS38),2) -> -12.25 | S38: =ROUND((ROUND((AF38*AV38*I38),2)*BA38),2) -> -1478.02 | T38: =ROUND(CU38*I38,2) -> 0 | U38: =CV38*I38 -> -108.91936 | V38: =CW38*I38 -> 0 | W38: =ROUND(CX38*I38,2) -> 0 | X38: =ROUND(CY38,2) -> -1371.05 | Y38: =ROUND(CZ38,2) -> -730.23 | AA38: 59499003 | AB38: =ROUND((AC38+AD38+AF38),6) -> 443.404 | AC38: =ROUND(((ES38*1)),6) -> 58.8 | AD38: =ROUND(((((ET38*1.1))-((EU38*1.1)))+AE38),6) -> 38.302 | AE38: =ROUND(((EU38*1.1)),6) -> 2.871 | AF38: =ROUND(((EV38*1.1)),6) -> 346.302 | AG38: =ROUND((AP38),6) -> 0 | AH38: =((EW38*1.1)) -> 25.52 | AI38: =((EX38*1.1)) -> 0 | AJ38: =(AS38) -> 0 | AK38: 408.44 | AL38: 58.8 | AM38: 34.82 | AN38: 2.61 | AO38: 314.82 | AP38: 0 | AQ38: 23.2 | AR38: 0 | AS38: 0 | AT38: 92 | AU38: 49 | AV38: 1.067 | AW38: 1.028 | AZ38: 1 | BA38: 1 | BB38: 1 | BC38: 1 | BH38: 0 | BI38: 2 | BJ38: ТСН-2001.4. Доп. 1-42. Сб. 3, т. 34, поз. 3 | BM38: 64 | BN38: 59073636 | BO38: 4.3-34-3 | BP38: 1 | BQ38: 40 | BR38: 0 | BS38: 1 | BT38: 1 | BU38: 1 | BV38: 1 | BW38: 1 | BX38: 1 | BZ38: 92 | CA38: 49 | CE38: 30 | CF38: 0 | CG38: 0 | CM38: 0 | CN38: Поправка: Гл.12.Прил.8.п.8. 5_12.00.01.11.003 Наименование: При наличии усложненных условий производства работ (стесненность, сложность складирования и транспортной логистики, наличие в зоне производства работ действующего технологического оборудования или движения технологического транспорта и т.п.) для объектов, расположенных за пределами территории круговой магистральной системы улиц "Садовое кольцо" и за пределами Третьего транспортного кольца города Москвы пунктов "а" и "б", но в пределах Московской кольцевой автомобильной дороги | CO38: 0 | CP38: =(P38+Q38+S38) -> -1883.28 | CQ38: =ROUND((ROUND((AC38*AW38*1),2)*BC38),2) -> 60.45 | CR38: =(ROUND((ROUND((((ET38*1.1))*AV38*1),2)*BB38),2)+ROUND((ROUND(((AE38-((EU38*1.1)))*AV38*1),2)*BS38),2)) -> 40.87 | CS38: =ROUND((ROUND((AE38*AV38*1),2)*BS38),2) -> 3.06 | CT38: =ROUND((ROUND((AF38*AV38*1),2)*BA38),2) -> 369.5 | CU38: =AG38 -> 0 | CV38: =(AH38*AV38) -> 27.22984 | CW38: =AI38 -> 0 | CX38: =AJ38 -> 0 | CY38: =(((S38+R38)*AT38)/100) -> -1371.0484 | CZ38: =(((S38+R38)*AU38)/100) -> -730.2323 | DB38: 15 | DD38: *1 | DE38: *1,1 | DF38: *1,1 | DG38: *1,1 | DI38: *1,1 | DJ38: *1,1 | DN38: 0 | DO38: 0 | DP38: 1 | DQ38: 1 | DU38: 1013 | DV38: 1 остановка | DW38: 1 остановка | DX38: 1 | EE38: 59073703 | EF38: 40 | EG38: Монтаж оборудования | EH38: 0 | EJ38: 2 | EK38: 64 | EL38: ТСН-2001.4-3. Подъемно-транспортное оборудование | EM38: ТСН-2001.4-3-1 | EO38: Поправка: Гл.12.Прил.8.п.8. 5_12.00.01.11.003 | EQ38: 0 | ER38: 408.44 | ES38: 58.8 | ET38: 34.82 | EU38: 2.61 | EV38: 314.82 | EW38: 23.2 | EX38: 0 | EY38: 0 | FQ38: 0 | FR38: 0 | FS38: 0 | FX38: 92 | FY38: 49 | GD38: 1 | GF38: -1647615880 | GG38: 2 | GH38: 1 | GI38: 2 | GJ38: 0 | GK38: 0 | GL38: =ROUND(IF(AND(BH38=3,BI38=3,FS38<>0),P38,0),2) -> 0 | GM38: =ROUND(O38+X38+Y38,2)+GX38 -> -3984.56 | GN38: =IF(OR(BI38=0,BI38=1),GM38-GX38,0) -> 0 | GO38: =IF(BI38=2,GM38-GX38,0) -> -3984.56 | GP38: =IF(BI38=4,GM38-GX38,0) -> 0 | GR38: 0 | GS38: 3 | GT38: 0 | GV38: =ROUND((GT38),6) -> 0 | GW38: 1 | GX38: =ROUND(HC38*I38,2) -> 0 | HA38: 0 | HB38: 0 | HC38: =GV38*GW38 -> 0 | HS38: 0 | IK38: 0
A39: 17 | B39: 1 | C39: =ROW(SmtRes!A14) -> 14 | D39: =ROW(EtalonRes!A14) -> 14 | E39: 5 | F39: 4.3-34-3 | G39: За каждую остановку, более или менее указанных в характеристике лифта грузоподъемностью 100 кг в глухой шахте добавлять или уменьшать (схема управления микроэлектронная и микропроцессорная)/ грузовой подъёмник | H39: 1 остановка | I39: =ROUND(2-6,9) -> -4 | J39: 0 | K39: =ROUND(2-6,9) -> -4 | O39: =ROUND(CP39,2) -> -85859.75 | P39: =ROUND((ROUND((AC39*AW39*I39),2)*BC39),2) -> -2391.3 | Q39: =(ROUND((ROUND((((ET39*1.1))*AV39*I39),2)*BB39),2)+ROUND((ROUND(((AE39-((EU39*1.1)))*AV39*I39),2)*BS39),2)) -> -2192.13 | R39: =ROUND((ROUND((AE39*AV39*I39),2)*BS39),2) -> -673.63 | S39: =ROUND((ROUND((AF39*AV39*I39),2)*BA39),2) -> -81276.32 | T39: =ROUND(CU39*I39,2) -> 0 | U39: =CV39*I39 -> -108.91936 | V39: =CW39*I39 -> 0 | W39: =ROUND(CX39*I39,2) -> 0 | X39: =ROUND(CY39,2) -> -75393.95 | Y39: =ROUND(CZ39,2) -> -40155.48 | AA39: 59499000 | AB39: =ROUND((AC39+AD39+AF39),6) -> 443.404 | AC39: =ROUND(((ES39*1)),6) -> 58.8 | AD39: =ROUND(((((ET39*1.1))-((EU39*1.1)))+AE39),6) -> 38.302 | AE39: =ROUND(((EU39*1.1)),6) -> 2.871 | AF39: =ROUND(((EV39*1.1)),6) -> 346.302 | AG39: =ROUND((AP39),6) -> 0 | AH39: =((EW39*1.1)) -> 25.52 | AI39: =((EX39*1.1)) -> 0 | AJ39: =(AS39) -> 0 | AK39: 408.44 | AL39: 58.8 | AM39: 34.82 | AN39: 2.61 | AO39: 314.82 | AP39: 0 | AQ39: 23.2 | AR39: 0 | AS39: 0 | AT39: 92 | AU39: 49 | AV39: 1.067 | AW39: 1.028 | AZ39: 1 | BA39: 54.99 | BB39: 13.41 | BC39: 9.89 | BH39: 0 | BI39: 2 | BJ39: ТСН-2001.4. Доп. 1-42. Сб. 3, т. 34, поз. 3 | BM39: 64 | BN39: 59073636 | BO39: 4.3-34-3 | BP39: 1 | BQ39: 40 | BR39: 0 | BS39: 54.99 | BT39: 1 | BU39: 1 | BV39: 1 | BW39: 1 | BX39: 1 | BZ39: 92 | CA39: 49 | CE39: 30 | CF39: 0 | CG39: 0 | CM39: 0 | CN39: Поправка: Гл.12.Прил.8.п.8. 5_12.00.01.11.003 Наименование: При наличии усложненных условий производства работ (стесненность, сложность складирования и транспортной логистики, наличие в зоне производства работ действующего технологического оборудования или движения технологического транспорта и т.п.) для объектов, расположенных за пределами территории круговой магистральной системы улиц "Садовое кольцо" и за пределами Третьего транспортного кольца города Москвы пунктов "а" и "б", но в пределах Московской кольцевой автомобильной дороги | CO39: 0 | CP39: =(P39+Q39+S39) -> -85859.75 | CQ39: =ROUND((ROUND((AC39*AW39*1),2)*BC39),2) -> 597.85 | CR39: =(ROUND((ROUND((((ET39*1.1))*AV39*1),2)*BB39),2)+ROUND((ROUND(((AE39-((EU39*1.1)))*AV39*1),2)*BS39),2)) -> 548.07 | CS39: =ROUND((ROUND((AE39*AV39*1),2)*BS39),2) -> 168.27 | CT39: =ROUND((ROUND((AF39*AV39*1),2)*BA39),2) -> 20318.81 | CU39: =AG39 -> 0 | CV39: =(AH39*AV39) -> 27.22984 | CW39: =AI39 -> 0 | CX39: =AJ39 -> 0 | CY39: =(((S39+R39)*AT39)/100) -> -75393.954 | CZ39: =(((S39+R39)*AU39)/100) -> -40155.476 | DB39: 16 | DD39: *1 | DE39: *1,1 | DF39: *1,1 | DG39: *1,1 | DI39: *1,1 | DJ39: *1,1 | DN39: 0 | DO39: 0 | DP39: 1 | DQ39: 1 | DU39: 1013 | DV39: 1 остановка | DW39: 1 остановка | DX39: 1 | EE39: 59073703 | EF39: 40 | EG39: Монтаж оборудования | EH39: 0 | EJ39: 2 | EK39: 64 | EL39: ТСН-2001.4-3. Подъемно-транспортное оборудование | EM39: ТСН-2001.4-3-1 | EO39: Поправка: Гл.12.Прил.8.п.8. 5_12.00.01.11.003 | EQ39: 0 | ER39: 408.44 | ES39: 58.8 | ET39: 34.82 | EU39: 2.61 | EV39: 314.82 | EW39: 23.2 | EX39: 0 | EY39: 0 | FQ39: 0 | FR39: 0 | FS39: 0 | FX39: 92 | FY39: 49 | GD39: 1 | GF39: -1647615880 | GG39: 2 | GH39: 1 | GI39: 2 | GJ39: 0 | GK39: 0 | GL39: =ROUND(IF(AND(BH39=3,BI39=3,FS39<>0),P39,0),2) -> 0 | GM39: =ROUND(O39+X39+Y39,2)+GX39 -> -201409.18 | GN39: =IF(OR(BI39=0,BI39=1),GM39-GX39,0) -> 0 | GO39: =IF(BI39=2,GM39-GX39,0) -> -201409.18 | GP39: =IF(BI39=4,GM39-GX39,0) -> 0 | GR39: 0 | GS39: 3 | GT39: 0 | GV39: =ROUND((GT39),6) -> 0 | GW39: 1 | GX39: =ROUND(HC39*I39,2) -> 0 | HA39: 0 | HB39: 0 | HC39: =GV39*GW39 -> 0 | HS39: 0 | IK39: 0
A40: 17 | B40: 1 | C40: =ROW(SmtRes!A15) -> 15 | D40: =ROW(EtalonRes!A15) -> 15 | E40: 6 | F40: 4.3-34-4 | G40: За каждый 1 м высоты шахты, более или менее указанных в характеристике малогрузового лифта грузоподъемностью 100 кг в глухой шахте добавлять или уменьшать (схема управления микроэлектронная и микропроцессорная)/ грузовой подъёмник | H40: 1 М | I40: =ROUND((3.15+2.93-21),9) -> -14.92 | J40: 0 | K40: =ROUND((3.15+2.93-21),9) -> -14.92 | O40: =ROUND(CP40,2) -> -1554.18 | P40: =ROUND((ROUND((AC40*AW40*I40),2)*BC40),2) -> -9.66 | Q40: =(ROUND((ROUND((((ET40*1.1))*AV40*I40),2)*BB40),2)+ROUND((ROUND(((AE40-((EU40*1.1)))*AV40*I40),2)*BS40),2)) -> 0 | R40: =ROUND((ROUND((AE40*AV40*I40),2)*BS40),2) -> 0 | S40: =ROUND((ROUND((AF40*AV40*I40),2)*BA40),2) -> -1544.52 | T40: =ROUND(CU40*I40,2) -> 0 | U40: =CV40*I40 -> -113.82543 | V40: =CW40*I40 -> 0 | W40: =ROUND(CX40*I40,2) -> 0 | X40: =ROUND(CY40,2) -> -1420.96 | Y40: =ROUND(CZ40,2) -> -756.81 | AA40: 59499003 | AB40: =ROUND((AC40+AD40+AF40),6) -> 97.65 | AC40: =ROUND(((ES40*1)),6) -> 0.63 | AD40: =ROUND(((((ET40*1.1))-((EU40*1.1)))+AE40),6) -> 0 | AE40: =ROUND(((EU40*1.1)),6) -> 0 | AF40: =ROUND(((EV40*1.1)),6) -> 97.02 | AG40: =ROUND((AP40),6) -> 0 | AH40: =((EW40*1.1)) -> 7.15 | AI40: =((EX40*1.1)) -> 0 | AJ40: =(AS40) -> 0 | AK40: 88.83 | AL40: 0.63 | AM40: 0 | AN40: 0 | AO40: 88.2 | AP40: 0 | AQ40: 6.5 | AR40: 0 | AS40: 0 | AT40: 92 | AU40: 49 | AV40: 1.067 | AW40: 1.028 | AZ40: 1 | BA40: 1 | BB40: 1 | BC40: 1 | BH40: 0 | BI40: 2 | BJ40: ТСН-2001.4 Доп. 68, Сб. 3, т. 34, поз. 4 | BM40: 64 | BN40: 59073636 | BO40: 4.3-34-4 | BP40: 1 | BQ40: 40 | BR40: 0 | BS40: 1 | BT40: 1 | BU40: 1 | BV40: 1 | BW40: 1 | BX40: 1 | BZ40: 92 | CA40: 49 | CE40: 30 | CF40: 0 | CG40: 0 | CM40: 0 | CN40: Поправка: Гл.12.Прил.8.п.8. 5_12.00.01.11.003 Наименование: При наличии усложненных условий производства работ (стесненность, сложность складирования и транспортной логистики, наличие в зоне производства работ действующего технологического оборудования или движения технологического транспорта и т.п.) для объектов, расположенных за пределами территории круговой магистральной системы улиц "Садовое кольцо" и за пределами Третьего транспортного кольца города Москвы пунктов "а" и "б", но в пределах Московской кольцевой автомобильной дороги | CO40: 0 | CP40: =(P40+Q40+S40) -> -1554.18 | CQ40: =ROUND((ROUND((AC40*AW40*1),2)*BC40),2) -> 0.65 | CR40: =(ROUND((ROUND((((ET40*1.1))*AV40*1),2)*BB40),2)+ROUND((ROUND(((AE40-((EU40*1.1)))*AV40*1),2)*BS40),2)) -> 0 | CS40: =ROUND((ROUND((AE40*AV40*1),2)*BS40),2) -> 0 | CT40: =ROUND((ROUND((AF40*AV40*1),2)*BA40),2) -> 103.52 | CU40: =AG40 -> 0 | CV40: =(AH40*AV40) -> 7.62905 | CW40: =AI40 -> 0 | CX40: =AJ40 -> 0 | CY40: =(((S40+R40)*AT40)/100) -> -1420.9584 | CZ40: =(((S40+R40)*AU40)/100) -> -756.8148 | DB40: 17 | DD40: *1 | DE40: *1,1 | DF40: *1,1 | DG40: *1,1 | DI40: *1,1 | DJ40: *1,1 | DN40: 0 | DO40: 0 | DP40: 1 | DQ40: 1 | DU40: 1013 | DV40: 1 М | DW40: 1 М | DX40: 1 | EE40: 59073703 | EF40: 40 | EG40: Монтаж оборудования | EH40: 0 | EJ40: 2 | EK40: 64 | EL40: ТСН-2001.4-3. Подъемно-транспортное оборудование | EM40: ТСН-2001.4-3-1 | EO40: Поправка: Гл.12.Прил.8.п.8. 5_12.00.01.11.003 | EQ40: 0 | ER40: 88.83 | ES40: 0.63 | ET40: 0 | EU40: 0 | EV40: 88.2 | EW40: 6.5 | EX40: 0 | EY40: 0 | FQ40: 0 | FR40: 0 | FS40: 0 | FX40: 92 | FY40: 49 | GD40: 1 | GF40: -887566346 | GG40: 2 | GH40: 1 | GI40: 2 | GJ40: 0 | GK40: 0 | GL40: =ROUND(IF(AND(BH40=3,BI40=3,FS40<>0),P40,0),2) -> 0 | GM40: =ROUND(O40+X40+Y40,2)+GX40 -> -3731.95 | GN40: =IF(OR(BI40=0,BI40=1),GM40-GX40,0) -> 0 | GO40: =IF(BI40=2,GM40-GX40,0) -> -3731.95 | GP40: =IF(BI40=4,GM40-GX40,0) -> 0 | GR40: 0 | GS40: 3 | GT40: 0 | GV40: =ROUND((GT40),6) -> 0 | GW40: 1 | GX40: =ROUND(HC40*I40,2) -> 0 | HA40: 0 | HB40: 0 | HC40: =GV40*GW40 -> 0 | HS40: 0 | IK40: 0
A41: 17 | B41: 1 | C41: =ROW(SmtRes!A16) -> 16 | D41: =ROW(EtalonRes!A16) -> 16 | E41: 6 | F41: 4.3-34-4 | G41: За каждый 1 м высоты шахты, более или менее указанных в характеристике малогрузового лифта грузоподъемностью 100 кг в глухой шахте добавлять или уменьшать (схема управления микроэлектронная и микропроцессорная)/ грузовой подъёмник | H41: 1 М | I41: =ROUND((3.15+2.93-21),9) -> -14.92 | J41: 0 | K41: =ROUND((3.15+2.93-21),9) -> -14.92 | O41: =ROUND(CP41,2) -> -85028.69 | P41: =ROUND((ROUND((AC41*AW41*I41),2)*BC41),2) -> -95.54 | Q41: =(ROUND((ROUND((((ET41*1.1))*AV41*I41),2)*BB41),2)+ROUND((ROUND(((AE41-((EU41*1.1)))*AV41*I41),2)*BS41),2)) -> 0 | R41: =ROUND((ROUND((AE41*AV41*I41),2)*BS41),2) -> 0 | S41: =ROUND((ROUND((AF41*AV41*I41),2)*BA41),2) -> -84933.15 | T41: =ROUND(CU41*I41,2) -> 0 | U41: =CV41*I41 -> -113.82543 | V41: =CW41*I41 -> 0 | W41: =ROUND(CX41*I41,2) -> 0 | X41: =ROUND(CY41,2) -> -78138.5 | Y41: =ROUND(CZ41,2) -> -41617.24 | AA41: 59499000 | AB41: =ROUND((AC41+AD41+AF41),6) -> 97.65 | AC41: =ROUND(((ES41*1)),6) -> 0.63 | AD41: =ROUND(((((ET41*1.1))-((EU41*1.1)))+AE41),6) -> 0 | AE41: =ROUND(((EU41*1.1)),6) -> 0 | AF41: =ROUND(((EV41*1.1)),6) -> 97.02 | AG41: =ROUND((AP41),6) -> 0 | AH41: =((EW41*1.1)) -> 7.15 | AI41: =((EX41*1.1)) -> 0 | AJ41: =(AS41) -> 0 | AK41: 88.83 | AL41: 0.63 | AM41: 0 | AN41: 0 | AO41: 88.2 | AP41: 0 | AQ41: 6.5 | AR41: 0 | AS41: 0 | AT41: 92 | AU41: 49 | AV41: 1.067 | AW41: 1.028 | AZ41: 1 | BA41: 54.99 | BB41: 1 | BC41: 9.89 | BH41: 0 | BI41: 2 | BJ41: ТСН-2001.4 Доп. 68, Сб. 3, т. 34, поз. 4 | BM41: 64 | BN41: 59073636 | BO41: 4.3-34-4 | BP41: 1 | BQ41: 40 | BR41: 0 | BS41: 54.99 | BT41: 1 | BU41: 1 | BV41: 1 | BW41: 1 | BX41: 1 | BZ41: 92 | CA41: 49 | CE41: 30 | CF41: 0 | CG41: 0 | CM41: 0 | CN41: Поправка: Гл.12.Прил.8.п.8. 5_12.00.01.11.003 Наименование: При наличии усложненных условий производства работ (стесненность, сложность складирования и транспортной логистики, наличие в зоне производства работ действующего технологического оборудования или движения технологического транспорта и т.п.) для объектов, расположенных за пределами территории круговой магистральной системы улиц "Садовое кольцо" и за пределами Третьего транспортного кольца города Москвы пунктов "а" и "б", но в пределах Московской кольцевой автомобильной дороги | CO41: 0 | CP41: =(P41+Q41+S41) -> -85028.69 | CQ41: =ROUND((ROUND((AC41*AW41*1),2)*BC41),2) -> 6.43 | CR41: =(ROUND((ROUND((((ET41*1.1))*AV41*1),2)*BB41),2)+ROUND((ROUND(((AE41-((EU41*1.1)))*AV41*1),2)*BS41),2)) -> 0 | CS41: =ROUND((ROUND((AE41*AV41*1),2)*BS41),2) -> 0 | CT41: =ROUND((ROUND((AF41*AV41*1),2)*BA41),2) -> 5692.56 | CU41: =AG41 -> 0 | CV41: =(AH41*AV41) -> 7.62905 | CW41: =AI41 -> 0 | CX41: =AJ41 -> 0 | CY41: =(((S41+R41)*AT41)/100) -> -78138.498 | CZ41: =(((S41+R41)*AU41)/100) -> -41617.243 | DB41: 18 | DD41: *1 | DE41: *1,1 | DF41: *1,1 | DG41: *1,1 | DI41: *1,1 | DJ41: *1,1 | DN41: 0 | DO41: 0 | DP41: 1 | DQ41: 1 | DU41: 1013 | DV41: 1 М | DW41: 1 М | DX41: 1 | EE41: 59073703 | EF41: 40 | EG41: Монтаж оборудования | EH41: 0 | EJ41: 2 | EK41: 64 | EL41: ТСН-2001.4-3. Подъемно-транспортное оборудование | EM41: ТСН-2001.4-3-1 | EO41: Поправка: Гл.12.Прил.8.п.8. 5_12.00.01.11.003 | EQ41: 0 | ER41: 88.83 | ES41: 0.63 | ET41: 0 | EU41: 0 | EV41: 88.2 | EW41: 6.5 | EX41: 0 | EY41: 0 | FQ41: 0 | FR41: 0 | FS41: 0 | FX41: 92 | FY41: 49 | GD41: 1 | GF41: -887566346 | GG41: 2 | GH41: 1 | GI41: 2 | GJ41: 0 | GK41: 0 | GL41: =ROUND(IF(AND(BH41=3,BI41=3,FS41<>0),P41,0),2) -> 0 | GM41: =ROUND(O41+X41+Y41,2)+GX41 -> -204784.43 | GN41: =IF(OR(BI41=0,BI41=1),GM41-GX41,0) -> 0 | GO41: =IF(BI41=2,GM41-GX41,0) -> -204784.43 | GP41: =IF(BI41=4,GM41-GX41,0) -> 0 | GR41: 0 | GS41: 3 | GT41: 0 | GV41: =ROUND((GT41),6) -> 0 | GW41: 1 | GX41: =ROUND(HC41*I41,2) -> 0 | HA41: 0 | HB41: 0 | HC41: =GV41*GW41 -> 0 | HS41: 0 | IK41: 0
A42: 19 | B42: 1 | G42: Оборудование | AA42: 1 | IK42: 0
