Workbook

Sheet 02-01-18
A1: =Source!B1 -> Smeta.RU (495) 974-1589
J2: Форма № 4б
B3: "СОГЛАСОВАНО" | G3: "УТВЕРЖДАЮ"
B6: =CONCATENATE("______________________ ", IF(Source!AL12<>"", Source!AL12, "")) -> ______________________ | G6: =CONCATENATE("______________________ ", IF(Source!AH12<>"", Source!AH12, "")) -> ______________________
B7: "_____"________________ 2026 г. | G7: "_____"________________ 2026 г.
A10: Капитальный ремонт здания ГБОУ города Москвы «Школа №236» по адресу: город Москва, улица Клязьминская, дом 7, корп. 4 1этап | AP10: Капитальный ремонт здания ГБОУ города Москвы «Школа №236» по адресу: город Москва, улица Клязьминская, дом 7, корп. 4 (ТСН-2001 (Мосгосэкспертиза))
A11: (наименование стройки и/или объекта)
A13: =CONCATENATE( "ЛОКАЛЬНАЯ СМЕТА № ",IF(Source!F20<>"Новая локальная смета", Source!F20, "")) -> ЛОКАЛЬНАЯ СМЕТА № 02-01-18
A15: =IF(Source!G20<>"Новая локальная смета", Source!G20, "") -> Автоматизация и диспетчеризация инженерных систем.
A16: (наименование работ и затрат)
A18: =CONCATENATE( "Основание: чертежи № ", Source!J20) -> Основание: чертежи № 2024-00272-01-0-ИОС5.11
I20: В базисном уровне цен | J20: В текущем уровне цен
E21: Сметная стоимость | I21: =I22+I23+I24+I25 -> 1958.58 | J21: =J22+J23+J24+J25 -> 19507.41 | K21: тыс.руб.
E22: Строительные работы | I22: =ROUND((Source!F612)/1000, 2) -> 0 | J22: =ROUND((Source!P612)/1000, 2) -> 0 | K22: тыс.руб.
E23: Работы по монтажу оборудования | I23: =ROUND((Source!F613)/1000, 2) -> 298.81 | J23: =ROUND((Source!P613)/1000, 2) -> 6896.99 | K23: тыс.руб.
E24: Оборудование | I24: =ROUND((Source!F604)/1000, 2) -> 1659.77 | J24: =ROUND((Source!P604)/1000, 2) -> 12610.42 | K24: тыс.руб.
E25: Прочие работы и затраты | I25: =ROUND((Source!F614+Source!F615)/1000, 2) -> 0 | J25: =ROUND((Source!P614+Source!P615)/1000, 2) -> 0 | K25: тыс.руб.
E26: Средства на оплату труда | I26: =(Source!F610+ Source!F609)/1000 -> 41.81744 | J26: =((Source!P610 + Source!P609)/1000) -> 2299.541 | K26: тыс.руб.
E27: Затраты труда | I27: =Source!F617 -> 3300.0132 | K27: чел.-ч.
E28: Кроме того:
E29: Возврат материалов | I29: =SUM(Y35:Y814)/1000 -> 0 | J29: =SUM(Z35:Z814)/1000 -> 0 | K29: тыс.руб.
A31: Составлен(а) по ТСН-2001 с учетом Дополнения №: 80
A32: № и период сборника коэффициентов (индексов) пересчета: Коэффициенты к ТСН-2001 МГЭ Дополнение 80, строительство №217/80 III квартал 2025 года и Коэффициенты к ТСН-2001.13-2 Дополнение 46 №62/46 III квартал 2025 года | AP32: № и период сборника коэффициентов (индексов) пересчета: Коэффициенты к ТСН-2001 МГЭ Дополнение 80, строительство №217/80 III квартал 2025 года и Коэффициенты к ТСН-2001.13-2 Дополнение 46 №62/46 III квартал 2025 года
A33: № п/п | B33: Шифр расценки и коды ресурсов | C33: Наименование работ и затрат | D33: Ед. изм. | E33: Кол-во единиц | F33: Цена на ед. изм., руб. | G33: Попра- вочные коэффи- циенты | H33: Коэффи- циенты зимних удорожа- ний | I33: Всего в ценах на январь 2000 года, руб. | J33: Коэффи- циенты (индек- сы) пере- счета, нормы НР и СП | K33: ВСЕГО затрат в текущем уровне цен, руб.
A34: 1 | B34: 2 | C34: 3 | D34: 4 | E34: 5 | F34: 6 | G34: 7 | H34: 8 | I34: 9 | J34: 10 | K34: 11
A36: =CONCATENATE("Раздел: ",IF(Source!G24<>"Новый раздел", Source!G24, "")) -> Раздел: Система управления и диспетчерского контроля инженерного
A37: 1 | B37: 4.11-7-2 Поправка: Гл.12.Прил.8.п.8. 5_12.00.01.11.003 | C37: Установка аппарата настольного массой до 0,03 т | D37: =Source!H28 -> 1 ШТ. | E37: =Source!I28 -> 1 | Q37: =Source!X28 -> 40 | R37: =Source!X29 -> 2199.38 | S37: =Source!Y28 -> 20.44 | T37: =Source!Y29 -> 1124.13 | U37: =ROUND((175/100)*ROUND(Source!R28, 2), 2) -> 8.14 | V37: =ROUND((0/100)*ROUND(Source!R29, 2), 2) -> 0 | AC37: 0
C38: ЗП | F38: =Source!AO28 -> 34.55 | G38: =Source!DG28 -> *1,1 | H38: =Source!AV29 -> 1.047 | I38: =Source!S28 -> 39.79 | J38: =IF(Source!BA29<> 0, Source!BA29, 1) -> 54.99 | K38: =Source!S29 -> 2188.05
C39: ЭМ | F39: =Source!AM28 -> 26.59 | G39: =Source!DE28 -> *1,1 | H39: =Source!AV29 -> 1.047 | I39: =Source!Q28 -> 30.62 | J39: =IF(Source!BB29<> 0, Source!BB29, 1) -> 16.3 | K39: =Source!Q29 -> 499.11
C40: в т.ч. ЗПМ | F40: =Source!AN28 -> 4.04 | G40: =Source!DF28 -> *1,1 | H40: =Source!AV29 -> 1.047 | I40: =Source!R28 -> 4.65 | J40: =IF(Source!BS29<> 0, Source!BS29, 1) -> 54.99 | K40: =Source!R29 -> 255.7
C41: НР от ФОТ | D41: % | E41: =Source!BZ29 -> 90 | I41: =SUM(Q37:Q40) -> 40 | J41: =Source!AT29 -> 90 | K41: =SUM(R37:R40) -> 2199.38
C42: СП от ФОТ | D42: % | E42: =Source!CA29 -> 46 | I42: =SUM(S37:S41) -> 20.44 | J42: =Source!AU29 -> 46 | K42: =SUM(T37:T41) -> 1124.13
C43: ЗТР | D43: чел-ч | E43: =Source!AQ28 -> 3.09 | G43: =Source!DI28 -> *1,1 | H43: =Source!AV29 -> 1.047 | I43: =Source!U28 -> 3.558753
C44: ВСЕГО работ по позиции: | H44: =I38+I39+I41+I42+0-0-0 -> 130.85 | J44: =K38+K39+K41+K42+0-0-0 -> 6010.67
C45: ВСЕГО оборудование по позиции: | H45: =0+0 -> 0 | J45: =0+0 -> 0
C46: ВСЕГО по позиции: | H46: =I38+I39+I41+I42+0 -> 130.85 | J46: =K38+K39+K41+K42+0 -> 6010.67 | O46: =I38+I39+I41+I42+0 -> 130.85 | P46: =K38+K39+K41+K42+0 -> 6010.67
A48: 2 | B48: =Source!F30 -> КА №1 | C48: ОБОРУДОВАНИЕ:_x000D_ Моноблок Lenovo V50a-24IMB 8 548,55 = [75 385 / 1,2 / 7,66] + 3% Трансп + 1,2% Заг.скл | D48: =Source!H30 -> шт. | E48: =Source!I30 -> 1 | F48: =Source!AL30 -> 8548.55 | G48: =Source!DD30 | H48: =Source!AW31 -> 1 | I48: =Source!P30 -> 8548.55 | J48: =IF(Source!BC31<> 0, Source!BC31, 1) -> 7.66 | K48: =Source!P31 -> 65481.89 | Q48: =Source!X30 -> 0 | R48: =Source!X31 -> 0 | S48: =Source!Y30 -> 0 | T48: =Source!Y31 -> 0 | U48: =ROUND((175/100)*ROUND(Source!R30, 2), 2) -> 0 | V48: =ROUND((0/100)*ROUND(Source!R31, 2), 2) -> 0 | AC48: 5
C49: ВСЕГО по позиции: | H49: =I48+0 -> 8548.55 | J49: =K48+0 -> 65481.89 | O49: =I48+0 -> 8548.55 | P49: =K48+0 -> 65481.89
A51: 3 | B51: 4.10-118-5 Поправка: Гл.12.Прил.8.п.8. 5_12.00.01.11.003 | C51: Установка для трубных проводок шкафа настенного размерами до 640х840 мм | D51: =Source!H32 -> 1 ШТ. | E51: =Source!I32 -> 1 | Q51: =Source!X32 -> 24.91 | R51: =Source!X33 -> 1369.92 | S51: =Source!Y32 -> 12.73 | T51: =Source!Y33 -> 700.18 | U51: =ROUND((175/100)*ROUND(Source!R32, 2), 2) -> 0.51 | V51: =ROUND((0/100)*ROUND(Source!R33, 2), 2) -> 0 | AC51: 0
C52: ЗП | F52: =Source!AO32 -> 23.78 | G52: =Source!DG32 -> *1,1 | H52: =Source!AV33 -> 1.047 | I52: =Source!S32 -> 27.39 | J52: =IF(Source!BA33<> 0, Source!BA33, 1) -> 54.99 | K52: =Source!S33 -> 1506.18
...

Sheet Ведомость объемов работ
A1: =Source!B1 -> Smeta.RU (495) 974-1589
E3: "УТВЕРЖДАЮ"
D5: ___________________________
D7: ___________________________
D9: " ___ " ___________ 20 ___ г.
B12: =CONCATENATE("Ведомость объемов работ ", IF(Source!AN15<>"", Source!AN15," ")) -> Ведомость объемов работ
B13: =CONCATENATE("",Source!G12) -> Капитальный ремонт здания ГБОУ города Москвы «Школа №236» по адресу: город Москва, улица Клязьминская, дом 7, корп. 4 | AE13: =CONCATENATE(Source!F12, " ", Source!G12) -> Новый объект (ТСН-2001 (Мосгосэкспертиза)) Капитальный ремонт здания ГБОУ города Москвы «Школа №236» по адресу: город Москва, улица Клязьминская, дом 7, корп. 4
A16: № п/п | B16: № в ЛСР | C16: Наименование работ и затрат | D16: Единица измерения | E16: Количество | F16: Ссылка на чертежи, спецификации | G16: Формула расчета, расчет объемов работ и расхода материалов | H16: Примечание
A17: 1 | B17: 2 | C17: 3 | D17: 4 | E17: 5 | F17: 6 | G17: 7 | H17: 8
A18: =CONCATENATE("Локальная смета: ", Source!G20) -> Локальная смета: Автоматизация и диспетчеризация инженерных систем.
A19: =CONCATENATE("Раздел: ", Source!G24) -> Раздел: Система управления и диспетчерского контроля инженерного
A20: 1 | B20: =Source!E28 -> 1 | C20: =Source!G28 -> Установка аппарата настольного массой до 0,03 т | D20: 1 ШТ. | E20: =Source!I28 -> 1 | F20: =Source!U24 | G20: =Source!I28 -> 1
A21: 2 | B21: =Source!E30 -> 2 | C21: =Source!G30 -> Моноблок Lenovo V50a-24IMB | D21: шт. | E21: =Source!I30 -> 1 | F21: =Source!U24 | G21: =Source!I30 -> 1
A22: 3 | B22: =Source!E32 -> 3 | C22: =Source!G32 -> Установка для трубных проводок шкафа настенного размерами до 640х840 мм | D22: 1 ШТ. | E22: =Source!I32 -> 1 | F22: =Source!U24 | G22: =Source!I32 -> 1
A23: 3.1 | B23: =Source!E34 -> 3,1 | C23: =Source!G34 -> Щит навесной, с дверцей и замком, степень защиты IР55, размер 600х600х250 мм, металлоконструкция без аппаратов | D23: шт. | E23: =Source!I34 -> 1 | F23: =Source!U24
A24: 4 | B24: =Source!E36 -> 4 | C24: =Source!G36 -> Установка съемных и выдвижных блоков (модулей, ячеек, ТЭЗ) массой до 5 кг | D24: 1 ШТ. | E24: =Source!I36 -> 1 | F24: =Source!U24 | G24: =Source!I36 -> 1
A25: 5 | B25: =Source!E38 -> 5 | C25: =Source!G38 -> Шлюз tGW-715i Segnetics | D25: шт. | E25: =Source!I38 -> 1 | F25: =Source!U24 | G25: =Source!I38 -> 1
A26: 6 | B26: =Source!E40 -> 6 | C26: =Source!G40 -> Монтаж блока контроля датчиков (контроллер) | D26: 10 шт. | E26: =Source!I40 -> 0.1 | F26: =Source!U24 | G26: ="=1/"&"10" -> =1/10
A27: 7 | B27: =Source!E42 -> 7 | C27: =Source!G42 -> Контроллер Matrix-2230-70-0 Segnetics | D27: шт. | E27: =Source!I42 -> 1 | F27: =Source!U24 | G27: =Source!I42 -> 1
A28: 8 | B28: =Source!E44 -> 8 | C28: =Source!G44 -> Установка съемных и выдвижных блоков (модулей, ячеек, ТЭЗ) массой до 5 кг | D28: 1 ШТ. | E28: =Source!I44 -> 2 | F28: =Source!U24 | G28: =Source!I44 -> 2
A29: 9 | B29: =Source!E46 -> 9 | C29: =Source!G46 -> модуль сбора сигналов FMR-2222-10-0 Segnetics | D29: шт. | E29: =Source!I46 -> 2 | F29: =Source!U24 | G29: =Source!I46 -> 2
A30: 10 | B30: =Source!E48 -> 10 | C30: =Source!G48 -> Установка съемных и выдвижных блоков (модулей, ячеек, ТЭЗ) массой до 5 кг | D30: 1 ШТ. | E30: =Source!I48 -> 1 | F30: =Source!U24 | G30: =Source!I48 -> 1
A31: 11 | B31: =Source!E50 -> 11 | C31: =Source!G50 -> ИБП SKAT-UPS 1000 Segnetics | D31: шт. | E31: =Source!I50 -> 1 | F31: =Source!U24 | G31: =Source!I50 -> 1
A32: 12 | B32: =Source!E52 -> 12 | C32: =Source!G52 -> Трубы гофрированные поливинилхлоридные наружным диаметром 20 мм открыто по стенам и потолкам с установкой соединительных коробок | D32: 100 м | E32: =Source!I52 -> 23 | F32: =Source!U24 | G32: ="=2300/"&"100" -> =2300/100
A33: 12.1 | B33: =Source!E54 -> 12,1 | C33: =Source!G54 -> Трубы электротехнические, гофрированные, из ПВХ, негорючие, с зондом, наружный диаметр 20 мм | D33: м | E33: =Source!I54 -> 2346 | F33: =Source!U24
A34: 13 | B34: =Source!E56 -> 13 | C34: =Source!G56 -> Прокладка пластикового кабель-канала по кирпичному основанию | D34: 100 м | E34: =Source!I56 -> 2 | F34: =Source!U24 | G34: ="=200/"&"100" -> =200/100
A35: 13.1 | B35: =Source!E58 -> 13,1 | C35: =Source!G58 -> Кабель-канал, размер 10х15 мм | D35: м | E35: =Source!I58 -> 200 | F35: =Source!U24
A36: 14 | B36: =Source!E60 -> 14 | C36: =Source!G60 -> Затягивание провода в проложенные трубы и металлические рукава, первого одножильного или многожильного в общей оплетке, суммарное сечение до 2,5 мм2 | D36: 100 м | E36: =Source!I60 -> 10 | F36: =Source!U24 | G36: ="=1000/"&"100" -> =1000/100
A37: 14.1 | B37: =Source!E62 -> 14,1 | C37: =Source!G62 -> Кабель КПСЭнг(A)-LSLTx 1х2х0,75 | D37: м.п. | E37: =Source!I62 -> 1020 | F37: =Source!U24
A38: 15 | B38: =Source!E64 -> 15 | C38: =Source!G64 -> Затягивание провода в проложенные трубы и металлические рукава, первого одножильного или многожильного в общей оплетке, суммарное сечение до 2,5 мм2 | D38: 100 м | E38: =Source!I64 -> 13 | F38: =Source!U24 | G38: ="=1300/"&"100" -> =1300/100
A39: 15.1 | B39: =Source!E66 -> 15,1 | C39: =Source!G66 -> Кабель симметричный, парной скрутки, с изоляцией из сплошного полиэтилена, с общим экраном, в оболочке из ПВХ пластиката пониженной пожароопасности, с низким дымо- и газовыделением, марка КИПЭВнг(А)-LS, число пар и сечение жилы 2х2х0,6 мм2 | D39: км | E39: =Source!I66 -> 1.326 | F39: =Source!U24
A40: 16 | B40: =Source!E70 -> 16 | C40: =Source!G70 -> Прокладка в коробах провода сечением до 6 мм2 | D40: 100 м | E40: =Source!I70 -> 2 | F40: =Source!U24 | G40: ="=200/"&"100" -> =200/100
A41: 16.1 | B41: =Source!E72 -> 16,1 | C41: =Source!G72 -> Кабель симметричный, парной скрутки, с изоляцией из сплошного полиэтилена, с общим экраном, в оболочке из ПВХ пластиката пониженной пожароопасности, с низким дымо- и газовыделением, марка КИПЭВнг(А)-LS, число пар и сечение жилы 2х2х0,6 мм2 | D41: км | E41: =Source!I72 -> 0.204 | F41: =Source!U24
A42: =CONCATENATE("Раздел: ", Source!G105) -> Раздел: Программное обеспечение
A43: 17 | B43: =Source!E109 -> 17 | C43: =Source!G109 -> Исполнительная SCADA-система на 1000 внешних точек ввода-вывода MPS-MSRT4D-1K-S | D43: шт. | E43: =Source!I109 -> 1 | F43: =Source!U105 | G43: =Source!I109 -> 1
A44: 18 | B44: =Source!E111 -> 18 | C44: =Source!G111 -> OPC-сервер на одно рабочее место на 2500 точек. Universal Master OPC Server | D44: шт. | E44: =Source!I111 -> 1 | F44: =Source!U105 | G44: =Source!I111 -> 1
A45: =CONCATENATE("Раздел: ", Source!G144) -> Раздел: Диспетчеризация систем водоснабжения и канализации
A46: 19 | B46: =Source!E148 -> 19 | C46: =Source!G148 -> Монтаж детали на пультах и панелях - реле | D46: 1 ШТ. | E46: =Source!I148 -> 2 | F46: =Source!U144 | G46: =Source!I148 -> 2
A47: 20 | B47: =Source!E150 -> 20 | C47: =Source!G150 -> Датчик-реле уровня РОС301 | D47: шт. | E47: =Source!I150 -> 2 | F47: =Source!U144 | G47: =Source!I150 -> 2
A48: 21 | B48: =Source!E152 -> 21 | C48: =Source!G152 -> Трубы гофрированные поливинилхлоридные наружным диаметром 20 мм открыто по стенам и потолкам с установкой соединительных коробок | D48: 100 м | E48: =Source!I152 -> 1 | F48: =Source!U144 | G48: ="=100/"&"100" -> =100/100
...

Sheet Source
A1: 0 | B1: Smeta.RU (495) 974-1589 | D1: _PS_ | F1: 0 | G1: 0 | H1: 0 | I1: Smeta.RU | K1: 1 | L1: 74570 | M1: 10 | N1: 11 | O1: 15 | P1: 0 | Q1: 2
A12: 1 | B12: 664 | C12: 0 | D12: =ROW(A625) -> 625 | E12: 0 | F12: Новый объект (ТСН-2001 (Мосгосэкспертиза)) | G12: Капитальный ремонт здания ГБОУ города Москвы «Школа №236» по адресу: город Москва, улица Клязьминская, дом 7, корп. 4 | I12: 0 | K12: 0 | L12: 0 | M12: 4098 | O12: 0 | P12: 0 | Q12: 0 | R12: 0 | S12: 0 | T12: 1 | V12: 0 | BB12: 0 | BH12: Сметные нормы списания | BI12: Коды ОКП для ТСН-2001 МГЭ Дополнение 80 | BJ12: 1 | BK12: 1 | BL12: 0 | BM12: 0 | BN12: 1 | BO12: 0 | BP12: 6 | BQ12: 2 | BR12: 1 | BS12: 1 | BT12: 0 | BU12: 0 | BV12: 0 | BW12: 0 | BX12: 0 | BZ12: Типовой расчет для ТСН-2001 МГЭ, Дополнение 80, строительство | CA12: Территориальные сметные нормативы для Москвы ТСН-2001 (МГЭ), дополнение 80 | CB12: Территориальные сметные нормативы для Москвы ТСН-2001 (МГЭ), дополнение 80 | CC12: Территориальные сметные нормативы для Москвы ТСН-2001 (МГЭ), дополнение 80 | CD12: Территориальные сметные нормативы для Москвы ТСН-2001 (МГЭ), дополнение 80 | CE12: Поправки для ТСН-2001 от 30.12.2025 г. доп.80 | CF12: 0 | CG12: 0 | CH12: 8200 | CK12: 80 | CQ12: Территориальные сметные нормативы для Москвы (ТСН-2001) | CR12: ТЕР | CS12: 41660 | CT12: 1 | CU12: 80 | CY12: 0 | EC12: 0
A15: 15 | B15: 1
A18: 52 | B18: =B625 -> 664 | C18: =C625 -> 1 | D18: =D625 -> 12 | E18: =E625 -> 0 | F18: =F625 -> Новый объект (ТСН-2001 (Мосгосэкспертиза)) | G18: =G625 -> Капитальный ремонт здания ГБОУ города Москвы «Школа №236» по адресу: город Москва, улица Клязьминская, дом 7, корп. 4 | O18: =O625 -> 1897925.6 | P18: =P625 -> 1849266.9 | Q18: =Q625 -> 7979.47 | R18: =R625 -> 1138.16 | S18: =S625 -> 40679.28 | T18: =T625 -> 0 | U18: =U625 -> 3300.0132 | V18: =V625 -> 0 | ... GX18: =GX625 -> 0
A20: 3 | B20: 1 | D20: =ROW(A595) -> 595 | F20: 02-01-18 | G20: Автоматизация и диспетчеризация инженерных систем. | I20: 0 | J20: 2024-00272-01-0-ИОС5.11 | K20: -1 | L20: 02-01-18 | S20: 0 | T20: 0 | V20: 2 | BX20: 0 | CF20: 0 | CG20: 0
A22: 52 | B22: =B595 -> 1 | C22: =C595 -> 3 | D22: =D595 -> 20 | E22: =E595 -> 0 | F22: =F595 -> 02-01-18 | G22: =G595 -> Автоматизация и диспетчеризация инженерных систем. | O22: =O595 -> 1897925.6 | P22: =P595 -> 1849266.9 | Q22: =Q595 -> 7979.47 | R22: =R595 -> 1138.16 | S22: =S595 -> 40679.28 | T22: =T595 -> 0 | U22: =U595 -> 3300.0132 | V22: =V595 -> 0 | ... GX22: =GX595 -> 0
A24: 4 | B24: 1 | D24: =ROW(A75) -> 75 | F24: Новый раздел | G24: Система управления и диспетчерского контроля инженерного | I24: 0 | K24: 0 | S24: 0 | T24: 0 | V24: 2 | BX24: 0 | CJ24: 0
A26: 52 | B26: =B75 -> 1 | C26: =C75 -> 4 | D26: =D75 -> 24 | E26: =E75 -> 0 | F26: =F75 -> Новый раздел | G26: =G75 -> Система управления и диспетчерского контроля инженерного | O26: =O75 -> 116438.62 | P26: =P75 -> 107651.76 | Q26: =Q75 -> 1034.27 | R26: =R75 -> 173.24 | S26: =S75 -> 7752.59 | T26: =T75 -> 0 | U26: =U75 -> 615.2796 | V26: =V75 -> 0 | ... GX26: =GX75 -> 0
A28: 17 | B28: 1 | C28: =ROW(SmtRes!A2) -> 2 | D28: =ROW(EtalonRes!A3) -> 3 | E28: 1 | F28: 4.11-7-2 | G28: Установка аппарата настольного массой до 0,03 т | H28: 1 ШТ. | I28: 1 | J28: 0 | K28: 1 | O28: =ROUND(CP28,2) -> 70.41 | P28: =ROUND((ROUND((AC28*AW28*I28),2)*BC28),2) -> 0 | Q28: =(ROUND((ROUND((((ET28*1.1))*AV28*I28),2)*BB28),2)+ROUND((ROUND(((AE28-((EU28*1.1)))*AV28*I28),2)*BS28),2)) -> 30.62 | R28: =ROUND((ROUND((AE28*AV28*I28),2)*BS28),2) -> 4.65 | S28: =ROUND((ROUND((AF28*AV28*I28),2)*BA28),2) -> 39.79 | T28: =ROUND(CU28*I28,2) -> 0 | U28: =CV28*I28 -> 3.558753 | V28: =CW28*I28 -> 0 | W28: =ROUND(CX28*I28,2) -> 0 | X28: =ROUND(CY28,2) -> 40 | Y28: =ROUND(CZ28,2) -> 20.44 | AA28: 56959434 | AB28: =ROUND((AC28+AD28+AF28),6) -> 67.254 | AC28: =ROUND((ES28),6) -> 0 | AD28: =ROUND(((((ET28*1.1))-((EU28*1.1)))+AE28),6) -> 29.249 | AE28: =ROUND(((EU28*1.1)),6) -> 4.444 | AF28: =ROUND(((EV28*1.1)),6) -> 38.005 | AG28: =ROUND((AP28),6) -> 0 | AH28: =((EW28*1.1)) -> 3.399 | AI28: =((EX28*1.1)) -> 0 | AJ28: =(AS28) -> 0 | AK28: 61.14 | AL28: 0 | AM28: 26.59 | AN28: 4.04 | AO28: 34.55 | AP28: 0 | AQ28: 3.09 | AR28: 0 | AS28: 0 | AT28: 90 | AU28: 46 | AV28: 1.047 | AW28: 1 | AZ28: 1 | BA28: 1 | BB28: 1 | BC28: 1 | BH28: 0 | BI28: 2 | BJ28: ТСН-2001.4 Доп. 68, Сб. 11, т. 7, поз. 2 | BM28: 72 | BN28: 55992028 | BO28: 4.11-7-2 | BP28: 1 | BQ28: 40 | BR28: 0 | BS28: 1 | BT28: 1 | BU28: 1 | BV28: 1 | BW28: 1 | BX28: 1 | BZ28: 90 | CA28: 46 | CE28: 30 | CF28: 0 | CG28: 0 | CM28: 0 | CN28: Поправка: Гл.12.Прил.8.п.8. 5_12.00.01.11.003 Наименование: При наличии усложненных условий производства работ (стесненность, сложность складирования и транспортной логистики, наличие в зоне производства работ действующего технологического оборудования или движения технологического транспорта и т.п.) для объектов, расположенных за пределами территории круговой магистральной системы улиц "Садовое кольцо" и за пределами Третьего транспортного кольца города Москвы пунктов "а" и "б", но в пределах Московской кольцевой автомобильной дороги | CO28: 0 | CP28: =(P28+Q28+S28) -> 70.41 | CQ28: =ROUND((ROUND((AC28*AW28*1),2)*BC28),2) -> 0 | CR28: =(ROUND((ROUND((((ET28*1.1))*AV28*1),2)*BB28),2)+ROUND((ROUND(((AE28-((EU28*1.1)))*AV28*1),2)*BS28),2)) -> 30.62 | CS28: =ROUND((ROUND((AE28*AV28*1),2)*BS28),2) -> 4.65 | CT28: =ROUND((ROUND((AF28*AV28*1),2)*BA28),2) -> 39.79 | CU28: =AG28 -> 0 | CV28: =(AH28*AV28) -> 3.558753 | CW28: =AI28 -> 0 | CX28: =AJ28 -> 0 | CY28: =(((S28+R28)*AT28)/100) -> 39.996 | CZ28: =(((S28+R28)*AU28)/100) -> 20.4424 | DE28: *1,1 | DF28: *1,1 | DG28: *1,1 | DI28: *1,1 | DJ28: *1,1 | DN28: 0 | DO28: 0 | DP28: 1 | DQ28: 1 | DU28: 1013 | DV28: 1 ШТ. | DW28: 1 ШТ. | DX28: 1 | EE28: 55992157 | EF28: 40 | EG28: Монтаж оборудования | EH28: 0 | EJ28: 2 | EK28: 72 | EL28: ТСН-2001.4-11. Приборы и средства автоматизации и вычислительной техники | EM28: ТСН-2001.4-11-1 | EO28: Поправка: Гл.12.Прил.8.п.8. 5_12.00.01.11.003 | EQ28: 0 | ER28: 61.14 | ES28: 0 | ET28: 26.59 | EU28: 4.04 | EV28: 34.55 | EW28: 3.09 | EX28: 0 | EY28: 0 | FQ28: 0 | FR28: 0 | FS28: 0 | FX28: 90 | FY28: 46 | GD28: 1 | GF28: -1491520468 | GG28: 2 | GH28: 1 | GI28: 2 | GJ28: 0 | GK28: 0 | GL28: =ROUND(IF(AND(BH28=3,BI28=3,FS28<>0),P28,0),2) -> 0 | GM28: =ROUND(O28+X28+Y28,2)+GX28 -> 130.85 | GN28: =IF(OR(BI28=0,BI28=1),GM28-GX28,0) -> 0 | GO28: =IF(BI28=2,GM28-GX28,0) -> 130.85 | GP28: =IF(BI28=4,GM28-GX28,0) -> 0 | GR28: 0 | GS28: 3 | GT28: 0 | GV28: =ROUND((GT28),6) -> 0 | GW28: 1 | GX28: =ROUND(HC28*I28,2) -> 0 | HA28: 0 | HB28: 0 | HC28: =GV28*GW28 -> 0 | HS28: 0 | IK28: 0
A29: 17 | B29: 1 | C29: =ROW(SmtRes!A4) -> 4 | D29: =ROW(EtalonRes!A6) -> 6 | E29: 1 | F29: 4.11-7-2 | G29: Установка аппарата настольного массой до 0,03 т | H29: 1 ШТ. | I29: 1 | J29: 0 | K29: 1 | O29: =ROUND(CP29,2) -> 2687.16 | P29: =ROUND((ROUND((AC29*AW29*I29),2)*BC29),2) -> 0 | Q29: =(ROUND((ROUND((((ET29*1.1))*AV29*I29),2)*BB29),2)+ROUND((ROUND(((AE29-((EU29*1.1)))*AV29*I29),2)*BS29),2)) -> 499.11 | R29: =ROUND((ROUND((AE29*AV29*I29),2)*BS29),2) -> 255.7 | S29: =ROUND((ROUND((AF29*AV29*I29),2)*BA29),2) -> 2188.05 | T29: =ROUND(CU29*I29,2) -> 0 | U29: =CV29*I29 -> 3.558753 | V29: =CW29*I29 -> 0 | W29: =ROUND(CX29*I29,2) -> 0 | X29: =ROUND(CY29,2) -> 2199.38 | Y29: =ROUND(CZ29,2) -> 1124.13 | AA29: 56959431 | AB29: =ROUND((AC29+AD29+AF29),6) -> 67.254 | AC29: =ROUND((ES29),6) -> 0 | AD29: =ROUND(((((ET29*1.1))-((EU29*1.1)))+AE29),6) -> 29.249 | AE29: =ROUND(((EU29*1.1)),6) -> 4.444 | AF29: =ROUND(((EV29*1.1)),6) -> 38.005 | AG29: =ROUND((AP29),6) -> 0 | AH29: =((EW29*1.1)) -> 3.399 | AI29: =((EX29*1.1)) -> 0 | AJ29: =(AS29) -> 0 | AK29: 61.14 | AL29: 0 | AM29: 26.59 | AN29: 4.04 | AO29: 34.55 | AP29: 0 | AQ29: 3.09 | AR29: 0 | AS29: 0 | AT29: 90 | AU29: 46 | AV29: 1.047 | AW29: 1 | AZ29: 1 | BA29: 54.99 | BB29: 16.3 | BC29: 1 | BH29: 0 | BI29: 2 | BJ29: ТСН-2001.4 Доп. 68, Сб. 11, т. 7, поз. 2 | BM29: 72 | BN29: 55992028 | BO29: 4.11-7-2 | BP29: 1 | BQ29: 40 | BR29: 0 | BS29: 54.99 | BT29: 1 | BU29: 1 | BV29: 1 | BW29: 1 | BX29: 1 | BZ29: 90 | CA29: 46 | CE29: 30 | CF29: 0 | CG29: 0 | CM29: 0 | CN29: Поправка: Гл.12.Прил.8.п.8. 5_12.00.01.11.003 Наименование: При наличии усложненных условий производства работ (стесненность, сложность складирования и транспортной логистики, наличие в зоне производства работ действующего технологического оборудования или движения технологического транспорта и т.п.) для объектов, расположенных за пределами территории круговой магистральной системы улиц "Садовое кольцо" и за пределами Третьего транспортного кольца города Москвы пунктов "а" и "б", но в пределах Московской кольцевой автомобильной дороги | CO29: 0 | CP29: =(P29+Q29+S29) -> 2687.16 | CQ29: =ROUND((ROUND((AC29*AW29*1),2)*BC29),2) -> 0 | CR29: =(ROUND((ROUND((((ET29*1.1))*AV29*1),2)*BB29),2)+ROUND((ROUND(((AE29-((EU29*1.1)))*AV29*1),2)*BS29),2)) -> 499.11 | CS29: =ROUND((ROUND((AE29*AV29*1),2)*BS29),2) -> 255.7 | CT29: =ROUND((ROUND((AF29*AV29*1),2)*BA29),2) -> 2188.05 | CU29: =AG29 -> 0 | CV29: =(AH29*AV29) -> 3.558753 | CW29: =AI29 -> 0 | CX29: =AJ29 -> 0 | CY29: =(((S29+R29)*AT29)/100) -> 2199.375 | CZ29: =(((S29+R29)*AU29)/100) -> 1124.125 | DE29: *1,1 | DF29: *1,1 | DG29: *1,1 | DI29: *1,1 | DJ29: *1,1 | DN29: 0 | DO29: 0 | DP29: 1 | DQ29: 1 | DU29: 1013 | DV29: 1 ШТ. | DW29: 1 ШТ. | DX29: 1 | EE29: 55992157 | EF29: 40 | EG29: Монтаж оборудования | EH29: 0 | EJ29: 2 | EK29: 72 | EL29: ТСН-2001.4-11. Приборы и средства автоматизации и вычислительной техники | EM29: ТСН-2001.4-11-1 | EO29: Поправка: Гл.12.Прил.8.п.8. 5_12.00.01.11.003 | EQ29: 0 | ER29: 61.14 | ES29: 0 | ET29: 26.59 | EU29: 4.04 | EV29: 34.55 | EW29: 3.09 | EX29: 0 | EY29: 0 | FQ29: 0 | FR29: 0 | FS29: 0 | FX29: 90 | FY29: 46 | GD29: 1 | GF29: -1491520468 | GG29: 2 | GH29: 1 | GI29: 2 | GJ29: 0 | GK29: 0 | GL29: =ROUND(IF(AND(BH29=3,BI29=3,FS29<>0),P29,0),2) -> 0 | GM29: =ROUND(O29+X29+Y29,2)+GX29 -> 6010.67 | GN29: =IF(OR(BI29=0,BI29=1),GM29-GX29,0) -> 0 | GO29: =IF(BI29=2,GM29-GX29,0) -> 6010.67 | GP29: =IF(BI29=4,GM29-GX29,0) -> 0 | GR29: 0 | GS29: 3 | GT29: 0 | GV29: =ROUND((GT29),6) -> 0 | GW29: 1 | GX29: =ROUND(HC29*I29,2) -> 0 | HA29: 0 | HB29: 0 | HC29: =GV29*GW29 -> 0 | HS29: 0 | IK29: 0
A30: 17 | B30: 1 | E30: 2 | F30: КА №1 | G30: Моноблок Lenovo V50a-24IMB | H30: шт. | I30: 1 | J30: 0 | K30: 1 | O30: =ROUND(CP30,2) -> 8548.55 | P30: =ROUND((ROUND((AC30*I30),2)*BC30),2) -> 8548.55 | Q30: =(ROUND((ROUND(((ET30)*AV30*I30),2)*BB30),2)+ROUND((ROUND(((AE30-(EU30))*AV30*I30),2)*BS30),2)) -> 0 | R30: =ROUND((ROUND((AE30*AV30*I30),2)*BS30),2) -> 0 | S30: =ROUND((ROUND((AF30*AV30*I30),2)*BA30),2) -> 0 | T30: =ROUND(CU30*I30,2) -> 0 | U30: =CV30*I30 -> 0 | V30: =CW30*I30 -> 0 | W30: =ROUND(CX30*I30,2) -> 0 | X30: =ROUND(CY30,2) -> 0 | Y30: =ROUND(CZ30,2) -> 0 | AA30: 56959434 | AB30: =ROUND((AC30+AD30+AF30),6) -> 8548.55 | AC30: =ROUND((ES30),6) -> 8548.55 | AD30: =ROUND((((ET30)-(EU30))+AE30),6) -> 0 | AE30: =ROUND((EU30),6) -> 0 | AF30: =ROUND((EV30),6) -> 0 | AG30: =ROUND((AP30),6) -> 0 | AH30: =(EW30) -> 0 | AI30: =(EX30) -> 0 | AJ30: =(AS30) -> 0 | AK30: 8548.55 | AL30: 8548.55 | AM30: 0 | AN30: 0 | AO30: 0 | AP30: 0 | AQ30: 0 | AR30: 0 | AS30: 0 | AT30: 0 | AU30: 0 | AV30: 1 | AW30: 1 | AZ30: 1 | BA30: 1 | BB30: 1 | BC30: 1 | BH30: 3 | BI30: 3 | BM30: 746 | BN30: 0 | BP30: 0 | BQ30: 130 | BR30: 0 | BS30: 1 | BT30: 1 | BU30: 1 | BV30: 1 | BW30: 1 | BX30: 1 | BZ30: 0 | CA30: 0 | CE30: 30 | CF30: 0 | CG30: 0 | CM30: 0 | CO30: 0 | CP30: =(P30+Q30+S30) -> 8548.55 | CQ30: =ROUND((ROUND((AC30*1),2)*BC30),2) -> 8548.55 | CR30: =(ROUND((ROUND(((ET30)*AV30*1),2)*BB30),2)+ROUND((ROUND(((AE30-(EU30))*AV30*1),2)*BS30),2)) -> 0 | CS30: =ROUND((ROUND((AE30*AV30*1),2)*BS30),2) -> 0 | CT30: =ROUND((ROUND((AF30*AV30*1),2)*BA30),2) -> 0 | CU30: =AG30 -> 0 | CV30: =(AH30*AV30) -> 0 | CW30: =AI30 -> 0 | CX30: =AJ30 -> 0 | CY30: =(((S30+R30)*AT30)/100) -> 0 | CZ30: =(((S30+R30)*AU30)/100) -> 0 | DN30: 0 | DO30: 0 | DP30: 1 | DQ30: 1 | DU30: 1010 | DV30: шт. | DW30: шт. | DX30: 1 | EE30: 55992259 | EF30: 130 | EG30: Сметная стоимость оборудования | EH30: 0 | EJ30: 3 | EK30: 746 | EL30: ТСН-2001.13. Сметная стоимость оборудования | EM30: ТСН-2001.13 | EQ30: 0 | ER30: 0 | ES30: 8548.55 | ET30: 0 | EU30: 0 | EV30: 0 | EW30: 0 | EX30: 0 | EY30: 0 | FQ30: 0 | FR30: =P30 -> 8548.55 | FS30: 0 | FX30: 0 | FY30: 0 | GA30: [75 385 / 1,2 / 7,66] + 3% Трансп + 1,2% Заг.скл | GD30: 1 | GF30: 540965289 | GG30: 2 | GH30: 4 | GI30: -2 | GJ30: 0 | GK30: 0 | GL30: =ROUND(IF(AND(BH30=3,BI30=3,FS30<>0),P30,0),2) -> 0 | GM30: =ROUND(O30+X30+Y30,2)+GX30 -> 8548.55 | GN30: =IF(OR(BI30=0,BI30=1),GM30-GX30,0) -> 0 | GO30: =IF(BI30=2,GM30-GX30,0) -> 0 | GP30: =IF(BI30=4,GM30-GX30,0) -> 0 | GR30: 0 | GS30: 2 | GT30: 0 | GV30: =ROUND((GT30),6) -> 0 | GW30: 1 | GX30: =ROUND(HC30*I30,2) -> 0 | HA30: 0 | HB30: 0 | HC30: =GV30*GW30 -> 0 | HE30: 3 | HF30: 1,2 | HS30: 0 | IK30: 0
A31: 17 | B31: 1 | E31: 2 | F31: КА №1 | G31: Моноблок Lenovo V50a-24IMB | H31: шт. | I31: 1 | J31: 0 | K31: 1 | O31: =ROUND(CP31,2) -> 65481.89 | P31: =ROUND((ROUND((AC31*I31),2)*BC31),2) -> 65481.89 | Q31: =(ROUND((ROUND(((ET31)*AV31*I31),2)*BB31),2)+ROUND((ROUND(((AE31-(EU31))*AV31*I31),2)*BS31),2)) -> 0 | R31: =ROUND((ROUND((AE31*AV31*I31),2)*BS31),2) -> 0 | S31: =ROUND((ROUND((AF31*AV31*I31),2)*BA31),2) -> 0 | T31: =ROUND(CU31*I31,2) -> 0 | U31: =CV31*I31 -> 0 | V31: =CW31*I31 -> 0 | W31: =ROUND(CX31*I31,2) -> 0 | X31: =ROUND(CY31,2) -> 0 | Y31: =ROUND(CZ31,2) -> 0 | AA31: 56959431 | AB31: =ROUND((AC31+AD31+AF31),6) -> 8548.55 | AC31: =ROUND((ES31),6) -> 8548.55 | AD31: =ROUND((((ET31)-(EU31))+AE31),6) -> 0 | AE31: =ROUND((EU31),6) -> 0 | AF31: =ROUND((EV31),6) -> 0 | AG31: =ROUND((AP31),6) -> 0 | AH31: =(EW31) -> 0 | AI31: =(EX31) -> 0 | AJ31: =(AS31) -> 0 | AK31: 8548.55 | AL31: 8548.55 | AM31: 0 | AN31: 0 | AO31: 0 | AP31: 0 | AQ31: 0 | AR31: 0 | AS31: 0 | AT31: 0 | AU31: 0 | AV31: 1 | AW31: 1 | AZ31: 1 | BA31: 1 | BB31: 1 | BC31: 7.66 | BH31: 3 | BI31: 3 | BM31: 746 | BN31: 0 | BP31: 0 | BQ31: 130 | BR31: 0 | BS31: 1 | BT31: 1 | BU31: 1 | BV31: 1 | BW31: 1 | BX31: 1 | BZ31: 0 | CA31: 0 | CE31: 30 | CF31: 0 | CG31: 0 | CM31: 0 | CO31: 0 | CP31: =(P31+Q31+S31) -> 65481.89 | CQ31: =ROUND((ROUND((AC31*1),2)*BC31),2) -> 65481.89 | CR31: =(ROUND((ROUND(((ET31)*AV31*1),2)*BB31),2)+ROUND((ROUND(((AE31-(EU31))*AV31*1),2)*BS31),2)) -> 0 | CS31: =ROUND((ROUND((AE31*AV31*1),2)*BS31),2) -> 0 | CT31: =ROUND((ROUND((AF31*AV31*1),2)*BA31),2) -> 0 | CU31: =AG31 -> 0 | CV31: =(AH31*AV31) -> 0 | CW31: =AI31 -> 0 | CX31: =AJ31 -> 0 | CY31: =(((S31+R31)*AT31)/100) -> 0 | CZ31: =(((S31+R31)*AU31)/100) -> 0 | DN31: 0 | DO31: 0 | DP31: 1 | DQ31: 1 | DU31: 1010 | DV31: шт. | DW31: шт. | DX31: 1 | EE31: 55992259 | EF31: 130 | EG31: Сметная стоимость оборудования | EH31: 0 | EJ31: 3 | EK31: 746 | EL31: ТСН-2001.13. Сметная стоимость оборудования | EM31: ТСН-2001.13 | EQ31: 0 | ER31: 8548.55 | ES31: 8548.55 | ET31: 0 | EU31: 0 | EV31: 0 | EW31: 0 | EX31: 0 | EY31: 0 | EZ31: 5 | FC31: 1 | FD31: 18 | FF31: 75385 | FQ31: 0 | FR31: =P31 -> 65481.89 | FS31: 0 | FX31: 0 | FY31: 0 | GA31: [75 385 / 1,2 / 7,66] + 3% Трансп + 1,2% Заг.скл | GD31: 1 | GF31: 540965289 | GG31: 2 | GH31: 3 | GI31: 5 | GJ31: 0 | GK31: 0 | GL31: =ROUND(IF(AND(BH31=3,BI31=3,FS31<>0),P31,0),2) -> 0 | GM31: =ROUND(O31+X31+Y31,2)+GX31 -> 65481.89 | GN31: =IF(OR(BI31=0,BI31=1),GM31-GX31,0) -> 0 | GO31: =IF(BI31=2,GM31-GX31,0) -> 0 | GP31: =IF(BI31=4,GM31-GX31,0) -> 0 | GR31: 1 | GS31: 1 | GT31: 0 | GV31: =ROUND((GT31),6) -> 0 | GW31: 1 | GX31: =ROUND(HC31*I31,2) -> 0 | HA31: 0 | HB31: 0 | HC31: =GV31*GW31 -> 0 | HE31: 3 | HF31: 1,2 | HS31: 0 | IK31: 0
A32: 17 | B32: 1 | C32: =ROW(SmtRes!A11) -> 11 | D32: =ROW(EtalonRes!A13) -> 13 | E32: 3 | F32: 4.10-118-5 | G32: Установка для трубных проводок шкафа настенного размерами до 640х840 мм | H32: 1 ШТ. | I32: 1 | J32: 0 | K32: 1 | O32: =ROUND(CP32,2) -> 139.14 | P32: =ROUND((ROUND((AC32*AW32*I32),2)*BC32),2) -> 109.01 | Q32: =(ROUND((ROUND((((ET32*1.1))*AV32*I32),2)*BB32),2)+ROUND((ROUND(((AE32-((EU32*1.1)))*AV32*I32),2)*BS32),2)) -> 2.74 | R32: =ROUND((ROUND((AE32*AV32*I32),2)*BS32),2) -> 0.29 | S32: =ROUND((ROUND((AF32*AV32*I32),2)*BA32),2) -> 27.39 | T32: =ROUND(CU32*I32,2) -> 0 | U32: =CV32*I32 -> 2.3034 | V32: =CW32*I32 -> 0 | W32: =ROUND(CX32*I32,2) -> 0 | X32: =ROUND(CY32,2) -> 24.91 | Y32: =ROUND(CZ32,2) -> 12.73 | AA32: 56959434 | AB32: =ROUND((AC32+AD32+AF32),6) -> 137.786 | AC32: =ROUND((ES32),6) -> 109.01 | AD32: =ROUND(((((ET32*1.1))-((EU32*1.1)))+AE32),6) -> 2.618 | AE32: =ROUND(((EU32*1.1)),6) -> 0.275 | AF32: =ROUND(((EV32*1.1)),6) -> 26.158 | AG32: =ROUND((AP32),6) -> 0 | AH32: =((EW32*1.1)) -> 2.2 | AI32: =((EX32*1.1)) -> 0 | AJ32: =(AS32) -> 0 | AK32: 135.17 | AL32: 109.01 | AM32: 2.38 | AN32: 0.25 | AO32: 23.78 | AP32: 0 | AQ32: 2 | AR32: 0 | AS32: 0 | AT32: 90 | AU32: 46 | AV32: 1.047 | AW32: 1 | AZ32: 1 | BA32: 1 | BB32: 1 | BC32: 1 | BH32: 0 | BI32: 2 | BJ32: ТСН-2001.4 Доп. 79, Сб. 10, т. 118, поз. 5 | BM32: 68 | BN32: 55992028 | BO32: 4.10-118-5 | BP32: 1 | BQ32: 40 | BR32: 0 | BS32: 1 | BT32: 1 | BU32: 1 | BV32: 1 | BW32: 1 | BX32: 1 | BZ32: 90 | CA32: 46 | CE32: 30 | CF32: 0 | CG32: 0 | CM32: 0 | CN32: Поправка: Гл.12.Прил.8.п.8. 5_12.00.01.11.003 Наименование: При наличии усложненных условий производства работ (стесненность, сложность складирования и транспортной логистики, наличие в зоне производства работ действующего технологического оборудования или движения технологического транспорта и т.п.) для объектов, расположенных за пределами территории круговой магистральной системы улиц "Садовое кольцо" и за пределами Третьего транспортного кольца города Москвы пунктов "а" и "б", но в пределах Московской кольцевой автомобильной дороги | CO32: 0 | CP32: =(P32+Q32+S32) -> 139.14 | CQ32: =ROUND((ROUND((AC32*AW32*1),2)*BC32),2) -> 109.01 | CR32: =(ROUND((ROUND((((ET32*1.1))*AV32*1),2)*BB32),2)+ROUND((ROUND(((AE32-((EU32*1.1)))*AV32*1),2)*BS32),2)) -> 2.74 | CS32: =ROUND((ROUND((AE32*AV32*1),2)*BS32),2) -> 0.29 | CT32: =ROUND((ROUND((AF32*AV32*1),2)*BA32),2) -> 27.39 | CU32: =AG32 -> 0 | CV32: =(AH32*AV32) -> 2.3034 | CW32: =AI32 -> 0 | CX32: =AJ32 -> 0 | CY32: =(((S32+R32)*AT32)/100) -> 24.912 | CZ32: =(((S32+R32)*AU32)/100) -> 12.7328 | DE32: *1,1 | DF32: *1,1 | DG32: *1,1 | DI32: *1,1 | DJ32: *1,1 | DN32: 0 | DO32: 0 | DP32: 1 | DQ32: 1 | DU32: 1013 | DV32: 1 ШТ. | DW32: 1 ШТ. | DX32: 1 | EE32: 55992152 | EF32: 40 | EG32: Монтаж оборудования | EH32: 0 | EJ32: 2 | EK32: 68 | EL32: ТСН-2001.4-10. Прокладка и монтаж сетей связи | EM32: ТСН-2001.4-10-1 | EO32: Поправка: Гл.12.Прил.8.п.8. 5_12.00.01.11.003 | EQ32: 0 | ER32: 135.17 | ES32: 109.01 | ET32: 2.38 | EU32: 0.25 | EV32: 23.78 | EW32: 2 | EX32: 0 | EY32: 0 | FQ32: 0 | FR32: 0 | FS32: 0 | FX32: 90 | FY32: 46 | GD32: 1 | GF32: 438712902 | GG32: 2 | GH32: 1 | GI32: 2 | GJ32: 0 | GK32: 0 | GL32: =ROUND(IF(AND(BH32=3,BI32=3,FS32<>0),P32,0),2) -> 0 | GM32: =ROUND(O32+X32+Y32,2)+GX32 -> 176.78 | GN32: =IF(OR(BI32=0,BI32=1),GM32-GX32,0) -> 0 | GO32: =IF(BI32=2,GM32-GX32,0) -> 176.78 | GP32: =IF(BI32=4,GM32-GX32,0) -> 0 | GR32: 0 | GS32: 3 | GT32: 0 | GV32: =ROUND((GT32),6) -> 0 | GW32: 1 | GX32: =ROUND(HC32*I32,2) -> 0 | HA32: 0 | HB32: 0 | HC32: =GV32*GW32 -> 0 | HS32: 0 | IK32: 0
A33: 17 | B33: 1 | C33: =ROW(SmtRes!A18) -> 18 | D33: =ROW(EtalonRes!A20) -> 20 | E33: 3 | F33: 4.10-118-5 | G33: Установка для трубных проводок шкафа настенного размерами до 640х840 мм | H33: 1 ШТ. | I33: 1 | J33: 0 | K33: 1 | O33: =ROUND(CP33,2) -> 1899.88 | P33: =ROUND((ROUND((AC33*AW33*I33),2)*BC33),2) -> 355.37 | Q33: =(ROUND((ROUND((((ET33*1.1))*AV33*I33),2)*BB33),2)+ROUND((ROUND(((AE33-((EU33*1.1)))*AV33*I33),2)*BS33),2)) -> 38.33 | R33: =ROUND((ROUND((AE33*AV33*I33),2)*BS33),2) -> 15.95 | S33: =ROUND((ROUND((AF33*AV33*I33),2)*BA33),2) -> 1506.18 | T33: =ROUND(CU33*I33,2) -> 0 | U33: =CV33*I33 -> 2.3034 | V33: =CW33*I33 -> 0 | W33: =ROUND(CX33*I33,2) -> 0 | X33: =ROUND(CY33,2) -> 1369.92 | Y33: =ROUND(CZ33,2) -> 700.18 | AA33: 56959431 | AB33: =ROUND((AC33+AD33+AF33),6) -> 137.786 | AC33: =ROUND((ES33),6) -> 109.01 | AD33: =ROUND(((((ET33*1.1))-((EU33*1.1)))+AE33),6) -> 2.618 | AE33: =ROUND(((EU33*1.1)),6) -> 0.275 | AF33: =ROUND(((EV33*1.1)),6) -> 26.158 | AG33: =ROUND((AP33),6) -> 0 | AH33: =((EW33*1.1)) -> 2.2 | AI33: =((EX33*1.1)) -> 0 | AJ33: =(AS33) -> 0 | AK33: 135.17 | AL33: 109.01 | AM33: 2.38 | AN33: 0.25 | AO33: 23.78 | AP33: 0 | AQ33: 2 | AR33: 0 | AS33: 0 | AT33: 90 | AU33: 46 | AV33: 1.047 | AW33: 1 | AZ33: 1 | BA33: 54.99 | BB33: 13.99 | BC33: 3.26 | BH33: 0 | BI33: 2 | BJ33: ТСН-2001.4 Доп. 79, Сб. 10, т. 118, поз. 5 | BM33: 68 | BN33: 55992028 | BO33: 4.10-118-5 | BP33: 1 | BQ33: 40 | BR33: 0 | BS33: 54.99 | BT33: 1 | BU33: 1 | BV33: 1 | BW33: 1 | BX33: 1 | BZ33: 90 | CA33: 46 | CE33: 30 | CF33: 0 | CG33: 0 | CM33: 0 | CN33: Поправка: Гл.12.Прил.8.п.8. 5_12.00.01.11.003 Наименование: При наличии усложненных условий производства работ (стесненность, сложность складирования и транспортной логистики, наличие в зоне производства работ действующего технологического оборудования или движения технологического транспорта и т.п.) для объектов, расположенных за пределами территории круговой магистральной системы улиц "Садовое кольцо" и за пределами Третьего транспортного кольца города Москвы пунктов "а" и "б", но в пределах Московской кольцевой автомобильной дороги | CO33: 0 | CP33: =(P33+Q33+S33) -> 1899.88 | CQ33: =ROUND((ROUND((AC33*AW33*1),2)*BC33),2) -> 355.37 | CR33: =(ROUND((ROUND((((ET33*1.1))*AV33*1),2)*BB33),2)+ROUND((ROUND(((AE33-((EU33*1.1)))*AV33*1),2)*BS33),2)) -> 38.33 | CS33: =ROUND((ROUND((AE33*AV33*1),2)*BS33),2) -> 15.95 | CT33: =ROUND((ROUND((AF33*AV33*1),2)*BA33),2) -> 1506.18 | CU33: =AG33 -> 0 | CV33: =(AH33*AV33) -> 2.3034 | CW33: =AI33 -> 0 | CX33: =AJ33 -> 0 | CY33: =(((S33+R33)*AT33)/100) -> 1369.917 | CZ33: =(((S33+R33)*AU33)/100) -> 700.1798 | DE33: *1,1 | DF33: *1,1 | DG33: *1,1 | DI33: *1,1 | DJ33: *1,1 | DN33: 0 | DO33: 0 | DP33: 1 | DQ33: 1 | DU33: 1013 | DV33: 1 ШТ. | DW33: 1 ШТ. | DX33: 1 | EE33: 55992152 | EF33: 40 | EG33: Монтаж оборудования | EH33: 0 | EJ33: 2 | EK33: 68 | EL33: ТСН-2001.4-10. Прокладка и монтаж сетей связи | EM33: ТСН-2001.4-10-1 | EO33: Поправка: Гл.12.Прил.8.п.8. 5_12.00.01.11.003 | EQ33: 0 | ER33: 135.17 | ES33: 109.01 | ET33: 2.38 | EU33: 0.25 | EV33: 23.78 | EW33: 2 | EX33: 0 | EY33: 0 | FQ33: 0 | FR33: 0 | FS33: 0 | FX33: 90 | FY33: 46 | GD33: 1 | GF33: 438712902 | GG33: 2 | GH33: 1 | GI33: 2 | GJ33: 0 | GK33: 0 | GL33: =ROUND(IF(AND(BH33=3,BI33=3,FS33<>0),P33,0),2) -> 0 | GM33: =ROUND(O33+X33+Y33,2)+GX33 -> 3969.98 | GN33: =IF(OR(BI33=0,BI33=1),GM33-GX33,0) -> 0 | GO33: =IF(BI33=2,GM33-GX33,0) -> 3969.98 | GP33: =IF(BI33=4,GM33-GX33,0) -> 0 | GR33: 0 | GS33: 3 | GT33: 0 | GV33: =ROUND((GT33),6) -> 0 | GW33: 1 | GX33: =ROUND(HC33*I33,2) -> 0 | HA33: 0 | HB33: 0 | HC33: =GV33*GW33 -> 0 | HS33: 0 | IK33: 0
A34: 18 | B34: 1 | C34: 10 | E34: 3,1 | F34: 1.21-1-63 | G34: Щит навесной, с дверцей и замком, степень защиты IР55, размер 600х600х250 мм, металлоконструкция без аппаратов | H34: шт. | I34: =I32*J34 -> 1 | J34: 1 | K34: 1 | O34: =ROUND(CP34,2) -> 1975.19 | P34: =ROUND((ROUND((AC34*AW34*I34),2)*BC34),2) -> 1975.19 | Q34: =(ROUND((ROUND(((ET34)*AV34*I34),2)*BB34),2)+ROUND((ROUND(((AE34-(EU34))*AV34*I34),2)*BS34),2)) -> 0 | R34: =ROUND((ROUND((AE34*AV34*I34),2)*BS34),2) -> 0 | S34: =ROUND((ROUND((AF34*AV34*I34),2)*BA34),2) -> 0 | T34: =ROUND(CU34*I34,2) -> 0 | U34: =CV34*I34 -> 0 | V34: =CW34*I34 -> 0 | W34: =ROUND(CX34*I34,2) -> 0 | X34: =ROUND(CY34,2) -> 0 | Y34: =ROUND(CZ34,2) -> 0 | AA34: 56959434 | AB34: =ROUND((AC34+AD34+AF34),6) -> 1975.19 | AC34: =ROUND((ES34),6) -> 1975.19 | AD34: =ROUND((((ET34)-(EU34))+AE34),6) -> 0 | AE34: =ROUND((EU34),6) -> 0 | AF34: =ROUND((EV34),6) -> 0 | AG34: =ROUND((AP34),6) -> 0 | AH34: =(EW34) -> 0 | AI34: =(EX34) -> 0 | AJ34: =(AS34) -> 0 | AK34: 1975.19 | AL34: 1975.19 | AM34: 0 | AN34: 0 | AO34: 0 | AP34: 0 | AQ34: 0 | AR34: 0 | AS34: 0 | AT34: 90 | AU34: 46 | AV34: 1 | AW34: 1 | AZ34: 1 | BA34: 1 | BB34: 1 | BC34: 1 | BH34: 3 | BI34: 2 | BJ34: ТСН-2001.1 Доп. 79, Р. 21, о. 1, поз. 63 | BM34: 68 | BN34: 55992028 | BP34: 0 | BQ34: 40 | BR34: 0 | BS34: 1 | BT34: 1 | BU34: 1 | BV34: 1 | BW34: 1 | BX34: 1 | BZ34: 90 | CA34: 46 | CE34: 30 | CF34: 0 | CG34: 0 | CM34: 0 | CO34: 0 | CP34: =(P34+Q34+S34) -> 1975.19 | CQ34: =ROUND((ROUND((AC34*AW34*1),2)*BC34),2) -> 1975.19 | CR34: =(ROUND((ROUND(((ET34)*AV34*1),2)*BB34),2)+ROUND((ROUND(((AE34-(EU34))*AV34*1),2)*BS34),2)) -> 0 | CS34: =ROUND((ROUND((AE34*AV34*1),2)*BS34),2) -> 0 | CT34: =ROUND((ROUND((AF34*AV34*1),2)*BA34),2) -> 0 | CU34: =AG34 -> 0 | CV34: =(AH34*AV34) -> 0 | CW34: =AI34 -> 0 | CX34: =AJ34 -> 0 | CY34: =(((S34+R34)*AT34)/100) -> 0 | CZ34: =(((S34+R34)*AU34)/100) -> 0 | DN34: 0 | DO34: 0 | DP34: 1 | DQ34: 1 | DU34: 1010 | DV34: шт. | DW34: шт. | DX34: 1 | EE34: 55992152 | EF34: 40 | EG34: Монтаж оборудования | EH34: 0 | EJ34: 2 | EK34: 68 | EL34: ТСН-2001.4-10. Прокладка и монтаж сетей связи | EM34: ТСН-2001.4-10-1 | EQ34: 0 | ER34: 1975.19 | ES34: 1975.19 | ET34: 0 | EU34: 0 | EV34: 0 | EW34: 0 | EX34: 0 | FQ34: 0 | FR34: 0 | FS34: 0 | FX34: 90 | FY34: 46 | GD34: 1 | GF34: 672353504 | GG34: 2 | GH34: 1 | GI34: -2 | GJ34: 0 | GK34: 0 | GL34: =ROUND(IF(AND(BH34=3,BI34=3,FS34<>0),P34,0),2) -> 0 | GM34: =ROUND(O34+X34+Y34,2)+GX34 -> 1975.19 | GN34: =IF(OR(BI34=0,BI34=1),GM34-GX34,0) -> 0 | GO34: =IF(BI34=2,GM34-GX34,0) -> 1975.19 | GP34: =IF(BI34=4,GM34-GX34,0) -> 0 | GR34: 0 | GS34: 3 | GT34: 0 | GV34: =ROUND((GT34),6) -> 0 | GW34: 1 | GX34: =ROUND(HC34*I34,2) -> 0 | HA34: 0 | HB34: 0 | HC34: =GV34*GW34 -> 0 | HS34: 0 | IK34: 0
A35: 18 | B35: 1 | C35: 17 | E35: 3,1 | F35: 1.21-1-63 | G35: Щит навесной, с дверцей и замком, степень защиты IР55, размер 600х600х250 мм, металлоконструкция без аппаратов | H35: шт. | I35: =I33*J35 -> 1 | J35: 1 | K35: 1 | O35: =ROUND(CP35,2) -> 13549.8 | P35: =ROUND((ROUND((AC35*AW35*I35),2)*BC35),2) -> 13549.8 | Q35: =(ROUND((ROUND(((ET35)*AV35*I35),2)*BB35),2)+ROUND((ROUND(((AE35-(EU35))*AV35*I35),2)*BS35),2)) -> 0 | R35: =ROUND((ROUND((AE35*AV35*I35),2)*BS35),2) -> 0 | S35: =ROUND((ROUND((AF35*AV35*I35),2)*BA35),2) -> 0 | T35: =ROUND(CU35*I35,2) -> 0 | U35: =CV35*I35 -> 0 | V35: =CW35*I35 -> 0 | W35: =ROUND(CX35*I35,2) -> 0 | X35: =ROUND(CY35,2) -> 0 | Y35: =ROUND(CZ35,2) -> 0 | AA35: 56959431 | AB35: =ROUND((AC35+AD35+AF35),6) -> 1975.19 | AC35: =ROUND((ES35),6) -> 1975.19 | AD35: =ROUND((((ET35)-(EU35))+AE35),6) -> 0 | AE35: =ROUND((EU35),6) -> 0 | AF35: =ROUND((EV35),6) -> 0 | AG35: =ROUND((AP35),6) -> 0 | AH35: =(EW35) -> 0 | AI35: =(EX35) -> 0 | AJ35: =(AS35) -> 0 | AK35: 1975.19 | AL35: 1975.19 | AM35: 0 | AN35: 0 | AO35: 0 | AP35: 0 | AQ35: 0 | AR35: 0 | AS35: 0 | AT35: 90 | AU35: 46 | AV35: 1 | AW35: 1 | AZ35: 1 | BA35: 1 | BB35: 1 | BC35: 6.86 | BH35: 3 | BI35: 2 | BJ35: ТСН-2001.1 Доп. 79, Р. 21, о. 1, поз. 63 | BM35: 68 | BN35: 55992028 | BO35: 1.21-1-63 | BP35: 1 | BQ35: 40 | BR35: 0 | BS35: 1 | BT35: 1 | BU35: 1 | BV35: 1 | BW35: 1 | BX35: 1 | BZ35: 90 | CA35: 46 | CE35: 30 | CF35: 0 | CG35: 0 | CM35: 0 | CO35: 0 | CP35: =(P35+Q35+S35) -> 13549.8 | CQ35: =ROUND((ROUND((AC35*AW35*1),2)*BC35),2) -> 13549.8 | CR35: =(ROUND((ROUND(((ET35)*AV35*1),2)*BB35),2)+ROUND((ROUND(((AE35-(EU35))*AV35*1),2)*BS35),2)) -> 0 | CS35: =ROUND((ROUND((AE35*AV35*1),2)*BS35),2) -> 0 | CT35: =ROUND((ROUND((AF35*AV35*1),2)*BA35),2) -> 0 | CU35: =AG35 -> 0 | CV35: =(AH35*AV35) -> 0 | CW35: =AI35 -> 0 | CX35: =AJ35 -> 0 | CY35: =(((S35+R35)*AT35)/100) -> 0 | CZ35: =(((S35+R35)*AU35)/100) -> 0 | DN35: 0 | DO35: 0 | DP35: 1 | DQ35: 1 | DU35: 1010 | DV35: шт. | DW35: шт. | DX35: 1 | EE35: 55992152 | EF35: 40 | EG35: Монтаж оборудования | EH35: 0 | EJ35: 2 | EK35: 68 | EL35: ТСН-2001.4-10. Прокладка и монтаж сетей связи | EM35: ТСН-2001.4-10-1 | EQ35: 0 | ER35: 1975.19 | ES35: 1975.19 | ET35: 0 | EU35: 0 | EV35: 0 | EW35: 0 | EX35: 0 | FQ35: 0 | FR35: 0 | FS35: 0 | FX35: 90 | FY35: 46 | GD35: 1 | GF35: 672353504 | GG35: 2 | GH35: 1 | GI35: 2 | GJ35: 0 | GK35: 0 | GL35: =ROUND(IF(AND(BH35=3,BI35=3,FS35<>0),P35,0),2) -> 0 | GM35: =ROUND(O35+X35+Y35,2)+GX35 -> 13549.8 | GN35: =IF(OR(BI35=0,BI35=1),GM35-GX35,0) -> 0 | GO35: =IF(BI35=2,GM35-GX35,0) -> 13549.8 | GP35: =IF(BI35=4,GM35-GX35,0) -> 0 | GR35: 0 | GS35: 3 | GT35: 0 | GV35: =ROUND((GT35),6) -> 0 | GW35: 1 | GX35: =ROUND(HC35*I35,2) -> 0 | HA35: 0 | HB35: 0 | HC35: =GV35*GW35 -> 0 | HS35: 0 | IK35: 0
A36: 17 | B36: 1 | C36: =ROW(SmtRes!A20) -> 20 | D36: =ROW(EtalonRes!A23) -> 23 | E36: 4 | F36: 4.11-12-1 | G36: Установка съемных и выдвижных блоков (модулей, ячеек, ТЭЗ) массой до 5 кг | H36: 1 ШТ. | I36: 1 | J36: 0 | K36: 1 | O36: =ROUND(CP36,2) -> 14 | P36: =ROUND((ROUND((AC36*AW36*I36),2)*BC36),2) -> 0 | Q36: =(ROUND((ROUND((((ET36*1.1))*AV36*I36),2)*BB36),2)+ROUND((ROUND(((AE36-((EU36*1.1)))*AV36*I36),2)*BS36),2)) -> 0.58 | R36: =ROUND((ROUND((AE36*AV36*I36),2)*BS36),2) -> 0.09 | S36: =ROUND((ROUND((AF36*AV36*I36),2)*BA36),2) -> 13.42 | T36: =ROUND(CU36*I36,2) -> 0 | U36: =CV36*I36 -> 1.186251 | V36: =CW36*I36 -> 0 | W36: =ROUND(CX36*I36,2) -> 0 | X36: =ROUND(CY36,2) -> 12.16 | Y36: =ROUND(CZ36,2) -> 6.21 | AA36: 56959434 | AB36: =ROUND((AC36+AD36+AF36),6) -> 13.365 | AC36: =ROUND((ES36),6) -> 0 | AD36: =ROUND(((((ET36*1.1))-((EU36*1.1)))+AE36),6) -> 0.55 | AE36: =ROUND(((EU36*1.1)),6) -> 0.088 | AF36: =ROUND(((EV36*1.1)),6) -> 12.815 | AG36: =ROUND((AP36),6) -> 0 | AH36: =((EW36*1.1)) -> 1.133 | AI36: =((EX36*1.1)) -> 0 | AJ36: =(AS36) -> 0 | AK36: 12.15 | AL36: 0 | AM36: 0.5 | AN36: 0.08 | AO36: 11.65 | AP36: 0 | AQ36: 1.03 | AR36: 0 | AS36: 0 | AT36: 90 | AU36: 46 | AV36: 1.047 | AW36: 1 | AZ36: 1 | BA36: 1 | BB36: 1 | BC36: 1 | BH36: 0 | BI36: 2 | BJ36: ТСН-2001.4 Доп. 68, Сб. 11, т. 12, поз. 1 | BM36: 72 | BN36: 55992028 | BO36: 4.11-12-1 | BP36: 1 | BQ36: 40 | BR36: 0 | BS36: 1 | BT36: 1 | BU36: 1 | BV36: 1 | BW36: 1 | BX36: 1 | BZ36: 90 | CA36: 46 | CE36: 30 | CF36: 0 | CG36: 0 | CM36: 0 | CN36: Поправка: Гл.12.Прил.8.п.8. 5_12.00.01.11.003 Наименование: При наличии усложненных условий производства работ (стесненность, сложность складирования и транспортной логистики, наличие в зоне производства работ действующего технологического оборудования или движения технологического транспорта и т.п.) для объектов, расположенных за пределами территории круговой магистральной системы улиц "Садовое кольцо" и за пределами Третьего транспортного кольца города Москвы пунктов "а" и "б", но в пределах Московской кольцевой автомобильной дороги | CO36: 0 | CP36: =(P36+Q36+S36) -> 14 | CQ36: =ROUND((ROUND((AC36*AW36*1),2)*BC36),2) -> 0 | CR36: =(ROUND((ROUND((((ET36*1.1))*AV36*1),2)*BB36),2)+ROUND((ROUND(((AE36-((EU36*1.1)))*AV36*1),2)*BS36),2)) -> 0.58 | CS36: =ROUND((ROUND((AE36*AV36*1),2)*BS36),2) -> 0.09 | CT36: =ROUND((ROUND((AF36*AV36*1),2)*BA36),2) -> 13.42 | CU36: =AG36 -> 0 | CV36: =(AH36*AV36) -> 1.186251 | CW36: =AI36 -> 0 | CX36: =AJ36 -> 0 | CY36: =(((S36+R36)*AT36)/100) -> 12.159 | CZ36: =(((S36+R36)*AU36)/100) -> 6.2146 | DE36: *1,1 | DF36: *1,1 | DG36: *1,1 | DI36: *1,1 | DJ36: *1,1 | DN36: 0 | DO36: 0 | DP36: 1 | DQ36: 1 | DU36: 1013 | DV36: 1 ШТ. | DW36: 1 ШТ. | DX36: 1 | EE36: 55992157 | EF36: 40 | EG36: Монтаж оборудования | EH36: 0 | EJ36: 2 | EK36: 72 | EL36: ТСН-2001.4-11. Приборы и средства автоматизации и вычислительной техники | EM36: ТСН-2001.4-11-1 | EO36: Поправка: Гл.12.Прил.8.п.8. 5_12.00.01.11.003 | EQ36: 0 | ER36: 12.15 | ES36: 0 | ET36: 0.5 | EU36: 0.08 | EV36: 11.65 | EW36: 1.03 | EX36: 0 | EY36: 0 | FQ36: 0 | FR36: 0 | FS36: 0 | FX36: 90 | FY36: 46 | GD36: 1 | GF36: 1708693888 | GG36: 2 | GH36: 1 | GI36: 2 | GJ36: 0 | GK36: 0 | GL36: =ROUND(IF(AND(BH36=3,BI36=3,FS36<>0),P36,0),2) -> 0 | GM36: =ROUND(O36+X36+Y36,2)+GX36 -> 32.37 | GN36: =IF(OR(BI36=0,BI36=1),GM36-GX36,0) -> 0 | GO36: =IF(BI36=2,GM36-GX36,0) -> 32.37 | GP36: =IF(BI36=4,GM36-GX36,0) -> 0 | GR36: 0 | GS36: 3 | GT36: 0 | GV36: =ROUND((GT36),6) -> 0 | GW36: 1 | GX36: =ROUND(HC36*I36,2) -> 0 | HA36: 0 | HB36: 0 | HC36: =GV36*GW36 -> 0 | HS36: 0 | IK36: 0
A37: 17 | B37: 1 | C37: =ROW(SmtRes!A22) -> 22 | D37: =ROW(EtalonRes!A26) -> 26 | E37: 4 | F37: 4.11-12-1 | G37: Установка съемных и выдвижных блоков (модулей, ячеек, ТЭЗ) массой до 5 кг | H37: 1 ШТ. | I37: 1 | J37: 0 | K37: 1 | O37: =ROUND(CP37,2) -> 747.4 | P37: =ROUND((ROUND((AC37*AW37*I37),2)*BC37),2) -> 0 | Q37: =(ROUND((ROUND((((ET37*1.1))*AV37*I37),2)*BB37),2)+ROUND((ROUND(((AE37-((EU37*1.1)))*AV37*I37),2)*BS37),2)) -> 9.43 | R37: =ROUND((ROUND((AE37*AV37*I37),2)*BS37),2) -> 4.95 | S37: =ROUND((ROUND((AF37*AV37*I37),2)*BA37),2) -> 737.97 | T37: =ROUND(CU37*I37,2) -> 0 | U37: =CV37*I37 -> 1.186251 | V37: =CW37*I37 -> 0 | W37: =ROUND(CX37*I37,2) -> 0 | X37: =ROUND(CY37,2) -> 668.63 | Y37: =ROUND(CZ37,2) -> 341.74 | AA37: 56959431 | AB37: =ROUND((AC37+AD37+AF37),6) -> 13.365 | AC37: =ROUND((ES37),6) -> 0 | AD37: =ROUND(((((ET37*1.1))-((EU37*1.1)))+AE37),6) -> 0.55 | AE37: =ROUND(((EU37*1.1)),6) -> 0.088 | AF37: =ROUND(((EV37*1.1)),6) -> 12.815 | AG37: =ROUND((AP37),6) -> 0 | AH37: =((EW37*1.1)) -> 1.133 | AI37: =((EX37*1.1)) -> 0 | AJ37: =(AS37) -> 0 | AK37: 12.15 | AL37: 0 | AM37: 0.5 | AN37: 0.08 | AO37: 11.65 | AP37: 0 | AQ37: 1.03 | AR37: 0 | AS37: 0 | AT37: 90 | AU37: 46 | AV37: 1.047 | AW37: 1 | AZ37: 1 | BA37: 54.99 | BB37: 16.26 | BC37: 1 | BH37: 0 | BI37: 2 | BJ37: ТСН-2001.4 Доп. 68, Сб. 11, т. 12, поз. 1 | BM37: 72 | BN37: 55992028 | BO37: 4.11-12-1 | BP37: 1 | BQ37: 40 | BR37: 0 | BS37: 54.99 | BT37: 1 | BU37: 1 | BV37: 1 | BW37: 1 | BX37: 1 | BZ37: 90 | CA37: 46 | CE37: 30 | CF37: 0 | CG37: 0 | CM37: 0 | CN37: Поправка: Гл.12.Прил.8.п.8. 5_12.00.01.11.003 Наименование: При наличии усложненных условий производства работ (стесненность, сложность складирования и транспортной логистики, наличие в зоне производства работ действующего технологического оборудования или движения технологического транспорта и т.п.) для объектов, расположенных за пределами территории круговой магистральной системы улиц "Садовое кольцо" и за пределами Третьего транспортного кольца города Москвы пунктов "а" и "б", но в пределах Московской кольцевой автомобильной дороги | CO37: 0 | CP37: =(P37+Q37+S37) -> 747.4 | CQ37: =ROUND((ROUND((AC37*AW37*1),2)*BC37),2) -> 0 | CR37: =(ROUND((ROUND((((ET37*1.1))*AV37*1),2)*BB37),2)+ROUND((ROUND(((AE37-((EU37*1.1)))*AV37*1),2)*BS37),2)) -> 9.43 | CS37: =ROUND((ROUND((AE37*AV37*1),2)*BS37),2) -> 4.95 | CT37: =ROUND((ROUND((AF37*AV37*1),2)*BA37),2) -> 737.97 | CU37: =AG37 -> 0 | CV37: =(AH37*AV37) -> 1.186251 | CW37: =AI37 -> 0 | CX37: =AJ37 -> 0 | CY37: =(((S37+R37)*AT37)/100) -> 668.628 | CZ37: =(((S37+R37)*AU37)/100) -> 341.7432 | DE37: *1,1 | DF37: *1,1 | DG37: *1,1 | DI37: *1,1 | DJ37: *1,1 | DN37: 0 | DO37: 0 | DP37: 1 | DQ37: 1 | DU37: 1013 | DV37: 1 ШТ. | DW37: 1 ШТ. | DX37: 1 | EE37: 55992157 | EF37: 40 | EG37: Монтаж оборудования | EH37: 0 | EJ37: 2 | EK37: 72 | EL37: ТСН-2001.4-11. Приборы и средства автоматизации и вычислительной техники | EM37: ТСН-2001.4-11-1 | EO37: Поправка: Гл.12.Прил.8.п.8. 5_12.00.01.11.003 | EQ37: 0 | ER37: 12.15 | ES37: 0 | ET37: 0.5 | EU37: 0.08 | EV37: 11.65 | EW37: 1.03 | EX37: 0 | EY37: 0 | FQ37: 0 | FR37: 0 | FS37: 0 | FX37: 90 | FY37: 46 | GD37: 1 | GF37: 1708693888 | GG37: 2 | GH37: 1 | GI37: 2 | GJ37: 0 | GK37: 0 | GL37: =ROUND(IF(AND(BH37=3,BI37=3,FS37<>0),P37,0),2) -> 0 | GM37: =ROUND(O37+X37+Y37,2)+GX37 -> 1757.77 | GN37: =IF(OR(BI37=0,BI37=1),GM37-GX37,0) -> 0 | GO37: =IF(BI37=2,GM37-GX37,0) -> 1757.77 | GP37: =IF(BI37=4,GM37-GX37,0) -> 0 | GR37: 0 | GS37: 3 | GT37: 0 | GV37: =ROUND((GT37),6) -> 0 | GW37: 1 | GX37: =ROUND(HC37*I37,2) -> 0 | HA37: 0 | HB37: 0 | HC37: =GV37*GW37 -> 0 | HS37: 0 | IK37: 0
A38: 17 | B38: 1 | E38: 5 | F38: КА №2 | G38: Шлюз tGW-715i Segnetics | H38: шт. | I38: 1 | J38: 0 | K38: 1 | O38: =ROUND(CP38,2) -> 1618.36 | P38: =ROUND((ROUND((AC38*I38),2)*BC38),2) -> 1618.36 | Q38: =(ROUND((ROUND(((ET38)*AV38*I38),2)*BB38),2)+ROUND((ROUND(((AE38-(EU38))*AV38*I38),2)*BS38),2)) -> 0 | R38: =ROUND((ROUND((AE38*AV38*I38),2)*BS38),2) -> 0 | S38: =ROUND((ROUND((AF38*AV38*I38),2)*BA38),2) -> 0 | T38: =ROUND(CU38*I38,2) -> 0 | U38: =CV38*I38 -> 0 | V38: =CW38*I38 -> 0 | W38: =ROUND(CX38*I38,2) -> 0 | X38: =ROUND(CY38,2) -> 0 | Y38: =ROUND(CZ38,2) -> 0 | AA38: 56959434 | AB38: =ROUND((AC38+AD38+AF38),6) -> 1618.36 | AC38: =ROUND((ES38),6) -> 1618.36 | AD38: =ROUND((((ET38)-(EU38))+AE38),6) -> 0 | AE38: =ROUND((EU38),6) -> 0 | AF38: =ROUND((EV38),6) -> 0 | AG38: =ROUND((AP38),6) -> 0 | AH38: =(EW38) -> 0 | AI38: =(EX38) -> 0 | AJ38: =(AS38) -> 0 | AK38: 1618.36 | AL38: 1618.36 | AM38: 0 | AN38: 0 | AO38: 0 | AP38: 0 | AQ38: 0 | AR38: 0 | AS38: 0 | AT38: 0 | AU38: 0 | AV38: 1 | AW38: 1 | AZ38: 1 | BA38: 1 | BB38: 1 | BC38: 1 | BH38: 3 | BI38: 3 | BM38: 746 | BN38: 0 | BP38: 0 | BQ38: 130 | BR38: 0 | BS38: 1 | BT38: 1 | BU38: 1 | BV38: 1 | BW38: 1 | BX38: 1 | BZ38: 0 | CA38: 0 | CE38: 30 | CF38: 0 | CG38: 0 | CM38: 0 | CO38: 0 | CP38: =(P38+Q38+S38) -> 1618.36 | CQ38: =ROUND((ROUND((AC38*1),2)*BC38),2) -> 1618.36 | CR38: =(ROUND((ROUND(((ET38)*AV38*1),2)*BB38),2)+ROUND((ROUND(((AE38-(EU38))*AV38*1),2)*BS38),2)) -> 0 | CS38: =ROUND((ROUND((AE38*AV38*1),2)*BS38),2) -> 0 | CT38: =ROUND((ROUND((AF38*AV38*1),2)*BA38),2) -> 0 | CU38: =AG38 -> 0 | CV38: =(AH38*AV38) -> 0 | CW38: =AI38 -> 0 | CX38: =AJ38 -> 0 | CY38: =(((S38+R38)*AT38)/100) -> 0 | CZ38: =(((S38+R38)*AU38)/100) -> 0 | DN38: 0 | DO38: 0 | DP38: 1 | DQ38: 1 | DU38: 1010 | DV38: шт. | DW38: шт. | DX38: 1 | EE38: 55992259 | EF38: 130 | EG38: Сметная стоимость оборудования | EH38: 0 | EJ38: 3 | EK38: 746 | EL38: ТСН-2001.13. Сметная стоимость оборудования | EM38: ТСН-2001.13 | EQ38: 0 | ER38: 0 | ES38: 1618.36 | ET38: 0 | EU38: 0 | EV38: 0 | EW38: 0 | EX38: 0 | EY38: 0 | FQ38: 0 | FR38: =P38 -> 1618.36 | FS38: 0 | FX38: 0 | FY38: 0 | GA38: [14 271,44 / 1,2 / 7,66] + 3% Трансп + 1,2% Заг.скл | GD38: 1 | GF38: 493595391 | GG38: 2 | GH38: 4 | GI38: -2 | GJ38: 0 | GK38: 0 | GL38: =ROUND(IF(AND(BH38=3,BI38=3,FS38<>0),P38,0),2) -> 0 | GM38: =ROUND(O38+X38+Y38,2)+GX38 -> 1618.36 | GN38: =IF(OR(BI38=0,BI38=1),GM38-GX38,0) -> 0 | GO38: =IF(BI38=2,GM38-GX38,0) -> 0 | GP38: =IF(BI38=4,GM38-GX38,0) -> 0 | GR38: 0 | GS38: 2 | GT38: 0 | GV38: =ROUND((GT38),6) -> 0 | GW38: 1 | GX38: =ROUND(HC38*I38,2) -> 0 | HA38: 0 | HB38: 0 | HC38: =GV38*GW38 -> 0 | HE38: 3 | HF38: 1,2 | HS38: 0 | IK38: 0
A39: 17 | B39: 1 | E39: 5 | F39: КА №2 | G39: Шлюз tGW-715i Segnetics | H39: шт. | I39: 1 | J39: 0 | K39: 1 | O39: =ROUND(CP39,2) -> 12396.64 | P39: =ROUND((ROUND((AC39*I39),2)*BC39),2) -> 12396.64 | Q39: =(ROUND((ROUND(((ET39)*AV39*I39),2)*BB39),2)+ROUND((ROUND(((AE39-(EU39))*AV39*I39),2)*BS39),2)) -> 0 | R39: =ROUND((ROUND((AE39*AV39*I39),2)*BS39),2) -> 0 | S39: =ROUND((ROUND((AF39*AV39*I39),2)*BA39),2) -> 0 | T39: =ROUND(CU39*I39,2) -> 0 | U39: =CV39*I39 -> 0 | V39: =CW39*I39 -> 0 | W39: =ROUND(CX39*I39,2) -> 0 | X39: =ROUND(CY39,2) -> 0 | Y39: =ROUND(CZ39,2) -> 0 | AA39: 56959431 | AB39: =ROUND((AC39+AD39+AF39),6) -> 1618.36 | AC39: =ROUND((ES39),6) -> 1618.36 | AD39: =ROUND((((ET39)-(EU39))+AE39),6) -> 0 | AE39: =ROUND((EU39),6) -> 0 | AF39: =ROUND((EV39),6) -> 0 | AG39: =ROUND((AP39),6) -> 0 | AH39: =(EW39) -> 0 | AI39: =(EX39) -> 0 | AJ39: =(AS39) -> 0 | AK39: 1618.36 | AL39: 1618.36 | AM39: 0 | AN39: 0 | AO39: 0 | AP39: 0 | AQ39: 0 | AR39: 0 | AS39: 0 | AT39: 0 | AU39: 0 | AV39: 1 | AW39: 1 | AZ39: 1 | BA39: 1 | BB39: 1 | BC39: 7.66 | BH39: 3 | BI39: 3 | BM39: 746 | BN39: 0 | BP39: 0 | BQ39: 130 | BR39: 0 | BS39: 1 | BT39: 1 | BU39: 1 | BV39: 1 | BW39: 1 | BX39: 1 | BZ39: 0 | CA39: 0 | CE39: 30 | CF39: 0 | CG39: 0 | CM39: 0 | CO39: 0 | CP39: =(P39+Q39+S39) -> 12396.64 | CQ39: =ROUND((ROUND((AC39*1),2)*BC39),2) -> 12396.64 | CR39: =(ROUND((ROUND(((ET39)*AV39*1),2)*BB39),2)+ROUND((ROUND(((AE39-(EU39))*AV39*1),2)*BS39),2)) -> 0 | CS39: =ROUND((ROUND((AE39*AV39*1),2)*BS39),2) -> 0 | CT39: =ROUND((ROUND((AF39*AV39*1),2)*BA39),2) -> 0 | CU39: =AG39 -> 0 | CV39: =(AH39*AV39) -> 0 | CW39: =AI39 -> 0 | CX39: =AJ39 -> 0 | CY39: =(((S39+R39)*AT39)/100) -> 0 | CZ39: =(((S39+R39)*AU39)/100) -> 0 | DN39: 0 | DO39: 0 | DP39: 1 | DQ39: 1 | DU39: 1010 | DV39: шт. | DW39: шт. | DX39: 1 | EE39: 55992259 | EF39: 130 | EG39: Сметная стоимость оборудования | EH39: 0 | EJ39: 3 | EK39: 746 | EL39: ТСН-2001.13. Сметная стоимость оборудования | EM39: ТСН-2001.13 | EQ39: 0 | ER39: 1618.36 | ES39: 1618.36 | ET39: 0 | EU39: 0 | EV39: 0 | EW39: 0 | EX39: 0 | EY39: 0 | EZ39: 5 | FC39: 1 | FD39: 18 | FF39: 14271.44 | FQ39: 0 | FR39: =P39 -> 12396.64 | FS39: 0 | FX39: 0 | FY39: 0 | GA39: [14 271,44 / 1,2 / 7,66] + 3% Трансп + 1,2% Заг.скл | GD39: 1 | GF39: 493595391 | GG39: 2 | GH39: 3 | GI39: 5 | GJ39: 0 | GK39: 0 | GL39: =ROUND(IF(AND(BH39=3,BI39=3,FS39<>0),P39,0),2) -> 0 | GM39: =ROUND(O39+X39+Y39,2)+GX39 -> 12396.64 | GN39: =IF(OR(BI39=0,BI39=1),GM39-GX39,0) -> 0 | GO39: =IF(BI39=2,GM39-GX39,0) -> 0 | GP39: =IF(BI39=4,GM39-GX39,0) -> 0 | GR39: 1 | GS39: 1 | GT39: 0 | GV39: =ROUND((GT39),6) -> 0 | GW39: 1 | GX39: =ROUND(HC39*I39,2) -> 0 | HA39: 0 | HB39: 0 | HC39: =GV39*GW39 -> 0 | HE39: 3 | HF39: 1,2 | HS39: 0 | IK39: 0
A40: 17 | B40: 1 | C40: =ROW(SmtRes!A26) -> 26 | D40: =ROW(EtalonRes!A31) -> 31 | E40: 6 | F40: 4.10-176-1 | G40: Монтаж блока контроля датчиков (контроллер) | H40: 10 шт. | I40: =ROUND(1/10,9) -> 0.1 | J40: 0 | K40: =ROUND(1/10,9) -> 0.1 | O40: =ROUND(CP40,2) -> 54.5 | P40: =ROUND((ROUND((AC40*AW40*I40),2)*BC40),2) -> 0.13 | Q40: =(ROUND((ROUND((((ET40*1.1))*AV40*I40),2)*BB40),2)+ROUND((ROUND(((AE40-((EU40*1.1)))*AV40*I40),2)*BS40),2)) -> 0.13 | R40: =ROUND((ROUND((AE40*AV40*I40),2)*BS40),2) -> 0.01 | S40: =ROUND((ROUND((AF40*AV40*I40),2)*BA40),2) -> 54.24 | T40: =ROUND(CU40*I40,2) -> 0 | U40: =CV40*I40 -> 3.4504932 | V40: =CW40*I40 -> 0 | W40: =ROUND(CX40*I40,2) -> 0 | X40: =ROUND(CY40,2) -> 48.83 | Y40: =ROUND(CZ40,2) -> 24.96 | AA40: 56959434 | AB40: =ROUND((AC40+AD40+AF40),6) -> 520.534 | AC40: =ROUND((ES40),6) -> 1.29 | AD40: =ROUND(((((ET40*1.1))-((EU40*1.1)))+AE40),6) -> 1.21 | AE40: =ROUND(((EU40*1.1)),6) -> 0.143 | AF40: =ROUND(((EV40*1.1)),6) -> 518.034 | AG40: =ROUND((AP40),6) -> 0 | AH40: =((EW40*1.1)) -> 32.956 | AI40: =((EX40*1.1)) -> 0 | AJ40: =(AS40) -> 0 | AK40: 473.33 | AL40: 1.29 | AM40: 1.1 | AN40: 0.13 | AO40: 470.94 | AP40: 0 | AQ40: 29.96 | AR40: 0 | AS40: 0 | AT40: 90 | AU40: 46 | AV40: 1.047 | AW40: 1 | AZ40: 1 | BA40: 1 | BB40: 1 | BC40: 1 | BH40: 0 | BI40: 2 | BJ40: ТСН-2001.4 Доп. 80, Сб. 10, т. 176, поз. 1 | BM40: 68 | BN40: 55992028 | BO40: 4.10-176-1 | BP40: 1 | BQ40: 40 | BR40: 0 | BS40: 1 | BT40: 1 | BU40: 1 | BV40: 1 | BW40: 1 | BX40: 1 | BZ40: 90 | CA40: 46 | CE40: 30 | CF40: 0 | CG40: 0 | CM40: 0 | CN40: Поправка: Гл.12.Прил.8.п.8. 5_12.00.01.11.003 Наименование: При наличии усложненных условий производства работ (стесненность, сложность складирования и транспортной логистики, наличие в зоне производства работ действующего технологического оборудования или движения технологического транспорта и т.п.) для объектов, расположенных за пределами территории круговой магистральной системы улиц "Садовое кольцо" и за пределами Третьего транспортного кольца города Москвы пунктов "а" и "б", но в пределах Московской кольцевой автомобильной дороги | CO40: 0 | CP40: =(P40+Q40+S40) -> 54.5 | CQ40: =ROUND((ROUND((AC40*AW40*1),2)*BC40),2) -> 1.29 | CR40: =(ROUND((ROUND((((ET40*1.1))*AV40*1),2)*BB40),2)+ROUND((ROUND(((AE40-((EU40*1.1)))*AV40*1),2)*BS40),2)) -> 1.27 | CS40: =ROUND((ROUND((AE40*AV40*1),2)*BS40),2) -> 0.15 | CT40: =ROUND((ROUND((AF40*AV40*1),2)*BA40),2) -> 542.38 | CU40: =AG40 -> 0 | CV40: =(AH40*AV40) -> 34.504932 | CW40: =AI40 -> 0 | CX40: =AJ40 -> 0 | CY40: =(((S40+R40)*AT40)/100) -> 48.825 | CZ40: =(((S40+R40)*AU40)/100) -> 24.955 | DE40: *1,1 | DF40: *1,1 | DG40: *1,1 | DI40: *1,1 | DJ40: *1,1 | DN40: 0 | DO40: 0 | DP40: 1 | DQ40: 1 | DU40: 1010 | DV40: 10 шт. | DW40: 10 шт. | DX40: 10 | EE40: 55992152 | EF40: 40 | EG40: Монтаж оборудования | EH40: 0 | EJ40: 2 | EK40: 68 | EL40: ТСН-2001.4-10. Прокладка и монтаж сетей связи | EM40: ТСН-2001.4-10-1 | EO40: Поправка: Гл.12.Прил.8.п.8. 5_12.00.01.11.003 | EQ40: 0 | ER40: 473.33 | ES40: 1.29 | ET40: 1.1 | EU40: 0.13 | EV40: 470.94 | EW40: 29.96 | EX40: 0 | EY40: 0 | FQ40: 0 | FR40: 0 | FS40: 0 | FX40: 90 | FY40: 46 | GD40: 1 | GF40: -733186695 | GG40: 2 | GH40: 1 | GI40: 2 | GJ40: 0 | GK40: 0 | GL40: =ROUND(IF(AND(BH40=3,BI40=3,FS40<>0),P40,0),2) -> 0 | GM40: =ROUND(O40+X40+Y40,2)+GX40 -> 128.29 | GN40: =IF(OR(BI40=0,BI40=1),GM40-GX40,0) -> 0 | GO40: =IF(BI40=2,GM40-GX40,0) -> 128.29 | GP40: =IF(BI40=4,GM40-GX40,0) -> 0 | GR40: 0 | GS40: 3 | GT40: 0 | GV40: =ROUND((GT40),6) -> 0 | GW40: 1 | GX40: =ROUND(HC40*I40,2) -> 0 | HA40: 0 | HB40: 0 | HC40: =GV40*GW40 -> 0 | HS40: 0 | IK40: 0
