Workbook

Sheet 02-01-05
A1: =Source!B1 -> Smeta.RU (495) 974-1589
J2: Форма № 4б
A3: Капитальный ремонт здания Государственного бюджетного общеобразовательного учреждения города Москвы "Школа № 236" по адресу: г. Москва ул. Клязьминская, д. 7 к. 4. 1 этап. | AP3: Капитальный ремонт здания Государственного бюджетного общеобразовательного учреждения города Москвы "Школа № 236" по адресу: г. Москва ул. Клязьминская, д. 7 к. 4. 1 этап. 02-01-05 Система водоотведения
A4: (наименование стройки и/или объекта)
A6: =CONCATENATE( "ЛОКАЛЬНАЯ СМЕТА № ",IF(Source!F20<>"Новая локальная смета", Source!F20, "")) -> ЛОКАЛЬНАЯ СМЕТА № 02-01-05
A8: =IF(Source!G20<>"Новая локальная смета", Source!G20, "") -> Система водоотведения
A9: (наименование работ и затрат)
A11: =CONCATENATE( "Основание: чертежи № ", Source!J20) -> Основание: чертежи № 2024-00272-00-0-ИОС3
I13: В базисном уровне цен | J13: В текущем уровне цен
E14: Сметная стоимость | I14: =I15+I16+I17+I18 -> 980.89 | J14: =J15+J16+J17+J18 -> 9491.85 | K14: тыс.руб.
E15: Строительные работы | I15: =ROUND((Source!F1032)/1000, 2) -> 905.47 | J15: =ROUND((Source!P1032)/1000, 2) -> 8900.16 | K15: тыс.руб.
E16: Работы по монтажу оборудования | I16: =ROUND((Source!F1033)/1000, 2) -> 0.5 | J16: =ROUND((Source!P1033)/1000, 2) -> 17.83 | K16: тыс.руб.
E17: Оборудование | I17: =ROUND((Source!F1024)/1000, 2) -> 74.92 | J17: =ROUND((Source!P1024)/1000, 2) -> 573.86 | K17: тыс.руб.
E18: Прочие работы и затраты | I18: =ROUND((Source!F1034+Source!F1035)/1000, 2) -> 0 | J18: =ROUND((Source!P1034+Source!P1035)/1000, 2) -> 0 | K18: тыс.руб.
E19: Средства на оплату труда | I19: =(Source!F1030+ Source!F1029)/1000 -> 24.37609 | J19: =((Source!P1030 + Source!P1029)/1000) -> 1340.4412 | K19: тыс.руб.
E20: Затраты труда | I20: =Source!F1037 -> 1922.1302 | K20: чел.-ч.
E21: Кроме того:
E22: Возврат материалов | I22: =SUM(Y28:Y885)/1000 -> 0 | J22: =SUM(Z28:Z885)/1000 -> 0 | K22: тыс.руб.
A24: Составлен(а) по ТСН-2001 с учетом Дополнения №: 80
A25: № и период сборника коэффициентов (индексов) пересчета: Коэффициенты к ТСН-2001 МГЭ Дополнение 80, ремонт №217/80 III квартал 2025 года и Коэффициенты к ТСН-2001.13-2 Дополнение 46 №62/46 III квартал 2025 года | AP25: № и период сборника коэффициентов (индексов) пересчета: Коэффициенты к ТСН-2001 МГЭ Дополнение 80, ремонт №217/80 III квартал 2025 года и Коэффициенты к ТСН-2001.13-2 Дополнение 46 №62/46 III квартал 2025 года
A26: № п/п | B26: Шифр расценки и коды ресурсов | C26: Наименование работ и затрат | D26: Ед. изм. | E26: Кол-во единиц | F26: Цена на ед. изм., руб. | G26: Попра- вочные коэффи- циенты | H26: Коэффи- циенты зимних удорожа- ний | I26: Всего в ценах на январь 2000 года, руб. | J26: Коэффи- циенты (индек- сы) пере- счета, нормы НР и СП | K26: ВСЕГО затрат в текущем уровне цен, руб.
A27: 1 | B27: 2 | C27: 3 | D27: 4 | E27: 5 | F27: 6 | G27: 7 | H27: 8 | I27: 9 | J27: 10 | K27: 11
A29: =CONCATENATE("Раздел: ",IF(Source!G24<>"Новый раздел", Source!G24, "")) -> Раздел: Канализация хозяйственно-бытовая (К1) (подвал)
A31: =CONCATENATE("Подраздел: ",IF(Source!G28<>"Новый подраздел", Source!G28, "")) -> Подраздел: Монтажные работы
A32: 1 | B32: 3.16-36-1 Поправка: О.П. п.3.4. 6 Поправка: О.П. п.3.4.30.в | C32: Прокладка трубопроводов канализации из чугунных безраструбных труб, диаметр 50 мм | D32: =Source!H32 -> 100 м | E32: =Source!I32 -> 0.16 | Q32: =Source!X32 -> 433.5 | R32: =Source!X33 -> 23838.39 | S32: =Source!Y32 -> 242.6 | T32: =Source!Y33 -> 13340.75 | U32: =ROUND((175/100)*ROUND(Source!R32, 2), 2) -> 0.74 | V32: =ROUND((0/100)*ROUND(Source!R33, 2), 2) -> 0 | AC32: 0
C33: ="Объем: "&Source!I32&"=16/"&"100" -> Объем: 0,16=16/100
C34: ЗП | F34: =Source!AO32 -> 1839.65 | G34: =Source!DG32 -> *1,15)*1,1 | H34: =Source!AV33 -> 1.067 | I34: =Source!S32 -> 397.29 | J34: =IF(Source!BA33<> 0, Source!BA33, 1) -> 54.99 | K34: =Source!S33 -> 21846.98
C35: ЭМ | F35: =Source!AM32 -> 21.59 | G35: =Source!DE32 -> *1,25)*1,1 | H35: =Source!AV33 -> 1.067 | I35: =Source!Q32 -> 5.07 | J35: =IF(Source!BB33<> 0, Source!BB33, 1) -> 12.96 | K35: =Source!Q33 -> 65.71
C36: в т.ч. ЗПМ | F36: =Source!AN32 -> 1.77 | G36: =Source!DF32 -> *1,25)*1,1 | H36: =Source!AV33 -> 1.067 | I36: =Source!R32 -> 0.42 | J36: =IF(Source!BS33<> 0, Source!BS33, 1) -> 54.99 | K36: =Source!R33 -> 23.1
C37: МР | F37: =Source!AL32 -> 3.3 | G37: =Source!DD32 | H37: =Source!AW33 -> 1 | I37: =Source!P32 -> 0.53 | J37: =IF(Source!BC33<> 0, Source!BC33, 1) -> 8.95 | K37: =Source!P33 -> 4.74
A38: 1,1 | B38: =Source!F34 -> 1.12-8-74 | C38: Комплект деталей трубопроводов из чугуна с мелкодисперсным графитом с внутренним эпоксидным покрытием, наружным слоем краснокоричневой грунтовки (безраструбные трубы, фасонные части, крепеж), диаметр условного прохода 50 мм | D38: =Source!H34 -> м | E38: =Source!I34 -> 16 | F38: =Source!AK34 -> 1328.86 | H38: =Source!AW35 -> 1 | I38: =Source!O34 -> 21261.76 | J38: =IF(Source!BC35<> 0, Source!BC35, 1) -> 0.95 | K38: =Source!O35 -> 20198.67 | Q38: =Source!X34 -> 0 | R38: =Source!X35 -> 0 | S38: =Source!Y34 -> 0 | T38: =Source!Y35 -> 0 | U38: =ROUND((175/100)*ROUND(Source!R34, 2), 2) -> 0 | V38: =ROUND((0/100)*ROUND(Source!R35, 2), 2) -> 0 | AC38: 3
C39: НР от ФОТ | D39: % | E39: =Source!BZ33 -> 109 | I39: =SUM(Q32:Q38) -> 433.5 | J39: =Source!AT33 -> 109 | K39: =SUM(R32:R38) -> 23838.39
C40: СП от ФОТ | D40: % | E40: =Source!CA33 -> 61 | I40: =SUM(S32:S39) -> 242.6 | J40: =Source!AU33 -> 61 | K40: =SUM(T32:T39) -> 13340.75
C41: ЗТР | D41: чел-ч | E41: =Source!AQ32 -> 142.31 | G41: =Source!DI32 -> *1,15)*1,1 | H41: =Source!AV33 -> 1.067 | I41: =Source!U32 -> 30.733381
C42: Всего по позиции: | H42: =I34+I35+I37+I39+I40+SUM(I38:I38) -> 22340.75 | J42: =K34+K35+K37+K39+K40+SUM(K38:K38) -> 79295.24 | O42: =I34+I35+I37+I39+I40+SUM(I38:I38) -> 22340.75 | P42: =K34+K35+K37+K39+K40+SUM(K38:K38) -> 79295.24
A44: 2 | B44: 3.16-13-2 Поправка: О.П. п.3.4. 6 Поправка: О.П. п.3.4.30.в | C44: Прокладка трубопроводов канализации из ПВХ труб диаметром 100 мм - 150 мм | D44: =Source!H36 -> 100 м | E44: =Source!I36 -> 2.14 | Q44: =Source!X36 -> 2266.59 | R44: =Source!X37 -> 124639.77 | S44: =Source!Y36 -> 1268.46 | T44: =Source!Y37 -> 69752.53 | U44: =ROUND((175/100)*ROUND(Source!R36, 2), 2) -> 15.72 | V44: =ROUND((0/100)*ROUND(Source!R37, 2), 2) -> 0 | AC44: 0
C45: ="Объем: "&Source!I36&"=214/"&"100" -> Объем: 2,14=214/100
C46: ЗП | F46: =Source!AO36 -> 716.8 | G46: =Source!DG36 -> *1,15)*1,1 | H46: =Source!AV37 -> 1.067 | I46: =Source!S36 -> 2070.46 | J46: =IF(Source!BA37<> 0, Source!BA37, 1) -> 54.99 | K46: =Source!S37 -> 113854.6
C47: ЭМ | F47: =Source!AM36 -> 20.2 | G47: =Source!DE36 -> *1,25)*1,1 | H47: =Source!AV37 -> 1.067 | I47: =Source!Q36 -> 63.42 | J47: =IF(Source!BB37<> 0, Source!BB37, 1) -> 15.85 | K47: =Source!Q37 -> 1005.21
C48: в т.ч. ЗПМ | F48: =Source!AN36 -> 2.86 | G48: =Source!DF36 -> *1,25)*1,1 | H48: =Source!AV37 -> 1.067 | I48: =Source!R36 -> 8.98 | J48: =IF(Source!BS37<> 0, Source!BS37, 1) -> 54.99 | K48: =Source!R37 -> 493.81
...

Sheet Ведомость объемов работ
A1: =Source!B1 -> Smeta.RU (495) 974-1589
E3: "УТВЕРЖДАЮ"
D5: ___________________________
D7: ___________________________
D9: " ___ " ___________ 20 ___ г.
B12: =CONCATENATE("Ведомость объемов работ ", IF(Source!AN15<>"", Source!AN15," ")) -> Ведомость объемов работ
B13: =CONCATENATE(Source!F12, " ", Source!G12) -> Новый объект (ТСН-2001 (Мосгосэкспертиза)) 02-01-05 Система водоотведения
A16: № п/п | B16: № в ЛСР | C16: Наименование работ и затрат | D16: Единица измерения | E16: Количество | F16: Ссылка на чертежи, спецификации | G16: Формула расчета, расчет объемов работ и расхода материалов | H16: Примечание
A17: 1 | B17: 2 | C17: 3 | D17: 4 | E17: 5 | F17: 6 | G17: 7 | H17: 8
A18: =CONCATENATE("Локальная смета: ", Source!G20) -> Локальная смета: Система водоотведения
A19: =CONCATENATE("Раздел: ", Source!G24) -> Раздел: Канализация хозяйственно-бытовая (К1) (подвал)
A20: =CONCATENATE("Подраздел: ", Source!G28) -> Подраздел: Монтажные работы
A21: 1 | B21: =Source!E32 -> 1 | C21: =Source!G32 -> Прокладка трубопроводов канализации из чугунных безраструбных труб, диаметр 50 мм | D21: 100 м | E21: =Source!I32 -> 0.16 | F21: =Source!U28 | G21: ="=16/"&"100" -> =16/100
A22: 1.1 | B22: =Source!E34 -> 1,1 | C22: =Source!G34 -> Комплект деталей трубопроводов из чугуна с мелкодисперсным графитом с внутренним эпоксидным покрытием, наружным слоем краснокоричневой грунтовки (безраструбные трубы, фасонные части, крепеж), диаметр условного прохода 50 мм | D22: м | E22: =Source!I34 -> 16 | F22: =Source!U28
A23: 2 | B23: =Source!E36 -> 2 | C23: =Source!G36 -> Прокладка трубопроводов канализации из ПВХ труб диаметром 100 мм - 150 мм | D23: 100 м | E23: =Source!I36 -> 2.14 | F23: =Source!U28 | G23: ="=214/"&"100" -> =214/100
A24: 2.1 | B24: =Source!E38 -> 2,1 | C24: =Source!G38 -> Заготовка трубная из непластифицированного поливинилхлорида, для внутренней канализации, без средств крепления, диаметр 110 мм | D24: м | E24: =Source!I38 -> 214 | F24: =Source!U28
A25: 2.2 | B25: =Source!E40 -> 2,2 | C25: =Source!G40 -> Ревизия из полиэтилена, диаметр 110 мм | D25: шт. | E25: =Source!I40 -> 3 | F25: =Source!U28
A26: 2.3 | B26: =Source!E42 -> 2,3 | C26: =Source!G42 -> Ревизия из полиэтилена, диаметр 110 мм /прочистки | D26: шт. | E26: =Source!I42 -> 18 | F26: =Source!U28
A27: 3 | B27: =Source!E44 -> 3 | C27: =Source!G44 -> Прокладка трубопроводов канализации из ПВХ труб диаметром до 50 мм | D27: 100 м | E27: =Source!I44 -> 0.72 | F27: =Source!U28 | G27: ="=72/"&"100" -> =72/100
A28: 3.1 | B28: =Source!E46 -> 3,1 | C28: =Source!G46 -> Заготовка трубная из непластифицированного поливинилхлорида, для внутренней канализации, без средств крепления, диаметр 50 мм | D28: м | E28: =Source!I46 -> 72 | F28: =Source!U28
A29: 3.2 | B29: =Source!E48 -> 3,2 | C29: =Source!G48 -> Ревизия из полиэтилена низкого давления, с крышкой, для канализации, диаметр 50 мм | D29: шт. | E29: =Source!I48 -> 2 | F29: =Source!U28
A30: 3.3 | B30: =Source!E50 -> 3,3 | C30: =Source!G50 -> Ревизия из полиэтилена низкого давления, с крышкой, для канализации, диаметр 50 мм /прочистка | D30: шт. | E30: =Source!I50 -> 2 | F30: =Source!U28
A31: 4 | B31: =Source!E52 -> 4 | C31: =Source!G52 -> Врезки в действующие внутренние сети трубопроводов канализации диаметром 100 мм | D31: 1 врезка | E31: =Source!I52 -> 3 | F31: =Source!U28 | G31: =Source!I52 -> 3
A32: 5 | B32: =Source!E54 -> 5 | C32: =Source!G54 -> Установка противопожарных муфт на канализационных стояках из полипропиленовых труб в междуэтажных перекрытиях, муфт обжимных | D32: 100 шт. | E32: =Source!I54 -> 0.35 | F32: =Source!U28 | G32: ="=(19+"&"16)/"&"100" -> =(19+16)/100
A33: 5.1 | B33: =Source!E56 -> 5,1 | C33: =Source!G56 -> Муфта противопожарная из нержавеющей стали, с вкладышем из терморасширяющейся резины, для трубы диаметром 110 мм | D33: шт. | E33: =Source!I56 -> 19 | F33: =Source!U28
A34: 5.2 | B34: =Source!E58 -> 5,2 | C34: =Source!G58 -> Муфта противопожарная из нержавеющей стали, с вкладышем из терморасширяющейся резины, для трубы диаметром 50 мм | D34: шт. | E34: =Source!I58 -> 16 | F34: =Source!U28
A35: =CONCATENATE("Раздел: ", Source!G121) -> Раздел: Канализация хозяйственно-бытовая напорная (К1н) (подвал)
A36: =CONCATENATE("Подраздел: ", Source!G125) -> Подраздел: Монтажные работы
A37: 6 | B37: =Source!E129 -> 6 | C37: =Source!G129 -> Прокладка трубопроводов водоснабжения из стальных водогазопроводных оцинкованных труб диаметром 40 мм | D37: 100 м трубопровода | E37: =Source!I129 -> 0.1 | F37: =Source!U125 | G37: ="=10/"&"100" -> =10/100
A38: 6.1 | B38: =Source!E131 -> 6,1 | C38: =Source!G131 -> Хомуты из оцинкованной стали с резиновыми прокладками для жесткого и скользящего крепления полипропиленовых труб, наружный диаметр 32 мм /ф40мм | D38: шт. | E38: =Source!I131 -> 4 | F38: =Source!U125
A39: 6.2 | B39: =Source!E133 -> 6,2 | C39: =Source!G133 -> Кран шаровой, латунный, полнопроходной, муфтовый, 11б27п1, номинальное давление PN 1,6 МПа, номинальный диаметр DN 40 мм | D39: шт. | E39: =Source!I133 -> 1 | F39: =Source!U125
A40: 6.3 | B40: =Source!E135 -> 6,3 | C40: =Source!G135 -> Узел трубопровода из стальных водогазопроводных оцинкованных труб, с гильзами, для водоснабжения, диаметр условного прохода 40 мм | D40: м | E40: =Source!I135 -> 10 | F40: =Source!U125
A41: 7 | B41: =Source!E137 -> 7 | C41: =Source!G137 -> Клапан обратный общего назначения, латунный, с внутренней резьбой, температура до +100°С, номинальное давление PN 1,0 МПа, номинальный диаметр DN 40 мм | D41: шт. | E41: =Source!I137 -> 1 | F41: =Source!U125 | G41: =Source!I137 -> 1
A42: 8 | B42: =Source!E143 -> 8 | C42: =Source!G143 -> Монтаж механизма исполнительного массой до 20 кг | D42: 1 ШТ. | E42: =Source!I143 -> 1 | F42: =Source!U125 | G42: =Source!I143 -> 1
A43: 8.1 | B43: =Source!E145 -> 8,1 | C43: =Source!G145 -> Насосная установка Q=3,75м^3/ч; Н=8,8м; U=1х220В; N=0,6кВт CITILIFT TRIO | D43: шт. | E43: =Source!I145 -> 1 | F43: =Source!U125
A44: 9 | B44: =Source!E151 -> 9 | C44: =Source!G151 -> Прокладка трубопроводов водоснабжения из стальных водогазопроводных оцинкованных труб диаметром 32 мм | D44: 100 м трубопровода | E44: =Source!I151 -> 0.1 | F44: =Source!U125 | G44: ="=10/"&"100" -> =10/100
A45: 9.1 | B45: =Source!E153 -> 9,1 | C45: =Source!G153 -> Хомуты из оцинкованной стали с резиновыми прокладками для жесткого и скользящего крепления полипропиленовых труб, наружный диаметр 32 мм | D45: шт. | E45: =Source!I153 -> 5 | F45: =Source!U125
A46: 9.2 | B46: =Source!E155 -> 9,2 | C46: =Source!G155 -> Кран шаровой, латунный, полнопроходной, муфтовый, 11б27п1, номинальное давление PN 1,6 МПа, номинальный диаметр DN 32 мм | D46: шт. | E46: =Source!I155 -> 1 | F46: =Source!U125
A47: 9.3 | B47: =Source!E157 -> 9,3 | C47: =Source!G157 -> Уголок 90° из полипропилена PP-R тип 3 (PRC-R), ГОСТ 32415-2013, наружный диаметр 32 мм | D47: шт. | E47: =Source!I157 -> 4 | F47: =Source!U125
A48: 9.4 | B48: =Source!E159 -> 9,4 | C48: =Source!G159 -> Муфта из полипропилена PP-R, ГОСТ 32415-2013, комбинированная с металлом, под ключ, номинальное давление PN 25, номинальный диаметр DN 32 мм, наружная резьба 1'' | D48: шт. | E48: =Source!I159 -> 2 | F48: =Source!U125
...

Sheet Source
A1: 0 | B1: Smeta.RU (495) 974-1589 | D1: _PS_ | F1: 0 | G1: 0 | H1: 0 | I1: Smeta.RU | K1: 1 | L1: 74402 | M1: 10 | N1: 12 | O1: 0 | P1: 0 | Q1: 3
A4: 1 | B4: 1 | C4: -1 | G4: Капитальный ремонт здания Государственного бюджетного общеобразовательного учреждения города Москвы "Школа № 236" по адресу: г. Москва ул. Клязьминская, д. 7 к. 4. 1 этап | EC4: 0
A12: 1 | B12: 1086 | C12: 0 | D12: =ROW(A1045) -> 1045 | E12: 0 | F12: Новый объект (ТСН-2001 (Мосгосэкспертиза)) | G12: 02-01-05 Система водоотведения | I12: 0 | K12: 0 | L12: 0 | M12: 4098 | O12: 0 | P12: 0 | Q12: 0 | R12: 0 | S12: 0 | T12: 1 | V12: 0 | AB12: Кузнецова Е.А. | BB12: 0 | BH12: Сметные нормы списания | BI12: Коды ОКП для ТСН-2001 МГЭ Дополнение 80 | BJ12: 1 | BK12: 1 | BL12: 0 | BM12: 0 | BN12: 1 | BO12: 0 | BP12: 6 | BQ12: 2 | BR12: 1 | BS12: 1 | BT12: 0 | BU12: 0 | BV12: 1 | BW12: 0 | BX12: 0 | BZ12: Типовой расчет для ТСН-2001 МГЭ, Дополнение 80, ремонт | CA12: Территориальные сметные нормативы для Москвы ТСН-2001 (МГЭ), дополнение 80 | CB12: Территориальные сметные нормативы для Москвы ТСН-2001 (МГЭ), дополнение 80 | CC12: Территориальные сметные нормативы для Москвы ТСН-2001 (МГЭ), дополнение 80 | CD12: Территориальные сметные нормативы для Москвы ТСН-2001 (МГЭ), дополнение 80 | CE12: Поправки для ТСН-2001 от 03.02.2026 г. доп.80 | CF12: 0 | CG12: 0 | CH12: 327688 | CK12: 81 | CQ12: Территориальные сметные нормативы для Москвы (ТСН-2001) | CR12: ТЕР | CS12: 41660 | CT12: 1 | CU12: 80 | CY12: 0 | EC12: 0
A15: 15 | B15: 1
A18: 52 | B18: =B1045 -> 1086 | C18: =C1045 -> 1 | D18: =D1045 -> 12 | E18: =E1045 -> 0 | F18: =F1045 -> Новый объект (ТСН-2001 (Мосгосэкспертиза)) | G18: =G1045 -> 02-01-05 Система водоотведения | O18: =O1045 -> 940427.69 | P18: =P1045 -> 914640.81 | Q18: =Q1045 -> 1614.26 | R18: =R1045 -> 203.47 | S18: =S1045 -> 24172.62 | T18: =T1045 -> 0 | U18: =U1045 -> 1922.1302 | V18: =V1045 -> 0 | ... GX18: =GX1045 -> 0
A20: 3 | B20: 1 | D20: =ROW(A1015) -> 1015 | F20: 02-01-05 | G20: Система водоотведения | I20: 0 | J20: 2024-00272-00-0-ИОС3 | K20: -1 | L20: 02-01-05 | S20: 0 | T20: 0 | V20: 0 | BX20: 0 | CF20: 0 | CG20: 0
A22: 52 | B22: =B1015 -> 1 | C22: =C1015 -> 3 | D22: =D1015 -> 20 | E22: =E1015 -> 0 | F22: =F1015 -> 02-01-05 | G22: =G1015 -> Система водоотведения | O22: =O1015 -> 940427.69 | P22: =P1015 -> 914640.81 | Q22: =Q1015 -> 1614.26 | R22: =R1015 -> 203.47 | S22: =S1015 -> 24172.62 | T22: =T1015 -> 0 | U22: =U1015 -> 1922.1302 | V22: =V1015 -> 0 | ... GX22: =GX1015 -> 0
A24: 4 | B24: 1 | D24: =ROW(A91) -> 91 | F24: Новый раздел | G24: Канализация хозяйственно-бытовая (К1) (подвал) | I24: 0 | K24: 0 | S24: 0 | T24: 0 | V24: 0 | BX24: 0 | CJ24: 0
A26: 52 | B26: =B91 -> 1 | C26: =C91 -> 4 | D26: =D91 -> 24 | E26: =E91 -> 0 | F26: =F91 -> Новый раздел | G26: =G91 -> Канализация хозяйственно-бытовая (К1) (подвал) | O26: =O91 -> 81961.72 | P26: =P91 -> 78192.99 | Q26: =Q91 -> 82.81 | R26: =R91 -> 11.48 | S26: =S91 -> 3685.92 | T26: =T91 -> 0 | U26: =U91 -> 292.35437 | V26: =V91 -> 0 | ... GX26: =GX91 -> 0
A28: 5 | B28: 1 | D28: =ROW(A61) -> 61 | F28: Новый подраздел | G28: Монтажные работы | I28: 0 | K28: 0 | S28: 0 | T28: 0 | V28: 0 | BX28: 0 | CJ28: 0
A30: 52 | B30: =B61 -> 1 | C30: =C61 -> 5 | D30: =D61 -> 28 | E30: =E61 -> 0 | F30: =F61 -> Новый подраздел | G30: =G61 -> Монтажные работы | O30: =O61 -> 81961.72 | P30: =P61 -> 78192.99 | Q30: =Q61 -> 82.81 | R30: =R61 -> 11.48 | S30: =S61 -> 3685.92 | T30: =T61 -> 0 | U30: =U61 -> 292.35437 | V30: =V61 -> 0 | ... GX30: =GX61 -> 0
A32: 17 | B32: 1 | C32: =ROW(SmtRes!A8) -> 8 | D32: =ROW(EtalonRes!A8) -> 8 | E32: 1 | F32: 3.16-36-1 | G32: Прокладка трубопроводов канализации из чугунных безраструбных труб, диаметр 50 мм | H32: 100 м | I32: =ROUND(ROUND(16/100,4),9) -> 0.16 | J32: 0 | K32: =ROUND(ROUND(16/100,4),9) -> 0.16 | O32: =ROUND(CP32,2) -> 402.89 | P32: =ROUND((ROUND((AC32*AW32*I32),2)*BC32),2) -> 0.53 | Q32: =(ROUND((ROUND(((((ET32*1.25)*1.1))*AV32*I32),2)*BB32),2)+ROUND((ROUND(((AE32-(((EU32*1.25)*1.1)))*AV32*I32),2)*BS32),2)) -> 5.07 | R32: =ROUND((ROUND((AE32*AV32*I32),2)*BS32),2) -> 0.42 | S32: =ROUND((ROUND((AF32*AV32*I32),2)*BA32),2) -> 397.29 | T32: =ROUND(CU32*I32,2) -> 0 | U32: =CV32*I32 -> 30.733381 | V32: =CW32*I32 -> 0 | W32: =ROUND(CX32*I32,2) -> 0 | X32: =ROUND(CY32,2) -> 433.5 | Y32: =ROUND(CZ32,2) -> 242.6 | AA32: 59209203 | AB32: =ROUND((AC32+AD32+AF32),6) -> 2360.1435 | AC32: =ROUND((ES32),6) -> 3.3 | AD32: =ROUND((((((ET32*1.25)*1.1))-(((EU32*1.25)*1.1)))+AE32),6) -> 29.68625 | AE32: =ROUND((((EU32*1.25)*1.1)),6) -> 2.43375 | AF32: =ROUND((((EV32*1.15)*1.1)),6) -> 2327.1573 | AG32: =ROUND((AP32),6) -> 0 | AH32: =(((EW32*1.15)*1.1)) -> 180.02215 | AI32: =(((EX32*1.25)*1.1)) -> 0 | AJ32: =(AS32) -> 0 | AK32: 1864.54 | AL32: 3.3 | AM32: 21.59 | AN32: 1.77 | AO32: 1839.65 | AP32: 0 | AQ32: 142.31 | AR32: 0 | AS32: 0 | AT32: 109 | AU32: 61 | AV32: 1.067 | AW32: 1 | AZ32: 1 | BA32: 1 | BB32: 1 | BC32: 1 | BH32: 0 | BI32: 1 | BJ32: ТСН-2001.3 Доп. 72, Сб. 16, т. 36, поз. 1 | BM32: 21 | BN32: 58807811 | BO32: 3.16-36-1 | BP32: 1 | BQ32: 30 | BR32: 0 | BS32: 1 | BT32: 1 | BU32: 1 | BV32: 1 | BW32: 1 | BX32: 1 | BZ32: 109 | CA32: 61 | CE32: 30 | CF32: 0 | CG32: 0 | CM32: 0 | CN32: Поправка: О.П. п.3.4. 6 Наименование: Выполняемые при ремонте и реконструкции работы аналогичные технологическим процессам, характерным для нового строительства и отсутствующим в сборниках на ремонтно-строительные работы Поправка: О.П. п.3.4.30.в Наименование: При применении территориальных сметных нормативов для города Москвы затраты, учитывающие напряженные и стесненные условия производства работ (стесненность, сложность складирования и транспортной логистики и т.п.), исчисляются с применением коэффициентов к затратам труда и заработной плате рабочих, машинистов, времени эксплуатации машин и механизмов, стоимости эксплуатации машин в размере: для объектов, расположенных за пределами Третьего транспортного кольца города Москвы, но в пределах Московской кольцевой автомобильной дороги | CO32: 0 | CP32: =(P32+Q32+S32) -> 402.89 | CQ32: =ROUND((ROUND((AC32*AW32*1),2)*BC32),2) -> 3.3 | CR32: =(ROUND((ROUND(((((ET32*1.25)*1.1))*AV32*1),2)*BB32),2)+ROUND((ROUND(((AE32-(((EU32*1.25)*1.1)))*AV32*1),2)*BS32),2)) -> 31.68 | CS32: =ROUND((ROUND((AE32*AV32*1),2)*BS32),2) -> 2.6 | CT32: =ROUND((ROUND((AF32*AV32*1),2)*BA32),2) -> 2483.08 | CU32: =AG32 -> 0 | CV32: =(AH32*AV32) -> 192.08363 | CW32: =AI32 -> 0 | CX32: =AJ32 -> 0 | CY32: =(((S32+R32)*AT32)/100) -> 433.5039 | CZ32: =(((S32+R32)*AU32)/100) -> 242.6031 | DB32: 1 | DE32: *1,25)*1,1 | DF32: *1,25)*1,1 | DG32: *1,15)*1,1 | DI32: *1,15)*1,1 | DJ32: *1,25)*1,1 | DN32: 0 | DO32: 0 | DP32: 1 | DQ32: 1 | DU32: 1003 | DV32: 100 м | DW32: 100 м | DX32: 100 | EE32: 58807897 | EF32: 30 | EG32: Строительные работы | EH32: 0 | EJ32: 1 | EK32: 21 | EL32: ТСН-2001.3-16. Трубопроводы внутренние | EM32: ТСН-2001.3-16-1 | EO32: Поправка: О.П. п.3.4. 6 Поправка: О.П. п.3.4.30.в | EQ32: 0 | ER32: 1864.54 | ES32: 3.3 | ET32: 21.59 | EU32: 1.77 | EV32: 1839.65 | EW32: 142.31 | EX32: 0 | EY32: 0 | FQ32: 0 | FR32: 0 | FS32: 0 | FX32: 109 | FY32: 61 | GD32: 1 | GF32: -907190157 | GG32: 2 | GH32: 1 | GI32: 2 | GJ32: 0 | GK32: 0 | GL32: =ROUND(IF(AND(BH32=3,BI32=3,FS32<>0),P32,0),2) -> 0 | GM32: =ROUND(O32+X32+Y32,2)+GX32 -> 1078.99 | GN32: =IF(OR(BI32=0,BI32=1),GM32-GX32,0) -> 1078.99 | GO32: =IF(BI32=2,GM32-GX32,0) -> 0 | GP32: =IF(BI32=4,GM32-GX32,0) -> 0 | GR32: 0 | GS32: 3 | GT32: 0 | GV32: =ROUND((GT32),6) -> 0 | GW32: 1 | GX32: =ROUND(HC32*I32,2) -> 0 | HA32: 0 | HB32: 0 | HC32: =GV32*GW32 -> 0 | HS32: 0 | IK32: 0
A33: 17 | B33: 1 | C33: =ROW(SmtRes!A16) -> 16 | D33: =ROW(EtalonRes!A16) -> 16 | E33: 1 | F33: 3.16-36-1 | G33: Прокладка трубопроводов канализации из чугунных безраструбных труб, диаметр 50 мм | H33: 100 м | I33: =ROUND(ROUND(16/100,4),9) -> 0.16 | J33: 0 | K33: =ROUND(ROUND(16/100,4),9) -> 0.16 | O33: =ROUND(CP33,2) -> 21917.43 | P33: =ROUND((ROUND((AC33*AW33*I33),2)*BC33),2) -> 4.74 | Q33: =(ROUND((ROUND(((((ET33*1.25)*1.1))*AV33*I33),2)*BB33),2)+ROUND((ROUND(((AE33-(((EU33*1.25)*1.1)))*AV33*I33),2)*BS33),2)) -> 65.71 | R33: =ROUND((ROUND((AE33*AV33*I33),2)*BS33),2) -> 23.1 | S33: =ROUND((ROUND((AF33*AV33*I33),2)*BA33),2) -> 21846.98 | T33: =ROUND(CU33*I33,2) -> 0 | U33: =CV33*I33 -> 30.733381 | V33: =CW33*I33 -> 0 | W33: =ROUND(CX33*I33,2) -> 0 | X33: =ROUND(CY33,2) -> 23838.39 | Y33: =ROUND(CZ33,2) -> 13340.75 | AA33: 59209200 | AB33: =ROUND((AC33+AD33+AF33),6) -> 2360.1435 | AC33: =ROUND((ES33),6) -> 3.3 | AD33: =ROUND((((((ET33*1.25)*1.1))-(((EU33*1.25)*1.1)))+AE33),6) -> 29.68625 | AE33: =ROUND((((EU33*1.25)*1.1)),6) -> 2.43375 | AF33: =ROUND((((EV33*1.15)*1.1)),6) -> 2327.1573 | AG33: =ROUND((AP33),6) -> 0 | AH33: =(((EW33*1.15)*1.1)) -> 180.02215 | AI33: =(((EX33*1.25)*1.1)) -> 0 | AJ33: =(AS33) -> 0 | AK33: 1864.54 | AL33: 3.3 | AM33: 21.59 | AN33: 1.77 | AO33: 1839.65 | AP33: 0 | AQ33: 142.31 | AR33: 0 | AS33: 0 | AT33: 109 | AU33: 61 | AV33: 1.067 | AW33: 1 | AZ33: 1 | BA33: 54.99 | BB33: 12.96 | BC33: 8.95 | BH33: 0 | BI33: 1 | BJ33: ТСН-2001.3 Доп. 72, Сб. 16, т. 36, поз. 1 | BM33: 21 | BN33: 58807811 | BO33: 3.16-36-1 | BP33: 1 | BQ33: 30 | BR33: 0 | BS33: 54.99 | BT33: 1 | BU33: 1 | BV33: 1 | BW33: 1 | BX33: 1 | BZ33: 109 | CA33: 61 | CE33: 30 | CF33: 0 | CG33: 0 | CM33: 0 | CN33: Поправка: О.П. п.3.4. 6 Наименование: Выполняемые при ремонте и реконструкции работы аналогичные технологическим процессам, характерным для нового строительства и отсутствующим в сборниках на ремонтно-строительные работы Поправка: О.П. п.3.4.30.в Наименование: При применении территориальных сметных нормативов для города Москвы затраты, учитывающие напряженные и стесненные условия производства работ (стесненность, сложность складирования и транспортной логистики и т.п.), исчисляются с применением коэффициентов к затратам труда и заработной плате рабочих, машинистов, времени эксплуатации машин и механизмов, стоимости эксплуатации машин в размере: для объектов, расположенных за пределами Третьего транспортного кольца города Москвы, но в пределах Московской кольцевой автомобильной дороги | CO33: 0 | CP33: =(P33+Q33+S33) -> 21917.43 | CQ33: =ROUND((ROUND((AC33*AW33*1),2)*BC33),2) -> 29.54 | CR33: =(ROUND((ROUND(((((ET33*1.25)*1.1))*AV33*1),2)*BB33),2)+ROUND((ROUND(((AE33-(((EU33*1.25)*1.1)))*AV33*1),2)*BS33),2)) -> 410.57 | CS33: =ROUND((ROUND((AE33*AV33*1),2)*BS33),2) -> 142.97 | CT33: =ROUND((ROUND((AF33*AV33*1),2)*BA33),2) -> 136544.57 | CU33: =AG33 -> 0 | CV33: =(AH33*AV33) -> 192.08363 | CW33: =AI33 -> 0 | CX33: =AJ33 -> 0 | CY33: =(((S33+R33)*AT33)/100) -> 23838.387 | CZ33: =(((S33+R33)*AU33)/100) -> 13340.749 | DB33: 3 | DE33: *1,25)*1,1 | DF33: *1,25)*1,1 | DG33: *1,15)*1,1 | DI33: *1,15)*1,1 | DJ33: *1,25)*1,1 | DN33: 0 | DO33: 0 | DP33: 1 | DQ33: 1 | DU33: 1003 | DV33: 100 м | DW33: 100 м | DX33: 100 | EE33: 58807897 | EF33: 30 | EG33: Строительные работы | EH33: 0 | EJ33: 1 | EK33: 21 | EL33: ТСН-2001.3-16. Трубопроводы внутренние | EM33: ТСН-2001.3-16-1 | EO33: Поправка: О.П. п.3.4. 6 Поправка: О.П. п.3.4.30.в | EQ33: 0 | ER33: 1864.54 | ES33: 3.3 | ET33: 21.59 | EU33: 1.77 | EV33: 1839.65 | EW33: 142.31 | EX33: 0 | EY33: 0 | FQ33: 0 | FR33: 0 | FS33: 0 | FX33: 109 | FY33: 61 | GD33: 1 | GF33: -907190157 | GG33: 2 | GH33: 1 | GI33: 2 | GJ33: 0 | GK33: 0 | GL33: =ROUND(IF(AND(BH33=3,BI33=3,FS33<>0),P33,0),2) -> 0 | GM33: =ROUND(O33+X33+Y33,2)+GX33 -> 59096.57 | GN33: =IF(OR(BI33=0,BI33=1),GM33-GX33,0) -> 59096.57 | GO33: =IF(BI33=2,GM33-GX33,0) -> 0 | GP33: =IF(BI33=4,GM33-GX33,0) -> 0 | GR33: 0 | GS33: 3 | GT33: 0 | GV33: =ROUND((GT33),6) -> 0 | GW33: 1 | GX33: =ROUND(HC33*I33,2) -> 0 | HA33: 0 | HB33: 0 | HC33: =GV33*GW33 -> 0 | HS33: 0 | IK33: 0
A34: 18 | B34: 1 | C34: 8 | E34: 1,1 | F34: 1.12-8-74 | G34: Комплект деталей трубопроводов из чугуна с мелкодисперсным графитом с внутренним эпоксидным покрытием, наружным слоем краснокоричневой грунтовки (безраструбные трубы, фасонные части, крепеж), диаметр условного прохода 50 мм | H34: м | I34: =I32*J34 -> 16 | J34: 100 | K34: 100 | O34: =ROUND(CP34,2) -> 21261.76 | P34: =ROUND((ROUND((AC34*AW34*I34),2)*BC34),2) -> 21261.76 | Q34: =(ROUND((ROUND(((ET34)*AV34*I34),2)*BB34),2)+ROUND((ROUND(((AE34-(EU34))*AV34*I34),2)*BS34),2)) -> 0 | R34: =ROUND((ROUND((AE34*AV34*I34),2)*BS34),2) -> 0 | S34: =ROUND((ROUND((AF34*AV34*I34),2)*BA34),2) -> 0 | T34: =ROUND(CU34*I34,2) -> 0 | U34: =CV34*I34 -> 0 | V34: =CW34*I34 -> 0 | W34: =ROUND(CX34*I34,2) -> 0 | X34: =ROUND(CY34,2) -> 0 | Y34: =ROUND(CZ34,2) -> 0 | AA34: 59209203 | AB34: =ROUND((AC34+AD34+AF34),6) -> 1328.86 | AC34: =ROUND((ES34),6) -> 1328.86 | AD34: =ROUND((((ET34)-(EU34))+AE34),6) -> 0 | AE34: =ROUND((EU34),6) -> 0 | AF34: =ROUND((EV34),6) -> 0 | AG34: =ROUND((AP34),6) -> 0 | AH34: =(EW34) -> 0 | AI34: =(EX34) -> 0 | AJ34: =(AS34) -> 0 | AK34: 1328.86 | AL34: 1328.86 | AM34: 0 | AN34: 0 | AO34: 0 | AP34: 0 | AQ34: 0 | AR34: 0 | AS34: 0 | AT34: 109 | AU34: 61 | AV34: 1 | AW34: 1 | AZ34: 1 | BA34: 1 | BB34: 1 | BC34: 1 | BH34: 3 | BI34: 1 | BJ34: ТСН-2001.1 Доп. 79, Р. 12, о. 8, поз. 74 | BM34: 21 | BN34: 58807811 | BP34: 0 | BQ34: 30 | BR34: 0 | BS34: 1 | BT34: 1 | BU34: 1 | BV34: 1 | BW34: 1 | BX34: 1 | BZ34: 109 | CA34: 61 | CE34: 30 | CF34: 0 | CG34: 0 | CM34: 0 | CO34: 0 | CP34: =(P34+Q34+S34) -> 21261.76 | CQ34: =ROUND((ROUND((AC34*AW34*1),2)*BC34),2) -> 1328.86 | CR34: =(ROUND((ROUND(((ET34)*AV34*1),2)*BB34),2)+ROUND((ROUND(((AE34-(EU34))*AV34*1),2)*BS34),2)) -> 0 | CS34: =ROUND((ROUND((AE34*AV34*1),2)*BS34),2) -> 0 | CT34: =ROUND((ROUND((AF34*AV34*1),2)*BA34),2) -> 0 | CU34: =AG34 -> 0 | CV34: =(AH34*AV34) -> 0 | CW34: =AI34 -> 0 | CX34: =AJ34 -> 0 | CY34: =(((S34+R34)*AT34)/100) -> 0 | CZ34: =(((S34+R34)*AU34)/100) -> 0 | DN34: 0 | DO34: 0 | DP34: 1 | DQ34: 1 | DU34: 1003 | DV34: м | DW34: м | DX34: 1 | EE34: 58807897 | EF34: 30 | EG34: Строительные работы | EH34: 0 | EJ34: 1 | EK34: 21 | EL34: ТСН-2001.3-16. Трубопроводы внутренние | EM34: ТСН-2001.3-16-1 | EQ34: 0 | ER34: 1328.86 | ES34: 1328.86 | ET34: 0 | EU34: 0 | EV34: 0 | EW34: 0 | EX34: 0 | FQ34: 0 | FR34: 0 | FS34: 0 | FX34: 109 | FY34: 61 | GD34: 1 | GF34: 925110201 | GG34: 2 | GH34: 1 | GI34: -2 | GJ34: 0 | GK34: 0 | GL34: =ROUND(IF(AND(BH34=3,BI34=3,FS34<>0),P34,0),2) -> 0 | GM34: =ROUND(O34+X34+Y34,2)+GX34 -> 21261.76 | GN34: =IF(OR(BI34=0,BI34=1),GM34-GX34,0) -> 21261.76 | GO34: =IF(BI34=2,GM34-GX34,0) -> 0 | GP34: =IF(BI34=4,GM34-GX34,0) -> 0 | GR34: 0 | GS34: 3 | GT34: 0 | GV34: =ROUND((GT34),6) -> 0 | GW34: 1 | GX34: =ROUND(HC34*I34,2) -> 0 | HA34: 0 | HB34: 0 | HC34: =GV34*GW34 -> 0 | HS34: 0 | IK34: 0
A35: 18 | B35: 1 | C35: 16 | E35: 1,1 | F35: 1.12-8-74 | G35: Комплект деталей трубопроводов из чугуна с мелкодисперсным графитом с внутренним эпоксидным покрытием, наружным слоем краснокоричневой грунтовки (безраструбные трубы, фасонные части, крепеж), диаметр условного прохода 50 мм | H35: м | I35: =I33*J35 -> 16 | J35: 100 | K35: 100 | O35: =ROUND(CP35,2) -> 20198.67 | P35: =ROUND((ROUND((AC35*AW35*I35),2)*BC35),2) -> 20198.67 | Q35: =(ROUND((ROUND(((ET35)*AV35*I35),2)*BB35),2)+ROUND((ROUND(((AE35-(EU35))*AV35*I35),2)*BS35),2)) -> 0 | R35: =ROUND((ROUND((AE35*AV35*I35),2)*BS35),2) -> 0 | S35: =ROUND((ROUND((AF35*AV35*I35),2)*BA35),2) -> 0 | T35: =ROUND(CU35*I35,2) -> 0 | U35: =CV35*I35 -> 0 | V35: =CW35*I35 -> 0 | W35: =ROUND(CX35*I35,2) -> 0 | X35: =ROUND(CY35,2) -> 0 | Y35: =ROUND(CZ35,2) -> 0 | AA35: 59209200 | AB35: =ROUND((AC35+AD35+AF35),6) -> 1328.86 | AC35: =ROUND((ES35),6) -> 1328.86 | AD35: =ROUND((((ET35)-(EU35))+AE35),6) -> 0 | AE35: =ROUND((EU35),6) -> 0 | AF35: =ROUND((EV35),6) -> 0 | AG35: =ROUND((AP35),6) -> 0 | AH35: =(EW35) -> 0 | AI35: =(EX35) -> 0 | AJ35: =(AS35) -> 0 | AK35: 1328.86 | AL35: 1328.86 | AM35: 0 | AN35: 0 | AO35: 0 | AP35: 0 | AQ35: 0 | AR35: 0 | AS35: 0 | AT35: 109 | AU35: 61 | AV35: 1 | AW35: 1 | AZ35: 1 | BA35: 1 | BB35: 1 | BC35: 0.95 | BH35: 3 | BI35: 1 | BJ35: ТСН-2001.1 Доп. 79, Р. 12, о. 8, поз. 74 | BM35: 21 | BN35: 58807811 | BO35: 1.12-8-74 | BP35: 1 | BQ35: 30 | BR35: 0 | BS35: 1 | BT35: 1 | BU35: 1 | BV35: 1 | BW35: 1 | BX35: 1 | BZ35: 109 | CA35: 61 | CE35: 30 | CF35: 0 | CG35: 0 | CM35: 0 | CO35: 0 | CP35: =(P35+Q35+S35) -> 20198.67 | CQ35: =ROUND((ROUND((AC35*AW35*1),2)*BC35),2) -> 1262.42 | CR35: =(ROUND((ROUND(((ET35)*AV35*1),2)*BB35),2)+ROUND((ROUND(((AE35-(EU35))*AV35*1),2)*BS35),2)) -> 0 | CS35: =ROUND((ROUND((AE35*AV35*1),2)*BS35),2) -> 0 | CT35: =ROUND((ROUND((AF35*AV35*1),2)*BA35),2) -> 0 | CU35: =AG35 -> 0 | CV35: =(AH35*AV35) -> 0 | CW35: =AI35 -> 0 | CX35: =AJ35 -> 0 | CY35: =(((S35+R35)*AT35)/100) -> 0 | CZ35: =(((S35+R35)*AU35)/100) -> 0 | DN35: 0 | DO35: 0 | DP35: 1 | DQ35: 1 | DU35: 1003 | DV35: м | DW35: м | DX35: 1 | EE35: 58807897 | EF35: 30 | EG35: Строительные работы | EH35: 0 | EJ35: 1 | EK35: 21 | EL35: ТСН-2001.3-16. Трубопроводы внутренние | EM35: ТСН-2001.3-16-1 | EQ35: 0 | ER35: 1328.86 | ES35: 1328.86 | ET35: 0 | EU35: 0 | EV35: 0 | EW35: 0 | EX35: 0 | FQ35: 0 | FR35: 0 | FS35: 0 | FX35: 109 | FY35: 61 | GD35: 1 | GF35: 925110201 | GG35: 2 | GH35: 1 | GI35: 2 | GJ35: 0 | GK35: 0 | GL35: =ROUND(IF(AND(BH35=3,BI35=3,FS35<>0),P35,0),2) -> 0 | GM35: =ROUND(O35+X35+Y35,2)+GX35 -> 20198.67 | GN35: =IF(OR(BI35=0,BI35=1),GM35-GX35,0) -> 20198.67 | GO35: =IF(BI35=2,GM35-GX35,0) -> 0 | GP35: =IF(BI35=4,GM35-GX35,0) -> 0 | GR35: 0 | GS35: 3 | GT35: 0 | GV35: =ROUND((GT35),6) -> 0 | GW35: 1 | GX35: =ROUND(HC35*I35,2) -> 0 | HA35: 0 | HB35: 0 | HC35: =GV35*GW35 -> 0 | HS35: 0 | IK35: 0
A36: 17 | B36: 1 | C36: =ROW(SmtRes!A25) -> 25 | D36: =ROW(EtalonRes!A25) -> 25 | E36: 2 | F36: 3.16-13-2 | G36: Прокладка трубопроводов канализации из ПВХ труб диаметром 100 мм - 150 мм | H36: 100 м | I36: =ROUND(ROUND(214/100,4),9) -> 2.14 | J36: 0 | K36: =ROUND(ROUND(214/100,4),9) -> 2.14 | O36: =ROUND(CP36,2) -> 2629.74 | P36: =ROUND((ROUND((AC36*AW36*I36),2)*BC36),2) -> 495.86 | Q36: =(ROUND((ROUND(((((ET36*1.25)*1.1))*AV36*I36),2)*BB36),2)+ROUND((ROUND(((AE36-(((EU36*1.25)*1.1)))*AV36*I36),2)*BS36),2)) -> 63.42 | R36: =ROUND((ROUND((AE36*AV36*I36),2)*BS36),2) -> 8.98 | S36: =ROUND((ROUND((AF36*AV36*I36),2)*BA36),2) -> 2070.46 | T36: =ROUND(CU36*I36,2) -> 0 | U36: =CV36*I36 -> 161.75464 | V36: =CW36*I36 -> 0 | W36: =ROUND(CX36*I36,2) -> 0 | X36: =ROUND(CY36,2) -> 2266.59 | Y36: =ROUND(CZ36,2) -> 1268.46 | AA36: 59209203 | AB36: =ROUND((AC36+AD36+AF36),6) -> 1166.237 | AC36: =ROUND((ES36),6) -> 231.71 | AD36: =ROUND((((((ET36*1.25)*1.1))-(((EU36*1.25)*1.1)))+AE36),6) -> 27.775 | AE36: =ROUND((((EU36*1.25)*1.1)),6) -> 3.9325 | AF36: =ROUND((((EV36*1.15)*1.1)),6) -> 906.752 | AG36: =ROUND((AP36),6) -> 0 | AH36: =(((EW36*1.15)*1.1)) -> 70.84 | AI36: =(((EX36*1.25)*1.1)) -> 0 | AJ36: =(AS36) -> 0 | AK36: 968.71 | AL36: 231.71 | AM36: 20.2 | AN36: 2.86 | AO36: 716.8 | AP36: 0 | AQ36: 56 | AR36: 0 | AS36: 0 | AT36: 109 | AU36: 61 | AV36: 1.067 | AW36: 1 | AZ36: 1 | BA36: 1 | BB36: 1 | BC36: 1 | BH36: 0 | BI36: 1 | BJ36: ТСН-2001.3 Доп. 79, Сб. 16, т. 13, поз. 2 | BM36: 21 | BN36: 58807811 | BO36: 3.16-13-2 | BP36: 1 | BQ36: 30 | BR36: 0 | BS36: 1 | BT36: 1 | BU36: 1 | BV36: 1 | BW36: 1 | BX36: 1 | BZ36: 109 | CA36: 61 | CE36: 30 | CF36: 0 | CG36: 0 | CM36: 0 | CN36: Поправка: О.П. п.3.4. 6 Наименование: Выполняемые при ремонте и реконструкции работы аналогичные технологическим процессам, характерным для нового строительства и отсутствующим в сборниках на ремонтно-строительные работы Поправка: О.П. п.3.4.30.в Наименование: При применении территориальных сметных нормативов для города Москвы затраты, учитывающие напряженные и стесненные условия производства работ (стесненность, сложность складирования и транспортной логистики и т.п.), исчисляются с применением коэффициентов к затратам труда и заработной плате рабочих, машинистов, времени эксплуатации машин и механизмов, стоимости эксплуатации машин в размере: для объектов, расположенных за пределами Третьего транспортного кольца города Москвы, но в пределах Московской кольцевой автомобильной дороги | CO36: 0 | CP36: =(P36+Q36+S36) -> 2629.74 | CQ36: =ROUND((ROUND((AC36*AW36*1),2)*BC36),2) -> 231.71 | CR36: =(ROUND((ROUND(((((ET36*1.25)*1.1))*AV36*1),2)*BB36),2)+ROUND((ROUND(((AE36-(((EU36*1.25)*1.1)))*AV36*1),2)*BS36),2)) -> 29.64 | CS36: =ROUND((ROUND((AE36*AV36*1),2)*BS36),2) -> 4.2 | CT36: =ROUND((ROUND((AF36*AV36*1),2)*BA36),2) -> 967.5 | CU36: =AG36 -> 0 | CV36: =(AH36*AV36) -> 75.58628 | CW36: =AI36 -> 0 | CX36: =AJ36 -> 0 | CY36: =(((S36+R36)*AT36)/100) -> 2266.5896 | CZ36: =(((S36+R36)*AU36)/100) -> 1268.4584 | DB36: 5 | DE36: *1,25)*1,1 | DF36: *1,25)*1,1 | DG36: *1,15)*1,1 | DI36: *1,15)*1,1 | DJ36: *1,25)*1,1 | DN36: 0 | DO36: 0 | DP36: 1 | DQ36: 1 | DU36: 1003 | DV36: 100 м | DW36: 100 м | DX36: 100 | EE36: 58807897 | EF36: 30 | EG36: Строительные работы | EH36: 0 | EJ36: 1 | EK36: 21 | EL36: ТСН-2001.3-16. Трубопроводы внутренние | EM36: ТСН-2001.3-16-1 | EO36: Поправка: О.П. п.3.4. 6 Поправка: О.П. п.3.4.30.в | EQ36: 0 | ER36: 968.71 | ES36: 231.71 | ET36: 20.2 | EU36: 2.86 | EV36: 716.8 | EW36: 56 | EX36: 0 | EY36: 0 | FQ36: 0 | FR36: 0 | FS36: 0 | FX36: 109 | FY36: 61 | GD36: 1 | GF36: 974562283 | GG36: 2 | GH36: 1 | GI36: 2 | GJ36: 0 | GK36: 0 | GL36: =ROUND(IF(AND(BH36=3,BI36=3,FS36<>0),P36,0),2) -> 0 | GM36: =ROUND(O36+X36+Y36,2)+GX36 -> 6164.79 | GN36: =IF(OR(BI36=0,BI36=1),GM36-GX36,0) -> 6164.79 | GO36: =IF(BI36=2,GM36-GX36,0) -> 0 | GP36: =IF(BI36=4,GM36-GX36,0) -> 0 | GR36: 0 | GS36: 3 | GT36: 0 | GV36: =ROUND((GT36),6) -> 0 | GW36: 1 | GX36: =ROUND(HC36*I36,2) -> 0 | HA36: 0 | HB36: 0 | HC36: =GV36*GW36 -> 0 | HS36: 0 | IK36: 0
A37: 17 | B37: 1 | C37: =ROW(SmtRes!A34) -> 34 | D37: =ROW(EtalonRes!A34) -> 34 | E37: 2 | F37: 3.16-13-2 | G37: Прокладка трубопроводов канализации из ПВХ труб диаметром 100 мм - 150 мм | H37: 100 м | I37: =ROUND(ROUND(214/100,4),9) -> 2.14 | J37: 0 | K37: =ROUND(ROUND(214/100,4),9) -> 2.14 | O37: =ROUND(CP37,2) -> 122887.78 | P37: =ROUND((ROUND((AC37*AW37*I37),2)*BC37),2) -> 8027.97 | Q37: =(ROUND((ROUND(((((ET37*1.25)*1.1))*AV37*I37),2)*BB37),2)+ROUND((ROUND(((AE37-(((EU37*1.25)*1.1)))*AV37*I37),2)*BS37),2)) -> 1005.21 | R37: =ROUND((ROUND((AE37*AV37*I37),2)*BS37),2) -> 493.81 | S37: =ROUND((ROUND((AF37*AV37*I37),2)*BA37),2) -> 113854.6 | T37: =ROUND(CU37*I37,2) -> 0 | U37: =CV37*I37 -> 161.75464 | V37: =CW37*I37 -> 0 | W37: =ROUND(CX37*I37,2) -> 0 | X37: =ROUND(CY37,2) -> 124639.77 | Y37: =ROUND(CZ37,2) -> 69752.53 | AA37: 59209200 | AB37: =ROUND((AC37+AD37+AF37),6) -> 1166.237 | AC37: =ROUND((ES37),6) -> 231.71 | AD37: =ROUND((((((ET37*1.25)*1.1))-(((EU37*1.25)*1.1)))+AE37),6) -> 27.775 | AE37: =ROUND((((EU37*1.25)*1.1)),6) -> 3.9325 | AF37: =ROUND((((EV37*1.15)*1.1)),6) -> 906.752 | AG37: =ROUND((AP37),6) -> 0 | AH37: =(((EW37*1.15)*1.1)) -> 70.84 | AI37: =(((EX37*1.25)*1.1)) -> 0 | AJ37: =(AS37) -> 0 | AK37: 968.71 | AL37: 231.71 | AM37: 20.2 | AN37: 2.86 | AO37: 716.8 | AP37: 0 | AQ37: 56 | AR37: 0 | AS37: 0 | AT37: 109 | AU37: 61 | AV37: 1.067 | AW37: 1 | AZ37: 1 | BA37: 54.99 | BB37: 15.85 | BC37: 16.19 | BH37: 0 | BI37: 1 | BJ37: ТСН-2001.3 Доп. 79, Сб. 16, т. 13, поз. 2 | BM37: 21 | BN37: 58807811 | BO37: 3.16-13-2 | BP37: 1 | BQ37: 30 | BR37: 0 | BS37: 54.99 | BT37: 1 | BU37: 1 | BV37: 1 | BW37: 1 | BX37: 1 | BZ37: 109 | CA37: 61 | CE37: 30 | CF37: 0 | CG37: 0 | CM37: 0 | CN37: Поправка: О.П. п.3.4. 6 Наименование: Выполняемые при ремонте и реконструкции работы аналогичные технологическим процессам, характерным для нового строительства и отсутствующим в сборниках на ремонтно-строительные работы Поправка: О.П. п.3.4.30.в Наименование: При применении территориальных сметных нормативов для города Москвы затраты, учитывающие напряженные и стесненные условия производства работ (стесненность, сложность складирования и транспортной логистики и т.п.), исчисляются с применением коэффициентов к затратам труда и заработной плате рабочих, машинистов, времени эксплуатации машин и механизмов, стоимости эксплуатации машин в размере: для объектов, расположенных за пределами Третьего транспортного кольца города Москвы, но в пределах Московской кольцевой автомобильной дороги | CO37: 0 | CP37: =(P37+Q37+S37) -> 122887.78 | CQ37: =ROUND((ROUND((AC37*AW37*1),2)*BC37),2) -> 3751.38 | CR37: =(ROUND((ROUND(((((ET37*1.25)*1.1))*AV37*1),2)*BB37),2)+ROUND((ROUND(((AE37-(((EU37*1.25)*1.1)))*AV37*1),2)*BS37),2)) -> 469.79 | CS37: =ROUND((ROUND((AE37*AV37*1),2)*BS37),2) -> 230.96 | CT37: =ROUND((ROUND((AF37*AV37*1),2)*BA37),2) -> 53202.83 | CU37: =AG37 -> 0 | CV37: =(AH37*AV37) -> 75.58628 | CW37: =AI37 -> 0 | CX37: =AJ37 -> 0 | CY37: =(((S37+R37)*AT37)/100) -> 124639.77 | CZ37: =(((S37+R37)*AU37)/100) -> 69752.53 | DB37: 7 | DE37: *1,25)*1,1 | DF37: *1,25)*1,1 | DG37: *1,15)*1,1 | DI37: *1,15)*1,1 | DJ37: *1,25)*1,1 | DN37: 0 | DO37: 0 | DP37: 1 | DQ37: 1 | DU37: 1003 | DV37: 100 м | DW37: 100 м | DX37: 100 | EE37: 58807897 | EF37: 30 | EG37: Строительные работы | EH37: 0 | EJ37: 1 | EK37: 21 | EL37: ТСН-2001.3-16. Трубопроводы внутренние | EM37: ТСН-2001.3-16-1 | EO37: Поправка: О.П. п.3.4. 6 Поправка: О.П. п.3.4.30.в | EQ37: 0 | ER37: 968.71 | ES37: 231.71 | ET37: 20.2 | EU37: 2.86 | EV37: 716.8 | EW37: 56 | EX37: 0 | EY37: 0 | FQ37: 0 | FR37: 0 | FS37: 0 | FX37: 109 | FY37: 61 | GD37: 1 | GF37: 974562283 | GG37: 2 | GH37: 1 | GI37: 2 | GJ37: 0 | GK37: 0 | GL37: =ROUND(IF(AND(BH37=3,BI37=3,FS37<>0),P37,0),2) -> 0 | GM37: =ROUND(O37+X37+Y37,2)+GX37 -> 317280.08 | GN37: =IF(OR(BI37=0,BI37=1),GM37-GX37,0) -> 317280.08 | GO37: =IF(BI37=2,GM37-GX37,0) -> 0 | GP37: =IF(BI37=4,GM37-GX37,0) -> 0 | GR37: 0 | GS37: 3 | GT37: 0 | GV37: =ROUND((GT37),6) -> 0 | GW37: 1 | GX37: =ROUND(HC37*I37,2) -> 0 | HA37: 0 | HB37: 0 | HC37: =GV37*GW37 -> 0 | HS37: 0 | IK37: 0
A38: 18 | B38: 1 | C38: 22 | E38: 2,1 | F38: 1.12-1-80 | G38: Заготовка трубная из непластифицированного поливинилхлорида, для внутренней канализации, без средств крепления, диаметр 110 мм | H38: м | I38: =I36*J38 -> 214 | J38: 100 | K38: 100 | O38: =ROUND(CP38,2) -> 38353.08 | P38: =ROUND((ROUND((AC38*AW38*I38),2)*BC38),2) -> 38353.08 | Q38: =(ROUND((ROUND(((ET38)*AV38*I38),2)*BB38),2)+ROUND((ROUND(((AE38-(EU38))*AV38*I38),2)*BS38),2)) -> 0 | R38: =ROUND((ROUND((AE38*AV38*I38),2)*BS38),2) -> 0 | S38: =ROUND((ROUND((AF38*AV38*I38),2)*BA38),2) -> 0 | T38: =ROUND(CU38*I38,2) -> 0 | U38: =CV38*I38 -> 0 | V38: =CW38*I38 -> 0 | W38: =ROUND(CX38*I38,2) -> 0 | X38: =ROUND(CY38,2) -> 0 | Y38: =ROUND(CZ38,2) -> 0 | AA38: 59209203 | AB38: =ROUND((AC38+AD38+AF38),6) -> 179.22 | AC38: =ROUND((ES38),6) -> 179.22 | AD38: =ROUND((((ET38)-(EU38))+AE38),6) -> 0 | AE38: =ROUND((EU38),6) -> 0 | AF38: =ROUND((EV38),6) -> 0 | AG38: =ROUND((AP38),6) -> 0 | AH38: =(EW38) -> 0 | AI38: =(EX38) -> 0 | AJ38: =(AS38) -> 0 | AK38: 179.22 | AL38: 179.22 | AM38: 0 | AN38: 0 | AO38: 0 | AP38: 0 | AQ38: 0 | AR38: 0 | AS38: 0 | AT38: 109 | AU38: 61 | AV38: 1 | AW38: 1 | AZ38: 1 | BA38: 1 | BB38: 1 | BC38: 1 | BH38: 3 | BI38: 1 | BJ38: ТСН-2001.1 Доп. 79, Р. 12, о. 1, поз. 80 | BM38: 21 | BN38: 0 | BP38: 0 | BQ38: 30 | BR38: 0 | BS38: 1 | BT38: 1 | BU38: 1 | BV38: 1 | BW38: 1 | BX38: 1 | BZ38: 109 | CA38: 61 | CE38: 30 | CF38: 0 | CG38: 0 | CM38: 0 | CO38: 0 | CP38: =(P38+Q38+S38) -> 38353.08 | CQ38: =ROUND((ROUND((AC38*AW38*1),2)*BC38),2) -> 179.22 | CR38: =(ROUND((ROUND(((ET38)*AV38*1),2)*BB38),2)+ROUND((ROUND(((AE38-(EU38))*AV38*1),2)*BS38),2)) -> 0 | CS38: =ROUND((ROUND((AE38*AV38*1),2)*BS38),2) -> 0 | CT38: =ROUND((ROUND((AF38*AV38*1),2)*BA38),2) -> 0 | CU38: =AG38 -> 0 | CV38: =(AH38*AV38) -> 0 | CW38: =AI38 -> 0 | CX38: =AJ38 -> 0 | CY38: =(((S38+R38)*AT38)/100) -> 0 | CZ38: =(((S38+R38)*AU38)/100) -> 0 | DN38: 0 | DO38: 0 | DP38: 1 | DQ38: 1 | DU38: 1003 | DV38: м | DW38: м | DX38: 1 | EE38: 58807897 | EF38: 30 | EG38: Строительные работы | EH38: 0 | EJ38: 1 | EK38: 21 | EL38: ТСН-2001.3-16. Трубопроводы внутренние | EM38: ТСН-2001.3-16-1 | EQ38: 0 | ER38: 179.22 | ES38: 179.22 | ET38: 0 | EU38: 0 | EV38: 0 | EW38: 0 | EX38: 0 | FQ38: 0 | FR38: 0 | FS38: 0 | FX38: 109 | FY38: 61 | GD38: 1 | GF38: 1873563531 | GG38: 2 | GH38: 1 | GI38: -2 | GJ38: 0 | GK38: 0 | GL38: =ROUND(IF(AND(BH38=3,BI38=3,FS38<>0),P38,0),2) -> 0 | GM38: =ROUND(O38+X38+Y38,2)+GX38 -> 38353.08 | GN38: =IF(OR(BI38=0,BI38=1),GM38-GX38,0) -> 38353.08 | GO38: =IF(BI38=2,GM38-GX38,0) -> 0 | GP38: =IF(BI38=4,GM38-GX38,0) -> 0 | GR38: 0 | GS38: 3 | GT38: 0 | GV38: =ROUND((GT38),6) -> 0 | GW38: 1 | GX38: =ROUND(HC38*I38,2) -> 0 | HA38: 0 | HB38: 0 | HC38: =GV38*GW38 -> 0 | HS38: 0 | IK38: 0
A39: 18 | B39: 1 | C39: 31 | E39: 2,1 | F39: 1.12-1-80 | G39: Заготовка трубная из непластифицированного поливинилхлорида, для внутренней канализации, без средств крепления, диаметр 110 мм | H39: м | I39: =I37*J39 -> 214 | J39: 100 | K39: 100 | O39: =ROUND(CP39,2) -> 82459.12 | P39: =ROUND((ROUND((AC39*AW39*I39),2)*BC39),2) -> 82459.12 | Q39: =(ROUND((ROUND(((ET39)*AV39*I39),2)*BB39),2)+ROUND((ROUND(((AE39-(EU39))*AV39*I39),2)*BS39),2)) -> 0 | R39: =ROUND((ROUND((AE39*AV39*I39),2)*BS39),2) -> 0 | S39: =ROUND((ROUND((AF39*AV39*I39),2)*BA39),2) -> 0 | T39: =ROUND(CU39*I39,2) -> 0 | U39: =CV39*I39 -> 0 | V39: =CW39*I39 -> 0 | W39: =ROUND(CX39*I39,2) -> 0 | X39: =ROUND(CY39,2) -> 0 | Y39: =ROUND(CZ39,2) -> 0 | AA39: 59209200 | AB39: =ROUND((AC39+AD39+AF39),6) -> 179.22 | AC39: =ROUND((ES39),6) -> 179.22 | AD39: =ROUND((((ET39)-(EU39))+AE39),6) -> 0 | AE39: =ROUND((EU39),6) -> 0 | AF39: =ROUND((EV39),6) -> 0 | AG39: =ROUND((AP39),6) -> 0 | AH39: =(EW39) -> 0 | AI39: =(EX39) -> 0 | AJ39: =(AS39) -> 0 | AK39: 179.22 | AL39: 179.22 | AM39: 0 | AN39: 0 | AO39: 0 | AP39: 0 | AQ39: 0 | AR39: 0 | AS39: 0 | AT39: 109 | AU39: 61 | AV39: 1 | AW39: 1 | AZ39: 1 | BA39: 1 | BB39: 1 | BC39: 2.15 | BH39: 3 | BI39: 1 | BJ39: ТСН-2001.1 Доп. 79, Р. 12, о. 1, поз. 80 | BM39: 21 | BN39: 0 | BO39: 1.12-1-80 | BP39: 1 | BQ39: 30 | BR39: 0 | BS39: 1 | BT39: 1 | BU39: 1 | BV39: 1 | BW39: 1 | BX39: 1 | BZ39: 109 | CA39: 61 | CE39: 30 | CF39: 0 | CG39: 0 | CM39: 0 | CO39: 0 | CP39: =(P39+Q39+S39) -> 82459.12 | CQ39: =ROUND((ROUND((AC39*AW39*1),2)*BC39),2) -> 385.32 | CR39: =(ROUND((ROUND(((ET39)*AV39*1),2)*BB39),2)+ROUND((ROUND(((AE39-(EU39))*AV39*1),2)*BS39),2)) -> 0 | CS39: =ROUND((ROUND((AE39*AV39*1),2)*BS39),2) -> 0 | CT39: =ROUND((ROUND((AF39*AV39*1),2)*BA39),2) -> 0 | CU39: =AG39 -> 0 | CV39: =(AH39*AV39) -> 0 | CW39: =AI39 -> 0 | CX39: =AJ39 -> 0 | CY39: =(((S39+R39)*AT39)/100) -> 0 | CZ39: =(((S39+R39)*AU39)/100) -> 0 | DN39: 0 | DO39: 0 | DP39: 1 | DQ39: 1 | DU39: 1003 | DV39: м | DW39: м | DX39: 1 | EE39: 58807897 | EF39: 30 | EG39: Строительные работы | EH39: 0 | EJ39: 1 | EK39: 21 | EL39: ТСН-2001.3-16. Трубопроводы внутренние | EM39: ТСН-2001.3-16-1 | EQ39: 0 | ER39: 179.22 | ES39: 179.22 | ET39: 0 | EU39: 0 | EV39: 0 | EW39: 0 | EX39: 0 | FQ39: 0 | FR39: 0 | FS39: 0 | FX39: 109 | FY39: 61 | GD39: 1 | GF39: 1873563531 | GG39: 2 | GH39: 1 | GI39: 2 | GJ39: 0 | GK39: 0 | GL39: =ROUND(IF(AND(BH39=3,BI39=3,FS39<>0),P39,0),2) -> 0 | GM39: =ROUND(O39+X39+Y39,2)+GX39 -> 82459.12 | GN39: =IF(OR(BI39=0,BI39=1),GM39-GX39,0) -> 82459.12 | GO39: =IF(BI39=2,GM39-GX39,0) -> 0 | GP39: =IF(BI39=4,GM39-GX39,0) -> 0 | GR39: 0 | GS39: 3 | GT39: 0 | GV39: =ROUND((GT39),6) -> 0 | GW39: 1 | GX39: =ROUND(HC39*I39,2) -> 0 | HA39: 0 | HB39: 0 | HC39: =GV39*GW39 -> 0 | HS39: 0 | IK39: 0
A40: 18 | B40: 1 | C40: 23 | E40: 2,2 | F40: 1.12-5-133 | G40: Ревизия из полиэтилена, диаметр 110 мм | H40: шт. | I40: =I36*J40 -> 3 | J40: 1.4018692 | K40: 1.401869 | O40: =ROUND(CP40,2) -> 159.15 | P40: =ROUND((ROUND((AC40*AW40*I40),2)*BC40),2) -> 159.15 | Q40: =(ROUND((ROUND(((ET40)*AV40*I40),2)*BB40),2)+ROUND((ROUND(((AE40-(EU40))*AV40*I40),2)*BS40),2)) -> 0 | R40: =ROUND((ROUND((AE40*AV40*I40),2)*BS40),2) -> 0 | S40: =ROUND((ROUND((AF40*AV40*I40),2)*BA40),2) -> 0 | T40: =ROUND(CU40*I40,2) -> 0 | U40: =CV40*I40 -> 0 | V40: =CW40*I40 -> 0 | W40: =ROUND(CX40*I40,2) -> 0 | X40: =ROUND(CY40,2) -> 0 | Y40: =ROUND(CZ40,2) -> 0 | AA40: 59209203 | AB40: =ROUND((AC40+AD40+AF40),6) -> 53.05 | AC40: =ROUND((ES40),6) -> 53.05 | AD40: =ROUND((((ET40)-(EU40))+AE40),6) -> 0 | AE40: =ROUND((EU40),6) -> 0 | AF40: =ROUND((EV40),6) -> 0 | AG40: =ROUND((AP40),6) -> 0 | AH40: =(EW40) -> 0 | AI40: =(EX40) -> 0 | AJ40: =(AS40) -> 0 | AK40: 53.05 | AL40: 53.05 | AM40: 0 | AN40: 0 | AO40: 0 | AP40: 0 | AQ40: 0 | AR40: 0 | AS40: 0 | AT40: 109 | AU40: 61 | AV40: 1 | AW40: 1 | AZ40: 1 | BA40: 1 | BB40: 1 | BC40: 1 | BH40: 3 | BI40: 1 | BJ40: ТСН-2001.1 Доп. 67, Р. 12, о. 5, поз. 133 | BM40: 21 | BN40: 58807811 | BP40: 0 | BQ40: 30 | BR40: 0 | BS40: 1 | BT40: 1 | BU40: 1 | BV40: 1 | BW40: 1 | BX40: 1 | BZ40: 109 | CA40: 61 | CE40: 30 | CF40: 0 | CG40: 0 | CM40: 0 | CO40: 0 | CP40: =(P40+Q40+S40) -> 159.15 | CQ40: =ROUND((ROUND((AC40*AW40*1),2)*BC40),2) -> 53.05 | CR40: =(ROUND((ROUND(((ET40)*AV40*1),2)*BB40),2)+ROUND((ROUND(((AE40-(EU40))*AV40*1),2)*BS40),2)) -> 0 | CS40: =ROUND((ROUND((AE40*AV40*1),2)*BS40),2) -> 0 | CT40: =ROUND((ROUND((AF40*AV40*1),2)*BA40),2) -> 0 | CU40: =AG40 -> 0 | CV40: =(AH40*AV40) -> 0 | CW40: =AI40 -> 0 | CX40: =AJ40 -> 0 | CY40: =(((S40+R40)*AT40)/100) -> 0 | CZ40: =(((S40+R40)*AU40)/100) -> 0 | DN40: 0 | DO40: 0 | DP40: 1 | DQ40: 1 | DU40: 1010 | DV40: шт. | DW40: шт. | DX40: 1 | EE40: 58807897 | EF40: 30 | EG40: Строительные работы | EH40: 0 | EJ40: 1 | EK40: 21 | EL40: ТСН-2001.3-16. Трубопроводы внутренние | EM40: ТСН-2001.3-16-1 | EQ40: 0 | ER40: 53.05 | ES40: 53.05 | ET40: 0 | EU40: 0 | EV40: 0 | EW40: 0 | EX40: 0 | FQ40: 0 | FR40: 0 | FS40: 0 | FX40: 109 | FY40: 61 | GD40: 1 | GF40: -367918804 | GG40: 2 | GH40: 1 | GI40: -2 | GJ40: 0 | GK40: 0 | GL40: =ROUND(IF(AND(BH40=3,BI40=3,FS40<>0),P40,0),2) -> 0 | GM40: =ROUND(O40+X40+Y40,2)+GX40 -> 159.15 | GN40: =IF(OR(BI40=0,BI40=1),GM40-GX40,0) -> 159.15 | GO40: =IF(BI40=2,GM40-GX40,0) -> 0 | GP40: =IF(BI40=4,GM40-GX40,0) -> 0 | GR40: 0 | GS40: 3 | GT40: 0 | GV40: =ROUND((GT40),6) -> 0 | GW40: 1 | GX40: =ROUND(HC40*I40,2) -> 0 | HA40: 0 | HB40: 0 | HC40: =GV40*GW40 -> 0 | HS40: 0 | IK40: 0
A41: 18 | B41: 1 | C41: 32 | E41: 2,2 | F41: 1.12-5-133 | G41: Ревизия из полиэтилена, диаметр 110 мм | H41: шт. | I41: =I37*J41 -> 3 | J41: 1.4018692 | K41: 1.401869 | O41: =ROUND(CP41,2) -> 623.87 | P41: =ROUND((ROUND((AC41*AW41*I41),2)*BC41),2) -> 623.87 | Q41: =(ROUND((ROUND(((ET41)*AV41*I41),2)*BB41),2)+ROUND((ROUND(((AE41-(EU41))*AV41*I41),2)*BS41),2)) -> 0 | R41: =ROUND((ROUND((AE41*AV41*I41),2)*BS41),2) -> 0 | S41: =ROUND((ROUND((AF41*AV41*I41),2)*BA41),2) -> 0 | T41: =ROUND(CU41*I41,2) -> 0 | U41: =CV41*I41 -> 0 | V41: =CW41*I41 -> 0 | W41: =ROUND(CX41*I41,2) -> 0 | X41: =ROUND(CY41,2) -> 0 | Y41: =ROUND(CZ41,2) -> 0 | AA41: 59209200 | AB41: =ROUND((AC41+AD41+AF41),6) -> 53.05 | AC41: =ROUND((ES41),6) -> 53.05 | AD41: =ROUND((((ET41)-(EU41))+AE41),6) -> 0 | AE41: =ROUND((EU41),6) -> 0 | AF41: =ROUND((EV41),6) -> 0 | AG41: =ROUND((AP41),6) -> 0 | AH41: =(EW41) -> 0 | AI41: =(EX41) -> 0 | AJ41: =(AS41) -> 0 | AK41: 53.05 | AL41: 53.05 | AM41: 0 | AN41: 0 | AO41: 0 | AP41: 0 | AQ41: 0 | AR41: 0 | AS41: 0 | AT41: 109 | AU41: 61 | AV41: 1 | AW41: 1 | AZ41: 1 | BA41: 1 | BB41: 1 | BC41: 3.92 | BH41: 3 | BI41: 1 | BJ41: ТСН-2001.1 Доп. 67, Р. 12, о. 5, поз. 133 | BM41: 21 | BN41: 58807811 | BO41: 1.12-5-133 | BP41: 1 | BQ41: 30 | BR41: 0 | BS41: 1 | BT41: 1 | BU41: 1 | BV41: 1 | BW41: 1 | BX41: 1 | BZ41: 109 | CA41: 61 | CE41: 30 | CF41: 0 | CG41: 0 | CM41: 0 | CO41: 0 | CP41: =(P41+Q41+S41) -> 623.87 | CQ41: =ROUND((ROUND((AC41*AW41*1),2)*BC41),2) -> 207.96 | CR41: =(ROUND((ROUND(((ET41)*AV41*1),2)*BB41),2)+ROUND((ROUND(((AE41-(EU41))*AV41*1),2)*BS41),2)) -> 0 | CS41: =ROUND((ROUND((AE41*AV41*1),2)*BS41),2) -> 0 | CT41: =ROUND((ROUND((AF41*AV41*1),2)*BA41),2) -> 0 | CU41: =AG41 -> 0 | CV41: =(AH41*AV41) -> 0 | CW41: =AI41 -> 0 | CX41: =AJ41 -> 0 | CY41: =(((S41+R41)*AT41)/100) -> 0 | CZ41: =(((S41+R41)*AU41)/100) -> 0 | DN41: 0 | DO41: 0 | DP41: 1 | DQ41: 1 | DU41: 1010 | DV41: шт. | DW41: шт. | DX41: 1 | EE41: 58807897 | EF41: 30 | EG41: Строительные работы | EH41: 0 | EJ41: 1 | EK41: 21 | EL41: ТСН-2001.3-16. Трубопроводы внутренние | EM41: ТСН-2001.3-16-1 | EQ41: 0 | ER41: 53.05 | ES41: 53.05 | ET41: 0 | EU41: 0 | EV41: 0 | EW41: 0 | EX41: 0 | FQ41: 0 | FR41: 0 | FS41: 0 | FX41: 109 | FY41: 61 | GD41: 1 | GF41: -367918804 | GG41: 2 | GH41: 1 | GI41: 2 | GJ41: 0 | GK41: 0 | GL41: =ROUND(IF(AND(BH41=3,BI41=3,FS41<>0),P41,0),2) -> 0 | GM41: =ROUND(O41+X41+Y41,2)+GX41 -> 623.87 | GN41: =IF(OR(BI41=0,BI41=1),GM41-GX41,0) -> 623.87 | GO41: =IF(BI41=2,GM41-GX41,0) -> 0 | GP41: =IF(BI41=4,GM41-GX41,0) -> 0 | GR41: 0 | GS41: 3 | GT41: 0 | GV41: =ROUND((GT41),6) -> 0 | GW41: 1 | GX41: =ROUND(HC41*I41,2) -> 0 | HA41: 0 | HB41: 0 | HC41: =GV41*GW41 -> 0 | HS41: 0 | IK41: 0
A42: 18 | B42: 1 | C42: 24 | E42: 2,3 | F42: 1.12-5-133 | G42: Ревизия из полиэтилена, диаметр 110 мм /прочистки | H42: шт. | I42: =I36*J42 -> 18 | J42: 8.411215 | K42: 8.411215 | O42: =ROUND(CP42,2) -> 954.9 | P42: =ROUND((ROUND((AC42*AW42*I42),2)*BC42),2) -> 954.9 | Q42: =(ROUND((ROUND(((ET42)*AV42*I42),2)*BB42),2)+ROUND((ROUND(((AE42-(EU42))*AV42*I42),2)*BS42),2)) -> 0 | R42: =ROUND((ROUND((AE42*AV42*I42),2)*BS42),2) -> 0 | S42: =ROUND((ROUND((AF42*AV42*I42),2)*BA42),2) -> 0 | T42: =ROUND(CU42*I42,2) -> 0 | U42: =CV42*I42 -> 0 | V42: =CW42*I42 -> 0 | W42: =ROUND(CX42*I42,2) -> 0 | X42: =ROUND(CY42,2) -> 0 | Y42: =ROUND(CZ42,2) -> 0 | AA42: 59209203 | AB42: =ROUND((AC42+AD42+AF42),6) -> 53.05 | AC42: =ROUND((ES42),6) -> 53.05 | AD42: =ROUND((((ET42)-(EU42))+AE42),6) -> 0 | AE42: =ROUND((EU42),6) -> 0 | AF42: =ROUND((EV42),6) -> 0 | AG42: =ROUND((AP42),6) -> 0 | AH42: =(EW42) -> 0 | AI42: =(EX42) -> 0 | AJ42: =(AS42) -> 0 | AK42: 53.05 | AL42: 53.05 | AM42: 0 | AN42: 0 | AO42: 0 | AP42: 0 | AQ42: 0 | AR42: 0 | AS42: 0 | AT42: 109 | AU42: 61 | AV42: 1 | AW42: 1 | AZ42: 1 | BA42: 1 | BB42: 1 | BC42: 1 | BH42: 3 | BI42: 1 | BJ42: ТСН-2001.1 Доп. 67, Р. 12, о. 5, поз. 133 | BM42: 21 | BN42: 58807811 | BP42: 0 | BQ42: 30 | BR42: 0 | BS42: 1 | BT42: 1 | BU42: 1 | BV42: 1 | BW42: 1 | BX42: 1 | BZ42: 109 | CA42: 61 | CE42: 30 | CF42: 0 | CG42: 0 | CM42: 0 | CO42: 0 | CP42: =(P42+Q42+S42) -> 954.9 | CQ42: =ROUND((ROUND((AC42*AW42*1),2)*BC42),2) -> 53.05 | CR42: =(ROUND((ROUND(((ET42)*AV42*1),2)*BB42),2)+ROUND((ROUND(((AE42-(EU42))*AV42*1),2)*BS42),2)) -> 0 | CS42: =ROUND((ROUND((AE42*AV42*1),2)*BS42),2) -> 0 | CT42: =ROUND((ROUND((AF42*AV42*1),2)*BA42),2) -> 0 | CU42: =AG42 -> 0 | CV42: =(AH42*AV42) -> 0 | CW42: =AI42 -> 0 | CX42: =AJ42 -> 0 | CY42: =(((S42+R42)*AT42)/100) -> 0 | CZ42: =(((S42+R42)*AU42)/100) -> 0 | DN42: 0 | DO42: 0 | DP42: 1 | DQ42: 1 | DU42: 1010 | DV42: шт. | DW42: шт. | DX42: 1 | EE42: 58807897 | EF42: 30 | EG42: Строительные работы | EH42: 0 | EJ42: 1 | EK42: 21 | EL42: ТСН-2001.3-16. Трубопроводы внутренние | EM42: ТСН-2001.3-16-1 | EQ42: 0 | ER42: 53.05 | ES42: 53.05 | ET42: 0 | EU42: 0 | EV42: 0 | EW42: 0 | EX42: 0 | FQ42: 0 | FR42: 0 | FS42: 0 | FX42: 109 | FY42: 61 | GD42: 1 | GF42: -1159203431 | GG42: 2 | GH42: 1 | GI42: -2 | GJ42: 0 | GK42: 0 | GL42: =ROUND(IF(AND(BH42=3,BI42=3,FS42<>0),P42,0),2) -> 0 | GM42: =ROUND(O42+X42+Y42,2)+GX42 -> 954.9 | GN42: =IF(OR(BI42=0,BI42=1),GM42-GX42,0) -> 954.9 | GO42: =IF(BI42=2,GM42-GX42,0) -> 0 | GP42: =IF(BI42=4,GM42-GX42,0) -> 0 | GR42: 0 | GS42: 3 | GT42: 0 | GV42: =ROUND((GT42),6) -> 0 | GW42: 1 | GX42: =ROUND(HC42*I42,2) -> 0 | HA42: 0 | HB42: 0 | HC42: =GV42*GW42 -> 0 | HS42: 0 | IK42: 0
A43: 18 | B43: 1 | C43: 33 | E43: 2,3 | F43: 1.12-5-133 | G43: Ревизия из полиэтилена, диаметр 110 мм /прочистки | H43: шт. | I43: =I37*J43 -> 18 | J43: 8.411215 | K43: 8.411215 | O43: =ROUND(CP43,2) -> 3743.21 | P43: =ROUND((ROUND((AC43*AW43*I43),2)*BC43),2) -> 3743.21 | Q43: =(ROUND((ROUND(((ET43)*AV43*I43),2)*BB43),2)+ROUND((ROUND(((AE43-(EU43))*AV43*I43),2)*BS43),2)) -> 0 | R43: =ROUND((ROUND((AE43*AV43*I43),2)*BS43),2) -> 0 | S43: =ROUND((ROUND((AF43*AV43*I43),2)*BA43),2) -> 0 | T43: =ROUND(CU43*I43,2) -> 0 | U43: =CV43*I43 -> 0 | V43: =CW43*I43 -> 0 | W43: =ROUND(CX43*I43,2) -> 0 | X43: =ROUND(CY43,2) -> 0 | Y43: =ROUND(CZ43,2) -> 0 | AA43: 59209200 | AB43: =ROUND((AC43+AD43+AF43),6) -> 53.05 | AC43: =ROUND((ES43),6) -> 53.05 | AD43: =ROUND((((ET43)-(EU43))+AE43),6) -> 0 | AE43: =ROUND((EU43),6) -> 0 | AF43: =ROUND((EV43),6) -> 0 | AG43: =ROUND((AP43),6) -> 0 | AH43: =(EW43) -> 0 | AI43: =(EX43) -> 0 | AJ43: =(AS43) -> 0 | AK43: 53.05 | AL43: 53.05 | AM43: 0 | AN43: 0 | AO43: 0 | AP43: 0 | AQ43: 0 | AR43: 0 | AS43: 0 | AT43: 109 | AU43: 61 | AV43: 1 | AW43: 1 | AZ43: 1 | BA43: 1 | BB43: 1 | BC43: 3.92 | BH43: 3 | BI43: 1 | BJ43: ТСН-2001.1 Доп. 67, Р. 12, о. 5, поз. 133 | BM43: 21 | BN43: 58807811 | BO43: 1.12-5-133 | BP43: 1 | BQ43: 30 | BR43: 0 | BS43: 1 | BT43: 1 | BU43: 1 | BV43: 1 | BW43: 1 | BX43: 1 | BZ43: 109 | CA43: 61 | CE43: 30 | CF43: 0 | CG43: 0 | CM43: 0 | CO43: 0 | CP43: =(P43+Q43+S43) -> 3743.21 | CQ43: =ROUND((ROUND((AC43*AW43*1),2)*BC43),2) -> 207.96 | CR43: =(ROUND((ROUND(((ET43)*AV43*1),2)*BB43),2)+ROUND((ROUND(((AE43-(EU43))*AV43*1),2)*BS43),2)) -> 0 | CS43: =ROUND((ROUND((AE43*AV43*1),2)*BS43),2) -> 0 | CT43: =ROUND((ROUND((AF43*AV43*1),2)*BA43),2) -> 0 | CU43: =AG43 -> 0 | CV43: =(AH43*AV43) -> 0 | CW43: =AI43 -> 0 | CX43: =AJ43 -> 0 | CY43: =(((S43+R43)*AT43)/100) -> 0 | CZ43: =(((S43+R43)*AU43)/100) -> 0 | DN43: 0 | DO43: 0 | DP43: 1 | DQ43: 1 | DU43: 1010 | DV43: шт. | DW43: шт. | DX43: 1 | EE43: 58807897 | EF43: 30 | EG43: Строительные работы | EH43: 0 | EJ43: 1 | EK43: 21 | EL43: ТСН-2001.3-16. Трубопроводы внутренние | EM43: ТСН-2001.3-16-1 | EQ43: 0 | ER43: 53.05 | ES43: 53.05 | ET43: 0 | EU43: 0 | EV43: 0 | EW43: 0 | EX43: 0 | FQ43: 0 | FR43: 0 | FS43: 0 | FX43: 109 | FY43: 61 | GD43: 1 | GF43: -1159203431 | GG43: 2 | GH43: 1 | GI43: 2 | GJ43: 0 | GK43: 0 | GL43: =ROUND(IF(AND(BH43=3,BI43=3,FS43<>0),P43,0),2) -> 0 | GM43: =ROUND(O43+X43+Y43,2)+GX43 -> 3743.21 | GN43: =IF(OR(BI43=0,BI43=1),GM43-GX43,0) -> 3743.21 | GO43: =IF(BI43=2,GM43-GX43,0) -> 0 | GP43: =IF(BI43=4,GM43-GX43,0) -> 0 | GR43: 0 | GS43: 3 | GT43: 0 | GV43: =ROUND((GT43),6) -> 0 | GW43: 1 | GX43: =ROUND(HC43*I43,2) -> 0 | HA43: 0 | HB43: 0 | HC43: =GV43*GW43 -> 0 | HS43: 0 | IK43: 0
