Workbook

Sheet 02-01-11
A1: =Source!B1 -> Smeta.RU (495) 974-1589
J2: Форма № 4б
A3: Капитальный ремонт здания Государственного бюджетного общеобразовательного учреждения города Москвы «Школа № 236» по адресу: г. Москва, ул. Клязьминская, д. 7, к. 4. I этап | AP3: Капитальный ремонт здания Государственного бюджетного общеобразовательного учреждения города Москвы «Школа № 236» по адресу: г. Москва, ул. Клязьминская, д. 7, к. 4. I этап. 02-01-11 СКТ
A4: (наименование стройки и/или объекта)
A6: =CONCATENATE( "ЛОКАЛЬНАЯ СМЕТА № ",IF(Source!F20<>"Новая локальная смета", Source!F20, "")) -> ЛОКАЛЬНАЯ СМЕТА № 02-01-11
A8: =IF(Source!G20<>"Новая локальная смета", Source!G20, "") -> Система кабельного телевидения
A9: (наименование работ и затрат)
A11: =CONCATENATE( "Основание: чертежи № ", Source!J20) -> Основание: чертежи № 2024-00272-01-0-ИОС5.4
I13: В базисном уровне цен | J13: В текущем уровне цен
E14: Сметная стоимость | I14: =I15+I16+I17+I18 -> 22.04 | J14: =J15+J16+J17+J18 -> 267.52 | K14: тыс.руб.
E15: Строительные работы | I15: =ROUND((Source!F177)/1000, 2) -> 0 | J15: =ROUND((Source!P177)/1000, 2) -> 0 | K15: тыс.руб.
E16: Работы по монтажу оборудования | I16: =ROUND((Source!F178)/1000, 2) -> 13.25 | J16: =ROUND((Source!P178)/1000, 2) -> 200.2 | K16: тыс.руб.
E17: Оборудование | I17: =ROUND((Source!F169)/1000, 2) -> 8.79 | J17: =ROUND((Source!P169)/1000, 2) -> 67.32 | K17: тыс.руб.
E18: Прочие работы и затраты | I18: =ROUND((Source!F179+Source!F180)/1000, 2) -> 0 | J18: =ROUND((Source!P179+Source!P180)/1000, 2) -> 0 | K18: тыс.руб.
E19: Средства на оплату труда | I19: =(Source!F175+ Source!F174)/1000 -> 0.79884 | J19: =((Source!P175 + Source!P174)/1000) -> 43.92823 | K19: тыс.руб.
E20: Затраты труда | I20: =Source!F182 -> 63.539123 | K20: чел.-ч.
E21: Кроме того:
E22: Возврат материалов | I22: =SUM(Y28:Y136)/1000 -> 0 | J22: =SUM(Z28:Z136)/1000 -> 0 | K22: тыс.руб.
A24: Составлен(а) по ТСН-2001 с учетом Дополнения №: 80
A25: № и период сборника коэффициентов (индексов) пересчета: Коэффициенты к ТСН-2001 МГЭ Дополнение 80, строительство №217/80 III квартал 2025 года и Коэффициенты к ТСН-2001.13-2 Дополнение 46 №62/46 III квартал 2025 года | AP25: № и период сборника коэффициентов (индексов) пересчета: Коэффициенты к ТСН-2001 МГЭ Дополнение 80, строительство №217/80 III квартал 2025 года и Коэффициенты к ТСН-2001.13-2 Дополнение 46 №62/46 III квартал 2025 года
A26: № п/п | B26: Шифр расценки и коды ресурсов | C26: Наименование работ и затрат | D26: Ед. изм. | E26: Кол-во единиц | F26: Цена на ед. изм., руб. | G26: Попра- вочные коэффи- циенты | H26: Коэффи- циенты зимних удорожа- ний | I26: Всего в ценах на январь 2000 года, руб. | J26: Коэффи- циенты (индек- сы) пере- счета, нормы НР и СП | K26: ВСЕГО затрат в текущем уровне цен, руб.
A27: 1 | B27: 2 | C27: 3 | D27: 4 | E27: 5 | F27: 6 | G27: 7 | H27: 8 | I27: 9 | J27: 10 | K27: 11
A29: =CONCATENATE("Раздел: ",IF(Source!G24<>"Новый раздел", Source!G24, "")) -> Раздел: Оборудование
A30: 1 | B30: 4.10-136-5 Поправка: Гл.12.Прил.8.п.8. 5_12.00.01.11.003 | C30: Разные устройства, монтаж базового блока головной станции настенного типа | D30: =Source!H28 -> 1 ШТ. | E30: =Source!I28 -> 1 | Q30: =Source!X28 -> 126.86 | R30: =Source!X29 -> 6976.19 | S30: =Source!Y28 -> 70.78 | T30: =Source!Y29 -> 3891.98 | U30: =ROUND((175/100)*ROUND(Source!R28, 2), 2) -> 0 | V30: =ROUND((0/100)*ROUND(Source!R29, 2), 2) -> 0 | AC30: 0
C31: ЗП | F31: =Source!AO28 -> 111.68 | G31: =Source!DG28 -> *1,1 | H31: =Source!AV29 -> 1.087 | I31: =Source!S28 -> 133.54 | J31: =IF(Source!BA29<> 0, Source!BA29, 1) -> 54.99 | K31: =Source!S29 -> 7343.36
C32: МР | F32: =Source!AL28 -> 0.29 | G32: =Source!DD28 | H32: =Source!AW29 -> 1 | I32: =Source!P28 -> 0.29 | J32: =IF(Source!BC29<> 0, Source!BC29, 1) -> 9.9 | K32: =Source!P29 -> 2.87
A33: 1,1 | B33: =Source!F30 -> КА 1 | C33: ОБОРУДОВАНИЕ:_x000D_ Головная станция СКТ "Мини-ГС" на базе оборудования VS50 Pro в шкафу с блоком розеток и автоматом 8 788,39 = [77 500 / 1,2 / 7,66] + 3% Трансп + 1,2% Заг.скл | D33: =Source!H30 -> шт. | E33: =Source!I30 -> 1 | F33: =Source!AK30 -> 8788.39 | H33: =Source!AW31 -> 1 | I33: =Source!O30 -> 8788.39 | J33: =IF(Source!BC31<> 0, Source!BC31, 1) -> 7.66 | K33: =Source!O31 -> 67319.07 | Q33: =Source!X30 -> 0 | R33: =Source!X31 -> 0 | S33: =Source!Y30 -> 0 | T33: =Source!Y31 -> 0 | U33: =ROUND((175/100)*ROUND(Source!R30, 2), 2) -> 0 | V33: =ROUND((0/100)*ROUND(Source!R31, 2), 2) -> 0 | AC33: 5
C34: НР от ФОТ | D34: % | E34: =Source!BZ29 -> 95 | I34: =SUM(Q30:Q33) -> 126.86 | J34: =Source!AT29 -> 95 | K34: =SUM(R30:R33) -> 6976.19
C35: СП от ФОТ | D35: % | E35: =Source!CA29 -> 53 | I35: =SUM(S30:S34) -> 70.78 | J35: =Source!AU29 -> 53 | K35: =SUM(T30:T34) -> 3891.98
C36: ЗТР | D36: чел-ч | E36: =Source!AQ28 -> 8 | G36: =Source!DI28 -> *1,1 | H36: =Source!AV29 -> 1.087 | I36: =Source!U28 -> 9.5656
C37: ВСЕГО работ по позиции: | H37: =I31+I32+I34+I35+SUM(I33:I33)-SUMIF(AC33:AC33, 5, I33:I33)-SUMIF(AC33:AC33, 6, I33:I33) -> 331.47 | J37: =K31+K32+K34+K35+SUM(K33:K33)-SUMIF(AC33:AC33, 5, K33:K33)-SUMIF(AC33:AC33, 6, K33:K33) -> 18214.4
C38: ВСЕГО оборудование по позиции: | H38: =SUMIF(AC33:AC33, 5, I33:I33)+SUMIF(AC33:AC33, 6, I33:I33) -> 8788.39 | J38: =SUMIF(AC33:AC33, 5, K33:K33)+SUMIF(AC33:AC33, 6, K33:K33) -> 67319.07
C39: ВСЕГО по позиции: | H39: =I31+I32+I34+I35+SUM(I33:I33) -> 9119.86 | J39: =K31+K32+K34+K35+SUM(K33:K33) -> 85533.47 | O39: =I31+I32+I34+I35+SUM(I33:I33) -> 9119.86 | P39: =K31+K32+K34+K35+SUM(K33:K33) -> 85533.47
A41: 2 | B41: 4.11-2-1 Поправка: Гл.12.Прил.8.п.8. 5_12.00.01.11.003 | C41: Установка прибора на резьбовых соединениях | D41: =Source!H32 -> 1 ШТ. | E41: =Source!I32 -> 3 | Q41: =Source!X32 -> 12.12 | R41: =Source!X33 -> 666.65 | S41: =Source!Y32 -> 6.2 | T41: =Source!Y33 -> 340.73 | U41: =ROUND((175/100)*ROUND(Source!R32, 2), 2) -> 0 | V41: =ROUND((0/100)*ROUND(Source!R33, 2), 2) -> 0 | AC41: 0
C42: ЗП | F42: =Source!AO32 -> 3.9 | G42: =Source!DG32 -> *1,1 | H42: =Source!AV33 -> 1.047 | I42: =Source!S32 -> 13.47 | J42: =IF(Source!BA33<> 0, Source!BA33, 1) -> 54.99 | K42: =Source!S33 -> 740.72
C43: МР | F43: =Source!AL32 -> 0.81 | G43: =Source!DD32 | H43: =Source!AW33 -> 1 | I43: =Source!P32 -> 2.43 | J43: =IF(Source!BC33<> 0, Source!BC33, 1) -> 8.8 | K43: =Source!P33 -> 21.38
A44: 2,1 | B44: =Source!F34 -> 1.14-1-551 | C44: Ответвитель направленный, абонентский, типа ОАТ 410 | D44: =Source!H34 -> шт. | E44: =Source!I34 -> 1 | F44: =Source!AK34 -> 39.87 | H44: =Source!AW35 -> 1 | I44: =Source!O34 -> 39.87 | J44: =IF(Source!BC35<> 0, Source!BC35, 1) -> 2.85 | K44: =Source!O35 -> 113.63 | Q44: =Source!X34 -> 0 | R44: =Source!X35 -> 0 | S44: =Source!Y34 -> 0 | T44: =Source!Y35 -> 0 | U44: =ROUND((175/100)*ROUND(Source!R34, 2), 2) -> 0 | V44: =ROUND((0/100)*ROUND(Source!R35, 2), 2) -> 0 | AC44: 3
A45: 2,2 | B45: =Source!F36 -> 1.14-1-552 | C45: Ответвитель направленный, абонентский, типа ОАТ 412 | D45: =Source!H36 -> шт. | E45: =Source!I36 -> 1 | F45: =Source!AK36 -> 40.05 | H45: =Source!AW37 -> 1 | I45: =Source!O36 -> 40.05 | J45: =IF(Source!BC37<> 0, Source!BC37, 1) -> 2.83 | K45: =Source!O37 -> 113.34 | Q45: =Source!X36 -> 0 | R45: =Source!X37 -> 0 | S45: =Source!Y36 -> 0 | T45: =Source!Y37 -> 0 | U45: =ROUND((175/100)*ROUND(Source!R36, 2), 2) -> 0 | V45: =ROUND((0/100)*ROUND(Source!R37, 2), 2) -> 0 | AC45: 3
A46: 2,3 | B46: =Source!F38 -> 1.14-1-553 | C46: Ответвитель направленный, абонентский, типа ОАТ 416 | D46: =Source!H38 -> шт. | E46: =Source!I38 -> 1 | F46: =Source!AK38 -> 40.17 | H46: =Source!AW39 -> 1 | I46: =Source!O38 -> 40.17 | J46: =IF(Source!BC39<> 0, Source!BC39, 1) -> 2.83 | K46: =Source!O39 -> 113.68 | Q46: =Source!X38 -> 0 | R46: =Source!X39 -> 0 | S46: =Source!Y38 -> 0 | T46: =Source!Y39 -> 0 | U46: =ROUND((175/100)*ROUND(Source!R38, 2), 2) -> 0 | V46: =ROUND((0/100)*ROUND(Source!R39, 2), 2) -> 0 | AC46: 3
C47: НР от ФОТ | D47: % | E47: =Source!BZ33 -> 90 | I47: =SUM(Q41:Q46) -> 12.12 | J47: =Source!AT33 -> 90 | K47: =SUM(R41:R46) -> 666.65
...

Sheet Ведомость объемов работ
A1: =Source!B1 -> Smeta.RU (495) 974-1589
E3: "УТВЕРЖДАЮ"
D5: ___________________________
D7: ___________________________
D9: " ___ " ___________ 20 ___ г.
B12: =CONCATENATE("Ведомость объемов работ ", IF(Source!AN15<>"", Source!AN15," ")) -> Ведомость объемов работ
B13: =CONCATENATE(Source!F12, " ", Source!G12) -> 02-01-11 02-01-11 СКТ
A16: № п/п | B16: № в ЛСР | C16: Наименование работ и затрат | D16: Единица измерения | E16: Количество | F16: Ссылка на чертежи, спецификации | G16: Формула расчета, расчет объемов работ и расхода материалов | H16: Примечание
A17: 1 | B17: 2 | C17: 3 | D17: 4 | E17: 5 | F17: 6 | G17: 7 | H17: 8
A18: =CONCATENATE("Локальная смета: ", Source!G20) -> Локальная смета: Система кабельного телевидения
A19: =CONCATENATE("Раздел: ", Source!G24) -> Раздел: Оборудование
A20: 1 | B20: =Source!E28 -> 1 | C20: =Source!G28 -> Разные устройства, монтаж базового блока головной станции настенного типа | D20: 1 ШТ. | E20: =Source!I28 -> 1 | F20: =Source!U24 | G20: =Source!I28 -> 1
A21: 1.1 | B21: =Source!E30 -> 1,1 | C21: =Source!G30 -> Головная станция СКТ "Мини-ГС" на базе оборудования VS50 Pro в шкафу с блоком розеток и автоматом | D21: шт. | E21: =Source!I30 -> 1 | F21: =Source!U24
A22: 2 | B22: =Source!E32 -> 2 | C22: =Source!G32 -> Установка прибора на резьбовых соединениях | D22: 1 ШТ. | E22: =Source!I32 -> 3 | F22: =Source!U24 | G22: =Source!I32 -> 3
A23: 2.1 | B23: =Source!E34 -> 2,1 | C23: =Source!G34 -> Ответвитель направленный, абонентский, типа ОАТ 410 | D23: шт. | E23: =Source!I34 -> 1 | F23: =Source!U24
A24: 2.2 | B24: =Source!E36 -> 2,2 | C24: =Source!G36 -> Ответвитель направленный, абонентский, типа ОАТ 412 | D24: шт. | E24: =Source!I36 -> 1 | F24: =Source!U24
A25: 2.3 | B25: =Source!E38 -> 2,3 | C25: =Source!G38 -> Ответвитель направленный, абонентский, типа ОАТ 416 | D25: шт. | E25: =Source!I38 -> 1 | F25: =Source!U24
A26: =CONCATENATE("Раздел: ", Source!G71) -> Раздел: Материалы
A27: 3 | B27: =Source!E75 -> 3 | C27: =Source!G75 -> Монтаж розетки штепсельной трехполюсной | D27: 100 шт. | E27: =Source!I75 -> 0.05 | F27: =Source!U71 | G27: ="=5/"&"100" -> =5/100
A28: 3.1 | B28: =Source!E77 -> 3,1 | C28: =Source!G77 -> Розетка телевизионная, скрытой установки, раздельная, двухместная, "штырь" и "гнездо", конечная, затухание 4 дБ, возвратные потери от 12 до 18 дБ, диапазон частот от 5 до 2400 МГц, степень защиты IP20, с безвинтовыми зажимами для радиочастотного коаксиального кабеля с диаметром внутреннего проводника от 0,58 до 1,15 мм и диаметром по изоляции от 3,7 до 5,8 мм, механизм с литой цинковой крепежной рамой, без декоративной крышки, размер не более 71х71х22 мм | D28: шт. | E28: =Source!I77 -> 5 | F28: =Source!U71
A29: 4 | B29: =Source!E79 -> 4 | C29: =Source!G79 -> Прокладка кабеля связи симметричного для цифровых систем передачи в трубах гофрированных: по бетонным и кирпичным поверхностям стен и потолка | D29: 100 м | E29: =Source!I79 -> 2 | F29: =Source!U71 | G29: ="=200/"&"100" -> =200/100
A30: 4.1 | B30: =Source!E81 -> 4,1 | C30: =Source!G81 -> Трубы электротехнические, гофрированные, из ПВХ, негорючие, с зондом, наружный диаметр 20 мм | D30: м | E30: =Source!I81 -> 204 | F30: =Source!U71
A31: 4.2 | B31: =Source!E83 -> 4,2 | C31: =Source!G83 -> Коробка установочная, для скрытой проводки, из полистирола, диаметр 65 мм, высота 40 мм, без саморезов | D31: шт. | E31: =Source!I83 -> 5 | F31: =Source!U71
A32: 4.3 | B32: =Source!E85 -> 4,3 | C32: =Source!G85 -> Держатель пластиковый с защелкой для крепления труб, рукавов и гибких вводов диаметром 20 мм | D32: 100 шт. | E32: =Source!I85 -> 6 | F32: =Source!U71
A33: 4.4 | B33: =Source!E87 -> 4,4 | C33: =Source!G87 -> Кабель коаксиальный РК 75-4,8-319нг(А)-LSLTx | D33: км | E33: =Source!I87 -> 0.255 | F33: =Source!U71
A34: 4.5 | B34: =Source!E89 -> 4,5 | C34: =Source!G89 -> Кабель коаксиальный РК 75-7-327нг(А)-LSLTx | D34: км | E34: =Source!I89 -> 0.1377 | F34: =Source!U71
A35: 4.6 | B35: =Source!E91 -> 4,6 | C35: =Source!G91 -> Разъем телевизионный F для коаксиального кабеля стандарта RG11 | D35: шт. | E35: =Source!I91 -> 20 | F35: =Source!U71
A36: 4.7 | B36: =Source!E93 -> 4,7 | C36: =Source!G93 -> Разъем телевизионный F для коаксиального кабеля стандарта RG6 | D36: шт. | E36: =Source!I93 -> 15 | F36: =Source!U71
A37: 5 | B37: =Source!E109 -> 5 | C37: =Source!G109 -> Антенные устройства, монтаж антенны коллективной для приема ТВ на антенной опоре высотой до 6 м без оттяжек на кровле с ранее оборудованными трубостойками | D37: 1 антенна | E37: =Source!I109 -> 1 | F37: =Source!U71 | G37: =Source!I109 -> 1
A38: 5.1 | B38: =Source!E111 -> 5,1 | C38: =Source!G111 -> Антенна ДМВ диапазона EB45LTE | D38: шт. | E38: =Source!I111 -> 1 | F38: =Source!U71
A39: 6 | B39: =Source!E113 -> 6 | C39: =Source!G113 -> Разные устройства, монтаж коробки телевизионной (ответвители, разветвители магистральные, домовые, абонентские), УСС, БФТК | D39: 1 ШТ. | E39: =Source!I113 -> 1 | F39: =Source!U71 | G39: =Source!I113 -> 1
A40: 6.1 | B40: =Source!E115 -> 6,1 | C40: =Source!G115 -> Грозозащита 75 Ом ОВР | D40: шт. | E40: =Source!I115 -> 1 | F40: =Source!U71
A41: 7 | B41: =Source!E117 -> 7 | C41: =Source!G117 -> Прокладка металлического рукава, наружный диаметр до 48 мм | D41: 100 м | E41: =Source!I117 -> 0.1 | F41: =Source!U71 | G41: ="=10/"&"100" -> =10/100
A42: 7.1 | B42: =Source!E119 -> 7,1 | C42: =Source!G119 -> Рукав металлический из алюминиевой ленты, негерметичный, уплотненный хлопчатобумажной нитью, для защиты кабеля от механических повреждений, номинальный диаметр 22 мм | D42: м | E42: =Source!I119 -> 10.3 | F42: =Source!U71
C45: Главный инженер проекта _________________ | D45: =IF(Source!X12<>"", Source!X12," ")
C47: Составил _________________ | D47: =IF(Source!AB12<>"", Source!AB12," ") -> Лукьянова А.Л.

Sheet Source
A1: 0 | B1: Smeta.RU (495) 974-1589 | D1: _PS_ | F1: 0 | G1: 0 | H1: 0 | I1: Smeta.RU | K1: 1 | L1: 74562 | M1: 10 | N1: 12 | O1: 0 | P1: 0 | Q1: 3
A4: 1 | B4: 1 | C4: -1 | G4: Капитальный ремонт здания Государственного бюджетного общеобразовательного учреждения города Москвы «Школа № 236» по адресу: г. Москва, ул. Клязьминская, д. 7, к. 4. I этап | EC4: 0
A12: 1 | B12: 229 | C12: 0 | D12: =ROW(A190) -> 190 | E12: 0 | F12: 02-01-11 | G12: 02-01-11 СКТ | I12: 0 | J12: 2024-00272-01-0-ИОС5.4 | K12: 0 | L12: 0 | M12: 4098 | O12: 0 | P12: 0 | Q12: 0 | R12: 0 | S12: 0 | T12: 1 | V12: 0 | AB12: Лукьянова А.Л. | BB12: 0 | BH12: Сметные нормы списания | BI12: Коды ОКП для ТСН-2001 МГЭ Дополнение 80 | BJ12: 1 | BK12: 1 | BL12: 0 | BM12: 0 | BN12: 1 | BO12: 0 | BP12: 6 | BQ12: 2 | BR12: 1 | BS12: 1 | BT12: 1 | BU12: 0 | BV12: 1 | BW12: 0 | BX12: 0 | BY12: ТСН-2001 (МГЭ) Доп 80 - Новое строительство | BZ12: Типовой расчет для ТСН-2001 МГЭ, Дополнение 80, строительство | CA12: Территориальные сметные нормативы для Москвы ТСН-2001 (МГЭ), дополнение 80 | CB12: Территориальные сметные нормативы для Москвы ТСН-2001 (МГЭ), дополнение 80 | CC12: Территориальные сметные нормативы для Москвы ТСН-2001 (МГЭ), дополнение 80 | CD12: Территориальные сметные нормативы для Москвы ТСН-2001 (МГЭ), дополнение 80 | CE12: Поправки для ТСН-2001 от 03.02.2026 г. доп.80 | CF12: 0 | CG12: 0 | CH12: 8200 | CK12: 80 | CQ12: Территориальные сметные нормативы для Москвы (ТСН-2001) | CR12: ТЕР | CS12: 41660 | CT12: 1 | CU12: 80 | CY12: 0 | EC12: 0
A15: 15 | B15: 1
A18: 52 | B18: =B190 -> 229 | C18: =C190 -> 1 | D18: =D190 -> 12 | E18: =E190 -> 0 | F18: =F190 -> 02-01-11 | G18: =G190 -> 02-01-11 СКТ | O18: =O190 -> 20912.05 | P18: =P190 -> 20094.21 | Q18: =Q190 -> 19.37 | R18: =R190 -> 0.37 | S18: =S190 -> 798.47 | T18: =T190 -> 0 | U18: =U190 -> 63.539123 | V18: =V190 -> 0 | ... GX18: =GX190 -> 0
A20: 3 | B20: 1 | D20: =ROW(A160) -> 160 | F20: 02-01-11 | G20: Система кабельного телевидения | I20: 0 | J20: 2024-00272-01-0-ИОС5.4 | K20: -1 | L20: 02-01-11 | S20: 0 | T20: 0 | V20: 0 | AB20: Лукьянова А.Л. | BX20: 0 | CF20: 0 | CG20: 0
A22: 52 | B22: =B160 -> 1 | C22: =C160 -> 3 | D22: =D160 -> 20 | E22: =E160 -> 0 | F22: =F160 -> 02-01-11 | G22: =G160 -> Система кабельного телевидения | O22: =O160 -> 20912.05 | P22: =P160 -> 20094.21 | Q22: =Q160 -> 19.37 | R22: =R160 -> 0.37 | S22: =S160 -> 798.47 | T22: =T160 -> 0 | U22: =U160 -> 63.539123 | V22: =V160 -> 0 | ... GX22: =GX160 -> 0
A24: 4 | B24: 1 | D24: =ROW(A41) -> 41 | G24: Оборудование | I24: 0 | K24: -1 | S24: 0 | T24: 0 | V24: 0 | BX24: 0 | CJ24: 0
A26: 52 | B26: =B41 -> 1 | C26: =C41 -> 4 | D26: =D41 -> 24 | E26: =E41 -> 0 | F26: =F41 | G26: =G41 -> Оборудование | O26: =O41 -> 9058.21 | P26: =P41 -> 8911.2 | Q26: =Q41 -> 0 | R26: =R41 -> 0 | S26: =S41 -> 147.01 | T26: =T41 -> 0 | U26: =U41 -> 10.60213 | V26: =V41 -> 0 | ... GX26: =GX41 -> 0
A28: 17 | B28: 1 | D28: =ROW(EtalonRes!A1) -> 1 | E28: 1 | F28: 4.10-136-5 | G28: Разные устройства, монтаж базового блока головной станции настенного типа | H28: 1 ШТ. | I28: 1 | J28: 0 | K28: 1 | O28: =ROUND(CP28,2) -> 133.83 | P28: =ROUND((ROUND((AC28*AW28*I28),2)*BC28),2) -> 0.29 | Q28: =(ROUND((ROUND((((ET28*1.1))*AV28*I28),2)*BB28),2)+ROUND((ROUND(((AE28-((EU28*1.1)))*AV28*I28),2)*BS28),2)) -> 0 | R28: =ROUND((ROUND((AE28*AV28*I28),2)*BS28),2) -> 0 | S28: =ROUND((ROUND((AF28*AV28*I28),2)*BA28),2) -> 133.54 | T28: =ROUND(CU28*I28,2) -> 0 | U28: =CV28*I28 -> 9.5656 | V28: =CW28*I28 -> 0 | W28: =ROUND(CX28*I28,2) -> 0 | X28: =ROUND(CY28,2) -> 126.86 | Y28: =ROUND(CZ28,2) -> 70.78 | AA28: 56503348 | AB28: =ROUND((AC28+AD28+AF28),6) -> 123.138 | AC28: =ROUND((ES28),6) -> 0.29 | AD28: =ROUND(((((ET28*1.1))-((EU28*1.1)))+AE28),6) -> 0 | AE28: =ROUND(((EU28*1.1)),6) -> 0 | AF28: =ROUND(((EV28*1.1)),6) -> 122.848 | AG28: =ROUND((AP28),6) -> 0 | AH28: =((EW28*1.1)) -> 8.8 | AI28: =((EX28*1.1)) -> 0 | AJ28: =(AS28) -> 0 | AK28: 111.97 | AL28: 0.29 | AM28: 0 | AN28: 0 | AO28: 111.68 | AP28: 0 | AQ28: 8 | AR28: 0 | AS28: 0 | AT28: 95 | AU28: 53 | AV28: 1.087 | AW28: 1 | AZ28: 1 | BA28: 1 | BB28: 1 | BC28: 1 | BH28: 0 | BI28: 2 | BJ28: ТСН-2001.4. Доп. 1-42. Сб. 10, т. 136, поз. 5 | BM28: 69 | BN28: 0 | BO28: 4.10-136-5 | BP28: 1 | BQ28: 40 | BR28: 0 | BS28: 1 | BT28: 1 | BU28: 1 | BV28: 1 | BW28: 1 | BX28: 1 | BZ28: 95 | CA28: 53 | CE28: 30 | CF28: 0 | CG28: 0 | CM28: 0 | CO28: 0 | CP28: =(P28+Q28+S28) -> 133.83 | CQ28: =ROUND((ROUND((AC28*AW28*1),2)*BC28),2) -> 0.29 | CR28: =(ROUND((ROUND((((ET28*1.1))*AV28*1),2)*BB28),2)+ROUND((ROUND(((AE28-((EU28*1.1)))*AV28*1),2)*BS28),2)) -> 0 | CS28: =ROUND((ROUND((AE28*AV28*1),2)*BS28),2) -> 0 | CT28: =ROUND((ROUND((AF28*AV28*1),2)*BA28),2) -> 133.54 | CU28: =AG28 -> 0 | CV28: =(AH28*AV28) -> 9.5656 | CW28: =AI28 -> 0 | CX28: =AJ28 -> 0 | CY28: =(((S28+R28)*AT28)/100) -> 126.863 | CZ28: =(((S28+R28)*AU28)/100) -> 70.7762 | DE28: *1,1 | DF28: *1,1 | DG28: *1,1 | DI28: *1,1 | DJ28: *1,1 | DN28: 0 | DO28: 0 | DP28: 1 | DQ28: 1 | DU28: 1013 | DV28: 1 ШТ. | DW28: 1 ШТ. | DX28: 1 | EE28: 58162631 | EF28: 40 | EG28: Монтаж оборудования | EH28: 0 | EJ28: 2 | EK28: 69 | EL28: ТСН-2001.4-10. Монтаж радиотелевизионного и электронного оборудования | EM28: ТСН-2001.4-10-2 | EO28: Поправка: Гл.12.Прил.8.п.8. 5_12.00.01.11.003 | EQ28: 0 | ER28: 111.97 | ES28: 0.29 | ET28: 0 | EU28: 0 | EV28: 111.68 | EW28: 8 | EX28: 0 | EY28: 0 | FQ28: 0 | FR28: 0 | FS28: 0 | FX28: 95 | FY28: 53 | GD28: 1 | GF28: -860106978 | GG28: 2 | GH28: 1 | GI28: 2 | GJ28: 0 | GK28: 0 | GL28: =ROUND(IF(AND(BH28=3,BI28=3,FS28<>0),P28,0),2) -> 0 | GM28: =ROUND(O28+X28+Y28,2)+GX28 -> 331.47 | GN28: =IF(OR(BI28=0,BI28=1),GM28-GX28,0) -> 0 | GO28: =IF(BI28=2,GM28-GX28,0) -> 331.47 | GP28: =IF(BI28=4,GM28-GX28,0) -> 0 | GR28: 0 | GS28: 3 | GT28: 0 | GV28: =ROUND((GT28),6) -> 0 | GW28: 1 | GX28: =ROUND(HC28*I28,2) -> 0 | HA28: 0 | HB28: 0 | HC28: =GV28*GW28 -> 0 | HS28: 0 | IK28: 0
A29: 17 | B29: 1 | D29: =ROW(EtalonRes!A2) -> 2 | E29: 1 | F29: 4.10-136-5 | G29: Разные устройства, монтаж базового блока головной станции настенного типа | H29: 1 ШТ. | I29: 1 | J29: 0 | K29: 1 | O29: =ROUND(CP29,2) -> 7346.23 | P29: =ROUND((ROUND((AC29*AW29*I29),2)*BC29),2) -> 2.87 | Q29: =(ROUND((ROUND((((ET29*1.1))*AV29*I29),2)*BB29),2)+ROUND((ROUND(((AE29-((EU29*1.1)))*AV29*I29),2)*BS29),2)) -> 0 | R29: =ROUND((ROUND((AE29*AV29*I29),2)*BS29),2) -> 0 | S29: =ROUND((ROUND((AF29*AV29*I29),2)*BA29),2) -> 7343.36 | T29: =ROUND(CU29*I29,2) -> 0 | U29: =CV29*I29 -> 9.5656 | V29: =CW29*I29 -> 0 | W29: =ROUND(CX29*I29,2) -> 0 | X29: =ROUND(CY29,2) -> 6976.19 | Y29: =ROUND(CZ29,2) -> 3891.98 | AA29: 56503350 | AB29: =ROUND((AC29+AD29+AF29),6) -> 123.138 | AC29: =ROUND((ES29),6) -> 0.29 | AD29: =ROUND(((((ET29*1.1))-((EU29*1.1)))+AE29),6) -> 0 | AE29: =ROUND(((EU29*1.1)),6) -> 0 | AF29: =ROUND(((EV29*1.1)),6) -> 122.848 | AG29: =ROUND((AP29),6) -> 0 | AH29: =((EW29*1.1)) -> 8.8 | AI29: =((EX29*1.1)) -> 0 | AJ29: =(AS29) -> 0 | AK29: 111.97 | AL29: 0.29 | AM29: 0 | AN29: 0 | AO29: 111.68 | AP29: 0 | AQ29: 8 | AR29: 0 | AS29: 0 | AT29: 95 | AU29: 53 | AV29: 1.087 | AW29: 1 | AZ29: 1 | BA29: 54.99 | BB29: 1 | BC29: 9.9 | BH29: 0 | BI29: 2 | BJ29: ТСН-2001.4. Доп. 1-42. Сб. 10, т. 136, поз. 5 | BM29: 69 | BN29: 0 | BO29: 4.10-136-5 | BP29: 1 | BQ29: 40 | BR29: 0 | BS29: 54.99 | BT29: 1 | BU29: 1 | BV29: 1 | BW29: 1 | BX29: 1 | BZ29: 95 | CA29: 53 | CE29: 30 | CF29: 0 | CG29: 0 | CM29: 0 | CO29: 0 | CP29: =(P29+Q29+S29) -> 7346.23 | CQ29: =ROUND((ROUND((AC29*AW29*1),2)*BC29),2) -> 2.87 | CR29: =(ROUND((ROUND((((ET29*1.1))*AV29*1),2)*BB29),2)+ROUND((ROUND(((AE29-((EU29*1.1)))*AV29*1),2)*BS29),2)) -> 0 | CS29: =ROUND((ROUND((AE29*AV29*1),2)*BS29),2) -> 0 | CT29: =ROUND((ROUND((AF29*AV29*1),2)*BA29),2) -> 7343.36 | CU29: =AG29 -> 0 | CV29: =(AH29*AV29) -> 9.5656 | CW29: =AI29 -> 0 | CX29: =AJ29 -> 0 | CY29: =(((S29+R29)*AT29)/100) -> 6976.192 | CZ29: =(((S29+R29)*AU29)/100) -> 3891.9808 | DE29: *1,1 | DF29: *1,1 | DG29: *1,1 | DI29: *1,1 | DJ29: *1,1 | DN29: 0 | DO29: 0 | DP29: 1 | DQ29: 1 | DU29: 1013 | DV29: 1 ШТ. | DW29: 1 ШТ. | DX29: 1 | EE29: 58162631 | EF29: 40 | EG29: Монтаж оборудования | EH29: 0 | EJ29: 2 | EK29: 69 | EL29: ТСН-2001.4-10. Монтаж радиотелевизионного и электронного оборудования | EM29: ТСН-2001.4-10-2 | EO29: Поправка: Гл.12.Прил.8.п.8. 5_12.00.01.11.003 | EQ29: 0 | ER29: 111.97 | ES29: 0.29 | ET29: 0 | EU29: 0 | EV29: 111.68 | EW29: 8 | EX29: 0 | EY29: 0 | FQ29: 0 | FR29: 0 | FS29: 0 | FX29: 95 | FY29: 53 | GD29: 1 | GF29: -860106978 | GG29: 2 | GH29: 1 | GI29: 2 | GJ29: 0 | GK29: 0 | GL29: =ROUND(IF(AND(BH29=3,BI29=3,FS29<>0),P29,0),2) -> 0 | GM29: =ROUND(O29+X29+Y29,2)+GX29 -> 18214.4 | GN29: =IF(OR(BI29=0,BI29=1),GM29-GX29,0) -> 0 | GO29: =IF(BI29=2,GM29-GX29,0) -> 18214.4 | GP29: =IF(BI29=4,GM29-GX29,0) -> 0 | GR29: 0 | GS29: 3 | GT29: 0 | GV29: =ROUND((GT29),6) -> 0 | GW29: 1 | GX29: =ROUND(HC29*I29,2) -> 0 | HA29: 0 | HB29: 0 | HC29: =GV29*GW29 -> 0 | HS29: 0 | IK29: 0
A30: 18 | B30: 1 | E30: 1,1 | F30: КА 1 | G30: Головная станция СКТ "Мини-ГС" на базе оборудования VS50 Pro в шкафу с блоком розеток и автоматом | H30: шт. | I30: =I28*J30 -> 1 | J30: 1 | K30: 1 | O30: =ROUND(CP30,2) -> 8788.39 | P30: =ROUND((ROUND((AC30*I30),2)*BC30),2) -> 8788.39 | Q30: =(ROUND((ROUND(((ET30)*AV30*I30),2)*BB30),2)+ROUND((ROUND(((AE30-(EU30))*AV30*I30),2)*BS30),2)) -> 0 | R30: =ROUND((ROUND((AE30*AV30*I30),2)*BS30),2) -> 0 | S30: =ROUND((ROUND((AF30*AV30*I30),2)*BA30),2) -> 0 | T30: =ROUND(CU30*I30,2) -> 0 | U30: =CV30*I30 -> 0 | V30: =CW30*I30 -> 0 | W30: =ROUND(CX30*I30,2) -> 0 | X30: =ROUND(CY30,2) -> 0 | Y30: =ROUND(CZ30,2) -> 0 | AA30: 56503348 | AB30: =ROUND((AC30+AD30+AF30),6) -> 8788.39 | AC30: =ROUND((ES30),6) -> 8788.39 | AD30: =ROUND((((ET30)-(EU30))+AE30),6) -> 0 | AE30: =ROUND((EU30),6) -> 0 | AF30: =ROUND((EV30),6) -> 0 | AG30: =ROUND((AP30),6) -> 0 | AH30: =(EW30) -> 0 | AI30: =(EX30) -> 0 | AJ30: =(AS30) -> 0 | AK30: 8788.39 | AL30: 8788.39 | AM30: 0 | AN30: 0 | AO30: 0 | AP30: 0 | AQ30: 0 | AR30: 0 | AS30: 0 | AT30: 0 | AU30: 0 | AV30: 1 | AW30: 1 | AZ30: 1 | BA30: 1 | BB30: 1 | BC30: 1 | BH30: 3 | BI30: 3 | BM30: 746 | BN30: 0 | BP30: 0 | BQ30: 130 | BR30: 0 | BS30: 1 | BT30: 1 | BU30: 1 | BV30: 1 | BW30: 1 | BX30: 1 | BZ30: 95 | CA30: 53 | CE30: 30 | CF30: 0 | CG30: 0 | CM30: 0 | CO30: 0 | CP30: =(P30+Q30+S30) -> 8788.39 | CQ30: =ROUND((ROUND((AC30*1),2)*BC30),2) -> 8788.39 | CR30: =(ROUND((ROUND(((ET30)*AV30*1),2)*BB30),2)+ROUND((ROUND(((AE30-(EU30))*AV30*1),2)*BS30),2)) -> 0 | CS30: =ROUND((ROUND((AE30*AV30*1),2)*BS30),2) -> 0 | CT30: =ROUND((ROUND((AF30*AV30*1),2)*BA30),2) -> 0 | CU30: =AG30 -> 0 | CV30: =(AH30*AV30) -> 0 | CW30: =AI30 -> 0 | CX30: =AJ30 -> 0 | CY30: =(((S30+R30)*AT30)/100) -> 0 | CZ30: =(((S30+R30)*AU30)/100) -> 0 | DN30: 0 | DO30: 0 | DP30: 1 | DQ30: 1 | DU30: 1010 | DV30: шт. | DW30: шт. | DX30: 1 | EE30: 58162750 | EF30: 130 | EG30: Сметная стоимость оборудования | EH30: 0 | EJ30: 3 | EK30: 746 | EL30: ТСН-2001.13. Сметная стоимость оборудования | EM30: ТСН-2001.13 | EQ30: 0 | ER30: 0 | ES30: 8788.39 | ET30: 0 | EU30: 0 | EV30: 0 | EW30: 0 | EX30: 0 | FQ30: 0 | FR30: =P30 -> 8788.39 | FS30: 0 | FX30: 95 | FY30: 53 | GA30: [77 500 / 1,2 / 7,66] + 3% Трансп + 1,2% Заг.скл | GD30: 1 | GF30: 1252201046 | GG30: 2 | GH30: 4 | GI30: -2 | GJ30: 0 | GK30: 0 | GL30: =ROUND(IF(AND(BH30=3,BI30=3,FS30<>0),P30,0),2) -> 0 | GM30: =ROUND(O30+X30+Y30,2)+GX30 -> 8788.39 | GN30: =IF(OR(BI30=0,BI30=1),GM30-GX30,0) -> 0 | GO30: =IF(BI30=2,GM30-GX30,0) -> 0 | GP30: =IF(BI30=4,GM30-GX30,0) -> 0 | GR30: 0 | GS30: 2 | GT30: 0 | GV30: =ROUND((GT30),6) -> 0 | GW30: 1 | GX30: =ROUND(HC30*I30,2) -> 0 | HA30: 0 | HB30: 0 | HC30: =GV30*GW30 -> 0 | HE30: 3 | HF30: 1,2 | HS30: 0 | IK30: 0
A31: 18 | B31: 1 | E31: 1,1 | F31: КА 1 | G31: Головная станция СКТ "Мини-ГС" на базе оборудования VS50 Pro в шкафу с блоком розеток и автоматом | H31: шт. | I31: =I29*J31 -> 1 | J31: 1 | K31: 1 | O31: =ROUND(CP31,2) -> 67319.07 | P31: =ROUND((ROUND((AC31*I31),2)*BC31),2) -> 67319.07 | Q31: =(ROUND((ROUND(((ET31)*AV31*I31),2)*BB31),2)+ROUND((ROUND(((AE31-(EU31))*AV31*I31),2)*BS31),2)) -> 0 | R31: =ROUND((ROUND((AE31*AV31*I31),2)*BS31),2) -> 0 | S31: =ROUND((ROUND((AF31*AV31*I31),2)*BA31),2) -> 0 | T31: =ROUND(CU31*I31,2) -> 0 | U31: =CV31*I31 -> 0 | V31: =CW31*I31 -> 0 | W31: =ROUND(CX31*I31,2) -> 0 | X31: =ROUND(CY31,2) -> 0 | Y31: =ROUND(CZ31,2) -> 0 | AA31: 56503350 | AB31: =ROUND((AC31+AD31+AF31),6) -> 8788.39 | AC31: =ROUND((ES31),6) -> 8788.39 | AD31: =ROUND((((ET31)-(EU31))+AE31),6) -> 0 | AE31: =ROUND((EU31),6) -> 0 | AF31: =ROUND((EV31),6) -> 0 | AG31: =ROUND((AP31),6) -> 0 | AH31: =(EW31) -> 0 | AI31: =(EX31) -> 0 | AJ31: =(AS31) -> 0 | AK31: 8788.39 | AL31: 8788.39 | AM31: 0 | AN31: 0 | AO31: 0 | AP31: 0 | AQ31: 0 | AR31: 0 | AS31: 0 | AT31: 0 | AU31: 0 | AV31: 1 | AW31: 1 | AZ31: 1 | BA31: 1 | BB31: 1 | BC31: 7.66 | BH31: 3 | BI31: 3 | BM31: 746 | BN31: 0 | BP31: 0 | BQ31: 130 | BR31: 0 | BS31: 1 | BT31: 1 | BU31: 1 | BV31: 1 | BW31: 1 | BX31: 1 | BZ31: 95 | CA31: 53 | CE31: 30 | CF31: 0 | CG31: 0 | CM31: 0 | CO31: 0 | CP31: =(P31+Q31+S31) -> 67319.07 | CQ31: =ROUND((ROUND((AC31*1),2)*BC31),2) -> 67319.07 | CR31: =(ROUND((ROUND(((ET31)*AV31*1),2)*BB31),2)+ROUND((ROUND(((AE31-(EU31))*AV31*1),2)*BS31),2)) -> 0 | CS31: =ROUND((ROUND((AE31*AV31*1),2)*BS31),2) -> 0 | CT31: =ROUND((ROUND((AF31*AV31*1),2)*BA31),2) -> 0 | CU31: =AG31 -> 0 | CV31: =(AH31*AV31) -> 0 | CW31: =AI31 -> 0 | CX31: =AJ31 -> 0 | CY31: =(((S31+R31)*AT31)/100) -> 0 | CZ31: =(((S31+R31)*AU31)/100) -> 0 | DN31: 0 | DO31: 0 | DP31: 1 | DQ31: 1 | DU31: 1010 | DV31: шт. | DW31: шт. | DX31: 1 | EE31: 58162750 | EF31: 130 | EG31: Сметная стоимость оборудования | EH31: 0 | EJ31: 3 | EK31: 746 | EL31: ТСН-2001.13. Сметная стоимость оборудования | EM31: ТСН-2001.13 | EQ31: 0 | ER31: 8788.39 | ES31: 8788.39 | ET31: 0 | EU31: 0 | EV31: 0 | EW31: 0 | EX31: 0 | EZ31: 5 | FC31: 1 | FD31: 18 | FF31: 77500 | FQ31: 0 | FR31: =P31 -> 67319.07 | FS31: 0 | FX31: 95 | FY31: 53 | GA31: [77 500 / 1,2 / 7,66] + 3% Трансп + 1,2% Заг.скл | GD31: 1 | GF31: 1252201046 | GG31: 2 | GH31: 3 | GI31: 5 | GJ31: 0 | GK31: 0 | GL31: =ROUND(IF(AND(BH31=3,BI31=3,FS31<>0),P31,0),2) -> 0 | GM31: =ROUND(O31+X31+Y31,2)+GX31 -> 67319.07 | GN31: =IF(OR(BI31=0,BI31=1),GM31-GX31,0) -> 0 | GO31: =IF(BI31=2,GM31-GX31,0) -> 0 | GP31: =IF(BI31=4,GM31-GX31,0) -> 0 | GR31: 1 | GS31: 1 | GT31: 0 | GV31: =ROUND((GT31),6) -> 0 | GW31: 1 | GX31: =ROUND(HC31*I31,2) -> 0 | HA31: 0 | HB31: 0 | HC31: =GV31*GW31 -> 0 | HE31: 3 | HF31: 1,2 | HS31: 0 | IK31: 0
A32: 17 | B32: 1 | D32: =ROW(EtalonRes!A6) -> 6 | E32: 2 | F32: 4.11-2-1 | G32: Установка прибора на резьбовых соединениях | H32: 1 ШТ. | I32: 3 | J32: 0 | K32: 3 | O32: =ROUND(CP32,2) -> 15.9 | P32: =ROUND((ROUND((AC32*AW32*I32),2)*BC32),2) -> 2.43 | Q32: =(ROUND((ROUND((((ET32*1.1))*AV32*I32),2)*BB32),2)+ROUND((ROUND(((AE32-((EU32*1.1)))*AV32*I32),2)*BS32),2)) -> 0 | R32: =ROUND((ROUND((AE32*AV32*I32),2)*BS32),2) -> 0 | S32: =ROUND((ROUND((AF32*AV32*I32),2)*BA32),2) -> 13.47 | T32: =ROUND(CU32*I32,2) -> 0 | U32: =CV32*I32 -> 1.03653 | V32: =CW32*I32 -> 0 | W32: =ROUND(CX32*I32,2) -> 0 | X32: =ROUND(CY32,2) -> 12.12 | Y32: =ROUND(CZ32,2) -> 6.2 | AA32: 56503348 | AB32: =ROUND((AC32+AD32+AF32),6) -> 5.1 | AC32: =ROUND((ES32),6) -> 0.81 | AD32: =ROUND(((((ET32*1.1))-((EU32*1.1)))+AE32),6) -> 0 | AE32: =ROUND(((EU32*1.1)),6) -> 0 | AF32: =ROUND(((EV32*1.1)),6) -> 4.29 | AG32: =ROUND((AP32),6) -> 0 | AH32: =((EW32*1.1)) -> 0.33 | AI32: =((EX32*1.1)) -> 0 | AJ32: =(AS32) -> 0 | AK32: 4.71 | AL32: 0.81 | AM32: 0 | AN32: 0 | AO32: 3.9 | AP32: 0 | AQ32: 0.3 | AR32: 0 | AS32: 0 | AT32: 90 | AU32: 46 | AV32: 1.047 | AW32: 1 | AZ32: 1 | BA32: 1 | BB32: 1 | BC32: 1 | BH32: 0 | BI32: 2 | BJ32: ТСН-2001.4 Доп. 67, Сб. 11, т. 2, поз. 1 | BM32: 72 | BN32: 0 | BO32: 4.11-2-1 | BP32: 1 | BQ32: 40 | BR32: 0 | BS32: 1 | BT32: 1 | BU32: 1 | BV32: 1 | BW32: 1 | BX32: 1 | BZ32: 90 | CA32: 46 | CE32: 30 | CF32: 0 | CG32: 0 | CM32: 0 | CO32: 0 | CP32: =(P32+Q32+S32) -> 15.9 | CQ32: =ROUND((ROUND((AC32*AW32*1),2)*BC32),2) -> 0.81 | CR32: =(ROUND((ROUND((((ET32*1.1))*AV32*1),2)*BB32),2)+ROUND((ROUND(((AE32-((EU32*1.1)))*AV32*1),2)*BS32),2)) -> 0 | CS32: =ROUND((ROUND((AE32*AV32*1),2)*BS32),2) -> 0 | CT32: =ROUND((ROUND((AF32*AV32*1),2)*BA32),2) -> 4.49 | CU32: =AG32 -> 0 | CV32: =(AH32*AV32) -> 0.34551 | CW32: =AI32 -> 0 | CX32: =AJ32 -> 0 | CY32: =(((S32+R32)*AT32)/100) -> 12.123 | CZ32: =(((S32+R32)*AU32)/100) -> 6.1962 | DE32: *1,1 | DF32: *1,1 | DG32: *1,1 | DI32: *1,1 | DJ32: *1,1 | DN32: 0 | DO32: 0 | DP32: 1 | DQ32: 1 | DU32: 1013 | DV32: 1 ШТ. | DW32: 1 ШТ. | DX32: 1 | EE32: 58162634 | EF32: 40 | EG32: Монтаж оборудования | EH32: 0 | EJ32: 2 | EK32: 72 | EL32: ТСН-2001.4-11. Приборы и средства автоматизации и вычислительной техники | EM32: ТСН-2001.4-11-1 | EO32: Поправка: Гл.12.Прил.8.п.8. 5_12.00.01.11.003 | EQ32: 0 | ER32: 4.71 | ES32: 0.81 | ET32: 0 | EU32: 0 | EV32: 3.9 | EW32: 0.3 | EX32: 0 | EY32: 0 | FQ32: 0 | FR32: 0 | FS32: 0 | FX32: 90 | FY32: 46 | GD32: 1 | GF32: -1494899736 | GG32: 2 | GH32: 1 | GI32: 2 | GJ32: 0 | GK32: 0 | GL32: =ROUND(IF(AND(BH32=3,BI32=3,FS32<>0),P32,0),2) -> 0 | GM32: =ROUND(O32+X32+Y32,2)+GX32 -> 34.22 | GN32: =IF(OR(BI32=0,BI32=1),GM32-GX32,0) -> 0 | GO32: =IF(BI32=2,GM32-GX32,0) -> 34.22 | GP32: =IF(BI32=4,GM32-GX32,0) -> 0 | GR32: 0 | GS32: 3 | GT32: 0 | GV32: =ROUND((GT32),6) -> 0 | GW32: 1 | GX32: =ROUND(HC32*I32,2) -> 0 | HA32: 0 | HB32: 0 | HC32: =GV32*GW32 -> 0 | HS32: 0 | IK32: 0
A33: 17 | B33: 1 | D33: =ROW(EtalonRes!A10) -> 10 | E33: 2 | F33: 4.11-2-1 | G33: Установка прибора на резьбовых соединениях | H33: 1 ШТ. | I33: 3 | J33: 0 | K33: 3 | O33: =ROUND(CP33,2) -> 762.1 | P33: =ROUND((ROUND((AC33*AW33*I33),2)*BC33),2) -> 21.38 | Q33: =(ROUND((ROUND((((ET33*1.1))*AV33*I33),2)*BB33),2)+ROUND((ROUND(((AE33-((EU33*1.1)))*AV33*I33),2)*BS33),2)) -> 0 | R33: =ROUND((ROUND((AE33*AV33*I33),2)*BS33),2) -> 0 | S33: =ROUND((ROUND((AF33*AV33*I33),2)*BA33),2) -> 740.72 | T33: =ROUND(CU33*I33,2) -> 0 | U33: =CV33*I33 -> 1.03653 | V33: =CW33*I33 -> 0 | W33: =ROUND(CX33*I33,2) -> 0 | X33: =ROUND(CY33,2) -> 666.65 | Y33: =ROUND(CZ33,2) -> 340.73 | AA33: 56503350 | AB33: =ROUND((AC33+AD33+AF33),6) -> 5.1 | AC33: =ROUND((ES33),6) -> 0.81 | AD33: =ROUND(((((ET33*1.1))-((EU33*1.1)))+AE33),6) -> 0 | AE33: =ROUND(((EU33*1.1)),6) -> 0 | AF33: =ROUND(((EV33*1.1)),6) -> 4.29 | AG33: =ROUND((AP33),6) -> 0 | AH33: =((EW33*1.1)) -> 0.33 | AI33: =((EX33*1.1)) -> 0 | AJ33: =(AS33) -> 0 | AK33: 4.71 | AL33: 0.81 | AM33: 0 | AN33: 0 | AO33: 3.9 | AP33: 0 | AQ33: 0.3 | AR33: 0 | AS33: 0 | AT33: 90 | AU33: 46 | AV33: 1.047 | AW33: 1 | AZ33: 1 | BA33: 54.99 | BB33: 1 | BC33: 8.8 | BH33: 0 | BI33: 2 | BJ33: ТСН-2001.4 Доп. 67, Сб. 11, т. 2, поз. 1 | BM33: 72 | BN33: 0 | BO33: 4.11-2-1 | BP33: 1 | BQ33: 40 | BR33: 0 | BS33: 54.99 | BT33: 1 | BU33: 1 | BV33: 1 | BW33: 1 | BX33: 1 | BZ33: 90 | CA33: 46 | CE33: 30 | CF33: 0 | CG33: 0 | CM33: 0 | CO33: 0 | CP33: =(P33+Q33+S33) -> 762.1 | CQ33: =ROUND((ROUND((AC33*AW33*1),2)*BC33),2) -> 7.13 | CR33: =(ROUND((ROUND((((ET33*1.1))*AV33*1),2)*BB33),2)+ROUND((ROUND(((AE33-((EU33*1.1)))*AV33*1),2)*BS33),2)) -> 0 | CS33: =ROUND((ROUND((AE33*AV33*1),2)*BS33),2) -> 0 | CT33: =ROUND((ROUND((AF33*AV33*1),2)*BA33),2) -> 246.91 | CU33: =AG33 -> 0 | CV33: =(AH33*AV33) -> 0.34551 | CW33: =AI33 -> 0 | CX33: =AJ33 -> 0 | CY33: =(((S33+R33)*AT33)/100) -> 666.648 | CZ33: =(((S33+R33)*AU33)/100) -> 340.7312 | DE33: *1,1 | DF33: *1,1 | DG33: *1,1 | DI33: *1,1 | DJ33: *1,1 | DN33: 0 | DO33: 0 | DP33: 1 | DQ33: 1 | DU33: 1013 | DV33: 1 ШТ. | DW33: 1 ШТ. | DX33: 1 | EE33: 58162634 | EF33: 40 | EG33: Монтаж оборудования | EH33: 0 | EJ33: 2 | EK33: 72 | EL33: ТСН-2001.4-11. Приборы и средства автоматизации и вычислительной техники | EM33: ТСН-2001.4-11-1 | EO33: Поправка: Гл.12.Прил.8.п.8. 5_12.00.01.11.003 | EQ33: 0 | ER33: 4.71 | ES33: 0.81 | ET33: 0 | EU33: 0 | EV33: 3.9 | EW33: 0.3 | EX33: 0 | EY33: 0 | FQ33: 0 | FR33: 0 | FS33: 0 | FX33: 90 | FY33: 46 | GD33: 1 | GF33: -1494899736 | GG33: 2 | GH33: 1 | GI33: 2 | GJ33: 0 | GK33: 0 | GL33: =ROUND(IF(AND(BH33=3,BI33=3,FS33<>0),P33,0),2) -> 0 | GM33: =ROUND(O33+X33+Y33,2)+GX33 -> 1769.48 | GN33: =IF(OR(BI33=0,BI33=1),GM33-GX33,0) -> 0 | GO33: =IF(BI33=2,GM33-GX33,0) -> 1769.48 | GP33: =IF(BI33=4,GM33-GX33,0) -> 0 | GR33: 0 | GS33: 3 | GT33: 0 | GV33: =ROUND((GT33),6) -> 0 | GW33: 1 | GX33: =ROUND(HC33*I33,2) -> 0 | HA33: 0 | HB33: 0 | HC33: =GV33*GW33 -> 0 | HS33: 0 | IK33: 0
A34: 18 | B34: 1 | E34: 2,1 | F34: 1.14-1-551 | G34: Ответвитель направленный, абонентский, типа ОАТ 410 | H34: шт. | I34: =I32*J34 -> 1 | J34: 0.33333333 | K34: 0.3333333 | O34: =ROUND(CP34,2) -> 39.87 | P34: =ROUND((ROUND((AC34*AW34*I34),2)*BC34),2) -> 39.87 | Q34: =(ROUND((ROUND(((ET34)*AV34*I34),2)*BB34),2)+ROUND((ROUND(((AE34-(EU34))*AV34*I34),2)*BS34),2)) -> 0 | R34: =ROUND((ROUND((AE34*AV34*I34),2)*BS34),2) -> 0 | S34: =ROUND((ROUND((AF34*AV34*I34),2)*BA34),2) -> 0 | T34: =ROUND(CU34*I34,2) -> 0 | U34: =CV34*I34 -> 0 | V34: =CW34*I34 -> 0 | W34: =ROUND(CX34*I34,2) -> 0 | X34: =ROUND(CY34,2) -> 0 | Y34: =ROUND(CZ34,2) -> 0 | AA34: 56503348 | AB34: =ROUND((AC34+AD34+AF34),6) -> 39.87 | AC34: =ROUND((ES34),6) -> 39.87 | AD34: =ROUND((((ET34)-(EU34))+AE34),6) -> 0 | AE34: =ROUND((EU34),6) -> 0 | AF34: =ROUND((EV34),6) -> 0 | AG34: =ROUND((AP34),6) -> 0 | AH34: =(EW34) -> 0 | AI34: =(EX34) -> 0 | AJ34: =(AS34) -> 0 | AK34: 39.87 | AL34: 39.87 | AM34: 0 | AN34: 0 | AO34: 0 | AP34: 0 | AQ34: 0 | AR34: 0 | AS34: 0 | AT34: 90 | AU34: 46 | AV34: 1 | AW34: 1 | AZ34: 1 | BA34: 1 | BB34: 1 | BC34: 1 | BH34: 3 | BI34: 2 | BJ34: ТСН-2001.1 Доп. 73, Р. 14, о. 1, поз. 551 | BM34: 72 | BN34: 0 | BP34: 0 | BQ34: 40 | BR34: 0 | BS34: 1 | BT34: 1 | BU34: 1 | BV34: 1 | BW34: 1 | BX34: 1 | BZ34: 90 | CA34: 46 | CE34: 30 | CF34: 0 | CG34: 0 | CM34: 0 | CO34: 0 | CP34: =(P34+Q34+S34) -> 39.87 | CQ34: =ROUND((ROUND((AC34*AW34*1),2)*BC34),2) -> 39.87 | CR34: =(ROUND((ROUND(((ET34)*AV34*1),2)*BB34),2)+ROUND((ROUND(((AE34-(EU34))*AV34*1),2)*BS34),2)) -> 0 | CS34: =ROUND((ROUND((AE34*AV34*1),2)*BS34),2) -> 0 | CT34: =ROUND((ROUND((AF34*AV34*1),2)*BA34),2) -> 0 | CU34: =AG34 -> 0 | CV34: =(AH34*AV34) -> 0 | CW34: =AI34 -> 0 | CX34: =AJ34 -> 0 | CY34: =(((S34+R34)*AT34)/100) -> 0 | CZ34: =(((S34+R34)*AU34)/100) -> 0 | DN34: 0 | DO34: 0 | DP34: 1 | DQ34: 1 | DU34: 1010 | DV34: шт. | DW34: шт. | DX34: 1 | EE34: 58162634 | EF34: 40 | EG34: Монтаж оборудования | EH34: 0 | EJ34: 2 | EK34: 72 | EL34: ТСН-2001.4-11. Приборы и средства автоматизации и вычислительной техники | EM34: ТСН-2001.4-11-1 | EQ34: 0 | ER34: 39.87 | ES34: 39.87 | ET34: 0 | EU34: 0 | EV34: 0 | EW34: 0 | EX34: 0 | FQ34: 0 | FR34: 0 | FS34: 0 | FX34: 90 | FY34: 46 | GD34: 1 | GF34: -1718720141 | GG34: 2 | GH34: 1 | GI34: -2 | GJ34: 0 | GK34: 0 | GL34: =ROUND(IF(AND(BH34=3,BI34=3,FS34<>0),P34,0),2) -> 0 | GM34: =ROUND(O34+X34+Y34,2)+GX34 -> 39.87 | GN34: =IF(OR(BI34=0,BI34=1),GM34-GX34,0) -> 0 | GO34: =IF(BI34=2,GM34-GX34,0) -> 39.87 | GP34: =IF(BI34=4,GM34-GX34,0) -> 0 | GR34: 0 | GS34: 3 | GT34: 0 | GV34: =ROUND((GT34),6) -> 0 | GW34: 1 | GX34: =ROUND(HC34*I34,2) -> 0 | HA34: 0 | HB34: 0 | HC34: =GV34*GW34 -> 0 | HS34: 0 | IK34: 0
A35: 18 | B35: 1 | E35: 2,1 | F35: 1.14-1-551 | G35: Ответвитель направленный, абонентский, типа ОАТ 410 | H35: шт. | I35: =I33*J35 -> 1 | J35: 0.33333333 | K35: 0.3333333 | O35: =ROUND(CP35,2) -> 113.63 | P35: =ROUND((ROUND((AC35*AW35*I35),2)*BC35),2) -> 113.63 | Q35: =(ROUND((ROUND(((ET35)*AV35*I35),2)*BB35),2)+ROUND((ROUND(((AE35-(EU35))*AV35*I35),2)*BS35),2)) -> 0 | R35: =ROUND((ROUND((AE35*AV35*I35),2)*BS35),2) -> 0 | S35: =ROUND((ROUND((AF35*AV35*I35),2)*BA35),2) -> 0 | T35: =ROUND(CU35*I35,2) -> 0 | U35: =CV35*I35 -> 0 | V35: =CW35*I35 -> 0 | W35: =ROUND(CX35*I35,2) -> 0 | X35: =ROUND(CY35,2) -> 0 | Y35: =ROUND(CZ35,2) -> 0 | AA35: 56503350 | AB35: =ROUND((AC35+AD35+AF35),6) -> 39.87 | AC35: =ROUND((ES35),6) -> 39.87 | AD35: =ROUND((((ET35)-(EU35))+AE35),6) -> 0 | AE35: =ROUND((EU35),6) -> 0 | AF35: =ROUND((EV35),6) -> 0 | AG35: =ROUND((AP35),6) -> 0 | AH35: =(EW35) -> 0 | AI35: =(EX35) -> 0 | AJ35: =(AS35) -> 0 | AK35: 39.87 | AL35: 39.87 | AM35: 0 | AN35: 0 | AO35: 0 | AP35: 0 | AQ35: 0 | AR35: 0 | AS35: 0 | AT35: 90 | AU35: 46 | AV35: 1 | AW35: 1 | AZ35: 1 | BA35: 1 | BB35: 1 | BC35: 2.85 | BH35: 3 | BI35: 2 | BJ35: ТСН-2001.1 Доп. 73, Р. 14, о. 1, поз. 551 | BM35: 72 | BN35: 0 | BO35: 1.14-1-551 | BP35: 1 | BQ35: 40 | BR35: 0 | BS35: 1 | BT35: 1 | BU35: 1 | BV35: 1 | BW35: 1 | BX35: 1 | BZ35: 90 | CA35: 46 | CE35: 30 | CF35: 0 | CG35: 0 | CM35: 0 | CO35: 0 | CP35: =(P35+Q35+S35) -> 113.63 | CQ35: =ROUND((ROUND((AC35*AW35*1),2)*BC35),2) -> 113.63 | CR35: =(ROUND((ROUND(((ET35)*AV35*1),2)*BB35),2)+ROUND((ROUND(((AE35-(EU35))*AV35*1),2)*BS35),2)) -> 0 | CS35: =ROUND((ROUND((AE35*AV35*1),2)*BS35),2) -> 0 | CT35: =ROUND((ROUND((AF35*AV35*1),2)*BA35),2) -> 0 | CU35: =AG35 -> 0 | CV35: =(AH35*AV35) -> 0 | CW35: =AI35 -> 0 | CX35: =AJ35 -> 0 | CY35: =(((S35+R35)*AT35)/100) -> 0 | CZ35: =(((S35+R35)*AU35)/100) -> 0 | DN35: 0 | DO35: 0 | DP35: 1 | DQ35: 1 | DU35: 1010 | DV35: шт. | DW35: шт. | DX35: 1 | EE35: 58162634 | EF35: 40 | EG35: Монтаж оборудования | EH35: 0 | EJ35: 2 | EK35: 72 | EL35: ТСН-2001.4-11. Приборы и средства автоматизации и вычислительной техники | EM35: ТСН-2001.4-11-1 | EQ35: 0 | ER35: 39.87 | ES35: 39.87 | ET35: 0 | EU35: 0 | EV35: 0 | EW35: 0 | EX35: 0 | FQ35: 0 | FR35: 0 | FS35: 0 | FX35: 90 | FY35: 46 | GD35: 1 | GF35: -1718720141 | GG35: 2 | GH35: 1 | GI35: 2 | GJ35: 0 | GK35: 0 | GL35: =ROUND(IF(AND(BH35=3,BI35=3,FS35<>0),P35,0),2) -> 0 | GM35: =ROUND(O35+X35+Y35,2)+GX35 -> 113.63 | GN35: =IF(OR(BI35=0,BI35=1),GM35-GX35,0) -> 0 | GO35: =IF(BI35=2,GM35-GX35,0) -> 113.63 | GP35: =IF(BI35=4,GM35-GX35,0) -> 0 | GR35: 0 | GS35: 3 | GT35: 0 | GV35: =ROUND((GT35),6) -> 0 | GW35: 1 | GX35: =ROUND(HC35*I35,2) -> 0 | HA35: 0 | HB35: 0 | HC35: =GV35*GW35 -> 0 | HS35: 0 | IK35: 0
A36: 18 | B36: 1 | E36: 2,2 | F36: 1.14-1-552 | G36: Ответвитель направленный, абонентский, типа ОАТ 412 | H36: шт. | I36: =I32*J36 -> 1 | J36: 0.33333333 | K36: 0.3333333 | O36: =ROUND(CP36,2) -> 40.05 | P36: =ROUND((ROUND((AC36*AW36*I36),2)*BC36),2) -> 40.05 | Q36: =(ROUND((ROUND(((ET36)*AV36*I36),2)*BB36),2)+ROUND((ROUND(((AE36-(EU36))*AV36*I36),2)*BS36),2)) -> 0 | R36: =ROUND((ROUND((AE36*AV36*I36),2)*BS36),2) -> 0 | S36: =ROUND((ROUND((AF36*AV36*I36),2)*BA36),2) -> 0 | T36: =ROUND(CU36*I36,2) -> 0 | U36: =CV36*I36 -> 0 | V36: =CW36*I36 -> 0 | W36: =ROUND(CX36*I36,2) -> 0 | X36: =ROUND(CY36,2) -> 0 | Y36: =ROUND(CZ36,2) -> 0 | AA36: 56503348 | AB36: =ROUND((AC36+AD36+AF36),6) -> 40.05 | AC36: =ROUND((ES36),6) -> 40.05 | AD36: =ROUND((((ET36)-(EU36))+AE36),6) -> 0 | AE36: =ROUND((EU36),6) -> 0 | AF36: =ROUND((EV36),6) -> 0 | AG36: =ROUND((AP36),6) -> 0 | AH36: =(EW36) -> 0 | AI36: =(EX36) -> 0 | AJ36: =(AS36) -> 0 | AK36: 40.05 | AL36: 40.05 | AM36: 0 | AN36: 0 | AO36: 0 | AP36: 0 | AQ36: 0 | AR36: 0 | AS36: 0 | AT36: 90 | AU36: 46 | AV36: 1 | AW36: 1 | AZ36: 1 | BA36: 1 | BB36: 1 | BC36: 1 | BH36: 3 | BI36: 2 | BJ36: ТСН-2001.1 Доп. 73, Р. 14, о. 1, поз. 552 | BM36: 72 | BN36: 0 | BP36: 0 | BQ36: 40 | BR36: 0 | BS36: 1 | BT36: 1 | BU36: 1 | BV36: 1 | BW36: 1 | BX36: 1 | BZ36: 90 | CA36: 46 | CE36: 30 | CF36: 0 | CG36: 0 | CM36: 0 | CO36: 0 | CP36: =(P36+Q36+S36) -> 40.05 | CQ36: =ROUND((ROUND((AC36*AW36*1),2)*BC36),2) -> 40.05 | CR36: =(ROUND((ROUND(((ET36)*AV36*1),2)*BB36),2)+ROUND((ROUND(((AE36-(EU36))*AV36*1),2)*BS36),2)) -> 0 | CS36: =ROUND((ROUND((AE36*AV36*1),2)*BS36),2) -> 0 | CT36: =ROUND((ROUND((AF36*AV36*1),2)*BA36),2) -> 0 | CU36: =AG36 -> 0 | CV36: =(AH36*AV36) -> 0 | CW36: =AI36 -> 0 | CX36: =AJ36 -> 0 | CY36: =(((S36+R36)*AT36)/100) -> 0 | CZ36: =(((S36+R36)*AU36)/100) -> 0 | DN36: 0 | DO36: 0 | DP36: 1 | DQ36: 1 | DU36: 1010 | DV36: шт. | DW36: шт. | DX36: 1 | EE36: 58162634 | EF36: 40 | EG36: Монтаж оборудования | EH36: 0 | EJ36: 2 | EK36: 72 | EL36: ТСН-2001.4-11. Приборы и средства автоматизации и вычислительной техники | EM36: ТСН-2001.4-11-1 | EQ36: 0 | ER36: 40.05 | ES36: 40.05 | ET36: 0 | EU36: 0 | EV36: 0 | EW36: 0 | EX36: 0 | FQ36: 0 | FR36: 0 | FS36: 0 | FX36: 90 | FY36: 46 | GD36: 1 | GF36: -1000652985 | GG36: 2 | GH36: 1 | GI36: -2 | GJ36: 0 | GK36: 0 | GL36: =ROUND(IF(AND(BH36=3,BI36=3,FS36<>0),P36,0),2) -> 0 | GM36: =ROUND(O36+X36+Y36,2)+GX36 -> 40.05 | GN36: =IF(OR(BI36=0,BI36=1),GM36-GX36,0) -> 0 | GO36: =IF(BI36=2,GM36-GX36,0) -> 40.05 | GP36: =IF(BI36=4,GM36-GX36,0) -> 0 | GR36: 0 | GS36: 3 | GT36: 0 | GV36: =ROUND((GT36),6) -> 0 | GW36: 1 | GX36: =ROUND(HC36*I36,2) -> 0 | HA36: 0 | HB36: 0 | HC36: =GV36*GW36 -> 0 | HS36: 0 | IK36: 0
A37: 18 | B37: 1 | E37: 2,2 | F37: 1.14-1-552 | G37: Ответвитель направленный, абонентский, типа ОАТ 412 | H37: шт. | I37: =I33*J37 -> 1 | J37: 0.33333333 | K37: 0.3333333 | O37: =ROUND(CP37,2) -> 113.34 | P37: =ROUND((ROUND((AC37*AW37*I37),2)*BC37),2) -> 113.34 | Q37: =(ROUND((ROUND(((ET37)*AV37*I37),2)*BB37),2)+ROUND((ROUND(((AE37-(EU37))*AV37*I37),2)*BS37),2)) -> 0 | R37: =ROUND((ROUND((AE37*AV37*I37),2)*BS37),2) -> 0 | S37: =ROUND((ROUND((AF37*AV37*I37),2)*BA37),2) -> 0 | T37: =ROUND(CU37*I37,2) -> 0 | U37: =CV37*I37 -> 0 | V37: =CW37*I37 -> 0 | W37: =ROUND(CX37*I37,2) -> 0 | X37: =ROUND(CY37,2) -> 0 | Y37: =ROUND(CZ37,2) -> 0 | AA37: 56503350 | AB37: =ROUND((AC37+AD37+AF37),6) -> 40.05 | AC37: =ROUND((ES37),6) -> 40.05 | AD37: =ROUND((((ET37)-(EU37))+AE37),6) -> 0 | AE37: =ROUND((EU37),6) -> 0 | AF37: =ROUND((EV37),6) -> 0 | AG37: =ROUND((AP37),6) -> 0 | AH37: =(EW37) -> 0 | AI37: =(EX37) -> 0 | AJ37: =(AS37) -> 0 | AK37: 40.05 | AL37: 40.05 | AM37: 0 | AN37: 0 | AO37: 0 | AP37: 0 | AQ37: 0 | AR37: 0 | AS37: 0 | AT37: 90 | AU37: 46 | AV37: 1 | AW37: 1 | AZ37: 1 | BA37: 1 | BB37: 1 | BC37: 2.83 | BH37: 3 | BI37: 2 | BJ37: ТСН-2001.1 Доп. 73, Р. 14, о. 1, поз. 552 | BM37: 72 | BN37: 0 | BO37: 1.14-1-552 | BP37: 1 | BQ37: 40 | BR37: 0 | BS37: 1 | BT37: 1 | BU37: 1 | BV37: 1 | BW37: 1 | BX37: 1 | BZ37: 90 | CA37: 46 | CE37: 30 | CF37: 0 | CG37: 0 | CM37: 0 | CO37: 0 | CP37: =(P37+Q37+S37) -> 113.34 | CQ37: =ROUND((ROUND((AC37*AW37*1),2)*BC37),2) -> 113.34 | CR37: =(ROUND((ROUND(((ET37)*AV37*1),2)*BB37),2)+ROUND((ROUND(((AE37-(EU37))*AV37*1),2)*BS37),2)) -> 0 | CS37: =ROUND((ROUND((AE37*AV37*1),2)*BS37),2) -> 0 | CT37: =ROUND((ROUND((AF37*AV37*1),2)*BA37),2) -> 0 | CU37: =AG37 -> 0 | CV37: =(AH37*AV37) -> 0 | CW37: =AI37 -> 0 | CX37: =AJ37 -> 0 | CY37: =(((S37+R37)*AT37)/100) -> 0 | CZ37: =(((S37+R37)*AU37)/100) -> 0 | DN37: 0 | DO37: 0 | DP37: 1 | DQ37: 1 | DU37: 1010 | DV37: шт. | DW37: шт. | DX37: 1 | EE37: 58162634 | EF37: 40 | EG37: Монтаж оборудования | EH37: 0 | EJ37: 2 | EK37: 72 | EL37: ТСН-2001.4-11. Приборы и средства автоматизации и вычислительной техники | EM37: ТСН-2001.4-11-1 | EQ37: 0 | ER37: 40.05 | ES37: 40.05 | ET37: 0 | EU37: 0 | EV37: 0 | EW37: 0 | EX37: 0 | FQ37: 0 | FR37: 0 | FS37: 0 | FX37: 90 | FY37: 46 | GD37: 1 | GF37: -1000652985 | GG37: 2 | GH37: 1 | GI37: 2 | GJ37: 0 | GK37: 0 | GL37: =ROUND(IF(AND(BH37=3,BI37=3,FS37<>0),P37,0),2) -> 0 | GM37: =ROUND(O37+X37+Y37,2)+GX37 -> 113.34 | GN37: =IF(OR(BI37=0,BI37=1),GM37-GX37,0) -> 0 | GO37: =IF(BI37=2,GM37-GX37,0) -> 113.34 | GP37: =IF(BI37=4,GM37-GX37,0) -> 0 | GR37: 0 | GS37: 3 | GT37: 0 | GV37: =ROUND((GT37),6) -> 0 | GW37: 1 | GX37: =ROUND(HC37*I37,2) -> 0 | HA37: 0 | HB37: 0 | HC37: =GV37*GW37 -> 0 | HS37: 0 | IK37: 0
A38: 18 | B38: 1 | E38: 2,3 | F38: 1.14-1-553 | G38: Ответвитель направленный, абонентский, типа ОАТ 416 | H38: шт. | I38: =I32*J38 -> 1 | J38: 0.33333333 | K38: 0.3333333 | O38: =ROUND(CP38,2) -> 40.17 | P38: =ROUND((ROUND((AC38*AW38*I38),2)*BC38),2) -> 40.17 | Q38: =(ROUND((ROUND(((ET38)*AV38*I38),2)*BB38),2)+ROUND((ROUND(((AE38-(EU38))*AV38*I38),2)*BS38),2)) -> 0 | R38: =ROUND((ROUND((AE38*AV38*I38),2)*BS38),2) -> 0 | S38: =ROUND((ROUND((AF38*AV38*I38),2)*BA38),2) -> 0 | T38: =ROUND(CU38*I38,2) -> 0 | U38: =CV38*I38 -> 0 | V38: =CW38*I38 -> 0 | W38: =ROUND(CX38*I38,2) -> 0 | X38: =ROUND(CY38,2) -> 0 | Y38: =ROUND(CZ38,2) -> 0 | AA38: 56503348 | AB38: =ROUND((AC38+AD38+AF38),6) -> 40.17 | AC38: =ROUND((ES38),6) -> 40.17 | AD38: =ROUND((((ET38)-(EU38))+AE38),6) -> 0 | AE38: =ROUND((EU38),6) -> 0 | AF38: =ROUND((EV38),6) -> 0 | AG38: =ROUND((AP38),6) -> 0 | AH38: =(EW38) -> 0 | AI38: =(EX38) -> 0 | AJ38: =(AS38) -> 0 | AK38: 40.17 | AL38: 40.17 | AM38: 0 | AN38: 0 | AO38: 0 | AP38: 0 | AQ38: 0 | AR38: 0 | AS38: 0 | AT38: 90 | AU38: 46 | AV38: 1 | AW38: 1 | AZ38: 1 | BA38: 1 | BB38: 1 | BC38: 1 | BH38: 3 | BI38: 2 | BJ38: ТСН-2001.1 Доп. 73, Р. 14, о. 1, поз. 553 | BM38: 72 | BN38: 0 | BP38: 0 | BQ38: 40 | BR38: 0 | BS38: 1 | BT38: 1 | BU38: 1 | BV38: 1 | BW38: 1 | BX38: 1 | BZ38: 90 | CA38: 46 | CE38: 30 | CF38: 0 | CG38: 0 | CM38: 0 | CO38: 0 | CP38: =(P38+Q38+S38) -> 40.17 | CQ38: =ROUND((ROUND((AC38*AW38*1),2)*BC38),2) -> 40.17 | CR38: =(ROUND((ROUND(((ET38)*AV38*1),2)*BB38),2)+ROUND((ROUND(((AE38-(EU38))*AV38*1),2)*BS38),2)) -> 0 | CS38: =ROUND((ROUND((AE38*AV38*1),2)*BS38),2) -> 0 | CT38: =ROUND((ROUND((AF38*AV38*1),2)*BA38),2) -> 0 | CU38: =AG38 -> 0 | CV38: =(AH38*AV38) -> 0 | CW38: =AI38 -> 0 | CX38: =AJ38 -> 0 | CY38: =(((S38+R38)*AT38)/100) -> 0 | CZ38: =(((S38+R38)*AU38)/100) -> 0 | DN38: 0 | DO38: 0 | DP38: 1 | DQ38: 1 | DU38: 1010 | DV38: шт. | DW38: шт. | DX38: 1 | EE38: 58162634 | EF38: 40 | EG38: Монтаж оборудования | EH38: 0 | EJ38: 2 | EK38: 72 | EL38: ТСН-2001.4-11. Приборы и средства автоматизации и вычислительной техники | EM38: ТСН-2001.4-11-1 | EQ38: 0 | ER38: 40.17 | ES38: 40.17 | ET38: 0 | EU38: 0 | EV38: 0 | EW38: 0 | EX38: 0 | FQ38: 0 | FR38: 0 | FS38: 0 | FX38: 90 | FY38: 46 | GD38: 1 | GF38: -872873899 | GG38: 2 | GH38: 1 | GI38: -2 | GJ38: 0 | GK38: 0 | GL38: =ROUND(IF(AND(BH38=3,BI38=3,FS38<>0),P38,0),2) -> 0 | GM38: =ROUND(O38+X38+Y38,2)+GX38 -> 40.17 | GN38: =IF(OR(BI38=0,BI38=1),GM38-GX38,0) -> 0 | GO38: =IF(BI38=2,GM38-GX38,0) -> 40.17 | GP38: =IF(BI38=4,GM38-GX38,0) -> 0 | GR38: 0 | GS38: 3 | GT38: 0 | GV38: =ROUND((GT38),6) -> 0 | GW38: 1 | GX38: =ROUND(HC38*I38,2) -> 0 | HA38: 0 | HB38: 0 | HC38: =GV38*GW38 -> 0 | HS38: 0 | IK38: 0
A39: 18 | B39: 1 | E39: 2,3 | F39: 1.14-1-553 | G39: Ответвитель направленный, абонентский, типа ОАТ 416 | H39: шт. | I39: =I33*J39 -> 1 | J39: 0.33333333 | K39: 0.3333333 | O39: =ROUND(CP39,2) -> 113.68 | P39: =ROUND((ROUND((AC39*AW39*I39),2)*BC39),2) -> 113.68 | Q39: =(ROUND((ROUND(((ET39)*AV39*I39),2)*BB39),2)+ROUND((ROUND(((AE39-(EU39))*AV39*I39),2)*BS39),2)) -> 0 | R39: =ROUND((ROUND((AE39*AV39*I39),2)*BS39),2) -> 0 | S39: =ROUND((ROUND((AF39*AV39*I39),2)*BA39),2) -> 0 | T39: =ROUND(CU39*I39,2) -> 0 | U39: =CV39*I39 -> 0 | V39: =CW39*I39 -> 0 | W39: =ROUND(CX39*I39,2) -> 0 | X39: =ROUND(CY39,2) -> 0 | Y39: =ROUND(CZ39,2) -> 0 | AA39: 56503350 | AB39: =ROUND((AC39+AD39+AF39),6) -> 40.17 | AC39: =ROUND((ES39),6) -> 40.17 | AD39: =ROUND((((ET39)-(EU39))+AE39),6) -> 0 | AE39: =ROUND((EU39),6) -> 0 | AF39: =ROUND((EV39),6) -> 0 | AG39: =ROUND((AP39),6) -> 0 | AH39: =(EW39) -> 0 | AI39: =(EX39) -> 0 | AJ39: =(AS39) -> 0 | AK39: 40.17 | AL39: 40.17 | AM39: 0 | AN39: 0 | AO39: 0 | AP39: 0 | AQ39: 0 | AR39: 0 | AS39: 0 | AT39: 90 | AU39: 46 | AV39: 1 | AW39: 1 | AZ39: 1 | BA39: 1 | BB39: 1 | BC39: 2.83 | BH39: 3 | BI39: 2 | BJ39: ТСН-2001.1 Доп. 73, Р. 14, о. 1, поз. 553 | BM39: 72 | BN39: 0 | BO39: 1.14-1-553 | BP39: 1 | BQ39: 40 | BR39: 0 | BS39: 1 | BT39: 1 | BU39: 1 | BV39: 1 | BW39: 1 | BX39: 1 | BZ39: 90 | CA39: 46 | CE39: 30 | CF39: 0 | CG39: 0 | CM39: 0 | CO39: 0 | CP39: =(P39+Q39+S39) -> 113.68 | CQ39: =ROUND((ROUND((AC39*AW39*1),2)*BC39),2) -> 113.68 | CR39: =(ROUND((ROUND(((ET39)*AV39*1),2)*BB39),2)+ROUND((ROUND(((AE39-(EU39))*AV39*1),2)*BS39),2)) -> 0 | CS39: =ROUND((ROUND((AE39*AV39*1),2)*BS39),2) -> 0 | CT39: =ROUND((ROUND((AF39*AV39*1),2)*BA39),2) -> 0 | CU39: =AG39 -> 0 | CV39: =(AH39*AV39) -> 0 | CW39: =AI39 -> 0 | CX39: =AJ39 -> 0 | CY39: =(((S39+R39)*AT39)/100) -> 0 | CZ39: =(((S39+R39)*AU39)/100) -> 0 | DN39: 0 | DO39: 0 | DP39: 1 | DQ39: 1 | DU39: 1010 | DV39: шт. | DW39: шт. | DX39: 1 | EE39: 58162634 | EF39: 40 | EG39: Монтаж оборудования | EH39: 0 | EJ39: 2 | EK39: 72 | EL39: ТСН-2001.4-11. Приборы и средства автоматизации и вычислительной техники | EM39: ТСН-2001.4-11-1 | EQ39: 0 | ER39: 40.17 | ES39: 40.17 | ET39: 0 | EU39: 0 | EV39: 0 | EW39: 0 | EX39: 0 | FQ39: 0 | FR39: 0 | FS39: 0 | FX39: 90 | FY39: 46 | GD39: 1 | GF39: -872873899 | GG39: 2 | GH39: 1 | GI39: 2 | GJ39: 0 | GK39: 0 | GL39: =ROUND(IF(AND(BH39=3,BI39=3,FS39<>0),P39,0),2) -> 0 | GM39: =ROUND(O39+X39+Y39,2)+GX39 -> 113.68 | GN39: =IF(OR(BI39=0,BI39=1),GM39-GX39,0) -> 0 | GO39: =IF(BI39=2,GM39-GX39,0) -> 113.68 | GP39: =IF(BI39=4,GM39-GX39,0) -> 0 | GR39: 0 | GS39: 3 | GT39: 0 | GV39: =ROUND((GT39),6) -> 0 | GW39: 1 | GX39: =ROUND(HC39*I39,2) -> 0 | HA39: 0 | HB39: 0 | HC39: =GV39*GW39 -> 0 | HS39: 0 | IK39: 0
A41: 51 | B41: =B24 -> 1 | C41: =A24 -> 4 | D41: =ROW(A24) -> 24 | F41: =IF(F24<>"",F24,"") | G41: =IF(G24<>"",G24,"") -> Оборудование | H41: 0 | O41: =ROUND(AB41,2) -> 9058.21 | P41: =ROUND(AC41,2) -> 8911.2 | Q41: =ROUND(AD41,2) -> 0 | R41: =ROUND(AE41,2) -> 0 | S41: =ROUND(AF41,2) -> 147.01 | T41: =ROUND(AG41,2) -> 0 | U41: =AH41 -> 10.60213 | V41: =AI41 -> 0 | W41: =ROUND(AJ41,2) -> 0 | X41: =ROUND(AK41,2) -> 138.98 | Y41: =ROUND(AL41,2) -> 76.98 | AB41: =ROUND(SUMIF(AA28:AA39,"=56503348",O28:O39),2) -> 9058.21 | AC41: =ROUND(SUMIF(AA28:AA39,"=56503348",P28:P39),2) -> 8911.2 | AD41: =ROUND(SUMIF(AA28:AA39,"=56503348",Q28:Q39),2) -> 0 | AE41: =ROUND(SUMIF(AA28:AA39,"=56503348",R28:R39),2) -> 0 | AF41: =ROUND(SUMIF(AA28:AA39,"=56503348",S28:S39),2) -> 147.01 | AG41: =ROUND(SUMIF(AA28:AA39,"=56503348",T28:T39),2) -> 0 | AH41: =SUMIF(AA28:AA39,"=56503348",U28:U39) -> 10.60213 | AI41: =SUMIF(AA28:AA39,"=56503348",V28:V39) -> 0 | AJ41: =ROUND(SUMIF(AA28:AA39,"=56503348",W28:W39),2) -> 0 | AK41: =ROUND(SUMIF(AA28:AA39,"=56503348",X28:X39),2) -> 138.98 | AL41: =ROUND(SUMIF(AA28:AA39,"=56503348",Y28:Y39),2) -> 76.98 | AO41: =ROUND(BX41,2) -> 0 | AP41: =ROUND(BY41,2) -> 8788.39 | AQ41: =ROUND(BZ41,2) -> 0 | AR41: =ROUND(CA41,2) -> 9274.17 | AS41: =ROUND(CB41,2) -> 0 | AT41: =ROUND(CC41,2) -> 485.78 | AU41: =ROUND(CD41,2) -> 0 | AV41: =ROUND(CE41,2) -> 8911.2 | ... BD41: =ROUND(CM41,2) -> 0 | BX41: =ROUND(SUMIF(AA28:AA39,"=56503348",FQ28:FQ39),2) -> 0 | BY41: =ROUND(SUMIF(AA28:AA39,"=56503348",FR28:FR39),2) -> 8788.39 | BZ41: =ROUND(SUMIF(AA28:AA39,"=56503348",GL28:GL39),2) -> 0 | CA41: =ROUND(SUMIF(AA28:AA39,"=56503348",GM28:GM39),2) -> 9274.17 | CB41: =ROUND(SUMIF(AA28:AA39,"=56503348",GN28:GN39),2) -> 0 | CC41: =ROUND(SUMIF(AA28:AA39,"=56503348",GO28:GO39),2) -> 485.78 | CD41: =ROUND(SUMIF(AA28:AA39,"=56503348",GP28:GP39),2) -> 0 | CE41: =AC41-BX41 -> 8911.2 | CF41: =AC41-BY41 -> 122.81 | CG41: =BX41-BZ41 -> 0 | CH41: =AC41-BX41-BY41+BZ41 -> 122.81 | CI41: =BY41-BZ41 -> 8788.39 | CJ41: =ROUND(SUMIF(AA28:AA39,"=56503348",GX28:GX39),2) -> 0 | CK41: =ROUND(SUMIF(AA28:AA39,"=56503348",GY28:GY39),2) -> 0 | CL41: =ROUND(SUMIF(AA28:AA39,"=56503348",GZ28:GZ39),2) -> 0 | CM41: =ROUND(SUMIF(AA28:AA39,"=56503348",HD28:HD39),2) -> 0 | DG41: =ROUND(DT41,2) -> 75768.05 | DH41: =ROUND(DU41,2) -> 67683.97 | DI41: =ROUND(DV41,2) -> 0 | DJ41: =ROUND(DW41,2) -> 0 | DK41: =ROUND(DX41,2) -> 8084.08 | DL41: =ROUND(DY41,2) -> 0 | DM41: =DZ41 -> 10.60213 | DN41: =EA41 -> 0 | DO41: =ROUND(EB41,2) -> 0 | DP41: =ROUND(EC41,2) -> 7642.84 | DQ41: =ROUND(ED41,2) -> 4232.71 | DT41: =ROUND(SUMIF(AA28:AA39,"=56503350",O28:O39),2) -> 75768.05 | DU41: =ROUND(SUMIF(AA28:AA39,"=56503350",P28:P39),2) -> 67683.97 | DV41: =ROUND(SUMIF(AA28:AA39,"=56503350",Q28:Q39),2) -> 0 | DW41: =ROUND(SUMIF(AA28:AA39,"=56503350",R28:R39),2) -> 0 | DX41: =ROUND(SUMIF(AA28:AA39,"=56503350",S28:S39),2) -> 8084.08 | DY41: =ROUND(SUMIF(AA28:AA39,"=56503350",T28:T39),2) -> 0 | DZ41: =SUMIF(AA28:AA39,"=56503350",U28:U39) -> 10.60213 | EA41: =SUMIF(AA28:AA39,"=56503350",V28:V39) -> 0 | EB41: =ROUND(SUMIF(AA28:AA39,"=56503350",W28:W39),2) -> 0 | EC41: =ROUND(SUMIF(AA28:AA39,"=56503350",X28:X39),2) -> 7642.84 | ED41: =ROUND(SUMIF(AA28:AA39,"=56503350",Y28:Y39),2) -> 4232.71 | EG41: =ROUND(FP41,2) -> 0 | EH41: =ROUND(FQ41,2) -> 67319.07 | EI41: =ROUND(FR41,2) -> 0 | EJ41: =ROUND(FS41,2) -> 87643.6 | EK41: =ROUND(FT41,2) -> 0 | EL41: =ROUND(FU41,2) -> 20324.53 | EM41: =ROUND(FV41,2) -> 0 | EN41: =ROUND(FW41,2) -> 67683.97 | ... EV41: =ROUND(GE41,2) -> 0 | FP41: =ROUND(SUMIF(AA28:AA39,"=56503350",FQ28:FQ39),2) -> 0 | FQ41: =ROUND(SUMIF(AA28:AA39,"=56503350",FR28:FR39),2) -> 67319.07 | FR41: =ROUND(SUMIF(AA28:AA39,"=56503350",GL28:GL39),2) -> 0 | FS41: =ROUND(SUMIF(AA28:AA39,"=56503350",GM28:GM39),2) -> 87643.6 | FT41: =ROUND(SUMIF(AA28:AA39,"=56503350",GN28:GN39),2) -> 0 | FU41: =ROUND(SUMIF(AA28:AA39,"=56503350",GO28:GO39),2) -> 20324.53 | FV41: =ROUND(SUMIF(AA28:AA39,"=56503350",GP28:GP39),2) -> 0 | FW41: =DU41-FP41 -> 67683.97 | FX41: =DU41-FQ41 -> 364.9 | FY41: =FP41-FR41 -> 0 | FZ41: =DU41-FP41-FQ41+FR41 -> 364.9 | GA41: =FQ41-FR41 -> 67319.07 | GB41: =ROUND(SUMIF(AA28:AA39,"=56503350",GX28:GX39),2) -> 0 | GC41: =ROUND(SUMIF(AA28:AA39,"=56503350",GY28:GY39),2) -> 0 | GD41: =ROUND(SUMIF(AA28:AA39,"=56503350",GZ28:GZ39),2) -> 0 | GE41: =ROUND(SUMIF(AA28:AA39,"=56503350",HD28:HD39),2) -> 0 | GX41: 0
A43: 50 | B43: 0 | C43: 0 | D43: 1 | E43: 201 | F43: =ROUND(Source!O41,O43) -> 9058.21 | G43: ПЗ | H43: Прямые затраты | K43: 201 | L43: 1 | M43: 3 | O43: 2 | P43: =ROUND(Source!DG41,O43) -> 75768.05 | W43: 9058.21 | X43: 1 | Y43: 9058.21 | Z43: 75768.05 | AA43: 1 | AB43: 75768.05
A44: 50 | B44: 0 | C44: 0 | D44: 1 | E44: 202 | F44: =ROUND(Source!P41,O44) -> 8911.2 | G44: СтМатОб | H44: Стоимость материальных ресурсов (всего) | K44: 202 | L44: 2 | M44: 3 | O44: 2 | P44: =ROUND(Source!DH41,O44) -> 67683.97 | W44: 8911.2 | X44: 1 | Y44: 8911.2 | Z44: 67683.97 | AA44: 1 | AB44: 67683.97
A45: 50 | B45: 0 | C45: 0 | D45: 1 | E45: 222 | F45: =ROUND(Source!AO41,O45) -> 0 | G45: СтМатОбЗак | H45: Стоимость материалов и оборудования заказчика | K45: 222 | L45: 3 | M45: 3 | O45: 2 | P45: =ROUND(Source!EG41,O45) -> 0 | W45: 0 | X45: 1 | Y45: 0 | Z45: 0 | AA45: 1 | AB45: 0
A46: 50 | B46: 0 | C46: 0 | D46: 1 | E46: 225 | F46: =ROUND(Source!AV41,O46) -> 8911.2 | G46: СтМатОбПод | H46: Стоимость материалов и оборудования подрядчика | K46: 225 | L46: 4 | M46: 3 | O46: 2 | P46: =ROUND(Source!EN41,O46) -> 67683.97 | W46: 8911.2 | X46: 1 | Y46: 8911.2 | Z46: 67683.97 | AA46: 1 | AB46: 67683.97
A47: 50 | B47: 0 | C47: 0 | D47: 1 | E47: 226 | F47: =ROUND(Source!AW41,O47) -> 122.81 | G47: СтМат | H47: Стоимость материалов (всего) | K47: 226 | L47: 5 | M47: 3 | O47: 2 | P47: =ROUND(Source!EO41,O47) -> 364.9 | W47: 122.81 | X47: 1 | Y47: 122.81 | Z47: 364.9 | AA47: 1 | AB47: 364.9
A48: 50 | B48: 0 | C48: 0 | D48: 1 | E48: 227 | F48: =ROUND(Source!AX41,O48) -> 0 | G48: СтМатЗак | H48: Стоимость материалов заказчика | K48: 227 | L48: 6 | M48: 3 | O48: 2 | P48: =ROUND(Source!EP41,O48) -> 0 | W48: 0 | X48: 1 | Y48: 0 | Z48: 0 | AA48: 1 | AB48: 0
A49: 50 | B49: 0 | C49: 0 | D49: 1 | E49: 228 | F49: =ROUND(Source!AY41,O49) -> 122.81 | G49: СтМатПод | H49: Стоимость материалов подрядчика | K49: 228 | L49: 7 | M49: 3 | O49: 2 | P49: =ROUND(Source!EQ41,O49) -> 364.9 | W49: 122.81 | X49: 1 | Y49: 122.81 | Z49: 364.9 | AA49: 1 | AB49: 364.9
A50: 50 | B50: 0 | C50: 0 | D50: 1 | E50: 216 | F50: =ROUND(Source!AP41,O50) -> 8788.39 | G50: Оборуд | H50: Стоимость оборудования (всего) | K50: 216 | L50: 8 | M50: 3 | O50: 2 | P50: =ROUND(Source!EH41,O50) -> 67319.07 | W50: 8788.39 | X50: 1 | Y50: 8788.39 | Z50: 67319.07 | AA50: 1 | AB50: 67319.07
A51: 50 | B51: 0 | C51: 0 | D51: 1 | E51: 223 | F51: =ROUND(Source!AQ41,O51) -> 0 | G51: ОборудЗак | H51: Стоимость оборудования заказчика | K51: 223 | L51: 9 | M51: 3 | O51: 2 | P51: =ROUND(Source!EI41,O51) -> 0 | W51: 0 | X51: 1 | Y51: 0 | Z51: 0 | AA51: 1 | AB51: 0
A52: 50 | B52: 0 | C52: 0 | D52: 1 | E52: 229 | F52: =ROUND(Source!AZ41,O52) -> 8788.39 | G52: ОборудПод | H52: Стоимость оборудования подрядчика | K52: 229 | L52: 10 | M52: 3 | O52: 2 | P52: =ROUND(Source!ER41,O52) -> 67319.07 | W52: 8788.39 | X52: 1 | Y52: 8788.39 | Z52: 67319.07 | AA52: 1 | AB52: 67319.07
A53: 50 | B53: 0 | C53: 0 | D53: 1 | E53: 203 | F53: =ROUND(Source!Q41,O53) -> 0 | G53: ЭММ | H53: Эксплуатация машин | K53: 203 | L53: 11 | M53: 3 | O53: 2 | P53: =ROUND(Source!DI41,O53) -> 0 | W53: 0 | X53: 1 | Y53: 0 | Z53: 0 | AA53: 1 | AB53: 0
A54: 50 | B54: 0 | C54: 0 | D54: 1 | E54: 231 | F54: =ROUND(Source!BB41,O54) -> 0 | G54: ЭММсНРиСП | H54: Эксплуатация машин по ТСН-2001.16 | K54: 231 | L54: 12 | M54: 3 | O54: 2 | P54: =ROUND(Source!ET41,O54) -> 0 | W54: 0 | X54: 1 | Y54: 0 | Z54: 0 | AA54: 1 | AB54: 0
A55: 50 | B55: 0 | C55: 0 | D55: 1 | E55: 204 | F55: =ROUND(Source!R41,O55) -> 0 | G55: ЗПМ | H55: ЗП машинистов | K55: 204 | L55: 13 | M55: 3 | O55: 2 | P55: =ROUND(Source!DJ41,O55) -> 0 | W55: 0 | X55: 1 | Y55: 0 | Z55: 0 | AA55: 1 | AB55: 0
A56: 50 | B56: 0 | C56: 0 | D56: 1 | E56: 205 | F56: =ROUND(Source!S41,O56) -> 147.01 | G56: ОЗП | H56: Основная ЗП рабочих | K56: 205 | L56: 14 | M56: 3 | O56: 2 | P56: =ROUND(Source!DK41,O56) -> 8084.08 | W56: 147.01 | X56: 1 | Y56: 147.01 | Z56: 8084.08 | AA56: 1 | AB56: 8084.08
A57: 50 | B57: 0 | C57: 0 | D57: 1 | E57: 232 | F57: =ROUND(Source!BC41,O57) -> 0 | G57: ОЗПсНРиСП | H57: Основная ЗП рабочих по ТСН-2001.16 | K57: 232 | L57: 15 | M57: 3 | O57: 2 | P57: =ROUND(Source!EU41,O57) -> 0 | W57: 0 | X57: 1 | Y57: 0 | Z57: 0 | AA57: 1 | AB57: 0
A58: 50 | B58: 0 | C58: 0 | D58: 1 | E58: 214 | F58: =ROUND(Source!AS41,O58) -> 0 | G58: Строит | H58: Строительные работы с НР и СП | K58: 214 | L58: 16 | M58: 3 | O58: 2 | P58: =ROUND(Source!EK41,O58) -> 0 | W58: 0 | X58: 1 | Y58: 0 | Z58: 0 | AA58: 1 | AB58: 0
A59: 50 | B59: 0 | C59: 0 | D59: 1 | E59: 215 | F59: =ROUND(Source!AT41,O59) -> 485.78 | G59: Монтаж | H59: Монтажные работы с НР и СП | K59: 215 | L59: 17 | M59: 3 | O59: 2 | P59: =ROUND(Source!EL41,O59) -> 20324.53 | W59: 485.78 | X59: 1 | Y59: 485.78 | Z59: 20324.53 | AA59: 1 | AB59: 20324.53
