Workbook

Sheet 02-01-15
A1: =Source!B1 -> Smeta.RU (495) 974-1589
J2: Форма № 4б
A3: Капитальный ремонт здания Государственного бюджетного общеобразовательного учреждения города Москвы "Школа № 236" по адресу: г. Москва ул. Клязьминская, д. 7 к. 4. 1 этап. | AP3: Капитальный ремонт здания Государственного бюджетного общеобразовательного учреждения города Москвы "Школа № 236" по адресу: г. Москва ул. Клязьминская, д. 7 к. 4. 1 этап. 02-01-15 Система контроля и управления доступом
A4: (наименование стройки и/или объекта)
A6: =CONCATENATE( "ЛОКАЛЬНАЯ СМЕТА № ",IF(Source!F20<>"Новая локальная смета", Source!F20, "")) -> ЛОКАЛЬНАЯ СМЕТА № 02-01-15
A8: =IF(Source!G20<>"Новая локальная смета", Source!G20, "") -> Система контроля и управления доступом
A9: (наименование работ и затрат)
A11: =CONCATENATE( "Основание: чертежи № ", Source!J20) -> Основание: чертежи № 2024-00272-00-ИОС5.8
I13: В базисном уровне цен | J13: В текущем уровне цен
E14: Сметная стоимость | I14: =I15+I16+I17+I18 -> 572.71 | J14: =J15+J16+J17+J18 -> 5607.16 | K14: тыс.руб.
E15: Строительные работы | I15: =ROUND((Source!F270)/1000, 2) -> 0.13 | J15: =ROUND((Source!P270)/1000, 2) -> 1.03 | K15: тыс.руб.
E16: Работы по монтажу оборудования | I16: =ROUND((Source!F271)/1000, 2) -> 73.21 | J16: =ROUND((Source!P271)/1000, 2) -> 1780.46 | K16: тыс.руб.
E17: Оборудование | I17: =ROUND((Source!F262)/1000, 2) -> 499.37 | J17: =ROUND((Source!P262)/1000, 2) -> 3825.67 | K17: тыс.руб.
E18: Прочие работы и затраты | I18: =ROUND((Source!F272+Source!F273)/1000, 2) -> 0 | J18: =ROUND((Source!P272+Source!P273)/1000, 2) -> 0 | K18: тыс.руб.
E19: Средства на оплату труда | I19: =(Source!F268+ Source!F267)/1000 -> 10.39772 | J19: =((Source!P268 + Source!P267)/1000) -> 571.77061 | K19: тыс.руб.
E20: Затраты труда | I20: =Source!F275 -> 787.70867 | K20: чел.-ч.
E21: Кроме того:
E22: Возврат материалов | I22: =SUM(Y28:Y387)/1000 -> 0 | J22: =SUM(Z28:Z387)/1000 -> 0 | K22: тыс.руб.
A24: Составлен(а) по ТСН-2001 с учетом Дополнения №: 80
A25: № и период сборника коэффициентов (индексов) пересчета: Коэффициенты к ТСН-2001 МГЭ Дополнение 80, строительство №217/80 III квартал 2025 года и Коэффициенты к ТСН-2001.13-2 Дополнение 46 №62/46 III квартал 2025 года | AP25: № и период сборника коэффициентов (индексов) пересчета: Коэффициенты к ТСН-2001 МГЭ Дополнение 80, строительство №217/80 III квартал 2025 года и Коэффициенты к ТСН-2001.13-2 Дополнение 46 №62/46 III квартал 2025 года
A26: № п/п | B26: Шифр расценки и коды ресурсов | C26: Наименование работ и затрат | D26: Ед. изм. | E26: Кол-во единиц | F26: Цена на ед. изм., руб. | G26: Попра- вочные коэффи- циенты | H26: Коэффи- циенты зимних удорожа- ний | I26: Всего в ценах на январь 2000 года, руб. | J26: Коэффи- циенты (индек- сы) пере- счета, нормы НР и СП | K26: ВСЕГО затрат в текущем уровне цен, руб.
A27: 1 | B27: 2 | C27: 3 | D27: 4 | E27: 5 | F27: 6 | G27: 7 | H27: 8 | I27: 9 | J27: 10 | K27: 11
A29: =CONCATENATE("Раздел: ",IF(Source!G24<>"Новый раздел", Source!G24, "")) -> Раздел: Оборудование
A30: 1 | B30: 4.10-176-1 Поправка: Гл.12.Прил.8.п.8. 5_12.00.01.11.003 | C30: Монтаж блока контроля датчиков (контроллер) | D30: =Source!H28 -> 10 шт. | E30: =Source!I28 -> 0.2 | Q30: =Source!X28 -> 97.66 | R30: =Source!X29 -> 5370.27 | S30: =Source!Y28 -> 49.91 | T30: =Source!Y29 -> 2744.81 | U30: =ROUND((175/100)*ROUND(Source!R28, 2), 2) -> 0.05 | V30: =ROUND((0/100)*ROUND(Source!R29, 2), 2) -> 0 | AC30: 0
C31: ="Объем: "&Source!I28&"=2/"&"10" -> Объем: 0,2=2/10
C32: ЗП | F32: =Source!AO28 -> 470.94 | G32: =Source!DG28 -> *1,1 | H32: =Source!AV29 -> 1.047 | I32: =Source!S28 -> 108.48 | J32: =IF(Source!BA29<> 0, Source!BA29, 1) -> 54.99 | K32: =Source!S29 -> 5965.32
C33: ЭМ | F33: =Source!AM28 -> 1.1 | G33: =Source!DE28 -> *1,1 | H33: =Source!AV29 -> 1.047 | I33: =Source!Q28 -> 0.25 | J33: =IF(Source!BB29<> 0, Source!BB29, 1) -> 14.48 | K33: =Source!Q29 -> 3.62
C34: в т.ч. ЗПМ | F34: =Source!AN28 -> 0.13 | G34: =Source!DF28 -> *1,1 | H34: =Source!AV29 -> 1.047 | I34: =Source!R28 -> 0.03 | J34: =IF(Source!BS29<> 0, Source!BS29, 1) -> 54.99 | K34: =Source!R29 -> 1.65
C35: МР | F35: =Source!AL28 -> 1.29 | G35: =Source!DD28 -> *1 | H35: =Source!AW29 -> 1 | I35: =Source!P28 -> 0.26 | J35: =IF(Source!BC29<> 0, Source!BC29, 1) -> 7.25 | K35: =Source!P29 -> 1.89
C36: НР от ФОТ | D36: % | E36: =Source!BZ29 -> 90 | I36: =SUM(Q30:Q35) -> 97.66 | J36: =Source!AT29 -> 90 | K36: =SUM(R30:R35) -> 5370.27
C37: СП от ФОТ | D37: % | E37: =Source!CA29 -> 46 | I37: =SUM(S30:S36) -> 49.91 | J37: =Source!AU29 -> 46 | K37: =SUM(T30:T36) -> 2744.81
C38: ЗТР | D38: чел-ч | E38: =Source!AQ28 -> 29.96 | G38: =Source!DI28 -> *1,1 | H38: =Source!AV29 -> 1.047 | I38: =Source!U28 -> 6.9009864
C39: Всего по позиции: | H39: =I32+I33+I35+I36+I37+0 -> 256.56 | J39: =K32+K33+K35+K36+K37+0 -> 14085.91 | O39: =I32+I33+I35+I36+I37+0 -> 256.56 | P39: =K32+K33+K35+K36+K37+0 -> 14085.91
A41: 2 | B41: =Source!F30 -> КА 1 | C41: ОБОРУДОВАНИЕ:_x000D_ Сетевой контроллер доступа "STR20-IP" до 8 точек, встроенное ПО 7 314,21 = [64 500 / 1,2 / 7,66] + 3% Трансп + 1,2% Заг.скл | D41: =Source!H30 -> шт. | E41: =Source!I30 -> 20 | F41: =Source!AL30 -> 7314.21 | G41: =Source!DD30 | H41: =Source!AW31 -> 1 | I41: =Source!P30 -> 146284.2 | J41: =IF(Source!BC31<> 0, Source!BC31, 1) -> 7.66 | K41: =Source!P31 -> 1120537 | Q41: =Source!X30 -> 0 | R41: =Source!X31 -> 0 | S41: =Source!Y30 -> 0 | T41: =Source!Y31 -> 0 | U41: =ROUND((175/100)*ROUND(Source!R30, 2), 2) -> 0 | V41: =ROUND((0/100)*ROUND(Source!R31, 2), 2) -> 0 | AC41: 5
C42: Всего по позиции: | H42: =I41+0 -> 146284.2 | J42: =K41+0 -> 1120537 | O42: =I41+0 -> 146284.2 | P42: =K41+0 -> 1120537
A44: 3 | B44: 4.10-80-4 Поправка: Гл.12.Прил.8.п.8. 5_12.00.01.11.003 | C44: Аппараты приемные, приборы ПС приемно-контрольные, пусковые, прибор ПС на 4 луча | D44: =Source!H32 -> 1 ШТ. | E44: =Source!I32 -> 12 | Q44: =Source!X32 -> 557.12 | R44: =Source!X33 -> 30635.92 | S44: =Source!Y32 -> 284.75 | T44: =Source!Y33 -> 15658.36 | U44: =ROUND((175/100)*ROUND(Source!R32, 2), 2) -> 0.25 | V44: =ROUND((0/100)*ROUND(Source!R33, 2), 2) -> 0 | AC44: 0
C45: ЗП | F45: =Source!AO32 -> 44.78 | G45: =Source!DG32 -> *1,1 | H45: =Source!AV33 -> 1.047 | I45: =Source!S32 -> 618.88 | J45: =IF(Source!BA33<> 0, Source!BA33, 1) -> 54.99 | K45: =Source!S33 -> 34032.21
C46: ЭМ | F46: =Source!AM32 -> 0.12 | G46: =Source!DE32 -> *1,1 | H46: =Source!AV33 -> 1.047 | I46: =Source!Q32 -> 1.66 | J46: =IF(Source!BB33<> 0, Source!BB33, 1) -> 13.75 | K46: =Source!Q33 -> 22.83
C47: в т.ч. ЗПМ | F47: =Source!AN32 -> 0.01 | G47: =Source!DF32 -> *1,1 | H47: =Source!AV33 -> 1.047 | I47: =Source!R32 -> 0.14 | J47: =IF(Source!BS33<> 0, Source!BS33, 1) -> 54.99 | K47: =Source!R33 -> 7.7
C48: МР | F48: =Source!AL32 -> 6.44 | G48: =Source!DD32 -> *1 | H48: =Source!AW33 -> 1 | I48: =Source!P32 -> 77.28 | J48: =IF(Source!BC33<> 0, Source!BC33, 1) -> 9.89 | K48: =Source!P33 -> 764.3
...

Sheet Ведомость объемов работ
A1: =Source!B1 -> Smeta.RU (495) 974-1589
E3: "УТВЕРЖДАЮ"
D5: ___________________________
D7: ___________________________
D9: " ___ " ___________ 20 ___ г.
B12: =CONCATENATE("Ведомость объемов работ ", IF(Source!AN15<>"", Source!AN15," ")) -> Ведомость объемов работ
B13: =CONCATENATE(Source!F12, " ", Source!G12) -> Новый объект (ТСН-2001 (Мосгосэкспертиза)) 02-01-15 Система контроля и управления доступом | AE13: =CONCATENATE(Source!F12, " ", Source!G12) -> Новый объект (ТСН-2001 (Мосгосэкспертиза)) 02-01-15 Система контроля и управления доступом
A16: № п/п | B16: № в ЛСР | C16: Наименование работ и затрат | D16: Единица измерения | E16: Количество | F16: Ссылка на чертежи, спецификации | G16: Формула расчета, расчет объемов работ и расхода материалов | H16: Примечание
A17: 1 | B17: 2 | C17: 3 | D17: 4 | E17: 5 | F17: 6 | G17: 7 | H17: 8
A18: =CONCATENATE("Локальная смета: ", Source!G20) -> Локальная смета: Система контроля и управления доступом
A19: =CONCATENATE("Раздел: ", Source!G24) -> Раздел: Оборудование
A20: 1 | B20: =Source!E28 -> 1 | C20: =Source!G28 -> Монтаж блока контроля датчиков (контроллер) | D20: 10 шт. | E20: =Source!I28 -> 0.2 | F20: =Source!U24 | G20: ="=2/"&"10" -> =2/10
A21: 2 | B21: =Source!E30 -> 2 | C21: =Source!G30 -> Сетевой контроллер доступа "STR20-IP" до 8 точек, встроенное ПО | D21: шт. | E21: =Source!I30 -> 20 | F21: =Source!U24 | G21: =Source!I30 -> 20
A22: 3 | B22: =Source!E32 -> 3 | C22: =Source!G32 -> Аппараты приемные, приборы ПС приемно-контрольные, пусковые, прибор ПС на 4 луча | D22: 1 ШТ. | E22: =Source!I32 -> 12 | F22: =Source!U24 | G22: =Source!I32 -> 12
A23: 4 | B23: =Source!E34 -> 4 | C23: =Source!G34 -> Модуль доступа-контроллер доступа STR-1AP-M на 2 точки | D23: шт. | E23: =Source!I34 -> 12 | F23: =Source!U24 | G23: =Source!I34 -> 12
A24: 5 | B24: =Source!E36 -> 5 | C24: =Source!G36 -> Аппараты приемные, приборы ПС приемно-контрольные, пусковые, прибор ПС на 4 луча | D24: 1 ШТ. | E24: =Source!I36 -> 15 | F24: =Source!U24 | G24: =Source!I36 -> 15
A25: 6 | B25: =Source!E38 -> 6 | C25: =Source!G38 -> Модуль доступа-контроллер доступа STR-2AP-M на 4 точки | D25: шт. | E25: =Source!I38 -> 15 | F25: =Source!U24 | G25: =Source!I38 -> 15
A26: 7 | B26: =Source!E40 -> 7 | C26: =Source!G40 -> Монтаж конструкции для установки приборов и средств автоматизации массой до 2 кг | D26: 1 ШТ. | E26: =Source!I40 -> 27 | F26: =Source!U24 | G26: =Source!I40 -> 27
A27: 8 | B27: =Source!E42 -> 8 | C27: =Source!G42 -> Электромагнитный замок с монтажным комплектом "AL-400 Premium " | D27: шт. | E27: =Source!I42 -> 27 | F27: =Source!U24 | G27: =Source!I42 -> 27
A28: 9 | B28: =Source!E44 -> 9 | C28: =Source!G44 -> Извещатели ОС автоматические, контактный, магнито-контактный на открывание окон, дверей | D28: 1 ШТ. | E28: =Source!I44 -> 42 | F28: =Source!U24 | G28: ="=38+"&"4" -> =38+4
A29: 10 | B29: =Source!E46 -> 10 | C29: =Source!G46 -> Извещатель охр. магнито-контактный для металлических дверей ИО 102-26 исп. Аякс | D29: шт. | E29: =Source!I46 -> 38 | F29: =Source!U24 | G29: =Source!I46 -> 38
A30: 11 | B30: =Source!E48 -> 11 | C30: =Source!G48 -> Извещатель охр. магнито-контактный для неметалл. поверхностей ИО 102-2 СМК | D30: шт. | E30: =Source!I48 -> 4 | F30: =Source!U24 | G30: =Source!I48 -> 4
A31: 12 | B31: =Source!E50 -> 12 | C31: =Source!G50 -> Монтаж устройства связи с согласующим устройством (вызывная панель) | D31: 10 шт. | E31: =Source!I50 -> 4.2 | F31: =Source!U24 | G31: ="=42/"&"10" -> =42/10
A32: 13 | B32: =Source!E52 -> 13 | C32: =Source!G52 -> Считыватель для установки на улице и в помещение,-40....+55гр интерфейс Wiegand 26-58, формат карт Mifare, EM-Marin,HID Prox RusGuard R-15 multi | D32: шт. | E32: =Source!I52 -> 42 | F32: =Source!U24 | G32: =Source!I52 -> 42
A33: 14 | B33: =Source!E54 -> 14 | C33: =Source!G54 -> Монтаж ключа или кнопки на панели | D33: 1 ШТ. | E33: =Source!I54 -> 12 | F33: =Source!U24 | G33: =Source!I54 -> 12
A34: 14.1 | B34: =Source!E56 -> 14,1 | C34: =Source!G56 -> Кнопка экстренного выхода ST-FR115 | D34: шт. | E34: =Source!I56 -> 12 | F34: =Source!U24
A35: 15 | B35: =Source!E58 -> 15 | C35: =Source!G58 -> Монтаж детали на пультах и панелях - кнопка | D35: 1 ШТ. | E35: =Source!I58 -> 27 | F35: =Source!U24 | G35: =Source!I58 -> 27
A36: 16 | B36: =Source!E60 -> 16 | C36: =Source!G60 -> Кнопка разблокировки дверей "ИПР 513-10" "АВАРИЙНЫЙ ВЫХОД" SB 1 | D36: шт. | E36: =Source!I60 -> 27 | F36: =Source!U24 | G36: =Source!I60 -> 27
A37: 17 | B37: =Source!E62 -> 17 | C37: =Source!G62 -> Монтаж блока бесперебойного питания (ББП) в диспетчерской | D37: 1 ШТ. | E37: =Source!I62 -> 2 | F37: =Source!U24 | G37: =Source!I62 -> 2
A38: 18 | B38: =Source!E64 -> 18 | C38: =Source!G64 -> Резервный источник питания,12В ИВЭПР 12/3,5 2x7 -Р | D38: шт. | E38: =Source!I64 -> 2 | F38: =Source!U24 | G38: =Source!I64 -> 2
A39: 19 | B39: =Source!E66 -> 19 | C39: =Source!G66 -> Батарея аккумуляторная, емкость 7 А·ч, напряжение 12 В. | D39: шт. | E39: =Source!I66 -> 4 | F39: =Source!U24 | G39: =Source!I66 -> 4
A40: 20 | B40: =Source!E68 -> 20 | C40: =Source!G68 -> Установка съемных и выдвижных блоков (модулей, ячеек, ТЭЗ) массой до 5 кг | D40: 1 ШТ. | E40: =Source!I68 -> 7 | F40: =Source!U24 | G40: =Source!I68 -> 7
A41: 20.1 | B41: =Source!E70 -> 20,1 | C41: =Source!G70 -> Коммутационная панель категории 5е UTP19",1U,24xRj45,п-корды PLHD-24 Dual IDC-1U | D41: шт. | E41: =Source!I70 -> 49 | F41: =Source!U24
A42: 21 | B42: =Source!E72 -> 21 | C42: =Source!G72 -> Установка рамки со штифтами на винтах в нарезных отверстиях | D42: 1 рамка | E42: =Source!I72 -> 7 | F42: =Source!U24 | G42: =Source!I72 -> 7
A43: 21.1 | B43: =Source!E74 -> 21,1 | C43: =Source!G74 -> Горизонтальный органайзер, слотовый с крышкой, MX-CMC-1U-45-B | D43: шт. | E43: =Source!I74 -> 7 | F43: =Source!U24
A44: 22 | B44: =Source!E76 -> 22 | C44: =Source!G76 -> Установка аппарата настольного массой до 0,03 т | D44: 1 ШТ. | E44: =Source!I76 -> 1 | F44: =Source!U24 | G44: =Source!I76 -> 1
A45: 23 | B45: =Source!E78 -> 23 | C45: =Source!G78 -> Центральный прибор индикации и управления с ПО FireSec в составе: блок системный, монитор- размер 21.5 дюйм, пульт индикации и управления, блок АВР ЦПИУ, Рубеж-АРМ исп.1 | D45: шт. | E45: =Source!I78 -> 1 | F45: =Source!U24 | G45: =Source!I78 -> 1
A46: 24 | B46: =Source!E80 -> 24 | C46: =Source!G80 -> Монтаж блока бесперебойного питания (ББП) в диспетчерской | D46: 1 ШТ. | E46: =Source!I80 -> 1 | F46: =Source!U24 | G46: =Source!I80 -> 1
A47: 25 | B47: =Source!E82 -> 25 | C47: =Source!G82 -> Источник бесперебойного питания Rapan-USB 3000 | D47: шт. | E47: =Source!I82 -> 1 | F47: =Source!U24 | G47: =Source!I82 -> 1
A48: 26 | B48: =Source!E84 -> 26 | C48: =Source!G84 -> Монтаж коммутатора служебной связи | D48: 1 ШТ. | E48: =Source!I84 -> 7 | F48: =Source!U24 | G48: =Source!I84 -> 7
...

Sheet Source
A1: 0 | B1: Smeta.RU (495) 974-1589 | D1: _PS_ | F1: 0 | G1: 0 | H1: 0 | I1: Smeta.RU | K1: 1 | L1: 74402 | M1: 10 | N1: 12 | O1: 0 | P1: 0 | Q1: 3
A4: 1 | B4: 1 | C4: -1 | G4: Капитальный ремонт здания Государственного бюджетного общеобразовательного учреждения города Москвы "Школа № 236" по адресу: г. Москва ул. Клязьминская, д. 7 к. 4. 1 этап | EC4: 0
A12: 1 | B12: 322 | C12: 0 | D12: =ROW(A283) -> 283 | E12: 0 | F12: Новый объект (ТСН-2001 (Мосгосэкспертиза)) | G12: 02-01-15 Система контроля и управления доступом | I12: 0 | K12: 0 | L12: 0 | M12: 4098 | O12: 0 | P12: 0 | Q12: 0 | R12: 0 | S12: 0 | T12: 1 | V12: 0 | AB12: Кузнецова Е.А. | BB12: 0 | BH12: Сметные нормы списания | BI12: Коды ОКП для ТСН-2001 МГЭ Дополнение 80 | BJ12: 1 | BK12: 1 | BL12: 0 | BM12: 0 | BN12: 1 | BO12: 0 | BP12: 6 | BQ12: 2 | BR12: 1 | BS12: 1 | BT12: 0 | BU12: 0 | BV12: 0 | BW12: 0 | BX12: 0 | BZ12: Типовой расчет для ТСН-2001 МГЭ, Дополнение 80, строительство | CA12: Территориальные сметные нормативы для Москвы ТСН-2001 (МГЭ), дополнение 80 | CB12: Территориальные сметные нормативы для Москвы ТСН-2001 (МГЭ), дополнение 80 | CC12: Территориальные сметные нормативы для Москвы ТСН-2001 (МГЭ), дополнение 80 | CD12: Территориальные сметные нормативы для Москвы ТСН-2001 (МГЭ), дополнение 80 | CE12: Поправки для ТСН-2001 от 03.10.2025 г. доп.79 | CF12: 0 | CG12: 0 | CH12: 327688 | CK12: 80 | CQ12: Территориальные сметные нормативы для Москвы (ТСН-2001) | CR12: ТЕР | CS12: 41660 | CT12: 1 | CU12: 80 | CY12: 0 | EC12: 0
A15: 15 | B15: 1
A18: 52 | B18: =B283 -> 322 | C18: =C283 -> 1 | D18: =D283 -> 12 | E18: =E283 -> 0 | F18: =F283 -> Новый объект (ТСН-2001 (Мосгосэкспертиза)) | G18: =G283 -> 02-01-15 Система контроля и управления доступом | O18: =O283 -> 557859.14 | P18: =P283 -> 546496.67 | Q18: =Q283 -> 1139.47 | R18: =R283 -> 174.72 | S18: =S283 -> 10223 | T18: =T283 -> 0 | U18: =U283 -> 787.70867 | V18: =V283 -> 0 | ... GX18: =GX283 -> 0
A20: 3 | B20: 1 | D20: =ROW(A253) -> 253 | F20: 02-01-15 | G20: Система контроля и управления доступом | I20: 0 | J20: 2024-00272-00-ИОС5.8 | K20: -1 | L20: 02-01-15 | S20: 0 | T20: 0 | V20: 2 | BX20: 0 | CF20: 0 | CG20: 0
A22: 52 | B22: =B253 -> 1 | C22: =C253 -> 3 | D22: =D253 -> 20 | E22: =E253 -> 0 | F22: =F253 -> 02-01-15 | G22: =G253 -> Система контроля и управления доступом | O22: =O253 -> 557859.14 | P22: =P253 -> 546496.67 | Q22: =Q253 -> 1139.47 | R22: =R253 -> 174.72 | S22: =S253 -> 10223 | T22: =T253 -> 0 | U22: =U253 -> 787.70867 | V22: =V253 -> 0 | ... GX22: =GX253 -> 0
A24: 4 | B24: 1 | D24: =ROW(A91) -> 91 | F24: Новый раздел | G24: Оборудование | I24: 0 | K24: 0 | S24: 0 | T24: 0 | V24: 2 | BX24: 0 | CJ24: 0
A26: 52 | B26: =B91 -> 1 | C26: =C91 -> 4 | D26: =D91 -> 24 | E26: =E91 -> 0 | F26: =F91 -> Новый раздел | G26: =G91 -> Оборудование | O26: =O91 -> 500427.42 | P26: =P91 -> 495367.76 | Q26: =Q91 -> 354.18 | R26: =R91 -> 46.3 | S26: =S91 -> 4705.48 | T26: =T91 -> 0 | U26: =U91 -> 355.44917 | V26: =V91 -> 0 | ... GX26: =GX91 -> 0
A28: 17 | B28: 1 | C28: =ROW(SmtRes!A4) -> 4 | D28: =ROW(EtalonRes!A5) -> 5 | E28: 1 | F28: 4.10-176-1 | G28: Монтаж блока контроля датчиков (контроллер) | H28: 10 шт. | I28: =ROUND(ROUND(2/10,4),9) -> 0.2 | J28: 0 | K28: =ROUND(ROUND(2/10,4),9) -> 0.2 | O28: =ROUND(CP28,2) -> 108.99 | P28: =ROUND((ROUND((AC28*AW28*I28),2)*BC28),2) -> 0.26 | Q28: =(ROUND((ROUND((((ET28*1.1))*AV28*I28),2)*BB28),2)+ROUND((ROUND(((AE28-((EU28*1.1)))*AV28*I28),2)*BS28),2)) -> 0.25 | R28: =ROUND((ROUND((AE28*AV28*I28),2)*BS28),2) -> 0.03 | S28: =ROUND((ROUND((AF28*AV28*I28),2)*BA28),2) -> 108.48 | T28: =ROUND(CU28*I28,2) -> 0 | U28: =CV28*I28 -> 6.9009864 | V28: =CW28*I28 -> 0 | W28: =ROUND(CX28*I28,2) -> 0 | X28: =ROUND(CY28,2) -> 97.66 | Y28: =ROUND(CZ28,2) -> 49.91 | AA28: 59213216 | AB28: =ROUND((AC28+AD28+AF28),6) -> 520.534 | AC28: =ROUND(((ES28*1)),6) -> 1.29 | AD28: =ROUND(((((ET28*1.1))-((EU28*1.1)))+AE28),6) -> 1.21 | AE28: =ROUND(((EU28*1.1)),6) -> 0.143 | AF28: =ROUND(((EV28*1.1)),6) -> 518.034 | AG28: =ROUND((AP28),6) -> 0 | AH28: =((EW28*1.1)) -> 32.956 | AI28: =((EX28*1.1)) -> 0 | AJ28: =(AS28) -> 0 | AK28: 473.33 | AL28: 1.29 | AM28: 1.1 | AN28: 0.13 | AO28: 470.94 | AP28: 0 | AQ28: 29.96 | AR28: 0 | AS28: 0 | AT28: 90 | AU28: 46 | AV28: 1.047 | AW28: 1 | AZ28: 1 | BA28: 1 | BB28: 1 | BC28: 1 | BH28: 0 | BI28: 2 | BJ28: ТСН-2001.4 Доп. 80, Сб. 10, т. 176, поз. 1 | BM28: 68 | BN28: 58808062 | BO28: 4.10-176-1 | BP28: 1 | BQ28: 40 | BR28: 0 | BS28: 1 | BT28: 1 | BU28: 1 | BV28: 1 | BW28: 1 | BX28: 1 | BZ28: 90 | CA28: 46 | CE28: 30 | CF28: 0 | CG28: 0 | CM28: 0 | CN28: Поправка: Гл.12.Прил.8.п.8. 5_12.00.01.11.003 Наименование: При наличии усложненных условий производства работ (стесненность, сложность складирования и транспортной логистики, наличие в зоне производства работ действующего технологического оборудования или движения технологического транспорта и т.п.) для объектов, расположенных за пределами территории круговой магистральной системы улиц "Садовое кольцо" и за пределами Третьего транспортного кольца города Москвы пунктов "а" и "б", но в пределах Московской кольцевой автомобильной дороги | CO28: 0 | CP28: =(P28+Q28+S28) -> 108.99 | CQ28: =ROUND((ROUND((AC28*AW28*1),2)*BC28),2) -> 1.29 | CR28: =(ROUND((ROUND((((ET28*1.1))*AV28*1),2)*BB28),2)+ROUND((ROUND(((AE28-((EU28*1.1)))*AV28*1),2)*BS28),2)) -> 1.27 | CS28: =ROUND((ROUND((AE28*AV28*1),2)*BS28),2) -> 0.15 | CT28: =ROUND((ROUND((AF28*AV28*1),2)*BA28),2) -> 542.38 | CU28: =AG28 -> 0 | CV28: =(AH28*AV28) -> 34.504932 | CW28: =AI28 -> 0 | CX28: =AJ28 -> 0 | CY28: =(((S28+R28)*AT28)/100) -> 97.659 | CZ28: =(((S28+R28)*AU28)/100) -> 49.9146 | DB28: 1 | DD28: *1 | DE28: *1,1 | DF28: *1,1 | DG28: *1,1 | DI28: *1,1 | DJ28: *1,1 | DN28: 0 | DO28: 0 | DP28: 1 | DQ28: 1 | DU28: 1010 | DV28: 10 шт. | DW28: 10 шт. | DX28: 10 | EE28: 58808178 | EF28: 40 | EG28: Монтаж оборудования | EH28: 0 | EJ28: 2 | EK28: 68 | EL28: ТСН-2001.4-10. Прокладка и монтаж сетей связи | EM28: ТСН-2001.4-10-1 | EO28: Поправка: Гл.12.Прил.8.п.8. 5_12.00.01.11.003 | EQ28: 0 | ER28: 473.33 | ES28: 1.29 | ET28: 1.1 | EU28: 0.13 | EV28: 470.94 | EW28: 29.96 | EX28: 0 | EY28: 0 | FQ28: 0 | FR28: 0 | FS28: 0 | FX28: 90 | FY28: 46 | GD28: 1 | GF28: -733186695 | GG28: 2 | GH28: 1 | GI28: 2 | GJ28: 0 | GK28: 0 | GL28: =ROUND(IF(AND(BH28=3,BI28=3,FS28<>0),P28,0),2) -> 0 | GM28: =ROUND(O28+X28+Y28,2)+GX28 -> 256.56 | GN28: =IF(OR(BI28=0,BI28=1),GM28-GX28,0) -> 0 | GO28: =IF(BI28=2,GM28-GX28,0) -> 256.56 | GP28: =IF(BI28=4,GM28-GX28,0) -> 0 | GR28: 0 | GS28: 3 | GT28: 0 | GV28: =ROUND((GT28),6) -> 0 | GW28: 1 | GX28: =ROUND(HC28*I28,2) -> 0 | HA28: 0 | HB28: 0 | HC28: =GV28*GW28 -> 0 | HS28: 0 | IK28: 0
A29: 17 | B29: 1 | C29: =ROW(SmtRes!A8) -> 8 | D29: =ROW(EtalonRes!A10) -> 10 | E29: 1 | F29: 4.10-176-1 | G29: Монтаж блока контроля датчиков (контроллер) | H29: 10 шт. | I29: =ROUND(ROUND(2/10,4),9) -> 0.2 | J29: 0 | K29: =ROUND(ROUND(2/10,4),9) -> 0.2 | O29: =ROUND(CP29,2) -> 5970.83 | P29: =ROUND((ROUND((AC29*AW29*I29),2)*BC29),2) -> 1.89 | Q29: =(ROUND((ROUND((((ET29*1.1))*AV29*I29),2)*BB29),2)+ROUND((ROUND(((AE29-((EU29*1.1)))*AV29*I29),2)*BS29),2)) -> 3.62 | R29: =ROUND((ROUND((AE29*AV29*I29),2)*BS29),2) -> 1.65 | S29: =ROUND((ROUND((AF29*AV29*I29),2)*BA29),2) -> 5965.32 | T29: =ROUND(CU29*I29,2) -> 0 | U29: =CV29*I29 -> 6.9009864 | V29: =CW29*I29 -> 0 | W29: =ROUND(CX29*I29,2) -> 0 | X29: =ROUND(CY29,2) -> 5370.27 | Y29: =ROUND(CZ29,2) -> 2744.81 | AA29: 59213213 | AB29: =ROUND((AC29+AD29+AF29),6) -> 520.534 | AC29: =ROUND(((ES29*1)),6) -> 1.29 | AD29: =ROUND(((((ET29*1.1))-((EU29*1.1)))+AE29),6) -> 1.21 | AE29: =ROUND(((EU29*1.1)),6) -> 0.143 | AF29: =ROUND(((EV29*1.1)),6) -> 518.034 | AG29: =ROUND((AP29),6) -> 0 | AH29: =((EW29*1.1)) -> 32.956 | AI29: =((EX29*1.1)) -> 0 | AJ29: =(AS29) -> 0 | AK29: 473.33 | AL29: 1.29 | AM29: 1.1 | AN29: 0.13 | AO29: 470.94 | AP29: 0 | AQ29: 29.96 | AR29: 0 | AS29: 0 | AT29: 90 | AU29: 46 | AV29: 1.047 | AW29: 1 | AZ29: 1 | BA29: 54.99 | BB29: 14.48 | BC29: 7.25 | BH29: 0 | BI29: 2 | BJ29: ТСН-2001.4 Доп. 80, Сб. 10, т. 176, поз. 1 | BM29: 68 | BN29: 58808062 | BO29: 4.10-176-1 | BP29: 1 | BQ29: 40 | BR29: 0 | BS29: 54.99 | BT29: 1 | BU29: 1 | BV29: 1 | BW29: 1 | BX29: 1 | BZ29: 90 | CA29: 46 | CE29: 30 | CF29: 0 | CG29: 0 | CM29: 0 | CN29: Поправка: Гл.12.Прил.8.п.8. 5_12.00.01.11.003 Наименование: При наличии усложненных условий производства работ (стесненность, сложность складирования и транспортной логистики, наличие в зоне производства работ действующего технологического оборудования или движения технологического транспорта и т.п.) для объектов, расположенных за пределами территории круговой магистральной системы улиц "Садовое кольцо" и за пределами Третьего транспортного кольца города Москвы пунктов "а" и "б", но в пределах Московской кольцевой автомобильной дороги | CO29: 0 | CP29: =(P29+Q29+S29) -> 5970.83 | CQ29: =ROUND((ROUND((AC29*AW29*1),2)*BC29),2) -> 9.35 | CR29: =(ROUND((ROUND((((ET29*1.1))*AV29*1),2)*BB29),2)+ROUND((ROUND(((AE29-((EU29*1.1)))*AV29*1),2)*BS29),2)) -> 18.39 | CS29: =ROUND((ROUND((AE29*AV29*1),2)*BS29),2) -> 8.25 | CT29: =ROUND((ROUND((AF29*AV29*1),2)*BA29),2) -> 29825.48 | CU29: =AG29 -> 0 | CV29: =(AH29*AV29) -> 34.504932 | CW29: =AI29 -> 0 | CX29: =AJ29 -> 0 | CY29: =(((S29+R29)*AT29)/100) -> 5370.273 | CZ29: =(((S29+R29)*AU29)/100) -> 2744.8062 | DB29: 2 | DD29: *1 | DE29: *1,1 | DF29: *1,1 | DG29: *1,1 | DI29: *1,1 | DJ29: *1,1 | DN29: 0 | DO29: 0 | DP29: 1 | DQ29: 1 | DU29: 1010 | DV29: 10 шт. | DW29: 10 шт. | DX29: 10 | EE29: 58808178 | EF29: 40 | EG29: Монтаж оборудования | EH29: 0 | EJ29: 2 | EK29: 68 | EL29: ТСН-2001.4-10. Прокладка и монтаж сетей связи | EM29: ТСН-2001.4-10-1 | EO29: Поправка: Гл.12.Прил.8.п.8. 5_12.00.01.11.003 | EQ29: 0 | ER29: 473.33 | ES29: 1.29 | ET29: 1.1 | EU29: 0.13 | EV29: 470.94 | EW29: 29.96 | EX29: 0 | EY29: 0 | FQ29: 0 | FR29: 0 | FS29: 0 | FX29: 90 | FY29: 46 | GD29: 1 | GF29: -733186695 | GG29: 2 | GH29: 1 | GI29: 2 | GJ29: 0 | GK29: 0 | GL29: =ROUND(IF(AND(BH29=3,BI29=3,FS29<>0),P29,0),2) -> 0 | GM29: =ROUND(O29+X29+Y29,2)+GX29 -> 14085.91 | GN29: =IF(OR(BI29=0,BI29=1),GM29-GX29,0) -> 0 | GO29: =IF(BI29=2,GM29-GX29,0) -> 14085.91 | GP29: =IF(BI29=4,GM29-GX29,0) -> 0 | GR29: 0 | GS29: 3 | GT29: 0 | GV29: =ROUND((GT29),6) -> 0 | GW29: 1 | GX29: =ROUND(HC29*I29,2) -> 0 | HA29: 0 | HB29: 0 | HC29: =GV29*GW29 -> 0 | HS29: 0 | IK29: 0
A30: 17 | B30: 1 | E30: 2 | F30: КА 1 | G30: Сетевой контроллер доступа "STR20-IP" до 8 точек, встроенное ПО | H30: шт. | I30: =ROUND(ROUND(20,4),9) -> 20 | J30: 0 | K30: =ROUND(ROUND(20,4),9) -> 20 | O30: =ROUND(CP30,2) -> 146284.2 | P30: =ROUND((ROUND((AC30*I30),2)*BC30),2) -> 146284.2 | Q30: =(ROUND((ROUND(((ET30)*AV30*I30),2)*BB30),2)+ROUND((ROUND(((AE30-(EU30))*AV30*I30),2)*BS30),2)) -> 0 | R30: =ROUND((ROUND((AE30*AV30*I30),2)*BS30),2) -> 0 | S30: =ROUND((ROUND((AF30*AV30*I30),2)*BA30),2) -> 0 | T30: =ROUND(CU30*I30,2) -> 0 | U30: =CV30*I30 -> 0 | V30: =CW30*I30 -> 0 | W30: =ROUND(CX30*I30,2) -> 0 | X30: =ROUND(CY30,2) -> 0 | Y30: =ROUND(CZ30,2) -> 0 | AA30: 59213216 | AB30: =ROUND((AC30+AD30+AF30),6) -> 7314.21 | AC30: =ROUND((ES30),6) -> 7314.21 | AD30: =ROUND((((ET30)-(EU30))+AE30),6) -> 0 | AE30: =ROUND((EU30),6) -> 0 | AF30: =ROUND((EV30),6) -> 0 | AG30: =ROUND((AP30),6) -> 0 | AH30: =(EW30) -> 0 | AI30: =(EX30) -> 0 | AJ30: =(AS30) -> 0 | AK30: 7314.21 | AL30: 7314.21 | AM30: 0 | AN30: 0 | AO30: 0 | AP30: 0 | AQ30: 0 | AR30: 0 | AS30: 0 | AT30: 0 | AU30: 0 | AV30: 1 | AW30: 1 | AZ30: 1 | BA30: 1 | BB30: 1 | BC30: 1 | BH30: 3 | BI30: 3 | BM30: 746 | BN30: 0 | BP30: 0 | BQ30: 130 | BR30: 0 | BS30: 1 | BT30: 1 | BU30: 1 | BV30: 1 | BW30: 1 | BX30: 1 | BZ30: 0 | CA30: 0 | CE30: 30 | CF30: 0 | CG30: 0 | CM30: 0 | CO30: 0 | CP30: =(P30+Q30+S30) -> 146284.2 | CQ30: =ROUND((ROUND((AC30*1),2)*BC30),2) -> 7314.21 | CR30: =(ROUND((ROUND(((ET30)*AV30*1),2)*BB30),2)+ROUND((ROUND(((AE30-(EU30))*AV30*1),2)*BS30),2)) -> 0 | CS30: =ROUND((ROUND((AE30*AV30*1),2)*BS30),2) -> 0 | CT30: =ROUND((ROUND((AF30*AV30*1),2)*BA30),2) -> 0 | CU30: =AG30 -> 0 | CV30: =(AH30*AV30) -> 0 | CW30: =AI30 -> 0 | CX30: =AJ30 -> 0 | CY30: =(((S30+R30)*AT30)/100) -> 0 | CZ30: =(((S30+R30)*AU30)/100) -> 0 | DN30: 0 | DO30: 0 | DP30: 1 | DQ30: 1 | DU30: 1010 | DV30: шт. | DW30: шт. | DX30: 1 | EE30: 58808284 | EF30: 130 | EG30: Сметная стоимость оборудования | EH30: 0 | EJ30: 3 | EK30: 746 | EL30: ТСН-2001.13. Сметная стоимость оборудования | EM30: ТСН-2001.13 | EQ30: 0 | ER30: 0 | ES30: 7314.21 | ET30: 0 | EU30: 0 | EV30: 0 | EW30: 0 | EX30: 0 | EY30: 0 | FQ30: 0 | FR30: =P30 -> 146284.2 | FS30: 0 | FX30: 0 | FY30: 0 | GA30: [64 500 / 1,2 / 7,66] + 3% Трансп + 1,2% Заг.скл | GD30: 1 | GF30: -1151737737 | GG30: 2 | GH30: 4 | GI30: -2 | GJ30: 0 | GK30: 0 | GL30: =ROUND(IF(AND(BH30=3,BI30=3,FS30<>0),P30,0),2) -> 0 | GM30: =ROUND(O30+X30+Y30,2)+GX30 -> 146284.2 | GN30: =IF(OR(BI30=0,BI30=1),GM30-GX30,0) -> 0 | GO30: =IF(BI30=2,GM30-GX30,0) -> 0 | GP30: =IF(BI30=4,GM30-GX30,0) -> 0 | GR30: 0 | GS30: 2 | GT30: 0 | GV30: =ROUND((GT30),6) -> 0 | GW30: 1 | GX30: =ROUND(HC30*I30,2) -> 0 | HA30: 0 | HB30: 0 | HC30: =GV30*GW30 -> 0 | HE30: 3 | HF30: 1,2 | HS30: 0 | IK30: 0
A31: 17 | B31: 1 | E31: 2 | F31: КА 1 | G31: Сетевой контроллер доступа "STR20-IP" до 8 точек, встроенное ПО | H31: шт. | I31: =ROUND(ROUND(20,4),9) -> 20 | J31: 0 | K31: =ROUND(ROUND(20,4),9) -> 20 | O31: =ROUND(CP31,2) -> 1120537 | P31: =ROUND((ROUND((AC31*I31),2)*BC31),2) -> 1120537 | Q31: =(ROUND((ROUND(((ET31)*AV31*I31),2)*BB31),2)+ROUND((ROUND(((AE31-(EU31))*AV31*I31),2)*BS31),2)) -> 0 | R31: =ROUND((ROUND((AE31*AV31*I31),2)*BS31),2) -> 0 | S31: =ROUND((ROUND((AF31*AV31*I31),2)*BA31),2) -> 0 | T31: =ROUND(CU31*I31,2) -> 0 | U31: =CV31*I31 -> 0 | V31: =CW31*I31 -> 0 | W31: =ROUND(CX31*I31,2) -> 0 | X31: =ROUND(CY31,2) -> 0 | Y31: =ROUND(CZ31,2) -> 0 | AA31: 59213213 | AB31: =ROUND((AC31+AD31+AF31),6) -> 7314.21 | AC31: =ROUND((ES31),6) -> 7314.21 | AD31: =ROUND((((ET31)-(EU31))+AE31),6) -> 0 | AE31: =ROUND((EU31),6) -> 0 | AF31: =ROUND((EV31),6) -> 0 | AG31: =ROUND((AP31),6) -> 0 | AH31: =(EW31) -> 0 | AI31: =(EX31) -> 0 | AJ31: =(AS31) -> 0 | AK31: 7314.21 | AL31: 7314.21 | AM31: 0 | AN31: 0 | AO31: 0 | AP31: 0 | AQ31: 0 | AR31: 0 | AS31: 0 | AT31: 0 | AU31: 0 | AV31: 1 | AW31: 1 | AZ31: 1 | BA31: 1 | BB31: 1 | BC31: 7.66 | BH31: 3 | BI31: 3 | BM31: 746 | BN31: 0 | BP31: 0 | BQ31: 130 | BR31: 0 | BS31: 1 | BT31: 1 | BU31: 1 | BV31: 1 | BW31: 1 | BX31: 1 | BZ31: 0 | CA31: 0 | CE31: 30 | CF31: 0 | CG31: 0 | CM31: 0 | CO31: 0 | CP31: =(P31+Q31+S31) -> 1120537 | CQ31: =ROUND((ROUND((AC31*1),2)*BC31),2) -> 56026.85 | CR31: =(ROUND((ROUND(((ET31)*AV31*1),2)*BB31),2)+ROUND((ROUND(((AE31-(EU31))*AV31*1),2)*BS31),2)) -> 0 | CS31: =ROUND((ROUND((AE31*AV31*1),2)*BS31),2) -> 0 | CT31: =ROUND((ROUND((AF31*AV31*1),2)*BA31),2) -> 0 | CU31: =AG31 -> 0 | CV31: =(AH31*AV31) -> 0 | CW31: =AI31 -> 0 | CX31: =AJ31 -> 0 | CY31: =(((S31+R31)*AT31)/100) -> 0 | CZ31: =(((S31+R31)*AU31)/100) -> 0 | DN31: 0 | DO31: 0 | DP31: 1 | DQ31: 1 | DU31: 1010 | DV31: шт. | DW31: шт. | DX31: 1 | EE31: 58808284 | EF31: 130 | EG31: Сметная стоимость оборудования | EH31: 0 | EJ31: 3 | EK31: 746 | EL31: ТСН-2001.13. Сметная стоимость оборудования | EM31: ТСН-2001.13 | EQ31: 0 | ER31: 7314.21 | ES31: 7314.21 | ET31: 0 | EU31: 0 | EV31: 0 | EW31: 0 | EX31: 0 | EY31: 0 | EZ31: 5 | FC31: 1 | FD31: 18 | FF31: 64500 | FQ31: 0 | FR31: =P31 -> 1120537 | FS31: 0 | FX31: 0 | FY31: 0 | GA31: [64 500 / 1,2 / 7,66] + 3% Трансп + 1,2% Заг.скл | GD31: 1 | GF31: -1151737737 | GG31: 2 | GH31: 3 | GI31: 5 | GJ31: 0 | GK31: 0 | GL31: =ROUND(IF(AND(BH31=3,BI31=3,FS31<>0),P31,0),2) -> 0 | GM31: =ROUND(O31+X31+Y31,2)+GX31 -> 1120537 | GN31: =IF(OR(BI31=0,BI31=1),GM31-GX31,0) -> 0 | GO31: =IF(BI31=2,GM31-GX31,0) -> 0 | GP31: =IF(BI31=4,GM31-GX31,0) -> 0 | GR31: 2 | GS31: 1 | GT31: 0 | GV31: =ROUND((GT31),6) -> 0 | GW31: 1 | GX31: =ROUND(HC31*I31,2) -> 0 | HA31: 0 | HB31: 0 | HC31: =GV31*GW31 -> 0 | HE31: 3 | HF31: 1,2 | HS31: 0 | IK31: 0
A32: 17 | B32: 1 | C32: =ROW(SmtRes!A9) -> 9 | D32: =ROW(EtalonRes!A11) -> 11 | E32: 3 | F32: 4.10-80-4 | G32: Аппараты приемные, приборы ПС приемно-контрольные, пусковые, прибор ПС на 4 луча | H32: 1 ШТ. | I32: =ROUND(ROUND(12,4),9) -> 12 | J32: 0 | K32: =ROUND(ROUND(12,4),9) -> 12 | O32: =ROUND(CP32,2) -> 697.82 | P32: =ROUND((ROUND((AC32*AW32*I32),2)*BC32),2) -> 77.28 | Q32: =(ROUND((ROUND((((ET32*1.1))*AV32*I32),2)*BB32),2)+ROUND((ROUND(((AE32-((EU32*1.1)))*AV32*I32),2)*BS32),2)) -> 1.66 | R32: =ROUND((ROUND((AE32*AV32*I32),2)*BS32),2) -> 0.14 | S32: =ROUND((ROUND((AF32*AV32*I32),2)*BA32),2) -> 618.88 | T32: =ROUND(CU32*I32,2) -> 0 | U32: =CV32*I32 -> 45.60732 | V32: =CW32*I32 -> 0 | W32: =ROUND(CX32*I32,2) -> 0 | X32: =ROUND(CY32,2) -> 557.12 | Y32: =ROUND(CZ32,2) -> 284.75 | AA32: 59213216 | AB32: =ROUND((AC32+AD32+AF32),6) -> 55.83 | AC32: =ROUND(((ES32*1)),6) -> 6.44 | AD32: =ROUND(((((ET32*1.1))-((EU32*1.1)))+AE32),6) -> 0.132 | AE32: =ROUND(((EU32*1.1)),6) -> 0.011 | AF32: =ROUND(((EV32*1.1)),6) -> 49.258 | AG32: =ROUND((AP32),6) -> 0 | AH32: =((EW32*1.1)) -> 3.63 | AI32: =((EX32*1.1)) -> 0 | AJ32: =(AS32) -> 0 | AK32: 51.34 | AL32: 6.44 | AM32: 0.12 | AN32: 0.01 | AO32: 44.78 | AP32: 0 | AQ32: 3.3 | AR32: 0 | AS32: 0 | AT32: 90 | AU32: 46 | AV32: 1.047 | AW32: 1 | AZ32: 1 | BA32: 1 | BB32: 1 | BC32: 1 | BH32: 0 | BI32: 2 | BJ32: ТСН-2001.4. Доп. 1-42. Сб. 10, т. 80, поз. 4 | BM32: 68 | BN32: 58808062 | BO32: 4.10-80-4 | BP32: 1 | BQ32: 40 | BR32: 0 | BS32: 1 | BT32: 1 | BU32: 1 | BV32: 1 | BW32: 1 | BX32: 1 | BZ32: 90 | CA32: 46 | CE32: 30 | CF32: 0 | CG32: 0 | CM32: 0 | CN32: Поправка: Гл.12.Прил.8.п.8. 5_12.00.01.11.003 Наименование: При наличии усложненных условий производства работ (стесненность, сложность складирования и транспортной логистики, наличие в зоне производства работ действующего технологического оборудования или движения технологического транспорта и т.п.) для объектов, расположенных за пределами территории круговой магистральной системы улиц "Садовое кольцо" и за пределами Третьего транспортного кольца города Москвы пунктов "а" и "б", но в пределах Московской кольцевой автомобильной дороги | CO32: 0 | CP32: =(P32+Q32+S32) -> 697.82 | CQ32: =ROUND((ROUND((AC32*AW32*1),2)*BC32),2) -> 6.44 | CR32: =(ROUND((ROUND((((ET32*1.1))*AV32*1),2)*BB32),2)+ROUND((ROUND(((AE32-((EU32*1.1)))*AV32*1),2)*BS32),2)) -> 0.14 | CS32: =ROUND((ROUND((AE32*AV32*1),2)*BS32),2) -> 0.01 | CT32: =ROUND((ROUND((AF32*AV32*1),2)*BA32),2) -> 51.57 | CU32: =AG32 -> 0 | CV32: =(AH32*AV32) -> 3.80061 | CW32: =AI32 -> 0 | CX32: =AJ32 -> 0 | CY32: =(((S32+R32)*AT32)/100) -> 557.118 | CZ32: =(((S32+R32)*AU32)/100) -> 284.7492 | DB32: 3 | DD32: *1 | DE32: *1,1 | DF32: *1,1 | DG32: *1,1 | DI32: *1,1 | DJ32: *1,1 | DN32: 0 | DO32: 0 | DP32: 1 | DQ32: 1 | DU32: 1013 | DV32: 1 ШТ. | DW32: 1 ШТ. | DX32: 1 | EE32: 58808178 | EF32: 40 | EG32: Монтаж оборудования | EH32: 0 | EJ32: 2 | EK32: 68 | EL32: ТСН-2001.4-10. Прокладка и монтаж сетей связи | EM32: ТСН-2001.4-10-1 | EO32: Поправка: Гл.12.Прил.8.п.8. 5_12.00.01.11.003 | EQ32: 0 | ER32: 51.34 | ES32: 6.44 | ET32: 0.12 | EU32: 0.01 | EV32: 44.78 | EW32: 3.3 | EX32: 0 | EY32: 0 | FQ32: 0 | FR32: 0 | FS32: 0 | FX32: 90 | FY32: 46 | GD32: 1 | GF32: -1862862500 | GG32: 2 | GH32: 1 | GI32: 2 | GJ32: 0 | GK32: 0 | GL32: =ROUND(IF(AND(BH32=3,BI32=3,FS32<>0),P32,0),2) -> 0 | GM32: =ROUND(O32+X32+Y32,2)+GX32 -> 1539.69 | GN32: =IF(OR(BI32=0,BI32=1),GM32-GX32,0) -> 0 | GO32: =IF(BI32=2,GM32-GX32,0) -> 1539.69 | GP32: =IF(BI32=4,GM32-GX32,0) -> 0 | GR32: 0 | GS32: 3 | GT32: 0 | GV32: =ROUND((GT32),6) -> 0 | GW32: 1 | GX32: =ROUND(HC32*I32,2) -> 0 | HA32: 0 | HB32: 0 | HC32: =GV32*GW32 -> 0 | HS32: 0 | IK32: 0
A33: 17 | B33: 1 | C33: =ROW(SmtRes!A10) -> 10 | D33: =ROW(EtalonRes!A12) -> 12 | E33: 3 | F33: 4.10-80-4 | G33: Аппараты приемные, приборы ПС приемно-контрольные, пусковые, прибор ПС на 4 луча | H33: 1 ШТ. | I33: =ROUND(ROUND(12,4),9) -> 12 | J33: 0 | K33: =ROUND(ROUND(12,4),9) -> 12 | O33: =ROUND(CP33,2) -> 34819.34 | P33: =ROUND((ROUND((AC33*AW33*I33),2)*BC33),2) -> 764.3 | Q33: =(ROUND((ROUND((((ET33*1.1))*AV33*I33),2)*BB33),2)+ROUND((ROUND(((AE33-((EU33*1.1)))*AV33*I33),2)*BS33),2)) -> 22.83 | R33: =ROUND((ROUND((AE33*AV33*I33),2)*BS33),2) -> 7.7 | S33: =ROUND((ROUND((AF33*AV33*I33),2)*BA33),2) -> 34032.21 | T33: =ROUND(CU33*I33,2) -> 0 | U33: =CV33*I33 -> 45.60732 | V33: =CW33*I33 -> 0 | W33: =ROUND(CX33*I33,2) -> 0 | X33: =ROUND(CY33,2) -> 30635.92 | Y33: =ROUND(CZ33,2) -> 15658.36 | AA33: 59213213 | AB33: =ROUND((AC33+AD33+AF33),6) -> 55.83 | AC33: =ROUND(((ES33*1)),6) -> 6.44 | AD33: =ROUND(((((ET33*1.1))-((EU33*1.1)))+AE33),6) -> 0.132 | AE33: =ROUND(((EU33*1.1)),6) -> 0.011 | AF33: =ROUND(((EV33*1.1)),6) -> 49.258 | AG33: =ROUND((AP33),6) -> 0 | AH33: =((EW33*1.1)) -> 3.63 | AI33: =((EX33*1.1)) -> 0 | AJ33: =(AS33) -> 0 | AK33: 51.34 | AL33: 6.44 | AM33: 0.12 | AN33: 0.01 | AO33: 44.78 | AP33: 0 | AQ33: 3.3 | AR33: 0 | AS33: 0 | AT33: 90 | AU33: 46 | AV33: 1.047 | AW33: 1 | AZ33: 1 | BA33: 54.99 | BB33: 13.75 | BC33: 9.89 | BH33: 0 | BI33: 2 | BJ33: ТСН-2001.4. Доп. 1-42. Сб. 10, т. 80, поз. 4 | BM33: 68 | BN33: 58808062 | BO33: 4.10-80-4 | BP33: 1 | BQ33: 40 | BR33: 0 | BS33: 54.99 | BT33: 1 | BU33: 1 | BV33: 1 | BW33: 1 | BX33: 1 | BZ33: 90 | CA33: 46 | CE33: 30 | CF33: 0 | CG33: 0 | CM33: 0 | CN33: Поправка: Гл.12.Прил.8.п.8. 5_12.00.01.11.003 Наименование: При наличии усложненных условий производства работ (стесненность, сложность складирования и транспортной логистики, наличие в зоне производства работ действующего технологического оборудования или движения технологического транспорта и т.п.) для объектов, расположенных за пределами территории круговой магистральной системы улиц "Садовое кольцо" и за пределами Третьего транспортного кольца города Москвы пунктов "а" и "б", но в пределах Московской кольцевой автомобильной дороги | CO33: 0 | CP33: =(P33+Q33+S33) -> 34819.34 | CQ33: =ROUND((ROUND((AC33*AW33*1),2)*BC33),2) -> 63.69 | CR33: =(ROUND((ROUND((((ET33*1.1))*AV33*1),2)*BB33),2)+ROUND((ROUND(((AE33-((EU33*1.1)))*AV33*1),2)*BS33),2)) -> 1.93 | CS33: =ROUND((ROUND((AE33*AV33*1),2)*BS33),2) -> 0.55 | CT33: =ROUND((ROUND((AF33*AV33*1),2)*BA33),2) -> 2835.83 | CU33: =AG33 -> 0 | CV33: =(AH33*AV33) -> 3.80061 | CW33: =AI33 -> 0 | CX33: =AJ33 -> 0 | CY33: =(((S33+R33)*AT33)/100) -> 30635.919 | CZ33: =(((S33+R33)*AU33)/100) -> 15658.359 | DB33: 4 | DD33: *1 | DE33: *1,1 | DF33: *1,1 | DG33: *1,1 | DI33: *1,1 | DJ33: *1,1 | DN33: 0 | DO33: 0 | DP33: 1 | DQ33: 1 | DU33: 1013 | DV33: 1 ШТ. | DW33: 1 ШТ. | DX33: 1 | EE33: 58808178 | EF33: 40 | EG33: Монтаж оборудования | EH33: 0 | EJ33: 2 | EK33: 68 | EL33: ТСН-2001.4-10. Прокладка и монтаж сетей связи | EM33: ТСН-2001.4-10-1 | EO33: Поправка: Гл.12.Прил.8.п.8. 5_12.00.01.11.003 | EQ33: 0 | ER33: 51.34 | ES33: 6.44 | ET33: 0.12 | EU33: 0.01 | EV33: 44.78 | EW33: 3.3 | EX33: 0 | EY33: 0 | FQ33: 0 | FR33: 0 | FS33: 0 | FX33: 90 | FY33: 46 | GD33: 1 | GF33: -1862862500 | GG33: 2 | GH33: 1 | GI33: 2 | GJ33: 0 | GK33: 0 | GL33: =ROUND(IF(AND(BH33=3,BI33=3,FS33<>0),P33,0),2) -> 0 | GM33: =ROUND(O33+X33+Y33,2)+GX33 -> 81113.62 | GN33: =IF(OR(BI33=0,BI33=1),GM33-GX33,0) -> 0 | GO33: =IF(BI33=2,GM33-GX33,0) -> 81113.62 | GP33: =IF(BI33=4,GM33-GX33,0) -> 0 | GR33: 0 | GS33: 3 | GT33: 0 | GV33: =ROUND((GT33),6) -> 0 | GW33: 1 | GX33: =ROUND(HC33*I33,2) -> 0 | HA33: 0 | HB33: 0 | HC33: =GV33*GW33 -> 0 | HS33: 0 | IK33: 0
A34: 17 | B34: 1 | E34: 4 | F34: КА 2 | G34: Модуль доступа-контроллер доступа STR-1AP-M на 2 точки | H34: шт. | I34: =ROUND(ROUND(12,4),9) -> 12 | J34: 0 | K34: =ROUND(ROUND(12,4),9) -> 12 | O34: =ROUND(CP34,2) -> 21636.48 | P34: =ROUND((ROUND((AC34*I34),2)*BC34),2) -> 21636.48 | Q34: =(ROUND((ROUND(((ET34)*AV34*I34),2)*BB34),2)+ROUND((ROUND(((AE34-(EU34))*AV34*I34),2)*BS34),2)) -> 0 | R34: =ROUND((ROUND((AE34*AV34*I34),2)*BS34),2) -> 0 | S34: =ROUND((ROUND((AF34*AV34*I34),2)*BA34),2) -> 0 | T34: =ROUND(CU34*I34,2) -> 0 | U34: =CV34*I34 -> 0 | V34: =CW34*I34 -> 0 | W34: =ROUND(CX34*I34,2) -> 0 | X34: =ROUND(CY34,2) -> 0 | Y34: =ROUND(CZ34,2) -> 0 | AA34: 59213216 | AB34: =ROUND((AC34+AD34+AF34),6) -> 1803.04 | AC34: =ROUND((ES34),6) -> 1803.04 | AD34: =ROUND((((ET34)-(EU34))+AE34),6) -> 0 | AE34: =ROUND((EU34),6) -> 0 | AF34: =ROUND((EV34),6) -> 0 | AG34: =ROUND((AP34),6) -> 0 | AH34: =(EW34) -> 0 | AI34: =(EX34) -> 0 | AJ34: =(AS34) -> 0 | AK34: 1803.04 | AL34: 1803.04 | AM34: 0 | AN34: 0 | AO34: 0 | AP34: 0 | AQ34: 0 | AR34: 0 | AS34: 0 | AT34: 0 | AU34: 0 | AV34: 1 | AW34: 1 | AZ34: 1 | BA34: 1 | BB34: 1 | BC34: 1 | BH34: 3 | BI34: 3 | BM34: 746 | BN34: 0 | BP34: 0 | BQ34: 130 | BR34: 0 | BS34: 1 | BT34: 1 | BU34: 1 | BV34: 1 | BW34: 1 | BX34: 1 | BZ34: 0 | CA34: 0 | CE34: 30 | CF34: 0 | CG34: 0 | CM34: 0 | CO34: 0 | CP34: =(P34+Q34+S34) -> 21636.48 | CQ34: =ROUND((ROUND((AC34*1),2)*BC34),2) -> 1803.04 | CR34: =(ROUND((ROUND(((ET34)*AV34*1),2)*BB34),2)+ROUND((ROUND(((AE34-(EU34))*AV34*1),2)*BS34),2)) -> 0 | CS34: =ROUND((ROUND((AE34*AV34*1),2)*BS34),2) -> 0 | CT34: =ROUND((ROUND((AF34*AV34*1),2)*BA34),2) -> 0 | CU34: =AG34 -> 0 | CV34: =(AH34*AV34) -> 0 | CW34: =AI34 -> 0 | CX34: =AJ34 -> 0 | CY34: =(((S34+R34)*AT34)/100) -> 0 | CZ34: =(((S34+R34)*AU34)/100) -> 0 | DN34: 0 | DO34: 0 | DP34: 1 | DQ34: 1 | DU34: 1010 | DV34: шт. | DW34: шт. | DX34: 1 | EE34: 58808284 | EF34: 130 | EG34: Сметная стоимость оборудования | EH34: 0 | EJ34: 3 | EK34: 746 | EL34: ТСН-2001.13. Сметная стоимость оборудования | EM34: ТСН-2001.13 | EQ34: 0 | ER34: 0 | ES34: 1803.04 | ET34: 0 | EU34: 0 | EV34: 0 | EW34: 0 | EX34: 0 | EY34: 0 | FQ34: 0 | FR34: =P34 -> 21636.48 | FS34: 0 | FX34: 0 | FY34: 0 | GA34: [15 900 / 1,2 / 7,66] + 3% Трансп + 1,2% Заг.скл | GD34: 1 | GF34: 1328923490 | GG34: 2 | GH34: 4 | GI34: -2 | GJ34: 0 | GK34: 0 | GL34: =ROUND(IF(AND(BH34=3,BI34=3,FS34<>0),P34,0),2) -> 0 | GM34: =ROUND(O34+X34+Y34,2)+GX34 -> 21636.48 | GN34: =IF(OR(BI34=0,BI34=1),GM34-GX34,0) -> 0 | GO34: =IF(BI34=2,GM34-GX34,0) -> 0 | GP34: =IF(BI34=4,GM34-GX34,0) -> 0 | GR34: 0 | GS34: 2 | GT34: 0 | GV34: =ROUND((GT34),6) -> 0 | GW34: 1 | GX34: =ROUND(HC34*I34,2) -> 0 | HA34: 0 | HB34: 0 | HC34: =GV34*GW34 -> 0 | HE34: 3 | HF34: 1,2 | HS34: 0 | IK34: 0
A35: 17 | B35: 1 | E35: 4 | F35: КА 2 | G35: Модуль доступа-контроллер доступа STR-1AP-M на 2 точки | H35: шт. | I35: =ROUND(ROUND(12,4),9) -> 12 | J35: 0 | K35: =ROUND(ROUND(12,4),9) -> 12 | O35: =ROUND(CP35,2) -> 165735.44 | P35: =ROUND((ROUND((AC35*I35),2)*BC35),2) -> 165735.44 | Q35: =(ROUND((ROUND(((ET35)*AV35*I35),2)*BB35),2)+ROUND((ROUND(((AE35-(EU35))*AV35*I35),2)*BS35),2)) -> 0 | R35: =ROUND((ROUND((AE35*AV35*I35),2)*BS35),2) -> 0 | S35: =ROUND((ROUND((AF35*AV35*I35),2)*BA35),2) -> 0 | T35: =ROUND(CU35*I35,2) -> 0 | U35: =CV35*I35 -> 0 | V35: =CW35*I35 -> 0 | W35: =ROUND(CX35*I35,2) -> 0 | X35: =ROUND(CY35,2) -> 0 | Y35: =ROUND(CZ35,2) -> 0 | AA35: 59213213 | AB35: =ROUND((AC35+AD35+AF35),6) -> 1803.04 | AC35: =ROUND((ES35),6) -> 1803.04 | AD35: =ROUND((((ET35)-(EU35))+AE35),6) -> 0 | AE35: =ROUND((EU35),6) -> 0 | AF35: =ROUND((EV35),6) -> 0 | AG35: =ROUND((AP35),6) -> 0 | AH35: =(EW35) -> 0 | AI35: =(EX35) -> 0 | AJ35: =(AS35) -> 0 | AK35: 1803.04 | AL35: 1803.04 | AM35: 0 | AN35: 0 | AO35: 0 | AP35: 0 | AQ35: 0 | AR35: 0 | AS35: 0 | AT35: 0 | AU35: 0 | AV35: 1 | AW35: 1 | AZ35: 1 | BA35: 1 | BB35: 1 | BC35: 7.66 | BH35: 3 | BI35: 3 | BM35: 746 | BN35: 0 | BP35: 0 | BQ35: 130 | BR35: 0 | BS35: 1 | BT35: 1 | BU35: 1 | BV35: 1 | BW35: 1 | BX35: 1 | BZ35: 0 | CA35: 0 | CE35: 30 | CF35: 0 | CG35: 0 | CM35: 0 | CO35: 0 | CP35: =(P35+Q35+S35) -> 165735.44 | CQ35: =ROUND((ROUND((AC35*1),2)*BC35),2) -> 13811.29 | CR35: =(ROUND((ROUND(((ET35)*AV35*1),2)*BB35),2)+ROUND((ROUND(((AE35-(EU35))*AV35*1),2)*BS35),2)) -> 0 | CS35: =ROUND((ROUND((AE35*AV35*1),2)*BS35),2) -> 0 | CT35: =ROUND((ROUND((AF35*AV35*1),2)*BA35),2) -> 0 | CU35: =AG35 -> 0 | CV35: =(AH35*AV35) -> 0 | CW35: =AI35 -> 0 | CX35: =AJ35 -> 0 | CY35: =(((S35+R35)*AT35)/100) -> 0 | CZ35: =(((S35+R35)*AU35)/100) -> 0 | DN35: 0 | DO35: 0 | DP35: 1 | DQ35: 1 | DU35: 1010 | DV35: шт. | DW35: шт. | DX35: 1 | EE35: 58808284 | EF35: 130 | EG35: Сметная стоимость оборудования | EH35: 0 | EJ35: 3 | EK35: 746 | EL35: ТСН-2001.13. Сметная стоимость оборудования | EM35: ТСН-2001.13 | EQ35: 0 | ER35: 1803.04 | ES35: 1803.04 | ET35: 0 | EU35: 0 | EV35: 0 | EW35: 0 | EX35: 0 | EY35: 0 | EZ35: 5 | FC35: 1 | FD35: 18 | FF35: 15900 | FQ35: 0 | FR35: =P35 -> 165735.44 | FS35: 0 | FX35: 0 | FY35: 0 | GA35: [15 900 / 1,2 / 7,66] + 3% Трансп + 1,2% Заг.скл | GD35: 1 | GF35: 1328923490 | GG35: 2 | GH35: 3 | GI35: 5 | GJ35: 0 | GK35: 0 | GL35: =ROUND(IF(AND(BH35=3,BI35=3,FS35<>0),P35,0),2) -> 0 | GM35: =ROUND(O35+X35+Y35,2)+GX35 -> 165735.44 | GN35: =IF(OR(BI35=0,BI35=1),GM35-GX35,0) -> 0 | GO35: =IF(BI35=2,GM35-GX35,0) -> 0 | GP35: =IF(BI35=4,GM35-GX35,0) -> 0 | GR35: 2 | GS35: 1 | GT35: 0 | GV35: =ROUND((GT35),6) -> 0 | GW35: 1 | GX35: =ROUND(HC35*I35,2) -> 0 | HA35: 0 | HB35: 0 | HC35: =GV35*GW35 -> 0 | HE35: 3 | HF35: 1,2 | HS35: 0 | IK35: 0
A36: 17 | B36: 1 | C36: =ROW(SmtRes!A11) -> 11 | D36: =ROW(EtalonRes!A13) -> 13 | E36: 5 | F36: 4.10-80-4 | G36: Аппараты приемные, приборы ПС приемно-контрольные, пусковые, прибор ПС на 4 луча | H36: 1 ШТ. | I36: =ROUND(ROUND(15,4),9) -> 15 | J36: 0 | K36: =ROUND(ROUND(15,4),9) -> 15 | O36: =ROUND(CP36,2) -> 872.27 | P36: =ROUND((ROUND((AC36*AW36*I36),2)*BC36),2) -> 96.6 | Q36: =(ROUND((ROUND((((ET36*1.1))*AV36*I36),2)*BB36),2)+ROUND((ROUND(((AE36-((EU36*1.1)))*AV36*I36),2)*BS36),2)) -> 2.07 | R36: =ROUND((ROUND((AE36*AV36*I36),2)*BS36),2) -> 0.17 | S36: =ROUND((ROUND((AF36*AV36*I36),2)*BA36),2) -> 773.6 | T36: =ROUND(CU36*I36,2) -> 0 | U36: =CV36*I36 -> 57.00915 | V36: =CW36*I36 -> 0 | W36: =ROUND(CX36*I36,2) -> 0 | X36: =ROUND(CY36,2) -> 696.39 | Y36: =ROUND(CZ36,2) -> 355.93 | AA36: 59213216 | AB36: =ROUND((AC36+AD36+AF36),6) -> 55.83 | AC36: =ROUND(((ES36*1)),6) -> 6.44 | AD36: =ROUND(((((ET36*1.1))-((EU36*1.1)))+AE36),6) -> 0.132 | AE36: =ROUND(((EU36*1.1)),6) -> 0.011 | AF36: =ROUND(((EV36*1.1)),6) -> 49.258 | AG36: =ROUND((AP36),6) -> 0 | AH36: =((EW36*1.1)) -> 3.63 | AI36: =((EX36*1.1)) -> 0 | AJ36: =(AS36) -> 0 | AK36: 51.34 | AL36: 6.44 | AM36: 0.12 | AN36: 0.01 | AO36: 44.78 | AP36: 0 | AQ36: 3.3 | AR36: 0 | AS36: 0 | AT36: 90 | AU36: 46 | AV36: 1.047 | AW36: 1 | AZ36: 1 | BA36: 1 | BB36: 1 | BC36: 1 | BH36: 0 | BI36: 2 | BJ36: ТСН-2001.4. Доп. 1-42. Сб. 10, т. 80, поз. 4 | BM36: 68 | BN36: 58808062 | BO36: 4.10-80-4 | BP36: 1 | BQ36: 40 | BR36: 0 | BS36: 1 | BT36: 1 | BU36: 1 | BV36: 1 | BW36: 1 | BX36: 1 | BZ36: 90 | CA36: 46 | CE36: 30 | CF36: 0 | CG36: 0 | CM36: 0 | CN36: Поправка: Гл.12.Прил.8.п.8. 5_12.00.01.11.003 Наименование: При наличии усложненных условий производства работ (стесненность, сложность складирования и транспортной логистики, наличие в зоне производства работ действующего технологического оборудования или движения технологического транспорта и т.п.) для объектов, расположенных за пределами территории круговой магистральной системы улиц "Садовое кольцо" и за пределами Третьего транспортного кольца города Москвы пунктов "а" и "б", но в пределах Московской кольцевой автомобильной дороги | CO36: 0 | CP36: =(P36+Q36+S36) -> 872.27 | CQ36: =ROUND((ROUND((AC36*AW36*1),2)*BC36),2) -> 6.44 | CR36: =(ROUND((ROUND((((ET36*1.1))*AV36*1),2)*BB36),2)+ROUND((ROUND(((AE36-((EU36*1.1)))*AV36*1),2)*BS36),2)) -> 0.14 | CS36: =ROUND((ROUND((AE36*AV36*1),2)*BS36),2) -> 0.01 | CT36: =ROUND((ROUND((AF36*AV36*1),2)*BA36),2) -> 51.57 | CU36: =AG36 -> 0 | CV36: =(AH36*AV36) -> 3.80061 | CW36: =AI36 -> 0 | CX36: =AJ36 -> 0 | CY36: =(((S36+R36)*AT36)/100) -> 696.393 | CZ36: =(((S36+R36)*AU36)/100) -> 355.9342 | DB36: 5 | DD36: *1 | DE36: *1,1 | DF36: *1,1 | DG36: *1,1 | DI36: *1,1 | DJ36: *1,1 | DN36: 0 | DO36: 0 | DP36: 1 | DQ36: 1 | DU36: 1013 | DV36: 1 ШТ. | DW36: 1 ШТ. | DX36: 1 | EE36: 58808178 | EF36: 40 | EG36: Монтаж оборудования | EH36: 0 | EJ36: 2 | EK36: 68 | EL36: ТСН-2001.4-10. Прокладка и монтаж сетей связи | EM36: ТСН-2001.4-10-1 | EO36: Поправка: Гл.12.Прил.8.п.8. 5_12.00.01.11.003 | EQ36: 0 | ER36: 51.34 | ES36: 6.44 | ET36: 0.12 | EU36: 0.01 | EV36: 44.78 | EW36: 3.3 | EX36: 0 | EY36: 0 | FQ36: 0 | FR36: 0 | FS36: 0 | FX36: 90 | FY36: 46 | GD36: 1 | GF36: -1862862500 | GG36: 2 | GH36: 1 | GI36: 2 | GJ36: 0 | GK36: 0 | GL36: =ROUND(IF(AND(BH36=3,BI36=3,FS36<>0),P36,0),2) -> 0 | GM36: =ROUND(O36+X36+Y36,2)+GX36 -> 1924.59 | GN36: =IF(OR(BI36=0,BI36=1),GM36-GX36,0) -> 0 | GO36: =IF(BI36=2,GM36-GX36,0) -> 1924.59 | GP36: =IF(BI36=4,GM36-GX36,0) -> 0 | GR36: 0 | GS36: 3 | GT36: 0 | GV36: =ROUND((GT36),6) -> 0 | GW36: 1 | GX36: =ROUND(HC36*I36,2) -> 0 | HA36: 0 | HB36: 0 | HC36: =GV36*GW36 -> 0 | HS36: 0 | IK36: 0
A37: 17 | B37: 1 | C37: =ROW(SmtRes!A12) -> 12 | D37: =ROW(EtalonRes!A14) -> 14 | E37: 5 | F37: 4.10-80-4 | G37: Аппараты приемные, приборы ПС приемно-контрольные, пусковые, прибор ПС на 4 луча | H37: 1 ШТ. | I37: =ROUND(ROUND(15,4),9) -> 15 | J37: 0 | K37: =ROUND(ROUND(15,4),9) -> 15 | O37: =ROUND(CP37,2) -> 43524.09 | P37: =ROUND((ROUND((AC37*AW37*I37),2)*BC37),2) -> 955.37 | Q37: =(ROUND((ROUND((((ET37*1.1))*AV37*I37),2)*BB37),2)+ROUND((ROUND(((AE37-((EU37*1.1)))*AV37*I37),2)*BS37),2)) -> 28.46 | R37: =ROUND((ROUND((AE37*AV37*I37),2)*BS37),2) -> 9.35 | S37: =ROUND((ROUND((AF37*AV37*I37),2)*BA37),2) -> 42540.26 | T37: =ROUND(CU37*I37,2) -> 0 | U37: =CV37*I37 -> 57.00915 | V37: =CW37*I37 -> 0 | W37: =ROUND(CX37*I37,2) -> 0 | X37: =ROUND(CY37,2) -> 38294.65 | Y37: =ROUND(CZ37,2) -> 19572.82 | AA37: 59213213 | AB37: =ROUND((AC37+AD37+AF37),6) -> 55.83 | AC37: =ROUND(((ES37*1)),6) -> 6.44 | AD37: =ROUND(((((ET37*1.1))-((EU37*1.1)))+AE37),6) -> 0.132 | AE37: =ROUND(((EU37*1.1)),6) -> 0.011 | AF37: =ROUND(((EV37*1.1)),6) -> 49.258 | AG37: =ROUND((AP37),6) -> 0 | AH37: =((EW37*1.1)) -> 3.63 | AI37: =((EX37*1.1)) -> 0 | AJ37: =(AS37) -> 0 | AK37: 51.34 | AL37: 6.44 | AM37: 0.12 | AN37: 0.01 | AO37: 44.78 | AP37: 0 | AQ37: 3.3 | AR37: 0 | AS37: 0 | AT37: 90 | AU37: 46 | AV37: 1.047 | AW37: 1 | AZ37: 1 | BA37: 54.99 | BB37: 13.75 | BC37: 9.89 | BH37: 0 | BI37: 2 | BJ37: ТСН-2001.4. Доп. 1-42. Сб. 10, т. 80, поз. 4 | BM37: 68 | BN37: 58808062 | BO37: 4.10-80-4 | BP37: 1 | BQ37: 40 | BR37: 0 | BS37: 54.99 | BT37: 1 | BU37: 1 | BV37: 1 | BW37: 1 | BX37: 1 | BZ37: 90 | CA37: 46 | CE37: 30 | CF37: 0 | CG37: 0 | CM37: 0 | CN37: Поправка: Гл.12.Прил.8.п.8. 5_12.00.01.11.003 Наименование: При наличии усложненных условий производства работ (стесненность, сложность складирования и транспортной логистики, наличие в зоне производства работ действующего технологического оборудования или движения технологического транспорта и т.п.) для объектов, расположенных за пределами территории круговой магистральной системы улиц "Садовое кольцо" и за пределами Третьего транспортного кольца города Москвы пунктов "а" и "б", но в пределах Московской кольцевой автомобильной дороги | CO37: 0 | CP37: =(P37+Q37+S37) -> 43524.09 | CQ37: =ROUND((ROUND((AC37*AW37*1),2)*BC37),2) -> 63.69 | CR37: =(ROUND((ROUND((((ET37*1.1))*AV37*1),2)*BB37),2)+ROUND((ROUND(((AE37-((EU37*1.1)))*AV37*1),2)*BS37),2)) -> 1.93 | CS37: =ROUND((ROUND((AE37*AV37*1),2)*BS37),2) -> 0.55 | CT37: =ROUND((ROUND((AF37*AV37*1),2)*BA37),2) -> 2835.83 | CU37: =AG37 -> 0 | CV37: =(AH37*AV37) -> 3.80061 | CW37: =AI37 -> 0 | CX37: =AJ37 -> 0 | CY37: =(((S37+R37)*AT37)/100) -> 38294.649 | CZ37: =(((S37+R37)*AU37)/100) -> 19572.821 | DB37: 6 | DD37: *1 | DE37: *1,1 | DF37: *1,1 | DG37: *1,1 | DI37: *1,1 | DJ37: *1,1 | DN37: 0 | DO37: 0 | DP37: 1 | DQ37: 1 | DU37: 1013 | DV37: 1 ШТ. | DW37: 1 ШТ. | DX37: 1 | EE37: 58808178 | EF37: 40 | EG37: Монтаж оборудования | EH37: 0 | EJ37: 2 | EK37: 68 | EL37: ТСН-2001.4-10. Прокладка и монтаж сетей связи | EM37: ТСН-2001.4-10-1 | EO37: Поправка: Гл.12.Прил.8.п.8. 5_12.00.01.11.003 | EQ37: 0 | ER37: 51.34 | ES37: 6.44 | ET37: 0.12 | EU37: 0.01 | EV37: 44.78 | EW37: 3.3 | EX37: 0 | EY37: 0 | FQ37: 0 | FR37: 0 | FS37: 0 | FX37: 90 | FY37: 46 | GD37: 1 | GF37: -1862862500 | GG37: 2 | GH37: 1 | GI37: 2 | GJ37: 0 | GK37: 0 | GL37: =ROUND(IF(AND(BH37=3,BI37=3,FS37<>0),P37,0),2) -> 0 | GM37: =ROUND(O37+X37+Y37,2)+GX37 -> 101391.56 | GN37: =IF(OR(BI37=0,BI37=1),GM37-GX37,0) -> 0 | GO37: =IF(BI37=2,GM37-GX37,0) -> 101391.56 | GP37: =IF(BI37=4,GM37-GX37,0) -> 0 | GR37: 0 | GS37: 3 | GT37: 0 | GV37: =ROUND((GT37),6) -> 0 | GW37: 1 | GX37: =ROUND(HC37*I37,2) -> 0 | HA37: 0 | HB37: 0 | HC37: =GV37*GW37 -> 0 | HS37: 0 | IK37: 0
A38: 17 | B38: 1 | E38: 6 | F38: КА 3 | G38: Модуль доступа-контроллер доступа STR-2AP-M на 4 точки | H38: шт. | I38: =ROUND(ROUND(15,4),9) -> 15 | J38: 0 | K38: =ROUND(ROUND(15,4),9) -> 15 | O38: =ROUND(CP38,2) -> 111142.05 | P38: =ROUND((ROUND((AC38*I38),2)*BC38),2) -> 111142.05 | Q38: =(ROUND((ROUND(((ET38)*AV38*I38),2)*BB38),2)+ROUND((ROUND(((AE38-(EU38))*AV38*I38),2)*BS38),2)) -> 0 | R38: =ROUND((ROUND((AE38*AV38*I38),2)*BS38),2) -> 0 | S38: =ROUND((ROUND((AF38*AV38*I38),2)*BA38),2) -> 0 | T38: =ROUND(CU38*I38,2) -> 0 | U38: =CV38*I38 -> 0 | V38: =CW38*I38 -> 0 | W38: =ROUND(CX38*I38,2) -> 0 | X38: =ROUND(CY38,2) -> 0 | Y38: =ROUND(CZ38,2) -> 0 | AA38: 59213216 | AB38: =ROUND((AC38+AD38+AF38),6) -> 7409.47 | AC38: =ROUND((ES38),6) -> 7409.47 | AD38: =ROUND((((ET38)-(EU38))+AE38),6) -> 0 | AE38: =ROUND((EU38),6) -> 0 | AF38: =ROUND((EV38),6) -> 0 | AG38: =ROUND((AP38),6) -> 0 | AH38: =(EW38) -> 0 | AI38: =(EX38) -> 0 | AJ38: =(AS38) -> 0 | AK38: 7409.47 | AL38: 7409.47 | AM38: 0 | AN38: 0 | AO38: 0 | AP38: 0 | AQ38: 0 | AR38: 0 | AS38: 0 | AT38: 0 | AU38: 0 | AV38: 1 | AW38: 1 | AZ38: 1 | BA38: 1 | BB38: 1 | BC38: 1 | BH38: 3 | BI38: 3 | BM38: 746 | BN38: 0 | BP38: 0 | BQ38: 130 | BR38: 0 | BS38: 1 | BT38: 1 | BU38: 1 | BV38: 1 | BW38: 1 | BX38: 1 | BZ38: 0 | CA38: 0 | CE38: 30 | CF38: 0 | CG38: 0 | CM38: 0 | CO38: 0 | CP38: =(P38+Q38+S38) -> 111142.05 | CQ38: =ROUND((ROUND((AC38*1),2)*BC38),2) -> 7409.47 | CR38: =(ROUND((ROUND(((ET38)*AV38*1),2)*BB38),2)+ROUND((ROUND(((AE38-(EU38))*AV38*1),2)*BS38),2)) -> 0 | CS38: =ROUND((ROUND((AE38*AV38*1),2)*BS38),2) -> 0 | CT38: =ROUND((ROUND((AF38*AV38*1),2)*BA38),2) -> 0 | CU38: =AG38 -> 0 | CV38: =(AH38*AV38) -> 0 | CW38: =AI38 -> 0 | CX38: =AJ38 -> 0 | CY38: =(((S38+R38)*AT38)/100) -> 0 | CZ38: =(((S38+R38)*AU38)/100) -> 0 | DN38: 0 | DO38: 0 | DP38: 1 | DQ38: 1 | DU38: 1010 | DV38: шт. | DW38: шт. | DX38: 1 | EE38: 58808284 | EF38: 130 | EG38: Сметная стоимость оборудования | EH38: 0 | EJ38: 3 | EK38: 746 | EL38: ТСН-2001.13. Сметная стоимость оборудования | EM38: ТСН-2001.13 | EQ38: 0 | ER38: 0 | ES38: 7409.47 | ET38: 0 | EU38: 0 | EV38: 0 | EW38: 0 | EX38: 0 | EY38: 0 | FQ38: 0 | FR38: =P38 -> 111142.05 | FS38: 0 | FX38: 0 | FY38: 0 | GA38: [65 340 / 1,2 / 7,66] + 3% Трансп + 1,2% Заг.скл | GD38: 1 | GF38: -1498015221 | GG38: 2 | GH38: 4 | GI38: 0 | GJ38: 0 | GK38: 0 | GL38: =ROUND(IF(AND(BH38=3,BI38=3,FS38<>0),P38,0),2) -> 0 | GM38: =ROUND(O38+X38+Y38,2)+GX38 -> 111142.05 | GN38: =IF(OR(BI38=0,BI38=1),GM38-GX38,0) -> 0 | GO38: =IF(BI38=2,GM38-GX38,0) -> 0 | GP38: =IF(BI38=4,GM38-GX38,0) -> 0 | GR38: 0 | GS38: 2 | GT38: 0 | GV38: =ROUND((GT38),6) -> 0 | GW38: 1 | GX38: =ROUND(HC38*I38,2) -> 0 | HA38: 0 | HB38: 0 | HC38: =GV38*GW38 -> 0 | HE38: 3 | HF38: 1,2 | HS38: 0 | IK38: 0
A39: 17 | B39: 1 | E39: 6 | F39: КА 3 | G39: Модуль доступа-контроллер доступа STR-2AP-M на 4 точки | H39: шт. | I39: =ROUND(ROUND(15,4),9) -> 15 | J39: 0 | K39: =ROUND(ROUND(15,4),9) -> 15 | O39: =ROUND(CP39,2) -> 851348.1 | P39: =ROUND((ROUND((AC39*I39),2)*BC39),2) -> 851348.1 | Q39: =(ROUND((ROUND(((ET39)*AV39*I39),2)*BB39),2)+ROUND((ROUND(((AE39-(EU39))*AV39*I39),2)*BS39),2)) -> 0 | R39: =ROUND((ROUND((AE39*AV39*I39),2)*BS39),2) -> 0 | S39: =ROUND((ROUND((AF39*AV39*I39),2)*BA39),2) -> 0 | T39: =ROUND(CU39*I39,2) -> 0 | U39: =CV39*I39 -> 0 | V39: =CW39*I39 -> 0 | W39: =ROUND(CX39*I39,2) -> 0 | X39: =ROUND(CY39,2) -> 0 | Y39: =ROUND(CZ39,2) -> 0 | AA39: 59213213 | AB39: =ROUND((AC39+AD39+AF39),6) -> 7409.47 | AC39: =ROUND((ES39),6) -> 7409.47 | AD39: =ROUND((((ET39)-(EU39))+AE39),6) -> 0 | AE39: =ROUND((EU39),6) -> 0 | AF39: =ROUND((EV39),6) -> 0 | AG39: =ROUND((AP39),6) -> 0 | AH39: =(EW39) -> 0 | AI39: =(EX39) -> 0 | AJ39: =(AS39) -> 0 | AK39: 7409.47 | AL39: 7409.47 | AM39: 0 | AN39: 0 | AO39: 0 | AP39: 0 | AQ39: 0 | AR39: 0 | AS39: 0 | AT39: 0 | AU39: 0 | AV39: 1 | AW39: 1 | AZ39: 1 | BA39: 1 | BB39: 1 | BC39: 7.66 | BH39: 3 | BI39: 3 | BM39: 746 | BN39: 0 | BP39: 0 | BQ39: 130 | BR39: 0 | BS39: 1 | BT39: 1 | BU39: 1 | BV39: 1 | BW39: 1 | BX39: 1 | BZ39: 0 | CA39: 0 | CE39: 30 | CF39: 0 | CG39: 0 | CM39: 0 | CO39: 0 | CP39: =(P39+Q39+S39) -> 851348.1 | CQ39: =ROUND((ROUND((AC39*1),2)*BC39),2) -> 56756.54 | CR39: =(ROUND((ROUND(((ET39)*AV39*1),2)*BB39),2)+ROUND((ROUND(((AE39-(EU39))*AV39*1),2)*BS39),2)) -> 0 | CS39: =ROUND((ROUND((AE39*AV39*1),2)*BS39),2) -> 0 | CT39: =ROUND((ROUND((AF39*AV39*1),2)*BA39),2) -> 0 | CU39: =AG39 -> 0 | CV39: =(AH39*AV39) -> 0 | CW39: =AI39 -> 0 | CX39: =AJ39 -> 0 | CY39: =(((S39+R39)*AT39)/100) -> 0 | CZ39: =(((S39+R39)*AU39)/100) -> 0 | DN39: 0 | DO39: 0 | DP39: 1 | DQ39: 1 | DU39: 1010 | DV39: шт. | DW39: шт. | DX39: 1 | EE39: 58808284 | EF39: 130 | EG39: Сметная стоимость оборудования | EH39: 0 | EJ39: 3 | EK39: 746 | EL39: ТСН-2001.13. Сметная стоимость оборудования | EM39: ТСН-2001.13 | EQ39: 0 | ER39: 7409.47 | ES39: 7409.47 | ET39: 0 | EU39: 0 | EV39: 0 | EW39: 0 | EX39: 0 | EY39: 0 | EZ39: 5 | FC39: 1 | FD39: 18 | FF39: 65340 | FQ39: 0 | FR39: =P39 -> 851348.1 | FS39: 0 | FX39: 0 | FY39: 0 | GA39: [65 340 / 1,2 / 7,66] + 3% Трансп + 1,2% Заг.скл | GD39: 1 | GF39: -1498015221 | GG39: 2 | GH39: 3 | GI39: 5 | GJ39: 0 | GK39: 0 | GL39: =ROUND(IF(AND(BH39=3,BI39=3,FS39<>0),P39,0),2) -> 0 | GM39: =ROUND(O39+X39+Y39,2)+GX39 -> 851348.1 | GN39: =IF(OR(BI39=0,BI39=1),GM39-GX39,0) -> 0 | GO39: =IF(BI39=2,GM39-GX39,0) -> 0 | GP39: =IF(BI39=4,GM39-GX39,0) -> 0 | GR39: 2 | GS39: 1 | GT39: 0 | GV39: =ROUND((GT39),6) -> 0 | GW39: 1 | GX39: =ROUND(HC39*I39,2) -> 0 | HA39: 0 | HB39: 0 | HC39: =GV39*GW39 -> 0 | HE39: 3 | HF39: 1,2 | HS39: 0 | IK39: 0
A40: 17 | B40: 1 | C40: =ROW(SmtRes!A28) -> 28 | D40: =ROW(EtalonRes!A31) -> 31 | E40: 7 | F40: 4.11-1-2 | G40: Монтаж конструкции для установки приборов и средств автоматизации массой до 2 кг | H40: 1 ШТ. | I40: =ROUND(ROUND(27,4),9) -> 27 | J40: 0 | K40: =ROUND(ROUND(27,4),9) -> 27 | O40: =ROUND(CP40,2) -> 1200.41 | P40: =ROUND((ROUND((AC40*AW40*I40),2)*BC40),2) -> 960.66 | Q40: =(ROUND((ROUND((((ET40*1.1))*AV40*I40),2)*BB40),2)+ROUND((ROUND(((AE40-((EU40*1.1)))*AV40*I40),2)*BS40),2)) -> 54.73 | R40: =ROUND((ROUND((AE40*AV40*I40),2)*BS40),2) -> 11.51 | S40: =ROUND((ROUND((AF40*AV40*I40),2)*BA40),2) -> 185.02 | T40: =ROUND(CU40*I40,2) -> 0 | U40: =CV40*I40 -> 16.169868 | V40: =CW40*I40 -> 0 | W40: =ROUND(CX40*I40,2) -> 0 | X40: =ROUND(CY40,2) -> 176.88 | Y40: =ROUND(CZ40,2) -> 90.4 | AA40: 59213216 | AB40: =ROUND((AC40+AD40+AF40),6) -> 44.061 | AC40: =ROUND(((ES40*1)),6) -> 35.58 | AD40: =ROUND(((((ET40*1.1))-((EU40*1.1)))+AE40),6) -> 1.936 | AE40: =ROUND(((EU40*1.1)),6) -> 0.407 | AF40: =ROUND(((EV40*1.1)),6) -> 6.545 | AG40: =ROUND((AP40),6) -> 0 | AH40: =((EW40*1.1)) -> 0.572 | AI40: =((EX40*1.1)) -> 0 | AJ40: =(AS40) -> 0 | AK40: 43.29 | AL40: 35.58 | AM40: 1.76 | AN40: 0.37 | AO40: 5.95 | AP40: 0 | AQ40: 0.52 | AR40: 0 | AS40: 0 | AT40: 90 | AU40: 46 | AV40: 1.047 | AW40: 1 | AZ40: 1 | BA40: 1 | BB40: 1 | BC40: 1 | BH40: 0 | BI40: 2 | BJ40: ТСН-2001.4 Доп. 80, Сб. 11, т. 1, поз. 2 | BM40: 72 | BN40: 58808062 | BO40: 4.11-1-2 | BP40: 1 | BQ40: 40 | BR40: 0 | BS40: 1 | BT40: 1 | BU40: 1 | BV40: 1 | BW40: 1 | BX40: 1 | BZ40: 90 | CA40: 46 | CE40: 30 | CF40: 0 | CG40: 0 | CM40: 0 | CN40: Поправка: Гл.12.Прил.8.п.8. 5_12.00.01.11.003 Наименование: При наличии усложненных условий производства работ (стесненность, сложность складирования и транспортной логистики, наличие в зоне производства работ действующего технологического оборудования или движения технологического транспорта и т.п.) для объектов, расположенных за пределами территории круговой магистральной системы улиц "Садовое кольцо" и за пределами Третьего транспортного кольца города Москвы пунктов "а" и "б", но в пределах Московской кольцевой автомобильной дороги | CO40: 0 | CP40: =(P40+Q40+S40) -> 1200.41 | CQ40: =ROUND((ROUND((AC40*AW40*1),2)*BC40),2) -> 35.58 | CR40: =(ROUND((ROUND((((ET40*1.1))*AV40*1),2)*BB40),2)+ROUND((ROUND(((AE40-((EU40*1.1)))*AV40*1),2)*BS40),2)) -> 2.03 | CS40: =ROUND((ROUND((AE40*AV40*1),2)*BS40),2) -> 0.43 | CT40: =ROUND((ROUND((AF40*AV40*1),2)*BA40),2) -> 6.85 | CU40: =AG40 -> 0 | CV40: =(AH40*AV40) -> 0.598884 | CW40: =AI40 -> 0 | CX40: =AJ40 -> 0 | CY40: =(((S40+R40)*AT40)/100) -> 176.877 | CZ40: =(((S40+R40)*AU40)/100) -> 90.4038 | DB40: 7 | DD40: *1 | DE40: *1,1 | DF40: *1,1 | DG40: *1,1 | DI40: *1,1 | DJ40: *1,1 | DN40: 0 | DO40: 0 | DP40: 1 | DQ40: 1 | DU40: 1013 | DV40: 1 ШТ. | DW40: 1 ШТ. | DX40: 1 | EE40: 58808182 | EF40: 40 | EG40: Монтаж оборудования | EH40: 0 | EJ40: 2 | EK40: 72 | EL40: ТСН-2001.4-11. Приборы и средства автоматизации и вычислительной техники | EM40: ТСН-2001.4-11-1 | EO40: Поправка: Гл.12.Прил.8.п.8. 5_12.00.01.11.003 | EQ40: 0 | ER40: 43.29 | ES40: 35.58 | ET40: 1.76 | EU40: 0.37 | EV40: 5.95 | EW40: 0.52 | EX40: 0 | EY40: 0 | FQ40: 0 | FR40: 0 | FS40: 0 | FX40: 90 | FY40: 46 | GD40: 1 | GF40: -1951604615 | GG40: 2 | GH40: 1 | GI40: 2 | GJ40: 0 | GK40: 0 | GL40: =ROUND(IF(AND(BH40=3,BI40=3,FS40<>0),P40,0),2) -> 0 | GM40: =ROUND(O40+X40+Y40,2)+GX40 -> 1467.69 | GN40: =IF(OR(BI40=0,BI40=1),GM40-GX40,0) -> 0 | GO40: =IF(BI40=2,GM40-GX40,0) -> 1467.69 | GP40: =IF(BI40=4,GM40-GX40,0) -> 0 | GR40: 0 | GS40: 3 | GT40: 0 | GV40: =ROUND((GT40),6) -> 0 | GW40: 1 | GX40: =ROUND(HC40*I40,2) -> 0 | HA40: 0 | HB40: 0 | HC40: =GV40*GW40 -> 0 | HS40: 0 | IK40: 0
