Workbook

Sheet 02-01-10
A1: =Source!B1 -> Smeta.RU (495) 974-1589
J2: Форма № 4б
A3: Капитальный ремонт здания Государственного бюджетного общеобразовательного учреждения города Москвы "Школа №236" по адресу: г. Москва, улица Клязьминская, дом 7, корпус 4. | AP3: Капитальный ремонт здания Государственного бюджетного общеобразовательного учреждения города Москвы "Школа №236" по адресу: г. Москва, улица Клязьминская, дом 7, корпус 4. 02-01-10 РТС
A4: (наименование стройки и/или объекта)
A6: =CONCATENATE( "ЛОКАЛЬНАЯ СМЕТА № ",IF(Source!F20<>"Новая локальная смета", Source!F20, "")) -> ЛОКАЛЬНАЯ СМЕТА № 02-01-10
A8: =IF(Source!G20<>"Новая локальная смета", Source!G20, "") -> Радиотрансляционная сеть
A9: (наименование работ и затрат)
A11: =CONCATENATE( "Основание: чертежи № ", Source!J20) -> Основание: чертежи № 2024-00272-01-0-ИОС5.3
I13: В базисном уровне цен | J13: В текущем уровне цен
E14: Сметная стоимость | I14: =I15+I16+I17+I18 -> 195.07 | J14: =J15+J16+J17+J18 -> 1717.49 | K14: тыс.руб.
E15: Строительные работы | I15: =ROUND((Source!F238)/1000, 2) -> 0 | J15: =ROUND((Source!P238)/1000, 2) -> 0 | K15: тыс.руб.
E16: Работы по монтажу оборудования | I16: =ROUND((Source!F239)/1000, 2) -> 17.03 | J16: =ROUND((Source!P239)/1000, 2) -> 353.21 | K16: тыс.руб.
E17: Оборудование | I17: =ROUND((Source!F230)/1000, 2) -> 178.04 | J17: =ROUND((Source!P230)/1000, 2) -> 1364.28 | K17: тыс.руб.
E18: Прочие работы и затраты | I18: =ROUND((Source!F240+Source!F241)/1000, 2) -> 0 | J18: =ROUND((Source!P240+Source!P241)/1000, 2) -> 0 | K18: тыс.руб.
E19: Средства на оплату труда | I19: =(Source!F236+ Source!F235)/1000 -> 1.79751 | J19: =((Source!P236 + Source!P235)/1000) -> 98.84508 | K19: тыс.руб.
E20: Затраты труда | I20: =Source!F243 -> 138.52903 | K20: чел.-ч.
E21: Кроме того:
E22: Возврат материалов | I22: =SUM(Y28:Y300)/1000 -> 0 | J22: =SUM(Z28:Z300)/1000 -> 0 | K22: тыс.руб.
A24: Составлен(а) по ТСН-2001 с учетом Дополнения №: 80
A25: № и период сборника коэффициентов (индексов) пересчета: Коэффициенты к ТСН-2001 МГЭ Дополнение 80, строительство №217/80 III квартал 2025 года и Коэффициенты к ТСН-2001.13-2 Дополнение 46 №62/46 III квартал 2025 года | AP25: № и период сборника коэффициентов (индексов) пересчета: Коэффициенты к ТСН-2001 МГЭ Дополнение 80, строительство №217/80 III квартал 2025 года и Коэффициенты к ТСН-2001.13-2 Дополнение 46 №62/46 III квартал 2025 года
A26: № п/п | B26: Шифр расценки и коды ресурсов | C26: Наименование работ и затрат | D26: Ед. изм. | E26: Кол-во единиц | F26: Цена на ед. изм., руб. | G26: Попра- вочные коэффи- циенты | H26: Коэффи- циенты зимних удорожа- ний | I26: Всего в ценах на январь 2000 года, руб. | J26: Коэффи- циенты (индек- сы) пере- счета, нормы НР и СП | K26: ВСЕГО затрат в текущем уровне цен, руб.
A27: 1 | B27: 2 | C27: 3 | D27: 4 | E27: 5 | F27: 6 | G27: 7 | H27: 8 | I27: 9 | J27: 10 | K27: 11
A29: =CONCATENATE("Раздел: ",IF(Source!G24<>"Новый раздел", Source!G24, "")) -> Раздел: Оборудование
A30: 1 | B30: =Source!F28 -> 4.11-17-1 | C30: Монтаж щитов и пультов массой до 50кг | D30: =Source!H28 -> 1 ШТ. | E30: =Source!I28 -> 1 | Q30: =Source!X28 -> 62.37 | R30: =Source!X29 -> 3429.73 | S30: =Source!Y28 -> 31.88 | T30: =Source!Y29 -> 1752.97 | U30: =ROUND((175/100)*ROUND(Source!R28, 2), 2) -> 0.77 | V30: =ROUND((0/100)*ROUND(Source!R29, 2), 2) -> 0 | AC30: 0
C31: ЗП | F31: =Source!AO28 -> 59.79 | G31: =Source!DG28 -> *1,1 | H31: =Source!AV29 -> 1.047 | I31: =Source!S28 -> 68.86 | J31: =IF(Source!BA29<> 0, Source!BA29, 1) -> 54.99 | K31: =Source!S29 -> 3786.61
C32: ЭМ | F32: =Source!AM28 -> 4.27 | G32: =Source!DE28 -> *1,1 | H32: =Source!AV29 -> 1.047 | I32: =Source!Q28 -> 4.92 | J32: =IF(Source!BB29<> 0, Source!BB29, 1) -> 14.09 | K32: =Source!Q29 -> 69.32
C33: в т.ч. ЗПМ | F33: =Source!AN28 -> 0.38 | G33: =Source!DF28 -> *1,1 | H33: =Source!AV29 -> 1.047 | I33: =Source!R28 -> 0.44 | J33: =IF(Source!BS29<> 0, Source!BS29, 1) -> 54.99 | K33: =Source!R29 -> 24.2
C34: МР | F34: =Source!AL28 -> 89.36 | G34: =Source!DD28 | H34: =Source!AW29 -> 1 | I34: =Source!P28 -> 89.36 | J34: =IF(Source!BC29<> 0, Source!BC29, 1) -> 5.08 | K34: =Source!P29 -> 453.95
A35: 1,1 | B35: =Source!F30 -> КА-1 | C35: ОБОРУДОВАНИЕ:_x000D_ Устройство подачи программ вещания УППВ 1918 М1 исп. У (исп. 2022) 45 303,63 = [399 507,72 / 1,2 / 7,66] + 3% Трансп + 1,2% Заг.скл | D35: =Source!H30 -> шт. | E35: =Source!I30 -> 1 | F35: =Source!AK30 -> 45303.63 | H35: =Source!AW31 -> 1 | I35: =Source!O30 -> 45303.63 | J35: =IF(Source!BC31<> 0, Source!BC31, 1) -> 7.66 | K35: =Source!O31 -> 347025.81 | Q35: =Source!X30 -> 0 | R35: =Source!X31 -> 0 | S35: =Source!Y30 -> 0 | T35: =Source!Y31 -> 0 | U35: =ROUND((175/100)*ROUND(Source!R30, 2), 2) -> 0 | V35: =ROUND((0/100)*ROUND(Source!R31, 2), 2) -> 0 | AC35: 5
C36: НР от ФОТ | D36: % | E36: =Source!BZ29 -> 90 | I36: =SUM(Q30:Q35) -> 62.37 | J36: =Source!AT29 -> 90 | K36: =SUM(R30:R35) -> 3429.73
C37: СП от ФОТ | D37: % | E37: =Source!CA29 -> 46 | I37: =SUM(S30:S36) -> 31.88 | J37: =Source!AU29 -> 46 | K37: =SUM(T30:T36) -> 1752.97
C38: ЗТР | D38: чел-ч | E38: =Source!AQ28 -> 5.15 | G38: =Source!DI28 -> *1,1 | H38: =Source!AV29 -> 1.047 | I38: =Source!U28 -> 5.931255
C39: ВСЕГО работ по позиции: | H39: =I31+I32+I34+I36+I37+SUM(I35:I35)-SUMIF(AC35:AC35, 5, I35:I35)-SUMIF(AC35:AC35, 6, I35:I35) -> 257.39 | J39: =K31+K32+K34+K36+K37+SUM(K35:K35)-SUMIF(AC35:AC35, 5, K35:K35)-SUMIF(AC35:AC35, 6, K35:K35) -> 9492.58
C40: ВСЕГО оборудование по позиции: | H40: =SUMIF(AC35:AC35, 5, I35:I35)+SUMIF(AC35:AC35, 6, I35:I35) -> 45303.63 | J40: =SUMIF(AC35:AC35, 5, K35:K35)+SUMIF(AC35:AC35, 6, K35:K35) -> 347025.81
C41: ВСЕГО по позиции: | H41: =I31+I32+I34+I36+I37+SUM(I35:I35) -> 45561.02 | J41: =K31+K32+K34+K36+K37+SUM(K35:K35) -> 356518.39 | O41: =I31+I32+I34+I36+I37+SUM(I35:I35) -> 45561.02 | P41: =K31+K32+K34+K36+K37+SUM(K35:K35) -> 356518.39
A43: 2 | B43: =Source!F32 -> 4.11-12-1 | C43: Установка съемных и выдвижных блоков (модулей, ячеек, ТЭЗ) массой до 5 кг | D43: =Source!H32 -> 1 ШТ. | E43: =Source!I32 -> 1 | Q43: =Source!X32 -> 12.16 | R43: =Source!X33 -> 668.63 | S43: =Source!Y32 -> 6.21 | T43: =Source!Y33 -> 341.74 | U43: =ROUND((175/100)*ROUND(Source!R32, 2), 2) -> 0.16 | V43: =ROUND((0/100)*ROUND(Source!R33, 2), 2) -> 0 | AC43: 0
C44: ЗП | F44: =Source!AO32 -> 11.65 | G44: =Source!DG32 -> *1,1 | H44: =Source!AV33 -> 1.047 | I44: =Source!S32 -> 13.42 | J44: =IF(Source!BA33<> 0, Source!BA33, 1) -> 54.99 | K44: =Source!S33 -> 737.97
C45: ЭМ | F45: =Source!AM32 -> 0.5 | G45: =Source!DE32 -> *1,1 | H45: =Source!AV33 -> 1.047 | I45: =Source!Q32 -> 0.58 | J45: =IF(Source!BB33<> 0, Source!BB33, 1) -> 16.26 | K45: =Source!Q33 -> 9.43
C46: в т.ч. ЗПМ | F46: =Source!AN32 -> 0.08 | G46: =Source!DF32 -> *1,1 | H46: =Source!AV33 -> 1.047 | I46: =Source!R32 -> 0.09 | J46: =IF(Source!BS33<> 0, Source!BS33, 1) -> 54.99 | K46: =Source!R33 -> 4.95
A47: 2,1 | B47: =Source!F34 -> КА-2 | C47: ОБОРУДОВАНИЕ:_x000D_ Модуль для приема интернет вещания радиостанции «Радио Москвы» 3 841,94 = [33 880 / 1,2 / 7,66] + 3% Трансп + 1,2% Заг.скл | D47: =Source!H34 -> шт. | E47: =Source!I34 -> 1 | F47: =Source!AK34 -> 3841.94 | H47: =Source!AW35 -> 1 | I47: =Source!O34 -> 3841.94 | J47: =IF(Source!BC35<> 0, Source!BC35, 1) -> 7.66 | K47: =Source!O35 -> 29429.26 | Q47: =Source!X34 -> 0 | R47: =Source!X35 -> 0 | S47: =Source!Y34 -> 0 | T47: =Source!Y35 -> 0 | U47: =ROUND((175/100)*ROUND(Source!R34, 2), 2) -> 0 | V47: =ROUND((0/100)*ROUND(Source!R35, 2), 2) -> 0 | AC47: 5
...

Sheet Ведомость объемов работ
A1: =Source!B1 -> Smeta.RU (495) 974-1589
B4: =CONCATENATE("Ведомость объемов работ ", IF(Source!AN15<>"", Source!AN15," ")) -> Ведомость объемов работ
B5: =CONCATENATE(Source!F12, " ", Source!G12) -> 02-01-10 РТС
A8: № п/п | B8: № в ЛСР | C8: Наименование работ и затрат | D8: Единица измерения | E8: Количество | F8: Ссылка на чертежи, спецификации | G8: Формула расчета, расчет объемов работ и расхода материалов | H8: Примечание
A9: 1 | B9: 2 | C9: 3 | D9: 4 | E9: 5 | F9: 6 | G9: 7 | H9: 8
A10: =CONCATENATE("Локальная смета: ", Source!G20) -> Локальная смета: Радиотрансляционная сеть
A11: =CONCATENATE("Раздел: ", Source!G24) -> Раздел: Оборудование
A12: 1 | B12: =Source!E28 -> 1 | C12: =Source!G28 -> Монтаж щитов и пультов массой до 50кг | D12: 1 ШТ. | E12: =Source!I28 -> 1 | F12: =Source!U24 | G12: =Source!I28 -> 1
A13: 2 | B13: =Source!E32 -> 2 | C13: =Source!G32 -> Установка съемных и выдвижных блоков (модулей, ячеек, ТЭЗ) массой до 5 кг | D13: 1 ШТ. | E13: =Source!I32 -> 1 | F13: =Source!U24 | G13: =Source!I32 -> 1
A14: 3 | B14: =Source!E36 -> 3 | C14: =Source!G36 -> Монтаж щитов и пультов массой до 50кг | D14: 1 ШТ. | E14: =Source!I36 -> 1 | F14: =Source!U24 | G14: =Source!I36 -> 1
A15: 4 | B15: =Source!E40 -> 4 | C15: =Source!G40 -> Монтаж щита распределительного настенного типа | D15: 1 ШТ. | E15: =Source!I40 -> 1 | F15: =Source!U24 | G15: =Source!I40 -> 1
A16: 5 | B16: =Source!E44 -> 5 | C16: =Source!G44 -> Монтаж розетки штепсельной скрытого типа | D16: 100 шт. | E16: =Source!I44 -> 0.07 | F16: =Source!U24 | G16: ="=7/"&"100" -> =7/100
A17: =CONCATENATE("Раздел: ", Source!G81) -> Раздел: Кабельные изделия
A18: 6 | B18: =Source!E85 -> 6 | C18: =Source!G85 -> Трубы гофрированные поливинилхлоридные наружным диаметром 20 мм открыто по стенам и потолкам с установкой соединительных коробок | D18: 100 м | E18: =Source!I85 -> 2 | F18: =Source!U81 | G18: ="=200/"&"100" -> =200/100
A19: 7 | B19: =Source!E91 -> 7 | C19: =Source!G91 -> Прокладка металлического рукава, наружный диаметр до 48 мм | D19: 100 м | E19: =Source!I91 -> 0.3 | F19: =Source!U81 | G19: ="=30/"&"100" -> =30/100
A20: 8 | B20: =Source!E95 -> 8 | C20: =Source!G95 -> Затягивание провода в проложенные трубы и металлические рукава, первого одножильного или многожильного в общей оплетке, суммарное сечение до 6 мм2 | D20: 100 м | E20: =Source!I95 -> 2.3 | F20: =Source!U81 | G20: ="=(200+"&"30)/"&"100" -> =(200+30)/100
A21: 9 | B21: =Source!E97 -> 9 | C21: =Source!G97 -> Добавлять на затягивание провода в проложенные трубы и металлические рукава каждого последующего одножильного или многожильного в общей оплетке, суммарное сечение до 6 мм2 (к нормам и расценкам 4.8-175-1 и 4.8-175-2) | D21: 100 м | E21: =Source!I97 -> 4.2 | F21: =Source!U81 | G21: ="=(150+"&"350+"&"10+"&"40+"&"20+"&"50+"&"20+"&"10-"&"230)/"&"100" -> =(150+350+10+40+20+50+20+10-230)/100
A22: 10 | B22: =Source!E99 -> 10 | C22: =Source!G99 -> Кабель распределительный КПСВВнг(А)-LSLTx 1x2x1,5 | D22: км | E22: =Source!I99 -> 0.153 | F22: =Source!U81 | G22: ="=(150*"&"1,02)/"&"1000" -> =(150*1,02)/1000
A23: 11 | B23: =Source!E101 -> 11 | C23: =Source!G101 -> Кабель абонентский КПСВВнг(А)-LSLTx 1x2x0,5 | D23: км | E23: =Source!I101 -> 0.357 | F23: =Source!U81 | G23: ="=(350*"&"1,02)/"&"1000" -> =(350*1,02)/1000
A24: 12 | B24: =Source!E103 -> 12 | C24: =Source!G103 -> Кабель витая пара FTP кат. 5е ЛОУТОКС КВПЭфнг(С)-LSLTx-5е 4x2x0,52 | D24: км | E24: =Source!I103 -> 0.0102 | F24: =Source!U81 | G24: ="=(10*"&"1,02)/"&"1000" -> =(10*1,02)/1000
A25: 13 | B25: =Source!E105 -> 13 | C25: =Source!G105 -> Кабель коаксиальный Паракс RG-6 РК 75-4,8-318нг(А)-LSLTx | D25: км | E25: =Source!I105 -> 0.0408 | F25: =Source!U81 | G25: ="=(40*"&"1,02)/"&"1000" -> =(40*1,02)/1000
A26: 14 | B26: =Source!E107 -> 14 | C26: =Source!G107 -> Кабель сопряжения с СОУЭ КПСВэВнг(А)-LSLTx 2x2x0,5 | D26: км | E26: =Source!I107 -> 0.0204 | F26: =Source!U81 | G26: ="=(20*"&"1,02)/"&"1000" -> =(20*1,02)/1000
A27: 15 | B27: =Source!E109 -> 15 | C27: =Source!G109 -> Кабель коаксиальный РК50-7-37нг(А)-HF | D27: км | E27: =Source!I109 -> 0.051 | F27: =Source!U81 | G27: ="=(50*"&"1,02)/"&"1000" -> =(50*1,02)/1000
A28: 16 | B28: =Source!E111 -> 16 | C28: =Source!G111 -> Кабель коммутации передачи сигнала 20нг(А)-FRLSLTx 2x2x0,75 | D28: км | E28: =Source!I111 -> 0.0204 | F28: =Source!U81 | G28: ="=(20*"&"1,02)/"&"1000" -> =(20*1,02)/1000
A29: 17 | B29: =Source!E113 -> 17 | C29: =Source!G113 -> Кабель сопряжения оборудования СОЧС с ОСО КПСВЭВнг(А)-LSLTx 2x2x0,75 | D29: км | E29: =Source!I113 -> 0.102 | F29: =Source!U81 | G29: ="=(100*"&"1,02)/"&"1000" -> =(100*1,02)/1000
A30: =CONCATENATE("Раздел: ", Source!G146) -> Раздел: Материалы
A31: 18 | B31: =Source!E150 -> 18 | C31: =Source!G150 -> Установка для трубных проводок коробки оконечной | D31: 100 шт. | E31: =Source!I150 -> 0.02 | F31: =Source!U146 | G31: ="=2/"&"100" -> =2/100
A32: 19 | B32: =Source!E154 -> 19 | C32: =Source!G154 -> Установка для трубных проводок коробки оконечной | D32: 100 шт. | E32: =Source!I154 -> 0.02 | F32: =Source!U146 | G32: ="=2/"&"100" -> =2/100
A33: 20 | B33: =Source!E158 -> 20 | C33: =Source!G158 -> Антенные устройства, монтаж антенны дополнительной для приема ТВ на ранее установленной опоре, с действующими ТВ антеннами | D33: 1 антенна | E33: =Source!I158 -> 1 | F33: =Source!U146 | G33: =Source!I158 -> 1
A34: 21 | B34: =Source!E162 -> 21 | C34: =Source!G162 -> Антенные устройства, монтаж антенны коллективной для приема ТВ на антенной опоре высотой до 6 м без оттяжек на кровле с ранее оборудованными трубостойками | D34: 1 антенна | E34: =Source!I162 -> 1 | F34: =Source!U146 | G34: =Source!I162 -> 1
A35: 22 | B35: =Source!E166 -> 22 | C35: =Source!G166 -> Антенные устройства, монтаж металлоконструкций для телевизионных антенн (Масса антенны в сборе - 5,1 кг) | D35: 1 Т | E35: =Source!I166 -> 0.0051 | F35: =Source!U146 | G35: ="=5,1/"&"1000" -> =5,1/1000
A36: 23 | B36: =Source!E168 -> 23 | C36: =Source!G168 -> Мачта для телевизионной антенны, высота не более 6 м, без защелок-натяжителей и проволоки для оттяжек | D36: шт. | E36: =Source!I168 -> 1 | F36: =Source!U146 | G36: =Source!I168 -> 1
A37: 24 | B37: =Source!E170 -> 24 | C37: =Source!G170 -> Опора модернизированная с грузом 8х20 кг NPMM-60 | D37: ШТ | E37: =Source!I170 -> 1 | F37: =Source!U146 | G37: =Source!I170 -> 1
A38: 25 | B38: =Source!E172 -> 25 | C38: =Source!G172 -> Комплект заземления мачты (трос стальной 8,3мм-10м; на конечник КВТ35-8-9-1шт.; сжим У859М-1шт.) | D38: ШТ | E38: =Source!I172 -> 1 | F38: =Source!U146 | G38: =Source!I172 -> 1
A39: 26 | B39: =Source!E174 -> 26 | C39: =Source!G174 -> Грозозащита для воздушных абонентских линий | D39: 1 комплект | E39: =Source!I174 -> 1 | F39: =Source!U146 | G39: =Source!I174 -> 1
A40: 27 | B40: =Source!E178 -> 27 | C40: =Source!G178 -> Разъем телевизионный F для коаксиального кабеля стандарта RG6 | D40: шт. | E40: =Source!I178 -> 10 | F40: =Source!U146 | G40: =Source!I178 -> 10
A41: 28 | B41: =Source!E180 -> 28 | C41: =Source!G180 -> Коннектор (вилка) телекоммуникационный 8P8C, RJ45, категория 5E | D41: 100 шт. | E41: =Source!I180 -> 0.04 | F41: =Source!U146 | G41: ="=4/"&"100" -> =4/100
A42: 29 | B42: =Source!E182 -> 29 | C42: =Source!G182 -> Разъем телевизионный "папа", прямой, для коаксиального кабеля стандарта RG6 | D42: шт. | E42: =Source!I182 -> 3 | F42: =Source!U146 | G42: =Source!I182 -> 3
A43: 30 | B43: =Source!E184 -> 30 | C43: =Source!G184 -> Разъем телевизионный F для коаксиального кабеля стандарта RG6 | D43: шт. | E43: =Source!I184 -> 1 | F43: =Source!U146 | G43: =Source!I184 -> 1
A44: 31 | B44: =Source!E186 -> 31 | C44: =Source!G186 -> Грозозащита для воздушных абонентских линий | D44: 1 комплект | E44: =Source!I186 -> 1 | F44: =Source!U146 | G44: =Source!I186 -> 1
...

Sheet Source
A1: 0 | B1: Smeta.RU (495) 974-1589 | D1: _PS_ | F1: 0 | G1: 0 | H1: 0 | I1: Smeta.RU | K1: 1 | L1: 74563 | M1: 10 | N1: 12 | O1: 0 | P1: 0 | Q1: 3
A4: 1 | B4: 1 | C4: -1 | G4: Капитальный ремонт здания Государственного бюджетного общеобразовательного учреждения города Москвы "Школа №236" по адресу: г. Москва, улица Клязьминская, дом 7, корпус 4 | EC4: 0
A12: 1 | B12: 290 | C12: 0 | D12: =ROW(A251) -> 251 | E12: 0 | G12: 02-01-10 РТС | I12: 0 | J12: 2024-00272-01-0-ИОС5.3 | K12: 0 | L12: 0 | M12: 4098 | O12: 0 | P12: 0 | Q12: 0 | R12: 0 | S12: 0 | T12: 1 | V12: 0 | AB12: Соколова И.Н. | BB12: 0 | BH12: Сметные нормы списания | BI12: Коды ОКП для ТСН-2001 МГЭ Дополнение 80 | BJ12: 1 | BK12: 1 | BL12: 0 | BM12: 0 | BN12: 1 | BO12: 0 | BP12: 6 | BQ12: 2 | BR12: 1 | BS12: 1 | BT12: 0 | BU12: 0 | BV12: 0 | BW12: 0 | BX12: 0 | BZ12: Типовой расчет для ТСН-2001 МГЭ, Дополнение 80, строительство (1) | CA12: Территориальные сметные нормативы для Москвы ТСН-2001 (МГЭ), дополнение 80 | CB12: Территориальные сметные нормативы для Москвы ТСН-2001 (МГЭ), дополнение 80 | CC12: Территориальные сметные нормативы для Москвы ТСН-2001 (МГЭ), дополнение 80 | CD12: Территориальные сметные нормативы для Москвы ТСН-2001 (МГЭ), дополнение 80 | CE12: Поправки для ТСН-2001 от 28.11.2025 г. доп.79 | CF12: 0 | CG12: 0 | CH12: 8200 | CK12: 80 | CQ12: Территориальные сметные нормативы для Москвы (ТСН-2001) | CR12: ТЕР | CS12: 41660 | CT12: 1 | CU12: 80 | CY12: 0 | EC12: 0
A15: 15 | B15: 1
A18: 52 | B18: =B251 -> 290 | C18: =C251 -> 1 | D18: =D251 -> 12 | E18: =E251 -> 0 | F18: =F251 | G18: =G251 -> 02-01-10 РТС | O18: =O251 -> 192447.83 | P18: =P251 -> 190510.95 | Q18: =Q251 -> 157.38 | R18: =R251 -> 18.01 | S18: =S251 -> 1779.5 | T18: =T251 -> 0 | U18: =U251 -> 138.52903 | V18: =V251 -> 0 | ... GX18: =GX251 -> 0
A20: 3 | B20: 1 | D20: =ROW(A221) -> 221 | F20: 02-01-10 | G20: Радиотрансляционная сеть | I20: 0 | J20: 2024-00272-01-0-ИОС5.3 | K20: -1 | L20: 02-01-10 | S20: 0 | T20: 0 | V20: 2 | BX20: 0 | CF20: 0 | CG20: 0
A22: 52 | B22: =B221 -> 1 | C22: =C221 -> 3 | D22: =D221 -> 20 | E22: =E221 -> 0 | F22: =F221 -> 02-01-10 | G22: =G221 -> Радиотрансляционная сеть | O22: =O221 -> 192447.83 | P22: =P221 -> 190510.95 | Q22: =Q221 -> 157.38 | R22: =R221 -> 18.01 | S22: =S221 -> 1779.5 | T22: =T221 -> 0 | U22: =U221 -> 138.52903 | V22: =V221 -> 0 | ... GX22: =GX221 -> 0
A24: 4 | B24: 1 | D24: =ROW(A51) -> 51 | G24: Оборудование | I24: 0 | K24: -1 | S24: 0 | T24: 0 | V24: 2 | BX24: 0 | CJ24: 0
A26: 52 | B26: =B51 -> 1 | C26: =C51 -> 4 | D26: =D51 -> 24 | E26: =E51 -> 0 | F26: =F51 | G26: =G51 -> Оборудование | O26: =O51 -> 175166.44 | P26: =P51 -> 174472.47 | Q26: =Q51 -> 10.49 | R26: =R51 -> 0.98 | S26: =S51 -> 683.48 | T26: =T51 -> 0 | U26: =U51 -> 52.573723 | V26: =V51 -> 0 | ... GX26: =GX51 -> 0
A28: 17 | B28: 1 | C28: =ROW(SmtRes!A12) -> 12 | D28: =ROW(EtalonRes!A12) -> 12 | E28: 1 | F28: 4.11-17-1 | G28: Монтаж щитов и пультов массой до 50кг | H28: 1 ШТ. | I28: 1 | J28: 0 | K28: 1 | O28: =ROUND(CP28,2) -> 163.14 | P28: =ROUND((ROUND((AC28*AW28*I28),2)*BC28),2) -> 89.36 | Q28: =(ROUND((ROUND((((ET28*1.1))*AV28*I28),2)*BB28),2)+ROUND((ROUND(((AE28-((EU28*1.1)))*AV28*I28),2)*BS28),2)) -> 4.92 | R28: =(ROUND((ROUND((((EU28*1.1))*AV28*I28),2)*BS28),2)+ROUND((ROUND(((AE28-((EU28*1.1)))*AV28*I28),2)*BS28),2)) -> 0.44 | S28: =ROUND((ROUND((AF28*AV28*I28),2)*BA28),2) -> 68.86 | T28: =ROUND(CU28*I28,2) -> 0 | U28: =CV28*I28 -> 5.931255 | V28: =CW28*I28 -> 0 | W28: =ROUND(CX28*I28,2) -> 0 | X28: =(ROUND((((S28+ROUND((ROUND((((EU28*1.1))*AV28*I28),2)*BS28),2))*AT28)/100),2)+ROUND(((ROUND((ROUND(((AE28-((EU28*1.1)))*AV28*I28),2)*BS28),2)*AT28)/100),2)) -> 62.37 | Y28: =(ROUND((((S28+ROUND((ROUND((((EU28*1.1))*AV28*I28),2)*BS28),2))*AU28)/100),2)+ROUND(((ROUND((ROUND(((AE28-((EU28*1.1)))*AV28*I28),2)*BS28),2)*AU28)/100),2)) -> 31.88 | AA28: 60256985 | AB28: =ROUND((AC28+AD28+AF28),6) -> 159.826 | AC28: =ROUND((ES28),6) -> 89.36 | AD28: =ROUND(((((ET28*1.1))-((EU28*1.1)))+AE28),6) -> 4.697 | AE28: =ROUND(((EU28*1.1)),6) -> 0.418 | AF28: =ROUND(((EV28*1.1)),6) -> 65.769 | AG28: =ROUND((AP28),6) -> 0 | AH28: =((EW28*1.1)) -> 5.665 | AI28: =((EX28*1.1)) -> 0 | AJ28: =(AS28) -> 0 | AK28: 153.42 | AL28: 89.36 | AM28: 4.27 | AN28: 0.38 | AO28: 59.79 | AP28: 0 | AQ28: 5.15 | AR28: 0 | AS28: 0 | AT28: 90 | AU28: 46 | AV28: 1.047 | AW28: 1 | AZ28: 1 | BA28: 1 | BB28: 1 | BC28: 1 | BH28: 0 | BI28: 2 | BJ28: ТСН-2001.4 Доп. 80, Сб. 11, т. 17, поз. 1 | BM28: 72 | BN28: 58973116 | BO28: 4.11-17-1 | BP28: 1 | BQ28: 40 | BR28: 0 | BS28: 1 | BT28: 1 | BU28: 1 | BV28: 1 | BW28: 1 | BX28: 1 | BZ28: 90 | CA28: 46 | CE28: 1566 | CF28: 0 | CG28: 0 | CM28: 0 | CN28: Поправка: О.П. п.3.4.30.в Наименование: При применении территориальных сметных нормативов для города Москвы затраты, учитывающие напряженные и стесненные условия производства работ (стесненность, сложность складирования и транспортной логистики и т.п.), исчисляются с применением коэффициентов к затратам труда и заработной плате рабочих, машинистов, времени эксплуатации машин и механизмов, стоимости эксплуатации машин в размере: для объектов, расположенных за пределами Третьего транспортного кольца города Москвы, но в пределах Московской кольцевой автомобильной дороги | CO28: 0 | CP28: =(P28+Q28+S28) -> 163.14 | CQ28: =ROUND((ROUND((AC28*AW28*1),2)*BC28),2) -> 89.36 | CR28: =(ROUND((ROUND((((ET28*1.1))*AV28*1),2)*BB28),2)+ROUND((ROUND(((AE28-((EU28*1.1)))*AV28*1),2)*BS28),2)) -> 4.92 | CS28: =(ROUND((ROUND((((EU28*1.1))*AV28*1),2)*BS28),2)+ROUND((ROUND(((AE28-((EU28*1.1)))*AV28*1),2)*BS28),2)) -> 0.44 | CT28: =ROUND((ROUND((AF28*AV28*1),2)*BA28),2) -> 68.86 | CU28: =AG28 -> 0 | CV28: =(AH28*AV28) -> 5.931255 | CW28: =AI28 -> 0 | CX28: =AJ28 -> 0 | CY28: =(ROUND((((S28+ROUND((ROUND((((EU28*1.1))*AV28*1),2)*BS28),2))*AT28)/100),2)+ROUND(((ROUND((ROUND(((AE28-((EU28*1.1)))*AV28*1),2)*BS28),2)*AT28)/100),2)) -> 62.37 | CZ28: =(ROUND((((S28+ROUND((ROUND((((EU28*1.1))*AV28*1),2)*BS28),2))*AU28)/100),2)+ROUND(((ROUND((ROUND(((AE28-((EU28*1.1)))*AV28*1),2)*BS28),2)*AU28)/100),2)) -> 31.88 | DB28: 1 | DE28: *1,1 | DF28: *1,1 | DG28: *1,1 | DI28: *1,1 | DJ28: *1,1 | DN28: 0 | DO28: 0 | DP28: 1 | DQ28: 1 | DU28: 1013 | DV28: 1 ШТ. | DW28: 1 ШТ. | DX28: 1 | EE28: 60088536 | EF28: 40 | EG28: Монтаж оборудования | EH28: 0 | EJ28: 2 | EK28: 72 | EL28: ТСН-2001.4-11. Приборы и средства автоматизации и вычислительной техники | EM28: ТСН-2001.4-11-1 | EO28: Поправка: О.П. п.3.4.30.в | EQ28: 0 | ER28: 153.42 | ES28: 89.36 | ET28: 4.27 | EU28: 0.38 | EV28: 59.79 | EW28: 5.15 | EX28: 0 | EY28: 0 | FQ28: 0 | FR28: 0 | FS28: 0 | FX28: 90 | FY28: 46 | GD28: 1 | GF28: 1767555919 | GG28: 2 | GH28: 1 | GI28: 2 | GJ28: 0 | GK28: 0 | GL28: =ROUND(IF(AND(BH28=3,BI28=3,FS28<>0),P28,0),2) -> 0 | GM28: =ROUND(O28+X28+Y28,2)+GX28 -> 257.39 | GN28: =IF(OR(BI28=0,BI28=1),GM28-GX28,0) -> 0 | GO28: =IF(BI28=2,GM28-GX28,0) -> 257.39 | GP28: =IF(BI28=4,GM28-GX28,0) -> 0 | GR28: 0 | GS28: 3 | GT28: 0 | GV28: =ROUND((GT28),6) -> 0 | GW28: 1 | GX28: =ROUND(HC28*I28,2) -> 0 | HA28: 0 | HB28: 0 | HC28: =GV28*GW28 -> 0 | HS28: 0 | IK28: 0
A29: 17 | B29: 1 | C29: =ROW(SmtRes!A24) -> 24 | D29: =ROW(EtalonRes!A24) -> 24 | E29: 1 | F29: 4.11-17-1 | G29: Монтаж щитов и пультов массой до 50кг | H29: 1 ШТ. | I29: 1 | J29: 0 | K29: 1 | O29: =ROUND(CP29,2) -> 4309.88 | P29: =ROUND((ROUND((AC29*AW29*I29),2)*BC29),2) -> 453.95 | Q29: =(ROUND((ROUND((((ET29*1.1))*AV29*I29),2)*BB29),2)+ROUND((ROUND(((AE29-((EU29*1.1)))*AV29*I29),2)*BS29),2)) -> 69.32 | R29: =(ROUND((ROUND((((EU29*1.1))*AV29*I29),2)*BS29),2)+ROUND((ROUND(((AE29-((EU29*1.1)))*AV29*I29),2)*BS29),2)) -> 24.2 | S29: =ROUND((ROUND((AF29*AV29*I29),2)*BA29),2) -> 3786.61 | T29: =ROUND(CU29*I29,2) -> 0 | U29: =CV29*I29 -> 5.931255 | V29: =CW29*I29 -> 0 | W29: =ROUND(CX29*I29,2) -> 0 | X29: =(ROUND((((S29+ROUND((ROUND((((EU29*1.1))*AV29*I29),2)*BS29),2))*AT29)/100),2)+ROUND(((ROUND((ROUND(((AE29-((EU29*1.1)))*AV29*I29),2)*BS29),2)*AT29)/100),2)) -> 3429.73 | Y29: =(ROUND((((S29+ROUND((ROUND((((EU29*1.1))*AV29*I29),2)*BS29),2))*AU29)/100),2)+ROUND(((ROUND((ROUND(((AE29-((EU29*1.1)))*AV29*I29),2)*BS29),2)*AU29)/100),2)) -> 1752.97 | AA29: 60256982 | AB29: =ROUND((AC29+AD29+AF29),6) -> 159.826 | AC29: =ROUND((ES29),6) -> 89.36 | AD29: =ROUND(((((ET29*1.1))-((EU29*1.1)))+AE29),6) -> 4.697 | AE29: =ROUND(((EU29*1.1)),6) -> 0.418 | AF29: =ROUND(((EV29*1.1)),6) -> 65.769 | AG29: =ROUND((AP29),6) -> 0 | AH29: =((EW29*1.1)) -> 5.665 | AI29: =((EX29*1.1)) -> 0 | AJ29: =(AS29) -> 0 | AK29: 153.42 | AL29: 89.36 | AM29: 4.27 | AN29: 0.38 | AO29: 59.79 | AP29: 0 | AQ29: 5.15 | AR29: 0 | AS29: 0 | AT29: 90 | AU29: 46 | AV29: 1.047 | AW29: 1 | AZ29: 1 | BA29: 54.99 | BB29: 14.09 | BC29: 5.08 | BH29: 0 | BI29: 2 | BJ29: ТСН-2001.4 Доп. 80, Сб. 11, т. 17, поз. 1 | BM29: 72 | BN29: 58973116 | BO29: 4.11-17-1 | BP29: 1 | BQ29: 40 | BR29: 0 | BS29: 54.99 | BT29: 1 | BU29: 1 | BV29: 1 | BW29: 1 | BX29: 1 | BZ29: 90 | CA29: 46 | CE29: 1566 | CF29: 0 | CG29: 0 | CM29: 0 | CN29: Поправка: О.П. п.3.4.30.в Наименование: При применении территориальных сметных нормативов для города Москвы затраты, учитывающие напряженные и стесненные условия производства работ (стесненность, сложность складирования и транспортной логистики и т.п.), исчисляются с применением коэффициентов к затратам труда и заработной плате рабочих, машинистов, времени эксплуатации машин и механизмов, стоимости эксплуатации машин в размере: для объектов, расположенных за пределами Третьего транспортного кольца города Москвы, но в пределах Московской кольцевой автомобильной дороги | CO29: 0 | CP29: =(P29+Q29+S29) -> 4309.88 | CQ29: =ROUND((ROUND((AC29*AW29*1),2)*BC29),2) -> 453.95 | CR29: =(ROUND((ROUND((((ET29*1.1))*AV29*1),2)*BB29),2)+ROUND((ROUND(((AE29-((EU29*1.1)))*AV29*1),2)*BS29),2)) -> 69.32 | CS29: =(ROUND((ROUND((((EU29*1.1))*AV29*1),2)*BS29),2)+ROUND((ROUND(((AE29-((EU29*1.1)))*AV29*1),2)*BS29),2)) -> 24.2 | CT29: =ROUND((ROUND((AF29*AV29*1),2)*BA29),2) -> 3786.61 | CU29: =AG29 -> 0 | CV29: =(AH29*AV29) -> 5.931255 | CW29: =AI29 -> 0 | CX29: =AJ29 -> 0 | CY29: =(ROUND((((S29+ROUND((ROUND((((EU29*1.1))*AV29*1),2)*BS29),2))*AT29)/100),2)+ROUND(((ROUND((ROUND(((AE29-((EU29*1.1)))*AV29*1),2)*BS29),2)*AT29)/100),2)) -> 3429.73 | CZ29: =(ROUND((((S29+ROUND((ROUND((((EU29*1.1))*AV29*1),2)*BS29),2))*AU29)/100),2)+ROUND(((ROUND((ROUND(((AE29-((EU29*1.1)))*AV29*1),2)*BS29),2)*AU29)/100),2)) -> 1752.97 | DB29: 2 | DE29: *1,1 | DF29: *1,1 | DG29: *1,1 | DI29: *1,1 | DJ29: *1,1 | DN29: 0 | DO29: 0 | DP29: 1 | DQ29: 1 | DU29: 1013 | DV29: 1 ШТ. | DW29: 1 ШТ. | DX29: 1 | EE29: 60088536 | EF29: 40 | EG29: Монтаж оборудования | EH29: 0 | EJ29: 2 | EK29: 72 | EL29: ТСН-2001.4-11. Приборы и средства автоматизации и вычислительной техники | EM29: ТСН-2001.4-11-1 | EO29: Поправка: О.П. п.3.4.30.в | EQ29: 0 | ER29: 153.42 | ES29: 89.36 | ET29: 4.27 | EU29: 0.38 | EV29: 59.79 | EW29: 5.15 | EX29: 0 | EY29: 0 | FQ29: 0 | FR29: 0 | FS29: 0 | FX29: 90 | FY29: 46 | GD29: 1 | GF29: 1767555919 | GG29: 2 | GH29: 1 | GI29: 2 | GJ29: 0 | GK29: 0 | GL29: =ROUND(IF(AND(BH29=3,BI29=3,FS29<>0),P29,0),2) -> 0 | GM29: =ROUND(O29+X29+Y29,2)+GX29 -> 9492.58 | GN29: =IF(OR(BI29=0,BI29=1),GM29-GX29,0) -> 0 | GO29: =IF(BI29=2,GM29-GX29,0) -> 9492.58 | GP29: =IF(BI29=4,GM29-GX29,0) -> 0 | GR29: 0 | GS29: 3 | GT29: 0 | GV29: =ROUND((GT29),6) -> 0 | GW29: 1 | GX29: =ROUND(HC29*I29,2) -> 0 | HA29: 0 | HB29: 0 | HC29: =GV29*GW29 -> 0 | HS29: 0 | IK29: 0
A30: 18 | B30: 1 | C30: 12 | E30: 1,1 | F30: КА-1 | G30: Устройство подачи программ вещания УППВ 1918 М1 исп. У (исп. 2022) | H30: шт. | I30: =I28*J30 -> 1 | J30: 1 | K30: 1 | O30: =ROUND(CP30,2) -> 45303.63 | P30: =ROUND((ROUND((AC30*I30),2)*BC30),2) -> 45303.63 | Q30: =(ROUND((ROUND(((ET30)*AV30*I30),2)*BB30),2)+ROUND((ROUND(((AE30-(EU30))*AV30*I30),2)*BS30),2)) -> 0 | R30: =(ROUND((ROUND(((EU30)*AV30*I30),2)*BS30),2)+ROUND((ROUND(((AE30-(EU30))*AV30*I30),2)*BS30),2)) -> 0 | S30: =ROUND((ROUND((AF30*AV30*I30),2)*BA30),2) -> 0 | T30: =ROUND(CU30*I30,2) -> 0 | U30: =CV30*I30 -> 0 | V30: =CW30*I30 -> 0 | W30: =ROUND(CX30*I30,2) -> 0 | X30: =(ROUND((((S30+ROUND((ROUND(((EU30)*AV30*I30),2)*BS30),2))*AT30)/100),2)+ROUND(((ROUND((ROUND(((AE30-(EU30))*AV30*I30),2)*BS30),2)*AT30)/100),2)) -> 0 | Y30: =(ROUND((((S30+ROUND((ROUND(((EU30)*AV30*I30),2)*BS30),2))*AU30)/100),2)+ROUND(((ROUND((ROUND(((AE30-(EU30))*AV30*I30),2)*BS30),2)*AU30)/100),2)) -> 0 | AA30: 60256985 | AB30: =ROUND((AC30+AD30+AF30),6) -> 45303.63 | AC30: =ROUND((ES30),6) -> 45303.63 | AD30: =ROUND((((ET30)-(EU30))+AE30),6) -> 0 | AE30: =ROUND((EU30),6) -> 0 | AF30: =ROUND((EV30),6) -> 0 | AG30: =ROUND((AP30),6) -> 0 | AH30: =(EW30) -> 0 | AI30: =(EX30) -> 0 | AJ30: =(AS30) -> 0 | AK30: 45303.63 | AL30: 45303.63 | AM30: 0 | AN30: 0 | AO30: 0 | AP30: 0 | AQ30: 0 | AR30: 0 | AS30: 0 | AT30: 0 | AU30: 0 | AV30: 1 | AW30: 1 | AZ30: 1 | BA30: 1 | BB30: 1 | BC30: 1 | BH30: 3 | BI30: 3 | BM30: 746 | BN30: 0 | BP30: 0 | BQ30: 130 | BR30: 0 | BS30: 1 | BT30: 1 | BU30: 1 | BV30: 1 | BW30: 1 | BX30: 1 | BZ30: 90 | CA30: 46 | CE30: 1566 | CF30: 0 | CG30: 0 | CM30: 0 | CO30: 0 | CP30: =(P30+Q30+S30) -> 45303.63 | CQ30: =ROUND((ROUND((AC30*1),2)*BC30),2) -> 45303.63 | CR30: =(ROUND((ROUND(((ET30)*AV30*1),2)*BB30),2)+ROUND((ROUND(((AE30-(EU30))*AV30*1),2)*BS30),2)) -> 0 | CS30: =(ROUND((ROUND(((EU30)*AV30*1),2)*BS30),2)+ROUND((ROUND(((AE30-(EU30))*AV30*1),2)*BS30),2)) -> 0 | CT30: =ROUND((ROUND((AF30*AV30*1),2)*BA30),2) -> 0 | CU30: =AG30 -> 0 | CV30: =(AH30*AV30) -> 0 | CW30: =AI30 -> 0 | CX30: =AJ30 -> 0 | CY30: =(ROUND((((S30+ROUND((ROUND(((EU30)*AV30*1),2)*BS30),2))*AT30)/100),2)+ROUND(((ROUND((ROUND(((AE30-(EU30))*AV30*1),2)*BS30),2)*AT30)/100),2)) -> 0 | CZ30: =(ROUND((((S30+ROUND((ROUND(((EU30)*AV30*1),2)*BS30),2))*AU30)/100),2)+ROUND(((ROUND((ROUND(((AE30-(EU30))*AV30*1),2)*BS30),2)*AU30)/100),2)) -> 0 | DN30: 0 | DO30: 0 | DP30: 1 | DQ30: 1 | DU30: 1010 | DV30: шт. | DW30: шт. | DX30: 1 | EE30: 60088638 | EF30: 130 | EG30: Сметная стоимость оборудования | EH30: 0 | EJ30: 3 | EK30: 746 | EL30: ТСН-2001.13. Сметная стоимость оборудования | EM30: ТСН-2001.13 | EQ30: 0 | ER30: 0 | ES30: 45303.63 | ET30: 0 | EU30: 0 | EV30: 0 | EW30: 0 | EX30: 0 | FQ30: 0 | FR30: =P30 -> 45303.63 | FS30: 0 | FX30: 90 | FY30: 46 | GA30: [399 507,72 / 1,2 / 7,66] + 3% Трансп + 1,2% Заг.скл | GD30: 1 | GF30: -1306002714 | GG30: 2 | GH30: 4 | GI30: -2 | GJ30: 0 | GK30: 0 | GL30: =ROUND(IF(AND(BH30=3,BI30=3,FS30<>0),P30,0),2) -> 0 | GM30: =ROUND(O30+X30+Y30,2)+GX30 -> 45303.63 | GN30: =IF(OR(BI30=0,BI30=1),GM30-GX30,0) -> 0 | GO30: =IF(BI30=2,GM30-GX30,0) -> 0 | GP30: =IF(BI30=4,GM30-GX30,0) -> 0 | GR30: 0 | GS30: 2 | GT30: 0 | GV30: =ROUND((GT30),6) -> 0 | GW30: 1 | GX30: =ROUND(HC30*I30,2) -> 0 | HA30: 0 | HB30: 0 | HC30: =GV30*GW30 -> 0 | HE30: 3 | HF30: 1,2 | HS30: 0 | IK30: 0
A31: 18 | B31: 1 | C31: 24 | E31: 1,1 | F31: КА-1 | G31: Устройство подачи программ вещания УППВ 1918 М1 исп. У (исп. 2022) | H31: шт. | I31: =I29*J31 -> 1 | J31: 1 | K31: 1 | O31: =ROUND(CP31,2) -> 347025.81 | P31: =ROUND((ROUND((AC31*I31),2)*BC31),2) -> 347025.81 | Q31: =(ROUND((ROUND(((ET31)*AV31*I31),2)*BB31),2)+ROUND((ROUND(((AE31-(EU31))*AV31*I31),2)*BS31),2)) -> 0 | R31: =(ROUND((ROUND(((EU31)*AV31*I31),2)*BS31),2)+ROUND((ROUND(((AE31-(EU31))*AV31*I31),2)*BS31),2)) -> 0 | S31: =ROUND((ROUND((AF31*AV31*I31),2)*BA31),2) -> 0 | T31: =ROUND(CU31*I31,2) -> 0 | U31: =CV31*I31 -> 0 | V31: =CW31*I31 -> 0 | W31: =ROUND(CX31*I31,2) -> 0 | X31: =(ROUND((((S31+ROUND((ROUND(((EU31)*AV31*I31),2)*BS31),2))*AT31)/100),2)+ROUND(((ROUND((ROUND(((AE31-(EU31))*AV31*I31),2)*BS31),2)*AT31)/100),2)) -> 0 | Y31: =(ROUND((((S31+ROUND((ROUND(((EU31)*AV31*I31),2)*BS31),2))*AU31)/100),2)+ROUND(((ROUND((ROUND(((AE31-(EU31))*AV31*I31),2)*BS31),2)*AU31)/100),2)) -> 0 | AA31: 60256982 | AB31: =ROUND((AC31+AD31+AF31),6) -> 45303.63 | AC31: =ROUND((ES31),6) -> 45303.63 | AD31: =ROUND((((ET31)-(EU31))+AE31),6) -> 0 | AE31: =ROUND((EU31),6) -> 0 | AF31: =ROUND((EV31),6) -> 0 | AG31: =ROUND((AP31),6) -> 0 | AH31: =(EW31) -> 0 | AI31: =(EX31) -> 0 | AJ31: =(AS31) -> 0 | AK31: 45303.63 | AL31: 45303.63 | AM31: 0 | AN31: 0 | AO31: 0 | AP31: 0 | AQ31: 0 | AR31: 0 | AS31: 0 | AT31: 0 | AU31: 0 | AV31: 1 | AW31: 1 | AZ31: 1 | BA31: 1 | BB31: 1 | BC31: 7.66 | BH31: 3 | BI31: 3 | BM31: 746 | BN31: 0 | BP31: 0 | BQ31: 130 | BR31: 0 | BS31: 1 | BT31: 1 | BU31: 1 | BV31: 1 | BW31: 1 | BX31: 1 | BZ31: 90 | CA31: 46 | CE31: 1566 | CF31: 0 | CG31: 0 | CM31: 0 | CO31: 0 | CP31: =(P31+Q31+S31) -> 347025.81 | CQ31: =ROUND((ROUND((AC31*1),2)*BC31),2) -> 347025.81 | CR31: =(ROUND((ROUND(((ET31)*AV31*1),2)*BB31),2)+ROUND((ROUND(((AE31-(EU31))*AV31*1),2)*BS31),2)) -> 0 | CS31: =(ROUND((ROUND(((EU31)*AV31*1),2)*BS31),2)+ROUND((ROUND(((AE31-(EU31))*AV31*1),2)*BS31),2)) -> 0 | CT31: =ROUND((ROUND((AF31*AV31*1),2)*BA31),2) -> 0 | CU31: =AG31 -> 0 | CV31: =(AH31*AV31) -> 0 | CW31: =AI31 -> 0 | CX31: =AJ31 -> 0 | CY31: =(ROUND((((S31+ROUND((ROUND(((EU31)*AV31*1),2)*BS31),2))*AT31)/100),2)+ROUND(((ROUND((ROUND(((AE31-(EU31))*AV31*1),2)*BS31),2)*AT31)/100),2)) -> 0 | CZ31: =(ROUND((((S31+ROUND((ROUND(((EU31)*AV31*1),2)*BS31),2))*AU31)/100),2)+ROUND(((ROUND((ROUND(((AE31-(EU31))*AV31*1),2)*BS31),2)*AU31)/100),2)) -> 0 | DN31: 0 | DO31: 0 | DP31: 1 | DQ31: 1 | DU31: 1010 | DV31: шт. | DW31: шт. | DX31: 1 | EE31: 60088638 | EF31: 130 | EG31: Сметная стоимость оборудования | EH31: 0 | EJ31: 3 | EK31: 746 | EL31: ТСН-2001.13. Сметная стоимость оборудования | EM31: ТСН-2001.13 | EQ31: 0 | ER31: 0 | ES31: 45303.63 | ET31: 0 | EU31: 0 | EV31: 0 | EW31: 0 | EX31: 0 | EZ31: 5 | FC31: 1 | FD31: 18 | FF31: 399507.72 | FQ31: 0 | FR31: =P31 -> 347025.81 | FS31: 0 | FX31: 90 | FY31: 46 | GA31: [399 507,72 / 1,2 / 7,66] + 3% Трансп + 1,2% Заг.скл | GD31: 1 | GF31: -1306002714 | GG31: 2 | GH31: 3 | GI31: 5 | GJ31: 0 | GK31: 0 | GL31: =ROUND(IF(AND(BH31=3,BI31=3,FS31<>0),P31,0),2) -> 0 | GM31: =ROUND(O31+X31+Y31,2)+GX31 -> 347025.81 | GN31: =IF(OR(BI31=0,BI31=1),GM31-GX31,0) -> 0 | GO31: =IF(BI31=2,GM31-GX31,0) -> 0 | GP31: =IF(BI31=4,GM31-GX31,0) -> 0 | GR31: 1 | GS31: 1 | GT31: 0 | GV31: =ROUND((GT31),6) -> 0 | GW31: 1 | GX31: =ROUND(HC31*I31,2) -> 0 | HA31: 0 | HB31: 0 | HC31: =GV31*GW31 -> 0 | HE31: 3 | HF31: 1,2 | HS31: 0 | IK31: 0
A32: 17 | B32: 1 | C32: =ROW(SmtRes!A27) -> 27 | D32: =ROW(EtalonRes!A27) -> 27 | E32: 2 | F32: 4.11-12-1 | G32: Установка съемных и выдвижных блоков (модулей, ячеек, ТЭЗ) массой до 5 кг | H32: 1 ШТ. | I32: 1 | J32: 0 | K32: 1 | O32: =ROUND(CP32,2) -> 14 | P32: =ROUND((ROUND((AC32*AW32*I32),2)*BC32),2) -> 0 | Q32: =(ROUND((ROUND((((ET32*1.1))*AV32*I32),2)*BB32),2)+ROUND((ROUND(((AE32-((EU32*1.1)))*AV32*I32),2)*BS32),2)) -> 0.58 | R32: =(ROUND((ROUND((((EU32*1.1))*AV32*I32),2)*BS32),2)+ROUND((ROUND(((AE32-((EU32*1.1)))*AV32*I32),2)*BS32),2)) -> 0.09 | S32: =ROUND((ROUND((AF32*AV32*I32),2)*BA32),2) -> 13.42 | T32: =ROUND(CU32*I32,2) -> 0 | U32: =CV32*I32 -> 1.186251 | V32: =CW32*I32 -> 0 | W32: =ROUND(CX32*I32,2) -> 0 | X32: =(ROUND((((S32+ROUND((ROUND((((EU32*1.1))*AV32*I32),2)*BS32),2))*AT32)/100),2)+ROUND(((ROUND((ROUND(((AE32-((EU32*1.1)))*AV32*I32),2)*BS32),2)*AT32)/100),2)) -> 12.16 | Y32: =(ROUND((((S32+ROUND((ROUND((((EU32*1.1))*AV32*I32),2)*BS32),2))*AU32)/100),2)+ROUND(((ROUND((ROUND(((AE32-((EU32*1.1)))*AV32*I32),2)*BS32),2)*AU32)/100),2)) -> 6.21 | AA32: 60256985 | AB32: =ROUND((AC32+AD32+AF32),6) -> 13.365 | AC32: =ROUND((ES32),6) -> 0 | AD32: =ROUND(((((ET32*1.1))-((EU32*1.1)))+AE32),6) -> 0.55 | AE32: =ROUND(((EU32*1.1)),6) -> 0.088 | AF32: =ROUND(((EV32*1.1)),6) -> 12.815 | AG32: =ROUND((AP32),6) -> 0 | AH32: =((EW32*1.1)) -> 1.133 | AI32: =((EX32*1.1)) -> 0 | AJ32: =(AS32) -> 0 | AK32: 12.15 | AL32: 0 | AM32: 0.5 | AN32: 0.08 | AO32: 11.65 | AP32: 0 | AQ32: 1.03 | AR32: 0 | AS32: 0 | AT32: 90 | AU32: 46 | AV32: 1.047 | AW32: 1 | AZ32: 1 | BA32: 1 | BB32: 1 | BC32: 1 | BH32: 0 | BI32: 2 | BJ32: ТСН-2001.4 Доп. 68, Сб. 11, т. 12, поз. 1 | BM32: 72 | BN32: 58973116 | BO32: 4.11-12-1 | BP32: 1 | BQ32: 40 | BR32: 0 | BS32: 1 | BT32: 1 | BU32: 1 | BV32: 1 | BW32: 1 | BX32: 1 | BZ32: 90 | CA32: 46 | CE32: 1566 | CF32: 0 | CG32: 0 | CM32: 0 | CN32: Поправка: О.П. п.3.4.30.в Наименование: При применении территориальных сметных нормативов для города Москвы затраты, учитывающие напряженные и стесненные условия производства работ (стесненность, сложность складирования и транспортной логистики и т.п.), исчисляются с применением коэффициентов к затратам труда и заработной плате рабочих, машинистов, времени эксплуатации машин и механизмов, стоимости эксплуатации машин в размере: для объектов, расположенных за пределами Третьего транспортного кольца города Москвы, но в пределах Московской кольцевой автомобильной дороги | CO32: 0 | CP32: =(P32+Q32+S32) -> 14 | CQ32: =ROUND((ROUND((AC32*AW32*1),2)*BC32),2) -> 0 | CR32: =(ROUND((ROUND((((ET32*1.1))*AV32*1),2)*BB32),2)+ROUND((ROUND(((AE32-((EU32*1.1)))*AV32*1),2)*BS32),2)) -> 0.58 | CS32: =(ROUND((ROUND((((EU32*1.1))*AV32*1),2)*BS32),2)+ROUND((ROUND(((AE32-((EU32*1.1)))*AV32*1),2)*BS32),2)) -> 0.09 | CT32: =ROUND((ROUND((AF32*AV32*1),2)*BA32),2) -> 13.42 | CU32: =AG32 -> 0 | CV32: =(AH32*AV32) -> 1.186251 | CW32: =AI32 -> 0 | CX32: =AJ32 -> 0 | CY32: =(ROUND((((S32+ROUND((ROUND((((EU32*1.1))*AV32*1),2)*BS32),2))*AT32)/100),2)+ROUND(((ROUND((ROUND(((AE32-((EU32*1.1)))*AV32*1),2)*BS32),2)*AT32)/100),2)) -> 12.16 | CZ32: =(ROUND((((S32+ROUND((ROUND((((EU32*1.1))*AV32*1),2)*BS32),2))*AU32)/100),2)+ROUND(((ROUND((ROUND(((AE32-((EU32*1.1)))*AV32*1),2)*BS32),2)*AU32)/100),2)) -> 6.21 | DB32: 3 | DE32: *1,1 | DF32: *1,1 | DG32: *1,1 | DI32: *1,1 | DJ32: *1,1 | DN32: 0 | DO32: 0 | DP32: 1 | DQ32: 1 | DU32: 1013 | DV32: 1 ШТ. | DW32: 1 ШТ. | DX32: 1 | EE32: 60088536 | EF32: 40 | EG32: Монтаж оборудования | EH32: 0 | EJ32: 2 | EK32: 72 | EL32: ТСН-2001.4-11. Приборы и средства автоматизации и вычислительной техники | EM32: ТСН-2001.4-11-1 | EO32: Поправка: О.П. п.3.4.30.в | EQ32: 0 | ER32: 12.15 | ES32: 0 | ET32: 0.5 | EU32: 0.08 | EV32: 11.65 | EW32: 1.03 | EX32: 0 | EY32: 0 | FQ32: 0 | FR32: 0 | FS32: 0 | FX32: 90 | FY32: 46 | GD32: 1 | GF32: 1708693888 | GG32: 2 | GH32: 1 | GI32: 2 | GJ32: 0 | GK32: 0 | GL32: =ROUND(IF(AND(BH32=3,BI32=3,FS32<>0),P32,0),2) -> 0 | GM32: =ROUND(O32+X32+Y32,2)+GX32 -> 32.37 | GN32: =IF(OR(BI32=0,BI32=1),GM32-GX32,0) -> 0 | GO32: =IF(BI32=2,GM32-GX32,0) -> 32.37 | GP32: =IF(BI32=4,GM32-GX32,0) -> 0 | GR32: 0 | GS32: 3 | GT32: 0 | GV32: =ROUND((GT32),6) -> 0 | GW32: 1 | GX32: =ROUND(HC32*I32,2) -> 0 | HA32: 0 | HB32: 0 | HC32: =GV32*GW32 -> 0 | HS32: 0 | IK32: 0
A33: 17 | B33: 1 | C33: =ROW(SmtRes!A30) -> 30 | D33: =ROW(EtalonRes!A30) -> 30 | E33: 2 | F33: 4.11-12-1 | G33: Установка съемных и выдвижных блоков (модулей, ячеек, ТЭЗ) массой до 5 кг | H33: 1 ШТ. | I33: 1 | J33: 0 | K33: 1 | O33: =ROUND(CP33,2) -> 747.4 | P33: =ROUND((ROUND((AC33*AW33*I33),2)*BC33),2) -> 0 | Q33: =(ROUND((ROUND((((ET33*1.1))*AV33*I33),2)*BB33),2)+ROUND((ROUND(((AE33-((EU33*1.1)))*AV33*I33),2)*BS33),2)) -> 9.43 | R33: =(ROUND((ROUND((((EU33*1.1))*AV33*I33),2)*BS33),2)+ROUND((ROUND(((AE33-((EU33*1.1)))*AV33*I33),2)*BS33),2)) -> 4.95 | S33: =ROUND((ROUND((AF33*AV33*I33),2)*BA33),2) -> 737.97 | T33: =ROUND(CU33*I33,2) -> 0 | U33: =CV33*I33 -> 1.186251 | V33: =CW33*I33 -> 0 | W33: =ROUND(CX33*I33,2) -> 0 | X33: =(ROUND((((S33+ROUND((ROUND((((EU33*1.1))*AV33*I33),2)*BS33),2))*AT33)/100),2)+ROUND(((ROUND((ROUND(((AE33-((EU33*1.1)))*AV33*I33),2)*BS33),2)*AT33)/100),2)) -> 668.63 | Y33: =(ROUND((((S33+ROUND((ROUND((((EU33*1.1))*AV33*I33),2)*BS33),2))*AU33)/100),2)+ROUND(((ROUND((ROUND(((AE33-((EU33*1.1)))*AV33*I33),2)*BS33),2)*AU33)/100),2)) -> 341.74 | AA33: 60256982 | AB33: =ROUND((AC33+AD33+AF33),6) -> 13.365 | AC33: =ROUND((ES33),6) -> 0 | AD33: =ROUND(((((ET33*1.1))-((EU33*1.1)))+AE33),6) -> 0.55 | AE33: =ROUND(((EU33*1.1)),6) -> 0.088 | AF33: =ROUND(((EV33*1.1)),6) -> 12.815 | AG33: =ROUND((AP33),6) -> 0 | AH33: =((EW33*1.1)) -> 1.133 | AI33: =((EX33*1.1)) -> 0 | AJ33: =(AS33) -> 0 | AK33: 12.15 | AL33: 0 | AM33: 0.5 | AN33: 0.08 | AO33: 11.65 | AP33: 0 | AQ33: 1.03 | AR33: 0 | AS33: 0 | AT33: 90 | AU33: 46 | AV33: 1.047 | AW33: 1 | AZ33: 1 | BA33: 54.99 | BB33: 16.26 | BC33: 1 | BH33: 0 | BI33: 2 | BJ33: ТСН-2001.4 Доп. 68, Сб. 11, т. 12, поз. 1 | BM33: 72 | BN33: 58973116 | BO33: 4.11-12-1 | BP33: 1 | BQ33: 40 | BR33: 0 | BS33: 54.99 | BT33: 1 | BU33: 1 | BV33: 1 | BW33: 1 | BX33: 1 | BZ33: 90 | CA33: 46 | CE33: 1566 | CF33: 0 | CG33: 0 | CM33: 0 | CN33: Поправка: О.П. п.3.4.30.в Наименование: При применении территориальных сметных нормативов для города Москвы затраты, учитывающие напряженные и стесненные условия производства работ (стесненность, сложность складирования и транспортной логистики и т.п.), исчисляются с применением коэффициентов к затратам труда и заработной плате рабочих, машинистов, времени эксплуатации машин и механизмов, стоимости эксплуатации машин в размере: для объектов, расположенных за пределами Третьего транспортного кольца города Москвы, но в пределах Московской кольцевой автомобильной дороги | CO33: 0 | CP33: =(P33+Q33+S33) -> 747.4 | CQ33: =ROUND((ROUND((AC33*AW33*1),2)*BC33),2) -> 0 | CR33: =(ROUND((ROUND((((ET33*1.1))*AV33*1),2)*BB33),2)+ROUND((ROUND(((AE33-((EU33*1.1)))*AV33*1),2)*BS33),2)) -> 9.43 | CS33: =(ROUND((ROUND((((EU33*1.1))*AV33*1),2)*BS33),2)+ROUND((ROUND(((AE33-((EU33*1.1)))*AV33*1),2)*BS33),2)) -> 4.95 | CT33: =ROUND((ROUND((AF33*AV33*1),2)*BA33),2) -> 737.97 | CU33: =AG33 -> 0 | CV33: =(AH33*AV33) -> 1.186251 | CW33: =AI33 -> 0 | CX33: =AJ33 -> 0 | CY33: =(ROUND((((S33+ROUND((ROUND((((EU33*1.1))*AV33*1),2)*BS33),2))*AT33)/100),2)+ROUND(((ROUND((ROUND(((AE33-((EU33*1.1)))*AV33*1),2)*BS33),2)*AT33)/100),2)) -> 668.63 | CZ33: =(ROUND((((S33+ROUND((ROUND((((EU33*1.1))*AV33*1),2)*BS33),2))*AU33)/100),2)+ROUND(((ROUND((ROUND(((AE33-((EU33*1.1)))*AV33*1),2)*BS33),2)*AU33)/100),2)) -> 341.74 | DB33: 4 | DE33: *1,1 | DF33: *1,1 | DG33: *1,1 | DI33: *1,1 | DJ33: *1,1 | DN33: 0 | DO33: 0 | DP33: 1 | DQ33: 1 | DU33: 1013 | DV33: 1 ШТ. | DW33: 1 ШТ. | DX33: 1 | EE33: 60088536 | EF33: 40 | EG33: Монтаж оборудования | EH33: 0 | EJ33: 2 | EK33: 72 | EL33: ТСН-2001.4-11. Приборы и средства автоматизации и вычислительной техники | EM33: ТСН-2001.4-11-1 | EO33: Поправка: О.П. п.3.4.30.в | EQ33: 0 | ER33: 12.15 | ES33: 0 | ET33: 0.5 | EU33: 0.08 | EV33: 11.65 | EW33: 1.03 | EX33: 0 | EY33: 0 | FQ33: 0 | FR33: 0 | FS33: 0 | FX33: 90 | FY33: 46 | GD33: 1 | GF33: 1708693888 | GG33: 2 | GH33: 1 | GI33: 2 | GJ33: 0 | GK33: 0 | GL33: =ROUND(IF(AND(BH33=3,BI33=3,FS33<>0),P33,0),2) -> 0 | GM33: =ROUND(O33+X33+Y33,2)+GX33 -> 1757.77 | GN33: =IF(OR(BI33=0,BI33=1),GM33-GX33,0) -> 0 | GO33: =IF(BI33=2,GM33-GX33,0) -> 1757.77 | GP33: =IF(BI33=4,GM33-GX33,0) -> 0 | GR33: 0 | GS33: 3 | GT33: 0 | GV33: =ROUND((GT33),6) -> 0 | GW33: 1 | GX33: =ROUND(HC33*I33,2) -> 0 | HA33: 0 | HB33: 0 | HC33: =GV33*GW33 -> 0 | HS33: 0 | IK33: 0
A34: 18 | B34: 1 | C34: 27 | E34: 2,1 | F34: КА-2 | G34: Модуль для приема интернет вещания радиостанции «Радио Москвы» | H34: шт. | I34: =I32*J34 -> 1 | J34: 1 | K34: 1 | O34: =ROUND(CP34,2) -> 3841.94 | P34: =ROUND((ROUND((AC34*I34),2)*BC34),2) -> 3841.94 | Q34: =(ROUND((ROUND(((ET34)*AV34*I34),2)*BB34),2)+ROUND((ROUND(((AE34-(EU34))*AV34*I34),2)*BS34),2)) -> 0 | R34: =(ROUND((ROUND(((EU34)*AV34*I34),2)*BS34),2)+ROUND((ROUND(((AE34-(EU34))*AV34*I34),2)*BS34),2)) -> 0 | S34: =ROUND((ROUND((AF34*AV34*I34),2)*BA34),2) -> 0 | T34: =ROUND(CU34*I34,2) -> 0 | U34: =CV34*I34 -> 0 | V34: =CW34*I34 -> 0 | W34: =ROUND(CX34*I34,2) -> 0 | X34: =(ROUND((((S34+ROUND((ROUND(((EU34)*AV34*I34),2)*BS34),2))*AT34)/100),2)+ROUND(((ROUND((ROUND(((AE34-(EU34))*AV34*I34),2)*BS34),2)*AT34)/100),2)) -> 0 | Y34: =(ROUND((((S34+ROUND((ROUND(((EU34)*AV34*I34),2)*BS34),2))*AU34)/100),2)+ROUND(((ROUND((ROUND(((AE34-(EU34))*AV34*I34),2)*BS34),2)*AU34)/100),2)) -> 0 | AA34: 60256985 | AB34: =ROUND((AC34+AD34+AF34),6) -> 3841.94 | AC34: =ROUND((ES34),6) -> 3841.94 | AD34: =ROUND((((ET34)-(EU34))+AE34),6) -> 0 | AE34: =ROUND((EU34),6) -> 0 | AF34: =ROUND((EV34),6) -> 0 | AG34: =ROUND((AP34),6) -> 0 | AH34: =(EW34) -> 0 | AI34: =(EX34) -> 0 | AJ34: =(AS34) -> 0 | AK34: 3841.94 | AL34: 3841.94 | AM34: 0 | AN34: 0 | AO34: 0 | AP34: 0 | AQ34: 0 | AR34: 0 | AS34: 0 | AT34: 0 | AU34: 0 | AV34: 1 | AW34: 1 | AZ34: 1 | BA34: 1 | BB34: 1 | BC34: 1 | BH34: 3 | BI34: 3 | BM34: 746 | BN34: 0 | BP34: 0 | BQ34: 130 | BR34: 0 | BS34: 1 | BT34: 1 | BU34: 1 | BV34: 1 | BW34: 1 | BX34: 1 | BZ34: 90 | CA34: 46 | CE34: 1566 | CF34: 0 | CG34: 0 | CM34: 0 | CO34: 0 | CP34: =(P34+Q34+S34) -> 3841.94 | CQ34: =ROUND((ROUND((AC34*1),2)*BC34),2) -> 3841.94 | CR34: =(ROUND((ROUND(((ET34)*AV34*1),2)*BB34),2)+ROUND((ROUND(((AE34-(EU34))*AV34*1),2)*BS34),2)) -> 0 | CS34: =(ROUND((ROUND(((EU34)*AV34*1),2)*BS34),2)+ROUND((ROUND(((AE34-(EU34))*AV34*1),2)*BS34),2)) -> 0 | CT34: =ROUND((ROUND((AF34*AV34*1),2)*BA34),2) -> 0 | CU34: =AG34 -> 0 | CV34: =(AH34*AV34) -> 0 | CW34: =AI34 -> 0 | CX34: =AJ34 -> 0 | CY34: =(ROUND((((S34+ROUND((ROUND(((EU34)*AV34*1),2)*BS34),2))*AT34)/100),2)+ROUND(((ROUND((ROUND(((AE34-(EU34))*AV34*1),2)*BS34),2)*AT34)/100),2)) -> 0 | CZ34: =(ROUND((((S34+ROUND((ROUND(((EU34)*AV34*1),2)*BS34),2))*AU34)/100),2)+ROUND(((ROUND((ROUND(((AE34-(EU34))*AV34*1),2)*BS34),2)*AU34)/100),2)) -> 0 | DN34: 0 | DO34: 0 | DP34: 1 | DQ34: 1 | DU34: 1010 | DV34: шт. | DW34: шт. | DX34: 1 | EE34: 60088638 | EF34: 130 | EG34: Сметная стоимость оборудования | EH34: 0 | EJ34: 3 | EK34: 746 | EL34: ТСН-2001.13. Сметная стоимость оборудования | EM34: ТСН-2001.13 | EQ34: 0 | ER34: 0 | ES34: 3841.94 | ET34: 0 | EU34: 0 | EV34: 0 | EW34: 0 | EX34: 0 | FQ34: 0 | FR34: =P34 -> 3841.94 | FS34: 0 | FX34: 90 | FY34: 46 | GA34: [33 880 / 1,2 / 7,66] + 3% Трансп + 1,2% Заг.скл | GD34: 1 | GF34: -1229013042 | GG34: 2 | GH34: 4 | GI34: -2 | GJ34: 0 | GK34: 0 | GL34: =ROUND(IF(AND(BH34=3,BI34=3,FS34<>0),P34,0),2) -> 0 | GM34: =ROUND(O34+X34+Y34,2)+GX34 -> 3841.94 | GN34: =IF(OR(BI34=0,BI34=1),GM34-GX34,0) -> 0 | GO34: =IF(BI34=2,GM34-GX34,0) -> 0 | GP34: =IF(BI34=4,GM34-GX34,0) -> 0 | GR34: 0 | GS34: 2 | GT34: 0 | GV34: =ROUND((GT34),6) -> 0 | GW34: 1 | GX34: =ROUND(HC34*I34,2) -> 0 | HA34: 0 | HB34: 0 | HC34: =GV34*GW34 -> 0 | HE34: 3 | HF34: 1,2 | HS34: 0 | IK34: 0
A35: 18 | B35: 1 | C35: 30 | E35: 2,1 | F35: КА-2 | G35: Модуль для приема интернет вещания радиостанции «Радио Москвы» | H35: шт. | I35: =I33*J35 -> 1 | J35: 1 | K35: 1 | O35: =ROUND(CP35,2) -> 29429.26 | P35: =ROUND((ROUND((AC35*I35),2)*BC35),2) -> 29429.26 | Q35: =(ROUND((ROUND(((ET35)*AV35*I35),2)*BB35),2)+ROUND((ROUND(((AE35-(EU35))*AV35*I35),2)*BS35),2)) -> 0 | R35: =(ROUND((ROUND(((EU35)*AV35*I35),2)*BS35),2)+ROUND((ROUND(((AE35-(EU35))*AV35*I35),2)*BS35),2)) -> 0 | S35: =ROUND((ROUND((AF35*AV35*I35),2)*BA35),2) -> 0 | T35: =ROUND(CU35*I35,2) -> 0 | U35: =CV35*I35 -> 0 | V35: =CW35*I35 -> 0 | W35: =ROUND(CX35*I35,2) -> 0 | X35: =(ROUND((((S35+ROUND((ROUND(((EU35)*AV35*I35),2)*BS35),2))*AT35)/100),2)+ROUND(((ROUND((ROUND(((AE35-(EU35))*AV35*I35),2)*BS35),2)*AT35)/100),2)) -> 0 | Y35: =(ROUND((((S35+ROUND((ROUND(((EU35)*AV35*I35),2)*BS35),2))*AU35)/100),2)+ROUND(((ROUND((ROUND(((AE35-(EU35))*AV35*I35),2)*BS35),2)*AU35)/100),2)) -> 0 | AA35: 60256982 | AB35: =ROUND((AC35+AD35+AF35),6) -> 3841.94 | AC35: =ROUND((ES35),6) -> 3841.94 | AD35: =ROUND((((ET35)-(EU35))+AE35),6) -> 0 | AE35: =ROUND((EU35),6) -> 0 | AF35: =ROUND((EV35),6) -> 0 | AG35: =ROUND((AP35),6) -> 0 | AH35: =(EW35) -> 0 | AI35: =(EX35) -> 0 | AJ35: =(AS35) -> 0 | AK35: 3841.94 | AL35: 3841.94 | AM35: 0 | AN35: 0 | AO35: 0 | AP35: 0 | AQ35: 0 | AR35: 0 | AS35: 0 | AT35: 0 | AU35: 0 | AV35: 1 | AW35: 1 | AZ35: 1 | BA35: 1 | BB35: 1 | BC35: 7.66 | BH35: 3 | BI35: 3 | BM35: 746 | BN35: 0 | BP35: 0 | BQ35: 130 | BR35: 0 | BS35: 1 | BT35: 1 | BU35: 1 | BV35: 1 | BW35: 1 | BX35: 1 | BZ35: 90 | CA35: 46 | CE35: 1566 | CF35: 0 | CG35: 0 | CM35: 0 | CO35: 0 | CP35: =(P35+Q35+S35) -> 29429.26 | CQ35: =ROUND((ROUND((AC35*1),2)*BC35),2) -> 29429.26 | CR35: =(ROUND((ROUND(((ET35)*AV35*1),2)*BB35),2)+ROUND((ROUND(((AE35-(EU35))*AV35*1),2)*BS35),2)) -> 0 | CS35: =(ROUND((ROUND(((EU35)*AV35*1),2)*BS35),2)+ROUND((ROUND(((AE35-(EU35))*AV35*1),2)*BS35),2)) -> 0 | CT35: =ROUND((ROUND((AF35*AV35*1),2)*BA35),2) -> 0 | CU35: =AG35 -> 0 | CV35: =(AH35*AV35) -> 0 | CW35: =AI35 -> 0 | CX35: =AJ35 -> 0 | CY35: =(ROUND((((S35+ROUND((ROUND(((EU35)*AV35*1),2)*BS35),2))*AT35)/100),2)+ROUND(((ROUND((ROUND(((AE35-(EU35))*AV35*1),2)*BS35),2)*AT35)/100),2)) -> 0 | CZ35: =(ROUND((((S35+ROUND((ROUND(((EU35)*AV35*1),2)*BS35),2))*AU35)/100),2)+ROUND(((ROUND((ROUND(((AE35-(EU35))*AV35*1),2)*BS35),2)*AU35)/100),2)) -> 0 | DN35: 0 | DO35: 0 | DP35: 1 | DQ35: 1 | DU35: 1010 | DV35: шт. | DW35: шт. | DX35: 1 | EE35: 60088638 | EF35: 130 | EG35: Сметная стоимость оборудования | EH35: 0 | EJ35: 3 | EK35: 746 | EL35: ТСН-2001.13. Сметная стоимость оборудования | EM35: ТСН-2001.13 | EQ35: 0 | ER35: 0 | ES35: 3841.94 | ET35: 0 | EU35: 0 | EV35: 0 | EW35: 0 | EX35: 0 | EZ35: 5 | FC35: 1 | FD35: 18 | FF35: 33880 | FQ35: 0 | FR35: =P35 -> 29429.26 | FS35: 0 | FX35: 90 | FY35: 46 | GA35: [33 880 / 1,2 / 7,66] + 3% Трансп + 1,2% Заг.скл | GD35: 1 | GF35: -1229013042 | GG35: 2 | GH35: 3 | GI35: 5 | GJ35: 0 | GK35: 0 | GL35: =ROUND(IF(AND(BH35=3,BI35=3,FS35<>0),P35,0),2) -> 0 | GM35: =ROUND(O35+X35+Y35,2)+GX35 -> 29429.26 | GN35: =IF(OR(BI35=0,BI35=1),GM35-GX35,0) -> 0 | GO35: =IF(BI35=2,GM35-GX35,0) -> 0 | GP35: =IF(BI35=4,GM35-GX35,0) -> 0 | GR35: 1 | GS35: 1 | GT35: 0 | GV35: =ROUND((GT35),6) -> 0 | GW35: 1 | GX35: =ROUND(HC35*I35,2) -> 0 | HA35: 0 | HB35: 0 | HC35: =GV35*GW35 -> 0 | HE35: 3 | HF35: 1,2 | HS35: 0 | IK35: 0
A36: 17 | B36: 1 | C36: =ROW(SmtRes!A42) -> 42 | D36: =ROW(EtalonRes!A42) -> 42 | E36: 3 | F36: 4.11-17-1 | G36: Монтаж щитов и пультов массой до 50кг | H36: 1 ШТ. | I36: 1 | J36: 0 | K36: 1 | O36: =ROUND(CP36,2) -> 163.14 | P36: =ROUND((ROUND((AC36*AW36*I36),2)*BC36),2) -> 89.36 | Q36: =(ROUND((ROUND((((ET36*1.1))*AV36*I36),2)*BB36),2)+ROUND((ROUND(((AE36-((EU36*1.1)))*AV36*I36),2)*BS36),2)) -> 4.92 | R36: =(ROUND((ROUND((((EU36*1.1))*AV36*I36),2)*BS36),2)+ROUND((ROUND(((AE36-((EU36*1.1)))*AV36*I36),2)*BS36),2)) -> 0.44 | S36: =ROUND((ROUND((AF36*AV36*I36),2)*BA36),2) -> 68.86 | T36: =ROUND(CU36*I36,2) -> 0 | U36: =CV36*I36 -> 5.931255 | V36: =CW36*I36 -> 0 | W36: =ROUND(CX36*I36,2) -> 0 | X36: =(ROUND((((S36+ROUND((ROUND((((EU36*1.1))*AV36*I36),2)*BS36),2))*AT36)/100),2)+ROUND(((ROUND((ROUND(((AE36-((EU36*1.1)))*AV36*I36),2)*BS36),2)*AT36)/100),2)) -> 62.37 | Y36: =(ROUND((((S36+ROUND((ROUND((((EU36*1.1))*AV36*I36),2)*BS36),2))*AU36)/100),2)+ROUND(((ROUND((ROUND(((AE36-((EU36*1.1)))*AV36*I36),2)*BS36),2)*AU36)/100),2)) -> 31.88 | AA36: 60256985 | AB36: =ROUND((AC36+AD36+AF36),6) -> 159.826 | AC36: =ROUND((ES36),6) -> 89.36 | AD36: =ROUND(((((ET36*1.1))-((EU36*1.1)))+AE36),6) -> 4.697 | AE36: =ROUND(((EU36*1.1)),6) -> 0.418 | AF36: =ROUND(((EV36*1.1)),6) -> 65.769 | AG36: =ROUND((AP36),6) -> 0 | AH36: =((EW36*1.1)) -> 5.665 | AI36: =((EX36*1.1)) -> 0 | AJ36: =(AS36) -> 0 | AK36: 153.42 | AL36: 89.36 | AM36: 4.27 | AN36: 0.38 | AO36: 59.79 | AP36: 0 | AQ36: 5.15 | AR36: 0 | AS36: 0 | AT36: 90 | AU36: 46 | AV36: 1.047 | AW36: 1 | AZ36: 1 | BA36: 1 | BB36: 1 | BC36: 1 | BH36: 0 | BI36: 2 | BJ36: ТСН-2001.4 Доп. 80, Сб. 11, т. 17, поз. 1 | BM36: 72 | BN36: 58973116 | BO36: 4.11-17-1 | BP36: 1 | BQ36: 40 | BR36: 0 | BS36: 1 | BT36: 1 | BU36: 1 | BV36: 1 | BW36: 1 | BX36: 1 | BZ36: 90 | CA36: 46 | CE36: 1566 | CF36: 0 | CG36: 0 | CM36: 0 | CN36: Поправка: О.П. п.3.4.30.в Наименование: При применении территориальных сметных нормативов для города Москвы затраты, учитывающие напряженные и стесненные условия производства работ (стесненность, сложность складирования и транспортной логистики и т.п.), исчисляются с применением коэффициентов к затратам труда и заработной плате рабочих, машинистов, времени эксплуатации машин и механизмов, стоимости эксплуатации машин в размере: для объектов, расположенных за пределами Третьего транспортного кольца города Москвы, но в пределах Московской кольцевой автомобильной дороги | CO36: 0 | CP36: =(P36+Q36+S36) -> 163.14 | CQ36: =ROUND((ROUND((AC36*AW36*1),2)*BC36),2) -> 89.36 | CR36: =(ROUND((ROUND((((ET36*1.1))*AV36*1),2)*BB36),2)+ROUND((ROUND(((AE36-((EU36*1.1)))*AV36*1),2)*BS36),2)) -> 4.92 | CS36: =(ROUND((ROUND((((EU36*1.1))*AV36*1),2)*BS36),2)+ROUND((ROUND(((AE36-((EU36*1.1)))*AV36*1),2)*BS36),2)) -> 0.44 | CT36: =ROUND((ROUND((AF36*AV36*1),2)*BA36),2) -> 68.86 | CU36: =AG36 -> 0 | CV36: =(AH36*AV36) -> 5.931255 | CW36: =AI36 -> 0 | CX36: =AJ36 -> 0 | CY36: =(ROUND((((S36+ROUND((ROUND((((EU36*1.1))*AV36*1),2)*BS36),2))*AT36)/100),2)+ROUND(((ROUND((ROUND(((AE36-((EU36*1.1)))*AV36*1),2)*BS36),2)*AT36)/100),2)) -> 62.37 | CZ36: =(ROUND((((S36+ROUND((ROUND((((EU36*1.1))*AV36*1),2)*BS36),2))*AU36)/100),2)+ROUND(((ROUND((ROUND(((AE36-((EU36*1.1)))*AV36*1),2)*BS36),2)*AU36)/100),2)) -> 31.88 | DB36: 5 | DE36: *1,1 | DF36: *1,1 | DG36: *1,1 | DI36: *1,1 | DJ36: *1,1 | DN36: 0 | DO36: 0 | DP36: 1 | DQ36: 1 | DU36: 1013 | DV36: 1 ШТ. | DW36: 1 ШТ. | DX36: 1 | EE36: 60088536 | EF36: 40 | EG36: Монтаж оборудования | EH36: 0 | EJ36: 2 | EK36: 72 | EL36: ТСН-2001.4-11. Приборы и средства автоматизации и вычислительной техники | EM36: ТСН-2001.4-11-1 | EO36: Поправка: О.П. п.3.4.30.в | EQ36: 0 | ER36: 153.42 | ES36: 89.36 | ET36: 4.27 | EU36: 0.38 | EV36: 59.79 | EW36: 5.15 | EX36: 0 | EY36: 0 | FQ36: 0 | FR36: 0 | FS36: 0 | FX36: 90 | FY36: 46 | GD36: 1 | GF36: 1767555919 | GG36: 2 | GH36: 1 | GI36: 2 | GJ36: 0 | GK36: 0 | GL36: =ROUND(IF(AND(BH36=3,BI36=3,FS36<>0),P36,0),2) -> 0 | GM36: =ROUND(O36+X36+Y36,2)+GX36 -> 257.39 | GN36: =IF(OR(BI36=0,BI36=1),GM36-GX36,0) -> 0 | GO36: =IF(BI36=2,GM36-GX36,0) -> 257.39 | GP36: =IF(BI36=4,GM36-GX36,0) -> 0 | GR36: 0 | GS36: 3 | GT36: 0 | GV36: =ROUND((GT36),6) -> 0 | GW36: 1 | GX36: =ROUND(HC36*I36,2) -> 0 | HA36: 0 | HB36: 0 | HC36: =GV36*GW36 -> 0 | HS36: 0 | IK36: 0
A37: 17 | B37: 1 | C37: =ROW(SmtRes!A54) -> 54 | D37: =ROW(EtalonRes!A54) -> 54 | E37: 3 | F37: 4.11-17-1 | G37: Монтаж щитов и пультов массой до 50кг | H37: 1 ШТ. | I37: 1 | J37: 0 | K37: 1 | O37: =ROUND(CP37,2) -> 4309.88 | P37: =ROUND((ROUND((AC37*AW37*I37),2)*BC37),2) -> 453.95 | Q37: =(ROUND((ROUND((((ET37*1.1))*AV37*I37),2)*BB37),2)+ROUND((ROUND(((AE37-((EU37*1.1)))*AV37*I37),2)*BS37),2)) -> 69.32 | R37: =(ROUND((ROUND((((EU37*1.1))*AV37*I37),2)*BS37),2)+ROUND((ROUND(((AE37-((EU37*1.1)))*AV37*I37),2)*BS37),2)) -> 24.2 | S37: =ROUND((ROUND((AF37*AV37*I37),2)*BA37),2) -> 3786.61 | T37: =ROUND(CU37*I37,2) -> 0 | U37: =CV37*I37 -> 5.931255 | V37: =CW37*I37 -> 0 | W37: =ROUND(CX37*I37,2) -> 0 | X37: =(ROUND((((S37+ROUND((ROUND((((EU37*1.1))*AV37*I37),2)*BS37),2))*AT37)/100),2)+ROUND(((ROUND((ROUND(((AE37-((EU37*1.1)))*AV37*I37),2)*BS37),2)*AT37)/100),2)) -> 3429.73 | Y37: =(ROUND((((S37+ROUND((ROUND((((EU37*1.1))*AV37*I37),2)*BS37),2))*AU37)/100),2)+ROUND(((ROUND((ROUND(((AE37-((EU37*1.1)))*AV37*I37),2)*BS37),2)*AU37)/100),2)) -> 1752.97 | AA37: 60256982 | AB37: =ROUND((AC37+AD37+AF37),6) -> 159.826 | AC37: =ROUND((ES37),6) -> 89.36 | AD37: =ROUND(((((ET37*1.1))-((EU37*1.1)))+AE37),6) -> 4.697 | AE37: =ROUND(((EU37*1.1)),6) -> 0.418 | AF37: =ROUND(((EV37*1.1)),6) -> 65.769 | AG37: =ROUND((AP37),6) -> 0 | AH37: =((EW37*1.1)) -> 5.665 | AI37: =((EX37*1.1)) -> 0 | AJ37: =(AS37) -> 0 | AK37: 153.42 | AL37: 89.36 | AM37: 4.27 | AN37: 0.38 | AO37: 59.79 | AP37: 0 | AQ37: 5.15 | AR37: 0 | AS37: 0 | AT37: 90 | AU37: 46 | AV37: 1.047 | AW37: 1 | AZ37: 1 | BA37: 54.99 | BB37: 14.09 | BC37: 5.08 | BH37: 0 | BI37: 2 | BJ37: ТСН-2001.4 Доп. 80, Сб. 11, т. 17, поз. 1 | BM37: 72 | BN37: 58973116 | BO37: 4.11-17-1 | BP37: 1 | BQ37: 40 | BR37: 0 | BS37: 54.99 | BT37: 1 | BU37: 1 | BV37: 1 | BW37: 1 | BX37: 1 | BZ37: 90 | CA37: 46 | CE37: 1566 | CF37: 0 | CG37: 0 | CM37: 0 | CN37: Поправка: О.П. п.3.4.30.в Наименование: При применении территориальных сметных нормативов для города Москвы затраты, учитывающие напряженные и стесненные условия производства работ (стесненность, сложность складирования и транспортной логистики и т.п.), исчисляются с применением коэффициентов к затратам труда и заработной плате рабочих, машинистов, времени эксплуатации машин и механизмов, стоимости эксплуатации машин в размере: для объектов, расположенных за пределами Третьего транспортного кольца города Москвы, но в пределах Московской кольцевой автомобильной дороги | CO37: 0 | CP37: =(P37+Q37+S37) -> 4309.88 | CQ37: =ROUND((ROUND((AC37*AW37*1),2)*BC37),2) -> 453.95 | CR37: =(ROUND((ROUND((((ET37*1.1))*AV37*1),2)*BB37),2)+ROUND((ROUND(((AE37-((EU37*1.1)))*AV37*1),2)*BS37),2)) -> 69.32 | CS37: =(ROUND((ROUND((((EU37*1.1))*AV37*1),2)*BS37),2)+ROUND((ROUND(((AE37-((EU37*1.1)))*AV37*1),2)*BS37),2)) -> 24.2 | CT37: =ROUND((ROUND((AF37*AV37*1),2)*BA37),2) -> 3786.61 | CU37: =AG37 -> 0 | CV37: =(AH37*AV37) -> 5.931255 | CW37: =AI37 -> 0 | CX37: =AJ37 -> 0 | CY37: =(ROUND((((S37+ROUND((ROUND((((EU37*1.1))*AV37*1),2)*BS37),2))*AT37)/100),2)+ROUND(((ROUND((ROUND(((AE37-((EU37*1.1)))*AV37*1),2)*BS37),2)*AT37)/100),2)) -> 3429.73 | CZ37: =(ROUND((((S37+ROUND((ROUND((((EU37*1.1))*AV37*1),2)*BS37),2))*AU37)/100),2)+ROUND(((ROUND((ROUND(((AE37-((EU37*1.1)))*AV37*1),2)*BS37),2)*AU37)/100),2)) -> 1752.97 | DB37: 6 | DE37: *1,1 | DF37: *1,1 | DG37: *1,1 | DI37: *1,1 | DJ37: *1,1 | DN37: 0 | DO37: 0 | DP37: 1 | DQ37: 1 | DU37: 1013 | DV37: 1 ШТ. | DW37: 1 ШТ. | DX37: 1 | EE37: 60088536 | EF37: 40 | EG37: Монтаж оборудования | EH37: 0 | EJ37: 2 | EK37: 72 | EL37: ТСН-2001.4-11. Приборы и средства автоматизации и вычислительной техники | EM37: ТСН-2001.4-11-1 | EO37: Поправка: О.П. п.3.4.30.в | EQ37: 0 | ER37: 153.42 | ES37: 89.36 | ET37: 4.27 | EU37: 0.38 | EV37: 59.79 | EW37: 5.15 | EX37: 0 | EY37: 0 | FQ37: 0 | FR37: 0 | FS37: 0 | FX37: 90 | FY37: 46 | GD37: 1 | GF37: 1767555919 | GG37: 2 | GH37: 1 | GI37: 2 | GJ37: 0 | GK37: 0 | GL37: =ROUND(IF(AND(BH37=3,BI37=3,FS37<>0),P37,0),2) -> 0 | GM37: =ROUND(O37+X37+Y37,2)+GX37 -> 9492.58 | GN37: =IF(OR(BI37=0,BI37=1),GM37-GX37,0) -> 0 | GO37: =IF(BI37=2,GM37-GX37,0) -> 9492.58 | GP37: =IF(BI37=4,GM37-GX37,0) -> 0 | GR37: 0 | GS37: 3 | GT37: 0 | GV37: =ROUND((GT37),6) -> 0 | GW37: 1 | GX37: =ROUND(HC37*I37,2) -> 0 | HA37: 0 | HB37: 0 | HC37: =GV37*GW37 -> 0 | HS37: 0 | IK37: 0
