Workbook

Sheet 02-01-14
A1: =Source!B1 -> Smeta.RU (495) 974-1589
J2: Форма № 4б
A3: Капитальный ремонт здания Государственного бюджетного общеобразовательного учреждения города Москвы "Школа №236" по адресу: г. Москва, улица Клязьминская, дом 7, корпус 4. | AP3: Капитальный ремонт здания Государственного бюджетного общеобразовательного учреждения города Москвы "Школа №236" по адресу: г. Москва, улица Клязьминская, дом 7, корпус 4. 02-01-14 СОТ
A4: (наименование стройки и/или объекта)
A6: =CONCATENATE( "ЛОКАЛЬНАЯ СМЕТА № ",IF(Source!F20<>"Новая локальная смета", Source!F20, "")) -> ЛОКАЛЬНАЯ СМЕТА № 02-01-14
A8: =IF(Source!G20<>"Новая локальная смета", Source!G20, "") -> Система охранного теленаблюдения
A9: (наименование работ и затрат)
A11: =CONCATENATE( "Основание: чертежи № ", Source!J20) -> Основание: чертежи № 2024-00281-00-ИОС5.7
I13: В базисном уровне цен | J13: В текущем уровне цен
E14: Сметная стоимость | I14: =I15+I16+I17+I18 -> 1045.29 | J14: =J15+J16+J17+J18 -> 10298 | K14: тыс.руб.
E15: Строительные работы | I15: =ROUND((Source!F222)/1000, 2) -> 0 | J15: =ROUND((Source!P222)/1000, 2) -> 0 | K15: тыс.руб.
E16: Работы по монтажу оборудования | I16: =ROUND((Source!F223)/1000, 2) -> 135.31 | J16: =ROUND((Source!P223)/1000, 2) -> 3332.58 | K16: тыс.руб.
E17: Оборудование | I17: =ROUND((Source!F214)/1000, 2) -> 909.98 | J17: =ROUND((Source!P214)/1000, 2) -> 6965.42 | K17: тыс.руб.
E18: Прочие работы и затраты | I18: =ROUND((Source!F224+Source!F225)/1000, 2) -> 0 | J18: =ROUND((Source!P224+Source!P225)/1000, 2) -> 0 | K18: тыс.руб.
E19: Средства на оплату труда | I19: =(Source!F220+ Source!F219)/1000 -> 19.03358 | J19: =((Source!P220 + Source!P219)/1000) -> 1046.6566 | K19: тыс.руб.
E20: Затраты труда | I20: =Source!F227 -> 1399.7195 | K20: чел.-ч.
E21: Кроме того:
E22: Возврат материалов | I22: =SUM(Y28:Y283)/1000 -> 0 | J22: =SUM(Z28:Z283)/1000 -> 0 | K22: тыс.руб.
A24: Составлен(а) по ТСН-2001 с учетом Дополнения №: 80
A25: № и период сборника коэффициентов (индексов) пересчета: Коэффициенты к ТСН-2001 МГЭ Дополнение 80, строительство №217/80 III квартал 2025 года и Коэффициенты к ТСН-2001.13-2 Дополнение 46 №62/46 III квартал 2025 года | AP25: № и период сборника коэффициентов (индексов) пересчета: Коэффициенты к ТСН-2001 МГЭ Дополнение 80, строительство №217/80 III квартал 2025 года и Коэффициенты к ТСН-2001.13-2 Дополнение 46 №62/46 III квартал 2025 года
A26: № п/п | B26: Шифр расценки и коды ресурсов | C26: Наименование работ и затрат | D26: Ед. изм. | E26: Кол-во единиц | F26: Цена на ед. изм., руб. | G26: Попра- вочные коэффи- циенты | H26: Коэффи- циенты зимних удорожа- ний | I26: Всего в ценах на январь 2000 года, руб. | J26: Коэффи- циенты (индек- сы) пере- счета, нормы НР и СП | K26: ВСЕГО затрат в текущем уровне цен, руб.
A27: 1 | B27: 2 | C27: 3 | D27: 4 | E27: 5 | F27: 6 | G27: 7 | H27: 8 | I27: 9 | J27: 10 | K27: 11
A29: =CONCATENATE("Раздел: ",IF(Source!G24<>"Новый раздел", Source!G24, "")) -> Раздел: Оборудование
A30: 1 | B30: =Source!F28 -> 4.10-174-1 | C30: Монтаж внутренней камеры видеонаблюдения | D30: =Source!H28 -> 10 шт. | E30: =Source!I28 -> 2.8 | Q30: =Source!X28 -> 718.46 | R30: =Source!X29 -> 39508.17 | S30: =Source!Y28 -> 367.21 | T30: =Source!Y29 -> 20193.07 | U30: =ROUND((175/100)*ROUND(Source!R28, 2), 2) -> 0.74 | V30: =ROUND((0/100)*ROUND(Source!R29, 2), 2) -> 0 | AC30: 0
C31: ="Объем: "&Source!I28&"=28/"&"10" -> Объем: 2,8=28/10
C32: ЗП | F32: =Source!AO28 -> 247.42 | G32: =Source!DG28 -> *1,1 | H32: =Source!AV29 -> 1.047 | I32: =Source!S28 -> 797.87 | J32: =IF(Source!BA29<> 0, Source!BA29, 1) -> 54.99 | K32: =Source!S29 -> 43874.87
C33: ЭМ | F33: =Source!AM28 -> 2.36 | G33: =Source!DE28 -> *1,1 | H33: =Source!AV29 -> 1.047 | I33: =Source!Q28 -> 7.61 | J33: =IF(Source!BB29<> 0, Source!BB29, 1) -> 11.36 | K33: =Source!Q29 -> 86.45
C34: в т.ч. ЗПМ | F34: =Source!AN28 -> 0.13 | G34: =Source!DF28 -> *1,1 | H34: =Source!AV29 -> 1.047 | I34: =Source!R28 -> 0.42 | J34: =IF(Source!BS29<> 0, Source!BS29, 1) -> 54.99 | K34: =Source!R29 -> 23.1
C35: МР | F35: =Source!AL28 -> 42.51 | G35: =Source!DD28 | H35: =Source!AW29 -> 1 | I35: =Source!P28 -> 119.03 | J35: =IF(Source!BC29<> 0, Source!BC29, 1) -> 1.93 | K35: =Source!P29 -> 229.73
C36: НР от ФОТ | D36: % | E36: =Source!BZ29 -> 90 | I36: =SUM(Q30:Q35) -> 718.46 | J36: =Source!AT29 -> 90 | K36: =SUM(R30:R35) -> 39508.17
C37: СП от ФОТ | D37: % | E37: =Source!CA29 -> 46 | I37: =SUM(S30:S36) -> 367.21 | J37: =Source!AU29 -> 46 | K37: =SUM(T30:T36) -> 20193.07
C38: ЗТР | D38: чел-ч | E38: =Source!AQ28 -> 15.54 | G38: =Source!DI28 -> *1,1 | H38: =Source!AV29 -> 1.047 | I38: =Source!U28 -> 50.11277
C39: ВСЕГО работ по позиции: | H39: =I32+I33+I35+I36+I37+0-0-0 -> 2010.18 | J39: =K32+K33+K35+K36+K37+0-0-0 -> 103892.29
C40: ВСЕГО оборудование по позиции: | H40: =0+0 -> 0 | J40: =0+0 -> 0
C41: ВСЕГО по позиции: | H41: =I32+I33+I35+I36+I37+0 -> 2010.18 | J41: =K32+K33+K35+K36+K37+0 -> 103892.29 | O41: =I32+I33+I35+I36+I37+0 -> 2010.18 | P41: =K32+K33+K35+K36+K37+0 -> 103892.29
A43: 2 | B43: =Source!F30 -> КА-1 | C43: ОБОРУДОВАНИЕ:_x000D_ Цилиндрическая IP-видеокамера с фиксированным объективом IP 2 Мп; 1/3" КМОП, 1920х1080-25/30к/с; встроенный микрофон; Дальность ИК подсветки 30м; объектив 2.8мм(3.6мм, 6ммопционально) ; режим "день/ночь", H264/ MJPEG ( Доп. поток) ; ; PoE 5 Вт; -40 ~ +60°C, TR-D2121CL3 4.0 1 011,06 = [8 916 / 1,2 / 7,66] + 3% Трансп + 1,2% Заг.скл | D43: =Source!H30 -> ШТ | E43: =Source!I30 -> 28 | F43: =Source!AL30 -> 1011.06 | G43: =Source!DD30 | H43: =Source!AW31 -> 1 | I43: =Source!P30 -> 28309.68 | J43: =IF(Source!BC31<> 0, Source!BC31, 1) -> 7.66 | K43: =Source!P31 -> 216852.15 | Q43: =Source!X30 -> 0 | R43: =Source!X31 -> 0 | S43: =Source!Y30 -> 0 | T43: =Source!Y31 -> 0 | U43: =ROUND((175/100)*ROUND(Source!R30, 2), 2) -> 0 | V43: =ROUND((0/100)*ROUND(Source!R31, 2), 2) -> 0 | AC43: 5
C44: ВСЕГО по позиции: | H44: =I43+0 -> 28309.68 | J44: =K43+0 -> 216852.15 | O44: =I43+0 -> 28309.68 | P44: =K43+0 -> 216852.15
A46: 3 | B46: =Source!F32 -> 4.10-136-1 | C46: Разные устройства, монтаж коробки телевизионной (ответвители, разветвители магистральные, домовые, абонентские), УСС, БФТК | D46: =Source!H32 -> 1 ШТ. | E46: =Source!I32 -> 28 | Q46: =Source!X32 -> 350.5 | R46: =Source!X33 -> 19274.13 | S46: =Source!Y32 -> 195.54 | T46: =Source!Y33 -> 10752.94 | U46: =ROUND((175/100)*ROUND(Source!R32, 2), 2) -> 0 | V46: =ROUND((0/100)*ROUND(Source!R33, 2), 2) -> 0 | AC46: 0
C47: ЗП | F47: =Source!AO32 -> 11.02 | G47: =Source!DG32 -> *1,1 | H47: =Source!AV33 -> 1.087 | I47: =Source!S32 -> 368.95 | J47: =IF(Source!BA33<> 0, Source!BA33, 1) -> 54.99 | K47: =Source!S33 -> 20288.56
C48: МР | F48: =Source!AL32 -> 0.29 | G48: =Source!DD32 | H48: =Source!AW33 -> 1 | I48: =Source!P32 -> 8.12 | J48: =IF(Source!BC33<> 0, Source!BC33, 1) -> 9.9 | K48: =Source!P33 -> 80.39
...

Sheet Ведомость объемов работ
A1: =Source!B1 -> Smeta.RU (495) 974-1589
B4: =CONCATENATE("Ведомость объемов работ ", IF(Source!AN15<>"", Source!AN15," ")) -> Ведомость объемов работ
B5: =CONCATENATE(Source!F12, " ", Source!G12) -> 02-01-14 СОТ
A8: № п/п | B8: № в ЛСР | C8: Наименование работ и затрат | D8: Единица измерения | E8: Количество | F8: Ссылка на чертежи, спецификации | G8: Формула расчета, расчет объемов работ и расхода материалов | H8: Примечание
A9: 1 | B9: 2 | C9: 3 | D9: 4 | E9: 5 | F9: 6 | G9: 7 | H9: 8
A10: =CONCATENATE("Локальная смета: ", Source!G20) -> Локальная смета: Система охранного теленаблюдения
A11: =CONCATENATE("Раздел: ", Source!G24) -> Раздел: Оборудование
A12: 1 | B12: =Source!E28 -> 1 | C12: =Source!G28 -> Монтаж внутренней камеры видеонаблюдения | D12: 10 шт. | E12: =Source!I28 -> 2.8 | F12: =Source!U24 | G12: ="=28/"&"10" -> =28/10
A13: 2 | B13: =Source!E30 -> 2 | C13: =Source!G30 -> Цилиндрическая IP-видеокамера с фиксированным объективом IP 2 Мп; 1/3" КМОП, 1920х1080-25/30к/с; встроенный микрофон; Дальность ИК подсветки 30м; объектив 2.8мм(3.6мм, 6ммопционально) ; режим "день/ночь", H264/ MJPEG ( Доп. поток) ; ; PoE 5 Вт; -40 ~ +60°C, TR-D2121CL3 4.0 | D13: ШТ | E13: =Source!I30 -> 28 | F13: =Source!U24 | G13: =Source!I30 -> 28
A14: 3 | B14: =Source!E32 -> 3 | C14: =Source!G32 -> Разные устройства, монтаж коробки телевизионной (ответвители, разветвители магистральные, домовые, абонентские), УСС, БФТК | D14: 1 ШТ. | E14: =Source!I32 -> 28 | F14: =Source!U24 | G14: =Source!I32 -> 28
A15: 4 | B15: =Source!E34 -> 4 | C15: =Source!G34 -> Устройство грозозащиты NST NS-LP-1GP/D | D15: ШТ | E15: =Source!I34 -> 28 | F15: =Source!U24 | G15: =Source!I34 -> 28
A16: 5 | B16: =Source!E36 -> 5 | C16: =Source!G36 -> Монтаж наружной камеры видеонаблюдения | D16: 10 шт. | E16: =Source!I36 -> 10.9 | F16: =Source!U24 | G16: ="=109/"&"10" -> =109/10
A17: 6 | B17: =Source!E38 -> 6 | C17: =Source!G38 -> Купольная IP-видеокамера с фиксированным объективом IP 2 Мп; 1/2.8" КМОП, 1920х1080-25/30к/с; встроенный микрофон; Дальность ИК подсветки 25м; объектив 2.8мм(3.6мм, 6ммопционально) ; режим "день/ночь", H264/ MJPEG ( Доп. поток) ; ; PoE 5 Вт; TR-D2D2 v2 2.7-13.5 | D17: ШТ | E17: =Source!I38 -> 109 | F17: =Source!U24 | G17: =Source!I38 -> 109
A18: 7 | B18: =Source!E40 -> 7 | C18: =Source!G40 -> Монтаж устройства цифровой регистрации | D18: 1 устройство | E18: =Source!I40 -> 1 | F18: =Source!U24 | G18: =Source!I40 -> 1
A19: 8 | B19: =Source!E42 -> 8 | C19: =Source!G42 -> IP-видеорегистратор UltraStation 24/10 на 256 каналов, 24 HDD на 10 Тбайт UltraStation 24/10 256 v2 с 24 HDD | D19: ШТ | E19: =Source!I42 -> 1 | F19: =Source!U24 | G19: =Source!I42 -> 1
A20: 9 | B20: =Source!E44 -> 9 | C20: =Source!G44 -> Программное обеспечение TRASSIR ЕЦХД | D20: ШТ | E20: =Source!I44 -> 1 | F20: =Source!U24 | G20: =Source!I44 -> 1
A21: 10 | B21: =Source!E46 -> 10 | C21: =Source!G46 -> Монтаж коммутатора служебной связи | D21: 1 ШТ. | E21: =Source!I46 -> 9 | F21: =Source!U24 | G21: ="=1+"&"1+"&"7" -> =1+1+7
A22: 11 | B22: =Source!E48 -> 11 | C22: =Source!G48 -> Коммутатор агрегации MES3300-16F | D22: ШТ | E22: =Source!I48 -> 1 | F22: =Source!U24 | G22: =Source!I48 -> 1
A23: 12 | B23: =Source!E50 -> 12 | C23: =Source!G50 -> Коммутатор доступа 48 PoE MES2420-48P | D23: ШТ | E23: =Source!I50 -> 1 | F23: =Source!U24 | G23: =Source!I50 -> 1
A24: 13 | B24: =Source!E52 -> 13 | C24: =Source!G52 -> Коммутатор доступа 24 PoE MES2300-24P | D24: ШТ | E24: =Source!I52 -> 7 | F24: =Source!U24 | G24: =Source!I52 -> 7
A25: 14 | B25: =Source!E54 -> 14 | C25: =Source!G54 -> Монтаж платы дополнительной, устанавливаемой на готовом месте стойки | D25: 1 ШТ. | E25: =Source!I54 -> 18 | F25: =Source!U24 | G25: =Source!I54 -> 18
A26: 15 | B26: =Source!E56 -> 15 | C26: =Source!G56 -> SFP 1,25 GE модуль 550 м, ММ, 2 волокна, 850 пт, LC, DDM FH-S8512CDL05 | D26: ШТ | E26: =Source!I56 -> 18 | F26: =Source!U24 | G26: =Source!I56 -> 18
A27: 16 | B27: =Source!E58 -> 16 | C27: =Source!G58 -> Монтаж платы дополнительной, устанавливаемой на готовом месте стойки | D27: 1 ШТ. | E27: =Source!I58 -> 3 | F27: =Source!U24 | G27: =Source!I58 -> 3
A28: 17 | B28: =Source!E60 -> 17 | C28: =Source!G60 -> Грозозащита для локальной вычислительной сети, 16 GE RJ-45 SP-IP16/1000PR | D28: ШТ | E28: =Source!I60 -> 3 | F28: =Source!U24 | G28: =Source!I60 -> 3
A29: 18 | B29: =Source!E62 -> 18 | C29: =Source!G62 -> Монтаж аппаратуры настенной | D29: 1 ШТ. | E29: =Source!I62 -> 4 | F29: =Source!U24 | G29: =Source!I62 -> 4
A30: 19 | B30: =Source!E64 -> 19 | C30: =Source!G64 -> Кронштейн настенного крепления RDW 2701K | D30: ШТ | E30: =Source!I64 -> 4 | F30: =Source!U24 | G30: =Source!I64 -> 4
A31: 20 | B31: =Source!E66 -> 20 | C31: =Source!G66 -> Монитор RDW 2701K | D31: ШТ | E31: =Source!I66 -> 4 | F31: =Source!U24 | G31: =Source!I66 -> 4
A32: 21 | B32: =Source!E68 -> 21 | C32: =Source!G68 -> Монтаж аппаратуры настольной массой до 20 кг | D32: 1 ШТ. | E32: =Source!I68 -> 1 | F32: =Source!U24 | G32: =Source!I68 -> 1
A33: 22 | B33: =Source!E70 -> 22 | C33: =Source!G70 -> Рабочая станция DEPO Race VT955 | D33: ШТ | E33: =Source!I70 -> 1 | F33: =Source!U24 | G33: =Source!I70 -> 1
A34: 23 | B34: =Source!E72 -> 23 | C34: =Source!G72 -> Монтаж блока бесперебойного питания (ББП) в диспетчерской | D34: 1 ШТ. | E34: =Source!I72 -> 8 | F34: =Source!U24 | G34: =Source!I72 -> 8
A35: 24 | B35: =Source!E74 -> 24 | C35: =Source!G74 -> Источник бесперебойного питания 3000 ВА/2700 Вт SKAT-UPS 3000-RACK-ON-6x9-E | D35: ШТ | E35: =Source!I74 -> 8 | F35: =Source!U24 | G35: =Source!I74 -> 8
A36: 25 | B36: =Source!E76 -> 25 | C36: =Source!G76 -> Батарейный блок 18Ач/72В SKAT BC 72/18S3 RACK | D36: ШТ | E36: =Source!I76 -> 2 | F36: =Source!U24 | G36: =Source!I76 -> 2
A37: =CONCATENATE("Раздел: ", Source!G109) -> Раздел: Материалы и кабельные изделия
A38: 26 | B38: =Source!E113 -> 26 | C38: =Source!G113 -> Установка съемных и выдвижных блоков (модулей, ячеек, ТЭЗ) массой до 5 кг | D38: 1 ШТ. | E38: =Source!I113 -> 18 | F38: =Source!U109 | G38: ="=2+"&"8+"&"1+"&"7" -> =2+8+1+7
A39: 27 | B39: =Source!E115 -> 27 | C39: =Source!G115 -> Оптический распределительный кросс укомплектованный: LC (Duplex) 24 шт, (ОМЗ) FOBX24-1U-24LCUD03 | D39: ШТ | E39: =Source!I115 -> 2 | F39: =Source!U109 | G39: =Source!I115 -> 2
A40: 28 | B40: =Source!E117 -> 28 | C40: =Source!G117 -> Оптический распределительный кросс укомплектованный: LC (Duplex) 8 шт, (ОМЗ) FOBX24-1U-8LCUD03 | D40: ШТ | E40: =Source!I117 -> 8 | F40: =Source!U109 | G40: =Source!I117 -> 8
A41: 29 | B41: =Source!E119 -> 29 | C41: =Source!G119 -> 1U патч-панель кат.5E UTP 48 портов (DUAL IDC) высокой плотности PP48-1UC5EU-D05H | D41: ШТ | E41: =Source!I119 -> 1 | F41: =Source!U109 | G41: =Source!I119 -> 1
A42: 30 | B42: =Source!E121 -> 30 | C42: =Source!G121 -> 1U патч-панель кат.5E UTP 24портов (DUAL IDC) высокой плотности PP24-1UC5EU-D05-1 | D42: ШТ | E42: =Source!I121 -> 7 | F42: =Source!U109 | G42: =Source!I121 -> 7
A43: =CONCATENATE("Раздел: ", Source!G154) -> Раздел: Кабельные изделия
A44: 31 | B44: =Source!E158 -> 31 | C44: =Source!G158 -> Трубы гофрированные поливинилхлоридные наружным диаметром 20 мм открыто по стенам и потолкам с установкой соединительных коробок | D44: 100 м | E44: =Source!I158 -> 30 | F44: =Source!U154 | G44: ="=3000/"&"100" -> =3000/100
...

Sheet Source
A1: 0 | B1: Smeta.RU (495) 974-1589 | D1: _PS_ | F1: 0 | G1: 0 | H1: 0 | I1: Smeta.RU | K1: 1 | L1: 74563 | M1: 10 | N1: 12 | O1: 0 | P1: 0 | Q1: 3
A4: 1 | B4: 1 | C4: -1 | G4: Капитальный ремонт здания Государственного бюджетного общеобразовательного учреждения города Москвы "Школа №236" по адресу: г. Москва, улица Клязьминская, дом 7, корпус 4 | EC4: 0
A12: 1 | B12: 274 | C12: 0 | D12: =ROW(A235) -> 235 | E12: 0 | G12: 02-01-14 СОТ | I12: 0 | J12: 2024-00281-00-ИОС5.7 | K12: 0 | L12: 0 | M12: 4098 | O12: 0 | P12: 0 | Q12: 0 | R12: 0 | S12: 0 | T12: 1 | V12: 0 | AB12: Соколова И.Н. | BB12: 0 | BH12: Сметные нормы списания | BI12: Коды ОКП для ТСН-2001 МГЭ Дополнение 80 | BJ12: 1 | BK12: 1 | BL12: 0 | BM12: 0 | BN12: 1 | BO12: 0 | BP12: 6 | BQ12: 2 | BR12: 1 | BS12: 1 | BT12: 0 | BU12: 0 | BV12: 0 | BW12: 0 | BX12: 0 | BZ12: Типовой расчет для ТСН-2001 МГЭ, Дополнение 80, строительство (1) | CA12: Территориальные сметные нормативы для Москвы ТСН-2001 (МГЭ), дополнение 80 | CB12: Территориальные сметные нормативы для Москвы ТСН-2001 (МГЭ), дополнение 80 | CC12: Территориальные сметные нормативы для Москвы ТСН-2001 (МГЭ), дополнение 80 | CD12: Территориальные сметные нормативы для Москвы ТСН-2001 (МГЭ), дополнение 80 | CE12: Поправки для ТСН-2001 от 28.11.2025 г. доп.79 | CF12: 0 | CG12: 0 | CH12: 8200 | CK12: 80 | CQ12: Территориальные сметные нормативы для Москвы (ТСН-2001) | CR12: ТЕР | CS12: 41660 | CT12: 1 | CU12: 80 | CY12: 0 | EC12: 0
A15: 15 | B15: 1
A18: 52 | B18: =B235 -> 274 | C18: =C235 -> 1 | D18: =D235 -> 12 | E18: =E235 -> 0 | F18: =F235 | G18: =G235 -> 02-01-14 СОТ | O18: =O235 -> 1018066.3 | P18: =P235 -> 997324.72 | Q18: =Q235 -> 1999.81 | R18: =R235 -> 291.77 | S18: =S235 -> 18741.81 | T18: =T235 -> 0 | U18: =U235 -> 1399.7195 | V18: =V235 -> 0 | ... GX18: =GX235 -> 0
A20: 3 | B20: 1 | D20: =ROW(A205) -> 205 | F20: 02-01-14 | G20: Система охранного теленаблюдения | I20: 0 | J20: 2024-00281-00-ИОС5.7 | K20: -1 | L20: 02-01-14 | S20: 0 | T20: 0 | V20: 2 | BX20: 0 | CF20: 0 | CG20: 0
A22: 52 | B22: =B205 -> 1 | C22: =C205 -> 3 | D22: =D205 -> 20 | E22: =E205 -> 0 | F22: =F205 -> 02-01-14 | G22: =G205 -> Система охранного теленаблюдения | O22: =O205 -> 1018066.3 | P22: =P205 -> 997324.72 | Q22: =Q205 -> 1999.81 | R22: =R205 -> 291.77 | S22: =S205 -> 18741.81 | T22: =T205 -> 0 | U22: =U205 -> 1399.7195 | V22: =V205 -> 0 | ... GX22: =GX205 -> 0
A24: 4 | B24: 1 | D24: =ROW(A79) -> 79 | G24: Оборудование | I24: 0 | K24: -1 | S24: 0 | T24: 0 | V24: 2 | BX24: 0 | CJ24: 0
A26: 52 | B26: =B79 -> 1 | C26: =C79 -> 4 | D26: =D79 -> 24 | E26: =E79 -> 0 | F26: =F79 | G26: =G79 -> Оборудование | O26: =O79 -> 899801.87 | P26: =P79 -> 890668.32 | Q26: =Q79 -> 557.09 | R26: =R79 -> 59.23 | S26: =S79 -> 8576.46 | T26: =T79 -> 0 | U26: =U79 -> 593.36134 | V26: =V79 -> 0 | ... GX26: =GX79 -> 0
A28: 17 | B28: 1 | C28: =ROW(SmtRes!A6) -> 6 | D28: =ROW(EtalonRes!A7) -> 7 | E28: 1 | F28: 4.10-174-1 | G28: Монтаж внутренней камеры видеонаблюдения | H28: 10 шт. | I28: =ROUND(28/10,9) -> 2.8 | J28: 0 | K28: =ROUND(28/10,9) -> 2.8 | O28: =ROUND(CP28,2) -> 924.51 | P28: =ROUND((ROUND((AC28*AW28*I28),2)*BC28),2) -> 119.03 | Q28: =(ROUND((ROUND((((ET28*1.1))*AV28*I28),2)*BB28),2)+ROUND((ROUND(((AE28-((EU28*1.1)))*AV28*I28),2)*BS28),2)) -> 7.61 | R28: =(ROUND((ROUND((((EU28*1.1))*AV28*I28),2)*BS28),2)+ROUND((ROUND(((AE28-((EU28*1.1)))*AV28*I28),2)*BS28),2)) -> 0.42 | S28: =ROUND((ROUND((AF28*AV28*I28),2)*BA28),2) -> 797.87 | T28: =ROUND(CU28*I28,2) -> 0 | U28: =CV28*I28 -> 50.11277 | V28: =CW28*I28 -> 0 | W28: =ROUND(CX28*I28,2) -> 0 | X28: =(ROUND((((S28+ROUND((ROUND((((EU28*1.1))*AV28*I28),2)*BS28),2))*AT28)/100),2)+ROUND(((ROUND((ROUND(((AE28-((EU28*1.1)))*AV28*I28),2)*BS28),2)*AT28)/100),2)) -> 718.46 | Y28: =(ROUND((((S28+ROUND((ROUND((((EU28*1.1))*AV28*I28),2)*BS28),2))*AU28)/100),2)+ROUND(((ROUND((ROUND(((AE28-((EU28*1.1)))*AV28*I28),2)*BS28),2)*AU28)/100),2)) -> 367.21 | AA28: 60258064 | AB28: =ROUND((AC28+AD28+AF28),6) -> 317.268 | AC28: =ROUND((ES28),6) -> 42.51 | AD28: =ROUND(((((ET28*1.1))-((EU28*1.1)))+AE28),6) -> 2.596 | AE28: =ROUND(((EU28*1.1)),6) -> 0.143 | AF28: =ROUND(((EV28*1.1)),6) -> 272.162 | AG28: =ROUND((AP28),6) -> 0 | AH28: =((EW28*1.1)) -> 17.094 | AI28: =((EX28*1.1)) -> 0 | AJ28: =(AS28) -> 0 | AK28: 292.29 | AL28: 42.51 | AM28: 2.36 | AN28: 0.13 | AO28: 247.42 | AP28: 0 | AQ28: 15.54 | AR28: 0 | AS28: 0 | AT28: 90 | AU28: 46 | AV28: 1.047 | AW28: 1 | AZ28: 1 | BA28: 1 | BB28: 1 | BC28: 1 | BH28: 0 | BI28: 2 | BJ28: ТСН-2001.4 Доп. 68, Сб. 10, т. 174, поз. 1 | BM28: 68 | BN28: 58973116 | BO28: 4.10-174-1 | BP28: 1 | BQ28: 40 | BR28: 0 | BS28: 1 | BT28: 1 | BU28: 1 | BV28: 1 | BW28: 1 | BX28: 1 | BZ28: 90 | CA28: 46 | CE28: 1566 | CF28: 0 | CG28: 0 | CM28: 0 | CN28: Поправка: О.П. п.3.4.30.в Наименование: При применении территориальных сметных нормативов для города Москвы затраты, учитывающие напряженные и стесненные условия производства работ (стесненность, сложность складирования и транспортной логистики и т.п.), исчисляются с применением коэффициентов к затратам труда и заработной плате рабочих, машинистов, времени эксплуатации машин и механизмов, стоимости эксплуатации машин в размере: для объектов, расположенных за пределами Третьего транспортного кольца города Москвы, но в пределах Московской кольцевой автомобильной дороги | CO28: 0 | CP28: =(P28+Q28+S28) -> 924.51 | CQ28: =ROUND((ROUND((AC28*AW28*1),2)*BC28),2) -> 42.51 | CR28: =(ROUND((ROUND((((ET28*1.1))*AV28*1),2)*BB28),2)+ROUND((ROUND(((AE28-((EU28*1.1)))*AV28*1),2)*BS28),2)) -> 2.72 | CS28: =(ROUND((ROUND((((EU28*1.1))*AV28*1),2)*BS28),2)+ROUND((ROUND(((AE28-((EU28*1.1)))*AV28*1),2)*BS28),2)) -> 0.15 | CT28: =ROUND((ROUND((AF28*AV28*1),2)*BA28),2) -> 284.95 | CU28: =AG28 -> 0 | CV28: =(AH28*AV28) -> 17.897418 | CW28: =AI28 -> 0 | CX28: =AJ28 -> 0 | CY28: =(ROUND((((S28+ROUND((ROUND((((EU28*1.1))*AV28*1),2)*BS28),2))*AT28)/100),2)+ROUND(((ROUND((ROUND(((AE28-((EU28*1.1)))*AV28*1),2)*BS28),2)*AT28)/100),2)) -> 718.22 | CZ28: =(ROUND((((S28+ROUND((ROUND((((EU28*1.1))*AV28*1),2)*BS28),2))*AU28)/100),2)+ROUND(((ROUND((ROUND(((AE28-((EU28*1.1)))*AV28*1),2)*BS28),2)*AU28)/100),2)) -> 367.09 | DB28: 1 | DE28: *1,1 | DF28: *1,1 | DG28: *1,1 | DI28: *1,1 | DJ28: *1,1 | DN28: 0 | DO28: 0 | DP28: 1 | DQ28: 1 | DU28: 1010 | DV28: 10 шт. | DW28: 10 шт. | DX28: 10 | EE28: 60088532 | EF28: 40 | EG28: Монтаж оборудования | EH28: 0 | EJ28: 2 | EK28: 68 | EL28: ТСН-2001.4-10. Прокладка и монтаж сетей связи | EM28: ТСН-2001.4-10-1 | EO28: Поправка: О.П. п.3.4.30.в | EQ28: 0 | ER28: 292.29 | ES28: 42.51 | ET28: 2.36 | EU28: 0.13 | EV28: 247.42 | EW28: 15.54 | EX28: 0 | EY28: 0 | FQ28: 0 | FR28: 0 | FS28: 0 | FX28: 90 | FY28: 46 | GD28: 1 | GF28: -1957665847 | GG28: 2 | GH28: 1 | GI28: 2 | GJ28: 0 | GK28: 0 | GL28: =ROUND(IF(AND(BH28=3,BI28=3,FS28<>0),P28,0),2) -> 0 | GM28: =ROUND(O28+X28+Y28,2)+GX28 -> 2010.18 | GN28: =IF(OR(BI28=0,BI28=1),GM28-GX28,0) -> 0 | GO28: =IF(BI28=2,GM28-GX28,0) -> 2010.18 | GP28: =IF(BI28=4,GM28-GX28,0) -> 0 | GR28: 0 | GS28: 3 | GT28: 0 | GV28: =ROUND((GT28),6) -> 0 | GW28: 1 | GX28: =ROUND(HC28*I28,2) -> 0 | HA28: 0 | HB28: 0 | HC28: =GV28*GW28 -> 0 | HS28: 0 | IK28: 0
A29: 17 | B29: 1 | C29: =ROW(SmtRes!A12) -> 12 | D29: =ROW(EtalonRes!A14) -> 14 | E29: 1 | F29: 4.10-174-1 | G29: Монтаж внутренней камеры видеонаблюдения | H29: 10 шт. | I29: =ROUND(28/10,9) -> 2.8 | J29: 0 | K29: =ROUND(28/10,9) -> 2.8 | O29: =ROUND(CP29,2) -> 44191.05 | P29: =ROUND((ROUND((AC29*AW29*I29),2)*BC29),2) -> 229.73 | Q29: =(ROUND((ROUND((((ET29*1.1))*AV29*I29),2)*BB29),2)+ROUND((ROUND(((AE29-((EU29*1.1)))*AV29*I29),2)*BS29),2)) -> 86.45 | R29: =(ROUND((ROUND((((EU29*1.1))*AV29*I29),2)*BS29),2)+ROUND((ROUND(((AE29-((EU29*1.1)))*AV29*I29),2)*BS29),2)) -> 23.1 | S29: =ROUND((ROUND((AF29*AV29*I29),2)*BA29),2) -> 43874.87 | T29: =ROUND(CU29*I29,2) -> 0 | U29: =CV29*I29 -> 50.11277 | V29: =CW29*I29 -> 0 | W29: =ROUND(CX29*I29,2) -> 0 | X29: =(ROUND((((S29+ROUND((ROUND((((EU29*1.1))*AV29*I29),2)*BS29),2))*AT29)/100),2)+ROUND(((ROUND((ROUND(((AE29-((EU29*1.1)))*AV29*I29),2)*BS29),2)*AT29)/100),2)) -> 39508.17 | Y29: =(ROUND((((S29+ROUND((ROUND((((EU29*1.1))*AV29*I29),2)*BS29),2))*AU29)/100),2)+ROUND(((ROUND((ROUND(((AE29-((EU29*1.1)))*AV29*I29),2)*BS29),2)*AU29)/100),2)) -> 20193.07 | AA29: 60258061 | AB29: =ROUND((AC29+AD29+AF29),6) -> 317.268 | AC29: =ROUND((ES29),6) -> 42.51 | AD29: =ROUND(((((ET29*1.1))-((EU29*1.1)))+AE29),6) -> 2.596 | AE29: =ROUND(((EU29*1.1)),6) -> 0.143 | AF29: =ROUND(((EV29*1.1)),6) -> 272.162 | AG29: =ROUND((AP29),6) -> 0 | AH29: =((EW29*1.1)) -> 17.094 | AI29: =((EX29*1.1)) -> 0 | AJ29: =(AS29) -> 0 | AK29: 292.29 | AL29: 42.51 | AM29: 2.36 | AN29: 0.13 | AO29: 247.42 | AP29: 0 | AQ29: 15.54 | AR29: 0 | AS29: 0 | AT29: 90 | AU29: 46 | AV29: 1.047 | AW29: 1 | AZ29: 1 | BA29: 54.99 | BB29: 11.36 | BC29: 1.93 | BH29: 0 | BI29: 2 | BJ29: ТСН-2001.4 Доп. 68, Сб. 10, т. 174, поз. 1 | BM29: 68 | BN29: 58973116 | BO29: 4.10-174-1 | BP29: 1 | BQ29: 40 | BR29: 0 | BS29: 54.99 | BT29: 1 | BU29: 1 | BV29: 1 | BW29: 1 | BX29: 1 | BZ29: 90 | CA29: 46 | CE29: 1566 | CF29: 0 | CG29: 0 | CM29: 0 | CN29: Поправка: О.П. п.3.4.30.в Наименование: При применении территориальных сметных нормативов для города Москвы затраты, учитывающие напряженные и стесненные условия производства работ (стесненность, сложность складирования и транспортной логистики и т.п.), исчисляются с применением коэффициентов к затратам труда и заработной плате рабочих, машинистов, времени эксплуатации машин и механизмов, стоимости эксплуатации машин в размере: для объектов, расположенных за пределами Третьего транспортного кольца города Москвы, но в пределах Московской кольцевой автомобильной дороги | CO29: 0 | CP29: =(P29+Q29+S29) -> 44191.05 | CQ29: =ROUND((ROUND((AC29*AW29*1),2)*BC29),2) -> 82.04 | CR29: =(ROUND((ROUND((((ET29*1.1))*AV29*1),2)*BB29),2)+ROUND((ROUND(((AE29-((EU29*1.1)))*AV29*1),2)*BS29),2)) -> 30.9 | CS29: =(ROUND((ROUND((((EU29*1.1))*AV29*1),2)*BS29),2)+ROUND((ROUND(((AE29-((EU29*1.1)))*AV29*1),2)*BS29),2)) -> 8.25 | CT29: =ROUND((ROUND((AF29*AV29*1),2)*BA29),2) -> 15669.4 | CU29: =AG29 -> 0 | CV29: =(AH29*AV29) -> 17.897418 | CW29: =AI29 -> 0 | CX29: =AJ29 -> 0 | CY29: =(ROUND((((S29+ROUND((ROUND((((EU29*1.1))*AV29*1),2)*BS29),2))*AT29)/100),2)+ROUND(((ROUND((ROUND(((AE29-((EU29*1.1)))*AV29*1),2)*BS29),2)*AT29)/100),2)) -> 39494.81 | CZ29: =(ROUND((((S29+ROUND((ROUND((((EU29*1.1))*AV29*1),2)*BS29),2))*AU29)/100),2)+ROUND(((ROUND((ROUND(((AE29-((EU29*1.1)))*AV29*1),2)*BS29),2)*AU29)/100),2)) -> 20186.24 | DB29: 2 | DE29: *1,1 | DF29: *1,1 | DG29: *1,1 | DI29: *1,1 | DJ29: *1,1 | DN29: 0 | DO29: 0 | DP29: 1 | DQ29: 1 | DU29: 1010 | DV29: 10 шт. | DW29: 10 шт. | DX29: 10 | EE29: 60088532 | EF29: 40 | EG29: Монтаж оборудования | EH29: 0 | EJ29: 2 | EK29: 68 | EL29: ТСН-2001.4-10. Прокладка и монтаж сетей связи | EM29: ТСН-2001.4-10-1 | EO29: Поправка: О.П. п.3.4.30.в | EQ29: 0 | ER29: 292.29 | ES29: 42.51 | ET29: 2.36 | EU29: 0.13 | EV29: 247.42 | EW29: 15.54 | EX29: 0 | EY29: 0 | FQ29: 0 | FR29: 0 | FS29: 0 | FX29: 90 | FY29: 46 | GD29: 1 | GF29: -1957665847 | GG29: 2 | GH29: 1 | GI29: 2 | GJ29: 0 | GK29: 0 | GL29: =ROUND(IF(AND(BH29=3,BI29=3,FS29<>0),P29,0),2) -> 0 | GM29: =ROUND(O29+X29+Y29,2)+GX29 -> 103892.29 | GN29: =IF(OR(BI29=0,BI29=1),GM29-GX29,0) -> 0 | GO29: =IF(BI29=2,GM29-GX29,0) -> 103892.29 | GP29: =IF(BI29=4,GM29-GX29,0) -> 0 | GR29: 0 | GS29: 3 | GT29: 0 | GV29: =ROUND((GT29),6) -> 0 | GW29: 1 | GX29: =ROUND(HC29*I29,2) -> 0 | HA29: 0 | HB29: 0 | HC29: =GV29*GW29 -> 0 | HS29: 0 | IK29: 0
A30: 17 | B30: 1 | E30: 2 | F30: КА-1 | G30: Цилиндрическая IP-видеокамера с фиксированным объективом IP 2 Мп; 1/3" КМОП, 1920х1080-25/30к/с; встроенный микрофон; Дальность ИК подсветки 30м; объектив 2.8мм(3.6мм, 6ммопционально) ; режим "день/ночь", H264/ MJPEG ( Доп. поток) ; ; PoE 5 Вт; -40 ~ +60°C, TR-D2121CL3 4.0 | H30: ШТ | I30: 28 | J30: 0 | K30: 28 | O30: =ROUND(CP30,2) -> 28309.68 | P30: =ROUND((ROUND((AC30*I30),2)*BC30),2) -> 28309.68 | Q30: =(ROUND((ROUND(((ET30)*AV30*I30),2)*BB30),2)+ROUND((ROUND(((AE30-(EU30))*AV30*I30),2)*BS30),2)) -> 0 | R30: =(ROUND((ROUND(((EU30)*AV30*I30),2)*BS30),2)+ROUND((ROUND(((AE30-(EU30))*AV30*I30),2)*BS30),2)) -> 0 | S30: =ROUND((ROUND((AF30*AV30*I30),2)*BA30),2) -> 0 | T30: =ROUND(CU30*I30,2) -> 0 | U30: =CV30*I30 -> 0 | V30: =CW30*I30 -> 0 | W30: =ROUND(CX30*I30,2) -> 0 | X30: =(ROUND((((S30+ROUND((ROUND(((EU30)*AV30*I30),2)*BS30),2))*AT30)/100),2)+ROUND(((ROUND((ROUND(((AE30-(EU30))*AV30*I30),2)*BS30),2)*AT30)/100),2)) -> 0 | Y30: =(ROUND((((S30+ROUND((ROUND(((EU30)*AV30*I30),2)*BS30),2))*AU30)/100),2)+ROUND(((ROUND((ROUND(((AE30-(EU30))*AV30*I30),2)*BS30),2)*AU30)/100),2)) -> 0 | AA30: 60258064 | AB30: =ROUND((AC30+AD30+AF30),6) -> 1011.06 | AC30: =ROUND((ES30),6) -> 1011.06 | AD30: =ROUND((((ET30)-(EU30))+AE30),6) -> 0 | AE30: =ROUND((EU30),6) -> 0 | AF30: =ROUND((EV30),6) -> 0 | AG30: =ROUND((AP30),6) -> 0 | AH30: =(EW30) -> 0 | AI30: =(EX30) -> 0 | AJ30: =(AS30) -> 0 | AK30: 1011.06 | AL30: 1011.06 | AM30: 0 | AN30: 0 | AO30: 0 | AP30: 0 | AQ30: 0 | AR30: 0 | AS30: 0 | AT30: 0 | AU30: 0 | AV30: 1 | AW30: 1 | AZ30: 1 | BA30: 1 | BB30: 1 | BC30: 1 | BH30: 3 | BI30: 3 | BM30: 746 | BN30: 0 | BP30: 0 | BQ30: 130 | BR30: 0 | BS30: 1 | BT30: 1 | BU30: 1 | BV30: 1 | BW30: 1 | BX30: 1 | BZ30: 0 | CA30: 0 | CE30: 1566 | CF30: 0 | CG30: 0 | CM30: 0 | CO30: 0 | CP30: =(P30+Q30+S30) -> 28309.68 | CQ30: =ROUND((ROUND((AC30*1),2)*BC30),2) -> 1011.06 | CR30: =(ROUND((ROUND(((ET30)*AV30*1),2)*BB30),2)+ROUND((ROUND(((AE30-(EU30))*AV30*1),2)*BS30),2)) -> 0 | CS30: =(ROUND((ROUND(((EU30)*AV30*1),2)*BS30),2)+ROUND((ROUND(((AE30-(EU30))*AV30*1),2)*BS30),2)) -> 0 | CT30: =ROUND((ROUND((AF30*AV30*1),2)*BA30),2) -> 0 | CU30: =AG30 -> 0 | CV30: =(AH30*AV30) -> 0 | CW30: =AI30 -> 0 | CX30: =AJ30 -> 0 | CY30: =(ROUND((((S30+ROUND((ROUND(((EU30)*AV30*1),2)*BS30),2))*AT30)/100),2)+ROUND(((ROUND((ROUND(((AE30-(EU30))*AV30*1),2)*BS30),2)*AT30)/100),2)) -> 0 | CZ30: =(ROUND((((S30+ROUND((ROUND(((EU30)*AV30*1),2)*BS30),2))*AU30)/100),2)+ROUND(((ROUND((ROUND(((AE30-(EU30))*AV30*1),2)*BS30),2)*AU30)/100),2)) -> 0 | DN30: 0 | DO30: 0 | DP30: 1 | DQ30: 1 | DU30: 1013 | DV30: ШТ | DW30: ШТ | DX30: 1 | EE30: 60088638 | EF30: 130 | EG30: Сметная стоимость оборудования | EH30: 0 | EJ30: 3 | EK30: 746 | EL30: ТСН-2001.13. Сметная стоимость оборудования | EM30: ТСН-2001.13 | EQ30: 0 | ER30: 0 | ES30: 1011.06 | ET30: 0 | EU30: 0 | EV30: 0 | EW30: 0 | EX30: 0 | EY30: 0 | FQ30: 0 | FR30: =P30 -> 28309.68 | FS30: 0 | FX30: 0 | FY30: 0 | GA30: [8 916 / 1,2 / 7,66] + 3% Трансп + 1,2% Заг.скл | GD30: 1 | GF30: -1132090366 | GG30: 2 | GH30: 4 | GI30: -2 | GJ30: 0 | GK30: 0 | GL30: =ROUND(IF(AND(BH30=3,BI30=3,FS30<>0),P30,0),2) -> 0 | GM30: =ROUND(O30+X30+Y30,2)+GX30 -> 28309.68 | GN30: =IF(OR(BI30=0,BI30=1),GM30-GX30,0) -> 0 | GO30: =IF(BI30=2,GM30-GX30,0) -> 0 | GP30: =IF(BI30=4,GM30-GX30,0) -> 0 | GR30: 0 | GS30: 2 | GT30: 0 | GV30: =ROUND((GT30),6) -> 0 | GW30: 1 | GX30: =ROUND(HC30*I30,2) -> 0 | HA30: 0 | HB30: 0 | HC30: =GV30*GW30 -> 0 | HE30: 3 | HF30: 1,2 | HS30: 0 | IK30: 0
A31: 17 | B31: 1 | E31: 2 | F31: КА-1 | G31: Цилиндрическая IP-видеокамера с фиксированным объективом IP 2 Мп; 1/3" КМОП, 1920х1080-25/30к/с; встроенный микрофон; Дальность ИК подсветки 30м; объектив 2.8мм(3.6мм, 6ммопционально) ; режим "день/ночь", H264/ MJPEG ( Доп. поток) ; ; PoE 5 Вт; -40 ~ +60°C, TR-D2121CL3 4.0 | H31: ШТ | I31: 28 | J31: 0 | K31: 28 | O31: =ROUND(CP31,2) -> 216852.15 | P31: =ROUND((ROUND((AC31*I31),2)*BC31),2) -> 216852.15 | Q31: =(ROUND((ROUND(((ET31)*AV31*I31),2)*BB31),2)+ROUND((ROUND(((AE31-(EU31))*AV31*I31),2)*BS31),2)) -> 0 | R31: =(ROUND((ROUND(((EU31)*AV31*I31),2)*BS31),2)+ROUND((ROUND(((AE31-(EU31))*AV31*I31),2)*BS31),2)) -> 0 | S31: =ROUND((ROUND((AF31*AV31*I31),2)*BA31),2) -> 0 | T31: =ROUND(CU31*I31,2) -> 0 | U31: =CV31*I31 -> 0 | V31: =CW31*I31 -> 0 | W31: =ROUND(CX31*I31,2) -> 0 | X31: =(ROUND((((S31+ROUND((ROUND(((EU31)*AV31*I31),2)*BS31),2))*AT31)/100),2)+ROUND(((ROUND((ROUND(((AE31-(EU31))*AV31*I31),2)*BS31),2)*AT31)/100),2)) -> 0 | Y31: =(ROUND((((S31+ROUND((ROUND(((EU31)*AV31*I31),2)*BS31),2))*AU31)/100),2)+ROUND(((ROUND((ROUND(((AE31-(EU31))*AV31*I31),2)*BS31),2)*AU31)/100),2)) -> 0 | AA31: 60258061 | AB31: =ROUND((AC31+AD31+AF31),6) -> 1011.06 | AC31: =ROUND((ES31),6) -> 1011.06 | AD31: =ROUND((((ET31)-(EU31))+AE31),6) -> 0 | AE31: =ROUND((EU31),6) -> 0 | AF31: =ROUND((EV31),6) -> 0 | AG31: =ROUND((AP31),6) -> 0 | AH31: =(EW31) -> 0 | AI31: =(EX31) -> 0 | AJ31: =(AS31) -> 0 | AK31: 1011.06 | AL31: 1011.06 | AM31: 0 | AN31: 0 | AO31: 0 | AP31: 0 | AQ31: 0 | AR31: 0 | AS31: 0 | AT31: 0 | AU31: 0 | AV31: 1 | AW31: 1 | AZ31: 1 | BA31: 1 | BB31: 1 | BC31: 7.66 | BH31: 3 | BI31: 3 | BM31: 746 | BN31: 0 | BP31: 0 | BQ31: 130 | BR31: 0 | BS31: 1 | BT31: 1 | BU31: 1 | BV31: 1 | BW31: 1 | BX31: 1 | BZ31: 0 | CA31: 0 | CE31: 1566 | CF31: 0 | CG31: 0 | CM31: 0 | CO31: 0 | CP31: =(P31+Q31+S31) -> 216852.15 | CQ31: =ROUND((ROUND((AC31*1),2)*BC31),2) -> 7744.72 | CR31: =(ROUND((ROUND(((ET31)*AV31*1),2)*BB31),2)+ROUND((ROUND(((AE31-(EU31))*AV31*1),2)*BS31),2)) -> 0 | CS31: =(ROUND((ROUND(((EU31)*AV31*1),2)*BS31),2)+ROUND((ROUND(((AE31-(EU31))*AV31*1),2)*BS31),2)) -> 0 | CT31: =ROUND((ROUND((AF31*AV31*1),2)*BA31),2) -> 0 | CU31: =AG31 -> 0 | CV31: =(AH31*AV31) -> 0 | CW31: =AI31 -> 0 | CX31: =AJ31 -> 0 | CY31: =(ROUND((((S31+ROUND((ROUND(((EU31)*AV31*1),2)*BS31),2))*AT31)/100),2)+ROUND(((ROUND((ROUND(((AE31-(EU31))*AV31*1),2)*BS31),2)*AT31)/100),2)) -> 0 | CZ31: =(ROUND((((S31+ROUND((ROUND(((EU31)*AV31*1),2)*BS31),2))*AU31)/100),2)+ROUND(((ROUND((ROUND(((AE31-(EU31))*AV31*1),2)*BS31),2)*AU31)/100),2)) -> 0 | DN31: 0 | DO31: 0 | DP31: 1 | DQ31: 1 | DU31: 1013 | DV31: ШТ | DW31: ШТ | DX31: 1 | EE31: 60088638 | EF31: 130 | EG31: Сметная стоимость оборудования | EH31: 0 | EJ31: 3 | EK31: 746 | EL31: ТСН-2001.13. Сметная стоимость оборудования | EM31: ТСН-2001.13 | EQ31: 0 | ER31: 0 | ES31: 1011.06 | ET31: 0 | EU31: 0 | EV31: 0 | EW31: 0 | EX31: 0 | EY31: 0 | EZ31: 5 | FC31: 1 | FD31: 18 | FF31: 8916 | FQ31: 0 | FR31: =P31 -> 216852.15 | FS31: 0 | FX31: 0 | FY31: 0 | GA31: [8 916 / 1,2 / 7,66] + 3% Трансп + 1,2% Заг.скл | GD31: 1 | GF31: -1132090366 | GG31: 2 | GH31: 3 | GI31: 5 | GJ31: 0 | GK31: 0 | GL31: =ROUND(IF(AND(BH31=3,BI31=3,FS31<>0),P31,0),2) -> 0 | GM31: =ROUND(O31+X31+Y31,2)+GX31 -> 216852.15 | GN31: =IF(OR(BI31=0,BI31=1),GM31-GX31,0) -> 0 | GO31: =IF(BI31=2,GM31-GX31,0) -> 0 | GP31: =IF(BI31=4,GM31-GX31,0) -> 0 | GR31: 1 | GS31: 1 | GT31: 0 | GV31: =ROUND((GT31),6) -> 0 | GW31: 1 | GX31: =ROUND(HC31*I31,2) -> 0 | HA31: 0 | HB31: 0 | HC31: =GV31*GW31 -> 0 | HE31: 3 | HF31: 1,2 | HS31: 0 | IK31: 0
A32: 17 | B32: 1 | C32: =ROW(SmtRes!A13) -> 13 | D32: =ROW(EtalonRes!A15) -> 15 | E32: 3 | F32: 4.10-136-1 | G32: Разные устройства, монтаж коробки телевизионной (ответвители, разветвители магистральные, домовые, абонентские), УСС, БФТК | H32: 1 ШТ. | I32: 28 | J32: 0 | K32: 28 | O32: =ROUND(CP32,2) -> 377.07 | P32: =ROUND((ROUND((AC32*AW32*I32),2)*BC32),2) -> 8.12 | Q32: =(ROUND((ROUND((((ET32*1.1))*AV32*I32),2)*BB32),2)+ROUND((ROUND(((AE32-((EU32*1.1)))*AV32*I32),2)*BS32),2)) -> 0 | R32: =(ROUND((ROUND((((EU32*1.1))*AV32*I32),2)*BS32),2)+ROUND((ROUND(((AE32-((EU32*1.1)))*AV32*I32),2)*BS32),2)) -> 0 | S32: =ROUND((ROUND((AF32*AV32*I32),2)*BA32),2) -> 368.95 | T32: =ROUND(CU32*I32,2) -> 0 | U32: =CV32*I32 -> 26.78368 | V32: =CW32*I32 -> 0 | W32: =ROUND(CX32*I32,2) -> 0 | X32: =(ROUND((((S32+ROUND((ROUND((((EU32*1.1))*AV32*I32),2)*BS32),2))*AT32)/100),2)+ROUND(((ROUND((ROUND(((AE32-((EU32*1.1)))*AV32*I32),2)*BS32),2)*AT32)/100),2)) -> 350.5 | Y32: =(ROUND((((S32+ROUND((ROUND((((EU32*1.1))*AV32*I32),2)*BS32),2))*AU32)/100),2)+ROUND(((ROUND((ROUND(((AE32-((EU32*1.1)))*AV32*I32),2)*BS32),2)*AU32)/100),2)) -> 195.54 | AA32: 60258064 | AB32: =ROUND((AC32+AD32+AF32),6) -> 12.412 | AC32: =ROUND((ES32),6) -> 0.29 | AD32: =ROUND(((((ET32*1.1))-((EU32*1.1)))+AE32),6) -> 0 | AE32: =ROUND(((EU32*1.1)),6) -> 0 | AF32: =ROUND(((EV32*1.1)),6) -> 12.122 | AG32: =ROUND((AP32),6) -> 0 | AH32: =((EW32*1.1)) -> 0.88 | AI32: =((EX32*1.1)) -> 0 | AJ32: =(AS32) -> 0 | AK32: 11.31 | AL32: 0.29 | AM32: 0 | AN32: 0 | AO32: 11.02 | AP32: 0 | AQ32: 0.8 | AR32: 0 | AS32: 0 | AT32: 95 | AU32: 53 | AV32: 1.087 | AW32: 1 | AZ32: 1 | BA32: 1 | BB32: 1 | BC32: 1 | BH32: 0 | BI32: 2 | BJ32: ТСН-2001.4. Доп. 1-42. Сб. 10, т. 136, поз. 1 | BM32: 69 | BN32: 58973116 | BO32: 4.10-136-1 | BP32: 1 | BQ32: 40 | BR32: 0 | BS32: 1 | BT32: 1 | BU32: 1 | BV32: 1 | BW32: 1 | BX32: 1 | BZ32: 95 | CA32: 53 | CE32: 1566 | CF32: 0 | CG32: 0 | CM32: 0 | CN32: Поправка: О.П. п.3.4.30.в Наименование: При применении территориальных сметных нормативов для города Москвы затраты, учитывающие напряженные и стесненные условия производства работ (стесненность, сложность складирования и транспортной логистики и т.п.), исчисляются с применением коэффициентов к затратам труда и заработной плате рабочих, машинистов, времени эксплуатации машин и механизмов, стоимости эксплуатации машин в размере: для объектов, расположенных за пределами Третьего транспортного кольца города Москвы, но в пределах Московской кольцевой автомобильной дороги | CO32: 0 | CP32: =(P32+Q32+S32) -> 377.07 | CQ32: =ROUND((ROUND((AC32*AW32*1),2)*BC32),2) -> 0.29 | CR32: =(ROUND((ROUND((((ET32*1.1))*AV32*1),2)*BB32),2)+ROUND((ROUND(((AE32-((EU32*1.1)))*AV32*1),2)*BS32),2)) -> 0 | CS32: =(ROUND((ROUND((((EU32*1.1))*AV32*1),2)*BS32),2)+ROUND((ROUND(((AE32-((EU32*1.1)))*AV32*1),2)*BS32),2)) -> 0 | CT32: =ROUND((ROUND((AF32*AV32*1),2)*BA32),2) -> 13.18 | CU32: =AG32 -> 0 | CV32: =(AH32*AV32) -> 0.95656 | CW32: =AI32 -> 0 | CX32: =AJ32 -> 0 | CY32: =(ROUND((((S32+ROUND((ROUND((((EU32*1.1))*AV32*1),2)*BS32),2))*AT32)/100),2)+ROUND(((ROUND((ROUND(((AE32-((EU32*1.1)))*AV32*1),2)*BS32),2)*AT32)/100),2)) -> 350.5 | CZ32: =(ROUND((((S32+ROUND((ROUND((((EU32*1.1))*AV32*1),2)*BS32),2))*AU32)/100),2)+ROUND(((ROUND((ROUND(((AE32-((EU32*1.1)))*AV32*1),2)*BS32),2)*AU32)/100),2)) -> 195.54 | DB32: 3 | DE32: *1,1 | DF32: *1,1 | DG32: *1,1 | DI32: *1,1 | DJ32: *1,1 | DN32: 0 | DO32: 0 | DP32: 1 | DQ32: 1 | DU32: 1013 | DV32: 1 ШТ. | DW32: 1 ШТ. | DX32: 1 | EE32: 60088533 | EF32: 40 | EG32: Монтаж оборудования | EH32: 0 | EJ32: 2 | EK32: 69 | EL32: ТСН-2001.4-10. Монтаж радиотелевизионного и электронного оборудования | EM32: ТСН-2001.4-10-2 | EO32: Поправка: О.П. п.3.4.30.в | EQ32: 0 | ER32: 11.31 | ES32: 0.29 | ET32: 0 | EU32: 0 | EV32: 11.02 | EW32: 0.8 | EX32: 0 | EY32: 0 | FQ32: 0 | FR32: 0 | FS32: 0 | FX32: 95 | FY32: 53 | GD32: 1 | GF32: 105814318 | GG32: 2 | GH32: 1 | GI32: 2 | GJ32: 0 | GK32: 0 | GL32: =ROUND(IF(AND(BH32=3,BI32=3,FS32<>0),P32,0),2) -> 0 | GM32: =ROUND(O32+X32+Y32,2)+GX32 -> 923.11 | GN32: =IF(OR(BI32=0,BI32=1),GM32-GX32,0) -> 0 | GO32: =IF(BI32=2,GM32-GX32,0) -> 923.11 | GP32: =IF(BI32=4,GM32-GX32,0) -> 0 | GR32: 0 | GS32: 3 | GT32: 0 | GV32: =ROUND((GT32),6) -> 0 | GW32: 1 | GX32: =ROUND(HC32*I32,2) -> 0 | HA32: 0 | HB32: 0 | HC32: =GV32*GW32 -> 0 | HS32: 0 | IK32: 0
A33: 17 | B33: 1 | C33: =ROW(SmtRes!A14) -> 14 | D33: =ROW(EtalonRes!A16) -> 16 | E33: 3 | F33: 4.10-136-1 | G33: Разные устройства, монтаж коробки телевизионной (ответвители, разветвители магистральные, домовые, абонентские), УСС, БФТК | H33: 1 ШТ. | I33: 28 | J33: 0 | K33: 28 | O33: =ROUND(CP33,2) -> 20368.95 | P33: =ROUND((ROUND((AC33*AW33*I33),2)*BC33),2) -> 80.39 | Q33: =(ROUND((ROUND((((ET33*1.1))*AV33*I33),2)*BB33),2)+ROUND((ROUND(((AE33-((EU33*1.1)))*AV33*I33),2)*BS33),2)) -> 0 | R33: =(ROUND((ROUND((((EU33*1.1))*AV33*I33),2)*BS33),2)+ROUND((ROUND(((AE33-((EU33*1.1)))*AV33*I33),2)*BS33),2)) -> 0 | S33: =ROUND((ROUND((AF33*AV33*I33),2)*BA33),2) -> 20288.56 | T33: =ROUND(CU33*I33,2) -> 0 | U33: =CV33*I33 -> 26.78368 | V33: =CW33*I33 -> 0 | W33: =ROUND(CX33*I33,2) -> 0 | X33: =(ROUND((((S33+ROUND((ROUND((((EU33*1.1))*AV33*I33),2)*BS33),2))*AT33)/100),2)+ROUND(((ROUND((ROUND(((AE33-((EU33*1.1)))*AV33*I33),2)*BS33),2)*AT33)/100),2)) -> 19274.13 | Y33: =(ROUND((((S33+ROUND((ROUND((((EU33*1.1))*AV33*I33),2)*BS33),2))*AU33)/100),2)+ROUND(((ROUND((ROUND(((AE33-((EU33*1.1)))*AV33*I33),2)*BS33),2)*AU33)/100),2)) -> 10752.94 | AA33: 60258061 | AB33: =ROUND((AC33+AD33+AF33),6) -> 12.412 | AC33: =ROUND((ES33),6) -> 0.29 | AD33: =ROUND(((((ET33*1.1))-((EU33*1.1)))+AE33),6) -> 0 | AE33: =ROUND(((EU33*1.1)),6) -> 0 | AF33: =ROUND(((EV33*1.1)),6) -> 12.122 | AG33: =ROUND((AP33),6) -> 0 | AH33: =((EW33*1.1)) -> 0.88 | AI33: =((EX33*1.1)) -> 0 | AJ33: =(AS33) -> 0 | AK33: 11.31 | AL33: 0.29 | AM33: 0 | AN33: 0 | AO33: 11.02 | AP33: 0 | AQ33: 0.8 | AR33: 0 | AS33: 0 | AT33: 95 | AU33: 53 | AV33: 1.087 | AW33: 1 | AZ33: 1 | BA33: 54.99 | BB33: 1 | BC33: 9.9 | BH33: 0 | BI33: 2 | BJ33: ТСН-2001.4. Доп. 1-42. Сб. 10, т. 136, поз. 1 | BM33: 69 | BN33: 58973116 | BO33: 4.10-136-1 | BP33: 1 | BQ33: 40 | BR33: 0 | BS33: 54.99 | BT33: 1 | BU33: 1 | BV33: 1 | BW33: 1 | BX33: 1 | BZ33: 95 | CA33: 53 | CE33: 1566 | CF33: 0 | CG33: 0 | CM33: 0 | CN33: Поправка: О.П. п.3.4.30.в Наименование: При применении территориальных сметных нормативов для города Москвы затраты, учитывающие напряженные и стесненные условия производства работ (стесненность, сложность складирования и транспортной логистики и т.п.), исчисляются с применением коэффициентов к затратам труда и заработной плате рабочих, машинистов, времени эксплуатации машин и механизмов, стоимости эксплуатации машин в размере: для объектов, расположенных за пределами Третьего транспортного кольца города Москвы, но в пределах Московской кольцевой автомобильной дороги | CO33: 0 | CP33: =(P33+Q33+S33) -> 20368.95 | CQ33: =ROUND((ROUND((AC33*AW33*1),2)*BC33),2) -> 2.87 | CR33: =(ROUND((ROUND((((ET33*1.1))*AV33*1),2)*BB33),2)+ROUND((ROUND(((AE33-((EU33*1.1)))*AV33*1),2)*BS33),2)) -> 0 | CS33: =(ROUND((ROUND((((EU33*1.1))*AV33*1),2)*BS33),2)+ROUND((ROUND(((AE33-((EU33*1.1)))*AV33*1),2)*BS33),2)) -> 0 | CT33: =ROUND((ROUND((AF33*AV33*1),2)*BA33),2) -> 724.77 | CU33: =AG33 -> 0 | CV33: =(AH33*AV33) -> 0.95656 | CW33: =AI33 -> 0 | CX33: =AJ33 -> 0 | CY33: =(ROUND((((S33+ROUND((ROUND((((EU33*1.1))*AV33*1),2)*BS33),2))*AT33)/100),2)+ROUND(((ROUND((ROUND(((AE33-((EU33*1.1)))*AV33*1),2)*BS33),2)*AT33)/100),2)) -> 19274.13 | CZ33: =(ROUND((((S33+ROUND((ROUND((((EU33*1.1))*AV33*1),2)*BS33),2))*AU33)/100),2)+ROUND(((ROUND((ROUND(((AE33-((EU33*1.1)))*AV33*1),2)*BS33),2)*AU33)/100),2)) -> 10752.94 | DB33: 4 | DE33: *1,1 | DF33: *1,1 | DG33: *1,1 | DI33: *1,1 | DJ33: *1,1 | DN33: 0 | DO33: 0 | DP33: 1 | DQ33: 1 | DU33: 1013 | DV33: 1 ШТ. | DW33: 1 ШТ. | DX33: 1 | EE33: 60088533 | EF33: 40 | EG33: Монтаж оборудования | EH33: 0 | EJ33: 2 | EK33: 69 | EL33: ТСН-2001.4-10. Монтаж радиотелевизионного и электронного оборудования | EM33: ТСН-2001.4-10-2 | EO33: Поправка: О.П. п.3.4.30.в | EQ33: 0 | ER33: 11.31 | ES33: 0.29 | ET33: 0 | EU33: 0 | EV33: 11.02 | EW33: 0.8 | EX33: 0 | EY33: 0 | FQ33: 0 | FR33: 0 | FS33: 0 | FX33: 95 | FY33: 53 | GD33: 1 | GF33: 105814318 | GG33: 2 | GH33: 1 | GI33: 2 | GJ33: 0 | GK33: 0 | GL33: =ROUND(IF(AND(BH33=3,BI33=3,FS33<>0),P33,0),2) -> 0 | GM33: =ROUND(O33+X33+Y33,2)+GX33 -> 50396.02 | GN33: =IF(OR(BI33=0,BI33=1),GM33-GX33,0) -> 0 | GO33: =IF(BI33=2,GM33-GX33,0) -> 50396.02 | GP33: =IF(BI33=4,GM33-GX33,0) -> 0 | GR33: 0 | GS33: 3 | GT33: 0 | GV33: =ROUND((GT33),6) -> 0 | GW33: 1 | GX33: =ROUND(HC33*I33,2) -> 0 | HA33: 0 | HB33: 0 | HC33: =GV33*GW33 -> 0 | HS33: 0 | IK33: 0
A34: 17 | B34: 1 | E34: 4 | F34: КА-2 | G34: Устройство грозозащиты NST NS-LP-1GP/D | H34: ШТ | I34: 28 | J34: 0 | K34: 28 | O34: =ROUND(CP34,2) -> 7826.56 | P34: =ROUND((ROUND((AC34*AW34*I34),2)*BC34),2) -> 7826.56 | Q34: =(ROUND((ROUND(((ET34)*AV34*I34),2)*BB34),2)+ROUND((ROUND(((AE34-(EU34))*AV34*I34),2)*BS34),2)) -> 0 | R34: =(ROUND((ROUND(((EU34)*AV34*I34),2)*BS34),2)+ROUND((ROUND(((AE34-(EU34))*AV34*I34),2)*BS34),2)) -> 0 | S34: =ROUND((ROUND((AF34*AV34*I34),2)*BA34),2) -> 0 | T34: =ROUND(CU34*I34,2) -> 0 | U34: =CV34*I34 -> 0 | V34: =CW34*I34 -> 0 | W34: =ROUND(CX34*I34,2) -> 0 | X34: =(ROUND((((S34+ROUND((ROUND(((EU34)*AV34*I34),2)*BS34),2))*AT34)/100),2)+ROUND(((ROUND((ROUND(((AE34-(EU34))*AV34*I34),2)*BS34),2)*AT34)/100),2)) -> 0 | Y34: =(ROUND((((S34+ROUND((ROUND(((EU34)*AV34*I34),2)*BS34),2))*AU34)/100),2)+ROUND(((ROUND((ROUND(((AE34-(EU34))*AV34*I34),2)*BS34),2)*AU34)/100),2)) -> 0 | AA34: 60258064 | AB34: =ROUND((AC34+AD34+AF34),6) -> 279.52 | AC34: =ROUND((ES34),6) -> 279.52 | AD34: =ROUND((((ET34)-(EU34))+AE34),6) -> 0 | AE34: =ROUND((EU34),6) -> 0 | AF34: =ROUND((EV34),6) -> 0 | AG34: =ROUND((AP34),6) -> 0 | AH34: =(EW34) -> 0 | AI34: =(EX34) -> 0 | AJ34: =(AS34) -> 0 | AK34: 279.52 | AL34: 279.52 | AM34: 0 | AN34: 0 | AO34: 0 | AP34: 0 | AQ34: 0 | AR34: 0 | AS34: 0 | AT34: 0 | AU34: 0 | AV34: 1 | AW34: 1 | AZ34: 1 | BA34: 1 | BB34: 1 | BC34: 1 | BH34: 3 | BI34: 2 | BM34: 400002 | BN34: 0 | BP34: 0 | BQ34: 202 | BR34: 0 | BS34: 1 | BT34: 1 | BU34: 1 | BV34: 1 | BW34: 1 | BX34: 1 | BZ34: 0 | CA34: 0 | CE34: 1566 | CF34: 0 | CG34: 0 | CM34: 0 | CO34: 0 | CP34: =(P34+Q34+S34) -> 7826.56 | CQ34: =ROUND((ROUND((AC34*AW34*1),2)*BC34),2) -> 279.52 | CR34: =(ROUND((ROUND(((ET34)*AV34*1),2)*BB34),2)+ROUND((ROUND(((AE34-(EU34))*AV34*1),2)*BS34),2)) -> 0 | CS34: =(ROUND((ROUND(((EU34)*AV34*1),2)*BS34),2)+ROUND((ROUND(((AE34-(EU34))*AV34*1),2)*BS34),2)) -> 0 | CT34: =ROUND((ROUND((AF34*AV34*1),2)*BA34),2) -> 0 | CU34: =AG34 -> 0 | CV34: =(AH34*AV34) -> 0 | CW34: =AI34 -> 0 | CX34: =AJ34 -> 0 | CY34: =(ROUND((((S34+ROUND((ROUND(((EU34)*AV34*1),2)*BS34),2))*AT34)/100),2)+ROUND(((ROUND((ROUND(((AE34-(EU34))*AV34*1),2)*BS34),2)*AT34)/100),2)) -> 0 | CZ34: =(ROUND((((S34+ROUND((ROUND(((EU34)*AV34*1),2)*BS34),2))*AU34)/100),2)+ROUND(((ROUND((ROUND(((AE34-(EU34))*AV34*1),2)*BS34),2)*AU34)/100),2)) -> 0 | DN34: 0 | DO34: 0 | DP34: 1 | DQ34: 1 | DU34: 1013 | DV34: ШТ | DW34: ШТ | DX34: 1 | EE34: 60088644 | EF34: 202 | EG34: Материалы | EH34: 0 | EJ34: 1 | EK34: 400002 | EL34: Материалы, изделия и конструкции | EM34: Материалы | EQ34: 0 | ER34: 0 | ES34: 279.52 | ET34: 0 | EU34: 0 | EV34: 0 | EW34: 0 | EX34: 0 | EY34: 0 | FQ34: 0 | FR34: 0 | FS34: 0 | FX34: 0 | FY34: 0 | GA34: [3 249 / 1,2 / 9,88] + 2% Заг.скл | GD34: 1 | GF34: 1071266394 | GG34: 2 | GH34: 4 | GI34: -2 | GJ34: 0 | GK34: 0 | GL34: =ROUND(IF(AND(BH34=3,BI34=3,FS34<>0),P34,0),2) -> 0 | GM34: =ROUND(O34+X34+Y34,2)+GX34 -> 7826.56 | GN34: =IF(OR(BI34=0,BI34=1),GM34-GX34,0) -> 0 | GO34: =IF(BI34=2,GM34-GX34,0) -> 7826.56 | GP34: =IF(BI34=4,GM34-GX34,0) -> 0 | GR34: 0 | GS34: 2 | GT34: 0 | GV34: =ROUND((GT34),6) -> 0 | GW34: 1 | GX34: =ROUND(HC34*I34,2) -> 0 | HA34: 0 | HB34: 0 | HC34: =GV34*GW34 -> 0 | HE34: 0 | HF34: 2 | HS34: 0 | IK34: 0
A35: 17 | B35: 1 | E35: 4 | F35: КА-2 | G35: Устройство грозозащиты NST NS-LP-1GP/D | H35: ШТ | I35: 28 | J35: 0 | K35: 28 | O35: =ROUND(CP35,2) -> 77326.41 | P35: =ROUND((ROUND((AC35*AW35*I35),2)*BC35),2) -> 77326.41 | Q35: =(ROUND((ROUND(((ET35)*AV35*I35),2)*BB35),2)+ROUND((ROUND(((AE35-(EU35))*AV35*I35),2)*BS35),2)) -> 0 | R35: =(ROUND((ROUND(((EU35)*AV35*I35),2)*BS35),2)+ROUND((ROUND(((AE35-(EU35))*AV35*I35),2)*BS35),2)) -> 0 | S35: =ROUND((ROUND((AF35*AV35*I35),2)*BA35),2) -> 0 | T35: =ROUND(CU35*I35,2) -> 0 | U35: =CV35*I35 -> 0 | V35: =CW35*I35 -> 0 | W35: =ROUND(CX35*I35,2) -> 0 | X35: =(ROUND((((S35+ROUND((ROUND(((EU35)*AV35*I35),2)*BS35),2))*AT35)/100),2)+ROUND(((ROUND((ROUND(((AE35-(EU35))*AV35*I35),2)*BS35),2)*AT35)/100),2)) -> 0 | Y35: =(ROUND((((S35+ROUND((ROUND(((EU35)*AV35*I35),2)*BS35),2))*AU35)/100),2)+ROUND(((ROUND((ROUND(((AE35-(EU35))*AV35*I35),2)*BS35),2)*AU35)/100),2)) -> 0 | AA35: 60258061 | AB35: =ROUND((AC35+AD35+AF35),6) -> 279.52 | AC35: =ROUND((ES35),6) -> 279.52 | AD35: =ROUND((((ET35)-(EU35))+AE35),6) -> 0 | AE35: =ROUND((EU35),6) -> 0 | AF35: =ROUND((EV35),6) -> 0 | AG35: =ROUND((AP35),6) -> 0 | AH35: =(EW35) -> 0 | AI35: =(EX35) -> 0 | AJ35: =(AS35) -> 0 | AK35: 279.52 | AL35: 279.52 | AM35: 0 | AN35: 0 | AO35: 0 | AP35: 0 | AQ35: 0 | AR35: 0 | AS35: 0 | AT35: 0 | AU35: 0 | AV35: 1 | AW35: 1 | AZ35: 1 | BA35: 1 | BB35: 1 | BC35: 9.88 | BH35: 3 | BI35: 2 | BM35: 400002 | BN35: 0 | BP35: 0 | BQ35: 202 | BR35: 0 | BS35: 1 | BT35: 1 | BU35: 1 | BV35: 1 | BW35: 1 | BX35: 1 | BZ35: 0 | CA35: 0 | CE35: 1566 | CF35: 0 | CG35: 0 | CM35: 0 | CO35: 0 | CP35: =(P35+Q35+S35) -> 77326.41 | CQ35: =ROUND((ROUND((AC35*AW35*1),2)*BC35),2) -> 2761.66 | CR35: =(ROUND((ROUND(((ET35)*AV35*1),2)*BB35),2)+ROUND((ROUND(((AE35-(EU35))*AV35*1),2)*BS35),2)) -> 0 | CS35: =(ROUND((ROUND(((EU35)*AV35*1),2)*BS35),2)+ROUND((ROUND(((AE35-(EU35))*AV35*1),2)*BS35),2)) -> 0 | CT35: =ROUND((ROUND((AF35*AV35*1),2)*BA35),2) -> 0 | CU35: =AG35 -> 0 | CV35: =(AH35*AV35) -> 0 | CW35: =AI35 -> 0 | CX35: =AJ35 -> 0 | CY35: =(ROUND((((S35+ROUND((ROUND(((EU35)*AV35*1),2)*BS35),2))*AT35)/100),2)+ROUND(((ROUND((ROUND(((AE35-(EU35))*AV35*1),2)*BS35),2)*AT35)/100),2)) -> 0 | CZ35: =(ROUND((((S35+ROUND((ROUND(((EU35)*AV35*1),2)*BS35),2))*AU35)/100),2)+ROUND(((ROUND((ROUND(((AE35-(EU35))*AV35*1),2)*BS35),2)*AU35)/100),2)) -> 0 | DN35: 0 | DO35: 0 | DP35: 1 | DQ35: 1 | DU35: 1013 | DV35: ШТ | DW35: ШТ | DX35: 1 | EE35: 60088644 | EF35: 202 | EG35: Материалы | EH35: 0 | EJ35: 1 | EK35: 400002 | EL35: Материалы, изделия и конструкции | EM35: Материалы | EQ35: 0 | ER35: 0 | ES35: 279.52 | ET35: 0 | EU35: 0 | EV35: 0 | EW35: 0 | EX35: 0 | EY35: 0 | EZ35: 5 | FC35: 1 | FD35: 18 | FF35: 3249 | FQ35: 0 | FR35: 0 | FS35: 0 | FX35: 0 | FY35: 0 | GA35: [3 249 / 1,2 / 9,88] + 2% Заг.скл | GD35: 1 | GF35: 1071266394 | GG35: 2 | GH35: 3 | GI35: 5 | GJ35: 0 | GK35: 0 | GL35: =ROUND(IF(AND(BH35=3,BI35=3,FS35<>0),P35,0),2) -> 0 | GM35: =ROUND(O35+X35+Y35,2)+GX35 -> 77326.41 | GN35: =IF(OR(BI35=0,BI35=1),GM35-GX35,0) -> 0 | GO35: =IF(BI35=2,GM35-GX35,0) -> 77326.41 | GP35: =IF(BI35=4,GM35-GX35,0) -> 0 | GR35: 1 | GS35: 1 | GT35: 0 | GV35: =ROUND((GT35),6) -> 0 | GW35: 1 | GX35: =ROUND(HC35*I35,2) -> 0 | HA35: 0 | HB35: 0 | HC35: =GV35*GW35 -> 0 | HE35: 0 | HF35: 2 | HS35: 0 | IK35: 0
A36: 17 | B36: 1 | C36: =ROW(SmtRes!A20) -> 20 | D36: =ROW(EtalonRes!A23) -> 23 | E36: 5 | F36: 4.10-174-2 | G36: Монтаж наружной камеры видеонаблюдения | H36: 10 шт. | I36: =ROUND(109/10,9) -> 10.9 | J36: 0 | K36: =ROUND(109/10,9) -> 10.9 | O36: =ROUND(CP36,2) -> 5530.34 | P36: =ROUND((ROUND((AC36*AW36*I36),2)*BC36),2) -> 463.36 | Q36: =(ROUND((ROUND((((ET36*1.1))*AV36*I36),2)*BB36),2)+ROUND((ROUND(((AE36-((EU36*1.1)))*AV36*I36),2)*BS36),2)) -> 29.63 | R36: =(ROUND((ROUND((((EU36*1.1))*AV36*I36),2)*BS36),2)+ROUND((ROUND(((AE36-((EU36*1.1)))*AV36*I36),2)*BS36),2)) -> 1.63 | S36: =ROUND((ROUND((AF36*AV36*I36),2)*BA36),2) -> 5037.35 | T36: =ROUND(CU36*I36,2) -> 0 | U36: =CV36*I36 -> 317.98091 | V36: =CW36*I36 -> 0 | W36: =ROUND(CX36*I36,2) -> 0 | X36: =(ROUND((((S36+ROUND((ROUND((((EU36*1.1))*AV36*I36),2)*BS36),2))*AT36)/100),2)+ROUND(((ROUND((ROUND(((AE36-((EU36*1.1)))*AV36*I36),2)*BS36),2)*AT36)/100),2)) -> 4535.08 | Y36: =(ROUND((((S36+ROUND((ROUND((((EU36*1.1))*AV36*I36),2)*BS36),2))*AU36)/100),2)+ROUND(((ROUND((ROUND(((AE36-((EU36*1.1)))*AV36*I36),2)*BS36),2)*AU36)/100),2)) -> 2317.93 | AA36: 60258064 | AB36: =ROUND((AC36+AD36+AF36),6) -> 486.503 | AC36: =ROUND((ES36),6) -> 42.51 | AD36: =ROUND(((((ET36*1.1))-((EU36*1.1)))+AE36),6) -> 2.596 | AE36: =ROUND(((EU36*1.1)),6) -> 0.143 | AF36: =ROUND(((EV36*1.1)),6) -> 441.397 | AG36: =ROUND((AP36),6) -> 0 | AH36: =((EW36*1.1)) -> 27.863 | AI36: =((EX36*1.1)) -> 0 | AJ36: =(AS36) -> 0 | AK36: 446.14 | AL36: 42.51 | AM36: 2.36 | AN36: 0.13 | AO36: 401.27 | AP36: 0 | AQ36: 25.33 | AR36: 0 | AS36: 0 | AT36: 90 | AU36: 46 | AV36: 1.047 | AW36: 1 | AZ36: 1 | BA36: 1 | BB36: 1 | BC36: 1 | BH36: 0 | BI36: 2 | BJ36: ТСН-2001.4 Доп. 68, Сб. 10, т. 174, поз. 2 | BM36: 68 | BN36: 58973116 | BO36: 4.10-174-2 | BP36: 1 | BQ36: 40 | BR36: 0 | BS36: 1 | BT36: 1 | BU36: 1 | BV36: 1 | BW36: 1 | BX36: 1 | BZ36: 90 | CA36: 46 | CE36: 1566 | CF36: 0 | CG36: 0 | CM36: 0 | CN36: Поправка: О.П. п.3.4.30.в Наименование: При применении территориальных сметных нормативов для города Москвы затраты, учитывающие напряженные и стесненные условия производства работ (стесненность, сложность складирования и транспортной логистики и т.п.), исчисляются с применением коэффициентов к затратам труда и заработной плате рабочих, машинистов, времени эксплуатации машин и механизмов, стоимости эксплуатации машин в размере: для объектов, расположенных за пределами Третьего транспортного кольца города Москвы, но в пределах Московской кольцевой автомобильной дороги | CO36: 0 | CP36: =(P36+Q36+S36) -> 5530.34 | CQ36: =ROUND((ROUND((AC36*AW36*1),2)*BC36),2) -> 42.51 | CR36: =(ROUND((ROUND((((ET36*1.1))*AV36*1),2)*BB36),2)+ROUND((ROUND(((AE36-((EU36*1.1)))*AV36*1),2)*BS36),2)) -> 2.72 | CS36: =(ROUND((ROUND((((EU36*1.1))*AV36*1),2)*BS36),2)+ROUND((ROUND(((AE36-((EU36*1.1)))*AV36*1),2)*BS36),2)) -> 0.15 | CT36: =ROUND((ROUND((AF36*AV36*1),2)*BA36),2) -> 462.14 | CU36: =AG36 -> 0 | CV36: =(AH36*AV36) -> 29.172561 | CW36: =AI36 -> 0 | CX36: =AJ36 -> 0 | CY36: =(ROUND((((S36+ROUND((ROUND((((EU36*1.1))*AV36*1),2)*BS36),2))*AT36)/100),2)+ROUND(((ROUND((ROUND(((AE36-((EU36*1.1)))*AV36*1),2)*BS36),2)*AT36)/100),2)) -> 4533.75 | CZ36: =(ROUND((((S36+ROUND((ROUND((((EU36*1.1))*AV36*1),2)*BS36),2))*AU36)/100),2)+ROUND(((ROUND((ROUND(((AE36-((EU36*1.1)))*AV36*1),2)*BS36),2)*AU36)/100),2)) -> 2317.25 | DB36: 5 | DE36: *1,1 | DF36: *1,1 | DG36: *1,1 | DI36: *1,1 | DJ36: *1,1 | DN36: 0 | DO36: 0 | DP36: 1 | DQ36: 1 | DU36: 1010 | DV36: 10 шт. | DW36: 10 шт. | DX36: 10 | EE36: 60088532 | EF36: 40 | EG36: Монтаж оборудования | EH36: 0 | EJ36: 2 | EK36: 68 | EL36: ТСН-2001.4-10. Прокладка и монтаж сетей связи | EM36: ТСН-2001.4-10-1 | EO36: Поправка: О.П. п.3.4.30.в | EQ36: 0 | ER36: 446.14 | ES36: 42.51 | ET36: 2.36 | EU36: 0.13 | EV36: 401.27 | EW36: 25.33 | EX36: 0 | EY36: 0 | FQ36: 0 | FR36: 0 | FS36: 0 | FX36: 90 | FY36: 46 | GD36: 1 | GF36: -2118561153 | GG36: 2 | GH36: 1 | GI36: 2 | GJ36: 0 | GK36: 0 | GL36: =ROUND(IF(AND(BH36=3,BI36=3,FS36<>0),P36,0),2) -> 0 | GM36: =ROUND(O36+X36+Y36,2)+GX36 -> 12383.35 | GN36: =IF(OR(BI36=0,BI36=1),GM36-GX36,0) -> 0 | GO36: =IF(BI36=2,GM36-GX36,0) -> 12383.35 | GP36: =IF(BI36=4,GM36-GX36,0) -> 0 | GR36: 0 | GS36: 3 | GT36: 0 | GV36: =ROUND((GT36),6) -> 0 | GW36: 1 | GX36: =ROUND(HC36*I36,2) -> 0 | HA36: 0 | HB36: 0 | HC36: =GV36*GW36 -> 0 | HS36: 0 | IK36: 0
A37: 17 | B37: 1 | C37: =ROW(SmtRes!A26) -> 26 | D37: =ROW(EtalonRes!A30) -> 30 | E37: 5 | F37: 4.10-174-2 | G37: Монтаж наружной камеры видеонаблюдения | H37: 10 шт. | I37: =ROUND(109/10,9) -> 10.9 | J37: 0 | K37: =ROUND(109/10,9) -> 10.9 | O37: =ROUND(CP37,2) -> 278234.76 | P37: =ROUND((ROUND((AC37*AW37*I37),2)*BC37),2) -> 894.28 | Q37: =(ROUND((ROUND((((ET37*1.1))*AV37*I37),2)*BB37),2)+ROUND((ROUND(((AE37-((EU37*1.1)))*AV37*I37),2)*BS37),2)) -> 336.6 | R37: =(ROUND((ROUND((((EU37*1.1))*AV37*I37),2)*BS37),2)+ROUND((ROUND(((AE37-((EU37*1.1)))*AV37*I37),2)*BS37),2)) -> 89.63 | S37: =ROUND((ROUND((AF37*AV37*I37),2)*BA37),2) -> 277003.88 | T37: =ROUND(CU37*I37,2) -> 0 | U37: =CV37*I37 -> 317.98091 | V37: =CW37*I37 -> 0 | W37: =ROUND(CX37*I37,2) -> 0 | X37: =(ROUND((((S37+ROUND((ROUND((((EU37*1.1))*AV37*I37),2)*BS37),2))*AT37)/100),2)+ROUND(((ROUND((ROUND(((AE37-((EU37*1.1)))*AV37*I37),2)*BS37),2)*AT37)/100),2)) -> 249384.16 | Y37: =(ROUND((((S37+ROUND((ROUND((((EU37*1.1))*AV37*I37),2)*BS37),2))*AU37)/100),2)+ROUND(((ROUND((ROUND(((AE37-((EU37*1.1)))*AV37*I37),2)*BS37),2)*AU37)/100),2)) -> 127463.01 | AA37: 60258061 | AB37: =ROUND((AC37+AD37+AF37),6) -> 486.503 | AC37: =ROUND((ES37),6) -> 42.51 | AD37: =ROUND(((((ET37*1.1))-((EU37*1.1)))+AE37),6) -> 2.596 | AE37: =ROUND(((EU37*1.1)),6) -> 0.143 | AF37: =ROUND(((EV37*1.1)),6) -> 441.397 | AG37: =ROUND((AP37),6) -> 0 | AH37: =((EW37*1.1)) -> 27.863 | AI37: =((EX37*1.1)) -> 0 | AJ37: =(AS37) -> 0 | AK37: 446.14 | AL37: 42.51 | AM37: 2.36 | AN37: 0.13 | AO37: 401.27 | AP37: 0 | AQ37: 25.33 | AR37: 0 | AS37: 0 | AT37: 90 | AU37: 46 | AV37: 1.047 | AW37: 1 | AZ37: 1 | BA37: 54.99 | BB37: 11.36 | BC37: 1.93 | BH37: 0 | BI37: 2 | BJ37: ТСН-2001.4 Доп. 68, Сб. 10, т. 174, поз. 2 | BM37: 68 | BN37: 58973116 | BO37: 4.10-174-2 | BP37: 1 | BQ37: 40 | BR37: 0 | BS37: 54.99 | BT37: 1 | BU37: 1 | BV37: 1 | BW37: 1 | BX37: 1 | BZ37: 90 | CA37: 46 | CE37: 1566 | CF37: 0 | CG37: 0 | CM37: 0 | CN37: Поправка: О.П. п.3.4.30.в Наименование: При применении территориальных сметных нормативов для города Москвы затраты, учитывающие напряженные и стесненные условия производства работ (стесненность, сложность складирования и транспортной логистики и т.п.), исчисляются с применением коэффициентов к затратам труда и заработной плате рабочих, машинистов, времени эксплуатации машин и механизмов, стоимости эксплуатации машин в размере: для объектов, расположенных за пределами Третьего транспортного кольца города Москвы, но в пределах Московской кольцевой автомобильной дороги | CO37: 0 | CP37: =(P37+Q37+S37) -> 278234.76 | CQ37: =ROUND((ROUND((AC37*AW37*1),2)*BC37),2) -> 82.04 | CR37: =(ROUND((ROUND((((ET37*1.1))*AV37*1),2)*BB37),2)+ROUND((ROUND(((AE37-((EU37*1.1)))*AV37*1),2)*BS37),2)) -> 30.9 | CS37: =(ROUND((ROUND((((EU37*1.1))*AV37*1),2)*BS37),2)+ROUND((ROUND(((AE37-((EU37*1.1)))*AV37*1),2)*BS37),2)) -> 8.25 | CT37: =ROUND((ROUND((AF37*AV37*1),2)*BA37),2) -> 25413.08 | CU37: =AG37 -> 0 | CV37: =(AH37*AV37) -> 29.172561 | CW37: =AI37 -> 0 | CX37: =AJ37 -> 0 | CY37: =(ROUND((((S37+ROUND((ROUND((((EU37*1.1))*AV37*1),2)*BS37),2))*AT37)/100),2)+ROUND(((ROUND((ROUND(((AE37-((EU37*1.1)))*AV37*1),2)*BS37),2)*AT37)/100),2)) -> 249310.92 | CZ37: =(ROUND((((S37+ROUND((ROUND((((EU37*1.1))*AV37*1),2)*BS37),2))*AU37)/100),2)+ROUND(((ROUND((ROUND(((AE37-((EU37*1.1)))*AV37*1),2)*BS37),2)*AU37)/100),2)) -> 127425.58 | DB37: 6 | DE37: *1,1 | DF37: *1,1 | DG37: *1,1 | DI37: *1,1 | DJ37: *1,1 | DN37: 0 | DO37: 0 | DP37: 1 | DQ37: 1 | DU37: 1010 | DV37: 10 шт. | DW37: 10 шт. | DX37: 10 | EE37: 60088532 | EF37: 40 | EG37: Монтаж оборудования | EH37: 0 | EJ37: 2 | EK37: 68 | EL37: ТСН-2001.4-10. Прокладка и монтаж сетей связи | EM37: ТСН-2001.4-10-1 | EO37: Поправка: О.П. п.3.4.30.в | EQ37: 0 | ER37: 446.14 | ES37: 42.51 | ET37: 2.36 | EU37: 0.13 | EV37: 401.27 | EW37: 25.33 | EX37: 0 | EY37: 0 | FQ37: 0 | FR37: 0 | FS37: 0 | FX37: 90 | FY37: 46 | GD37: 1 | GF37: -2118561153 | GG37: 2 | GH37: 1 | GI37: 2 | GJ37: 0 | GK37: 0 | GL37: =ROUND(IF(AND(BH37=3,BI37=3,FS37<>0),P37,0),2) -> 0 | GM37: =ROUND(O37+X37+Y37,2)+GX37 -> 655081.93 | GN37: =IF(OR(BI37=0,BI37=1),GM37-GX37,0) -> 0 | GO37: =IF(BI37=2,GM37-GX37,0) -> 655081.93 | GP37: =IF(BI37=4,GM37-GX37,0) -> 0 | GR37: 0 | GS37: 3 | GT37: 0 | GV37: =ROUND((GT37),6) -> 0 | GW37: 1 | GX37: =ROUND(HC37*I37,2) -> 0 | HA37: 0 | HB37: 0 | HC37: =GV37*GW37 -> 0 | HS37: 0 | IK37: 0
