Workbook

Sheet 02-01-03
A1: =Source!B1 -> Smeta.RU (495) 974-1589
J2: Форма № 4б
A3: Капитальный ремонт здания Государственного бюджетного общеобразовательного учреждения города Москвы "Школа №236" по адресу: г. Москва, улица Клязьминская, дом 7, корпус 4. | AP3: Капитальный ремонт здания Государственного бюджетного общеобразовательного учреждения города Москвы "Школа №236" по адресу: г. Москва, улица Клязьминская, дом 7, корпус 4. 02-01-03 ЭОМ
A4: (наименование стройки и/или объекта)
A6: =CONCATENATE( "ЛОКАЛЬНАЯ СМЕТА № ",IF(Source!F20<>"Новая локальная смета", Source!F20, "")) -> ЛОКАЛЬНАЯ СМЕТА № 02-01-03
A8: =IF(Source!G20<>"Новая локальная смета", Source!G20, "") -> Система электроснабжения
A9: (наименование работ и затрат)
A11: =CONCATENATE( "Основание: чертежи № ", Source!J20) -> Основание: чертежи № 2024-00272-01-0-ИОС1
I13: В базисном уровне цен | J13: В текущем уровне цен
E14: Сметная стоимость | I14: =I15+I16+I17+I18 -> 6460.79 | J14: =J15+J16+J17+J18 -> 59208.78 | K14: тыс.руб.
E15: Строительные работы | I15: =ROUND((Source!F863)/1000, 2) -> 0 | J15: =ROUND((Source!P863)/1000, 2) -> 0 | K15: тыс.руб.
E16: Работы по монтажу оборудования | I16: =ROUND((Source!F864)/1000, 2) -> 5360.51 | J16: =ROUND((Source!P864)/1000, 2) -> 50786.26 | K16: тыс.руб.
E17: Оборудование | I17: =ROUND((Source!F855)/1000, 2) -> 1100.28 | J17: =ROUND((Source!P855)/1000, 2) -> 8422.52 | K17: тыс.руб.
E18: Прочие работы и затраты | I18: =ROUND((Source!F865+Source!F866)/1000, 2) -> 0 | J18: =ROUND((Source!P865+Source!P866)/1000, 2) -> 0 | K18: тыс.руб.
E19: Средства на оплату труда | I19: =(Source!F861+ Source!F860)/1000 -> 74.37731 | J19: =((Source!P861 + Source!P860)/1000) -> 4090.0083 | K19: тыс.руб.
E20: Затраты труда | I20: =Source!F868 -> 5619.3181 | K20: чел.-ч.
E21: Кроме того:
E22: Возврат материалов | I22: =SUM(Y28:Y1292)/1000 -> 0 | J22: =SUM(Z28:Z1292)/1000 -> 0 | K22: тыс.руб.
A24: Составлен(а) по ТСН-2001 с учетом Дополнения №: 80
A25: № и период сборника коэффициентов (индексов) пересчета: Коэффициенты к ТСН-2001 МГЭ Дополнение 80, строительство №217/80 III квартал 2025 года и Коэффициенты к ТСН-2001.13-2 Дополнение 46 №62/46 III квартал 2025 года | AP25: № и период сборника коэффициентов (индексов) пересчета: Коэффициенты к ТСН-2001 МГЭ Дополнение 80, строительство №217/80 III квартал 2025 года и Коэффициенты к ТСН-2001.13-2 Дополнение 46 №62/46 III квартал 2025 года
A26: № п/п | B26: Шифр расценки и коды ресурсов | C26: Наименование работ и затрат | D26: Ед. изм. | E26: Кол-во единиц | F26: Цена на ед. изм., руб. | G26: Попра- вочные коэффи- циенты | H26: Коэффи- циенты зимних удорожа- ний | I26: Всего в ценах на январь 2000 года, руб. | J26: Коэффи- циенты (индек- сы) пере- счета, нормы НР и СП | K26: ВСЕГО затрат в текущем уровне цен, руб.
A27: 1 | B27: 2 | C27: 3 | D27: 4 | E27: 5 | F27: 6 | G27: 7 | H27: 8 | I27: 9 | J27: 10 | K27: 11
A29: =CONCATENATE("Раздел: ",IF(Source!G24<>"Новый раздел", Source!G24, "")) -> Раздел: Щитовое оборудование
B31: =Source!G28 -> Вводная панель
A32: 1 | B32: =Source!F29 -> 4.8-238-3 | C32: Монтаж щитов и стеллажей с блоками резисторов (ящиками сопротивлений) высотой свыше 1700 мм, щита заводского изготовления однорядного или двухрядного открытого исполнения шириной 800 мм | D32: =Source!H29 -> 1 м ширины по фронту | E32: =Source!I29 -> 1.2 | Q32: =Source!X29 -> 116.75 | R32: =Source!X30 -> 6420.04 | S32: =Source!Y29 -> 61.38 | T32: =Source!Y30 -> 3375.49 | U32: =ROUND((175/100)*ROUND(Source!R29, 2), 2) -> 16.47 | V32: =ROUND((0/100)*ROUND(Source!R30, 2), 2) -> 0 | AC32: 0
C33: ="Объем: "&Source!I29&"=0,6+"&"0,6" -> Объем: 1,2=0,6+0,6
C34: ЗП | F34: =Source!AO29 -> 80.28 | G34: =Source!DG29 -> *1,1 | H34: =Source!AV30 -> 1.047 | I34: =Source!S29 -> 110.95 | J34: =IF(Source!BA30<> 0, Source!BA30, 1) -> 54.99 | K34: =Source!S30 -> 6101.14
C35: ЭМ | F35: =Source!AM29 -> 56.75 | G35: =Source!DE29 -> *1,1 | H35: =Source!AV30 -> 1.047 | I35: =Source!Q29 -> 78.43 | J35: =IF(Source!BB30<> 0, Source!BB30, 1) -> 15.3 | K35: =Source!Q30 -> 1199.98
C36: в т.ч. ЗПМ | F36: =Source!AN29 -> 6.81 | G36: =Source!DF29 -> *1,1 | H36: =Source!AV30 -> 1.047 | I36: =Source!R29 -> 9.41 | J36: =IF(Source!BS30<> 0, Source!BS30, 1) -> 54.99 | K36: =Source!R30 -> 517.46
C37: МР | F37: =Source!AL29 -> 23.66 | G37: =Source!DD29 | H37: =Source!AW30 -> 1 | I37: =Source!P29 -> 28.39 | J37: =IF(Source!BC30<> 0, Source!BC30, 1) -> 7.98 | K37: =Source!P30 -> 226.55
A38: 1,1 | B38: =Source!F31 -> 1.1-1-58 | C38: Болты строительные с гайками, оцинкованные, М10х100 мм | D38: =Source!H31 -> т | E38: =Source!I31 -> 0.000612 | F38: =Source!AK31 -> 24609.76 | H38: =Source!AW32 -> 1 | I38: =Source!O31 -> 15.06 | J38: =IF(Source!BC32<> 0, Source!BC32, 1) -> 5.15 | K38: =Source!O32 -> 77.56 | Q38: =Source!X31 -> 0 | R38: =Source!X32 -> 0 | S38: =Source!Y31 -> 0 | T38: =Source!Y32 -> 0 | U38: =ROUND((175/100)*ROUND(Source!R31, 2), 2) -> 0 | V38: =ROUND((0/100)*ROUND(Source!R32, 2), 2) -> 0 | AC38: 3
C39: НР от ФОТ | D39: % | E39: =Source!BZ30 -> 97 | I39: =SUM(Q32:Q38) -> 116.75 | J39: =Source!AT30 -> 97 | K39: =SUM(R32:R38) -> 6420.04
C40: СП от ФОТ | D40: % | E40: =Source!CA30 -> 51 | I40: =SUM(S32:S39) -> 61.38 | J40: =Source!AU30 -> 51 | K40: =SUM(T32:T39) -> 3375.49
C41: ЗТР | D41: чел-ч | E41: =Source!AQ29 -> 6.18 | G41: =Source!DI29 -> *1,1 | H41: =Source!AV30 -> 1.047 | I41: =Source!U29 -> 8.5410072
C42: ВСЕГО работ по позиции: | H42: =I34+I35+I37+I39+I40+SUM(I38:I38)-SUMIF(AC38:AC38, 5, I38:I38)-SUMIF(AC38:AC38, 6, I38:I38) -> 410.96 | J42: =K34+K35+K37+K39+K40+SUM(K38:K38)-SUMIF(AC38:AC38, 5, K38:K38)-SUMIF(AC38:AC38, 6, K38:K38) -> 17400.76
C43: ВСЕГО оборудование по позиции: | H43: =SUMIF(AC38:AC38, 5, I38:I38)+SUMIF(AC38:AC38, 6, I38:I38) -> 0 | J43: =SUMIF(AC38:AC38, 5, K38:K38)+SUMIF(AC38:AC38, 6, K38:K38) -> 0
C44: ВСЕГО по позиции: | H44: =I34+I35+I37+I39+I40+SUM(I38:I38) -> 410.96 | J44: =K34+K35+K37+K39+K40+SUM(K38:K38) -> 17400.76 | O44: =I34+I35+I37+I39+I40+SUM(I38:I38) -> 410.96 | P44: =K34+K35+K37+K39+K40+SUM(K38:K38) -> 17400.76
A46: 2 | B46: =Source!F33 -> КА-1 | C46: ОБОРУДОВАНИЕ:_x000D_ Вводная панель ВП1 60 887,82 = [536 936,24 / 1,2 / 7,66] + 3% Трансп + 1,2% Заг.скл | D46: =Source!H33 -> ШТ | E46: =Source!I33 -> 1 | F46: =Source!AL33 -> 60887.82 | G46: =Source!DD33 | H46: =Source!AW34 -> 1 | I46: =Source!P33 -> 60887.82 | J46: =IF(Source!BC34<> 0, Source!BC34, 1) -> 7.66 | K46: =Source!P34 -> 466400.7 | Q46: =Source!X33 -> 0 | R46: =Source!X34 -> 0 | S46: =Source!Y33 -> 0 | T46: =Source!Y34 -> 0 | U46: =ROUND((175/100)*ROUND(Source!R33, 2), 2) -> 0 | V46: =ROUND((0/100)*ROUND(Source!R34, 2), 2) -> 0 | AC46: 5
C47: ВСЕГО по позиции: | H47: =I46+0 -> 60887.82 | J47: =K46+0 -> 466400.7 | O47: =I46+0 -> 60887.82 | P47: =K46+0 -> 466400.7
A49: 3 | B49: =Source!F35 -> КА-2 | C49: ОБОРУДОВАНИЕ:_x000D_ Вводная панель ВП1 44 301,78 = [390 673,02 / 1,2 / 7,66] + 3% Трансп + 1,2% Заг.скл | D49: =Source!H35 -> ШТ | E49: =Source!I35 -> 1 | F49: =Source!AL35 -> 44301.78 | G49: =Source!DD35 | H49: =Source!AW36 -> 1 | I49: =Source!P35 -> 44301.78 | J49: =IF(Source!BC36<> 0, Source!BC36, 1) -> 7.66 | K49: =Source!P36 -> 339351.63 | Q49: =Source!X35 -> 0 | R49: =Source!X36 -> 0 | S49: =Source!Y35 -> 0 | T49: =Source!Y36 -> 0 | U49: =ROUND((175/100)*ROUND(Source!R35, 2), 2) -> 0 | V49: =ROUND((0/100)*ROUND(Source!R36, 2), 2) -> 0 | AC49: 5
...

Sheet Ведомость объемов работ
A1: =Source!B1 -> Smeta.RU (495) 974-1589
B4: =CONCATENATE("Ведомость объемов работ ", IF(Source!AN15<>"", Source!AN15," ")) -> Ведомость объемов работ
B5: =CONCATENATE(Source!F12, " ", Source!G12) -> 02-01-03 ЭОМ
A8: № п/п | B8: № в ЛСР | C8: Наименование работ и затрат | D8: Единица измерения | E8: Количество | F8: Ссылка на чертежи, спецификации | G8: Формула расчета, расчет объемов работ и расхода материалов | H8: Примечание
A9: 1 | B9: 2 | C9: 3 | D9: 4 | E9: 5 | F9: 6 | G9: 7 | H9: 8
A10: =CONCATENATE("Локальная смета: ", Source!G20) -> Локальная смета: Система электроснабжения
A11: =CONCATENATE("Раздел: ", Source!G24) -> Раздел: Щитовое оборудование
A12: 1 | B12: =Source!E29 -> 1 | C12: =Source!G29 -> Монтаж щитов и стеллажей с блоками резисторов (ящиками сопротивлений) высотой свыше 1700 мм, щита заводского изготовления однорядного или двухрядного открытого исполнения шириной 800 мм | D12: 1 м ширины по фронту | E12: =Source!I29 -> 1.2 | F12: =Source!U24 | G12: ="=0,6+"&"0,6" -> =0,6+0,6
A13: 2 | B13: =Source!E33 -> 2 | C13: =Source!G33 -> Вводная панель ВП1 | D13: ШТ | E13: =Source!I33 -> 1 | F13: =Source!U24 | G13: =Source!I33 -> 1
A14: 3 | B14: =Source!E35 -> 3 | C14: =Source!G35 -> Вводная панель ВП1 | D14: ШТ | E14: =Source!I35 -> 1 | F14: =Source!U24 | G14: =Source!I35 -> 1
A15: 4 | B15: =Source!E38 -> 4 | C15: =Source!G38 -> Монтаж щитов и стеллажей с блоками резисторов (ящиками сопротивлений) высотой свыше 1700 мм, щита заводского изготовления однорядного или двухрядного открытого исполнения шириной 800 мм | D15: 1 м ширины по фронту | E15: =Source!I38 -> 1.2 | F15: =Source!U24 | G15: ="=0,6+"&"0,6" -> =0,6+0,6
A16: 5 | B16: =Source!E42 -> 5 | C16: =Source!G42 -> Распределительная панель РП-1 | D16: ШТ | E16: =Source!I42 -> 1 | F16: =Source!U24 | G16: =Source!I42 -> 1
A17: 6 | B17: =Source!E44 -> 6 | C17: =Source!G44 -> Распределительная панель РП-2 | D17: ШТ | E17: =Source!I44 -> 1 | F17: =Source!U24 | G17: =Source!I44 -> 1
A18: 7 | B18: =Source!E47 -> 7 | C18: =Source!G47 -> Монтаж щитов и стеллажей с блоками резисторов (ящиками сопротивлений) высотой свыше 1700 мм, щита заводского изготовления однорядного или двухрядного открытого исполнения шириной 800 мм | D18: 1 м ширины по фронту | E18: =Source!I47 -> 0.6 | F18: =Source!U24 | G18: =Source!I47 -> 0.6
A19: 8 | B19: =Source!E51 -> 8 | C19: =Source!G51 -> Панель ЩГП с АВР | D19: ШТ | E19: =Source!I51 -> 1 | F19: =Source!U24 | G19: =Source!I51 -> 1
A20: 9 | B20: =Source!E54 -> 9 | C20: =Source!G54 -> Монтаж щитов и стеллажей с блоками резисторов (ящиками сопротивлений) высотой свыше 1700 мм, щита заводского изготовления однорядного или двухрядного открытого исполнения шириной 800 мм | D20: 1 м ширины по фронту | E20: =Source!I54 -> 0.6 | F20: =Source!U24 | G20: =Source!I54 -> 0.6
A21: 10 | B21: =Source!E58 -> 10 | C21: =Source!G58 -> Панель ПЭСПЗ с АВР | D21: ШТ | E21: =Source!I58 -> 1 | F21: =Source!U24 | G21: =Source!I58 -> 1
A22: 11 | B22: =Source!E61 -> 11 | C22: =Source!G61 -> Монтаж пультов и шкафов управления, пульта управления напольного, высотой до 1200 мм, глубиной и шириной по фронту до 700х1000 мм | D22: 1 ШТ. | E22: =Source!I61 -> 2 | F22: =Source!U24 | G22: =Source!I61 -> 2
A23: 12 | B23: =Source!E65 -> 12 | C23: =Source!G65 -> УКРМ 50-10 | D23: ШТ | E23: =Source!I65 -> 2 | F23: =Source!U24 | G23: =Source!I65 -> 2
A24: 13 | B24: =Source!E68 -> 13 | C24: =Source!G68 -> Монтаж пультов и шкафов управления, шкафа (пульта) управления навесного, высотой, шириной, глубиной до 600х600х350 мм | D24: 1 ШТ. | E24: =Source!I68 -> 60 | F24: =Source!U24 | G24: =Source!I68 -> 60
A25: 14 | B25: =Source!E72 -> 14 | C25: =Source!G72 -> ЩМТ-1 | D25: ШТ | E25: =Source!I72 -> 1 | F25: =Source!U24 | G25: =Source!I72 -> 1
A26: 15 | B26: =Source!E74 -> 15 | C26: =Source!G74 -> ЩО1.1 | D26: ШТ | E26: =Source!I74 -> 1 | F26: =Source!U24 | G26: =Source!I74 -> 1
A27: 16 | B27: =Source!E76 -> 16 | C27: =Source!G76 -> ЩО1.2 | D27: ШТ | E27: =Source!I76 -> 1 | F27: =Source!U24 | G27: =Source!I76 -> 1
A28: 17 | B28: =Source!E78 -> 17 | C28: =Source!G78 -> ЩО1.3 | D28: ШТ | E28: =Source!I78 -> 1 | F28: =Source!U24 | G28: =Source!I78 -> 1
A29: 18 | B29: =Source!E80 -> 18 | C29: =Source!G80 -> ЩО1.4 | D29: ШТ | E29: =Source!I80 -> 1 | F29: =Source!U24 | G29: =Source!I80 -> 1
A30: 19 | B30: =Source!E82 -> 19 | C30: =Source!G82 -> ЩО2.1 | D30: ШТ | E30: =Source!I82 -> 1 | F30: =Source!U24 | G30: =Source!I82 -> 1
A31: 20 | B31: =Source!E84 -> 20 | C31: =Source!G84 -> ЩО2.2 | D31: ШТ | E31: =Source!I84 -> 1 | F31: =Source!U24 | G31: =Source!I84 -> 1
A32: 21 | B32: =Source!E86 -> 21 | C32: =Source!G86 -> ЩО2.3 | D32: ШТ | E32: =Source!I86 -> 1 | F32: =Source!U24 | G32: =Source!I86 -> 1
A33: 22 | B33: =Source!E88 -> 22 | C33: =Source!G88 -> ЩО2.4 | D33: ШТ | E33: =Source!I88 -> 1 | F33: =Source!U24 | G33: =Source!I88 -> 1
A34: 23 | B34: =Source!E90 -> 23 | C34: =Source!G90 -> ЩО3.1 | D34: ШТ | E34: =Source!I90 -> 1 | F34: =Source!U24 | G34: =Source!I90 -> 1
A35: 24 | B35: =Source!E92 -> 24 | C35: =Source!G92 -> ЩО3.2 | D35: ШТ | E35: =Source!I92 -> 1 | F35: =Source!U24 | G35: =Source!I92 -> 1
A36: 25 | B36: =Source!E94 -> 25 | C36: =Source!G94 -> ЩО3.3 | D36: ШТ | E36: =Source!I94 -> 1 | F36: =Source!U24 | G36: =Source!I94 -> 1
A37: 26 | B37: =Source!E96 -> 26 | C37: =Source!G96 -> ЩО3.4 | D37: ШТ | E37: =Source!I96 -> 1 | F37: =Source!U24 | G37: =Source!I96 -> 1
A38: 27 | B38: =Source!E98 -> 27 | C38: =Source!G98 -> ЩОА1.1 | D38: ШТ | E38: =Source!I98 -> 1 | F38: =Source!U24 | G38: =Source!I98 -> 1
A39: 28 | B39: =Source!E100 -> 28 | C39: =Source!G100 -> ЩОА1.2 | D39: ШТ | E39: =Source!I100 -> 1 | F39: =Source!U24 | G39: =Source!I100 -> 1
A40: 29 | B40: =Source!E102 -> 29 | C40: =Source!G102 -> ЩОА1.3 | D40: ШТ | E40: =Source!I102 -> 1 | F40: =Source!U24 | G40: =Source!I102 -> 1
A41: 30 | B41: =Source!E104 -> 30 | C41: =Source!G104 -> ЩОА1.4 | D41: ШТ | E41: =Source!I104 -> 1 | F41: =Source!U24 | G41: =Source!I104 -> 1
A42: 31 | B42: =Source!E106 -> 31 | C42: =Source!G106 -> ЩОА2.1 | D42: ШТ | E42: =Source!I106 -> 1 | F42: =Source!U24 | G42: =Source!I106 -> 1
A43: 32 | B43: =Source!E108 -> 32 | C43: =Source!G108 -> ЩОА2.2 | D43: ШТ | E43: =Source!I108 -> 1 | F43: =Source!U24 | G43: =Source!I108 -> 1
A44: 33 | B44: =Source!E110 -> 33 | C44: =Source!G110 -> ЩОА2.3 | D44: ШТ | E44: =Source!I110 -> 1 | F44: =Source!U24 | G44: =Source!I110 -> 1
...

Sheet Source
A1: 0 | B1: Smeta.RU (495) 974-1589 | D1: _PS_ | F1: 0 | G1: 0 | H1: 0 | I1: Smeta.RU | K1: 1 | L1: 74563 | M1: 10 | N1: 12 | O1: 0 | P1: 0 | Q1: 3
A4: 1 | B4: 1 | C4: -1 | G4: Капитальный ремонт здания Государственного бюджетного общеобразовательного учреждения города Москвы "Школа №236" по адресу: г. Москва, улица Клязьминская, дом 7, корпус 4 | EC4: 0
A12: 1 | B12: 915 | C12: 0 | D12: =ROW(A876) -> 876 | E12: 0 | G12: 02-01-03 ЭОМ | I12: 0 | J12: 2024-00272-01-0-ИОС1 | K12: 0 | L12: 0 | M12: 4098 | O12: 0 | P12: 0 | Q12: 0 | R12: 0 | S12: 0 | T12: 1 | V12: 0 | AB12: Соколова И.Н. | BB12: 0 | BH12: Сметные нормы списания | BI12: Коды ОКП для ТСН-2001 МГЭ Дополнение 80 | BJ12: 1 | BK12: 1 | BL12: 0 | BM12: 0 | BN12: 1 | BO12: 0 | BP12: 6 | BQ12: 2 | BR12: 1 | BS12: 1 | BT12: 0 | BU12: 0 | BV12: 0 | BW12: 0 | BX12: 0 | BZ12: Типовой расчет для ТСН-2001 МГЭ, Дополнение 80, строительство | CA12: Территориальные сметные нормативы для Москвы ТСН-2001 (МГЭ), дополнение 80 | CB12: Территориальные сметные нормативы для Москвы ТСН-2001 (МГЭ), дополнение 80 | CC12: Территориальные сметные нормативы для Москвы ТСН-2001 (МГЭ), дополнение 80 | CD12: Территориальные сметные нормативы для Москвы ТСН-2001 (МГЭ), дополнение 80 | CE12: Поправки для ТСН-2001 от 03.02.2026 г. доп.80 | CF12: 0 | CG12: 0 | CH12: 8200 | CK12: 80 | CQ12: Территориальные сметные нормативы для Москвы (ТСН-2001) | CR12: ТЕР | CS12: 41660 | CT12: 1 | CU12: 80 | CY12: 0 | EC12: 0
A15: 15 | B15: 1
A18: 52 | B18: =B876 -> 915 | C18: =C876 -> 1 | D18: =D876 -> 12 | E18: =E876 -> 0 | F18: =F876 | G18: =G876 -> 02-01-03 ЭОМ | O18: =O876 -> 6350730 | P18: =P876 -> 6264077.8 | Q18: =Q876 -> 17638.23 | R18: =R876 -> 5363.32 | S18: =S876 -> 69013.99 | T18: =T876 -> 0 | U18: =U876 -> 5619.3181 | V18: =V876 -> 0 | ... GX18: =GX876 -> 0
A20: 3 | B20: 1 | D20: =ROW(A846) -> 846 | F20: 02-01-03 | G20: Система электроснабжения | I20: 0 | J20: 2024-00272-01-0-ИОС1 | K20: -1 | L20: 02-01-03 | S20: 0 | T20: 0 | V20: 2 | BX20: 0 | CF20: 0 | CG20: 0
A22: 52 | B22: =B846 -> 1 | C22: =C846 -> 3 | D22: =D846 -> 20 | E22: =E846 -> 0 | F22: =F846 -> 02-01-03 | G22: =G846 -> Система электроснабжения | O22: =O846 -> 6350730 | P22: =P846 -> 6264077.8 | Q22: =Q846 -> 17638.23 | R22: =R846 -> 5363.32 | S22: =S846 -> 69013.99 | T22: =T846 -> 0 | U22: =U846 -> 5619.3181 | V22: =V846 -> 0 | ... GX22: =GX846 -> 0
A24: 4 | B24: 1 | D24: =ROW(A193) -> 193 | G24: Щитовое оборудование | I24: 0 | K24: -1 | S24: 0 | T24: 0 | V24: 2 | BX24: 0 | CJ24: 0
A26: 52 | B26: =B193 -> 1 | C26: =C193 -> 4 | D26: =D193 -> 24 | E26: =E193 -> 0 | F26: =F193 | G26: =G193 -> Щитовое оборудование | O26: =O193 -> 1099578 | P26: =P193 -> 1095773.9 | Q26: =Q193 -> 1560.4 | R26: =R193 -> 268.99 | S26: =S193 -> 2243.67 | T26: =T193 -> 0 | U26: =U193 -> 172.71815 | V26: =V193 -> 0 | ... GX26: =GX193 -> 0
A28: 19 | B28: 1 | G28: Вводная панель | AA28: 1 | IK28: 0
A29: 17 | B29: 1 | C29: =ROW(SmtRes!A8) -> 8 | D29: =ROW(EtalonRes!A9) -> 9 | E29: 1 | F29: 4.8-238-3 | G29: Монтаж щитов и стеллажей с блоками резисторов (ящиками сопротивлений) высотой свыше 1700 мм, щита заводского изготовления однорядного или двухрядного открытого исполнения шириной 800 мм | H29: 1 м ширины по фронту | I29: =ROUND(0.6+0.6,9) -> 1.2 | J29: 0 | K29: =ROUND(0.6+0.6,9) -> 1.2 | O29: =ROUND(CP29,2) -> 217.77 | P29: =ROUND((ROUND((AC29*AW29*I29),2)*BC29),2) -> 28.39 | Q29: =(ROUND((ROUND((((ET29*1.1))*AV29*I29),2)*BB29),2)+ROUND((ROUND(((AE29-((EU29*1.1)))*AV29*I29),2)*BS29),2)) -> 78.43 | R29: =ROUND((ROUND((AE29*AV29*I29),2)*BS29),2) -> 9.41 | S29: =ROUND((ROUND((AF29*AV29*I29),2)*BA29),2) -> 110.95 | T29: =ROUND(CU29*I29,2) -> 0 | U29: =CV29*I29 -> 8.5410072 | V29: =CW29*I29 -> 0 | W29: =ROUND(CX29*I29,2) -> 0 | X29: =ROUND(CY29,2) -> 116.75 | Y29: =ROUND(CZ29,2) -> 61.38 | AA29: 60252778 | AB29: =ROUND((AC29+AD29+AF29),6) -> 174.393 | AC29: =ROUND((ES29),6) -> 23.66 | AD29: =ROUND(((((ET29*1.1))-((EU29*1.1)))+AE29),6) -> 62.425 | AE29: =ROUND(((EU29*1.1)),6) -> 7.491 | AF29: =ROUND(((EV29*1.1)),6) -> 88.308 | AG29: =ROUND((AP29),6) -> 0 | AH29: =((EW29*1.1)) -> 6.798 | AI29: =((EX29*1.1)) -> 0 | AJ29: =(AS29) -> 0 | AK29: 160.69 | AL29: 23.66 | AM29: 56.75 | AN29: 6.81 | AO29: 80.28 | AP29: 0 | AQ29: 6.18 | AR29: 0 | AS29: 0 | AT29: 97 | AU29: 51 | AV29: 1.047 | AW29: 1 | AZ29: 1 | BA29: 1 | BB29: 1 | BC29: 1 | BH29: 0 | BI29: 2 | BJ29: ТСН-2001.4 Доп. 79, Сб. 8, т. 238, поз. 3 | BM29: 67 | BN29: 59540665 | BO29: 4.8-238-3 | BP29: 1 | BQ29: 40 | BR29: 0 | BS29: 1 | BT29: 1 | BU29: 1 | BV29: 1 | BW29: 1 | BX29: 1 | BZ29: 97 | CA29: 51 | CE29: 30 | CF29: 0 | CG29: 0 | CM29: 0 | CN29: Поправка: О.П. п.3.4.30.в Наименование: При применении территориальных сметных нормативов для города Москвы затраты, учитывающие напряженные и стесненные условия производства работ (стесненность, сложность складирования и транспортной логистики и т.п.), исчисляются с применением коэффициентов к затратам труда и заработной плате рабочих, машинистов, времени эксплуатации машин и механизмов, стоимости эксплуатации машин в размере: для объектов, расположенных за пределами Третьего транспортного кольца города Москвы, но в пределах Московской кольцевой автомобильной дороги | CO29: 0 | CP29: =(P29+Q29+S29) -> 217.77 | CQ29: =ROUND((ROUND((AC29*AW29*1),2)*BC29),2) -> 23.66 | CR29: =(ROUND((ROUND((((ET29*1.1))*AV29*1),2)*BB29),2)+ROUND((ROUND(((AE29-((EU29*1.1)))*AV29*1),2)*BS29),2)) -> 65.36 | CS29: =ROUND((ROUND((AE29*AV29*1),2)*BS29),2) -> 7.84 | CT29: =ROUND((ROUND((AF29*AV29*1),2)*BA29),2) -> 92.46 | CU29: =AG29 -> 0 | CV29: =(AH29*AV29) -> 7.117506 | CW29: =AI29 -> 0 | CX29: =AJ29 -> 0 | CY29: =(((S29+R29)*AT29)/100) -> 116.7492 | CZ29: =(((S29+R29)*AU29)/100) -> 61.3836 | DB29: 1 | DE29: *1,1 | DF29: *1,1 | DG29: *1,1 | DI29: *1,1 | DJ29: *1,1 | DN29: 0 | DO29: 0 | DP29: 1 | DQ29: 1 | DU29: 1013 | DV29: 1 м ширины по фронту | DW29: 1 м ширины по фронту | DX29: 1 | EE29: 59540733 | EF29: 40 | EG29: Монтаж оборудования | EH29: 0 | EJ29: 2 | EK29: 67 | EL29: ТСН-2001.4-8. Электротехнические установки | EM29: ТСН-2001.4-8-1 | EO29: Поправка: О.П. п.3.4.30.в | EQ29: 0 | ER29: 160.69 | ES29: 23.66 | ET29: 56.75 | EU29: 6.81 | EV29: 80.28 | EW29: 6.18 | EX29: 0 | EY29: 0 | FQ29: 0 | FR29: 0 | FS29: 0 | FX29: 97 | FY29: 51 | GD29: 1 | GF29: 373468362 | GG29: 2 | GH29: 1 | GI29: 2 | GJ29: 0 | GK29: 0 | GL29: =ROUND(IF(AND(BH29=3,BI29=3,FS29<>0),P29,0),2) -> 0 | GM29: =ROUND(O29+X29+Y29,2)+GX29 -> 395.9 | GN29: =IF(OR(BI29=0,BI29=1),GM29-GX29,0) -> 0 | GO29: =IF(BI29=2,GM29-GX29,0) -> 395.9 | GP29: =IF(BI29=4,GM29-GX29,0) -> 0 | GR29: 0 | GS29: 3 | GT29: 0 | GV29: =ROUND((GT29),6) -> 0 | GW29: 1 | GX29: =ROUND(HC29*I29,2) -> 0 | HA29: 0 | HB29: 0 | HC29: =GV29*GW29 -> 0 | HS29: 0 | IK29: 0
A30: 17 | B30: 1 | C30: =ROW(SmtRes!A16) -> 16 | D30: =ROW(EtalonRes!A18) -> 18 | E30: 1 | F30: 4.8-238-3 | G30: Монтаж щитов и стеллажей с блоками резисторов (ящиками сопротивлений) высотой свыше 1700 мм, щита заводского изготовления однорядного или двухрядного открытого исполнения шириной 800 мм | H30: 1 м ширины по фронту | I30: =ROUND(0.6+0.6,9) -> 1.2 | J30: 0 | K30: =ROUND(0.6+0.6,9) -> 1.2 | O30: =ROUND(CP30,2) -> 7527.67 | P30: =ROUND((ROUND((AC30*AW30*I30),2)*BC30),2) -> 226.55 | Q30: =(ROUND((ROUND((((ET30*1.1))*AV30*I30),2)*BB30),2)+ROUND((ROUND(((AE30-((EU30*1.1)))*AV30*I30),2)*BS30),2)) -> 1199.98 | R30: =ROUND((ROUND((AE30*AV30*I30),2)*BS30),2) -> 517.46 | S30: =ROUND((ROUND((AF30*AV30*I30),2)*BA30),2) -> 6101.14 | T30: =ROUND(CU30*I30,2) -> 0 | U30: =CV30*I30 -> 8.5410072 | V30: =CW30*I30 -> 0 | W30: =ROUND(CX30*I30,2) -> 0 | X30: =ROUND(CY30,2) -> 6420.04 | Y30: =ROUND(CZ30,2) -> 3375.49 | AA30: 60252775 | AB30: =ROUND((AC30+AD30+AF30),6) -> 174.393 | AC30: =ROUND((ES30),6) -> 23.66 | AD30: =ROUND(((((ET30*1.1))-((EU30*1.1)))+AE30),6) -> 62.425 | AE30: =ROUND(((EU30*1.1)),6) -> 7.491 | AF30: =ROUND(((EV30*1.1)),6) -> 88.308 | AG30: =ROUND((AP30),6) -> 0 | AH30: =((EW30*1.1)) -> 6.798 | AI30: =((EX30*1.1)) -> 0 | AJ30: =(AS30) -> 0 | AK30: 160.69 | AL30: 23.66 | AM30: 56.75 | AN30: 6.81 | AO30: 80.28 | AP30: 0 | AQ30: 6.18 | AR30: 0 | AS30: 0 | AT30: 97 | AU30: 51 | AV30: 1.047 | AW30: 1 | AZ30: 1 | BA30: 54.99 | BB30: 15.3 | BC30: 7.98 | BH30: 0 | BI30: 2 | BJ30: ТСН-2001.4 Доп. 79, Сб. 8, т. 238, поз. 3 | BM30: 67 | BN30: 59540665 | BO30: 4.8-238-3 | BP30: 1 | BQ30: 40 | BR30: 0 | BS30: 54.99 | BT30: 1 | BU30: 1 | BV30: 1 | BW30: 1 | BX30: 1 | BZ30: 97 | CA30: 51 | CE30: 30 | CF30: 0 | CG30: 0 | CM30: 0 | CN30: Поправка: О.П. п.3.4.30.в Наименование: При применении территориальных сметных нормативов для города Москвы затраты, учитывающие напряженные и стесненные условия производства работ (стесненность, сложность складирования и транспортной логистики и т.п.), исчисляются с применением коэффициентов к затратам труда и заработной плате рабочих, машинистов, времени эксплуатации машин и механизмов, стоимости эксплуатации машин в размере: для объектов, расположенных за пределами Третьего транспортного кольца города Москвы, но в пределах Московской кольцевой автомобильной дороги | CO30: 0 | CP30: =(P30+Q30+S30) -> 7527.67 | CQ30: =ROUND((ROUND((AC30*AW30*1),2)*BC30),2) -> 188.81 | CR30: =(ROUND((ROUND((((ET30*1.1))*AV30*1),2)*BB30),2)+ROUND((ROUND(((AE30-((EU30*1.1)))*AV30*1),2)*BS30),2)) -> 1000.01 | CS30: =ROUND((ROUND((AE30*AV30*1),2)*BS30),2) -> 431.12 | CT30: =ROUND((ROUND((AF30*AV30*1),2)*BA30),2) -> 5084.38 | CU30: =AG30 -> 0 | CV30: =(AH30*AV30) -> 7.117506 | CW30: =AI30 -> 0 | CX30: =AJ30 -> 0 | CY30: =(((S30+R30)*AT30)/100) -> 6420.042 | CZ30: =(((S30+R30)*AU30)/100) -> 3375.486 | DB30: 2 | DE30: *1,1 | DF30: *1,1 | DG30: *1,1 | DI30: *1,1 | DJ30: *1,1 | DN30: 0 | DO30: 0 | DP30: 1 | DQ30: 1 | DU30: 1013 | DV30: 1 м ширины по фронту | DW30: 1 м ширины по фронту | DX30: 1 | EE30: 59540733 | EF30: 40 | EG30: Монтаж оборудования | EH30: 0 | EJ30: 2 | EK30: 67 | EL30: ТСН-2001.4-8. Электротехнические установки | EM30: ТСН-2001.4-8-1 | EO30: Поправка: О.П. п.3.4.30.в | EQ30: 0 | ER30: 160.69 | ES30: 23.66 | ET30: 56.75 | EU30: 6.81 | EV30: 80.28 | EW30: 6.18 | EX30: 0 | EY30: 0 | FQ30: 0 | FR30: 0 | FS30: 0 | FX30: 97 | FY30: 51 | GD30: 1 | GF30: 373468362 | GG30: 2 | GH30: 1 | GI30: 2 | GJ30: 0 | GK30: 0 | GL30: =ROUND(IF(AND(BH30=3,BI30=3,FS30<>0),P30,0),2) -> 0 | GM30: =ROUND(O30+X30+Y30,2)+GX30 -> 17323.2 | GN30: =IF(OR(BI30=0,BI30=1),GM30-GX30,0) -> 0 | GO30: =IF(BI30=2,GM30-GX30,0) -> 17323.2 | GP30: =IF(BI30=4,GM30-GX30,0) -> 0 | GR30: 0 | GS30: 3 | GT30: 0 | GV30: =ROUND((GT30),6) -> 0 | GW30: 1 | GX30: =ROUND(HC30*I30,2) -> 0 | HA30: 0 | HB30: 0 | HC30: =GV30*GW30 -> 0 | HS30: 0 | IK30: 0
A31: 18 | B31: 1 | C31: 7 | E31: 1,1 | F31: 1.1-1-58 | G31: Болты строительные с гайками, оцинкованные, М10х100 мм | H31: т | I31: =I29*J31 -> 0.000612 | J31: 0.00051 | K31: 0.00051 | O31: =ROUND(CP31,2) -> 15.06 | P31: =ROUND((ROUND((AC31*AW31*I31),2)*BC31),2) -> 15.06 | Q31: =(ROUND((ROUND(((ET31)*AV31*I31),2)*BB31),2)+ROUND((ROUND(((AE31-(EU31))*AV31*I31),2)*BS31),2)) -> 0 | R31: =ROUND((ROUND((AE31*AV31*I31),2)*BS31),2) -> 0 | S31: =ROUND((ROUND((AF31*AV31*I31),2)*BA31),2) -> 0 | T31: =ROUND(CU31*I31,2) -> 0 | U31: =CV31*I31 -> 0 | V31: =CW31*I31 -> 0 | W31: =ROUND(CX31*I31,2) -> 0 | X31: =ROUND(CY31,2) -> 0 | Y31: =ROUND(CZ31,2) -> 0 | AA31: 60252778 | AB31: =ROUND((AC31+AD31+AF31),6) -> 24609.76 | AC31: =ROUND((ES31),6) -> 24609.76 | AD31: =ROUND((((ET31)-(EU31))+AE31),6) -> 0 | AE31: =ROUND((EU31),6) -> 0 | AF31: =ROUND((EV31),6) -> 0 | AG31: =ROUND((AP31),6) -> 0 | AH31: =(EW31) -> 0 | AI31: =(EX31) -> 0 | AJ31: =(AS31) -> 0 | AK31: 24609.76 | AL31: 24609.76 | AM31: 0 | AN31: 0 | AO31: 0 | AP31: 0 | AQ31: 0 | AR31: 0 | AS31: 0 | AT31: 97 | AU31: 51 | AV31: 1 | AW31: 1 | AZ31: 1 | BA31: 1 | BB31: 1 | BC31: 1 | BH31: 3 | BI31: 2 | BJ31: ТСН-2001.1 Доп. 79, Р. 1, о. 1, поз. 58 | BM31: 67 | BN31: 59540665 | BP31: 0 | BQ31: 40 | BR31: 0 | BS31: 1 | BT31: 1 | BU31: 1 | BV31: 1 | BW31: 1 | BX31: 1 | BZ31: 97 | CA31: 51 | CE31: 30 | CF31: 0 | CG31: 0 | CM31: 0 | CO31: 0 | CP31: =(P31+Q31+S31) -> 15.06 | CQ31: =ROUND((ROUND((AC31*AW31*1),2)*BC31),2) -> 24609.76 | CR31: =(ROUND((ROUND(((ET31)*AV31*1),2)*BB31),2)+ROUND((ROUND(((AE31-(EU31))*AV31*1),2)*BS31),2)) -> 0 | CS31: =ROUND((ROUND((AE31*AV31*1),2)*BS31),2) -> 0 | CT31: =ROUND((ROUND((AF31*AV31*1),2)*BA31),2) -> 0 | CU31: =AG31 -> 0 | CV31: =(AH31*AV31) -> 0 | CW31: =AI31 -> 0 | CX31: =AJ31 -> 0 | CY31: =(((S31+R31)*AT31)/100) -> 0 | CZ31: =(((S31+R31)*AU31)/100) -> 0 | DN31: 0 | DO31: 0 | DP31: 1 | DQ31: 1 | DU31: 1009 | DV31: т | DW31: т | DX31: 1000 | EE31: 59540733 | EF31: 40 | EG31: Монтаж оборудования | EH31: 0 | EJ31: 2 | EK31: 67 | EL31: ТСН-2001.4-8. Электротехнические установки | EM31: ТСН-2001.4-8-1 | EQ31: 0 | ER31: 24609.76 | ES31: 24609.76 | ET31: 0 | EU31: 0 | EV31: 0 | EW31: 0 | EX31: 0 | FQ31: 0 | FR31: 0 | FS31: 0 | FX31: 97 | FY31: 51 | GD31: 1 | GF31: -566361729 | GG31: 2 | GH31: 1 | GI31: -2 | GJ31: 0 | GK31: 0 | GL31: =ROUND(IF(AND(BH31=3,BI31=3,FS31<>0),P31,0),2) -> 0 | GM31: =ROUND(O31+X31+Y31,2)+GX31 -> 15.06 | GN31: =IF(OR(BI31=0,BI31=1),GM31-GX31,0) -> 0 | GO31: =IF(BI31=2,GM31-GX31,0) -> 15.06 | GP31: =IF(BI31=4,GM31-GX31,0) -> 0 | GR31: 0 | GS31: 3 | GT31: 0 | GV31: =ROUND((GT31),6) -> 0 | GW31: 1 | GX31: =ROUND(HC31*I31,2) -> 0 | HA31: 0 | HB31: 0 | HC31: =GV31*GW31 -> 0 | HS31: 0 | IK31: 0
A32: 18 | B32: 1 | C32: 15 | E32: 1,1 | F32: 1.1-1-58 | G32: Болты строительные с гайками, оцинкованные, М10х100 мм | H32: т | I32: =I30*J32 -> 0.000612 | J32: 0.00051 | K32: 0.00051 | O32: =ROUND(CP32,2) -> 77.56 | P32: =ROUND((ROUND((AC32*AW32*I32),2)*BC32),2) -> 77.56 | Q32: =(ROUND((ROUND(((ET32)*AV32*I32),2)*BB32),2)+ROUND((ROUND(((AE32-(EU32))*AV32*I32),2)*BS32),2)) -> 0 | R32: =ROUND((ROUND((AE32*AV32*I32),2)*BS32),2) -> 0 | S32: =ROUND((ROUND((AF32*AV32*I32),2)*BA32),2) -> 0 | T32: =ROUND(CU32*I32,2) -> 0 | U32: =CV32*I32 -> 0 | V32: =CW32*I32 -> 0 | W32: =ROUND(CX32*I32,2) -> 0 | X32: =ROUND(CY32,2) -> 0 | Y32: =ROUND(CZ32,2) -> 0 | AA32: 60252775 | AB32: =ROUND((AC32+AD32+AF32),6) -> 24609.76 | AC32: =ROUND((ES32),6) -> 24609.76 | AD32: =ROUND((((ET32)-(EU32))+AE32),6) -> 0 | AE32: =ROUND((EU32),6) -> 0 | AF32: =ROUND((EV32),6) -> 0 | AG32: =ROUND((AP32),6) -> 0 | AH32: =(EW32) -> 0 | AI32: =(EX32) -> 0 | AJ32: =(AS32) -> 0 | AK32: 24609.76 | AL32: 24609.76 | AM32: 0 | AN32: 0 | AO32: 0 | AP32: 0 | AQ32: 0 | AR32: 0 | AS32: 0 | AT32: 97 | AU32: 51 | AV32: 1 | AW32: 1 | AZ32: 1 | BA32: 1 | BB32: 1 | BC32: 5.15 | BH32: 3 | BI32: 2 | BJ32: ТСН-2001.1 Доп. 79, Р. 1, о. 1, поз. 58 | BM32: 67 | BN32: 59540665 | BO32: 1.1-1-58 | BP32: 1 | BQ32: 40 | BR32: 0 | BS32: 1 | BT32: 1 | BU32: 1 | BV32: 1 | BW32: 1 | BX32: 1 | BZ32: 97 | CA32: 51 | CE32: 30 | CF32: 0 | CG32: 0 | CM32: 0 | CO32: 0 | CP32: =(P32+Q32+S32) -> 77.56 | CQ32: =ROUND((ROUND((AC32*AW32*1),2)*BC32),2) -> 126740.26 | CR32: =(ROUND((ROUND(((ET32)*AV32*1),2)*BB32),2)+ROUND((ROUND(((AE32-(EU32))*AV32*1),2)*BS32),2)) -> 0 | CS32: =ROUND((ROUND((AE32*AV32*1),2)*BS32),2) -> 0 | CT32: =ROUND((ROUND((AF32*AV32*1),2)*BA32),2) -> 0 | CU32: =AG32 -> 0 | CV32: =(AH32*AV32) -> 0 | CW32: =AI32 -> 0 | CX32: =AJ32 -> 0 | CY32: =(((S32+R32)*AT32)/100) -> 0 | CZ32: =(((S32+R32)*AU32)/100) -> 0 | DN32: 0 | DO32: 0 | DP32: 1 | DQ32: 1 | DU32: 1009 | DV32: т | DW32: т | DX32: 1000 | EE32: 59540733 | EF32: 40 | EG32: Монтаж оборудования | EH32: 0 | EJ32: 2 | EK32: 67 | EL32: ТСН-2001.4-8. Электротехнические установки | EM32: ТСН-2001.4-8-1 | EQ32: 0 | ER32: 24609.76 | ES32: 24609.76 | ET32: 0 | EU32: 0 | EV32: 0 | EW32: 0 | EX32: 0 | FQ32: 0 | FR32: 0 | FS32: 0 | FX32: 97 | FY32: 51 | GD32: 1 | GF32: -566361729 | GG32: 2 | GH32: 1 | GI32: 2 | GJ32: 0 | GK32: 0 | GL32: =ROUND(IF(AND(BH32=3,BI32=3,FS32<>0),P32,0),2) -> 0 | GM32: =ROUND(O32+X32+Y32,2)+GX32 -> 77.56 | GN32: =IF(OR(BI32=0,BI32=1),GM32-GX32,0) -> 0 | GO32: =IF(BI32=2,GM32-GX32,0) -> 77.56 | GP32: =IF(BI32=4,GM32-GX32,0) -> 0 | GR32: 0 | GS32: 3 | GT32: 0 | GV32: =ROUND((GT32),6) -> 0 | GW32: 1 | GX32: =ROUND(HC32*I32,2) -> 0 | HA32: 0 | HB32: 0 | HC32: =GV32*GW32 -> 0 | HS32: 0 | IK32: 0
A33: 17 | B33: 1 | E33: 2 | F33: КА-1 | G33: Вводная панель ВП1 | H33: ШТ | I33: 1 | J33: 0 | K33: 1 | O33: =ROUND(CP33,2) -> 60887.82 | P33: =ROUND((ROUND((AC33*I33),2)*BC33),2) -> 60887.82 | Q33: =(ROUND((ROUND(((ET33)*AV33*I33),2)*BB33),2)+ROUND((ROUND(((AE33-(EU33))*AV33*I33),2)*BS33),2)) -> 0 | R33: =ROUND((ROUND((AE33*AV33*I33),2)*BS33),2) -> 0 | S33: =ROUND((ROUND((AF33*AV33*I33),2)*BA33),2) -> 0 | T33: =ROUND(CU33*I33,2) -> 0 | U33: =CV33*I33 -> 0 | V33: =CW33*I33 -> 0 | W33: =ROUND(CX33*I33,2) -> 0 | X33: =ROUND(CY33,2) -> 0 | Y33: =ROUND(CZ33,2) -> 0 | AA33: 60252778 | AB33: =ROUND((AC33+AD33+AF33),6) -> 60887.82 | AC33: =ROUND((ES33),6) -> 60887.82 | AD33: =ROUND((((ET33)-(EU33))+AE33),6) -> 0 | AE33: =ROUND((EU33),6) -> 0 | AF33: =ROUND((EV33),6) -> 0 | AG33: =ROUND((AP33),6) -> 0 | AH33: =(EW33) -> 0 | AI33: =(EX33) -> 0 | AJ33: =(AS33) -> 0 | AK33: 60887.82 | AL33: 60887.82 | AM33: 0 | AN33: 0 | AO33: 0 | AP33: 0 | AQ33: 0 | AR33: 0 | AS33: 0 | AT33: 0 | AU33: 0 | AV33: 1 | AW33: 1 | AZ33: 1 | BA33: 1 | BB33: 1 | BC33: 1 | BH33: 3 | BI33: 3 | BM33: 746 | BN33: 0 | BP33: 0 | BQ33: 130 | BR33: 0 | BS33: 1 | BT33: 1 | BU33: 1 | BV33: 1 | BW33: 1 | BX33: 1 | BZ33: 0 | CA33: 0 | CE33: 30 | CF33: 0 | CG33: 0 | CM33: 0 | CO33: 0 | CP33: =(P33+Q33+S33) -> 60887.82 | CQ33: =ROUND((ROUND((AC33*1),2)*BC33),2) -> 60887.82 | CR33: =(ROUND((ROUND(((ET33)*AV33*1),2)*BB33),2)+ROUND((ROUND(((AE33-(EU33))*AV33*1),2)*BS33),2)) -> 0 | CS33: =ROUND((ROUND((AE33*AV33*1),2)*BS33),2) -> 0 | CT33: =ROUND((ROUND((AF33*AV33*1),2)*BA33),2) -> 0 | CU33: =AG33 -> 0 | CV33: =(AH33*AV33) -> 0 | CW33: =AI33 -> 0 | CX33: =AJ33 -> 0 | CY33: =(((S33+R33)*AT33)/100) -> 0 | CZ33: =(((S33+R33)*AU33)/100) -> 0 | DN33: 0 | DO33: 0 | DP33: 1 | DQ33: 1 | DU33: 1013 | DV33: ШТ | DW33: ШТ | DX33: 1 | EE33: 59540854 | EF33: 130 | EG33: Сметная стоимость оборудования | EH33: 0 | EJ33: 3 | EK33: 746 | EL33: ТСН-2001.13. Сметная стоимость оборудования | EM33: ТСН-2001.13 | EQ33: 0 | ER33: 0 | ES33: 60887.82 | ET33: 0 | EU33: 0 | EV33: 0 | EW33: 0 | EX33: 0 | EY33: 0 | FQ33: 0 | FR33: =P33 -> 60887.82 | FS33: 0 | FX33: 0 | FY33: 0 | GA33: [536 936,24 / 1,2 / 7,66] + 3% Трансп + 1,2% Заг.скл | GD33: 1 | GF33: 1316245378 | GG33: 2 | GH33: 4 | GI33: -2 | GJ33: 0 | GK33: 0 | GL33: =ROUND(IF(AND(BH33=3,BI33=3,FS33<>0),P33,0),2) -> 0 | GM33: =ROUND(O33+X33+Y33,2)+GX33 -> 60887.82 | GN33: =IF(OR(BI33=0,BI33=1),GM33-GX33,0) -> 0 | GO33: =IF(BI33=2,GM33-GX33,0) -> 0 | GP33: =IF(BI33=4,GM33-GX33,0) -> 0 | GR33: 0 | GS33: 2 | GT33: 0 | GV33: =ROUND((GT33),6) -> 0 | GW33: 1 | GX33: =ROUND(HC33*I33,2) -> 0 | HA33: 0 | HB33: 0 | HC33: =GV33*GW33 -> 0 | HE33: 3 | HF33: 1,2 | HS33: 0 | IK33: 0
A34: 17 | B34: 1 | E34: 2 | F34: КА-1 | G34: Вводная панель ВП1 | H34: ШТ | I34: 1 | J34: 0 | K34: 1 | O34: =ROUND(CP34,2) -> 466400.7 | P34: =ROUND((ROUND((AC34*I34),2)*BC34),2) -> 466400.7 | Q34: =(ROUND((ROUND(((ET34)*AV34*I34),2)*BB34),2)+ROUND((ROUND(((AE34-(EU34))*AV34*I34),2)*BS34),2)) -> 0 | R34: =ROUND((ROUND((AE34*AV34*I34),2)*BS34),2) -> 0 | S34: =ROUND((ROUND((AF34*AV34*I34),2)*BA34),2) -> 0 | T34: =ROUND(CU34*I34,2) -> 0 | U34: =CV34*I34 -> 0 | V34: =CW34*I34 -> 0 | W34: =ROUND(CX34*I34,2) -> 0 | X34: =ROUND(CY34,2) -> 0 | Y34: =ROUND(CZ34,2) -> 0 | AA34: 60252775 | AB34: =ROUND((AC34+AD34+AF34),6) -> 60887.82 | AC34: =ROUND((ES34),6) -> 60887.82 | AD34: =ROUND((((ET34)-(EU34))+AE34),6) -> 0 | AE34: =ROUND((EU34),6) -> 0 | AF34: =ROUND((EV34),6) -> 0 | AG34: =ROUND((AP34),6) -> 0 | AH34: =(EW34) -> 0 | AI34: =(EX34) -> 0 | AJ34: =(AS34) -> 0 | AK34: 60887.82 | AL34: 60887.82 | AM34: 0 | AN34: 0 | AO34: 0 | AP34: 0 | AQ34: 0 | AR34: 0 | AS34: 0 | AT34: 0 | AU34: 0 | AV34: 1 | AW34: 1 | AZ34: 1 | BA34: 1 | BB34: 1 | BC34: 7.66 | BH34: 3 | BI34: 3 | BM34: 746 | BN34: 0 | BP34: 0 | BQ34: 130 | BR34: 0 | BS34: 1 | BT34: 1 | BU34: 1 | BV34: 1 | BW34: 1 | BX34: 1 | BZ34: 0 | CA34: 0 | CE34: 30 | CF34: 0 | CG34: 0 | CM34: 0 | CO34: 0 | CP34: =(P34+Q34+S34) -> 466400.7 | CQ34: =ROUND((ROUND((AC34*1),2)*BC34),2) -> 466400.7 | CR34: =(ROUND((ROUND(((ET34)*AV34*1),2)*BB34),2)+ROUND((ROUND(((AE34-(EU34))*AV34*1),2)*BS34),2)) -> 0 | CS34: =ROUND((ROUND((AE34*AV34*1),2)*BS34),2) -> 0 | CT34: =ROUND((ROUND((AF34*AV34*1),2)*BA34),2) -> 0 | CU34: =AG34 -> 0 | CV34: =(AH34*AV34) -> 0 | CW34: =AI34 -> 0 | CX34: =AJ34 -> 0 | CY34: =(((S34+R34)*AT34)/100) -> 0 | CZ34: =(((S34+R34)*AU34)/100) -> 0 | DN34: 0 | DO34: 0 | DP34: 1 | DQ34: 1 | DU34: 1013 | DV34: ШТ | DW34: ШТ | DX34: 1 | EE34: 59540854 | EF34: 130 | EG34: Сметная стоимость оборудования | EH34: 0 | EJ34: 3 | EK34: 746 | EL34: ТСН-2001.13. Сметная стоимость оборудования | EM34: ТСН-2001.13 | EQ34: 0 | ER34: 60887.82 | ES34: 60887.82 | ET34: 0 | EU34: 0 | EV34: 0 | EW34: 0 | EX34: 0 | EY34: 0 | EZ34: 5 | FC34: 1 | FD34: 18 | FF34: 536936.24 | FQ34: 0 | FR34: =P34 -> 466400.7 | FS34: 0 | FX34: 0 | FY34: 0 | GA34: [536 936,24 / 1,2 / 7,66] + 3% Трансп + 1,2% Заг.скл | GD34: 1 | GF34: 1316245378 | GG34: 2 | GH34: 3 | GI34: 5 | GJ34: 0 | GK34: 0 | GL34: =ROUND(IF(AND(BH34=3,BI34=3,FS34<>0),P34,0),2) -> 0 | GM34: =ROUND(O34+X34+Y34,2)+GX34 -> 466400.7 | GN34: =IF(OR(BI34=0,BI34=1),GM34-GX34,0) -> 0 | GO34: =IF(BI34=2,GM34-GX34,0) -> 0 | GP34: =IF(BI34=4,GM34-GX34,0) -> 0 | GR34: 1 | GS34: 1 | GT34: 0 | GV34: =ROUND((GT34),6) -> 0 | GW34: 1 | GX34: =ROUND(HC34*I34,2) -> 0 | HA34: 0 | HB34: 0 | HC34: =GV34*GW34 -> 0 | HE34: 3 | HF34: 1,2 | HS34: 0 | IK34: 0
A35: 17 | B35: 1 | E35: 3 | F35: КА-2 | G35: Вводная панель ВП1 | H35: ШТ | I35: 1 | J35: 0 | K35: 1 | O35: =ROUND(CP35,2) -> 44301.78 | P35: =ROUND((ROUND((AC35*I35),2)*BC35),2) -> 44301.78 | Q35: =(ROUND((ROUND(((ET35)*AV35*I35),2)*BB35),2)+ROUND((ROUND(((AE35-(EU35))*AV35*I35),2)*BS35),2)) -> 0 | R35: =ROUND((ROUND((AE35*AV35*I35),2)*BS35),2) -> 0 | S35: =ROUND((ROUND((AF35*AV35*I35),2)*BA35),2) -> 0 | T35: =ROUND(CU35*I35,2) -> 0 | U35: =CV35*I35 -> 0 | V35: =CW35*I35 -> 0 | W35: =ROUND(CX35*I35,2) -> 0 | X35: =ROUND(CY35,2) -> 0 | Y35: =ROUND(CZ35,2) -> 0 | AA35: 60252778 | AB35: =ROUND((AC35+AD35+AF35),6) -> 44301.78 | AC35: =ROUND((ES35),6) -> 44301.78 | AD35: =ROUND((((ET35)-(EU35))+AE35),6) -> 0 | AE35: =ROUND((EU35),6) -> 0 | AF35: =ROUND((EV35),6) -> 0 | AG35: =ROUND((AP35),6) -> 0 | AH35: =(EW35) -> 0 | AI35: =(EX35) -> 0 | AJ35: =(AS35) -> 0 | AK35: 44301.78 | AL35: 44301.78 | AM35: 0 | AN35: 0 | AO35: 0 | AP35: 0 | AQ35: 0 | AR35: 0 | AS35: 0 | AT35: 0 | AU35: 0 | AV35: 1 | AW35: 1 | AZ35: 1 | BA35: 1 | BB35: 1 | BC35: 1 | BH35: 3 | BI35: 3 | BM35: 746 | BN35: 0 | BP35: 0 | BQ35: 130 | BR35: 0 | BS35: 1 | BT35: 1 | BU35: 1 | BV35: 1 | BW35: 1 | BX35: 1 | BZ35: 0 | CA35: 0 | CE35: 30 | CF35: 0 | CG35: 0 | CM35: 0 | CO35: 0 | CP35: =(P35+Q35+S35) -> 44301.78 | CQ35: =ROUND((ROUND((AC35*1),2)*BC35),2) -> 44301.78 | CR35: =(ROUND((ROUND(((ET35)*AV35*1),2)*BB35),2)+ROUND((ROUND(((AE35-(EU35))*AV35*1),2)*BS35),2)) -> 0 | CS35: =ROUND((ROUND((AE35*AV35*1),2)*BS35),2) -> 0 | CT35: =ROUND((ROUND((AF35*AV35*1),2)*BA35),2) -> 0 | CU35: =AG35 -> 0 | CV35: =(AH35*AV35) -> 0 | CW35: =AI35 -> 0 | CX35: =AJ35 -> 0 | CY35: =(((S35+R35)*AT35)/100) -> 0 | CZ35: =(((S35+R35)*AU35)/100) -> 0 | DN35: 0 | DO35: 0 | DP35: 1 | DQ35: 1 | DU35: 1013 | DV35: ШТ | DW35: ШТ | DX35: 1 | EE35: 59540854 | EF35: 130 | EG35: Сметная стоимость оборудования | EH35: 0 | EJ35: 3 | EK35: 746 | EL35: ТСН-2001.13. Сметная стоимость оборудования | EM35: ТСН-2001.13 | EQ35: 0 | ER35: 0 | ES35: 44301.78 | ET35: 0 | EU35: 0 | EV35: 0 | EW35: 0 | EX35: 0 | EY35: 0 | FQ35: 0 | FR35: =P35 -> 44301.78 | FS35: 0 | FX35: 0 | FY35: 0 | GA35: [390 673,02 / 1,2 / 7,66] + 3% Трансп + 1,2% Заг.скл | GD35: 1 | GF35: -1527606560 | GG35: 2 | GH35: 4 | GI35: -2 | GJ35: 0 | GK35: 0 | GL35: =ROUND(IF(AND(BH35=3,BI35=3,FS35<>0),P35,0),2) -> 0 | GM35: =ROUND(O35+X35+Y35,2)+GX35 -> 44301.78 | GN35: =IF(OR(BI35=0,BI35=1),GM35-GX35,0) -> 0 | GO35: =IF(BI35=2,GM35-GX35,0) -> 0 | GP35: =IF(BI35=4,GM35-GX35,0) -> 0 | GR35: 0 | GS35: 2 | GT35: 0 | GV35: =ROUND((GT35),6) -> 0 | GW35: 1 | GX35: =ROUND(HC35*I35,2) -> 0 | HA35: 0 | HB35: 0 | HC35: =GV35*GW35 -> 0 | HE35: 3 | HF35: 1,2 | HS35: 0 | IK35: 0
A36: 17 | B36: 1 | E36: 3 | F36: КА-2 | G36: Вводная панель ВП1 | H36: ШТ | I36: 1 | J36: 0 | K36: 1 | O36: =ROUND(CP36,2) -> 339351.63 | P36: =ROUND((ROUND((AC36*I36),2)*BC36),2) -> 339351.63 | Q36: =(ROUND((ROUND(((ET36)*AV36*I36),2)*BB36),2)+ROUND((ROUND(((AE36-(EU36))*AV36*I36),2)*BS36),2)) -> 0 | R36: =ROUND((ROUND((AE36*AV36*I36),2)*BS36),2) -> 0 | S36: =ROUND((ROUND((AF36*AV36*I36),2)*BA36),2) -> 0 | T36: =ROUND(CU36*I36,2) -> 0 | U36: =CV36*I36 -> 0 | V36: =CW36*I36 -> 0 | W36: =ROUND(CX36*I36,2) -> 0 | X36: =ROUND(CY36,2) -> 0 | Y36: =ROUND(CZ36,2) -> 0 | AA36: 60252775 | AB36: =ROUND((AC36+AD36+AF36),6) -> 44301.78 | AC36: =ROUND((ES36),6) -> 44301.78 | AD36: =ROUND((((ET36)-(EU36))+AE36),6) -> 0 | AE36: =ROUND((EU36),6) -> 0 | AF36: =ROUND((EV36),6) -> 0 | AG36: =ROUND((AP36),6) -> 0 | AH36: =(EW36) -> 0 | AI36: =(EX36) -> 0 | AJ36: =(AS36) -> 0 | AK36: 44301.78 | AL36: 44301.78 | AM36: 0 | AN36: 0 | AO36: 0 | AP36: 0 | AQ36: 0 | AR36: 0 | AS36: 0 | AT36: 0 | AU36: 0 | AV36: 1 | AW36: 1 | AZ36: 1 | BA36: 1 | BB36: 1 | BC36: 7.66 | BH36: 3 | BI36: 3 | BM36: 746 | BN36: 0 | BP36: 0 | BQ36: 130 | BR36: 0 | BS36: 1 | BT36: 1 | BU36: 1 | BV36: 1 | BW36: 1 | BX36: 1 | BZ36: 0 | CA36: 0 | CE36: 30 | CF36: 0 | CG36: 0 | CM36: 0 | CO36: 0 | CP36: =(P36+Q36+S36) -> 339351.63 | CQ36: =ROUND((ROUND((AC36*1),2)*BC36),2) -> 339351.63 | CR36: =(ROUND((ROUND(((ET36)*AV36*1),2)*BB36),2)+ROUND((ROUND(((AE36-(EU36))*AV36*1),2)*BS36),2)) -> 0 | CS36: =ROUND((ROUND((AE36*AV36*1),2)*BS36),2) -> 0 | CT36: =ROUND((ROUND((AF36*AV36*1),2)*BA36),2) -> 0 | CU36: =AG36 -> 0 | CV36: =(AH36*AV36) -> 0 | CW36: =AI36 -> 0 | CX36: =AJ36 -> 0 | CY36: =(((S36+R36)*AT36)/100) -> 0 | CZ36: =(((S36+R36)*AU36)/100) -> 0 | DN36: 0 | DO36: 0 | DP36: 1 | DQ36: 1 | DU36: 1013 | DV36: ШТ | DW36: ШТ | DX36: 1 | EE36: 59540854 | EF36: 130 | EG36: Сметная стоимость оборудования | EH36: 0 | EJ36: 3 | EK36: 746 | EL36: ТСН-2001.13. Сметная стоимость оборудования | EM36: ТСН-2001.13 | EQ36: 0 | ER36: 44301.78 | ES36: 44301.78 | ET36: 0 | EU36: 0 | EV36: 0 | EW36: 0 | EX36: 0 | EY36: 0 | EZ36: 5 | FC36: 1 | FD36: 18 | FF36: 390673.02 | FQ36: 0 | FR36: =P36 -> 339351.63 | FS36: 0 | FX36: 0 | FY36: 0 | GA36: [390 673,02 / 1,2 / 7,66] + 3% Трансп + 1,2% Заг.скл | GD36: 1 | GF36: -1527606560 | GG36: 2 | GH36: 3 | GI36: 5 | GJ36: 0 | GK36: 0 | GL36: =ROUND(IF(AND(BH36=3,BI36=3,FS36<>0),P36,0),2) -> 0 | GM36: =ROUND(O36+X36+Y36,2)+GX36 -> 339351.63 | GN36: =IF(OR(BI36=0,BI36=1),GM36-GX36,0) -> 0 | GO36: =IF(BI36=2,GM36-GX36,0) -> 0 | GP36: =IF(BI36=4,GM36-GX36,0) -> 0 | GR36: 1 | GS36: 1 | GT36: 0 | GV36: =ROUND((GT36),6) -> 0 | GW36: 1 | GX36: =ROUND(HC36*I36,2) -> 0 | HA36: 0 | HB36: 0 | HC36: =GV36*GW36 -> 0 | HE36: 3 | HF36: 1,2 | HS36: 0 | IK36: 0
A37: 19 | B37: 1 | G37: Распределительная панель | AA37: 1 | IK37: 0
A38: 17 | B38: 1 | C38: =ROW(SmtRes!A24) -> 24 | D38: =ROW(EtalonRes!A27) -> 27 | E38: 4 | F38: 4.8-238-3 | G38: Монтаж щитов и стеллажей с блоками резисторов (ящиками сопротивлений) высотой свыше 1700 мм, щита заводского изготовления однорядного или двухрядного открытого исполнения шириной 800 мм | H38: 1 м ширины по фронту | I38: =ROUND(0.6+0.6,9) -> 1.2 | J38: 0 | K38: =ROUND(0.6+0.6,9) -> 1.2 | O38: =ROUND(CP38,2) -> 217.77 | P38: =ROUND((ROUND((AC38*AW38*I38),2)*BC38),2) -> 28.39 | Q38: =(ROUND((ROUND((((ET38*1.1))*AV38*I38),2)*BB38),2)+ROUND((ROUND(((AE38-((EU38*1.1)))*AV38*I38),2)*BS38),2)) -> 78.43 | R38: =ROUND((ROUND((AE38*AV38*I38),2)*BS38),2) -> 9.41 | S38: =ROUND((ROUND((AF38*AV38*I38),2)*BA38),2) -> 110.95 | T38: =ROUND(CU38*I38,2) -> 0 | U38: =CV38*I38 -> 8.5410072 | V38: =CW38*I38 -> 0 | W38: =ROUND(CX38*I38,2) -> 0 | X38: =ROUND(CY38,2) -> 116.75 | Y38: =ROUND(CZ38,2) -> 61.38 | AA38: 60252778 | AB38: =ROUND((AC38+AD38+AF38),6) -> 174.393 | AC38: =ROUND((ES38),6) -> 23.66 | AD38: =ROUND(((((ET38*1.1))-((EU38*1.1)))+AE38),6) -> 62.425 | AE38: =ROUND(((EU38*1.1)),6) -> 7.491 | AF38: =ROUND(((EV38*1.1)),6) -> 88.308 | AG38: =ROUND((AP38),6) -> 0 | AH38: =((EW38*1.1)) -> 6.798 | AI38: =((EX38*1.1)) -> 0 | AJ38: =(AS38) -> 0 | AK38: 160.69 | AL38: 23.66 | AM38: 56.75 | AN38: 6.81 | AO38: 80.28 | AP38: 0 | AQ38: 6.18 | AR38: 0 | AS38: 0 | AT38: 97 | AU38: 51 | AV38: 1.047 | AW38: 1 | AZ38: 1 | BA38: 1 | BB38: 1 | BC38: 1 | BH38: 0 | BI38: 2 | BJ38: ТСН-2001.4 Доп. 79, Сб. 8, т. 238, поз. 3 | BM38: 67 | BN38: 59540665 | BO38: 4.8-238-3 | BP38: 1 | BQ38: 40 | BR38: 0 | BS38: 1 | BT38: 1 | BU38: 1 | BV38: 1 | BW38: 1 | BX38: 1 | BZ38: 97 | CA38: 51 | CE38: 30 | CF38: 0 | CG38: 0 | CM38: 0 | CN38: Поправка: О.П. п.3.4.30.в Наименование: При применении территориальных сметных нормативов для города Москвы затраты, учитывающие напряженные и стесненные условия производства работ (стесненность, сложность складирования и транспортной логистики и т.п.), исчисляются с применением коэффициентов к затратам труда и заработной плате рабочих, машинистов, времени эксплуатации машин и механизмов, стоимости эксплуатации машин в размере: для объектов, расположенных за пределами Третьего транспортного кольца города Москвы, но в пределах Московской кольцевой автомобильной дороги | CO38: 0 | CP38: =(P38+Q38+S38) -> 217.77 | CQ38: =ROUND((ROUND((AC38*AW38*1),2)*BC38),2) -> 23.66 | CR38: =(ROUND((ROUND((((ET38*1.1))*AV38*1),2)*BB38),2)+ROUND((ROUND(((AE38-((EU38*1.1)))*AV38*1),2)*BS38),2)) -> 65.36 | CS38: =ROUND((ROUND((AE38*AV38*1),2)*BS38),2) -> 7.84 | CT38: =ROUND((ROUND((AF38*AV38*1),2)*BA38),2) -> 92.46 | CU38: =AG38 -> 0 | CV38: =(AH38*AV38) -> 7.117506 | CW38: =AI38 -> 0 | CX38: =AJ38 -> 0 | CY38: =(((S38+R38)*AT38)/100) -> 116.7492 | CZ38: =(((S38+R38)*AU38)/100) -> 61.3836 | DB38: 3 | DE38: *1,1 | DF38: *1,1 | DG38: *1,1 | DI38: *1,1 | DJ38: *1,1 | DN38: 0 | DO38: 0 | DP38: 1 | DQ38: 1 | DU38: 1013 | DV38: 1 м ширины по фронту | DW38: 1 м ширины по фронту | DX38: 1 | EE38: 59540733 | EF38: 40 | EG38: Монтаж оборудования | EH38: 0 | EJ38: 2 | EK38: 67 | EL38: ТСН-2001.4-8. Электротехнические установки | EM38: ТСН-2001.4-8-1 | EO38: Поправка: О.П. п.3.4.30.в | EQ38: 0 | ER38: 160.69 | ES38: 23.66 | ET38: 56.75 | EU38: 6.81 | EV38: 80.28 | EW38: 6.18 | EX38: 0 | EY38: 0 | FQ38: 0 | FR38: 0 | FS38: 0 | FX38: 97 | FY38: 51 | GD38: 1 | GF38: 373468362 | GG38: 2 | GH38: 1 | GI38: 2 | GJ38: 0 | GK38: 0 | GL38: =ROUND(IF(AND(BH38=3,BI38=3,FS38<>0),P38,0),2) -> 0 | GM38: =ROUND(O38+X38+Y38,2)+GX38 -> 395.9 | GN38: =IF(OR(BI38=0,BI38=1),GM38-GX38,0) -> 0 | GO38: =IF(BI38=2,GM38-GX38,0) -> 395.9 | GP38: =IF(BI38=4,GM38-GX38,0) -> 0 | GR38: 0 | GS38: 3 | GT38: 0 | GV38: =ROUND((GT38),6) -> 0 | GW38: 1 | GX38: =ROUND(HC38*I38,2) -> 0 | HA38: 0 | HB38: 0 | HC38: =GV38*GW38 -> 0 | HS38: 0 | IK38: 0
A39: 17 | B39: 1 | C39: =ROW(SmtRes!A32) -> 32 | D39: =ROW(EtalonRes!A36) -> 36 | E39: 4 | F39: 4.8-238-3 | G39: Монтаж щитов и стеллажей с блоками резисторов (ящиками сопротивлений) высотой свыше 1700 мм, щита заводского изготовления однорядного или двухрядного открытого исполнения шириной 800 мм | H39: 1 м ширины по фронту | I39: =ROUND(0.6+0.6,9) -> 1.2 | J39: 0 | K39: =ROUND(0.6+0.6,9) -> 1.2 | O39: =ROUND(CP39,2) -> 7527.67 | P39: =ROUND((ROUND((AC39*AW39*I39),2)*BC39),2) -> 226.55 | Q39: =(ROUND((ROUND((((ET39*1.1))*AV39*I39),2)*BB39),2)+ROUND((ROUND(((AE39-((EU39*1.1)))*AV39*I39),2)*BS39),2)) -> 1199.98 | R39: =ROUND((ROUND((AE39*AV39*I39),2)*BS39),2) -> 517.46 | S39: =ROUND((ROUND((AF39*AV39*I39),2)*BA39),2) -> 6101.14 | T39: =ROUND(CU39*I39,2) -> 0 | U39: =CV39*I39 -> 8.5410072 | V39: =CW39*I39 -> 0 | W39: =ROUND(CX39*I39,2) -> 0 | X39: =ROUND(CY39,2) -> 6420.04 | Y39: =ROUND(CZ39,2) -> 3375.49 | AA39: 60252775 | AB39: =ROUND((AC39+AD39+AF39),6) -> 174.393 | AC39: =ROUND((ES39),6) -> 23.66 | AD39: =ROUND(((((ET39*1.1))-((EU39*1.1)))+AE39),6) -> 62.425 | AE39: =ROUND(((EU39*1.1)),6) -> 7.491 | AF39: =ROUND(((EV39*1.1)),6) -> 88.308 | AG39: =ROUND((AP39),6) -> 0 | AH39: =((EW39*1.1)) -> 6.798 | AI39: =((EX39*1.1)) -> 0 | AJ39: =(AS39) -> 0 | AK39: 160.69 | AL39: 23.66 | AM39: 56.75 | AN39: 6.81 | AO39: 80.28 | AP39: 0 | AQ39: 6.18 | AR39: 0 | AS39: 0 | AT39: 97 | AU39: 51 | AV39: 1.047 | AW39: 1 | AZ39: 1 | BA39: 54.99 | BB39: 15.3 | BC39: 7.98 | BH39: 0 | BI39: 2 | BJ39: ТСН-2001.4 Доп. 79, Сб. 8, т. 238, поз. 3 | BM39: 67 | BN39: 59540665 | BO39: 4.8-238-3 | BP39: 1 | BQ39: 40 | BR39: 0 | BS39: 54.99 | BT39: 1 | BU39: 1 | BV39: 1 | BW39: 1 | BX39: 1 | BZ39: 97 | CA39: 51 | CE39: 30 | CF39: 0 | CG39: 0 | CM39: 0 | CN39: Поправка: О.П. п.3.4.30.в Наименование: При применении территориальных сметных нормативов для города Москвы затраты, учитывающие напряженные и стесненные условия производства работ (стесненность, сложность складирования и транспортной логистики и т.п.), исчисляются с применением коэффициентов к затратам труда и заработной плате рабочих, машинистов, времени эксплуатации машин и механизмов, стоимости эксплуатации машин в размере: для объектов, расположенных за пределами Третьего транспортного кольца города Москвы, но в пределах Московской кольцевой автомобильной дороги | CO39: 0 | CP39: =(P39+Q39+S39) -> 7527.67 | CQ39: =ROUND((ROUND((AC39*AW39*1),2)*BC39),2) -> 188.81 | CR39: =(ROUND((ROUND((((ET39*1.1))*AV39*1),2)*BB39),2)+ROUND((ROUND(((AE39-((EU39*1.1)))*AV39*1),2)*BS39),2)) -> 1000.01 | CS39: =ROUND((ROUND((AE39*AV39*1),2)*BS39),2) -> 431.12 | CT39: =ROUND((ROUND((AF39*AV39*1),2)*BA39),2) -> 5084.38 | CU39: =AG39 -> 0 | CV39: =(AH39*AV39) -> 7.117506 | CW39: =AI39 -> 0 | CX39: =AJ39 -> 0 | CY39: =(((S39+R39)*AT39)/100) -> 6420.042 | CZ39: =(((S39+R39)*AU39)/100) -> 3375.486 | DB39: 4 | DE39: *1,1 | DF39: *1,1 | DG39: *1,1 | DI39: *1,1 | DJ39: *1,1 | DN39: 0 | DO39: 0 | DP39: 1 | DQ39: 1 | DU39: 1013 | DV39: 1 м ширины по фронту | DW39: 1 м ширины по фронту | DX39: 1 | EE39: 59540733 | EF39: 40 | EG39: Монтаж оборудования | EH39: 0 | EJ39: 2 | EK39: 67 | EL39: ТСН-2001.4-8. Электротехнические установки | EM39: ТСН-2001.4-8-1 | EO39: Поправка: О.П. п.3.4.30.в | EQ39: 0 | ER39: 160.69 | ES39: 23.66 | ET39: 56.75 | EU39: 6.81 | EV39: 80.28 | EW39: 6.18 | EX39: 0 | EY39: 0 | FQ39: 0 | FR39: 0 | FS39: 0 | FX39: 97 | FY39: 51 | GD39: 1 | GF39: 373468362 | GG39: 2 | GH39: 1 | GI39: 2 | GJ39: 0 | GK39: 0 | GL39: =ROUND(IF(AND(BH39=3,BI39=3,FS39<>0),P39,0),2) -> 0 | GM39: =ROUND(O39+X39+Y39,2)+GX39 -> 17323.2 | GN39: =IF(OR(BI39=0,BI39=1),GM39-GX39,0) -> 0 | GO39: =IF(BI39=2,GM39-GX39,0) -> 17323.2 | GP39: =IF(BI39=4,GM39-GX39,0) -> 0 | GR39: 0 | GS39: 3 | GT39: 0 | GV39: =ROUND((GT39),6) -> 0 | GW39: 1 | GX39: =ROUND(HC39*I39,2) -> 0 | HA39: 0 | HB39: 0 | HC39: =GV39*GW39 -> 0 | HS39: 0 | IK39: 0
A40: 18 | B40: 1 | C40: 23 | E40: 4,1 | F40: 1.1-1-58 | G40: Болты строительные с гайками, оцинкованные, М10х100 мм | H40: т | I40: =I38*J40 -> 0.000612 | J40: 0.00051 | K40: 0.00051 | O40: =ROUND(CP40,2) -> 15.06 | P40: =ROUND((ROUND((AC40*AW40*I40),2)*BC40),2) -> 15.06 | Q40: =(ROUND((ROUND(((ET40)*AV40*I40),2)*BB40),2)+ROUND((ROUND(((AE40-(EU40))*AV40*I40),2)*BS40),2)) -> 0 | R40: =ROUND((ROUND((AE40*AV40*I40),2)*BS40),2) -> 0 | S40: =ROUND((ROUND((AF40*AV40*I40),2)*BA40),2) -> 0 | T40: =ROUND(CU40*I40,2) -> 0 | U40: =CV40*I40 -> 0 | V40: =CW40*I40 -> 0 | W40: =ROUND(CX40*I40,2) -> 0 | X40: =ROUND(CY40,2) -> 0 | Y40: =ROUND(CZ40,2) -> 0 | AA40: 60252778 | AB40: =ROUND((AC40+AD40+AF40),6) -> 24609.76 | AC40: =ROUND((ES40),6) -> 24609.76 | AD40: =ROUND((((ET40)-(EU40))+AE40),6) -> 0 | AE40: =ROUND((EU40),6) -> 0 | AF40: =ROUND((EV40),6) -> 0 | AG40: =ROUND((AP40),6) -> 0 | AH40: =(EW40) -> 0 | AI40: =(EX40) -> 0 | AJ40: =(AS40) -> 0 | AK40: 24609.76 | AL40: 24609.76 | AM40: 0 | AN40: 0 | AO40: 0 | AP40: 0 | AQ40: 0 | AR40: 0 | AS40: 0 | AT40: 97 | AU40: 51 | AV40: 1 | AW40: 1 | AZ40: 1 | BA40: 1 | BB40: 1 | BC40: 1 | BH40: 3 | BI40: 2 | BJ40: ТСН-2001.1 Доп. 79, Р. 1, о. 1, поз. 58 | BM40: 67 | BN40: 59540665 | BP40: 0 | BQ40: 40 | BR40: 0 | BS40: 1 | BT40: 1 | BU40: 1 | BV40: 1 | BW40: 1 | BX40: 1 | BZ40: 97 | CA40: 51 | CE40: 30 | CF40: 0 | CG40: 0 | CM40: 0 | CO40: 0 | CP40: =(P40+Q40+S40) -> 15.06 | CQ40: =ROUND((ROUND((AC40*AW40*1),2)*BC40),2) -> 24609.76 | CR40: =(ROUND((ROUND(((ET40)*AV40*1),2)*BB40),2)+ROUND((ROUND(((AE40-(EU40))*AV40*1),2)*BS40),2)) -> 0 | CS40: =ROUND((ROUND((AE40*AV40*1),2)*BS40),2) -> 0 | CT40: =ROUND((ROUND((AF40*AV40*1),2)*BA40),2) -> 0 | CU40: =AG40 -> 0 | CV40: =(AH40*AV40) -> 0 | CW40: =AI40 -> 0 | CX40: =AJ40 -> 0 | CY40: =(((S40+R40)*AT40)/100) -> 0 | CZ40: =(((S40+R40)*AU40)/100) -> 0 | DN40: 0 | DO40: 0 | DP40: 1 | DQ40: 1 | DU40: 1009 | DV40: т | DW40: т | DX40: 1000 | EE40: 59540733 | EF40: 40 | EG40: Монтаж оборудования | EH40: 0 | EJ40: 2 | EK40: 67 | EL40: ТСН-2001.4-8. Электротехнические установки | EM40: ТСН-2001.4-8-1 | EQ40: 0 | ER40: 24609.76 | ES40: 24609.76 | ET40: 0 | EU40: 0 | EV40: 0 | EW40: 0 | EX40: 0 | FQ40: 0 | FR40: 0 | FS40: 0 | FX40: 97 | FY40: 51 | GD40: 1 | GF40: -566361729 | GG40: 2 | GH40: 1 | GI40: -2 | GJ40: 0 | GK40: 0 | GL40: =ROUND(IF(AND(BH40=3,BI40=3,FS40<>0),P40,0),2) -> 0 | GM40: =ROUND(O40+X40+Y40,2)+GX40 -> 15.06 | GN40: =IF(OR(BI40=0,BI40=1),GM40-GX40,0) -> 0 | GO40: =IF(BI40=2,GM40-GX40,0) -> 15.06 | GP40: =IF(BI40=4,GM40-GX40,0) -> 0 | GR40: 0 | GS40: 3 | GT40: 0 | GV40: =ROUND((GT40),6) -> 0 | GW40: 1 | GX40: =ROUND(HC40*I40,2) -> 0 | HA40: 0 | HB40: 0 | HC40: =GV40*GW40 -> 0 | HS40: 0 | IK40: 0
A41: 18 | B41: 1 | C41: 31 | E41: 4,1 | F41: 1.1-1-58 | G41: Болты строительные с гайками, оцинкованные, М10х100 мм | H41: т | I41: =I39*J41 -> 0.000612 | J41: 0.00051 | K41: 0.00051 | O41: =ROUND(CP41,2) -> 77.56 | P41: =ROUND((ROUND((AC41*AW41*I41),2)*BC41),2) -> 77.56 | Q41: =(ROUND((ROUND(((ET41)*AV41*I41),2)*BB41),2)+ROUND((ROUND(((AE41-(EU41))*AV41*I41),2)*BS41),2)) -> 0 | R41: =ROUND((ROUND((AE41*AV41*I41),2)*BS41),2) -> 0 | S41: =ROUND((ROUND((AF41*AV41*I41),2)*BA41),2) -> 0 | T41: =ROUND(CU41*I41,2) -> 0 | U41: =CV41*I41 -> 0 | V41: =CW41*I41 -> 0 | W41: =ROUND(CX41*I41,2) -> 0 | X41: =ROUND(CY41,2) -> 0 | Y41: =ROUND(CZ41,2) -> 0 | AA41: 60252775 | AB41: =ROUND((AC41+AD41+AF41),6) -> 24609.76 | AC41: =ROUND((ES41),6) -> 24609.76 | AD41: =ROUND((((ET41)-(EU41))+AE41),6) -> 0 | AE41: =ROUND((EU41),6) -> 0 | AF41: =ROUND((EV41),6) -> 0 | AG41: =ROUND((AP41),6) -> 0 | AH41: =(EW41) -> 0 | AI41: =(EX41) -> 0 | AJ41: =(AS41) -> 0 | AK41: 24609.76 | AL41: 24609.76 | AM41: 0 | AN41: 0 | AO41: 0 | AP41: 0 | AQ41: 0 | AR41: 0 | AS41: 0 | AT41: 97 | AU41: 51 | AV41: 1 | AW41: 1 | AZ41: 1 | BA41: 1 | BB41: 1 | BC41: 5.15 | BH41: 3 | BI41: 2 | BJ41: ТСН-2001.1 Доп. 79, Р. 1, о. 1, поз. 58 | BM41: 67 | BN41: 59540665 | BO41: 1.1-1-58 | BP41: 1 | BQ41: 40 | BR41: 0 | BS41: 1 | BT41: 1 | BU41: 1 | BV41: 1 | BW41: 1 | BX41: 1 | BZ41: 97 | CA41: 51 | CE41: 30 | CF41: 0 | CG41: 0 | CM41: 0 | CO41: 0 | CP41: =(P41+Q41+S41) -> 77.56 | CQ41: =ROUND((ROUND((AC41*AW41*1),2)*BC41),2) -> 126740.26 | CR41: =(ROUND((ROUND(((ET41)*AV41*1),2)*BB41),2)+ROUND((ROUND(((AE41-(EU41))*AV41*1),2)*BS41),2)) -> 0 | CS41: =ROUND((ROUND((AE41*AV41*1),2)*BS41),2) -> 0 | CT41: =ROUND((ROUND((AF41*AV41*1),2)*BA41),2) -> 0 | CU41: =AG41 -> 0 | CV41: =(AH41*AV41) -> 0 | CW41: =AI41 -> 0 | CX41: =AJ41 -> 0 | CY41: =(((S41+R41)*AT41)/100) -> 0 | CZ41: =(((S41+R41)*AU41)/100) -> 0 | DN41: 0 | DO41: 0 | DP41: 1 | DQ41: 1 | DU41: 1009 | DV41: т | DW41: т | DX41: 1000 | EE41: 59540733 | EF41: 40 | EG41: Монтаж оборудования | EH41: 0 | EJ41: 2 | EK41: 67 | EL41: ТСН-2001.4-8. Электротехнические установки | EM41: ТСН-2001.4-8-1 | EQ41: 0 | ER41: 24609.76 | ES41: 24609.76 | ET41: 0 | EU41: 0 | EV41: 0 | EW41: 0 | EX41: 0 | FQ41: 0 | FR41: 0 | FS41: 0 | FX41: 97 | FY41: 51 | GD41: 1 | GF41: -566361729 | GG41: 2 | GH41: 1 | GI41: 2 | GJ41: 0 | GK41: 0 | GL41: =ROUND(IF(AND(BH41=3,BI41=3,FS41<>0),P41,0),2) -> 0 | GM41: =ROUND(O41+X41+Y41,2)+GX41 -> 77.56 | GN41: =IF(OR(BI41=0,BI41=1),GM41-GX41,0) -> 0 | GO41: =IF(BI41=2,GM41-GX41,0) -> 77.56 | GP41: =IF(BI41=4,GM41-GX41,0) -> 0 | GR41: 0 | GS41: 3 | GT41: 0 | GV41: =ROUND((GT41),6) -> 0 | GW41: 1 | GX41: =ROUND(HC41*I41,2) -> 0 | HA41: 0 | HB41: 0 | HC41: =GV41*GW41 -> 0 | HS41: 0 | IK41: 0
A42: 17 | B42: 1 | E42: 5 | F42: КА-3 | G42: Распределительная панель РП-1 | H42: ШТ | I42: 1 | J42: 0 | K42: 1 | O42: =ROUND(CP42,2) -> 38512.11 | P42: =ROUND((ROUND((AC42*I42),2)*BC42),2) -> 38512.11 | Q42: =(ROUND((ROUND(((ET42)*AV42*I42),2)*BB42),2)+ROUND((ROUND(((AE42-(EU42))*AV42*I42),2)*BS42),2)) -> 0 | R42: =ROUND((ROUND((AE42*AV42*I42),2)*BS42),2) -> 0 | S42: =ROUND((ROUND((AF42*AV42*I42),2)*BA42),2) -> 0 | T42: =ROUND(CU42*I42,2) -> 0 | U42: =CV42*I42 -> 0 | V42: =CW42*I42 -> 0 | W42: =ROUND(CX42*I42,2) -> 0 | X42: =ROUND(CY42,2) -> 0 | Y42: =ROUND(CZ42,2) -> 0 | AA42: 60252778 | AB42: =ROUND((AC42+AD42+AF42),6) -> 38512.11 | AC42: =ROUND((ES42),6) -> 38512.11 | AD42: =ROUND((((ET42)-(EU42))+AE42),6) -> 0 | AE42: =ROUND((EU42),6) -> 0 | AF42: =ROUND((EV42),6) -> 0 | AG42: =ROUND((AP42),6) -> 0 | AH42: =(EW42) -> 0 | AI42: =(EX42) -> 0 | AJ42: =(AS42) -> 0 | AK42: 38512.11 | AL42: 38512.11 | AM42: 0 | AN42: 0 | AO42: 0 | AP42: 0 | AQ42: 0 | AR42: 0 | AS42: 0 | AT42: 0 | AU42: 0 | AV42: 1 | AW42: 1 | AZ42: 1 | BA42: 1 | BB42: 1 | BC42: 1 | BH42: 3 | BI42: 3 | BM42: 746 | BN42: 0 | BP42: 0 | BQ42: 130 | BR42: 0 | BS42: 1 | BT42: 1 | BU42: 1 | BV42: 1 | BW42: 1 | BX42: 1 | BZ42: 0 | CA42: 0 | CE42: 30 | CF42: 0 | CG42: 0 | CM42: 0 | CO42: 0 | CP42: =(P42+Q42+S42) -> 38512.11 | CQ42: =ROUND((ROUND((AC42*1),2)*BC42),2) -> 38512.11 | CR42: =(ROUND((ROUND(((ET42)*AV42*1),2)*BB42),2)+ROUND((ROUND(((AE42-(EU42))*AV42*1),2)*BS42),2)) -> 0 | CS42: =ROUND((ROUND((AE42*AV42*1),2)*BS42),2) -> 0 | CT42: =ROUND((ROUND((AF42*AV42*1),2)*BA42),2) -> 0 | CU42: =AG42 -> 0 | CV42: =(AH42*AV42) -> 0 | CW42: =AI42 -> 0 | CX42: =AJ42 -> 0 | CY42: =(((S42+R42)*AT42)/100) -> 0 | CZ42: =(((S42+R42)*AU42)/100) -> 0 | DN42: 0 | DO42: 0 | DP42: 1 | DQ42: 1 | DU42: 1013 | DV42: ШТ | DW42: ШТ | DX42: 1 | EE42: 59540854 | EF42: 130 | EG42: Сметная стоимость оборудования | EH42: 0 | EJ42: 3 | EK42: 746 | EL42: ТСН-2001.13. Сметная стоимость оборудования | EM42: ТСН-2001.13 | EQ42: 0 | ER42: 0 | ES42: 38512.11 | ET42: 0 | EU42: 0 | EV42: 0 | EW42: 0 | EX42: 0 | EY42: 0 | FQ42: 0 | FR42: =P42 -> 38512.11 | FS42: 0 | FX42: 0 | FY42: 0 | GA42: [339 617,08 / 1,2 / 7,66] + 3% Трансп + 1,2% Заг.скл | GD42: 1 | GF42: -237304851 | GG42: 2 | GH42: 4 | GI42: -2 | GJ42: 0 | GK42: 0 | GL42: =ROUND(IF(AND(BH42=3,BI42=3,FS42<>0),P42,0),2) -> 0 | GM42: =ROUND(O42+X42+Y42,2)+GX42 -> 38512.11 | GN42: =IF(OR(BI42=0,BI42=1),GM42-GX42,0) -> 0 | GO42: =IF(BI42=2,GM42-GX42,0) -> 0 | GP42: =IF(BI42=4,GM42-GX42,0) -> 0 | GR42: 0 | GS42: 2 | GT42: 0 | GV42: =ROUND((GT42),6) -> 0 | GW42: 1 | GX42: =ROUND(HC42*I42,2) -> 0 | HA42: 0 | HB42: 0 | HC42: =GV42*GW42 -> 0 | HE42: 3 | HF42: 1,2 | HS42: 0 | IK42: 0
A43: 17 | B43: 1 | E43: 5 | F43: КА-3 | G43: Распределительная панель РП-1 | H43: ШТ | I43: 1 | J43: 0 | K43: 1 | O43: =ROUND(CP43,2) -> 295002.76 | P43: =ROUND((ROUND((AC43*I43),2)*BC43),2) -> 295002.76 | Q43: =(ROUND((ROUND(((ET43)*AV43*I43),2)*BB43),2)+ROUND((ROUND(((AE43-(EU43))*AV43*I43),2)*BS43),2)) -> 0 | R43: =ROUND((ROUND((AE43*AV43*I43),2)*BS43),2) -> 0 | S43: =ROUND((ROUND((AF43*AV43*I43),2)*BA43),2) -> 0 | T43: =ROUND(CU43*I43,2) -> 0 | U43: =CV43*I43 -> 0 | V43: =CW43*I43 -> 0 | W43: =ROUND(CX43*I43,2) -> 0 | X43: =ROUND(CY43,2) -> 0 | Y43: =ROUND(CZ43,2) -> 0 | AA43: 60252775 | AB43: =ROUND((AC43+AD43+AF43),6) -> 38512.11 | AC43: =ROUND((ES43),6) -> 38512.11 | AD43: =ROUND((((ET43)-(EU43))+AE43),6) -> 0 | AE43: =ROUND((EU43),6) -> 0 | AF43: =ROUND((EV43),6) -> 0 | AG43: =ROUND((AP43),6) -> 0 | AH43: =(EW43) -> 0 | AI43: =(EX43) -> 0 | AJ43: =(AS43) -> 0 | AK43: 38512.11 | AL43: 38512.11 | AM43: 0 | AN43: 0 | AO43: 0 | AP43: 0 | AQ43: 0 | AR43: 0 | AS43: 0 | AT43: 0 | AU43: 0 | AV43: 1 | AW43: 1 | AZ43: 1 | BA43: 1 | BB43: 1 | BC43: 7.66 | BH43: 3 | BI43: 3 | BM43: 746 | BN43: 0 | BP43: 0 | BQ43: 130 | BR43: 0 | BS43: 1 | BT43: 1 | BU43: 1 | BV43: 1 | BW43: 1 | BX43: 1 | BZ43: 0 | CA43: 0 | CE43: 30 | CF43: 0 | CG43: 0 | CM43: 0 | CO43: 0 | CP43: =(P43+Q43+S43) -> 295002.76 | CQ43: =ROUND((ROUND((AC43*1),2)*BC43),2) -> 295002.76 | CR43: =(ROUND((ROUND(((ET43)*AV43*1),2)*BB43),2)+ROUND((ROUND(((AE43-(EU43))*AV43*1),2)*BS43),2)) -> 0 | CS43: =ROUND((ROUND((AE43*AV43*1),2)*BS43),2) -> 0 | CT43: =ROUND((ROUND((AF43*AV43*1),2)*BA43),2) -> 0 | CU43: =AG43 -> 0 | CV43: =(AH43*AV43) -> 0 | CW43: =AI43 -> 0 | CX43: =AJ43 -> 0 | CY43: =(((S43+R43)*AT43)/100) -> 0 | CZ43: =(((S43+R43)*AU43)/100) -> 0 | DN43: 0 | DO43: 0 | DP43: 1 | DQ43: 1 | DU43: 1013 | DV43: ШТ | DW43: ШТ | DX43: 1 | EE43: 59540854 | EF43: 130 | EG43: Сметная стоимость оборудования | EH43: 0 | EJ43: 3 | EK43: 746 | EL43: ТСН-2001.13. Сметная стоимость оборудования | EM43: ТСН-2001.13 | EQ43: 0 | ER43: 38512.11 | ES43: 38512.11 | ET43: 0 | EU43: 0 | EV43: 0 | EW43: 0 | EX43: 0 | EY43: 0 | EZ43: 5 | FC43: 1 | FD43: 18 | FF43: 339617.08 | FQ43: 0 | FR43: =P43 -> 295002.76 | FS43: 0 | FX43: 0 | FY43: 0 | GA43: [339 617,08 / 1,2 / 7,66] + 3% Трансп + 1,2% Заг.скл | GD43: 1 | GF43: -237304851 | GG43: 2 | GH43: 3 | GI43: 5 | GJ43: 0 | GK43: 0 | GL43: =ROUND(IF(AND(BH43=3,BI43=3,FS43<>0),P43,0),2) -> 0 | GM43: =ROUND(O43+X43+Y43,2)+GX43 -> 295002.76 | GN43: =IF(OR(BI43=0,BI43=1),GM43-GX43,0) -> 0 | GO43: =IF(BI43=2,GM43-GX43,0) -> 0 | GP43: =IF(BI43=4,GM43-GX43,0) -> 0 | GR43: 1 | GS43: 1 | GT43: 0 | GV43: =ROUND((GT43),6) -> 0 | GW43: 1 | GX43: =ROUND(HC43*I43,2) -> 0 | HA43: 0 | HB43: 0 | HC43: =GV43*GW43 -> 0 | HE43: 3 | HF43: 1,2 | HS43: 0 | IK43: 0
