Workbook

Sheet 02-01-09
A1: =Source!B1 -> Smeta.RU (495) 974-1589
J2: Форма № 4б
A3: Капитальный ремонт здания Государственного бюджетного общеобразовательного учреждения города Москвы "Школа №236" по адресу: г. Москва, улица Клязьминская, дом 7, корпус 4. | AP3: Капитальный ремонт здания Государственного бюджетного общеобразовательного учреждения города Москвы "Школа №236" по адресу: г. Москва, улица Клязьминская, дом 7, корпус 4. 02-01-09 СОУЭ
A4: (наименование стройки и/или объекта)
A6: =CONCATENATE( "ЛОКАЛЬНАЯ СМЕТА № ",IF(Source!F20<>"Новая локальная смета", Source!F20, "")) -> ЛОКАЛЬНАЯ СМЕТА № 02-01-09
A8: =IF(Source!G20<>"Новая локальная смета", Source!G20, "") -> Система оповещения управления эвакуацией
A9: (наименование работ и затрат)
A11: =CONCATENATE( "Основание: чертежи № ", Source!J20) -> Основание: чертежи № 2024-00272-01-0-ИОС5.2
I13: В базисном уровне цен | J13: В текущем уровне цен
E14: Сметная стоимость | I14: =I15+I16+I17+I18 -> 213.64 | J14: =J15+J16+J17+J18 -> 3017.09 | K14: тыс.руб.
E15: Строительные работы | I15: =ROUND((Source!F240)/1000, 2) -> 0 | J15: =ROUND((Source!P240)/1000, 2) -> 0 | K15: тыс.руб.
E16: Работы по монтажу оборудования | I16: =ROUND((Source!F241)/1000, 2) -> 65.58 | J16: =ROUND((Source!P241)/1000, 2) -> 1882.99 | K16: тыс.руб.
E17: Оборудование | I17: =ROUND((Source!F232)/1000, 2) -> 148.06 | J17: =ROUND((Source!P232)/1000, 2) -> 1134.1 | K17: тыс.руб.
E18: Прочие работы и затраты | I18: =ROUND((Source!F242+Source!F243)/1000, 2) -> 0 | J18: =ROUND((Source!P242+Source!P243)/1000, 2) -> 0 | K18: тыс.руб.
E19: Средства на оплату труда | I19: =(Source!F238+ Source!F237)/1000 -> 11.66748 | J19: =((Source!P238 + Source!P237)/1000) -> 641.59471 | K19: тыс.руб.
E20: Затраты труда | I20: =Source!F245 -> 980.90519 | K20: чел.-ч.
E21: Кроме того:
E22: Возврат материалов | I22: =SUM(Y28:Y295)/1000 -> 0 | J22: =SUM(Z28:Z295)/1000 -> 0 | K22: тыс.руб.
A24: Составлен(а) по ТСН-2001 с учетом Дополнения №: 80
A25: № и период сборника коэффициентов (индексов) пересчета: Коэффициенты к ТСН-2001 МГЭ Дополнение 80, строительство №217/80 III квартал 2025 года и Коэффициенты к ТСН-2001.13-2 Дополнение 46 №62/46 III квартал 2025 года | AP25: № и период сборника коэффициентов (индексов) пересчета: Коэффициенты к ТСН-2001 МГЭ Дополнение 80, строительство №217/80 III квартал 2025 года и Коэффициенты к ТСН-2001.13-2 Дополнение 46 №62/46 III квартал 2025 года
A26: № п/п | B26: Шифр расценки и коды ресурсов | C26: Наименование работ и затрат | D26: Ед. изм. | E26: Кол-во единиц | F26: Цена на ед. изм., руб. | G26: Попра- вочные коэффи- циенты | H26: Коэффи- циенты зимних удорожа- ний | I26: Всего в ценах на январь 2000 года, руб. | J26: Коэффи- циенты (индек- сы) пере- счета, нормы НР и СП | K26: ВСЕГО затрат в текущем уровне цен, руб.
A27: 1 | B27: 2 | C27: 3 | D27: 4 | E27: 5 | F27: 6 | G27: 7 | H27: 8 | I27: 9 | J27: 10 | K27: 11
A29: =CONCATENATE("Раздел: ",IF(Source!G24<>"Новый раздел", Source!G24, "")) -> Раздел: Оборудование
A30: 1 | B30: =Source!F28 -> 4.10-118-1 | C30: Установка для трубных проводок шкафа напольного размерами до 600х600 мм | D30: =Source!H28 -> 1 ШТ. | E30: =Source!I28 -> 1 | Q30: =Source!X28 -> 22.45 | R30: =Source!X29 -> 1234.31 | S30: =Source!Y28 -> 11.47 | T30: =Source!Y29 -> 630.87 | U30: =ROUND((175/100)*ROUND(Source!R28, 2), 2) -> 0.51 | V30: =ROUND((0/100)*ROUND(Source!R29, 2), 2) -> 0 | AC30: 0
C31: ЗП | F31: =Source!AO28 -> 21.4 | G31: 1,1 | H31: =Source!AV29 -> 1.047 | I31: =Source!S28 -> 24.65 | J31: =IF(Source!BA29<> 0, Source!BA29, 1) -> 54.99 | K31: =Source!S29 -> 1355.5
C32: ЭМ | F32: =Source!AM28 -> 2.38 | G32: 1,1 | H32: =Source!AV29 -> 1.047 | I32: =Source!Q28 -> 2.74 | J32: =IF(Source!BB29<> 0, Source!BB29, 1) -> 13.99 | K32: =Source!Q29 -> 38.33
C33: в т.ч. ЗПМ | F33: =Source!AN28 -> 0.25 | G33: 1,1 | H33: =Source!AV29 -> 1.047 | I33: =Source!R28 -> 0.29 | J33: =IF(Source!BS29<> 0, Source!BS29, 1) -> 54.99 | K33: =Source!R29 -> 15.95
C34: МР | F34: =Source!AL28 -> 70.17 | H34: =Source!AW29 -> 1 | I34: =Source!P28 -> 70.17 | J34: =IF(Source!BC29<> 0, Source!BC29, 1) -> 1.86 | K34: =Source!P29 -> 130.52
C35: НР от ФОТ | D35: % | E35: =Source!BZ29 -> 90 | I35: =SUM(Q30:Q34) -> 22.45 | J35: =Source!AT29 -> 90 | K35: =SUM(R30:R34) -> 1234.31
C36: СП от ФОТ | D36: % | E36: =Source!CA29 -> 46 | I36: =SUM(S30:S35) -> 11.47 | J36: =Source!AU29 -> 46 | K36: =SUM(T30:T35) -> 630.87
C37: ЗТР | D37: чел-ч | E37: =Source!AQ28 -> 2 | G37: 1,1 | H37: =Source!AV29 -> 1.047 | I37: =Source!U28 -> 2.3034
C38: ВСЕГО работ по позиции: | H38: =I31+I32+I34+I35+I36+0-0-0 -> 131.48 | J38: =K31+K32+K34+K35+K36+0-0-0 -> 3389.53
C39: ВСЕГО оборудование по позиции: | H39: =0+0 -> 0 | J39: =0+0 -> 0
C40: ВСЕГО по позиции: | H40: =I31+I32+I34+I35+I36+0 -> 131.48 | J40: =K31+K32+K34+K35+K36+0 -> 3389.53 | O40: =I31+I32+I34+I35+I36+0 -> 131.48 | P40: =K31+K32+K34+K35+K36+0 -> 3389.53
A42: 2 | B42: =Source!F30 -> КА-1 | C42: Шкаф настенный LINEA W 18U 600x600 мм дверь стекло RAL9005 LWR5-18U66-GF 1 952,77 = [22 698,04 / 1,2 / 9,88] + 2% Заг.скл | D42: =Source!H30 -> шт. | E42: =Source!I30 -> 1 | F42: =Source!AL30 -> 1952.77 | H42: =Source!AW31 -> 1 | I42: =Source!P30 -> 1952.77 | J42: =IF(Source!BC31<> 0, Source!BC31, 1) -> 9.88 | K42: =Source!P31 -> 19293.37 | Q42: =Source!X30 -> 0 | R42: =Source!X31 -> 0 | S42: =Source!Y30 -> 0 | T42: =Source!Y31 -> 0 | U42: =ROUND((175/100)*ROUND(Source!R30, 2), 2) -> 0 | V42: =ROUND((0/100)*ROUND(Source!R31, 2), 2) -> 0 | AC42: 3
C43: ВСЕГО по позиции: | H43: =I42+0 -> 1952.77 | J43: =K42+0 -> 19293.37 | O43: =I42+0 -> 1952.77 | P43: =K42+0 -> 19293.37
A45: 3 | B45: =Source!F32 -> 4.10-170-2 | C45: Монтаж блока информационно-управляющего (БИУ) в диспетчерской | D45: =Source!H32 -> 1 ШТ. | E45: =Source!I32 -> 1 | Q45: =Source!X32 -> 34.7 | R45: =Source!X33 -> 1907.87 | S45: =Source!Y32 -> 17.73 | T45: =Source!Y33 -> 975.14 | U45: =ROUND((175/100)*ROUND(Source!R32, 2), 2) -> 0 | V45: =ROUND((0/100)*ROUND(Source!R33, 2), 2) -> 0 | AC45: 0
C46: ЗП | F46: =Source!AO32 -> 33.47 | G46: 1,1 | H46: =Source!AV33 -> 1.047 | I46: =Source!S32 -> 38.55 | J46: =IF(Source!BA33<> 0, Source!BA33, 1) -> 54.99 | K46: =Source!S33 -> 2119.86
C47: МР | F47: =Source!AL32 -> 2.34 | H47: =Source!AW33 -> 1 | I47: =Source!P32 -> 2.34 | J47: =IF(Source!BC33<> 0, Source!BC33, 1) -> 10.26 | K47: =Source!P33 -> 24.01
C48: НР от ФОТ | D48: % | E48: =Source!BZ33 -> 90 | I48: =SUM(Q45:Q47) -> 34.7 | J48: =Source!AT33 -> 90 | K48: =SUM(R45:R47) -> 1907.87
...

Sheet Ведомость объемов работ
A1: =Source!B1 -> Smeta.RU (495) 974-1589
B4: =CONCATENATE("Ведомость объемов работ ", IF(Source!AN15<>"", Source!AN15," ")) -> Ведомость объемов работ
B5: =CONCATENATE(Source!F12, " ", Source!G12) -> 02-01-09 СОУЭ
A8: № п/п | B8: № в ЛСР | C8: Наименование работ и затрат | D8: Единица измерения | E8: Количество | F8: Ссылка на чертежи, спецификации | G8: Формула расчета, расчет объемов работ и расхода материалов | H8: Примечание
A9: 1 | B9: 2 | C9: 3 | D9: 4 | E9: 5 | F9: 6 | G9: 7 | H9: 8
A10: =CONCATENATE("Локальная смета: ", Source!G20) -> Локальная смета: Система оповещения управления эвакуацией
A11: =CONCATENATE("Раздел: ", Source!G24) -> Раздел: Оборудование
A12: 1 | B12: =Source!E28 -> 1 | C12: =Source!G28 -> Установка для трубных проводок шкафа напольного размерами до 600х600 мм | D12: 1 ШТ. | E12: =Source!I28 -> 1 | F12: =Source!U24 | G12: =Source!I28 -> 1
A13: 2 | B13: =Source!E30 -> 2 | C13: =Source!G30 -> Шкаф настенный LINEA W 18U 600x600 мм дверь стекло RAL9005 LWR5-18U66-GF | D13: шт. | E13: =Source!I30 -> 1 | F13: =Source!U24 | G13: =Source!I30 -> 1
A14: 3 | B14: =Source!E32 -> 3 | C14: =Source!G32 -> Монтаж блока информационно-управляющего (БИУ) в диспетчерской | D14: 1 ШТ. | E14: =Source!I32 -> 1 | F14: =Source!U24 | G14: =Source!I32 -> 1
A15: 4 | B15: =Source!E34 -> 4 | C15: =Source!G34 -> Прибор управления оповещением пожарной Sonar SPM, мощность850 Вт, 20 зон/20 линий оповещения, прием сигнала от ОПС по АЛС, установка в стойку Sonar SPM-C20085-AR | D15: шт. | E15: =Source!I34 -> 1 | F15: =Source!U24 | G15: =Source!I34 -> 1
A16: 5 | B16: =Source!E36 -> 5 | C16: =Source!G36 -> Установка съемных и выдвижных блоков (модулей, ячеек, ТЭЗ) массой до 5 кг | D16: 1 ШТ. | E16: =Source!I36 -> 1 | F16: =Source!U24 | G16: =Source!I36 -> 1
A17: 6 | B17: =Source!E38 -> 6 | C17: =Source!G38 -> Конвертер DAP-IP для объединения приборов Sonar SPM в сеть Ethernet Sonar SNCA-8002 | D17: шт. | E17: =Source!I38 -> 1 | F17: =Source!U24 | G17: =Source!I38 -> 1
A18: 7 | B18: =Source!E40 -> 7 | C18: =Source!G40 -> Установка съемных и выдвижных блоков (модулей, ячеек, ТЭЗ) массой до 5 кг | D18: 1 ШТ. | E18: =Source!I40 -> 1 | F18: =Source!U24 | G18: =Source!I40 -> 1
A19: 8 | B19: =Source!E42 -> 8 | C19: =Source!G42 -> Комплект программируемого таймера Sonar STM-1004+GPS-2500 комплект | D19: шт. | E19: =Source!I42 -> 1 | F19: =Source!U24 | G19: =Source!I42 -> 1
A20: 9 | B20: =Source!E44 -> 9 | C20: =Source!G44 -> Установка прибора массой до 5 кг на металлоконструкциях или щитах | D20: 1 ШТ. | E20: =Source!I44 -> 1 | F20: =Source!U24 | G20: =Source!I44 -> 1
A21: 10 | B21: =Source!E48 -> 10 | C21: =Source!G48 -> Силовой блок рапределения питания по стойке оповещения, максимальный ток 50А Sonar RDIP-50A | D21: шт. | E21: =Source!I48 -> 1 | F21: =Source!U24 | G21: =Source!I48 -> 1
A22: 11 | B22: =Source!E50 -> 11 | C22: =Source!G50 -> Монтаж блока питания сети (БПС) в диспетчерской | D22: 1 ШТ. | E22: =Source!I50 -> 1 | F22: =Source!U24 | G22: =Source!I50 -> 1
A23: 12 | B23: =Source!E52 -> 12 | C23: =Source!G52 -> Зарядное устройство Sonar SBC-3250 | D23: шт. | E23: =Source!I52 -> 1 | F23: =Source!U24 | G23: =Source!I52 -> 1
A24: 13 | B24: =Source!E54 -> 13 | C24: =Source!G54 -> Установка прибора массой до 5 кг на металлоконструкциях или щитах | D24: 1 ШТ. | E24: =Source!I54 -> 1 | F24: =Source!U24 | G24: =Source!I54 -> 1
A25: 14 | B25: =Source!E58 -> 14 | C25: =Source!G58 -> Блок АКБ 24В. Заменяемые АКБ 12В, 5Ач, количество элементов в корпусе - 10 шт. Sonar SBB-2425 | D25: шт. | E25: =Source!I58 -> 1 | F25: =Source!U24 | G25: =Source!I58 -> 1
A26: 15 | B26: =Source!E60 -> 15 | C26: =Source!G60 -> Установка прибора массой до 5 кг на металлоконструкциях или щитах | D26: 1 ШТ. | E26: =Source!I60 -> 1 | F26: =Source!U24 | G26: =Source!I60 -> 1
A27: 16 | B27: =Source!E64 -> 16 | C27: =Source!G64 -> Блок АКБ 24В. Заменяемые АКБ 12В, 5Ач, количество элементов в корпусе - 18 шт. Sonar SBB-2450 | D27: шт. | E27: =Source!I64 -> 1 | F27: =Source!U24 | G27: =Source!I64 -> 1
A28: 17 | B28: =Source!E66 -> 17 | C28: =Source!G66 -> Аппараты приемные, устройства промежуточные на 1 луч | D28: 1 ШТ. | E28: =Source!I66 -> 2 | F28: =Source!U24 | G28: =Source!I66 -> 2
A29: 18 | B29: =Source!E68 -> 18 | C29: =Source!G68 -> Изолятор шлейфа ИЗ-1-R3 | D29: шт. | E29: =Source!I68 -> 2 | F29: =Source!U24 | G29: =Source!I68 -> 2
A30: 19 | B30: =Source!E70 -> 19 | C30: =Source!G70 -> Установка прибора массой до 5 кг на металлоконструкциях или щитах | D30: 1 ШТ. | E30: =Source!I70 -> 2 | F30: =Source!U24 | G30: =Source!I70 -> 2
A31: 20 | B31: =Source!E74 -> 20 | C31: =Source!G74 -> Кабельный органайзер 10" 1U 4 кольца для шкафа 10" серии LINEA WS черный CO05-1M4R-LWS | D31: шт. | E31: =Source!I74 -> 2 | F31: =Source!U24 | G31: =Source!I74 -> 2
A32: 21 | B32: =Source!E76 -> 21 | C32: =Source!G76 -> Установка прибора массой до 5 кг на металлоконструкциях или щитах | D32: 1 ШТ. | E32: =Source!I76 -> 1 | F32: =Source!U24 | G32: =Source!I76 -> 1
A33: 22 | B33: =Source!E80 -> 22 | C33: =Source!G80 -> Панель 19" с DIN-рейкой регулируемая по глубине STK-RACKMNT-704KA | D33: шт. | E33: =Source!I80 -> 1 | F33: =Source!U24 | G33: =Source!I80 -> 1
A34: 23 | B34: =Source!E82 -> 23 | C34: =Source!G82 -> Установка прибора массой до 5 кг на металлоконструкциях или щитах | D34: 1 ШТ. | E34: =Source!I82 -> 2 | F34: =Source!U24 | G34: =Source!I82 -> 2
A35: 24 | B35: =Source!E86 -> 24 | C35: =Source!G86 -> Шина заземления 483х25х3 мм медь ШМТ М1 12 точек подключения М6 ER-12-325-M1 | D35: шт. | E35: =Source!I86 -> 2 | F35: =Source!U24 | G35: =Source!I86 -> 2
A36: 25 | B36: =Source!E88 -> 25 | C36: =Source!G88 -> Коннектор powerCON (in) Sonar SPC-20B | D36: шт. | E36: =Source!I88 -> 3 | F36: =Source!U24 | G36: =Source!I88 -> 3
A37: 26 | B37: =Source!E90 -> 26 | C37: =Source!G90 -> Аккумулятор 12В, 5А*ч Delta | D37: шт. | E37: =Source!I90 -> 28 | F37: =Source!U24 | G37: =Source!I90 -> 28
A38: =CONCATENATE("Раздел: ", Source!G123) -> Раздел: Оборудование оповещения
A39: 27 | B39: =Source!E127 -> 27 | C39: =Source!G127 -> Монтаж громкоговорителя или звуковой колонки в помещении | D39: 1 ШТ. | E39: =Source!I127 -> 213 | F39: =Source!U123 | G39: =Source!I127 -> 213
A40: 28 | B40: =Source!E129 -> 28 | C40: =Source!G129 -> Громкоговоритель трансляционный настенный, 100В, мощность 6/3/1,5Вт Sonar SWS-106-103 | D40: шт. | E40: =Source!I129 -> 213 | F40: =Source!U123 | G40: =Source!I129 -> 213
A41: 29 | B41: =Source!E131 -> 29 | C41: =Source!G131 -> Установка для трубных проводок коробки оконечной | D41: 100 шт. | E41: =Source!I131 -> 0.04 | F41: =Source!U123 | G41: ="=4/"&"100" -> =4/100
A42: 30 | B42: =Source!E133 -> 30 | C42: =Source!G133 -> Фильтр оконечный для трансляционной линии при контроле линии переменным током Sonar SFT-2300-M | D42: шт. | E42: =Source!I133 -> 4 | F42: =Source!U123 | G42: =Source!I133 -> 4
A43: 31 | B43: =Source!E135 -> 31 | C43: =Source!G135 -> Установка пульта или табло вызывной сигнализации с количеством сигналов до 20 | D43: 1 ШТ. | E43: =Source!I135 -> 1 | F43: =Source!U123 | G43: =Source!I135 -> 1
A44: 32 | B44: =Source!E137 -> 32 | C44: =Source!G137 -> Пульт микрофонный Sonar SRM-7020C | D44: шт. | E44: =Source!I137 -> 1 | F44: =Source!U123 | G44: =Source!I137 -> 1
...

Sheet Source
A1: 0 | B1: Smeta.RU (495) 974-1589 | D1: _PS_ | F1: 0 | G1: 0 | H1: 0 | I1: Smeta.RU | K1: 1 | L1: 74563 | M1: 10 | N1: 12 | O1: 1 | P1: 0 | Q1: 0
A4: 1 | B4: 1 | C4: -1 | G4: Капитальный ремонт здания Государственного бюджетного общеобразовательного учреждения города Москвы "Школа №236" по адресу: г. Москва, улица Клязьминская, дом 7, корпус 4 | EC4: 0
A12: 1 | B12: 292 | C12: 0 | D12: =ROW(A253) -> 253 | E12: 0 | G12: 02-01-09 СОУЭ | I12: 0 | J12: 2024-00272-010-ИОС5.2 | K12: 0 | L12: 0 | M12: 4098 | O12: 0 | P12: 0 | Q12: 0 | R12: 0 | S12: 0 | T12: 1 | V12: 0 | AB12: Соколова И.Н. | BB12: 0 | BH12: Сметные нормы списания | BI12: Коды ОКП для ТСН-2001 МГЭ Дополнение 80 | BJ12: 1 | BK12: 1 | BL12: 0 | BM12: 0 | BN12: 1 | BO12: 0 | BP12: 6 | BQ12: 2 | BR12: 1 | BS12: 1 | BT12: 0 | BU12: 0 | BV12: 0 | BW12: 0 | BX12: 0 | BZ12: Типовой расчет для ТСН-2001 МГЭ, Дополнение 80, строительство (1) | CA12: Территориальные сметные нормативы для Москвы ТСН-2001 (МГЭ), дополнение 80 | CB12: Территориальные сметные нормативы для Москвы ТСН-2001 (МГЭ), дополнение 80 | CC12: Территориальные сметные нормативы для Москвы ТСН-2001 (МГЭ), дополнение 80 | CD12: Территориальные сметные нормативы для Москвы ТСН-2001 (МГЭ), дополнение 80 | CE12: Поправки для ТСН-2001 от 28.11.2025 г. доп.79 | CF12: 0 | CG12: 0 | CH12: 8200 | CK12: 81 | CQ12: Территориальные сметные нормативы для Москвы (ТСН-2001) | CR12: ТЕР | CS12: 41660 | CT12: 1 | CU12: 80 | CY12: 0 | EC12: 0
A15: 15 | B15: 1
A18: 52 | B18: =B253 -> 292 | C18: =C253 -> 1 | D18: =D253 -> 12 | E18: =E253 -> 0 | F18: =F253 | G18: =G253 -> 02-01-09 СОУЭ | O18: =O253 -> 197064.51 | P18: =P253 -> 185317.71 | Q18: =Q253 -> 79.81 | R18: =R253 -> 0.49 | S18: =S253 -> 11666.99 | T18: =T253 -> 0 | U18: =U253 -> 980.90519 | V18: =V253 -> 0 | ... GX18: =GX253 -> 0
A20: 3 | B20: 1 | D20: =ROW(A223) -> 223 | F20: 02-01-09 | G20: Система оповещения управления эвакуацией | I20: 0 | J20: 2024-00272-01-0-ИОС5.2 | K20: -1 | L20: 02-01-09 | S20: 0 | T20: 0 | V20: 2 | BX20: 0 | CF20: 0 | CG20: 0
A22: 52 | B22: =B223 -> 1 | C22: =C223 -> 3 | D22: =D223 -> 20 | E22: =E223 -> 0 | F22: =F223 -> 02-01-09 | G22: =G223 -> Система оповещения управления эвакуацией | O22: =O223 -> 197064.51 | P22: =P223 -> 185317.71 | Q22: =Q223 -> 79.81 | R22: =R223 -> 0.49 | S22: =S223 -> 11666.99 | T22: =T223 -> 0 | U22: =U223 -> 980.90519 | V22: =V223 -> 0 | ... GX22: =GX223 -> 0
A24: 4 | B24: 1 | D24: =ROW(A93) -> 93 | G24: Оборудование | I24: 0 | K24: -1 | S24: 0 | T24: 0 | V24: 2 | BX24: 0 | CJ24: 0
A26: 52 | B26: =B93 -> 1 | C26: =C93 -> 4 | D26: =D93 -> 24 | E26: =E93 -> 0 | F26: =F93 | G26: =G93 -> Оборудование | O26: =O93 -> 80435.66 | P26: =P93 -> 80220.57 | Q26: =Q93 -> 4.04 | R26: =R93 -> 0.49 | S26: =S93 -> 211.05 | T26: =T93 -> 0 | U26: =U93 -> 16.849371 | V26: =V93 -> 0 | ... GX26: =GX93 -> 0
A28: 17 | B28: 1 | C28: =ROW(SmtRes!A7) -> 7 | D28: =ROW(EtalonRes!A8) -> 8 | E28: 1 | F28: 4.10-118-1 | G28: Установка для трубных проводок шкафа напольного размерами до 600х600 мм | H28: 1 ШТ. | I28: 1 | J28: 0 | K28: 1 | O28: =ROUND(CP28,2) -> 97.56 | P28: =ROUND((ROUND((AC28*AW28*I28),2)*BC28),2) -> 70.17 | Q28: =(ROUND((ROUND((((ET28*1.1))*AV28*I28),2)*BB28),2)+ROUND((ROUND(((AE28-((EU28*1.1)))*AV28*I28),2)*BS28),2)) -> 2.74 | R28: =(ROUND((ROUND((((EU28*1.1))*AV28*I28),2)*BS28),2)+ROUND((ROUND(((AE28-((EU28*1.1)))*AV28*I28),2)*BS28),2)) -> 0.29 | S28: =ROUND((ROUND((AF28*AV28*I28),2)*BA28),2) -> 24.65 | T28: =ROUND(CU28*I28,2) -> 0 | U28: =CV28*I28 -> 2.3034 | V28: =CW28*I28 -> 0 | W28: =ROUND(CX28*I28,2) -> 0 | X28: =(ROUND((((S28+ROUND((ROUND((((EU28*1.1))*AV28*I28),2)*BS28),2))*AT28)/100),2)+ROUND(((ROUND((ROUND(((AE28-((EU28*1.1)))*AV28*I28),2)*BS28),2)*AT28)/100),2)) -> 22.45 | Y28: =(ROUND((((S28+ROUND((ROUND((((EU28*1.1))*AV28*I28),2)*BS28),2))*AU28)/100),2)+ROUND(((ROUND((ROUND(((AE28-((EU28*1.1)))*AV28*I28),2)*BS28),2)*AU28)/100),2)) -> 11.47 | AA28: 60256405 | AB28: =ROUND((AC28+AD28+AF28),6) -> 96.328 | AC28: =ROUND(((ES28*1)),6) -> 70.17 | AD28: =ROUND(((((ET28*1.1))-((EU28*1.1)))+AE28),6) -> 2.618 | AE28: =ROUND(((EU28*1.1)),6) -> 0.275 | AF28: =ROUND(((EV28*1.1)),6) -> 23.54 | AG28: =ROUND((AP28),6) -> 0 | AH28: =((EW28*1.1)) -> 2.2 | AI28: =((EX28*1.1)) -> 0 | AJ28: =(AS28) -> 0 | AK28: 93.95 | AL28: 70.17 | AM28: 2.38 | AN28: 0.25 | AO28: 21.4 | AP28: 0 | AQ28: 2 | AR28: 0 | AS28: 0 | AT28: 90 | AU28: 46 | AV28: 1.047 | AW28: 1 | AZ28: 1 | BA28: 1 | BB28: 1 | BC28: 1 | BH28: 0 | BI28: 2 | BJ28: ТСН-2001.4 Доп. 79, Сб. 10, т. 118, поз. 1 | BM28: 68 | BN28: 58973116 | BO28: 4.10-118-1 | BP28: 1 | BQ28: 40 | BR28: 0 | BS28: 1 | BT28: 1 | BU28: 1 | BV28: 1 | BW28: 1 | BX28: 1 | BZ28: 90 | CA28: 46 | CE28: 1566 | CF28: 0 | CG28: 0 | CM28: 0 | CN28: Поправка: Гл.12.Прил.8.п.8. 5_12.00.01.11.003 Наименование: При наличии усложненных условий производства работ (стесненность, сложность складирования и транспортной логистики, наличие в зоне производства работ действующего технологического оборудования или движения технологического транспорта и т.п.) для объектов, расположенных за пределами территории круговой магистральной системы улиц "Садовое кольцо" и за пределами Третьего транспортного кольца города Москвы пунктов "а" и "б", но в пределах Московской кольцевой автомобильной дороги | CO28: 0 | CP28: =(P28+Q28+S28) -> 97.56 | CQ28: =ROUND((ROUND((AC28*AW28*1),2)*BC28),2) -> 70.17 | CR28: =(ROUND((ROUND((((ET28*1.1))*AV28*1),2)*BB28),2)+ROUND((ROUND(((AE28-((EU28*1.1)))*AV28*1),2)*BS28),2)) -> 2.74 | CS28: =(ROUND((ROUND((((EU28*1.1))*AV28*1),2)*BS28),2)+ROUND((ROUND(((AE28-((EU28*1.1)))*AV28*1),2)*BS28),2)) -> 0.29 | CT28: =ROUND((ROUND((AF28*AV28*1),2)*BA28),2) -> 24.65 | CU28: =AG28 -> 0 | CV28: =(AH28*AV28) -> 2.3034 | CW28: =AI28 -> 0 | CX28: =AJ28 -> 0 | CY28: =(ROUND((((S28+ROUND((ROUND((((EU28*1.1))*AV28*1),2)*BS28),2))*AT28)/100),2)+ROUND(((ROUND((ROUND(((AE28-((EU28*1.1)))*AV28*1),2)*BS28),2)*AT28)/100),2)) -> 22.45 | CZ28: =(ROUND((((S28+ROUND((ROUND((((EU28*1.1))*AV28*1),2)*BS28),2))*AU28)/100),2)+ROUND(((ROUND((ROUND(((AE28-((EU28*1.1)))*AV28*1),2)*BS28),2)*AU28)/100),2)) -> 11.47 | DB28: 1 | DD28: *1 | DE28: *1,1 | DF28: *1,1 | DG28: *1,1 | DI28: *1,1 | DJ28: *1,1 | DN28: 0 | DO28: 0 | DP28: 1 | DQ28: 1 | DU28: 1013 | DV28: 1 ШТ. | DW28: 1 ШТ. | DX28: 1 | EE28: 60088532 | EF28: 40 | EG28: Монтаж оборудования | EH28: 0 | EJ28: 2 | EK28: 68 | EL28: ТСН-2001.4-10. Прокладка и монтаж сетей связи | EM28: ТСН-2001.4-10-1 | EO28: Поправка: Гл.12.Прил.8.п.8. 5_12.00.01.11.003 | EQ28: 0 | ER28: 93.95 | ES28: 70.17 | ET28: 2.38 | EU28: 0.25 | EV28: 21.4 | EW28: 2 | EX28: 0 | EY28: 0 | FQ28: 0 | FR28: 0 | FS28: 0 | FX28: 90 | FY28: 46 | GD28: 1 | GF28: -1502969864 | GG28: 2 | GH28: 1 | GI28: 2 | GJ28: 0 | GK28: 0 | GL28: =ROUND(IF(AND(BH28=3,BI28=3,FS28<>0),P28,0),2) -> 0 | GM28: =ROUND(O28+X28+Y28,2)+GX28 -> 131.48 | GN28: =IF(OR(BI28=0,BI28=1),GM28-GX28,0) -> 0 | GO28: =IF(BI28=2,GM28-GX28,0) -> 131.48 | GP28: =IF(BI28=4,GM28-GX28,0) -> 0 | GR28: 0 | GS28: 3 | GT28: 0 | GV28: =ROUND((GT28),6) -> 0 | GW28: 1 | GX28: =ROUND(HC28*I28,2) -> 0 | HA28: 0 | HB28: 0 | HC28: =GV28*GW28 -> 0 | HS28: 0 | IK28: 0
A29: 17 | B29: 1 | C29: =ROW(SmtRes!A14) -> 14 | D29: =ROW(EtalonRes!A16) -> 16 | E29: 1 | F29: 4.10-118-1 | G29: Установка для трубных проводок шкафа напольного размерами до 600х600 мм | H29: 1 ШТ. | I29: 1 | J29: 0 | K29: 1 | O29: =ROUND(CP29,2) -> 1524.35 | P29: =ROUND((ROUND((AC29*AW29*I29),2)*BC29),2) -> 130.52 | Q29: =(ROUND((ROUND((((ET29*1.1))*AV29*I29),2)*BB29),2)+ROUND((ROUND(((AE29-((EU29*1.1)))*AV29*I29),2)*BS29),2)) -> 38.33 | R29: =(ROUND((ROUND((((EU29*1.1))*AV29*I29),2)*BS29),2)+ROUND((ROUND(((AE29-((EU29*1.1)))*AV29*I29),2)*BS29),2)) -> 15.95 | S29: =ROUND((ROUND((AF29*AV29*I29),2)*BA29),2) -> 1355.5 | T29: =ROUND(CU29*I29,2) -> 0 | U29: =CV29*I29 -> 2.3034 | V29: =CW29*I29 -> 0 | W29: =ROUND(CX29*I29,2) -> 0 | X29: =(ROUND((((S29+ROUND((ROUND((((EU29*1.1))*AV29*I29),2)*BS29),2))*AT29)/100),2)+ROUND(((ROUND((ROUND(((AE29-((EU29*1.1)))*AV29*I29),2)*BS29),2)*AT29)/100),2)) -> 1234.31 | Y29: =(ROUND((((S29+ROUND((ROUND((((EU29*1.1))*AV29*I29),2)*BS29),2))*AU29)/100),2)+ROUND(((ROUND((ROUND(((AE29-((EU29*1.1)))*AV29*I29),2)*BS29),2)*AU29)/100),2)) -> 630.87 | AA29: 60256402 | AB29: =ROUND((AC29+AD29+AF29),6) -> 96.328 | AC29: =ROUND(((ES29*1)),6) -> 70.17 | AD29: =ROUND(((((ET29*1.1))-((EU29*1.1)))+AE29),6) -> 2.618 | AE29: =ROUND(((EU29*1.1)),6) -> 0.275 | AF29: =ROUND(((EV29*1.1)),6) -> 23.54 | AG29: =ROUND((AP29),6) -> 0 | AH29: =((EW29*1.1)) -> 2.2 | AI29: =((EX29*1.1)) -> 0 | AJ29: =(AS29) -> 0 | AK29: 93.95 | AL29: 70.17 | AM29: 2.38 | AN29: 0.25 | AO29: 21.4 | AP29: 0 | AQ29: 2 | AR29: 0 | AS29: 0 | AT29: 90 | AU29: 46 | AV29: 1.047 | AW29: 1 | AZ29: 1 | BA29: 54.99 | BB29: 13.99 | BC29: 1.86 | BH29: 0 | BI29: 2 | BJ29: ТСН-2001.4 Доп. 79, Сб. 10, т. 118, поз. 1 | BM29: 68 | BN29: 58973116 | BO29: 4.10-118-1 | BP29: 1 | BQ29: 40 | BR29: 0 | BS29: 54.99 | BT29: 1 | BU29: 1 | BV29: 1 | BW29: 1 | BX29: 1 | BZ29: 90 | CA29: 46 | CE29: 1566 | CF29: 0 | CG29: 0 | CM29: 0 | CN29: Поправка: Гл.12.Прил.8.п.8. 5_12.00.01.11.003 Наименование: При наличии усложненных условий производства работ (стесненность, сложность складирования и транспортной логистики, наличие в зоне производства работ действующего технологического оборудования или движения технологического транспорта и т.п.) для объектов, расположенных за пределами территории круговой магистральной системы улиц "Садовое кольцо" и за пределами Третьего транспортного кольца города Москвы пунктов "а" и "б", но в пределах Московской кольцевой автомобильной дороги | CO29: 0 | CP29: =(P29+Q29+S29) -> 1524.35 | CQ29: =ROUND((ROUND((AC29*AW29*1),2)*BC29),2) -> 130.52 | CR29: =(ROUND((ROUND((((ET29*1.1))*AV29*1),2)*BB29),2)+ROUND((ROUND(((AE29-((EU29*1.1)))*AV29*1),2)*BS29),2)) -> 38.33 | CS29: =(ROUND((ROUND((((EU29*1.1))*AV29*1),2)*BS29),2)+ROUND((ROUND(((AE29-((EU29*1.1)))*AV29*1),2)*BS29),2)) -> 15.95 | CT29: =ROUND((ROUND((AF29*AV29*1),2)*BA29),2) -> 1355.5 | CU29: =AG29 -> 0 | CV29: =(AH29*AV29) -> 2.3034 | CW29: =AI29 -> 0 | CX29: =AJ29 -> 0 | CY29: =(ROUND((((S29+ROUND((ROUND((((EU29*1.1))*AV29*1),2)*BS29),2))*AT29)/100),2)+ROUND(((ROUND((ROUND(((AE29-((EU29*1.1)))*AV29*1),2)*BS29),2)*AT29)/100),2)) -> 1234.31 | CZ29: =(ROUND((((S29+ROUND((ROUND((((EU29*1.1))*AV29*1),2)*BS29),2))*AU29)/100),2)+ROUND(((ROUND((ROUND(((AE29-((EU29*1.1)))*AV29*1),2)*BS29),2)*AU29)/100),2)) -> 630.87 | DB29: 2 | DD29: *1 | DE29: *1,1 | DF29: *1,1 | DG29: *1,1 | DI29: *1,1 | DJ29: *1,1 | DN29: 0 | DO29: 0 | DP29: 1 | DQ29: 1 | DU29: 1013 | DV29: 1 ШТ. | DW29: 1 ШТ. | DX29: 1 | EE29: 60088532 | EF29: 40 | EG29: Монтаж оборудования | EH29: 0 | EJ29: 2 | EK29: 68 | EL29: ТСН-2001.4-10. Прокладка и монтаж сетей связи | EM29: ТСН-2001.4-10-1 | EO29: Поправка: Гл.12.Прил.8.п.8. 5_12.00.01.11.003 | EQ29: 0 | ER29: 93.95 | ES29: 70.17 | ET29: 2.38 | EU29: 0.25 | EV29: 21.4 | EW29: 2 | EX29: 0 | EY29: 0 | FQ29: 0 | FR29: 0 | FS29: 0 | FX29: 90 | FY29: 46 | GD29: 1 | GF29: -1502969864 | GG29: 2 | GH29: 1 | GI29: 2 | GJ29: 0 | GK29: 0 | GL29: =ROUND(IF(AND(BH29=3,BI29=3,FS29<>0),P29,0),2) -> 0 | GM29: =ROUND(O29+X29+Y29,2)+GX29 -> 3389.53 | GN29: =IF(OR(BI29=0,BI29=1),GM29-GX29,0) -> 0 | GO29: =IF(BI29=2,GM29-GX29,0) -> 3389.53 | GP29: =IF(BI29=4,GM29-GX29,0) -> 0 | GR29: 0 | GS29: 3 | GT29: 0 | GV29: =ROUND((GT29),6) -> 0 | GW29: 1 | GX29: =ROUND(HC29*I29,2) -> 0 | HA29: 0 | HB29: 0 | HC29: =GV29*GW29 -> 0 | HS29: 0 | IK29: 0
A30: 17 | B30: 1 | E30: 2 | F30: КА-1 | G30: Шкаф настенный LINEA W 18U 600x600 мм дверь стекло RAL9005 LWR5-18U66-GF | H30: шт. | I30: 1 | J30: 0 | K30: 1 | O30: =ROUND(CP30,2) -> 1952.77 | P30: =ROUND((ROUND((AC30*AW30*I30),2)*BC30),2) -> 1952.77 | Q30: =(ROUND((ROUND(((ET30)*AV30*I30),2)*BB30),2)+ROUND((ROUND(((AE30-(EU30))*AV30*I30),2)*BS30),2)) -> 0 | R30: =(ROUND((ROUND(((EU30)*AV30*I30),2)*BS30),2)+ROUND((ROUND(((AE30-(EU30))*AV30*I30),2)*BS30),2)) -> 0 | S30: =ROUND((ROUND((AF30*AV30*I30),2)*BA30),2) -> 0 | T30: =ROUND(CU30*I30,2) -> 0 | U30: =CV30*I30 -> 0 | V30: =CW30*I30 -> 0 | W30: =ROUND(CX30*I30,2) -> 0 | X30: =(ROUND((((S30+ROUND((ROUND(((EU30)*AV30*I30),2)*BS30),2))*AT30)/100),2)+ROUND(((ROUND((ROUND(((AE30-(EU30))*AV30*I30),2)*BS30),2)*AT30)/100),2)) -> 0 | Y30: =(ROUND((((S30+ROUND((ROUND(((EU30)*AV30*I30),2)*BS30),2))*AU30)/100),2)+ROUND(((ROUND((ROUND(((AE30-(EU30))*AV30*I30),2)*BS30),2)*AU30)/100),2)) -> 0 | AA30: 60256405 | AB30: =ROUND((AC30+AD30+AF30),6) -> 1952.77 | AC30: =ROUND((ES30),6) -> 1952.77 | AD30: =ROUND((((ET30)-(EU30))+AE30),6) -> 0 | AE30: =ROUND((EU30),6) -> 0 | AF30: =ROUND((EV30),6) -> 0 | AG30: =ROUND((AP30),6) -> 0 | AH30: =(EW30) -> 0 | AI30: =(EX30) -> 0 | AJ30: =(AS30) -> 0 | AK30: 1952.77 | AL30: 1952.77 | AM30: 0 | AN30: 0 | AO30: 0 | AP30: 0 | AQ30: 0 | AR30: 0 | AS30: 0 | AT30: 90 | AU30: 46 | AV30: 1 | AW30: 1 | AZ30: 1 | BA30: 1 | BB30: 1 | BC30: 1 | BH30: 3 | BI30: 2 | BM30: 68 | BN30: 0 | BP30: 0 | BQ30: 40 | BR30: 0 | BS30: 1 | BT30: 1 | BU30: 1 | BV30: 1 | BW30: 1 | BX30: 1 | BZ30: 90 | CA30: 46 | CE30: 1566 | CF30: 0 | CG30: 0 | CM30: 0 | CO30: 0 | CP30: =(P30+Q30+S30) -> 1952.77 | CQ30: =ROUND((ROUND((AC30*AW30*1),2)*BC30),2) -> 1952.77 | CR30: =(ROUND((ROUND(((ET30)*AV30*1),2)*BB30),2)+ROUND((ROUND(((AE30-(EU30))*AV30*1),2)*BS30),2)) -> 0 | CS30: =(ROUND((ROUND(((EU30)*AV30*1),2)*BS30),2)+ROUND((ROUND(((AE30-(EU30))*AV30*1),2)*BS30),2)) -> 0 | CT30: =ROUND((ROUND((AF30*AV30*1),2)*BA30),2) -> 0 | CU30: =AG30 -> 0 | CV30: =(AH30*AV30) -> 0 | CW30: =AI30 -> 0 | CX30: =AJ30 -> 0 | CY30: =(ROUND((((S30+ROUND((ROUND(((EU30)*AV30*1),2)*BS30),2))*AT30)/100),2)+ROUND(((ROUND((ROUND(((AE30-(EU30))*AV30*1),2)*BS30),2)*AT30)/100),2)) -> 0 | CZ30: =(ROUND((((S30+ROUND((ROUND(((EU30)*AV30*1),2)*BS30),2))*AU30)/100),2)+ROUND(((ROUND((ROUND(((AE30-(EU30))*AV30*1),2)*BS30),2)*AU30)/100),2)) -> 0 | DN30: 0 | DO30: 0 | DP30: 1 | DQ30: 1 | DU30: 1010 | DV30: шт. | DW30: шт. | DX30: 1 | EE30: 60088532 | EF30: 40 | EG30: Монтаж оборудования | EH30: 0 | EJ30: 2 | EK30: 68 | EL30: ТСН-2001.4-10. Прокладка и монтаж сетей связи | EM30: ТСН-2001.4-10-1 | EQ30: 0 | ER30: 0 | ES30: 1952.77 | ET30: 0 | EU30: 0 | EV30: 0 | EW30: 0 | EX30: 0 | EY30: 0 | FQ30: 0 | FR30: 0 | FS30: 0 | FX30: 90 | FY30: 46 | GA30: [22 698,04 / 1,2 / 9,88] + 2% Заг.скл | GD30: 1 | GF30: 461997237 | GG30: 2 | GH30: 4 | GI30: -2 | GJ30: 0 | GK30: 0 | GL30: =ROUND(IF(AND(BH30=3,BI30=3,FS30<>0),P30,0),2) -> 0 | GM30: =ROUND(O30+X30+Y30,2)+GX30 -> 1952.77 | GN30: =IF(OR(BI30=0,BI30=1),GM30-GX30,0) -> 0 | GO30: =IF(BI30=2,GM30-GX30,0) -> 1952.77 | GP30: =IF(BI30=4,GM30-GX30,0) -> 0 | GR30: 0 | GS30: 2 | GT30: 0 | GV30: =ROUND((GT30),6) -> 0 | GW30: 1 | GX30: =ROUND(HC30*I30,2) -> 0 | HA30: 0 | HB30: 0 | HC30: =GV30*GW30 -> 0 | HE30: 0 | HF30: 2 | HS30: 0 | IK30: 0
A31: 17 | B31: 1 | E31: 2 | F31: КА-1 | G31: Шкаф настенный LINEA W 18U 600x600 мм дверь стекло RAL9005 LWR5-18U66-GF | H31: шт. | I31: 1 | J31: 0 | K31: 1 | O31: =ROUND(CP31,2) -> 19293.37 | P31: =ROUND((ROUND((AC31*AW31*I31),2)*BC31),2) -> 19293.37 | Q31: =(ROUND((ROUND(((ET31)*AV31*I31),2)*BB31),2)+ROUND((ROUND(((AE31-(EU31))*AV31*I31),2)*BS31),2)) -> 0 | R31: =(ROUND((ROUND(((EU31)*AV31*I31),2)*BS31),2)+ROUND((ROUND(((AE31-(EU31))*AV31*I31),2)*BS31),2)) -> 0 | S31: =ROUND((ROUND((AF31*AV31*I31),2)*BA31),2) -> 0 | T31: =ROUND(CU31*I31,2) -> 0 | U31: =CV31*I31 -> 0 | V31: =CW31*I31 -> 0 | W31: =ROUND(CX31*I31,2) -> 0 | X31: =(ROUND((((S31+ROUND((ROUND(((EU31)*AV31*I31),2)*BS31),2))*AT31)/100),2)+ROUND(((ROUND((ROUND(((AE31-(EU31))*AV31*I31),2)*BS31),2)*AT31)/100),2)) -> 0 | Y31: =(ROUND((((S31+ROUND((ROUND(((EU31)*AV31*I31),2)*BS31),2))*AU31)/100),2)+ROUND(((ROUND((ROUND(((AE31-(EU31))*AV31*I31),2)*BS31),2)*AU31)/100),2)) -> 0 | AA31: 60256402 | AB31: =ROUND((AC31+AD31+AF31),6) -> 1952.77 | AC31: =ROUND((ES31),6) -> 1952.77 | AD31: =ROUND((((ET31)-(EU31))+AE31),6) -> 0 | AE31: =ROUND((EU31),6) -> 0 | AF31: =ROUND((EV31),6) -> 0 | AG31: =ROUND((AP31),6) -> 0 | AH31: =(EW31) -> 0 | AI31: =(EX31) -> 0 | AJ31: =(AS31) -> 0 | AK31: 1952.77 | AL31: 1952.77 | AM31: 0 | AN31: 0 | AO31: 0 | AP31: 0 | AQ31: 0 | AR31: 0 | AS31: 0 | AT31: 90 | AU31: 46 | AV31: 1 | AW31: 1 | AZ31: 1 | BA31: 1 | BB31: 1 | BC31: 9.88 | BH31: 3 | BI31: 2 | BM31: 68 | BN31: 0 | BP31: 0 | BQ31: 40 | BR31: 0 | BS31: 1 | BT31: 1 | BU31: 1 | BV31: 1 | BW31: 1 | BX31: 1 | BZ31: 90 | CA31: 46 | CE31: 1566 | CF31: 0 | CG31: 0 | CM31: 0 | CO31: 0 | CP31: =(P31+Q31+S31) -> 19293.37 | CQ31: =ROUND((ROUND((AC31*AW31*1),2)*BC31),2) -> 19293.37 | CR31: =(ROUND((ROUND(((ET31)*AV31*1),2)*BB31),2)+ROUND((ROUND(((AE31-(EU31))*AV31*1),2)*BS31),2)) -> 0 | CS31: =(ROUND((ROUND(((EU31)*AV31*1),2)*BS31),2)+ROUND((ROUND(((AE31-(EU31))*AV31*1),2)*BS31),2)) -> 0 | CT31: =ROUND((ROUND((AF31*AV31*1),2)*BA31),2) -> 0 | CU31: =AG31 -> 0 | CV31: =(AH31*AV31) -> 0 | CW31: =AI31 -> 0 | CX31: =AJ31 -> 0 | CY31: =(ROUND((((S31+ROUND((ROUND(((EU31)*AV31*1),2)*BS31),2))*AT31)/100),2)+ROUND(((ROUND((ROUND(((AE31-(EU31))*AV31*1),2)*BS31),2)*AT31)/100),2)) -> 0 | CZ31: =(ROUND((((S31+ROUND((ROUND(((EU31)*AV31*1),2)*BS31),2))*AU31)/100),2)+ROUND(((ROUND((ROUND(((AE31-(EU31))*AV31*1),2)*BS31),2)*AU31)/100),2)) -> 0 | DN31: 0 | DO31: 0 | DP31: 1 | DQ31: 1 | DU31: 1010 | DV31: шт. | DW31: шт. | DX31: 1 | EE31: 60088532 | EF31: 40 | EG31: Монтаж оборудования | EH31: 0 | EJ31: 2 | EK31: 68 | EL31: ТСН-2001.4-10. Прокладка и монтаж сетей связи | EM31: ТСН-2001.4-10-1 | EQ31: 0 | ER31: 1952.77 | ES31: 1952.77 | ET31: 0 | EU31: 0 | EV31: 0 | EW31: 0 | EX31: 0 | EY31: 0 | EZ31: 5 | FC31: 1 | FD31: 18 | FF31: 22698.04 | FQ31: 0 | FR31: 0 | FS31: 0 | FX31: 90 | FY31: 46 | GA31: [22 698,04 / 1,2 / 9,88] + 2% Заг.скл | GD31: 1 | GF31: 461997237 | GG31: 2 | GH31: 3 | GI31: 5 | GJ31: 0 | GK31: 0 | GL31: =ROUND(IF(AND(BH31=3,BI31=3,FS31<>0),P31,0),2) -> 0 | GM31: =ROUND(O31+X31+Y31,2)+GX31 -> 19293.37 | GN31: =IF(OR(BI31=0,BI31=1),GM31-GX31,0) -> 0 | GO31: =IF(BI31=2,GM31-GX31,0) -> 19293.37 | GP31: =IF(BI31=4,GM31-GX31,0) -> 0 | GR31: 1 | GS31: 1 | GT31: 0 | GV31: =ROUND((GT31),6) -> 0 | GW31: 1 | GX31: =ROUND(HC31*I31,2) -> 0 | HA31: 0 | HB31: 0 | HC31: =GV31*GW31 -> 0 | HE31: 0 | HF31: 2 | HS31: 0 | IK31: 0
A32: 17 | B32: 1 | C32: =ROW(SmtRes!A18) -> 18 | D32: =ROW(EtalonRes!A21) -> 21 | E32: 3 | F32: 4.10-170-2 | G32: Монтаж блока информационно-управляющего (БИУ) в диспетчерской | H32: 1 ШТ. | I32: 1 | J32: 0 | K32: 1 | O32: =ROUND(CP32,2) -> 40.89 | P32: =ROUND((ROUND((AC32*AW32*I32),2)*BC32),2) -> 2.34 | Q32: =(ROUND((ROUND((((ET32*1.1))*AV32*I32),2)*BB32),2)+ROUND((ROUND(((AE32-((EU32*1.1)))*AV32*I32),2)*BS32),2)) -> 0 | R32: =(ROUND((ROUND((((EU32*1.1))*AV32*I32),2)*BS32),2)+ROUND((ROUND(((AE32-((EU32*1.1)))*AV32*I32),2)*BS32),2)) -> 0 | S32: =ROUND((ROUND((AF32*AV32*I32),2)*BA32),2) -> 38.55 | T32: =ROUND(CU32*I32,2) -> 0 | U32: =CV32*I32 -> 3.052005 | V32: =CW32*I32 -> 0 | W32: =ROUND(CX32*I32,2) -> 0 | X32: =(ROUND((((S32+ROUND((ROUND((((EU32*1.1))*AV32*I32),2)*BS32),2))*AT32)/100),2)+ROUND(((ROUND((ROUND(((AE32-((EU32*1.1)))*AV32*I32),2)*BS32),2)*AT32)/100),2)) -> 34.7 | Y32: =(ROUND((((S32+ROUND((ROUND((((EU32*1.1))*AV32*I32),2)*BS32),2))*AU32)/100),2)+ROUND(((ROUND((ROUND(((AE32-((EU32*1.1)))*AV32*I32),2)*BS32),2)*AU32)/100),2)) -> 17.73 | AA32: 60256405 | AB32: =ROUND((AC32+AD32+AF32),6) -> 39.157 | AC32: =ROUND(((ES32*1)),6) -> 2.34 | AD32: =ROUND(((((ET32*1.1))-((EU32*1.1)))+AE32),6) -> 0 | AE32: =ROUND(((EU32*1.1)),6) -> 0 | AF32: =ROUND(((EV32*1.1)),6) -> 36.817 | AG32: =ROUND((AP32),6) -> 0 | AH32: =((EW32*1.1)) -> 2.915 | AI32: =((EX32*1.1)) -> 0 | AJ32: =(AS32) -> 0 | AK32: 35.81 | AL32: 2.34 | AM32: 0 | AN32: 0 | AO32: 33.47 | AP32: 0 | AQ32: 2.65 | AR32: 0 | AS32: 0 | AT32: 90 | AU32: 46 | AV32: 1.047 | AW32: 1 | AZ32: 1 | BA32: 1 | BB32: 1 | BC32: 1 | BH32: 0 | BI32: 2 | BJ32: ТСН-2001.4 Доп. 67, Сб. 10, т. 170, поз. 2 | BM32: 68 | BN32: 58973116 | BO32: 4.10-170-2 | BP32: 1 | BQ32: 40 | BR32: 0 | BS32: 1 | BT32: 1 | BU32: 1 | BV32: 1 | BW32: 1 | BX32: 1 | BZ32: 90 | CA32: 46 | CE32: 1566 | CF32: 0 | CG32: 0 | CM32: 0 | CN32: Поправка: Гл.12.Прил.8.п.8. 5_12.00.01.11.003 Наименование: При наличии усложненных условий производства работ (стесненность, сложность складирования и транспортной логистики, наличие в зоне производства работ действующего технологического оборудования или движения технологического транспорта и т.п.) для объектов, расположенных за пределами территории круговой магистральной системы улиц "Садовое кольцо" и за пределами Третьего транспортного кольца города Москвы пунктов "а" и "б", но в пределах Московской кольцевой автомобильной дороги | CO32: 0 | CP32: =(P32+Q32+S32) -> 40.89 | CQ32: =ROUND((ROUND((AC32*AW32*1),2)*BC32),2) -> 2.34 | CR32: =(ROUND((ROUND((((ET32*1.1))*AV32*1),2)*BB32),2)+ROUND((ROUND(((AE32-((EU32*1.1)))*AV32*1),2)*BS32),2)) -> 0 | CS32: =(ROUND((ROUND((((EU32*1.1))*AV32*1),2)*BS32),2)+ROUND((ROUND(((AE32-((EU32*1.1)))*AV32*1),2)*BS32),2)) -> 0 | CT32: =ROUND((ROUND((AF32*AV32*1),2)*BA32),2) -> 38.55 | CU32: =AG32 -> 0 | CV32: =(AH32*AV32) -> 3.052005 | CW32: =AI32 -> 0 | CX32: =AJ32 -> 0 | CY32: =(ROUND((((S32+ROUND((ROUND((((EU32*1.1))*AV32*1),2)*BS32),2))*AT32)/100),2)+ROUND(((ROUND((ROUND(((AE32-((EU32*1.1)))*AV32*1),2)*BS32),2)*AT32)/100),2)) -> 34.7 | CZ32: =(ROUND((((S32+ROUND((ROUND((((EU32*1.1))*AV32*1),2)*BS32),2))*AU32)/100),2)+ROUND(((ROUND((ROUND(((AE32-((EU32*1.1)))*AV32*1),2)*BS32),2)*AU32)/100),2)) -> 17.73 | DB32: 3 | DD32: *1 | DE32: *1,1 | DF32: *1,1 | DG32: *1,1 | DI32: *1,1 | DJ32: *1,1 | DN32: 0 | DO32: 0 | DP32: 1 | DQ32: 1 | DU32: 1013 | DV32: 1 ШТ. | DW32: 1 ШТ. | DX32: 1 | EE32: 60088532 | EF32: 40 | EG32: Монтаж оборудования | EH32: 0 | EJ32: 2 | EK32: 68 | EL32: ТСН-2001.4-10. Прокладка и монтаж сетей связи | EM32: ТСН-2001.4-10-1 | EO32: Поправка: Гл.12.Прил.8.п.8. 5_12.00.01.11.003 | EQ32: 0 | ER32: 35.81 | ES32: 2.34 | ET32: 0 | EU32: 0 | EV32: 33.47 | EW32: 2.65 | EX32: 0 | EY32: 0 | FQ32: 0 | FR32: 0 | FS32: 0 | FX32: 90 | FY32: 46 | GD32: 1 | GF32: -1323780471 | GG32: 2 | GH32: 1 | GI32: 2 | GJ32: 0 | GK32: 0 | GL32: =ROUND(IF(AND(BH32=3,BI32=3,FS32<>0),P32,0),2) -> 0 | GM32: =ROUND(O32+X32+Y32,2)+GX32 -> 93.32 | GN32: =IF(OR(BI32=0,BI32=1),GM32-GX32,0) -> 0 | GO32: =IF(BI32=2,GM32-GX32,0) -> 93.32 | GP32: =IF(BI32=4,GM32-GX32,0) -> 0 | GR32: 0 | GS32: 3 | GT32: 0 | GV32: =ROUND((GT32),6) -> 0 | GW32: 1 | GX32: =ROUND(HC32*I32,2) -> 0 | HA32: 0 | HB32: 0 | HC32: =GV32*GW32 -> 0 | HS32: 0 | IK32: 0
A33: 17 | B33: 1 | C33: =ROW(SmtRes!A22) -> 22 | D33: =ROW(EtalonRes!A26) -> 26 | E33: 3 | F33: 4.10-170-2 | G33: Монтаж блока информационно-управляющего (БИУ) в диспетчерской | H33: 1 ШТ. | I33: 1 | J33: 0 | K33: 1 | O33: =ROUND(CP33,2) -> 2143.87 | P33: =ROUND((ROUND((AC33*AW33*I33),2)*BC33),2) -> 24.01 | Q33: =(ROUND((ROUND((((ET33*1.1))*AV33*I33),2)*BB33),2)+ROUND((ROUND(((AE33-((EU33*1.1)))*AV33*I33),2)*BS33),2)) -> 0 | R33: =(ROUND((ROUND((((EU33*1.1))*AV33*I33),2)*BS33),2)+ROUND((ROUND(((AE33-((EU33*1.1)))*AV33*I33),2)*BS33),2)) -> 0 | S33: =ROUND((ROUND((AF33*AV33*I33),2)*BA33),2) -> 2119.86 | T33: =ROUND(CU33*I33,2) -> 0 | U33: =CV33*I33 -> 3.052005 | V33: =CW33*I33 -> 0 | W33: =ROUND(CX33*I33,2) -> 0 | X33: =(ROUND((((S33+ROUND((ROUND((((EU33*1.1))*AV33*I33),2)*BS33),2))*AT33)/100),2)+ROUND(((ROUND((ROUND(((AE33-((EU33*1.1)))*AV33*I33),2)*BS33),2)*AT33)/100),2)) -> 1907.87 | Y33: =(ROUND((((S33+ROUND((ROUND((((EU33*1.1))*AV33*I33),2)*BS33),2))*AU33)/100),2)+ROUND(((ROUND((ROUND(((AE33-((EU33*1.1)))*AV33*I33),2)*BS33),2)*AU33)/100),2)) -> 975.14 | AA33: 60256402 | AB33: =ROUND((AC33+AD33+AF33),6) -> 39.157 | AC33: =ROUND(((ES33*1)),6) -> 2.34 | AD33: =ROUND(((((ET33*1.1))-((EU33*1.1)))+AE33),6) -> 0 | AE33: =ROUND(((EU33*1.1)),6) -> 0 | AF33: =ROUND(((EV33*1.1)),6) -> 36.817 | AG33: =ROUND((AP33),6) -> 0 | AH33: =((EW33*1.1)) -> 2.915 | AI33: =((EX33*1.1)) -> 0 | AJ33: =(AS33) -> 0 | AK33: 35.81 | AL33: 2.34 | AM33: 0 | AN33: 0 | AO33: 33.47 | AP33: 0 | AQ33: 2.65 | AR33: 0 | AS33: 0 | AT33: 90 | AU33: 46 | AV33: 1.047 | AW33: 1 | AZ33: 1 | BA33: 54.99 | BB33: 1 | BC33: 10.26 | BH33: 0 | BI33: 2 | BJ33: ТСН-2001.4 Доп. 67, Сб. 10, т. 170, поз. 2 | BM33: 68 | BN33: 58973116 | BO33: 4.10-170-2 | BP33: 1 | BQ33: 40 | BR33: 0 | BS33: 54.99 | BT33: 1 | BU33: 1 | BV33: 1 | BW33: 1 | BX33: 1 | BZ33: 90 | CA33: 46 | CE33: 1566 | CF33: 0 | CG33: 0 | CM33: 0 | CN33: Поправка: Гл.12.Прил.8.п.8. 5_12.00.01.11.003 Наименование: При наличии усложненных условий производства работ (стесненность, сложность складирования и транспортной логистики, наличие в зоне производства работ действующего технологического оборудования или движения технологического транспорта и т.п.) для объектов, расположенных за пределами территории круговой магистральной системы улиц "Садовое кольцо" и за пределами Третьего транспортного кольца города Москвы пунктов "а" и "б", но в пределах Московской кольцевой автомобильной дороги | CO33: 0 | CP33: =(P33+Q33+S33) -> 2143.87 | CQ33: =ROUND((ROUND((AC33*AW33*1),2)*BC33),2) -> 24.01 | CR33: =(ROUND((ROUND((((ET33*1.1))*AV33*1),2)*BB33),2)+ROUND((ROUND(((AE33-((EU33*1.1)))*AV33*1),2)*BS33),2)) -> 0 | CS33: =(ROUND((ROUND((((EU33*1.1))*AV33*1),2)*BS33),2)+ROUND((ROUND(((AE33-((EU33*1.1)))*AV33*1),2)*BS33),2)) -> 0 | CT33: =ROUND((ROUND((AF33*AV33*1),2)*BA33),2) -> 2119.86 | CU33: =AG33 -> 0 | CV33: =(AH33*AV33) -> 3.052005 | CW33: =AI33 -> 0 | CX33: =AJ33 -> 0 | CY33: =(ROUND((((S33+ROUND((ROUND((((EU33*1.1))*AV33*1),2)*BS33),2))*AT33)/100),2)+ROUND(((ROUND((ROUND(((AE33-((EU33*1.1)))*AV33*1),2)*BS33),2)*AT33)/100),2)) -> 1907.87 | CZ33: =(ROUND((((S33+ROUND((ROUND((((EU33*1.1))*AV33*1),2)*BS33),2))*AU33)/100),2)+ROUND(((ROUND((ROUND(((AE33-((EU33*1.1)))*AV33*1),2)*BS33),2)*AU33)/100),2)) -> 975.14 | DB33: 4 | DD33: *1 | DE33: *1,1 | DF33: *1,1 | DG33: *1,1 | DI33: *1,1 | DJ33: *1,1 | DN33: 0 | DO33: 0 | DP33: 1 | DQ33: 1 | DU33: 1013 | DV33: 1 ШТ. | DW33: 1 ШТ. | DX33: 1 | EE33: 60088532 | EF33: 40 | EG33: Монтаж оборудования | EH33: 0 | EJ33: 2 | EK33: 68 | EL33: ТСН-2001.4-10. Прокладка и монтаж сетей связи | EM33: ТСН-2001.4-10-1 | EO33: Поправка: Гл.12.Прил.8.п.8. 5_12.00.01.11.003 | EQ33: 0 | ER33: 35.81 | ES33: 2.34 | ET33: 0 | EU33: 0 | EV33: 33.47 | EW33: 2.65 | EX33: 0 | EY33: 0 | FQ33: 0 | FR33: 0 | FS33: 0 | FX33: 90 | FY33: 46 | GD33: 1 | GF33: -1323780471 | GG33: 2 | GH33: 1 | GI33: 2 | GJ33: 0 | GK33: 0 | GL33: =ROUND(IF(AND(BH33=3,BI33=3,FS33<>0),P33,0),2) -> 0 | GM33: =ROUND(O33+X33+Y33,2)+GX33 -> 5026.88 | GN33: =IF(OR(BI33=0,BI33=1),GM33-GX33,0) -> 0 | GO33: =IF(BI33=2,GM33-GX33,0) -> 5026.88 | GP33: =IF(BI33=4,GM33-GX33,0) -> 0 | GR33: 0 | GS33: 3 | GT33: 0 | GV33: =ROUND((GT33),6) -> 0 | GW33: 1 | GX33: =ROUND(HC33*I33,2) -> 0 | HA33: 0 | HB33: 0 | HC33: =GV33*GW33 -> 0 | HS33: 0 | IK33: 0
A34: 17 | B34: 1 | E34: 4 | F34: КА-2 | G34: Прибор управления оповещением пожарной Sonar SPM, мощность850 Вт, 20 зон/20 линий оповещения, прием сигнала от ОПС по АЛС, установка в стойку Sonar SPM-C20085-AR | H34: шт. | I34: 1 | J34: 0 | K34: 1 | O34: =ROUND(CP34,2) -> 32107.68 | P34: =ROUND((ROUND((AC34*I34),2)*BC34),2) -> 32107.68 | Q34: =(ROUND((ROUND(((ET34)*AV34*I34),2)*BB34),2)+ROUND((ROUND(((AE34-(EU34))*AV34*I34),2)*BS34),2)) -> 0 | R34: =(ROUND((ROUND(((EU34)*AV34*I34),2)*BS34),2)+ROUND((ROUND(((AE34-(EU34))*AV34*I34),2)*BS34),2)) -> 0 | S34: =ROUND((ROUND((AF34*AV34*I34),2)*BA34),2) -> 0 | T34: =ROUND(CU34*I34,2) -> 0 | U34: =CV34*I34 -> 0 | V34: =CW34*I34 -> 0 | W34: =ROUND(CX34*I34,2) -> 0 | X34: =(ROUND((((S34+ROUND((ROUND(((EU34)*AV34*I34),2)*BS34),2))*AT34)/100),2)+ROUND(((ROUND((ROUND(((AE34-(EU34))*AV34*I34),2)*BS34),2)*AT34)/100),2)) -> 0 | Y34: =(ROUND((((S34+ROUND((ROUND(((EU34)*AV34*I34),2)*BS34),2))*AU34)/100),2)+ROUND(((ROUND((ROUND(((AE34-(EU34))*AV34*I34),2)*BS34),2)*AU34)/100),2)) -> 0 | AA34: 60256405 | AB34: =ROUND((AC34+AD34+AF34),6) -> 32107.68 | AC34: =ROUND((ES34),6) -> 32107.68 | AD34: =ROUND((((ET34)-(EU34))+AE34),6) -> 0 | AE34: =ROUND((EU34),6) -> 0 | AF34: =ROUND((EV34),6) -> 0 | AG34: =ROUND((AP34),6) -> 0 | AH34: =(EW34) -> 0 | AI34: =(EX34) -> 0 | AJ34: =(AS34) -> 0 | AK34: 32107.68 | AL34: 32107.68 | AM34: 0 | AN34: 0 | AO34: 0 | AP34: 0 | AQ34: 0 | AR34: 0 | AS34: 0 | AT34: 0 | AU34: 0 | AV34: 1 | AW34: 1 | AZ34: 1 | BA34: 1 | BB34: 1 | BC34: 1 | BH34: 3 | BI34: 3 | BM34: 746 | BN34: 0 | BP34: 0 | BQ34: 130 | BR34: 0 | BS34: 1 | BT34: 1 | BU34: 1 | BV34: 1 | BW34: 1 | BX34: 1 | BZ34: 0 | CA34: 0 | CE34: 1566 | CF34: 0 | CG34: 0 | CM34: 0 | CO34: 0 | CP34: =(P34+Q34+S34) -> 32107.68 | CQ34: =ROUND((ROUND((AC34*1),2)*BC34),2) -> 32107.68 | CR34: =(ROUND((ROUND(((ET34)*AV34*1),2)*BB34),2)+ROUND((ROUND(((AE34-(EU34))*AV34*1),2)*BS34),2)) -> 0 | CS34: =(ROUND((ROUND(((EU34)*AV34*1),2)*BS34),2)+ROUND((ROUND(((AE34-(EU34))*AV34*1),2)*BS34),2)) -> 0 | CT34: =ROUND((ROUND((AF34*AV34*1),2)*BA34),2) -> 0 | CU34: =AG34 -> 0 | CV34: =(AH34*AV34) -> 0 | CW34: =AI34 -> 0 | CX34: =AJ34 -> 0 | CY34: =(ROUND((((S34+ROUND((ROUND(((EU34)*AV34*1),2)*BS34),2))*AT34)/100),2)+ROUND(((ROUND((ROUND(((AE34-(EU34))*AV34*1),2)*BS34),2)*AT34)/100),2)) -> 0 | CZ34: =(ROUND((((S34+ROUND((ROUND(((EU34)*AV34*1),2)*BS34),2))*AU34)/100),2)+ROUND(((ROUND((ROUND(((AE34-(EU34))*AV34*1),2)*BS34),2)*AU34)/100),2)) -> 0 | DN34: 0 | DO34: 0 | DP34: 1 | DQ34: 1 | DU34: 1010 | DV34: шт. | DW34: шт. | DX34: 1 | EE34: 60088638 | EF34: 130 | EG34: Сметная стоимость оборудования | EH34: 0 | EJ34: 3 | EK34: 746 | EL34: ТСН-2001.13. Сметная стоимость оборудования | EM34: ТСН-2001.13 | EQ34: 0 | ER34: 0 | ES34: 32107.68 | ET34: 0 | EU34: 0 | EV34: 0 | EW34: 0 | EX34: 0 | EY34: 0 | FQ34: 0 | FR34: =P34 -> 32107.68 | FS34: 0 | FX34: 0 | FY34: 0 | GA34: [283 140 / 1,2 / 7,66] + 3% Трансп + 1,2% Заг.скл | GD34: 1 | GF34: -1433651412 | GG34: 2 | GH34: 4 | GI34: -2 | GJ34: 0 | GK34: 0 | GL34: =ROUND(IF(AND(BH34=3,BI34=3,FS34<>0),P34,0),2) -> 0 | GM34: =ROUND(O34+X34+Y34,2)+GX34 -> 32107.68 | GN34: =IF(OR(BI34=0,BI34=1),GM34-GX34,0) -> 0 | GO34: =IF(BI34=2,GM34-GX34,0) -> 0 | GP34: =IF(BI34=4,GM34-GX34,0) -> 0 | GR34: 0 | GS34: 2 | GT34: 0 | GV34: =ROUND((GT34),6) -> 0 | GW34: 1 | GX34: =ROUND(HC34*I34,2) -> 0 | HA34: 0 | HB34: 0 | HC34: =GV34*GW34 -> 0 | HE34: 3 | HF34: 1,2 | HS34: 0 | IK34: 0
A35: 17 | B35: 1 | E35: 4 | F35: КА-2 | G35: Прибор управления оповещением пожарной Sonar SPM, мощность850 Вт, 20 зон/20 линий оповещения, прием сигнала от ОПС по АЛС, установка в стойку Sonar SPM-C20085-AR | H35: шт. | I35: 1 | J35: 0 | K35: 1 | O35: =ROUND(CP35,2) -> 245944.83 | P35: =ROUND((ROUND((AC35*I35),2)*BC35),2) -> 245944.83 | Q35: =(ROUND((ROUND(((ET35)*AV35*I35),2)*BB35),2)+ROUND((ROUND(((AE35-(EU35))*AV35*I35),2)*BS35),2)) -> 0 | R35: =(ROUND((ROUND(((EU35)*AV35*I35),2)*BS35),2)+ROUND((ROUND(((AE35-(EU35))*AV35*I35),2)*BS35),2)) -> 0 | S35: =ROUND((ROUND((AF35*AV35*I35),2)*BA35),2) -> 0 | T35: =ROUND(CU35*I35,2) -> 0 | U35: =CV35*I35 -> 0 | V35: =CW35*I35 -> 0 | W35: =ROUND(CX35*I35,2) -> 0 | X35: =(ROUND((((S35+ROUND((ROUND(((EU35)*AV35*I35),2)*BS35),2))*AT35)/100),2)+ROUND(((ROUND((ROUND(((AE35-(EU35))*AV35*I35),2)*BS35),2)*AT35)/100),2)) -> 0 | Y35: =(ROUND((((S35+ROUND((ROUND(((EU35)*AV35*I35),2)*BS35),2))*AU35)/100),2)+ROUND(((ROUND((ROUND(((AE35-(EU35))*AV35*I35),2)*BS35),2)*AU35)/100),2)) -> 0 | AA35: 60256402 | AB35: =ROUND((AC35+AD35+AF35),6) -> 32107.68 | AC35: =ROUND((ES35),6) -> 32107.68 | AD35: =ROUND((((ET35)-(EU35))+AE35),6) -> 0 | AE35: =ROUND((EU35),6) -> 0 | AF35: =ROUND((EV35),6) -> 0 | AG35: =ROUND((AP35),6) -> 0 | AH35: =(EW35) -> 0 | AI35: =(EX35) -> 0 | AJ35: =(AS35) -> 0 | AK35: 32107.68 | AL35: 32107.68 | AM35: 0 | AN35: 0 | AO35: 0 | AP35: 0 | AQ35: 0 | AR35: 0 | AS35: 0 | AT35: 0 | AU35: 0 | AV35: 1 | AW35: 1 | AZ35: 1 | BA35: 1 | BB35: 1 | BC35: 7.66 | BH35: 3 | BI35: 3 | BM35: 746 | BN35: 0 | BP35: 0 | BQ35: 130 | BR35: 0 | BS35: 1 | BT35: 1 | BU35: 1 | BV35: 1 | BW35: 1 | BX35: 1 | BZ35: 0 | CA35: 0 | CE35: 1566 | CF35: 0 | CG35: 0 | CM35: 0 | CO35: 0 | CP35: =(P35+Q35+S35) -> 245944.83 | CQ35: =ROUND((ROUND((AC35*1),2)*BC35),2) -> 245944.83 | CR35: =(ROUND((ROUND(((ET35)*AV35*1),2)*BB35),2)+ROUND((ROUND(((AE35-(EU35))*AV35*1),2)*BS35),2)) -> 0 | CS35: =(ROUND((ROUND(((EU35)*AV35*1),2)*BS35),2)+ROUND((ROUND(((AE35-(EU35))*AV35*1),2)*BS35),2)) -> 0 | CT35: =ROUND((ROUND((AF35*AV35*1),2)*BA35),2) -> 0 | CU35: =AG35 -> 0 | CV35: =(AH35*AV35) -> 0 | CW35: =AI35 -> 0 | CX35: =AJ35 -> 0 | CY35: =(ROUND((((S35+ROUND((ROUND(((EU35)*AV35*1),2)*BS35),2))*AT35)/100),2)+ROUND(((ROUND((ROUND(((AE35-(EU35))*AV35*1),2)*BS35),2)*AT35)/100),2)) -> 0 | CZ35: =(ROUND((((S35+ROUND((ROUND(((EU35)*AV35*1),2)*BS35),2))*AU35)/100),2)+ROUND(((ROUND((ROUND(((AE35-(EU35))*AV35*1),2)*BS35),2)*AU35)/100),2)) -> 0 | DN35: 0 | DO35: 0 | DP35: 1 | DQ35: 1 | DU35: 1010 | DV35: шт. | DW35: шт. | DX35: 1 | EE35: 60088638 | EF35: 130 | EG35: Сметная стоимость оборудования | EH35: 0 | EJ35: 3 | EK35: 746 | EL35: ТСН-2001.13. Сметная стоимость оборудования | EM35: ТСН-2001.13 | EQ35: 0 | ER35: 24359.21 | ES35: 32107.68 | ET35: 0 | EU35: 0 | EV35: 0 | EW35: 0 | EX35: 0 | EY35: 0 | EZ35: 5 | FC35: 1 | FD35: 18 | FF35: 283140 | FQ35: 0 | FR35: =P35 -> 245944.83 | FS35: 0 | FX35: 0 | FY35: 0 | GA35: [283 140 / 1,2 / 7,66] + 3% Трансп + 1,2% Заг.скл | GD35: 1 | GF35: -1433651412 | GG35: 2 | GH35: 3 | GI35: 5 | GJ35: 0 | GK35: 0 | GL35: =ROUND(IF(AND(BH35=3,BI35=3,FS35<>0),P35,0),2) -> 0 | GM35: =ROUND(O35+X35+Y35,2)+GX35 -> 245944.83 | GN35: =IF(OR(BI35=0,BI35=1),GM35-GX35,0) -> 0 | GO35: =IF(BI35=2,GM35-GX35,0) -> 0 | GP35: =IF(BI35=4,GM35-GX35,0) -> 0 | GR35: 1 | GS35: 1 | GT35: 0 | GV35: =ROUND((GT35),6) -> 0 | GW35: 1 | GX35: =ROUND(HC35*I35,2) -> 0 | HA35: 0 | HB35: 0 | HC35: =GV35*GW35 -> 0 | HE35: 3 | HF35: 1,2 | HS35: 0 | IK35: 0
A36: 17 | B36: 1 | C36: =ROW(SmtRes!A24) -> 24 | D36: =ROW(EtalonRes!A29) -> 29 | E36: 5 | F36: 4.11-12-1 | G36: Установка съемных и выдвижных блоков (модулей, ячеек, ТЭЗ) массой до 5 кг | H36: 1 ШТ. | I36: 1 | J36: 0 | K36: 1 | O36: =ROUND(CP36,2) -> 14 | P36: =ROUND((ROUND((AC36*AW36*I36),2)*BC36),2) -> 0 | Q36: =(ROUND((ROUND((((ET36*1.1))*AV36*I36),2)*BB36),2)+ROUND((ROUND(((AE36-((EU36*1.1)))*AV36*I36),2)*BS36),2)) -> 0.58 | R36: =(ROUND((ROUND((((EU36*1.1))*AV36*I36),2)*BS36),2)+ROUND((ROUND(((AE36-((EU36*1.1)))*AV36*I36),2)*BS36),2)) -> 0.09 | S36: =ROUND((ROUND((AF36*AV36*I36),2)*BA36),2) -> 13.42 | T36: =ROUND(CU36*I36,2) -> 0 | U36: =CV36*I36 -> 1.186251 | V36: =CW36*I36 -> 0 | W36: =ROUND(CX36*I36,2) -> 0 | X36: =(ROUND((((S36+ROUND((ROUND((((EU36*1.1))*AV36*I36),2)*BS36),2))*AT36)/100),2)+ROUND(((ROUND((ROUND(((AE36-((EU36*1.1)))*AV36*I36),2)*BS36),2)*AT36)/100),2)) -> 12.16 | Y36: =(ROUND((((S36+ROUND((ROUND((((EU36*1.1))*AV36*I36),2)*BS36),2))*AU36)/100),2)+ROUND(((ROUND((ROUND(((AE36-((EU36*1.1)))*AV36*I36),2)*BS36),2)*AU36)/100),2)) -> 6.21 | AA36: 60256405 | AB36: =ROUND((AC36+AD36+AF36),6) -> 13.365 | AC36: =ROUND(((ES36*1)),6) -> 0 | AD36: =ROUND(((((ET36*1.1))-((EU36*1.1)))+AE36),6) -> 0.55 | AE36: =ROUND(((EU36*1.1)),6) -> 0.088 | AF36: =ROUND(((EV36*1.1)),6) -> 12.815 | AG36: =ROUND((AP36),6) -> 0 | AH36: =((EW36*1.1)) -> 1.133 | AI36: =((EX36*1.1)) -> 0 | AJ36: =(AS36) -> 0 | AK36: 12.15 | AL36: 0 | AM36: 0.5 | AN36: 0.08 | AO36: 11.65 | AP36: 0 | AQ36: 1.03 | AR36: 0 | AS36: 0 | AT36: 90 | AU36: 46 | AV36: 1.047 | AW36: 1 | AZ36: 1 | BA36: 1 | BB36: 1 | BC36: 1 | BH36: 0 | BI36: 2 | BJ36: ТСН-2001.4 Доп. 68, Сб. 11, т. 12, поз. 1 | BM36: 72 | BN36: 58973116 | BO36: 4.11-12-1 | BP36: 1 | BQ36: 40 | BR36: 0 | BS36: 1 | BT36: 1 | BU36: 1 | BV36: 1 | BW36: 1 | BX36: 1 | BZ36: 90 | CA36: 46 | CE36: 1566 | CF36: 0 | CG36: 0 | CM36: 0 | CN36: Поправка: Гл.12.Прил.8.п.8. 5_12.00.01.11.003 Наименование: При наличии усложненных условий производства работ (стесненность, сложность складирования и транспортной логистики, наличие в зоне производства работ действующего технологического оборудования или движения технологического транспорта и т.п.) для объектов, расположенных за пределами территории круговой магистральной системы улиц "Садовое кольцо" и за пределами Третьего транспортного кольца города Москвы пунктов "а" и "б", но в пределах Московской кольцевой автомобильной дороги | CO36: 0 | CP36: =(P36+Q36+S36) -> 14 | CQ36: =ROUND((ROUND((AC36*AW36*1),2)*BC36),2) -> 0 | CR36: =(ROUND((ROUND((((ET36*1.1))*AV36*1),2)*BB36),2)+ROUND((ROUND(((AE36-((EU36*1.1)))*AV36*1),2)*BS36),2)) -> 0.58 | CS36: =(ROUND((ROUND((((EU36*1.1))*AV36*1),2)*BS36),2)+ROUND((ROUND(((AE36-((EU36*1.1)))*AV36*1),2)*BS36),2)) -> 0.09 | CT36: =ROUND((ROUND((AF36*AV36*1),2)*BA36),2) -> 13.42 | CU36: =AG36 -> 0 | CV36: =(AH36*AV36) -> 1.186251 | CW36: =AI36 -> 0 | CX36: =AJ36 -> 0 | CY36: =(ROUND((((S36+ROUND((ROUND((((EU36*1.1))*AV36*1),2)*BS36),2))*AT36)/100),2)+ROUND(((ROUND((ROUND(((AE36-((EU36*1.1)))*AV36*1),2)*BS36),2)*AT36)/100),2)) -> 12.16 | CZ36: =(ROUND((((S36+ROUND((ROUND((((EU36*1.1))*AV36*1),2)*BS36),2))*AU36)/100),2)+ROUND(((ROUND((ROUND(((AE36-((EU36*1.1)))*AV36*1),2)*BS36),2)*AU36)/100),2)) -> 6.21 | DB36: 5 | DD36: *1 | DE36: *1,1 | DF36: *1,1 | DG36: *1,1 | DI36: *1,1 | DJ36: *1,1 | DN36: 0 | DO36: 0 | DP36: 1 | DQ36: 1 | DU36: 1013 | DV36: 1 ШТ. | DW36: 1 ШТ. | DX36: 1 | EE36: 60088536 | EF36: 40 | EG36: Монтаж оборудования | EH36: 0 | EJ36: 2 | EK36: 72 | EL36: ТСН-2001.4-11. Приборы и средства автоматизации и вычислительной техники | EM36: ТСН-2001.4-11-1 | EO36: Поправка: Гл.12.Прил.8.п.8. 5_12.00.01.11.003 | EQ36: 0 | ER36: 12.15 | ES36: 0 | ET36: 0.5 | EU36: 0.08 | EV36: 11.65 | EW36: 1.03 | EX36: 0 | EY36: 0 | FQ36: 0 | FR36: 0 | FS36: 0 | FX36: 90 | FY36: 46 | GD36: 1 | GF36: 1708693888 | GG36: 2 | GH36: 1 | GI36: 2 | GJ36: 0 | GK36: 0 | GL36: =ROUND(IF(AND(BH36=3,BI36=3,FS36<>0),P36,0),2) -> 0 | GM36: =ROUND(O36+X36+Y36,2)+GX36 -> 32.37 | GN36: =IF(OR(BI36=0,BI36=1),GM36-GX36,0) -> 0 | GO36: =IF(BI36=2,GM36-GX36,0) -> 32.37 | GP36: =IF(BI36=4,GM36-GX36,0) -> 0 | GR36: 0 | GS36: 3 | GT36: 0 | GV36: =ROUND((GT36),6) -> 0 | GW36: 1 | GX36: =ROUND(HC36*I36,2) -> 0 | HA36: 0 | HB36: 0 | HC36: =GV36*GW36 -> 0 | HS36: 0 | IK36: 0
A37: 17 | B37: 1 | C37: =ROW(SmtRes!A26) -> 26 | D37: =ROW(EtalonRes!A32) -> 32 | E37: 5 | F37: 4.11-12-1 | G37: Установка съемных и выдвижных блоков (модулей, ячеек, ТЭЗ) массой до 5 кг | H37: 1 ШТ. | I37: 1 | J37: 0 | K37: 1 | O37: =ROUND(CP37,2) -> 747.4 | P37: =ROUND((ROUND((AC37*AW37*I37),2)*BC37),2) -> 0 | Q37: =(ROUND((ROUND((((ET37*1.1))*AV37*I37),2)*BB37),2)+ROUND((ROUND(((AE37-((EU37*1.1)))*AV37*I37),2)*BS37),2)) -> 9.43 | R37: =(ROUND((ROUND((((EU37*1.1))*AV37*I37),2)*BS37),2)+ROUND((ROUND(((AE37-((EU37*1.1)))*AV37*I37),2)*BS37),2)) -> 4.95 | S37: =ROUND((ROUND((AF37*AV37*I37),2)*BA37),2) -> 737.97 | T37: =ROUND(CU37*I37,2) -> 0 | U37: =CV37*I37 -> 1.186251 | V37: =CW37*I37 -> 0 | W37: =ROUND(CX37*I37,2) -> 0 | X37: =(ROUND((((S37+ROUND((ROUND((((EU37*1.1))*AV37*I37),2)*BS37),2))*AT37)/100),2)+ROUND(((ROUND((ROUND(((AE37-((EU37*1.1)))*AV37*I37),2)*BS37),2)*AT37)/100),2)) -> 668.63 | Y37: =(ROUND((((S37+ROUND((ROUND((((EU37*1.1))*AV37*I37),2)*BS37),2))*AU37)/100),2)+ROUND(((ROUND((ROUND(((AE37-((EU37*1.1)))*AV37*I37),2)*BS37),2)*AU37)/100),2)) -> 341.74 | AA37: 60256402 | AB37: =ROUND((AC37+AD37+AF37),6) -> 13.365 | AC37: =ROUND(((ES37*1)),6) -> 0 | AD37: =ROUND(((((ET37*1.1))-((EU37*1.1)))+AE37),6) -> 0.55 | AE37: =ROUND(((EU37*1.1)),6) -> 0.088 | AF37: =ROUND(((EV37*1.1)),6) -> 12.815 | AG37: =ROUND((AP37),6) -> 0 | AH37: =((EW37*1.1)) -> 1.133 | AI37: =((EX37*1.1)) -> 0 | AJ37: =(AS37) -> 0 | AK37: 12.15 | AL37: 0 | AM37: 0.5 | AN37: 0.08 | AO37: 11.65 | AP37: 0 | AQ37: 1.03 | AR37: 0 | AS37: 0 | AT37: 90 | AU37: 46 | AV37: 1.047 | AW37: 1 | AZ37: 1 | BA37: 54.99 | BB37: 16.26 | BC37: 1 | BH37: 0 | BI37: 2 | BJ37: ТСН-2001.4 Доп. 68, Сб. 11, т. 12, поз. 1 | BM37: 72 | BN37: 58973116 | BO37: 4.11-12-1 | BP37: 1 | BQ37: 40 | BR37: 0 | BS37: 54.99 | BT37: 1 | BU37: 1 | BV37: 1 | BW37: 1 | BX37: 1 | BZ37: 90 | CA37: 46 | CE37: 1566 | CF37: 0 | CG37: 0 | CM37: 0 | CN37: Поправка: Гл.12.Прил.8.п.8. 5_12.00.01.11.003 Наименование: При наличии усложненных условий производства работ (стесненность, сложность складирования и транспортной логистики, наличие в зоне производства работ действующего технологического оборудования или движения технологического транспорта и т.п.) для объектов, расположенных за пределами территории круговой магистральной системы улиц "Садовое кольцо" и за пределами Третьего транспортного кольца города Москвы пунктов "а" и "б", но в пределах Московской кольцевой автомобильной дороги | CO37: 0 | CP37: =(P37+Q37+S37) -> 747.4 | CQ37: =ROUND((ROUND((AC37*AW37*1),2)*BC37),2) -> 0 | CR37: =(ROUND((ROUND((((ET37*1.1))*AV37*1),2)*BB37),2)+ROUND((ROUND(((AE37-((EU37*1.1)))*AV37*1),2)*BS37),2)) -> 9.43 | CS37: =(ROUND((ROUND((((EU37*1.1))*AV37*1),2)*BS37),2)+ROUND((ROUND(((AE37-((EU37*1.1)))*AV37*1),2)*BS37),2)) -> 4.95 | CT37: =ROUND((ROUND((AF37*AV37*1),2)*BA37),2) -> 737.97 | CU37: =AG37 -> 0 | CV37: =(AH37*AV37) -> 1.186251 | CW37: =AI37 -> 0 | CX37: =AJ37 -> 0 | CY37: =(ROUND((((S37+ROUND((ROUND((((EU37*1.1))*AV37*1),2)*BS37),2))*AT37)/100),2)+ROUND(((ROUND((ROUND(((AE37-((EU37*1.1)))*AV37*1),2)*BS37),2)*AT37)/100),2)) -> 668.63 | CZ37: =(ROUND((((S37+ROUND((ROUND((((EU37*1.1))*AV37*1),2)*BS37),2))*AU37)/100),2)+ROUND(((ROUND((ROUND(((AE37-((EU37*1.1)))*AV37*1),2)*BS37),2)*AU37)/100),2)) -> 341.74 | DB37: 6 | DD37: *1 | DE37: *1,1 | DF37: *1,1 | DG37: *1,1 | DI37: *1,1 | DJ37: *1,1 | DN37: 0 | DO37: 0 | DP37: 1 | DQ37: 1 | DU37: 1013 | DV37: 1 ШТ. | DW37: 1 ШТ. | DX37: 1 | EE37: 60088536 | EF37: 40 | EG37: Монтаж оборудования | EH37: 0 | EJ37: 2 | EK37: 72 | EL37: ТСН-2001.4-11. Приборы и средства автоматизации и вычислительной техники | EM37: ТСН-2001.4-11-1 | EO37: Поправка: Гл.12.Прил.8.п.8. 5_12.00.01.11.003 | EQ37: 0 | ER37: 12.15 | ES37: 0 | ET37: 0.5 | EU37: 0.08 | EV37: 11.65 | EW37: 1.03 | EX37: 0 | EY37: 0 | FQ37: 0 | FR37: 0 | FS37: 0 | FX37: 90 | FY37: 46 | GD37: 1 | GF37: 1708693888 | GG37: 2 | GH37: 1 | GI37: 2 | GJ37: 0 | GK37: 0 | GL37: =ROUND(IF(AND(BH37=3,BI37=3,FS37<>0),P37,0),2) -> 0 | GM37: =ROUND(O37+X37+Y37,2)+GX37 -> 1757.77 | GN37: =IF(OR(BI37=0,BI37=1),GM37-GX37,0) -> 0 | GO37: =IF(BI37=2,GM37-GX37,0) -> 1757.77 | GP37: =IF(BI37=4,GM37-GX37,0) -> 0 | GR37: 0 | GS37: 3 | GT37: 0 | GV37: =ROUND((GT37),6) -> 0 | GW37: 1 | GX37: =ROUND(HC37*I37,2) -> 0 | HA37: 0 | HB37: 0 | HC37: =GV37*GW37 -> 0 | HS37: 0 | IK37: 0
A38: 17 | B38: 1 | E38: 6 | F38: КА-3 | G38: Конвертер DAP-IP для объединения приборов Sonar SPM в сеть Ethernet Sonar SNCA-8002 | H38: шт. | I38: 1 | J38: 0 | K38: 1 | O38: =ROUND(CP38,2) -> 6860.61 | P38: =ROUND((ROUND((AC38*I38),2)*BC38),2) -> 6860.61 | Q38: =(ROUND((ROUND(((ET38)*AV38*I38),2)*BB38),2)+ROUND((ROUND(((AE38-(EU38))*AV38*I38),2)*BS38),2)) -> 0 | R38: =(ROUND((ROUND(((EU38)*AV38*I38),2)*BS38),2)+ROUND((ROUND(((AE38-(EU38))*AV38*I38),2)*BS38),2)) -> 0 | S38: =ROUND((ROUND((AF38*AV38*I38),2)*BA38),2) -> 0 | T38: =ROUND(CU38*I38,2) -> 0 | U38: =CV38*I38 -> 0 | V38: =CW38*I38 -> 0 | W38: =ROUND(CX38*I38,2) -> 0 | X38: =(ROUND((((S38+ROUND((ROUND(((EU38)*AV38*I38),2)*BS38),2))*AT38)/100),2)+ROUND(((ROUND((ROUND(((AE38-(EU38))*AV38*I38),2)*BS38),2)*AT38)/100),2)) -> 0 | Y38: =(ROUND((((S38+ROUND((ROUND(((EU38)*AV38*I38),2)*BS38),2))*AU38)/100),2)+ROUND(((ROUND((ROUND(((AE38-(EU38))*AV38*I38),2)*BS38),2)*AU38)/100),2)) -> 0 | AA38: 60256405 | AB38: =ROUND((AC38+AD38+AF38),6) -> 6860.61 | AC38: =ROUND((ES38),6) -> 6860.61 | AD38: =ROUND((((ET38)-(EU38))+AE38),6) -> 0 | AE38: =ROUND((EU38),6) -> 0 | AF38: =ROUND((EV38),6) -> 0 | AG38: =ROUND((AP38),6) -> 0 | AH38: =(EW38) -> 0 | AI38: =(EX38) -> 0 | AJ38: =(AS38) -> 0 | AK38: 6860.61 | AL38: 6860.61 | AM38: 0 | AN38: 0 | AO38: 0 | AP38: 0 | AQ38: 0 | AR38: 0 | AS38: 0 | AT38: 0 | AU38: 0 | AV38: 1 | AW38: 1 | AZ38: 1 | BA38: 1 | BB38: 1 | BC38: 1 | BH38: 3 | BI38: 3 | BM38: 746 | BN38: 0 | BP38: 0 | BQ38: 130 | BR38: 0 | BS38: 1 | BT38: 1 | BU38: 1 | BV38: 1 | BW38: 1 | BX38: 1 | BZ38: 0 | CA38: 0 | CE38: 1566 | CF38: 0 | CG38: 0 | CM38: 0 | CO38: 0 | CP38: =(P38+Q38+S38) -> 6860.61 | CQ38: =ROUND((ROUND((AC38*1),2)*BC38),2) -> 6860.61 | CR38: =(ROUND((ROUND(((ET38)*AV38*1),2)*BB38),2)+ROUND((ROUND(((AE38-(EU38))*AV38*1),2)*BS38),2)) -> 0 | CS38: =(ROUND((ROUND(((EU38)*AV38*1),2)*BS38),2)+ROUND((ROUND(((AE38-(EU38))*AV38*1),2)*BS38),2)) -> 0 | CT38: =ROUND((ROUND((AF38*AV38*1),2)*BA38),2) -> 0 | CU38: =AG38 -> 0 | CV38: =(AH38*AV38) -> 0 | CW38: =AI38 -> 0 | CX38: =AJ38 -> 0 | CY38: =(ROUND((((S38+ROUND((ROUND(((EU38)*AV38*1),2)*BS38),2))*AT38)/100),2)+ROUND(((ROUND((ROUND(((AE38-(EU38))*AV38*1),2)*BS38),2)*AT38)/100),2)) -> 0 | CZ38: =(ROUND((((S38+ROUND((ROUND(((EU38)*AV38*1),2)*BS38),2))*AU38)/100),2)+ROUND(((ROUND((ROUND(((AE38-(EU38))*AV38*1),2)*BS38),2)*AU38)/100),2)) -> 0 | DN38: 0 | DO38: 0 | DP38: 1 | DQ38: 1 | DU38: 1010 | DV38: шт. | DW38: шт. | DX38: 1 | EE38: 60088638 | EF38: 130 | EG38: Сметная стоимость оборудования | EH38: 0 | EJ38: 3 | EK38: 746 | EL38: ТСН-2001.13. Сметная стоимость оборудования | EM38: ТСН-2001.13 | EQ38: 0 | ER38: 0 | ES38: 6860.61 | ET38: 0 | EU38: 0 | EV38: 0 | EW38: 0 | EX38: 0 | EY38: 0 | FQ38: 0 | FR38: =P38 -> 6860.61 | FS38: 0 | FX38: 0 | FY38: 0 | GA38: [60 500 / 1,2 / 7,66] + 3% Трансп + 1,2% Заг.скл | GD38: 1 | GF38: 831235936 | GG38: 2 | GH38: 4 | GI38: -2 | GJ38: 0 | GK38: 0 | GL38: =ROUND(IF(AND(BH38=3,BI38=3,FS38<>0),P38,0),2) -> 0 | GM38: =ROUND(O38+X38+Y38,2)+GX38 -> 6860.61 | GN38: =IF(OR(BI38=0,BI38=1),GM38-GX38,0) -> 0 | GO38: =IF(BI38=2,GM38-GX38,0) -> 0 | GP38: =IF(BI38=4,GM38-GX38,0) -> 0 | GR38: 0 | GS38: 2 | GT38: 0 | GV38: =ROUND((GT38),6) -> 0 | GW38: 1 | GX38: =ROUND(HC38*I38,2) -> 0 | HA38: 0 | HB38: 0 | HC38: =GV38*GW38 -> 0 | HE38: 3 | HF38: 1,2 | HS38: 0 | IK38: 0
