Workbook

Sheet 02-01-04
A1: =Source!B1 -> Smeta.RU (495) 974-1589
J2: Форма № 4б
A3: Капитальный ремонт здания Государственного бюджетного общеобразовательного учреждения города Москвы "Школа № 236" по адресу: г. Москва ул. Клязьминская, д. 7 к. 4. 1 этап. | AP3: Капитальный ремонт здания Государственного бюджетного общеобразовательного учреждения города Москвы "Школа № 236" по адресу: г. Москва ул. Клязьминская, д. 7 к. 4. 1 этап. 02-01-04 Система водоснабжения
A4: (наименование стройки и/или объекта)
A6: =CONCATENATE( "ЛОКАЛЬНАЯ СМЕТА № ",IF(Source!F20<>"Новая локальная смета", Source!F20, "")) -> ЛОКАЛЬНАЯ СМЕТА № 02-01-04
A8: =IF(Source!G20<>"Новая локальная смета", Source!G20, "") -> Система водоснабжения
A9: (наименование работ и затрат)
A11: =CONCATENATE( "Основание: чертежи № ", Source!J20) -> Основание: чертежи № 2024-00272-00-0-ИОС2
I13: В базисном уровне цен | J13: В текущем уровне цен
E14: Сметная стоимость | I14: =I15+I16+I17+I18 -> 587.47 | J14: =J15+J16+J17+J18 -> 7939.14 | K14: тыс.руб.
E15: Строительные работы | I15: =ROUND((Source!F974)/1000, 2) -> 521.12 | J15: =ROUND((Source!P974)/1000, 2) -> 7246.55 | K15: тыс.руб.
E16: Работы по монтажу оборудования | I16: =ROUND((Source!F975)/1000, 2) -> 39.95 | J16: =ROUND((Source!P975)/1000, 2) -> 490.36 | K16: тыс.руб.
E17: Оборудование | I17: =ROUND((Source!F966)/1000, 2) -> 26.4 | J17: =ROUND((Source!P966)/1000, 2) -> 202.23 | K17: тыс.руб.
E18: Прочие работы и затраты | I18: =ROUND((Source!F976+Source!F977)/1000, 2) -> 0 | J18: =ROUND((Source!P976+Source!P977)/1000, 2) -> 0 | K18: тыс.руб.
E19: Средства на оплату труда | I19: =(Source!F972+ Source!F971)/1000 -> 24.65016 | J19: =((Source!P972 + Source!P971)/1000) -> 1355.5124 | K19: тыс.руб.
E20: Затраты труда | I20: =Source!F979 -> 1905.881 | K20: чел.-ч.
E21: Кроме того:
E22: Возврат материалов | I22: =SUM(Y28:Y1213)/1000 -> 0 | J22: =SUM(Z28:Z1213)/1000 -> 0 | K22: тыс.руб.
A24: Составлен(а) по ТСН-2001 с учетом Дополнения №: 80
A25: № и период сборника коэффициентов (индексов) пересчета: Коэффициенты к ТСН-2001 МГЭ Дополнение 80, ремонт №217/80 III квартал 2025 года и Коэффициенты к ТСН-2001.13-2 Дополнение 46 №62/46 III квартал 2025 года | AP25: № и период сборника коэффициентов (индексов) пересчета: Коэффициенты к ТСН-2001 МГЭ Дополнение 80, ремонт №217/80 III квартал 2025 года и Коэффициенты к ТСН-2001.13-2 Дополнение 46 №62/46 III квартал 2025 года
A26: № п/п | B26: Шифр расценки и коды ресурсов | C26: Наименование работ и затрат | D26: Ед. изм. | E26: Кол-во единиц | F26: Цена на ед. изм., руб. | G26: Попра- вочные коэффи- циенты | H26: Коэффи- циенты зимних удорожа- ний | I26: Всего в ценах на январь 2000 года, руб. | J26: Коэффи- циенты (индек- сы) пере- счета, нормы НР и СП | K26: ВСЕГО затрат в текущем уровне цен, руб.
A27: 1 | B27: 2 | C27: 3 | D27: 4 | E27: 5 | F27: 6 | G27: 7 | H27: 8 | I27: 9 | J27: 10 | K27: 11
A29: =CONCATENATE("Раздел: ",IF(Source!G24<>"Новый раздел", Source!G24, "")) -> Раздел: Водопровод хозяйственно-питьевой В1 (Подземная часть)
A30: 1 | B30: 3.16-38-1 Поправка: О.П. п.3.4. 6 Поправка: О.П. п.3.4.30.в | C30: Прокладка трубопроводов из стальных труб на бессварных разъемных муфтовых соединениях диаметром до 25 мм | D30: =Source!H28 -> 100 м | E30: =Source!I28 -> 0.18 | Q30: =Source!X28 -> 62.81 | R30: =Source!X29 -> 3453.69 | S30: =Source!Y28 -> 35.15 | T30: =Source!Y29 -> 1932.8 | U30: =ROUND((175/100)*ROUND(Source!R28, 2), 2) -> 0.14 | V30: =ROUND((0/100)*ROUND(Source!R29, 2), 2) -> 0 | AC30: 0
C31: ="Объем: "&Source!I28&"=18/"&"100" -> Объем: 0,18=18/100
C32: ЗП | F32: =Source!AO28 -> 236.83 | G32: =Source!DG28 -> *1,15)*1,1 | H32: =Source!AV29 -> 1.067 | I32: =Source!S28 -> 57.54 | J32: =IF(Source!BA29<> 0, Source!BA29, 1) -> 54.99 | K32: =Source!S29 -> 3164.12
C33: ЭМ | F33: =Source!AM28 -> 4.07 | G33: =Source!DE28 -> *1,25)*1,1 | H33: =Source!AV29 -> 1.067 | I33: =Source!Q28 -> 1.07 | J33: =IF(Source!BB29<> 0, Source!BB29, 1) -> 12.44 | K33: =Source!Q29 -> 13.31
C34: в т.ч. ЗПМ | F34: =Source!AN28 -> 0.3 | G34: =Source!DF28 -> *1,25)*1,1 | H34: =Source!AV29 -> 1.067 | I34: =Source!R28 -> 0.08 | J34: =IF(Source!BS29<> 0, Source!BS29, 1) -> 54.99 | K34: =Source!R29 -> 4.4
C35: МР | F35: =Source!AL28 -> 30.04 | G35: =Source!DD28 | H35: =Source!AW29 -> 1 | I35: =Source!P28 -> 5.41 | J35: =IF(Source!BC29<> 0, Source!BC29, 1) -> 1.79 | K35: =Source!P29 -> 9.68
A36: 1,1 | B36: =Source!F30 -> 1.12-1-52 | C36: Узел трубопровода из стальных водогазопроводных оцинкованных труб, с гильзами, для водоснабжения, диаметр условного прохода 15 мм | D36: =Source!H30 -> м | E36: =Source!I30 -> 18 | F36: =Source!AK30 -> 28.1 | H36: =Source!AW31 -> 1 | I36: =Source!O30 -> 505.8 | J36: =IF(Source!BC31<> 0, Source!BC31, 1) -> 18.63 | K36: =Source!O31 -> 9423.05 | Q36: =Source!X30 -> 0 | R36: =Source!X31 -> 0 | S36: =Source!Y30 -> 0 | T36: =Source!Y31 -> 0 | U36: =ROUND((175/100)*ROUND(Source!R30, 2), 2) -> 0 | V36: =ROUND((0/100)*ROUND(Source!R31, 2), 2) -> 0 | AC36: 3
A37: 1,2 | B37: =Source!F32 -> 1.13-4-61 | C37: Кран шаровой, латунный, никелированный, полнопроходной, с алюминиевой рукояткой, муфтовый, температура рабочей среды от -15 до +110°С, номинальное давление PN 4,0 МПа, номинальный диаметр DN 15 мм | D37: =Source!H32 -> шт. | E37: =Source!I32 -> 6 | F37: =Source!AK32 -> 34.97 | H37: =Source!AW33 -> 1 | I37: =Source!O32 -> 209.82 | J37: =IF(Source!BC33<> 0, Source!BC33, 1) -> 18.72 | K37: =Source!O33 -> 3927.83 | Q37: =Source!X32 -> 0 | R37: =Source!X33 -> 0 | S37: =Source!Y32 -> 0 | T37: =Source!Y33 -> 0 | U37: =ROUND((175/100)*ROUND(Source!R32, 2), 2) -> 0 | V37: =ROUND((0/100)*ROUND(Source!R33, 2), 2) -> 0 | AC37: 3
A38: 1,3 | B38: =Source!F34 -> 1.13-4-137 | C38: Кран шаровой, латунный, никелированный, спускной, с наружной резьбой, с насадкой для шланга, с алюминиевой рукояткой, температура рабочей среды от -15 до +90°С, пропускная способность 1,9 м3/ч, номинальное давление PN 1,0 МПа, номинальный диаметр DN 15 мм | D38: =Source!H34 -> шт. | E38: =Source!I34 -> 44 | F38: =Source!AK34 -> 24.61 | H38: =Source!AW35 -> 1 | I38: =Source!O34 -> 1082.84 | J38: =IF(Source!BC35<> 0, Source!BC35, 1) -> 35.58 | K38: =Source!O35 -> 38527.45 | Q38: =Source!X34 -> 0 | R38: =Source!X35 -> 0 | S38: =Source!Y34 -> 0 | T38: =Source!Y35 -> 0 | U38: =ROUND((175/100)*ROUND(Source!R34, 2), 2) -> 0 | V38: =ROUND((0/100)*ROUND(Source!R35, 2), 2) -> 0 | AC38: 3
A39: 1,4 | B39: =Source!F36 -> 1.12-10-146 | C39: Хомут стальной, оцинкованный, двухболтовой, с поворотным механизмом, каучуковой прокладкой, для крепления труб диаметром от 16 до 20 мм, резьба М8/М10 | D39: =Source!H36 -> 100 шт. | E39: =Source!I36 -> 0.12 | F39: =Source!AK36 -> 526.22 | H39: =Source!AW37 -> 1 | I39: =Source!O36 -> 63.15 | J39: =IF(Source!BC37<> 0, Source!BC37, 1) -> 2.79 | K39: =Source!O37 -> 176.19 | Q39: =Source!X36 -> 0 | R39: =Source!X37 -> 0 | S39: =Source!Y36 -> 0 | T39: =Source!Y37 -> 0 | U39: =ROUND((175/100)*ROUND(Source!R36, 2), 2) -> 0 | V39: =ROUND((0/100)*ROUND(Source!R37, 2), 2) -> 0 | AC39: 3
C40: НР от ФОТ | D40: % | E40: =Source!BZ29 -> 109 | I40: =SUM(Q30:Q39) -> 62.81 | J40: =Source!AT29 -> 109 | K40: =SUM(R30:R39) -> 3453.69
C41: СП от ФОТ | D41: % | E41: =Source!CA29 -> 61 | I41: =SUM(S30:S40) -> 35.15 | J41: =Source!AU29 -> 61 | K41: =SUM(T30:T40) -> 1932.8
C42: ЗТР | D42: чел-ч | E42: =Source!AQ28 -> 19.12 | G42: =Source!DI28 -> *1,15)*1,1 | H42: =Source!AV29 -> 1.067 | I42: =Source!U28 -> 4.6453168
C43: Всего по позиции: | H43: =I32+I33+I35+I40+I41+SUM(I36:I39) -> 2023.59 | J43: =K32+K33+K35+K40+K41+SUM(K36:K39) -> 60628.12 | O43: =I32+I33+I35+I40+I41+SUM(I36:I39) -> 2023.59 | P43: =K32+K33+K35+K40+K41+SUM(K36:K39) -> 60628.12
A45: 2 | B45: 3.16-38-1 Поправка: О.П. п.3.4. 6 Поправка: О.П. п.3.4.30.в | C45: Прокладка трубопроводов из стальных труб на бессварных разъемных муфтовых соединениях диаметром до 25 мм | D45: =Source!H48 -> 100 м | E45: =Source!I48 -> 1.1 | Q45: =Source!X48 -> 383.8 | R45: =Source!X49 -> 21105.16 | S45: =Source!Y48 -> 214.79 | T45: =Source!Y49 -> 11811.14 | U45: =ROUND((175/100)*ROUND(Source!R48, 2), 2) -> 0.84 | V45: =ROUND((0/100)*ROUND(Source!R49, 2), 2) -> 0 | AC45: 0
C46: ="Объем: "&Source!I48&"=110/"&"100" -> Объем: 1,1=110/100
C47: ЗП | F47: =Source!AO48 -> 236.83 | G47: =Source!DG48 -> *1,15)*1,1 | H47: =Source!AV49 -> 1.067 | I47: =Source!S48 -> 351.63 | J47: =IF(Source!BA49<> 0, Source!BA49, 1) -> 54.99 | K47: =Source!S49 -> 19336.13
...

Sheet Ведомость объемов работ
A1: =Source!B1 -> Smeta.RU (495) 974-1589
E3: "УТВЕРЖДАЮ"
D5: ___________________________
D7: ___________________________
D9: " ___ " ___________ 20 ___ г.
B12: =CONCATENATE("Ведомость объемов работ ", IF(Source!AN15<>"", Source!AN15," ")) -> Ведомость объемов работ
B13: =CONCATENATE(Source!F12, " ", Source!G12) -> Новый объект (ТСН-2001 (Мосгосэкспертиза)) 02-01-04 Система водоснабжения
A16: № п/п | B16: № в ЛСР | C16: Наименование работ и затрат | D16: Единица измерения | E16: Количество | F16: Ссылка на чертежи, спецификации | G16: Формула расчета, расчет объемов работ и расхода материалов | H16: Примечание
A17: 1 | B17: 2 | C17: 3 | D17: 4 | E17: 5 | F17: 6 | G17: 7 | H17: 8
A18: =CONCATENATE("Локальная смета: ", Source!G20) -> Локальная смета: Система водоснабжения
A19: =CONCATENATE("Раздел: ", Source!G24) -> Раздел: Водопровод хозяйственно-питьевой В1 (Подземная часть)
A20: 1 | B20: =Source!E28 -> 1 | C20: =Source!G28 -> Прокладка трубопроводов из стальных труб на бессварных разъемных муфтовых соединениях диаметром до 25 мм | D20: 100 м | E20: =Source!I28 -> 0.18 | F20: =Source!U24 | G20: ="=18/"&"100" -> =18/100
A21: 1.1 | B21: =Source!E30 -> 1,1 | C21: =Source!G30 -> Узел трубопровода из стальных водогазопроводных оцинкованных труб, с гильзами, для водоснабжения, диаметр условного прохода 15 мм | D21: м | E21: =Source!I30 -> 18 | F21: =Source!U24
A22: 1.2 | B22: =Source!E32 -> 1,2 | C22: =Source!G32 -> Кран шаровой, латунный, никелированный, полнопроходной, с алюминиевой рукояткой, муфтовый, температура рабочей среды от -15 до +110°С, номинальное давление PN 4,0 МПа, номинальный диаметр DN 15 мм | D22: шт. | E22: =Source!I32 -> 6 | F22: =Source!U24
A23: 1.3 | B23: =Source!E34 -> 1,3 | C23: =Source!G34 -> Кран шаровой, латунный, никелированный, спускной, с наружной резьбой, с насадкой для шланга, с алюминиевой рукояткой, температура рабочей среды от -15 до +90°С, пропускная способность 1,9 м3/ч, номинальное давление PN 1,0 МПа, номинальный диаметр DN 15 мм | D23: шт. | E23: =Source!I34 -> 44 | F23: =Source!U24
A24: 1.4 | B24: =Source!E36 -> 1,4 | C24: =Source!G36 -> Хомут стальной, оцинкованный, двухболтовой, с поворотным механизмом, каучуковой прокладкой, для крепления труб диаметром от 16 до 20 мм, резьба М8/М10 | D24: 100 шт. | E24: =Source!I36 -> 0.12 | F24: =Source!U24
A25: 2 | B25: =Source!E48 -> 2 | C25: =Source!G48 -> Прокладка трубопроводов из стальных труб на бессварных разъемных муфтовых соединениях диаметром до 25 мм | D25: 100 м | E25: =Source!I48 -> 1.1 | F25: =Source!U24 | G25: ="=110/"&"100" -> =110/100
A26: 2.1 | B26: =Source!E50 -> 2,1 | C26: =Source!G50 -> Узел трубопровода из стальных водогазопроводных оцинкованных труб, с гильзами, для водоснабжения, диаметр условного прохода 20 мм | D26: м | E26: =Source!I50 -> 110 | F26: =Source!U24
A27: 2.2 | B27: =Source!E52 -> 2,2 | C27: =Source!G52 -> Кран шаровой, латунный, никелированный, полнопроходной, с алюминиевой рукояткой, муфтовый, температура рабочей среды от -15 до +110°С, номинальное давление PN 4,0 МПа, номинальный диаметр DN 20 мм | D27: шт. | E27: =Source!I52 -> 24 | F27: =Source!U24
A28: 2.3 | B28: =Source!E54 -> 2,3 | C28: =Source!G54 -> Хомут стальной, оцинкованный, двухболтовой, с поворотным механизмом, каучуковой прокладкой, для крепления труб диаметром от 16 до 20 мм, резьба М8/М10 | D28: 100 шт. | E28: =Source!I54 -> 0.55 | F28: =Source!U24
A29: 3 | B29: =Source!E64 -> 3 | C29: =Source!G64 -> Прокладка трубопроводов из стальных труб на бессварных разъемных муфтовых соединениях диаметром до 25 мм | D29: 100 м | E29: =Source!I64 -> 1.75 | F29: =Source!U24 | G29: ="=175/"&"100" -> =175/100
A30: 3.1 | B30: =Source!E66 -> 3,1 | C30: =Source!G66 -> Узел трубопровода из стальных водогазопроводных оцинкованных труб, с гильзами, для водоснабжения, диаметр условного прохода 25 мм | D30: м | E30: =Source!I66 -> 175 | F30: =Source!U24
A31: 3.2 | B31: =Source!E68 -> 3,2 | C31: =Source!G68 -> Хомут стальной, оцинкованный, двухболтовой, с поворотным механизмом, каучуковой прокладкой, для крепления труб диаметром от 16 до 20 мм, резьба М8/М10 | D31: 100 шт. | E31: =Source!I68 -> 0.87 | F31: =Source!U24
A32: 3.3 | B32: =Source!E70 -> 3,3 | C32: =Source!G70 -> Кран шаровой, латунный, никелированный, полнопроходной, с алюминиевой рукояткой, муфтовый, температура рабочей среды от -15 до +110°С, номинальное давление PN 4,0 МПа, номинальный диаметр DN 25 мм | D32: шт. | E32: =Source!I70 -> 14 | F32: =Source!U24
A33: 4 | B33: =Source!E80 -> 4 | C33: =Source!G80 -> Прокладка трубопроводов из стальных труб на бессварных разъемных муфтовых соединениях диаметром 32 мм | D33: 100 м | E33: =Source!I80 -> 0.4 | F33: =Source!U24 | G33: ="=40/"&"100" -> =40/100
A34: 4.1 | B34: =Source!E82 -> 4,1 | C34: =Source!G82 -> Узел трубопровода из стальных водогазопроводных оцинкованных труб, с гильзами, для водоснабжения, диаметр условного прохода 32 мм | D34: м | E34: =Source!I82 -> 40 | F34: =Source!U24
A35: 4.2 | B35: =Source!E84 -> 4,2 | C35: =Source!G84 -> Кран шаровой, латунный, никелированный, полнопроходной, с алюминиевой рукояткой, муфтовый, температура рабочей среды от -15 до +110°С, номинальное давление PN 4,0 МПа, номинальный диаметр DN 32 мм | D35: шт. | E35: =Source!I84 -> 2 | F35: =Source!U24
A36: 4.3 | B36: =Source!E86 -> 4,3 | C36: =Source!G86 -> Хомут стальной, оцинкованный, двухболтовой, с поворотным механизмом, каучуковой прокладкой, для крепления труб диаметром от 16 до 20 мм, резьба М8/М10 | D36: 100 шт. | E36: =Source!I86 -> 0.16 | F36: =Source!U24
A37: 5 | B37: =Source!E96 -> 5 | C37: =Source!G96 -> Прокладка трубопроводов из стальных труб на бессварных разъемных муфтовых соединениях диаметром 40 мм | D37: 100 м | E37: =Source!I96 -> 0.37 | F37: =Source!U24 | G37: ="=37/"&"100" -> =37/100
A38: 5.1 | B38: =Source!E98 -> 5,1 | C38: =Source!G98 -> Узел трубопровода из стальных водогазопроводных оцинкованных труб, с гильзами, для водоснабжения, диаметр условного прохода 40 мм | D38: м | E38: =Source!I98 -> 37 | F38: =Source!U24
A39: 5.2 | B39: =Source!E100 -> 5,2 | C39: =Source!G100 -> Хомут стальной, оцинкованный, двухболтовой, с поворотным механизмом, каучуковой прокладкой, для крепления труб диаметром от 16 до 20 мм, резьба М8/М10 | D39: 100 шт. | E39: =Source!I100 -> 0.12 | F39: =Source!U24
A40: 6 | B40: =Source!E108 -> 6 | C40: =Source!G108 -> Прокладка трубопроводов из стальных труб на бессварных разъемных муфтовых соединениях диаметром 50 мм | D40: 100 м | E40: =Source!I108 -> 0.35 | F40: =Source!U24 | G40: ="=35/"&"100" -> =35/100
A41: 6.1 | B41: =Source!E110 -> 6,1 | C41: =Source!G110 -> Трубы стальные сварные водогазопроводные, оцинкованные, обыкновенные, ГОСТ 3262-75, диаметр условного прохода 50 мм, толщина стенки 3,5 мм | D41: м | E41: =Source!I110 -> 35 | F41: =Source!U24
A42: 6.2 | B42: =Source!E112 -> 6,2 | C42: =Source!G112 -> Хомут стальной, оцинкованный, двухболтовой, с поворотным механизмом, каучуковой прокладкой, для крепления труб диаметром от 16 до 20 мм, резьба М8/М10 | D42: 100 шт. | E42: =Source!I112 -> 0.11 | F42: =Source!U24
A43: 7 | B43: =Source!E120 -> 7 | C43: =Source!G120 -> Прокладка трубопроводов из стальных труб на бессварных разъемных муфтовых соединениях диаметром 65 мм | D43: 100 м | E43: =Source!I120 -> 0.5 | F43: =Source!U24 | G43: ="=50/"&"100" -> =50/100
A44: 7.1 | B44: =Source!E122 -> 7,1 | C44: =Source!G122 -> Трубы стальные сварные водогазопроводные, оцинкованные, обыкновенные, ГОСТ 3262-75, диаметр условного прохода 65 мм, толщина стенки 4 мм | D44: м | E44: =Source!I122 -> 50 | F44: =Source!U24
A45: 7.2 | B45: =Source!E124 -> 7,2 | C45: =Source!G124 -> Хомут металлический для труб, диаметр от 104 до 112 мм | D45: шт. | E45: =Source!I124 -> 25 | F45: =Source!U24
A46: 8 | B46: =Source!E132 -> 8 | C46: =Source!G132 -> Прокладка трубопроводов из стальных труб на бессварных разъемных муфтовых соединениях диаметром 80 мм | D46: 100 м | E46: =Source!I132 -> 0.4 | F46: =Source!U24 | G46: ="=40/"&"100" -> =40/100
A47: 8.1 | B47: =Source!E134 -> 8,1 | C47: =Source!G134 -> Трубы стальные сварные водогазопроводные, оцинкованные, обыкновенные, ГОСТ 3262-75, диаметр условного прохода 80 мм, толщина стенки 4 мм | D47: м | E47: =Source!I134 -> 40 | F47: =Source!U24
A48: 8.2 | B48: =Source!E136 -> 8,2 | C48: =Source!G136 -> Хомут металлический для труб, диаметр от 104 до 112 мм | D48: шт. | E48: =Source!I136 -> 25 | F48: =Source!U24
...

Sheet Source
A1: 0 | B1: Smeta.RU (495) 974-1589 | D1: _PS_ | F1: 0 | G1: 0 | H1: 0 | I1: Smeta.RU | K1: 1 | L1: 74402 | M1: 10 | N1: 12 | O1: 0 | P1: 0 | Q1: 3
A4: 1 | B4: 1 | C4: -1 | G4: Капитальный ремонт здания Государственного бюджетного общеобразовательного учреждения города Москвы "Школа № 236" по адресу: г. Москва ул. Клязьминская, д. 7 к. 4. 1 этап | EC4: 0
A12: 1 | B12: 1028 | C12: 0 | D12: =ROW(A987) -> 987 | E12: 0 | F12: Новый объект (ТСН-2001 (Мосгосэкспертиза)) | G12: 02-01-04 Система водоснабжения | I12: 0 | K12: 0 | L12: 0 | M12: 4098 | O12: 0 | P12: 0 | Q12: 0 | R12: 0 | S12: 0 | T12: 1 | V12: 0 | AB12: Кузнецова Е.А. | BB12: 0 | BH12: Сметные нормы списания | BI12: Коды ОКП для ТСН-2001 МГЭ Дополнение 80 | BJ12: 1 | BK12: 1 | BL12: 0 | BM12: 0 | BN12: 1 | BO12: 0 | BP12: 6 | BQ12: 2 | BR12: 1 | BS12: 1 | BT12: 0 | BU12: 0 | BV12: 1 | BW12: 0 | BX12: 0 | BZ12: Типовой расчет для ТСН-2001 МГЭ, Дополнение 80, ремонт | CA12: Территориальные сметные нормативы для Москвы ТСН-2001 (МГЭ), дополнение 80 | CB12: Территориальные сметные нормативы для Москвы ТСН-2001 (МГЭ), дополнение 80 | CC12: Территориальные сметные нормативы для Москвы ТСН-2001 (МГЭ), дополнение 80 | CD12: Территориальные сметные нормативы для Москвы ТСН-2001 (МГЭ), дополнение 80 | CE12: Поправки для ТСН-2001 от 03.02.2026 г. доп.80 | CF12: 0 | CG12: 0 | CH12: 327688 | CK12: 81 | CQ12: Территориальные сметные нормативы для Москвы (ТСН-2001) | CR12: ТЕР | CS12: 41660 | CT12: 1 | CU12: 80 | CY12: 0 | EC12: 0
A15: 15 | B15: 1
A18: 52 | B18: =B987 -> 1028 | C18: =C987 -> 1 | D18: =D987 -> 12 | E18: =E987 -> 0 | F18: =F987 -> Новый объект (ТСН-2001 (Мосгосэкспертиза)) | G18: =G987 -> 02-01-04 Система водоснабжения | O18: =O987 -> 548525.22 | P18: =P987 -> 522059.51 | Q18: =Q987 -> 1991.9 | R18: =R987 -> 176.35 | S18: =S987 -> 24473.81 | T18: =T987 -> 0 | U18: =U987 -> 1905.881 | V18: =V987 -> 0 | ... GX18: =GX987 -> 0
A20: 3 | B20: 1 | D20: =ROW(A957) -> 957 | F20: 02-01-04 | G20: Система водоснабжения | I20: 0 | J20: 2024-00272-00-0-ИОС2 | K20: -1 | L20: 02-01-04 | S20: 0 | T20: 0 | V20: 0 | BX20: 0 | CF20: 0 | CG20: 0
A22: 52 | B22: =B957 -> 1 | C22: =C957 -> 3 | D22: =D957 -> 20 | E22: =E957 -> 0 | F22: =F957 -> 02-01-04 | G22: =G957 -> Система водоснабжения | O22: =O957 -> 548525.22 | P22: =P957 -> 522059.51 | Q22: =Q957 -> 1991.9 | R22: =R957 -> 176.35 | S22: =S957 -> 24473.81 | T22: =T957 -> 0 | U22: =U957 -> 1905.881 | V22: =V957 -> 0 | ... GX22: =GX957 -> 0
A24: 4 | B24: 1 | D24: =ROW(A242) -> 242 | F24: Новый раздел | G24: Водопровод хозяйственно-питьевой В1 (Подземная часть) | I24: 0 | K24: 0 | S24: 0 | T24: 0 | V24: 0 | BX24: 0 | CJ24: 0
A26: 52 | B26: =B242 -> 1 | C26: =C242 -> 4 | D26: =D242 -> 24 | E26: =E242 -> 0 | F26: =F242 -> Новый раздел | G26: =G242 -> Водопровод хозяйственно-питьевой В1 (Подземная часть) | O26: =O242 -> 59830.96 | P26: =P242 -> 55248.57 | Q26: =Q242 -> 147.9 | R26: =R242 -> 15.15 | S26: =S242 -> 4434.49 | T26: =T242 -> 0 | U26: =U242 -> 343.43591 | V26: =V242 -> 0 | ... GX26: =GX242 -> 0
A28: 17 | B28: 1 | C28: =ROW(SmtRes!A12) -> 12 | D28: =ROW(EtalonRes!A11) -> 11 | E28: 1 | F28: 3.16-38-1 | G28: Прокладка трубопроводов из стальных труб на бессварных разъемных муфтовых соединениях диаметром до 25 мм | H28: 100 м | I28: =ROUND(ROUND(18/100,4),9) -> 0.18 | J28: 0 | K28: =ROUND(ROUND(18/100,4),9) -> 0.18 | O28: =ROUND(CP28,2) -> 64.02 | P28: =ROUND((ROUND((AC28*AW28*I28),2)*BC28),2) -> 5.41 | Q28: =(ROUND((ROUND(((((ET28*1.25)*1.1))*AV28*I28),2)*BB28),2)+ROUND((ROUND(((AE28-(((EU28*1.25)*1.1)))*AV28*I28),2)*BS28),2)) -> 1.07 | R28: =ROUND((ROUND((AE28*AV28*I28),2)*BS28),2) -> 0.08 | S28: =ROUND((ROUND((AF28*AV28*I28),2)*BA28),2) -> 57.54 | T28: =ROUND(CU28*I28,2) -> 0 | U28: =CV28*I28 -> 4.6453168 | V28: =CW28*I28 -> 0 | W28: =ROUND(CX28*I28,2) -> 0 | X28: =ROUND(CY28,2) -> 62.81 | Y28: =ROUND(CZ28,2) -> 35.15 | AA28: 59204062 | AB28: =ROUND((AC28+AD28+AF28),6) -> 335.2262 | AC28: =ROUND((ES28),6) -> 30.04 | AD28: =ROUND((((((ET28*1.25)*1.1))-(((EU28*1.25)*1.1)))+AE28),6) -> 5.59625 | AE28: =ROUND((((EU28*1.25)*1.1)),6) -> 0.4125 | AF28: =ROUND((((EV28*1.15)*1.1)),6) -> 299.58995 | AG28: =ROUND((AP28),6) -> 0 | AH28: =(((EW28*1.15)*1.1)) -> 24.1868 | AI28: =(((EX28*1.25)*1.1)) -> 0 | AJ28: =(AS28) -> 0 | AK28: 270.94 | AL28: 30.04 | AM28: 4.07 | AN28: 0.3 | AO28: 236.83 | AP28: 0 | AQ28: 19.12 | AR28: 0 | AS28: 0 | AT28: 109 | AU28: 61 | AV28: 1.067 | AW28: 1 | AZ28: 1 | BA28: 1 | BB28: 1 | BC28: 1 | BH28: 0 | BI28: 1 | BJ28: ТСН-2001.3 Доп. 80, Сб. 16, т. 38, поз. 1 | BM28: 21 | BN28: 0 | BO28: 3.16-38-1 | BP28: 1 | BQ28: 30 | BR28: 0 | BS28: 1 | BT28: 1 | BU28: 1 | BV28: 1 | BW28: 1 | BX28: 1 | BZ28: 109 | CA28: 61 | CE28: 30 | CF28: 0 | CG28: 0 | CM28: 0 | CN28: Поправка: О.П. п.3.4. 6 Наименование: Выполняемые при ремонте и реконструкции работы аналогичные технологическим процессам, характерным для нового строительства и отсутствующим в сборниках на ремонтно-строительные работы Поправка: О.П. п.3.4.30.в Наименование: При применении территориальных сметных нормативов для города Москвы затраты, учитывающие напряженные и стесненные условия производства работ (стесненность, сложность складирования и транспортной логистики и т.п.), исчисляются с применением коэффициентов к затратам труда и заработной плате рабочих, машинистов, времени эксплуатации машин и механизмов, стоимости эксплуатации машин в размере: для объектов, расположенных за пределами Третьего транспортного кольца города Москвы, но в пределах Московской кольцевой автомобильной дороги | CO28: 0 | CP28: =(P28+Q28+S28) -> 64.02 | CQ28: =ROUND((ROUND((AC28*AW28*1),2)*BC28),2) -> 30.04 | CR28: =(ROUND((ROUND(((((ET28*1.25)*1.1))*AV28*1),2)*BB28),2)+ROUND((ROUND(((AE28-(((EU28*1.25)*1.1)))*AV28*1),2)*BS28),2)) -> 5.97 | CS28: =ROUND((ROUND((AE28*AV28*1),2)*BS28),2) -> 0.44 | CT28: =ROUND((ROUND((AF28*AV28*1),2)*BA28),2) -> 319.66 | CU28: =AG28 -> 0 | CV28: =(AH28*AV28) -> 25.807316 | CW28: =AI28 -> 0 | CX28: =AJ28 -> 0 | CY28: =(((S28+R28)*AT28)/100) -> 62.8058 | CZ28: =(((S28+R28)*AU28)/100) -> 35.1482 | DB28: 1 | DE28: *1,25)*1,1 | DF28: *1,25)*1,1 | DG28: *1,15)*1,1 | DI28: *1,15)*1,1 | DJ28: *1,25)*1,1 | DN28: 0 | DO28: 0 | DP28: 1 | DQ28: 1 | DU28: 1003 | DV28: 100 м | DW28: 100 м | DX28: 100 | EE28: 58807897 | EF28: 30 | EG28: Строительные работы | EH28: 0 | EJ28: 1 | EK28: 21 | EL28: ТСН-2001.3-16. Трубопроводы внутренние | EM28: ТСН-2001.3-16-1 | EO28: Поправка: О.П. п.3.4. 6 Поправка: О.П. п.3.4.30.в | EQ28: 0 | ER28: 270.94 | ES28: 30.04 | ET28: 4.07 | EU28: 0.3 | EV28: 236.83 | EW28: 19.12 | EX28: 0 | EY28: 0 | FQ28: 0 | FR28: 0 | FS28: 0 | FX28: 109 | FY28: 61 | GD28: 1 | GF28: -367569951 | GG28: 2 | GH28: 1 | GI28: 2 | GJ28: 0 | GK28: 0 | GL28: =ROUND(IF(AND(BH28=3,BI28=3,FS28<>0),P28,0),2) -> 0 | GM28: =ROUND(O28+X28+Y28,2)+GX28 -> 161.98 | GN28: =IF(OR(BI28=0,BI28=1),GM28-GX28,0) -> 161.98 | GO28: =IF(BI28=2,GM28-GX28,0) -> 0 | GP28: =IF(BI28=4,GM28-GX28,0) -> 0 | GR28: 0 | GS28: 3 | GT28: 0 | GV28: =ROUND((GT28),6) -> 0 | GW28: 1 | GX28: =ROUND(HC28*I28,2) -> 0 | HA28: 0 | HB28: 0 | HC28: =GV28*GW28 -> 0 | HS28: 0 | IK28: 0
A29: 17 | B29: 1 | C29: =ROW(SmtRes!A24) -> 24 | D29: =ROW(EtalonRes!A22) -> 22 | E29: 1 | F29: 3.16-38-1 | G29: Прокладка трубопроводов из стальных труб на бессварных разъемных муфтовых соединениях диаметром до 25 мм | H29: 100 м | I29: =ROUND(ROUND(18/100,4),9) -> 0.18 | J29: 0 | K29: =ROUND(ROUND(18/100,4),9) -> 0.18 | O29: =ROUND(CP29,2) -> 3187.11 | P29: =ROUND((ROUND((AC29*AW29*I29),2)*BC29),2) -> 9.68 | Q29: =(ROUND((ROUND(((((ET29*1.25)*1.1))*AV29*I29),2)*BB29),2)+ROUND((ROUND(((AE29-(((EU29*1.25)*1.1)))*AV29*I29),2)*BS29),2)) -> 13.31 | R29: =ROUND((ROUND((AE29*AV29*I29),2)*BS29),2) -> 4.4 | S29: =ROUND((ROUND((AF29*AV29*I29),2)*BA29),2) -> 3164.12 | T29: =ROUND(CU29*I29,2) -> 0 | U29: =CV29*I29 -> 4.6453168 | V29: =CW29*I29 -> 0 | W29: =ROUND(CX29*I29,2) -> 0 | X29: =ROUND(CY29,2) -> 3453.69 | Y29: =ROUND(CZ29,2) -> 1932.8 | AA29: 59204059 | AB29: =ROUND((AC29+AD29+AF29),6) -> 335.2262 | AC29: =ROUND((ES29),6) -> 30.04 | AD29: =ROUND((((((ET29*1.25)*1.1))-(((EU29*1.25)*1.1)))+AE29),6) -> 5.59625 | AE29: =ROUND((((EU29*1.25)*1.1)),6) -> 0.4125 | AF29: =ROUND((((EV29*1.15)*1.1)),6) -> 299.58995 | AG29: =ROUND((AP29),6) -> 0 | AH29: =(((EW29*1.15)*1.1)) -> 24.1868 | AI29: =(((EX29*1.25)*1.1)) -> 0 | AJ29: =(AS29) -> 0 | AK29: 270.94 | AL29: 30.04 | AM29: 4.07 | AN29: 0.3 | AO29: 236.83 | AP29: 0 | AQ29: 19.12 | AR29: 0 | AS29: 0 | AT29: 109 | AU29: 61 | AV29: 1.067 | AW29: 1 | AZ29: 1 | BA29: 54.99 | BB29: 12.44 | BC29: 1.79 | BH29: 0 | BI29: 1 | BJ29: ТСН-2001.3 Доп. 80, Сб. 16, т. 38, поз. 1 | BM29: 21 | BN29: 0 | BO29: 3.16-38-1 | BP29: 1 | BQ29: 30 | BR29: 0 | BS29: 54.99 | BT29: 1 | BU29: 1 | BV29: 1 | BW29: 1 | BX29: 1 | BZ29: 109 | CA29: 61 | CE29: 30 | CF29: 0 | CG29: 0 | CM29: 0 | CN29: Поправка: О.П. п.3.4. 6 Наименование: Выполняемые при ремонте и реконструкции работы аналогичные технологическим процессам, характерным для нового строительства и отсутствующим в сборниках на ремонтно-строительные работы Поправка: О.П. п.3.4.30.в Наименование: При применении территориальных сметных нормативов для города Москвы затраты, учитывающие напряженные и стесненные условия производства работ (стесненность, сложность складирования и транспортной логистики и т.п.), исчисляются с применением коэффициентов к затратам труда и заработной плате рабочих, машинистов, времени эксплуатации машин и механизмов, стоимости эксплуатации машин в размере: для объектов, расположенных за пределами Третьего транспортного кольца города Москвы, но в пределах Московской кольцевой автомобильной дороги | CO29: 0 | CP29: =(P29+Q29+S29) -> 3187.11 | CQ29: =ROUND((ROUND((AC29*AW29*1),2)*BC29),2) -> 53.77 | CR29: =(ROUND((ROUND(((((ET29*1.25)*1.1))*AV29*1),2)*BB29),2)+ROUND((ROUND(((AE29-(((EU29*1.25)*1.1)))*AV29*1),2)*BS29),2)) -> 74.27 | CS29: =ROUND((ROUND((AE29*AV29*1),2)*BS29),2) -> 24.2 | CT29: =ROUND((ROUND((AF29*AV29*1),2)*BA29),2) -> 17578.1 | CU29: =AG29 -> 0 | CV29: =(AH29*AV29) -> 25.807316 | CW29: =AI29 -> 0 | CX29: =AJ29 -> 0 | CY29: =(((S29+R29)*AT29)/100) -> 3453.6868 | CZ29: =(((S29+R29)*AU29)/100) -> 1932.7972 | DB29: 3 | DE29: *1,25)*1,1 | DF29: *1,25)*1,1 | DG29: *1,15)*1,1 | DI29: *1,15)*1,1 | DJ29: *1,25)*1,1 | DN29: 0 | DO29: 0 | DP29: 1 | DQ29: 1 | DU29: 1003 | DV29: 100 м | DW29: 100 м | DX29: 100 | EE29: 58807897 | EF29: 30 | EG29: Строительные работы | EH29: 0 | EJ29: 1 | EK29: 21 | EL29: ТСН-2001.3-16. Трубопроводы внутренние | EM29: ТСН-2001.3-16-1 | EO29: Поправка: О.П. п.3.4. 6 Поправка: О.П. п.3.4.30.в | EQ29: 0 | ER29: 270.94 | ES29: 30.04 | ET29: 4.07 | EU29: 0.3 | EV29: 236.83 | EW29: 19.12 | EX29: 0 | EY29: 0 | FQ29: 0 | FR29: 0 | FS29: 0 | FX29: 109 | FY29: 61 | GD29: 1 | GF29: -367569951 | GG29: 2 | GH29: 1 | GI29: 2 | GJ29: 0 | GK29: 0 | GL29: =ROUND(IF(AND(BH29=3,BI29=3,FS29<>0),P29,0),2) -> 0 | GM29: =ROUND(O29+X29+Y29,2)+GX29 -> 8573.6 | GN29: =IF(OR(BI29=0,BI29=1),GM29-GX29,0) -> 8573.6 | GO29: =IF(BI29=2,GM29-GX29,0) -> 0 | GP29: =IF(BI29=4,GM29-GX29,0) -> 0 | GR29: 0 | GS29: 3 | GT29: 0 | GV29: =ROUND((GT29),6) -> 0 | GW29: 1 | GX29: =ROUND(HC29*I29,2) -> 0 | HA29: 0 | HB29: 0 | HC29: =GV29*GW29 -> 0 | HS29: 0 | IK29: 0
A30: 18 | B30: 1 | C30: 10 | E30: 1,1 | F30: 1.12-1-52 | G30: Узел трубопровода из стальных водогазопроводных оцинкованных труб, с гильзами, для водоснабжения, диаметр условного прохода 15 мм | H30: м | I30: =I28*J30 -> 18 | J30: 100 | K30: 100 | O30: =ROUND(CP30,2) -> 505.8 | P30: =ROUND((ROUND((AC30*AW30*I30),2)*BC30),2) -> 505.8 | Q30: =(ROUND((ROUND(((ET30)*AV30*I30),2)*BB30),2)+ROUND((ROUND(((AE30-(EU30))*AV30*I30),2)*BS30),2)) -> 0 | R30: =ROUND((ROUND((AE30*AV30*I30),2)*BS30),2) -> 0 | S30: =ROUND((ROUND((AF30*AV30*I30),2)*BA30),2) -> 0 | T30: =ROUND(CU30*I30,2) -> 0 | U30: =CV30*I30 -> 0 | V30: =CW30*I30 -> 0 | W30: =ROUND(CX30*I30,2) -> 0 | X30: =ROUND(CY30,2) -> 0 | Y30: =ROUND(CZ30,2) -> 0 | AA30: 59204062 | AB30: =ROUND((AC30+AD30+AF30),6) -> 28.1 | AC30: =ROUND((ES30),6) -> 28.1 | AD30: =ROUND((((ET30)-(EU30))+AE30),6) -> 0 | AE30: =ROUND((EU30),6) -> 0 | AF30: =ROUND((EV30),6) -> 0 | AG30: =ROUND((AP30),6) -> 0 | AH30: =(EW30) -> 0 | AI30: =(EX30) -> 0 | AJ30: =(AS30) -> 0 | AK30: 28.1 | AL30: 28.1 | AM30: 0 | AN30: 0 | AO30: 0 | AP30: 0 | AQ30: 0 | AR30: 0 | AS30: 0 | AT30: 109 | AU30: 61 | AV30: 1 | AW30: 1 | AZ30: 1 | BA30: 1 | BB30: 1 | BC30: 1 | BH30: 3 | BI30: 1 | BJ30: ТСН-2001.1 Доп. 79, Р. 12, о. 1, поз. 52 | BM30: 21 | BN30: 0 | BP30: 0 | BQ30: 30 | BR30: 0 | BS30: 1 | BT30: 1 | BU30: 1 | BV30: 1 | BW30: 1 | BX30: 1 | BZ30: 109 | CA30: 61 | CE30: 30 | CF30: 0 | CG30: 0 | CM30: 0 | CO30: 0 | CP30: =(P30+Q30+S30) -> 505.8 | CQ30: =ROUND((ROUND((AC30*AW30*1),2)*BC30),2) -> 28.1 | CR30: =(ROUND((ROUND(((ET30)*AV30*1),2)*BB30),2)+ROUND((ROUND(((AE30-(EU30))*AV30*1),2)*BS30),2)) -> 0 | CS30: =ROUND((ROUND((AE30*AV30*1),2)*BS30),2) -> 0 | CT30: =ROUND((ROUND((AF30*AV30*1),2)*BA30),2) -> 0 | CU30: =AG30 -> 0 | CV30: =(AH30*AV30) -> 0 | CW30: =AI30 -> 0 | CX30: =AJ30 -> 0 | CY30: =(((S30+R30)*AT30)/100) -> 0 | CZ30: =(((S30+R30)*AU30)/100) -> 0 | DN30: 0 | DO30: 0 | DP30: 1 | DQ30: 1 | DU30: 1003 | DV30: м | DW30: м | DX30: 1 | EE30: 58807897 | EF30: 30 | EG30: Строительные работы | EH30: 0 | EJ30: 1 | EK30: 21 | EL30: ТСН-2001.3-16. Трубопроводы внутренние | EM30: ТСН-2001.3-16-1 | EQ30: 0 | ER30: 28.1 | ES30: 28.1 | ET30: 0 | EU30: 0 | EV30: 0 | EW30: 0 | EX30: 0 | FQ30: 0 | FR30: 0 | FS30: 0 | FX30: 109 | FY30: 61 | GD30: 1 | GF30: 949658601 | GG30: 2 | GH30: 1 | GI30: -2 | GJ30: 0 | GK30: 0 | GL30: =ROUND(IF(AND(BH30=3,BI30=3,FS30<>0),P30,0),2) -> 0 | GM30: =ROUND(O30+X30+Y30,2)+GX30 -> 505.8 | GN30: =IF(OR(BI30=0,BI30=1),GM30-GX30,0) -> 505.8 | GO30: =IF(BI30=2,GM30-GX30,0) -> 0 | GP30: =IF(BI30=4,GM30-GX30,0) -> 0 | GR30: 0 | GS30: 3 | GT30: 0 | GV30: =ROUND((GT30),6) -> 0 | GW30: 1 | GX30: =ROUND(HC30*I30,2) -> 0 | HA30: 0 | HB30: 0 | HC30: =GV30*GW30 -> 0 | HS30: 0 | IK30: 0
A31: 18 | B31: 1 | C31: 22 | E31: 1,1 | F31: 1.12-1-52 | G31: Узел трубопровода из стальных водогазопроводных оцинкованных труб, с гильзами, для водоснабжения, диаметр условного прохода 15 мм | H31: м | I31: =I29*J31 -> 18 | J31: 100 | K31: 100 | O31: =ROUND(CP31,2) -> 9423.05 | P31: =ROUND((ROUND((AC31*AW31*I31),2)*BC31),2) -> 9423.05 | Q31: =(ROUND((ROUND(((ET31)*AV31*I31),2)*BB31),2)+ROUND((ROUND(((AE31-(EU31))*AV31*I31),2)*BS31),2)) -> 0 | R31: =ROUND((ROUND((AE31*AV31*I31),2)*BS31),2) -> 0 | S31: =ROUND((ROUND((AF31*AV31*I31),2)*BA31),2) -> 0 | T31: =ROUND(CU31*I31,2) -> 0 | U31: =CV31*I31 -> 0 | V31: =CW31*I31 -> 0 | W31: =ROUND(CX31*I31,2) -> 0 | X31: =ROUND(CY31,2) -> 0 | Y31: =ROUND(CZ31,2) -> 0 | AA31: 59204059 | AB31: =ROUND((AC31+AD31+AF31),6) -> 28.1 | AC31: =ROUND((ES31),6) -> 28.1 | AD31: =ROUND((((ET31)-(EU31))+AE31),6) -> 0 | AE31: =ROUND((EU31),6) -> 0 | AF31: =ROUND((EV31),6) -> 0 | AG31: =ROUND((AP31),6) -> 0 | AH31: =(EW31) -> 0 | AI31: =(EX31) -> 0 | AJ31: =(AS31) -> 0 | AK31: 28.1 | AL31: 28.1 | AM31: 0 | AN31: 0 | AO31: 0 | AP31: 0 | AQ31: 0 | AR31: 0 | AS31: 0 | AT31: 109 | AU31: 61 | AV31: 1 | AW31: 1 | AZ31: 1 | BA31: 1 | BB31: 1 | BC31: 18.63 | BH31: 3 | BI31: 1 | BJ31: ТСН-2001.1 Доп. 79, Р. 12, о. 1, поз. 52 | BM31: 21 | BN31: 0 | BO31: 1.12-1-52 | BP31: 1 | BQ31: 30 | BR31: 0 | BS31: 1 | BT31: 1 | BU31: 1 | BV31: 1 | BW31: 1 | BX31: 1 | BZ31: 109 | CA31: 61 | CE31: 30 | CF31: 0 | CG31: 0 | CM31: 0 | CO31: 0 | CP31: =(P31+Q31+S31) -> 9423.05 | CQ31: =ROUND((ROUND((AC31*AW31*1),2)*BC31),2) -> 523.5 | CR31: =(ROUND((ROUND(((ET31)*AV31*1),2)*BB31),2)+ROUND((ROUND(((AE31-(EU31))*AV31*1),2)*BS31),2)) -> 0 | CS31: =ROUND((ROUND((AE31*AV31*1),2)*BS31),2) -> 0 | CT31: =ROUND((ROUND((AF31*AV31*1),2)*BA31),2) -> 0 | CU31: =AG31 -> 0 | CV31: =(AH31*AV31) -> 0 | CW31: =AI31 -> 0 | CX31: =AJ31 -> 0 | CY31: =(((S31+R31)*AT31)/100) -> 0 | CZ31: =(((S31+R31)*AU31)/100) -> 0 | DN31: 0 | DO31: 0 | DP31: 1 | DQ31: 1 | DU31: 1003 | DV31: м | DW31: м | DX31: 1 | EE31: 58807897 | EF31: 30 | EG31: Строительные работы | EH31: 0 | EJ31: 1 | EK31: 21 | EL31: ТСН-2001.3-16. Трубопроводы внутренние | EM31: ТСН-2001.3-16-1 | EQ31: 0 | ER31: 28.1 | ES31: 28.1 | ET31: 0 | EU31: 0 | EV31: 0 | EW31: 0 | EX31: 0 | FQ31: 0 | FR31: 0 | FS31: 0 | FX31: 109 | FY31: 61 | GD31: 1 | GF31: 949658601 | GG31: 2 | GH31: 1 | GI31: 2 | GJ31: 0 | GK31: 0 | GL31: =ROUND(IF(AND(BH31=3,BI31=3,FS31<>0),P31,0),2) -> 0 | GM31: =ROUND(O31+X31+Y31,2)+GX31 -> 9423.05 | GN31: =IF(OR(BI31=0,BI31=1),GM31-GX31,0) -> 9423.05 | GO31: =IF(BI31=2,GM31-GX31,0) -> 0 | GP31: =IF(BI31=4,GM31-GX31,0) -> 0 | GR31: 0 | GS31: 3 | GT31: 0 | GV31: =ROUND((GT31),6) -> 0 | GW31: 1 | GX31: =ROUND(HC31*I31,2) -> 0 | HA31: 0 | HB31: 0 | HC31: =GV31*GW31 -> 0 | HS31: 0 | IK31: 0
A32: 18 | B32: 1 | C32: 12 | E32: 1,2 | F32: 1.13-4-61 | G32: Кран шаровой, латунный, никелированный, полнопроходной, с алюминиевой рукояткой, муфтовый, температура рабочей среды от -15 до +110°С, номинальное давление PN 4,0 МПа, номинальный диаметр DN 15 мм | H32: шт. | I32: =I28*J32 -> 6 | J32: 33.333333 | K32: 33.333333 | O32: =ROUND(CP32,2) -> 209.82 | P32: =ROUND((ROUND((AC32*AW32*I32),2)*BC32),2) -> 209.82 | Q32: =(ROUND((ROUND(((ET32)*AV32*I32),2)*BB32),2)+ROUND((ROUND(((AE32-(EU32))*AV32*I32),2)*BS32),2)) -> 0 | R32: =ROUND((ROUND((AE32*AV32*I32),2)*BS32),2) -> 0 | S32: =ROUND((ROUND((AF32*AV32*I32),2)*BA32),2) -> 0 | T32: =ROUND(CU32*I32,2) -> 0 | U32: =CV32*I32 -> 0 | V32: =CW32*I32 -> 0 | W32: =ROUND(CX32*I32,2) -> 0 | X32: =ROUND(CY32,2) -> 0 | Y32: =ROUND(CZ32,2) -> 0 | AA32: 59204062 | AB32: =ROUND((AC32+AD32+AF32),6) -> 34.97 | AC32: =ROUND((ES32),6) -> 34.97 | AD32: =ROUND((((ET32)-(EU32))+AE32),6) -> 0 | AE32: =ROUND((EU32),6) -> 0 | AF32: =ROUND((EV32),6) -> 0 | AG32: =ROUND((AP32),6) -> 0 | AH32: =(EW32) -> 0 | AI32: =(EX32) -> 0 | AJ32: =(AS32) -> 0 | AK32: 34.97 | AL32: 34.97 | AM32: 0 | AN32: 0 | AO32: 0 | AP32: 0 | AQ32: 0 | AR32: 0 | AS32: 0 | AT32: 109 | AU32: 61 | AV32: 1 | AW32: 1 | AZ32: 1 | BA32: 1 | BB32: 1 | BC32: 1 | BH32: 3 | BI32: 1 | BJ32: ТСН-2001.1 Доп. 73, Р. 13, о. 4, поз. 61 | BM32: 21 | BN32: 0 | BP32: 0 | BQ32: 30 | BR32: 0 | BS32: 1 | BT32: 1 | BU32: 1 | BV32: 1 | BW32: 1 | BX32: 1 | BZ32: 109 | CA32: 61 | CE32: 30 | CF32: 0 | CG32: 0 | CM32: 0 | CO32: 0 | CP32: =(P32+Q32+S32) -> 209.82 | CQ32: =ROUND((ROUND((AC32*AW32*1),2)*BC32),2) -> 34.97 | CR32: =(ROUND((ROUND(((ET32)*AV32*1),2)*BB32),2)+ROUND((ROUND(((AE32-(EU32))*AV32*1),2)*BS32),2)) -> 0 | CS32: =ROUND((ROUND((AE32*AV32*1),2)*BS32),2) -> 0 | CT32: =ROUND((ROUND((AF32*AV32*1),2)*BA32),2) -> 0 | CU32: =AG32 -> 0 | CV32: =(AH32*AV32) -> 0 | CW32: =AI32 -> 0 | CX32: =AJ32 -> 0 | CY32: =(((S32+R32)*AT32)/100) -> 0 | CZ32: =(((S32+R32)*AU32)/100) -> 0 | DN32: 0 | DO32: 0 | DP32: 1 | DQ32: 1 | DU32: 1010 | DV32: шт. | DW32: шт. | DX32: 1 | EE32: 58807897 | EF32: 30 | EG32: Строительные работы | EH32: 0 | EJ32: 1 | EK32: 21 | EL32: ТСН-2001.3-16. Трубопроводы внутренние | EM32: ТСН-2001.3-16-1 | EQ32: 0 | ER32: 34.97 | ES32: 34.97 | ET32: 0 | EU32: 0 | EV32: 0 | EW32: 0 | EX32: 0 | FQ32: 0 | FR32: 0 | FS32: 0 | FX32: 109 | FY32: 61 | GD32: 1 | GF32: -1914030801 | GG32: 2 | GH32: 1 | GI32: -2 | GJ32: 0 | GK32: 0 | GL32: =ROUND(IF(AND(BH32=3,BI32=3,FS32<>0),P32,0),2) -> 0 | GM32: =ROUND(O32+X32+Y32,2)+GX32 -> 209.82 | GN32: =IF(OR(BI32=0,BI32=1),GM32-GX32,0) -> 209.82 | GO32: =IF(BI32=2,GM32-GX32,0) -> 0 | GP32: =IF(BI32=4,GM32-GX32,0) -> 0 | GR32: 0 | GS32: 3 | GT32: 0 | GV32: =ROUND((GT32),6) -> 0 | GW32: 1 | GX32: =ROUND(HC32*I32,2) -> 0 | HA32: 0 | HB32: 0 | HC32: =GV32*GW32 -> 0 | HS32: 0 | IK32: 0
A33: 18 | B33: 1 | C33: 24 | E33: 1,2 | F33: 1.13-4-61 | G33: Кран шаровой, латунный, никелированный, полнопроходной, с алюминиевой рукояткой, муфтовый, температура рабочей среды от -15 до +110°С, номинальное давление PN 4,0 МПа, номинальный диаметр DN 15 мм | H33: шт. | I33: =I29*J33 -> 6 | J33: 33.333333 | K33: 33.333333 | O33: =ROUND(CP33,2) -> 3927.83 | P33: =ROUND((ROUND((AC33*AW33*I33),2)*BC33),2) -> 3927.83 | Q33: =(ROUND((ROUND(((ET33)*AV33*I33),2)*BB33),2)+ROUND((ROUND(((AE33-(EU33))*AV33*I33),2)*BS33),2)) -> 0 | R33: =ROUND((ROUND((AE33*AV33*I33),2)*BS33),2) -> 0 | S33: =ROUND((ROUND((AF33*AV33*I33),2)*BA33),2) -> 0 | T33: =ROUND(CU33*I33,2) -> 0 | U33: =CV33*I33 -> 0 | V33: =CW33*I33 -> 0 | W33: =ROUND(CX33*I33,2) -> 0 | X33: =ROUND(CY33,2) -> 0 | Y33: =ROUND(CZ33,2) -> 0 | AA33: 59204059 | AB33: =ROUND((AC33+AD33+AF33),6) -> 34.97 | AC33: =ROUND((ES33),6) -> 34.97 | AD33: =ROUND((((ET33)-(EU33))+AE33),6) -> 0 | AE33: =ROUND((EU33),6) -> 0 | AF33: =ROUND((EV33),6) -> 0 | AG33: =ROUND((AP33),6) -> 0 | AH33: =(EW33) -> 0 | AI33: =(EX33) -> 0 | AJ33: =(AS33) -> 0 | AK33: 34.97 | AL33: 34.97 | AM33: 0 | AN33: 0 | AO33: 0 | AP33: 0 | AQ33: 0 | AR33: 0 | AS33: 0 | AT33: 109 | AU33: 61 | AV33: 1 | AW33: 1 | AZ33: 1 | BA33: 1 | BB33: 1 | BC33: 18.72 | BH33: 3 | BI33: 1 | BJ33: ТСН-2001.1 Доп. 73, Р. 13, о. 4, поз. 61 | BM33: 21 | BN33: 0 | BO33: 1.13-4-61 | BP33: 1 | BQ33: 30 | BR33: 0 | BS33: 1 | BT33: 1 | BU33: 1 | BV33: 1 | BW33: 1 | BX33: 1 | BZ33: 109 | CA33: 61 | CE33: 30 | CF33: 0 | CG33: 0 | CM33: 0 | CO33: 0 | CP33: =(P33+Q33+S33) -> 3927.83 | CQ33: =ROUND((ROUND((AC33*AW33*1),2)*BC33),2) -> 654.64 | CR33: =(ROUND((ROUND(((ET33)*AV33*1),2)*BB33),2)+ROUND((ROUND(((AE33-(EU33))*AV33*1),2)*BS33),2)) -> 0 | CS33: =ROUND((ROUND((AE33*AV33*1),2)*BS33),2) -> 0 | CT33: =ROUND((ROUND((AF33*AV33*1),2)*BA33),2) -> 0 | CU33: =AG33 -> 0 | CV33: =(AH33*AV33) -> 0 | CW33: =AI33 -> 0 | CX33: =AJ33 -> 0 | CY33: =(((S33+R33)*AT33)/100) -> 0 | CZ33: =(((S33+R33)*AU33)/100) -> 0 | DN33: 0 | DO33: 0 | DP33: 1 | DQ33: 1 | DU33: 1010 | DV33: шт. | DW33: шт. | DX33: 1 | EE33: 58807897 | EF33: 30 | EG33: Строительные работы | EH33: 0 | EJ33: 1 | EK33: 21 | EL33: ТСН-2001.3-16. Трубопроводы внутренние | EM33: ТСН-2001.3-16-1 | EQ33: 0 | ER33: 34.97 | ES33: 34.97 | ET33: 0 | EU33: 0 | EV33: 0 | EW33: 0 | EX33: 0 | FQ33: 0 | FR33: 0 | FS33: 0 | FX33: 109 | FY33: 61 | GD33: 1 | GF33: -1914030801 | GG33: 2 | GH33: 1 | GI33: 2 | GJ33: 0 | GK33: 0 | GL33: =ROUND(IF(AND(BH33=3,BI33=3,FS33<>0),P33,0),2) -> 0 | GM33: =ROUND(O33+X33+Y33,2)+GX33 -> 3927.83 | GN33: =IF(OR(BI33=0,BI33=1),GM33-GX33,0) -> 3927.83 | GO33: =IF(BI33=2,GM33-GX33,0) -> 0 | GP33: =IF(BI33=4,GM33-GX33,0) -> 0 | GR33: 0 | GS33: 3 | GT33: 0 | GV33: =ROUND((GT33),6) -> 0 | GW33: 1 | GX33: =ROUND(HC33*I33,2) -> 0 | HA33: 0 | HB33: 0 | HC33: =GV33*GW33 -> 0 | HS33: 0 | IK33: 0
A34: 18 | B34: 1 | C34: 11 | E34: 1,3 | F34: 1.13-4-137 | G34: Кран шаровой, латунный, никелированный, спускной, с наружной резьбой, с насадкой для шланга, с алюминиевой рукояткой, температура рабочей среды от -15 до +90°С, пропускная способность 1,9 м3/ч, номинальное давление PN 1,0 МПа, номинальный диаметр DN 15 мм | H34: шт. | I34: =I28*J34 -> 44 | J34: 244.44444 | K34: 244.44444 | O34: =ROUND(CP34,2) -> 1082.84 | P34: =ROUND((ROUND((AC34*AW34*I34),2)*BC34),2) -> 1082.84 | Q34: =(ROUND((ROUND(((ET34)*AV34*I34),2)*BB34),2)+ROUND((ROUND(((AE34-(EU34))*AV34*I34),2)*BS34),2)) -> 0 | R34: =ROUND((ROUND((AE34*AV34*I34),2)*BS34),2) -> 0 | S34: =ROUND((ROUND((AF34*AV34*I34),2)*BA34),2) -> 0 | T34: =ROUND(CU34*I34,2) -> 0 | U34: =CV34*I34 -> 0 | V34: =CW34*I34 -> 0 | W34: =ROUND(CX34*I34,2) -> 0 | X34: =ROUND(CY34,2) -> 0 | Y34: =ROUND(CZ34,2) -> 0 | AA34: 59204062 | AB34: =ROUND((AC34+AD34+AF34),6) -> 24.61 | AC34: =ROUND((ES34),6) -> 24.61 | AD34: =ROUND((((ET34)-(EU34))+AE34),6) -> 0 | AE34: =ROUND((EU34),6) -> 0 | AF34: =ROUND((EV34),6) -> 0 | AG34: =ROUND((AP34),6) -> 0 | AH34: =(EW34) -> 0 | AI34: =(EX34) -> 0 | AJ34: =(AS34) -> 0 | AK34: 24.61 | AL34: 24.61 | AM34: 0 | AN34: 0 | AO34: 0 | AP34: 0 | AQ34: 0 | AR34: 0 | AS34: 0 | AT34: 109 | AU34: 61 | AV34: 1 | AW34: 1 | AZ34: 1 | BA34: 1 | BB34: 1 | BC34: 1 | BH34: 3 | BI34: 1 | BJ34: ТСН-2001.1 Доп. 73, Р. 13, о. 4, поз. 137 | BM34: 21 | BN34: 0 | BP34: 0 | BQ34: 30 | BR34: 0 | BS34: 1 | BT34: 1 | BU34: 1 | BV34: 1 | BW34: 1 | BX34: 1 | BZ34: 109 | CA34: 61 | CE34: 30 | CF34: 0 | CG34: 0 | CM34: 0 | CO34: 0 | CP34: =(P34+Q34+S34) -> 1082.84 | CQ34: =ROUND((ROUND((AC34*AW34*1),2)*BC34),2) -> 24.61 | CR34: =(ROUND((ROUND(((ET34)*AV34*1),2)*BB34),2)+ROUND((ROUND(((AE34-(EU34))*AV34*1),2)*BS34),2)) -> 0 | CS34: =ROUND((ROUND((AE34*AV34*1),2)*BS34),2) -> 0 | CT34: =ROUND((ROUND((AF34*AV34*1),2)*BA34),2) -> 0 | CU34: =AG34 -> 0 | CV34: =(AH34*AV34) -> 0 | CW34: =AI34 -> 0 | CX34: =AJ34 -> 0 | CY34: =(((S34+R34)*AT34)/100) -> 0 | CZ34: =(((S34+R34)*AU34)/100) -> 0 | DN34: 0 | DO34: 0 | DP34: 1 | DQ34: 1 | DU34: 1010 | DV34: шт. | DW34: шт. | DX34: 1 | EE34: 58807897 | EF34: 30 | EG34: Строительные работы | EH34: 0 | EJ34: 1 | EK34: 21 | EL34: ТСН-2001.3-16. Трубопроводы внутренние | EM34: ТСН-2001.3-16-1 | EQ34: 0 | ER34: 24.61 | ES34: 24.61 | ET34: 0 | EU34: 0 | EV34: 0 | EW34: 0 | EX34: 0 | FQ34: 0 | FR34: 0 | FS34: 0 | FX34: 109 | FY34: 61 | GD34: 1 | GF34: -877742701 | GG34: 2 | GH34: 1 | GI34: -2 | GJ34: 0 | GK34: 0 | GL34: =ROUND(IF(AND(BH34=3,BI34=3,FS34<>0),P34,0),2) -> 0 | GM34: =ROUND(O34+X34+Y34,2)+GX34 -> 1082.84 | GN34: =IF(OR(BI34=0,BI34=1),GM34-GX34,0) -> 1082.84 | GO34: =IF(BI34=2,GM34-GX34,0) -> 0 | GP34: =IF(BI34=4,GM34-GX34,0) -> 0 | GR34: 0 | GS34: 3 | GT34: 0 | GV34: =ROUND((GT34),6) -> 0 | GW34: 1 | GX34: =ROUND(HC34*I34,2) -> 0 | HA34: 0 | HB34: 0 | HC34: =GV34*GW34 -> 0 | HS34: 0 | IK34: 0
A35: 18 | B35: 1 | C35: 23 | E35: 1,3 | F35: 1.13-4-137 | G35: Кран шаровой, латунный, никелированный, спускной, с наружной резьбой, с насадкой для шланга, с алюминиевой рукояткой, температура рабочей среды от -15 до +90°С, пропускная способность 1,9 м3/ч, номинальное давление PN 1,0 МПа, номинальный диаметр DN 15 мм | H35: шт. | I35: =I29*J35 -> 44 | J35: 244.44444 | K35: 244.44444 | O35: =ROUND(CP35,2) -> 38527.45 | P35: =ROUND((ROUND((AC35*AW35*I35),2)*BC35),2) -> 38527.45 | Q35: =(ROUND((ROUND(((ET35)*AV35*I35),2)*BB35),2)+ROUND((ROUND(((AE35-(EU35))*AV35*I35),2)*BS35),2)) -> 0 | R35: =ROUND((ROUND((AE35*AV35*I35),2)*BS35),2) -> 0 | S35: =ROUND((ROUND((AF35*AV35*I35),2)*BA35),2) -> 0 | T35: =ROUND(CU35*I35,2) -> 0 | U35: =CV35*I35 -> 0 | V35: =CW35*I35 -> 0 | W35: =ROUND(CX35*I35,2) -> 0 | X35: =ROUND(CY35,2) -> 0 | Y35: =ROUND(CZ35,2) -> 0 | AA35: 59204059 | AB35: =ROUND((AC35+AD35+AF35),6) -> 24.61 | AC35: =ROUND((ES35),6) -> 24.61 | AD35: =ROUND((((ET35)-(EU35))+AE35),6) -> 0 | AE35: =ROUND((EU35),6) -> 0 | AF35: =ROUND((EV35),6) -> 0 | AG35: =ROUND((AP35),6) -> 0 | AH35: =(EW35) -> 0 | AI35: =(EX35) -> 0 | AJ35: =(AS35) -> 0 | AK35: 24.61 | AL35: 24.61 | AM35: 0 | AN35: 0 | AO35: 0 | AP35: 0 | AQ35: 0 | AR35: 0 | AS35: 0 | AT35: 109 | AU35: 61 | AV35: 1 | AW35: 1 | AZ35: 1 | BA35: 1 | BB35: 1 | BC35: 35.58 | BH35: 3 | BI35: 1 | BJ35: ТСН-2001.1 Доп. 73, Р. 13, о. 4, поз. 137 | BM35: 21 | BN35: 0 | BO35: 1.13-4-137 | BP35: 1 | BQ35: 30 | BR35: 0 | BS35: 1 | BT35: 1 | BU35: 1 | BV35: 1 | BW35: 1 | BX35: 1 | BZ35: 109 | CA35: 61 | CE35: 30 | CF35: 0 | CG35: 0 | CM35: 0 | CO35: 0 | CP35: =(P35+Q35+S35) -> 38527.45 | CQ35: =ROUND((ROUND((AC35*AW35*1),2)*BC35),2) -> 875.62 | CR35: =(ROUND((ROUND(((ET35)*AV35*1),2)*BB35),2)+ROUND((ROUND(((AE35-(EU35))*AV35*1),2)*BS35),2)) -> 0 | CS35: =ROUND((ROUND((AE35*AV35*1),2)*BS35),2) -> 0 | CT35: =ROUND((ROUND((AF35*AV35*1),2)*BA35),2) -> 0 | CU35: =AG35 -> 0 | CV35: =(AH35*AV35) -> 0 | CW35: =AI35 -> 0 | CX35: =AJ35 -> 0 | CY35: =(((S35+R35)*AT35)/100) -> 0 | CZ35: =(((S35+R35)*AU35)/100) -> 0 | DN35: 0 | DO35: 0 | DP35: 1 | DQ35: 1 | DU35: 1010 | DV35: шт. | DW35: шт. | DX35: 1 | EE35: 58807897 | EF35: 30 | EG35: Строительные работы | EH35: 0 | EJ35: 1 | EK35: 21 | EL35: ТСН-2001.3-16. Трубопроводы внутренние | EM35: ТСН-2001.3-16-1 | EQ35: 0 | ER35: 24.61 | ES35: 24.61 | ET35: 0 | EU35: 0 | EV35: 0 | EW35: 0 | EX35: 0 | FQ35: 0 | FR35: 0 | FS35: 0 | FX35: 109 | FY35: 61 | GD35: 1 | GF35: -877742701 | GG35: 2 | GH35: 1 | GI35: 2 | GJ35: 0 | GK35: 0 | GL35: =ROUND(IF(AND(BH35=3,BI35=3,FS35<>0),P35,0),2) -> 0 | GM35: =ROUND(O35+X35+Y35,2)+GX35 -> 38527.45 | GN35: =IF(OR(BI35=0,BI35=1),GM35-GX35,0) -> 38527.45 | GO35: =IF(BI35=2,GM35-GX35,0) -> 0 | GP35: =IF(BI35=4,GM35-GX35,0) -> 0 | GR35: 0 | GS35: 3 | GT35: 0 | GV35: =ROUND((GT35),6) -> 0 | GW35: 1 | GX35: =ROUND(HC35*I35,2) -> 0 | HA35: 0 | HB35: 0 | HC35: =GV35*GW35 -> 0 | HS35: 0 | IK35: 0
A36: 18 | B36: 1 | C36: 9 | E36: 1,4 | F36: 1.12-10-146 | G36: Хомут стальной, оцинкованный, двухболтовой, с поворотным механизмом, каучуковой прокладкой, для крепления труб диаметром от 16 до 20 мм, резьба М8/М10 | H36: 100 шт. | I36: =I28*J36 -> 0.12 | J36: 0.66666667 | K36: 0.666667 | O36: =ROUND(CP36,2) -> 63.15 | P36: =ROUND((ROUND((AC36*AW36*I36),2)*BC36),2) -> 63.15 | Q36: =(ROUND((ROUND(((ET36)*AV36*I36),2)*BB36),2)+ROUND((ROUND(((AE36-(EU36))*AV36*I36),2)*BS36),2)) -> 0 | R36: =ROUND((ROUND((AE36*AV36*I36),2)*BS36),2) -> 0 | S36: =ROUND((ROUND((AF36*AV36*I36),2)*BA36),2) -> 0 | T36: =ROUND(CU36*I36,2) -> 0 | U36: =CV36*I36 -> 0 | V36: =CW36*I36 -> 0 | W36: =ROUND(CX36*I36,2) -> 0 | X36: =ROUND(CY36,2) -> 0 | Y36: =ROUND(CZ36,2) -> 0 | AA36: 59204062 | AB36: =ROUND((AC36+AD36+AF36),6) -> 526.22 | AC36: =ROUND((ES36),6) -> 526.22 | AD36: =ROUND((((ET36)-(EU36))+AE36),6) -> 0 | AE36: =ROUND((EU36),6) -> 0 | AF36: =ROUND((EV36),6) -> 0 | AG36: =ROUND((AP36),6) -> 0 | AH36: =(EW36) -> 0 | AI36: =(EX36) -> 0 | AJ36: =(AS36) -> 0 | AK36: 526.22 | AL36: 526.22 | AM36: 0 | AN36: 0 | AO36: 0 | AP36: 0 | AQ36: 0 | AR36: 0 | AS36: 0 | AT36: 109 | AU36: 61 | AV36: 1 | AW36: 1 | AZ36: 1 | BA36: 1 | BB36: 1 | BC36: 1 | BH36: 3 | BI36: 1 | BJ36: ТСН-2001.1 Доп. 79, Р. 12, о. 10, поз. 146 | BM36: 21 | BN36: 0 | BP36: 0 | BQ36: 30 | BR36: 0 | BS36: 1 | BT36: 1 | BU36: 1 | BV36: 1 | BW36: 1 | BX36: 1 | BZ36: 109 | CA36: 61 | CE36: 30 | CF36: 0 | CG36: 0 | CM36: 0 | CO36: 0 | CP36: =(P36+Q36+S36) -> 63.15 | CQ36: =ROUND((ROUND((AC36*AW36*1),2)*BC36),2) -> 526.22 | CR36: =(ROUND((ROUND(((ET36)*AV36*1),2)*BB36),2)+ROUND((ROUND(((AE36-(EU36))*AV36*1),2)*BS36),2)) -> 0 | CS36: =ROUND((ROUND((AE36*AV36*1),2)*BS36),2) -> 0 | CT36: =ROUND((ROUND((AF36*AV36*1),2)*BA36),2) -> 0 | CU36: =AG36 -> 0 | CV36: =(AH36*AV36) -> 0 | CW36: =AI36 -> 0 | CX36: =AJ36 -> 0 | CY36: =(((S36+R36)*AT36)/100) -> 0 | CZ36: =(((S36+R36)*AU36)/100) -> 0 | DN36: 0 | DO36: 0 | DP36: 1 | DQ36: 1 | DU36: 1010 | DV36: 100 шт. | DW36: 100 шт. | DX36: 100 | EE36: 58807897 | EF36: 30 | EG36: Строительные работы | EH36: 0 | EJ36: 1 | EK36: 21 | EL36: ТСН-2001.3-16. Трубопроводы внутренние | EM36: ТСН-2001.3-16-1 | EQ36: 0 | ER36: 526.22 | ES36: 526.22 | ET36: 0 | EU36: 0 | EV36: 0 | EW36: 0 | EX36: 0 | FQ36: 0 | FR36: 0 | FS36: 0 | FX36: 109 | FY36: 61 | GD36: 1 | GF36: 1873919888 | GG36: 2 | GH36: 1 | GI36: -2 | GJ36: 0 | GK36: 0 | GL36: =ROUND(IF(AND(BH36=3,BI36=3,FS36<>0),P36,0),2) -> 0 | GM36: =ROUND(O36+X36+Y36,2)+GX36 -> 63.15 | GN36: =IF(OR(BI36=0,BI36=1),GM36-GX36,0) -> 63.15 | GO36: =IF(BI36=2,GM36-GX36,0) -> 0 | GP36: =IF(BI36=4,GM36-GX36,0) -> 0 | GR36: 0 | GS36: 3 | GT36: 0 | GV36: =ROUND((GT36),6) -> 0 | GW36: 1 | GX36: =ROUND(HC36*I36,2) -> 0 | HA36: 0 | HB36: 0 | HC36: =GV36*GW36 -> 0 | HS36: 0 | IK36: 0
A37: 18 | B37: 1 | C37: 21 | E37: 1,4 | F37: 1.12-10-146 | G37: Хомут стальной, оцинкованный, двухболтовой, с поворотным механизмом, каучуковой прокладкой, для крепления труб диаметром от 16 до 20 мм, резьба М8/М10 | H37: 100 шт. | I37: =I29*J37 -> 0.12 | J37: 0.66666667 | K37: 0.666667 | O37: =ROUND(CP37,2) -> 176.19 | P37: =ROUND((ROUND((AC37*AW37*I37),2)*BC37),2) -> 176.19 | Q37: =(ROUND((ROUND(((ET37)*AV37*I37),2)*BB37),2)+ROUND((ROUND(((AE37-(EU37))*AV37*I37),2)*BS37),2)) -> 0 | R37: =ROUND((ROUND((AE37*AV37*I37),2)*BS37),2) -> 0 | S37: =ROUND((ROUND((AF37*AV37*I37),2)*BA37),2) -> 0 | T37: =ROUND(CU37*I37,2) -> 0 | U37: =CV37*I37 -> 0 | V37: =CW37*I37 -> 0 | W37: =ROUND(CX37*I37,2) -> 0 | X37: =ROUND(CY37,2) -> 0 | Y37: =ROUND(CZ37,2) -> 0 | AA37: 59204059 | AB37: =ROUND((AC37+AD37+AF37),6) -> 526.22 | AC37: =ROUND((ES37),6) -> 526.22 | AD37: =ROUND((((ET37)-(EU37))+AE37),6) -> 0 | AE37: =ROUND((EU37),6) -> 0 | AF37: =ROUND((EV37),6) -> 0 | AG37: =ROUND((AP37),6) -> 0 | AH37: =(EW37) -> 0 | AI37: =(EX37) -> 0 | AJ37: =(AS37) -> 0 | AK37: 526.22 | AL37: 526.22 | AM37: 0 | AN37: 0 | AO37: 0 | AP37: 0 | AQ37: 0 | AR37: 0 | AS37: 0 | AT37: 109 | AU37: 61 | AV37: 1 | AW37: 1 | AZ37: 1 | BA37: 1 | BB37: 1 | BC37: 2.79 | BH37: 3 | BI37: 1 | BJ37: ТСН-2001.1 Доп. 79, Р. 12, о. 10, поз. 146 | BM37: 21 | BN37: 0 | BO37: 1.12-10-146 | BP37: 1 | BQ37: 30 | BR37: 0 | BS37: 1 | BT37: 1 | BU37: 1 | BV37: 1 | BW37: 1 | BX37: 1 | BZ37: 109 | CA37: 61 | CE37: 30 | CF37: 0 | CG37: 0 | CM37: 0 | CO37: 0 | CP37: =(P37+Q37+S37) -> 176.19 | CQ37: =ROUND((ROUND((AC37*AW37*1),2)*BC37),2) -> 1468.15 | CR37: =(ROUND((ROUND(((ET37)*AV37*1),2)*BB37),2)+ROUND((ROUND(((AE37-(EU37))*AV37*1),2)*BS37),2)) -> 0 | CS37: =ROUND((ROUND((AE37*AV37*1),2)*BS37),2) -> 0 | CT37: =ROUND((ROUND((AF37*AV37*1),2)*BA37),2) -> 0 | CU37: =AG37 -> 0 | CV37: =(AH37*AV37) -> 0 | CW37: =AI37 -> 0 | CX37: =AJ37 -> 0 | CY37: =(((S37+R37)*AT37)/100) -> 0 | CZ37: =(((S37+R37)*AU37)/100) -> 0 | DN37: 0 | DO37: 0 | DP37: 1 | DQ37: 1 | DU37: 1010 | DV37: 100 шт. | DW37: 100 шт. | DX37: 100 | EE37: 58807897 | EF37: 30 | EG37: Строительные работы | EH37: 0 | EJ37: 1 | EK37: 21 | EL37: ТСН-2001.3-16. Трубопроводы внутренние | EM37: ТСН-2001.3-16-1 | EQ37: 0 | ER37: 526.22 | ES37: 526.22 | ET37: 0 | EU37: 0 | EV37: 0 | EW37: 0 | EX37: 0 | FQ37: 0 | FR37: 0 | FS37: 0 | FX37: 109 | FY37: 61 | GD37: 1 | GF37: 1873919888 | GG37: 2 | GH37: 1 | GI37: 2 | GJ37: 0 | GK37: 0 | GL37: =ROUND(IF(AND(BH37=3,BI37=3,FS37<>0),P37,0),2) -> 0 | GM37: =ROUND(O37+X37+Y37,2)+GX37 -> 176.19 | GN37: =IF(OR(BI37=0,BI37=1),GM37-GX37,0) -> 176.19 | GO37: =IF(BI37=2,GM37-GX37,0) -> 0 | GP37: =IF(BI37=4,GM37-GX37,0) -> 0 | GR37: 0 | GS37: 3 | GT37: 0 | GV37: =ROUND((GT37),6) -> 0 | GW37: 1 | GX37: =ROUND(HC37*I37,2) -> 0 | HA37: 0 | HB37: 0 | HC37: =GV37*GW37 -> 0 | HS37: 0 | IK37: 0
A38: 17 | B38: 1 | C38: =ROW(SmtRes!A40) -> 40 | D38: =ROW(EtalonRes!A37) -> 37 | F38: 3.16-7-1 | G38: Прокладка трубопроводов водоснабжения из стальных водогазопроводных оцинкованных труб диаметром 15 мм | H38: 100 м трубопровода | I38: =ROUND(ROUND(18/100,4)*0,9) -> 0 | J38: 0 | K38: =ROUND(ROUND(18/100,4)*0,9) -> 0 | O38: =ROUND(CP38,2) -> 0 | P38: =ROUND((ROUND((AC38*AW38*I38),2)*BC38),2) -> 0 | Q38: =(ROUND((ROUND(((((ET38*1.25)*1.1))*AV38*I38),2)*BB38),2)+ROUND((ROUND(((AE38-(((EU38*1.25)*1.1)))*AV38*I38),2)*BS38),2)) -> 0 | R38: =ROUND((ROUND((AE38*AV38*I38),2)*BS38),2) -> 0 | S38: =ROUND((ROUND((AF38*AV38*I38),2)*BA38),2) -> 0 | T38: =ROUND(CU38*I38,2) -> 0 | U38: =CV38*I38 -> 0 | V38: =CW38*I38 -> 0 | W38: =ROUND(CX38*I38,2) -> 0 | X38: =ROUND(CY38,2) -> 0 | Y38: =ROUND(CZ38,2) -> 0 | AA38: -1 | AB38: =ROUND((AC38+AD38+AF38),6) -> 648.2556 | AC38: =ROUND((ES38),6) -> 44.58 | AD38: =ROUND((((((ET38*1.25)*1.1))-(((EU38*1.25)*1.1)))+AE38),6) -> 65.68375 | AE38: =ROUND((((EU38*1.25)*1.1)),6) -> 8.3325 | AF38: =ROUND((((EV38*1.15)*1.1)),6) -> 537.99185 | AG38: =ROUND((AP38),6) -> 0 | AH38: =(((EW38*1.15)*1.1)) -> 42.6305 | AI38: =(((EX38*1.25)*1.1)) -> 0 | AJ38: =(AS38) -> 0 | AK38: 517.64 | AL38: 44.58 | AM38: 47.77 | AN38: 6.06 | AO38: 425.29 | AP38: 0 | AQ38: 33.7 | AR38: 0 | AS38: 0 | AT38: 109 | AU38: 61 | AV38: 1.067 | AW38: 1 | AZ38: 1 | BA38: 1 | BB38: 1 | BC38: 1 | BH38: 0 | BI38: 1 | BJ38: ТСН-2001.3 Доп. 79, Сб. 16, т. 7, поз. 1 | BM38: 21 | BN38: 0 | BO38: 3.16-7-1 | BP38: 1 | BQ38: 30 | BR38: 0 | BS38: 1 | BT38: 1 | BU38: 1 | BV38: 1 | BW38: 1 | BX38: 1 | BZ38: 109 | CA38: 61 | CE38: 30 | CF38: 0 | CG38: 0 | CM38: 0 | CN38: Поправка: О.П. п.3.4. 6 Наименование: Выполняемые при ремонте и реконструкции работы аналогичные технологическим процессам, характерным для нового строительства и отсутствующим в сборниках на ремонтно-строительные работы Поправка: О.П. п.3.4.30.в Наименование: При применении территориальных сметных нормативов для города Москвы затраты, учитывающие напряженные и стесненные условия производства работ (стесненность, сложность складирования и транспортной логистики и т.п.), исчисляются с применением коэффициентов к затратам труда и заработной плате рабочих, машинистов, времени эксплуатации машин и механизмов, стоимости эксплуатации машин в размере: для объектов, расположенных за пределами Третьего транспортного кольца города Москвы, но в пределах Московской кольцевой автомобильной дороги | CO38: 0 | CP38: =(P38+Q38+S38) -> 0 | CQ38: =ROUND((ROUND((AC38*AW38*1),2)*BC38),2) -> 44.58 | CR38: =(ROUND((ROUND(((((ET38*1.25)*1.1))*AV38*1),2)*BB38),2)+ROUND((ROUND(((AE38-(((EU38*1.25)*1.1)))*AV38*1),2)*BS38),2)) -> 70.08 | CS38: =ROUND((ROUND((AE38*AV38*1),2)*BS38),2) -> 8.89 | CT38: =ROUND((ROUND((AF38*AV38*1),2)*BA38),2) -> 574.04 | CU38: =AG38 -> 0 | CV38: =(AH38*AV38) -> 45.486744 | CW38: =AI38 -> 0 | CX38: =AJ38 -> 0 | CY38: =(((S38+R38)*AT38)/100) -> 0 | CZ38: =(((S38+R38)*AU38)/100) -> 0 | DB38: 5 | DE38: *1,25)*1,1 | DF38: *1,25)*1,1 | DG38: *1,15)*1,1 | DI38: *1,15)*1,1 | DJ38: *1,25)*1,1 | DN38: 0 | DO38: 0 | DP38: 1 | DQ38: 1 | DU38: 1013 | DV38: 100 м трубопровода | DW38: 100 м трубопровода | DX38: 1 | EE38: 58807897 | EF38: 30 | EG38: Строительные работы | EH38: 0 | EJ38: 1 | EK38: 21 | EL38: ТСН-2001.3-16. Трубопроводы внутренние | EM38: ТСН-2001.3-16-1 | EO38: Поправка: О.П. п.3.4. 6 Поправка: О.П. п.3.4.30.в | EQ38: 1024 | ER38: 517.64 | ES38: 44.58 | ET38: 47.77 | EU38: 6.06 | EV38: 425.29 | EW38: 33.7 | EX38: 0 | EY38: 0 | FQ38: 0 | FR38: 0 | FS38: 0 | FX38: 109 | FY38: 61 | GD38: 1 | GF38: 568000979 | GG38: 2 | GH38: 1 | GI38: 2 | GJ38: 0 | GK38: 0 | GL38: =ROUND(IF(AND(BH38=3,BI38=3,FS38<>0),P38,0),2) -> 0 | GM38: =ROUND(O38+X38+Y38,2)+GX38 -> 0 | GN38: =IF(OR(BI38=0,BI38=1),GM38-GX38,0) -> 0 | GO38: =IF(BI38=2,GM38-GX38,0) -> 0 | GP38: =IF(BI38=4,GM38-GX38,0) -> 0 | GR38: 0 | GS38: 3 | GT38: 0 | GV38: =ROUND((GT38),6) -> 0 | GW38: 1 | GX38: =ROUND(HC38*I38,2) -> 0 | HA38: 0 | HB38: 0 | HC38: =GV38*GW38 -> 0 | HS38: 0 | IK38: 0
A39: 17 | B39: 1 | C39: =ROW(SmtRes!A56) -> 56 | D39: =ROW(EtalonRes!A52) -> 52 | F39: 3.16-7-1 | G39: Прокладка трубопроводов водоснабжения из стальных водогазопроводных оцинкованных труб диаметром 15 мм | H39: 100 м трубопровода | I39: =ROUND(ROUND(18/100,4)*0,9) -> 0 | J39: 0 | K39: =ROUND(ROUND(18/100,4)*0,9) -> 0 | O39: =ROUND(CP39,2) -> 0 | P39: =ROUND((ROUND((AC39*AW39*I39),2)*BC39),2) -> 0 | Q39: =(ROUND((ROUND(((((ET39*1.25)*1.1))*AV39*I39),2)*BB39),2)+ROUND((ROUND(((AE39-(((EU39*1.25)*1.1)))*AV39*I39),2)*BS39),2)) -> 0 | R39: =ROUND((ROUND((AE39*AV39*I39),2)*BS39),2) -> 0 | S39: =ROUND((ROUND((AF39*AV39*I39),2)*BA39),2) -> 0 | T39: =ROUND(CU39*I39,2) -> 0 | U39: =CV39*I39 -> 0 | V39: =CW39*I39 -> 0 | W39: =ROUND(CX39*I39,2) -> 0 | X39: =ROUND(CY39,2) -> 0 | Y39: =ROUND(CZ39,2) -> 0 | AA39: -1 | AB39: =ROUND((AC39+AD39+AF39),6) -> 648.2556 | AC39: =ROUND((ES39),6) -> 44.58 | AD39: =ROUND((((((ET39*1.25)*1.1))-(((EU39*1.25)*1.1)))+AE39),6) -> 65.68375 | AE39: =ROUND((((EU39*1.25)*1.1)),6) -> 8.3325 | AF39: =ROUND((((EV39*1.15)*1.1)),6) -> 537.99185 | AG39: =ROUND((AP39),6) -> 0 | AH39: =(((EW39*1.15)*1.1)) -> 42.6305 | AI39: =(((EX39*1.25)*1.1)) -> 0 | AJ39: =(AS39) -> 0 | AK39: 517.64 | AL39: 44.58 | AM39: 47.77 | AN39: 6.06 | AO39: 425.29 | AP39: 0 | AQ39: 33.7 | AR39: 0 | AS39: 0 | AT39: 109 | AU39: 61 | AV39: 1.067 | AW39: 1 | AZ39: 1 | BA39: 54.99 | BB39: 15.37 | BC39: 6.15 | BH39: 0 | BI39: 1 | BJ39: ТСН-2001.3 Доп. 79, Сб. 16, т. 7, поз. 1 | BM39: 21 | BN39: 0 | BO39: 3.16-7-1 | BP39: 1 | BQ39: 30 | BR39: 0 | BS39: 54.99 | BT39: 1 | BU39: 1 | BV39: 1 | BW39: 1 | BX39: 1 | BZ39: 109 | CA39: 61 | CE39: 30 | CF39: 0 | CG39: 0 | CM39: 0 | CN39: Поправка: О.П. п.3.4. 6 Наименование: Выполняемые при ремонте и реконструкции работы аналогичные технологическим процессам, характерным для нового строительства и отсутствующим в сборниках на ремонтно-строительные работы Поправка: О.П. п.3.4.30.в Наименование: При применении территориальных сметных нормативов для города Москвы затраты, учитывающие напряженные и стесненные условия производства работ (стесненность, сложность складирования и транспортной логистики и т.п.), исчисляются с применением коэффициентов к затратам труда и заработной плате рабочих, машинистов, времени эксплуатации машин и механизмов, стоимости эксплуатации машин в размере: для объектов, расположенных за пределами Третьего транспортного кольца города Москвы, но в пределах Московской кольцевой автомобильной дороги | CO39: 0 | CP39: =(P39+Q39+S39) -> 0 | CQ39: =ROUND((ROUND((AC39*AW39*1),2)*BC39),2) -> 274.17 | CR39: =(ROUND((ROUND(((((ET39*1.25)*1.1))*AV39*1),2)*BB39),2)+ROUND((ROUND(((AE39-(((EU39*1.25)*1.1)))*AV39*1),2)*BS39),2)) -> 1077.13 | CS39: =ROUND((ROUND((AE39*AV39*1),2)*BS39),2) -> 488.86 | CT39: =ROUND((ROUND((AF39*AV39*1),2)*BA39),2) -> 31566.46 | CU39: =AG39 -> 0 | CV39: =(AH39*AV39) -> 45.486744 | CW39: =AI39 -> 0 | CX39: =AJ39 -> 0 | CY39: =(((S39+R39)*AT39)/100) -> 0 | CZ39: =(((S39+R39)*AU39)/100) -> 0 | DB39: 7 | DE39: *1,25)*1,1 | DF39: *1,25)*1,1 | DG39: *1,15)*1,1 | DI39: *1,15)*1,1 | DJ39: *1,25)*1,1 | DN39: 0 | DO39: 0 | DP39: 1 | DQ39: 1 | DU39: 1013 | DV39: 100 м трубопровода | DW39: 100 м трубопровода | DX39: 1 | EE39: 58807897 | EF39: 30 | EG39: Строительные работы | EH39: 0 | EJ39: 1 | EK39: 21 | EL39: ТСН-2001.3-16. Трубопроводы внутренние | EM39: ТСН-2001.3-16-1 | EO39: Поправка: О.П. п.3.4. 6 Поправка: О.П. п.3.4.30.в | EQ39: 1024 | ER39: 517.64 | ES39: 44.58 | ET39: 47.77 | EU39: 6.06 | EV39: 425.29 | EW39: 33.7 | EX39: 0 | EY39: 0 | FQ39: 0 | FR39: 0 | FS39: 0 | FX39: 109 | FY39: 61 | GD39: 1 | GF39: 568000979 | GG39: 2 | GH39: 1 | GI39: 2 | GJ39: 0 | GK39: 0 | GL39: =ROUND(IF(AND(BH39=3,BI39=3,FS39<>0),P39,0),2) -> 0 | GM39: =ROUND(O39+X39+Y39,2)+GX39 -> 0 | GN39: =IF(OR(BI39=0,BI39=1),GM39-GX39,0) -> 0 | GO39: =IF(BI39=2,GM39-GX39,0) -> 0 | GP39: =IF(BI39=4,GM39-GX39,0) -> 0 | GR39: 0 | GS39: 3 | GT39: 0 | GV39: =ROUND((GT39),6) -> 0 | GW39: 1 | GX39: =ROUND(HC39*I39,2) -> 0 | HA39: 0 | HB39: 0 | HC39: =GV39*GW39 -> 0 | HS39: 0 | IK39: 0
