Workbook

Sheet 02-01-22
A1: =Source!B1 -> Smeta.RU (495) 974-1589
J2: Форма № 4б
A3: Капитальный ремонт здания Государственного бюджетного общеобразовательного учреждения города Москвы «Школа № 236» по адресу: г. Москва, ул. Клязьминская, д. 7, к. 4. I этап | AP3: Капитальный ремонт здания Государственного бюджетного общеобразовательного учреждения города Москвы «Школа № 236» по адресу: г. Москва, ул. Клязьминская, д. 7, к. 4. I этап. 02-01-22 Мероприятия по обеспечению доступа инвалидов
A4: (наименование стройки и/или объекта)
A6: =CONCATENATE( "ЛОКАЛЬНАЯ СМЕТА № ",IF(Source!F20<>"Новая локальная смета", Source!F20, "")) -> ЛОКАЛЬНАЯ СМЕТА № 02-01-22
A8: =IF(Source!G20<>"Новая локальная смета", Source!G20, "") -> Мероприятия по обеспечению доступа инвалидов
A9: (наименование работ и затрат)
A11: =CONCATENATE( "Основание: чертежи № ", Source!J20) -> Основание: чертежи № 2024-00272-01-0-ОДИ.ВОР
I13: В базисном уровне цен | J13: В текущем уровне цен
E14: Сметная стоимость | I14: =I15+I16+I17+I19 -> 77.72 | J14: =J15+J16+J17+J19 -> 695.23 | K14: тыс.руб.
E15: Строительные работы | I15: =ROUND((Source!F480)/1000, 2) -> 42.72 | J15: =ROUND((Source!P480)/1000, 2) -> 516.2 | K15: тыс.руб.
E16: Работы по монтажу оборудования | I16: =ROUND((Source!F481)/1000, 2) -> 0 | J16: =ROUND((Source!P481)/1000, 2) -> 0 | K16: тыс.руб.
E17: Оборудование | I17: =ROUND((Source!F472)/1000, 2) -> 35 | J17: =ROUND((Source!P472)/1000, 2) -> 179.03 | K17: тыс.руб.
E18: В т.ч. оборудование не облагаемое НДС | I18: 19.80483 | J18: 62.665 | K18: тыс.руб.
E19: Прочие работы и затраты | I19: =ROUND((Source!F482+Source!F483)/1000, 2) -> 0 | J19: =ROUND((Source!P482+Source!P483)/1000, 2) -> 0 | K19: тыс.руб.
E20: Средства на оплату труда | I20: =(Source!F478+ Source!F477)/1000 -> 1.50994 | J20: =((Source!P478 + Source!P477)/1000) -> 83.03159 | K20: тыс.руб.
E21: Затраты труда | I21: =Source!F485 -> 97.728297 | K21: чел.-ч.
E22: Кроме того:
E23: Возврат материалов | I23: =SUM(Y29:Y450)/1000 -> 0 | J23: =SUM(Z29:Z450)/1000 -> 0 | K23: тыс.руб.
A25: Составлен(а) по ТСН-2001 с учетом Дополнения №: 80
A26: № и период сборника коэффициентов (индексов) пересчета: Коэффициенты к ТСН-2001 МГЭ Дополнение 80, ремонт №217/80 III квартал 2025 года и Коэффициенты к ТСН-2001.13-2 Дополнение 46 №62/46 III квартал 2025 года | AP26: № и период сборника коэффициентов (индексов) пересчета: Коэффициенты к ТСН-2001 МГЭ Дополнение 80, ремонт №217/80 III квартал 2025 года и Коэффициенты к ТСН-2001.13-2 Дополнение 46 №62/46 III квартал 2025 года
A27: № п/п | B27: Шифр расценки и коды ресурсов | C27: Наименование работ и затрат | D27: Ед. изм. | E27: Кол-во единиц | F27: Цена на ед. изм., руб. | G27: Попра- вочные коэффи- циенты | H27: Коэффи- циенты зимних удорожа- ний | I27: Всего в ценах на январь 2000 года, руб. | J27: Коэффи- циенты (индек- сы) пере- счета, нормы НР и СП | K27: ВСЕГО затрат в текущем уровне цен, руб.
A28: 1 | B28: 2 | C28: 3 | D28: 4 | E28: 5 | F28: 6 | G28: 7 | H28: 8 | I28: 9 | J28: 10 | K28: 11
A30: =CONCATENATE("Раздел: ",IF(Source!G24<>"Новый раздел", Source!G24, "")) -> Раздел: Оборудование санузла для МГН
A31: 1 | B31: 3.17-2-14 Поправка: Гл.12.Прил.8.п.8. 5_12.00.01.11.003 Поправка: Гл.6.Прил.2.2.п.2.2.6_06.00.01.07.001 | C31: Установка гарнитуры туалетной: поручней для ванн | D31: =Source!H28 -> 100 шт. | E31: =Source!I28 -> 0.05 | Q31: =Source!X28 -> 13.93 | R31: =Source!X29 -> 766.02 | S31: =Source!Y28 -> 7.8 | T31: =Source!Y29 -> 428.69 | U31: =ROUND((175/100)*ROUND(Source!R28, 2), 2) -> 0.07 | V31: =ROUND((0/100)*ROUND(Source!R29, 2), 2) -> 0 | AC31: 0
C32: ="Объем: "&Source!I28&"=(1+"&"1+"&"1+"&"1+"&"1)/"&"100" -> Объем: 0,05=(1+1+1+1+1)/100
C33: ЗП | F33: =Source!AO28 -> 188.72 | G33: =Source!DG28 -> *1,1)*1,15 | H33: =Source!AV29 -> 1.067 | I33: =Source!S28 -> 12.74 | J33: =IF(Source!BA29<> 0, Source!BA29, 1) -> 54.99 | K33: =Source!S29 -> 700.57
C34: ЭМ | F34: =Source!AM28 -> 7.54 | G34: =Source!DE28 -> *1,1)*1,25 | H34: =Source!AV29 -> 1.067 | I34: =Source!Q28 -> 0.55 | J34: =IF(Source!BB29<> 0, Source!BB29, 1) -> 12.07 | K34: =Source!Q29 -> 6.64
C35: в т.ч. ЗПМ | F35: =Source!AN28 -> 0.5 | G35: =Source!DF28 -> *1,1)*1,25 | H35: =Source!AV29 -> 1.067 | I35: =Source!R28 -> 0.04 | J35: =IF(Source!BS29<> 0, Source!BS29, 1) -> 54.99 | K35: =Source!R29 -> 2.2
C36: МР | F36: =Source!AL28 -> 5229.82 | G36: =Source!DD28 -> *1)*1 | H36: =Source!AW29 -> 1 | I36: =Source!P28 -> 261.49 | J36: =IF(Source!BC29<> 0, Source!BC29, 1) -> 0.75 | K36: =Source!P29 -> 196.12
C37: НР от ФОТ | D37: % | E37: =Source!BZ29 -> 109 | I37: =SUM(Q31:Q36) -> 13.93 | J37: =Source!AT29 -> 109 | K37: =SUM(R31:R36) -> 766.02
C38: СП от ФОТ | D38: % | E38: =Source!CA29 -> 61 | I38: =SUM(S31:S37) -> 7.8 | J38: =Source!AU29 -> 61 | K38: =SUM(T31:T37) -> 428.69
C39: ЗТР | D39: чел-ч | E39: =Source!AQ28 -> 16.89 | G39: =Source!DI28 -> *1,1)*1,15 | H39: =Source!AV29 -> 1.067 | I39: =Source!U28 -> 1.1398681
C40: ВСЕГО работ по позиции: | H40: =I33+I34+I36+I37+I38+0-0-0 -> 296.51 | J40: =K33+K34+K36+K37+K38+0-0-0 -> 2098.04
C41: ВСЕГО оборудование по позиции: | H41: =0+0 -> 0 | J41: =0+0 -> 0
C42: ВСЕГО по позиции: | H42: =I33+I34+I36+I37+I38+0 -> 296.51 | J42: =K33+K34+K36+K37+K38+0 -> 2098.04 | O42: =I33+I34+I36+I37+I38+0 -> 296.51 | P42: =K33+K34+K36+K37+K38+0 -> 2098.04
A44: 2 | B44: 3.17-2-13 Поправка: Гл.12.Прил.8.п.8. 5_12.00.01.11.003 Поправка: Гл.6.Прил.2.2.п.2.2.6_06.00.01.07.001 | C44: Установка гарнитуры туалетной: вешалок, подстаканников, дозаторов настенных и т.п./ крючки | D44: =Source!H30 -> 100 шт. | E44: =Source!I30 -> 0.02 | Q44: =Source!X30 -> 2.84 | R44: =Source!X31 -> 156.44 | S44: =Source!Y30 -> 1.59 | T44: =Source!Y31 -> 87.55 | U44: =ROUND((175/100)*ROUND(Source!R30, 2), 2) -> 0.05 | V44: =ROUND((0/100)*ROUND(Source!R31, 2), 2) -> 0 | AC44: 0
C45: ="Объем: "&Source!I30&"=2/"&"100" -> Объем: 0,02=2/100
C46: ЗП | F46: =Source!AO30 -> 95.59 | G46: =Source!DG30 -> *1,1)*1,15 | H46: =Source!AV31 -> 1.067 | I46: =Source!S30 -> 2.58 | J46: =IF(Source!BA31<> 0, Source!BA31, 1) -> 54.99 | K46: =Source!S31 -> 141.87
C47: ЭМ | F47: =Source!AM30 -> 8.97 | G47: =Source!DE30 -> *1,1)*1,25 | H47: =Source!AV31 -> 1.067 | I47: =Source!Q30 -> 0.26 | J47: =IF(Source!BB31<> 0, Source!BB31, 1) -> 14.34 | K47: =Source!Q31 -> 3.73
...

Sheet 02-01-22_1
A1: =Source!B1 -> Smeta.RU (495) 974-1589
E3: "УТВЕРЖДАЮ"
D5: ___________________________
D7: ___________________________
D9: " ___ " ___________ 20 ___ г.
B12: =CONCATENATE("Ведомость объемов работ ", IF(Source!AN15<>"", Source!AN15," ")) -> Ведомость объемов работ
B13: =CONCATENATE(Source!F12, " ", Source!G12) -> 02-01-22 02-01-22 Мероприятия по обеспечению доступа инвалидов
B14: =CONCATENATE(Source!F20, " ", Source!G20) -> 02-01-22 Мероприятия по обеспечению доступа инвалидов
A16: № п/п | B16: № в ЛСР | C16: Наименование работ и затрат | D16: Единица измерения | E16: Количество | F16: Ссылка на чертежи, спецификации | G16: Формула расчета, расчет объемов работ и расхода материалов | H16: Примечание
A17: 1 | B17: 2 | C17: 3 | D17: 4 | E17: 5 | F17: 6 | G17: 7 | H17: 8
A18: =CONCATENATE("Раздел: ", Source!G24) -> Раздел: Оборудование санузла для МГН
A19: 1 | B19: =Source!E28 -> 1 | C19: =Source!G28 -> Установка гарнитуры туалетной: поручней для ванн | D19: 100 шт. | E19: =Source!I28 -> 0.05 | F19: =Source!U24 | G19: ="=(1+"&"1+"&"1+"&"1+"&"1)/"&"100" -> =(1+1+1+1+1)/100
A20: 2 | B20: =Source!E30 -> 2 | C20: =Source!G30 -> Установка гарнитуры туалетной: вешалок, подстаканников, дозаторов настенных и т.п./ крючки | D20: 100 шт. | E20: =Source!I30 -> 0.02 | F20: =Source!U24 | G20: ="=2/"&"100" -> =2/100
A21: 3 | B21: =Source!E32 -> 3 | C21: =Source!G32 -> Установка гарнитуры туалетной полочек/зеркало | D21: 1 ШТ. | E21: =Source!I32 -> 1 | F21: =Source!U24 | G21: =Source!I32 -> 1
A22: 4 | B22: =Source!E34 -> 4 | C22: =Source!G34 -> Установка гарнитуры туалетной: вешалок, подстаканников, дозаторов настенных и т.п./диспенсер | D22: 100 шт. | E22: =Source!I34 -> 0.03 | F22: =Source!U24 | G22: ="=3/"&"100" -> =3/100
A23: 5 | B23: =Source!E36 -> 5 | C23: =Source!G36 -> Установка гарнитуры туалетной: вешалок, подстаканников, дозаторов настенных и т.п./ туалетный ершик с креплением на стену | D23: 100 шт. | E23: =Source!I36 -> 0.01 | F23: =Source!U24 | G23: ="=1/"&"100" -> =1/100
A24: =CONCATENATE("Раздел: ", Source!G69) -> Раздел: Оборудование, не облагаемое НДС
A25: 6 | B25: =Source!E73 -> 6 | C25: =Source!G73 -> Поручень реабилитационный откидной для установки около унитаза, габаритные размеры 700х700 мм. Материал сталь нержавеющая с полировкой, крепление к стене в трех точках, в комплекте: прокладки-амортизаторы резиновые, крепежные элементы | D25: КОМПЛЕКТ | E25: =Source!I73 -> 1 | F25: =Source!U69 | G25: =Source!I73 -> 1
A26: 7 | B26: =Source!E75 -> 7 | C26: =Source!G75 -> Поручень реабилитационный настенный, угловой, габаритные размеры 700х700 мм/ 600х600 мм | D26: КОМПЛЕКТ | E26: =Source!I75 -> 2 | F26: =Source!U69 | G26: ="=1+"&"1" -> =1+1
A27: 8 | B27: =Source!E77 -> 8 | C27: =Source!G77 -> Поручень реабилитационный настенный, габаритные размеры 1500х90 мм/ 1200х120 мм | D27: КОМПЛЕКТ | E27: =Source!I77 -> 1 | F27: =Source!U69 | G27: =Source!I77 -> 1
A28: 9 | B28: =Source!E79 -> 9 | C28: =Source!G79 -> Поручень реабилитационный односекционный, для установки около умывальника, габаритные размеры 700х260 мм/ настенно-напольный 850х196х600 мм | D28: КОМПЛЕКТ | E28: =Source!I79 -> 1 | F28: =Source!U69 | G28: =Source!I79 -> 1
A29: 10 | B29: =Source!E81 -> 10 | C29: =Source!G81 -> Крючок для подвески костылей, габаритные размеры 120х32 мм. Материал сталь нержавеющая с полировкой, крепление на стену, в комплекте: прокладки-амортизаторы резиновые, крепежные элементы | D29: КОМПЛЕКТ | E29: =Source!I81 -> 1 | F29: =Source!U69 | G29: =Source!I81 -> 1
A30: =CONCATENATE("Раздел: ", Source!G114) -> Раздел: Оборудование, облагаемое НДС
A31: 11 | B31: =Source!E118 -> 11 | C31: =Source!G118 -> Зеркало поворотное с ручкой управления, какркас из нержавеющей стали AISI 304, арт. 80035 | D31: шт. | E31: =Source!I118 -> 1 | F31: =Source!U114 | G31: =Source!I118 -> 1
A32: 12 | B32: =Source!E120 -> 12 | C32: =Source!G120 -> Корзина металлическая для мусора Tork Image Design B1, 50 л, без крышки, стальная, Артикул:460011 | D32: шт. | E32: =Source!I120 -> 1 | F32: =Source!U114 | G32: =Source!I120 -> 1
A33: 13 | B33: =Source!E122 -> 13 | C33: =Source!G122 -> Диспенсер настенный для бумажных полотенец, 325х245х109 мм, цвет: глянцевый хром, корпус из нержавеющей стали AISI 304 толщиной 1,2 мм. Типа 04046.В | D33: шт. | E33: =Source!I122 -> 1 | F33: =Source!U114 | G33: =Source!I122 -> 1
A34: 14 | B34: =Source!E124 -> 14 | C34: =Source!G124 -> Диспенсер для жидкого мыла сенсорный автоматический, 275х105х95 мм, цвет: глянцевый хром, корпус из нержавеющей стали AISI 304 толщиной 1,0 мм. Типа 03039.B | D34: шт. | E34: =Source!I124 -> 1 | F34: =Source!U114 | G34: =Source!I124 -> 1
A35: 15 | B35: =Source!E126 -> 15 | C35: =Source!G126 -> Диспенсер для туалетной бумаги, 260х112х260 мм, цвет: глянцевый хром, корпус изнержавеющей стали AISI 304 толщиной 1,0 мм. Типа 05006.B | D35: шт. | E35: =Source!I126 -> 1 | F35: =Source!U114 | G35: =Source!I126 -> 1
A36: 16 | B36: =Source!E128 -> 16 | C36: =Source!G128 -> Ершик туалетный с креплением на стену NIZA 16857.S | D36: шт. | E36: =Source!I128 -> 1 | F36: =Source!U114 | G36: =Source!I128 -> 1
A37: =CONCATENATE("Раздел: ", Source!G161) -> Раздел: Информационно-тактильные знаки
A38: 17 | B38: =Source!E165 -> 17 | C38: =Source!G165 -> Установка номерных табличек для этажа, подъезда/ Эвакуационный знак E01-01 (левосторонний), Эвакуационный знак E01-02 (правосторонний) | D38: 1 ШТ. | E38: =Source!I165 -> 6 | F38: =Source!U161 | G38: =Source!I165 -> 6
A39: 17.1 | B39: =Source!E167 -> 17,1 | C39: =Source!G167 -> Знак безопасности и эвакуационный указатель, из пластика с фотолюминесцентным покрытием, размер 200х200 мм | D39: шт. | E39: =Source!I167 -> 6 | F39: =Source!U161
A40: 18 | B40: =Source!E169 -> 18 | C40: =Source!G169 -> Установка номерных табличек для этажа, подъезда/Эвакуационный знак E02-01, "Направляющая стрелка" | D40: 1 ШТ. | E40: =Source!I169 -> 6 | F40: =Source!U161 | G40: =Source!I169 -> 6
A41: 18.1 | B41: =Source!E171 -> 18,1 | C41: =Source!G171 -> Знак безопасности и эвакуационный указатель, из пластика с фотолюминесцентным покрытием, размер 200х200 мм | D41: шт. | E41: =Source!I171 -> 6 | F41: =Source!U161
A42: 19 | B42: =Source!E173 -> 19 | C42: =Source!G173 -> Установка номерных табличек для этажа, подъезда/Эвакуационный знак E13 Направление к эвакуационному выходу по лестнице вниз (правосторонний), Е14 Направление к эвакуационному выходу по лестнице вниз (левосторонний) | D42: 1 ШТ. | E42: =Source!I173 -> 4 | F42: =Source!U161 | G42: =Source!I173 -> 4
A43: 19.1 | B43: =Source!E175 -> 19,1 | C43: =Source!G175 -> Знак безопасности и эвакуационный указатель, из пластика с фотолюминесцентным покрытием, размер 200х200 мм | D43: шт. | E43: =Source!I175 -> 4 | F43: =Source!U161
A44: 20 | B44: =Source!E177 -> 20 | C44: =Source!G177 -> Установка номерных табличек для этажа, подъезда/Эвакуационный знак E22,"Указатель выхода" | D44: 1 ШТ. | E44: =Source!I177 -> 21 | F44: =Source!U161 | G44: =Source!I177 -> 21
A45: 20.1 | B45: =Source!E179 -> 20,1 | C45: =Source!G179 -> Знак безопасности и эвакуационный указатель, из пластика с фотолюминесцентным покрытием, размер 200х200 мм | D45: шт. | E45: =Source!I179 -> 21 | F45: =Source!U161
A46: 21 | B46: =Source!E181 -> 21 | C46: =Source!G181 -> Установка номерных табличек для этажа, подъезда | D46: 1 ШТ. | E46: =Source!I181 -> 4 | F46: =Source!U161 | G46: =Source!I181 -> 4
A47: 21.1 | B47: =Source!E183 -> 21,1 | C47: =Source!G183 -> Тактильный знак СП 01, 150х150 мм "Доступность для инвалидов всех категорий" арт. 902-0-SP-18-150 | D47: шт. | E47: =Source!I183 -> 4 | F47: =Source!U161
...

Sheet Source
A1: 0 | B1: Smeta.RU (495) 974-1589 | D1: _PS_ | F1: 0 | G1: 0 | H1: 0 | I1: Smeta.RU | K1: 1 | L1: 74561 | M1: 10 | N1: 12 | O1: 0 | P1: 0 | Q1: 3
A4: 1 | B4: 1 | C4: -1 | G4: Капитальный ремонт здания Государственного бюджетного общеобразовательного учреждения города Москвы «Школа № 236» по адресу: г. Москва, ул. Клязьминская, д. 7, к. 4. I этап | EC4: 0
A12: 1 | B12: 534 | C12: 0 | D12: =ROW(A493) -> 493 | E12: 0 | F12: 02-01-22 | G12: 02-01-22 Мероприятия по обеспечению доступа инвалидов | I12: 0 | J12: 2024-00272-01-0-ОДИ.ВОР | K12: 0 | L12: 0 | M12: 4098 | O12: 0 | P12: 0 | Q12: 0 | R12: 0 | S12: 0 | T12: 1 | V12: 0 | AB12: Борисова Е.С. | BB12: 0 | BH12: Сметные нормы списания | BI12: Коды ОКП для ТСН-2001 МГЭ Дополнение 80 | BJ12: 1 | BK12: 1 | BL12: 0 | BM12: 0 | BN12: 1 | BO12: 0 | BP12: 6 | BQ12: 2 | BR12: 1 | BS12: 0 | BT12: 0 | BU12: 0 | BV12: 0 | BW12: 0 | BX12: 0 | BZ12: Типовой расчет для ТСН-2001 МГЭ, Дополнение 80, ремонт | CA12: Территориальные сметные нормативы для Москвы ТСН-2001 (МГЭ), дополнение 80 | CB12: Территориальные сметные нормативы для Москвы ТСН-2001 (МГЭ), дополнение 80 | CC12: Территориальные сметные нормативы для Москвы ТСН-2001 (МГЭ), дополнение 80 | CD12: Территориальные сметные нормативы для Москвы ТСН-2001 (МГЭ), дополнение 80 | CE12: Поправки для ТСН-2001 от 03.02.2026 г. доп.80 | CF12: 0 | CG12: 0 | CH12: 8 | CK12: 80 | CQ12: Территориальные сметные нормативы для Москвы (ТСН-2001) | CR12: ТЕР | CS12: 41660 | CT12: 1 | CU12: 80 | CY12: 0 | EC12: 0
A15: 15 | B15: 1
A18: 52 | B18: =B493 -> 534 | C18: =C493 -> 1 | D18: =D493 -> 12 | E18: =E493 -> 0 | F18: =F493 -> 02-01-22 | G18: =G493 -> 02-01-22 Мероприятия по обеспечению доступа инвалидов | O18: =O493 -> 75620.22 | P18: =P493 -> 74094.28 | Q18: =Q493 -> 17.6 | R18: =R493 -> 1.6 | S18: =S493 -> 1508.34 | T18: =T493 -> 0 | U18: =U493 -> 97.728297 | V18: =V493 -> 0 | ... GX18: =GX493 -> 0
A20: 3 | B20: 1 | D20: =ROW(A463) -> 463 | F20: 02-01-22 | G20: Мероприятия по обеспечению доступа инвалидов | I20: 0 | J20: 2024-00272-01-0-ОДИ.ВОР | K20: -1 | L20: 02-01-22 | S20: 0 | T20: 0 | V20: 2 | BX20: 0 | CF20: 0 | CG20: 0
A22: 52 | B22: =B463 -> 1 | C22: =C463 -> 3 | D22: =D463 -> 20 | E22: =E463 -> 0 | F22: =F463 -> 02-01-22 | G22: =G463 -> Мероприятия по обеспечению доступа инвалидов | O22: =O463 -> 75620.22 | P22: =P463 -> 74094.28 | Q22: =Q463 -> 17.6 | R22: =R463 -> 1.6 | S22: =S463 -> 1508.34 | T22: =T463 -> 0 | U22: =U463 -> 97.728297 | V22: =V463 -> 0 | ... GX22: =GX463 -> 0
A24: 4 | B24: 1 | D24: =ROW(A39) -> 39 | G24: Оборудование санузла для МГН | I24: 0 | K24: -1 | S24: 0 | T24: 0 | V24: 2 | BX24: 0 | CJ24: 0
A26: 52 | B26: =B39 -> 1 | C26: =C39 -> 4 | D26: =D39 -> 24 | E26: =E39 -> 0 | F26: =F39 | G26: =G39 -> Оборудование санузла для МГН | O26: =O39 -> 426.47 | P26: =P39 -> 393.93 | Q26: =Q39 -> 1.33 | R26: =R39 -> 0.12 | S26: =S39 -> 31.21 | T26: =T39 -> 0 | U26: =U39 -> 2.6850676 | V26: =V39 -> 0 | ... GX26: =GX39 -> 0
A28: 17 | B28: 1 | E28: 1 | F28: 3.17-2-14 | G28: Установка гарнитуры туалетной: поручней для ванн | H28: 100 шт. | I28: =ROUND((1+1+1+1+1)/100,9) -> 0.05 | J28: 0 | K28: =ROUND((1+1+1+1+1)/100,9) -> 0.05 | O28: =ROUND(CP28,2) -> 274.78 | P28: =ROUND((ROUND((AC28*AW28*I28),2)*BC28),2) -> 261.49 | Q28: =(ROUND((ROUND(((((ET28*1.1)*1.25))*AV28*I28),2)*BB28),2)+ROUND((ROUND(((AE28-(((EU28*1.1)*1.25)))*AV28*I28),2)*BS28),2)) -> 0.55 | R28: =(ROUND((ROUND(((((EU28*1.1)*1.25))*AV28*I28),2)*BS28),2)+ROUND((ROUND(((AE28-(((EU28*1.1)*1.25)))*AV28*I28),2)*BS28),2)) -> 0.04 | S28: =ROUND((ROUND((AF28*AV28*I28),2)*BA28),2) -> 12.74 | T28: =ROUND(CU28*I28,2) -> 0 | U28: =CV28*I28 -> 1.1398681 | V28: =CW28*I28 -> 0 | W28: =ROUND(CX28*I28,2) -> 0 | X28: =(ROUND((((S28+ROUND((ROUND(((((EU28*1.1)*1.25))*AV28*I28),2)*BS28),2))*AT28)/100),2)+ROUND(((ROUND((ROUND(((AE28-(((EU28*1.1)*1.25)))*AV28*I28),2)*BS28),2)*AT28)/100),2)) -> 13.93 | Y28: =(ROUND((((S28+ROUND((ROUND(((((EU28*1.1)*1.25))*AV28*I28),2)*BS28),2))*AU28)/100),2)+ROUND(((ROUND((ROUND(((AE28-(((EU28*1.1)*1.25)))*AV28*I28),2)*BS28),2)*AU28)/100),2)) -> 7.8 | AA28: 59499218 | AB28: =ROUND((AC28+AD28+AF28),6) -> 5478.9183 | AC28: =ROUND((((ES28*1)*1)),6) -> 5229.82 | AD28: =ROUND((((((ET28*1.1)*1.25))-(((EU28*1.1)*1.25)))+AE28),6) -> 10.3675 | AE28: =ROUND((((EU28*1.1)*1.25)),6) -> 0.6875 | AF28: =ROUND((((EV28*1.1)*1.15)),6) -> 238.7308 | AG28: =ROUND((AP28),6) -> 0 | AH28: =(((EW28*1.1)*1.15)) -> 21.36585 | AI28: =(((EX28*1.1)*1.25)) -> 0 | AJ28: =(AS28) -> 0 | AK28: 5426.08 | AL28: 5229.82 | AM28: 7.54 | AN28: 0.5 | AO28: 188.72 | AP28: 0 | AQ28: 16.89 | AR28: 0 | AS28: 0 | AT28: 109 | AU28: 61 | AV28: 1.067 | AW28: 1 | AZ28: 1 | BA28: 1 | BB28: 1 | BC28: 1 | BH28: 0 | BI28: 1 | BJ28: ТСН-2001.3 Доп. 80, Сб. 17, т. 2, поз. 14 | BM28: 22 | BN28: 0 | BO28: 3.17-2-14 | BP28: 1 | BQ28: 30 | BR28: 0 | BS28: 1 | BT28: 1 | BU28: 1 | BV28: 1 | BW28: 1 | BX28: 1 | BZ28: 109 | CA28: 61 | CE28: 1566 | CF28: 0 | CG28: 0 | CM28: 0 | CN28: Поправка: Гл.12.Прил.8.п.8. 5_12.00.01.11.003 Наименование: При наличии усложненных условий производства работ (стесненность, сложность складирования и транспортной логистики, наличие в зоне производства работ действующего технологического оборудования или движения технологического транспорта и т.п.) для объектов, расположенных за пределами территории круговой магистральной системы улиц "Садовое кольцо" и за пределами Третьего транспортного кольца города Москвы пунктов "а" и "б", но в пределах Московской кольцевой автомобильной дороги Поправка: Гл.6.Прил.2.2.п.2.2.6_06.00.01.07.001 Наименование: При выполнении при капитальном ремонте и реконструкции работ, аналогичных технологическим процессам, характерным для нового строительства, и отсутствующих в сборниках на ремонтно-строительные работы ТСН-2001.6 | CO28: 0 | CP28: =(P28+Q28+S28) -> 274.78 | CQ28: =ROUND((ROUND((AC28*AW28*1),2)*BC28),2) -> 5229.82 | CR28: =(ROUND((ROUND(((((ET28*1.1)*1.25))*AV28*1),2)*BB28),2)+ROUND((ROUND(((AE28-(((EU28*1.1)*1.25)))*AV28*1),2)*BS28),2)) -> 11.06 | CS28: =(ROUND((ROUND(((((EU28*1.1)*1.25))*AV28*1),2)*BS28),2)+ROUND((ROUND(((AE28-(((EU28*1.1)*1.25)))*AV28*1),2)*BS28),2)) -> 0.73 | CT28: =ROUND((ROUND((AF28*AV28*1),2)*BA28),2) -> 254.73 | CU28: =AG28 -> 0 | CV28: =(AH28*AV28) -> 22.797362 | CW28: =AI28 -> 0 | CX28: =AJ28 -> 0 | CY28: =(ROUND((((S28+ROUND((ROUND(((((EU28*1.1)*1.25))*AV28*1),2)*BS28),2))*AT28)/100),2)+ROUND(((ROUND((ROUND(((AE28-(((EU28*1.1)*1.25)))*AV28*1),2)*BS28),2)*AT28)/100),2)) -> 14.68 | CZ28: =(ROUND((((S28+ROUND((ROUND(((((EU28*1.1)*1.25))*AV28*1),2)*BS28),2))*AU28)/100),2)+ROUND(((ROUND((ROUND(((AE28-(((EU28*1.1)*1.25)))*AV28*1),2)*BS28),2)*AU28)/100),2)) -> 8.22 | DB28: 1 | DD28: *1)*1 | DE28: *1,1)*1,25 | DF28: *1,1)*1,25 | DG28: *1,1)*1,15 | DI28: *1,1)*1,15 | DJ28: *1,1)*1,25 | DN28: 0 | DO28: 0 | DP28: 1 | DQ28: 1 | DU28: 1010 | DV28: 100 шт. | DW28: 100 шт. | DX28: 100 | EE28: 59298928 | EF28: 30 | EG28: Строительные работы | EH28: 0 | EJ28: 1 | EK28: 22 | EL28: ТСН-2001.3-17. Водопровод и канализация - внутренние устройства | EM28: ТСН-2001.3-17-1 | EO28: Поправка: Гл.12.Прил.8.п.8. 5_12.00.01.11.003 Поправка: Гл.6.Прил.2.2.п.2.2.6_06.00.01.07.001 | EQ28: 0 | ER28: 5426.08 | ES28: 5229.82 | ET28: 7.54 | EU28: 0.5 | EV28: 188.72 | EW28: 16.89 | EX28: 0 | EY28: 0 | FQ28: 0 | FR28: 0 | FS28: 0 | FX28: 109 | FY28: 61 | GD28: 1 | GF28: -73133009 | GG28: 2 | GH28: 1 | GI28: 2 | GJ28: 0 | GK28: 0 | GL28: =ROUND(IF(AND(BH28=3,BI28=3,FS28<>0),P28,0),2) -> 0 | GM28: =ROUND(O28+X28+Y28,2)+GX28 -> 296.51 | GN28: =IF(OR(BI28=0,BI28=1),GM28-GX28,0) -> 296.51 | GO28: =IF(BI28=2,GM28-GX28,0) -> 0 | GP28: =IF(BI28=4,GM28-GX28,0) -> 0 | GR28: 0 | GS28: 3 | GT28: 0 | GV28: =ROUND((GT28),6) -> 0 | GW28: 1 | GX28: =ROUND(HC28*I28,2) -> 0 | HA28: 0 | HB28: 0 | HC28: =GV28*GW28 -> 0 | HS28: 0 | IK28: 0
A29: 17 | B29: 1 | E29: 1 | F29: 3.17-2-14 | G29: Установка гарнитуры туалетной: поручней для ванн | H29: 100 шт. | I29: =ROUND((1+1+1+1+1)/100,9) -> 0.05 | J29: 0 | K29: =ROUND((1+1+1+1+1)/100,9) -> 0.05 | O29: =ROUND(CP29,2) -> 903.33 | P29: =ROUND((ROUND((AC29*AW29*I29),2)*BC29),2) -> 196.12 | Q29: =(ROUND((ROUND(((((ET29*1.1)*1.25))*AV29*I29),2)*BB29),2)+ROUND((ROUND(((AE29-(((EU29*1.1)*1.25)))*AV29*I29),2)*BS29),2)) -> 6.64 | R29: =(ROUND((ROUND(((((EU29*1.1)*1.25))*AV29*I29),2)*BS29),2)+ROUND((ROUND(((AE29-(((EU29*1.1)*1.25)))*AV29*I29),2)*BS29),2)) -> 2.2 | S29: =ROUND((ROUND((AF29*AV29*I29),2)*BA29),2) -> 700.57 | T29: =ROUND(CU29*I29,2) -> 0 | U29: =CV29*I29 -> 1.1398681 | V29: =CW29*I29 -> 0 | W29: =ROUND(CX29*I29,2) -> 0 | X29: =(ROUND((((S29+ROUND((ROUND(((((EU29*1.1)*1.25))*AV29*I29),2)*BS29),2))*AT29)/100),2)+ROUND(((ROUND((ROUND(((AE29-(((EU29*1.1)*1.25)))*AV29*I29),2)*BS29),2)*AT29)/100),2)) -> 766.02 | Y29: =(ROUND((((S29+ROUND((ROUND(((((EU29*1.1)*1.25))*AV29*I29),2)*BS29),2))*AU29)/100),2)+ROUND(((ROUND((ROUND(((AE29-(((EU29*1.1)*1.25)))*AV29*I29),2)*BS29),2)*AU29)/100),2)) -> 428.69 | AA29: 59499215 | AB29: =ROUND((AC29+AD29+AF29),6) -> 5478.9183 | AC29: =ROUND((((ES29*1)*1)),6) -> 5229.82 | AD29: =ROUND((((((ET29*1.1)*1.25))-(((EU29*1.1)*1.25)))+AE29),6) -> 10.3675 | AE29: =ROUND((((EU29*1.1)*1.25)),6) -> 0.6875 | AF29: =ROUND((((EV29*1.1)*1.15)),6) -> 238.7308 | AG29: =ROUND((AP29),6) -> 0 | AH29: =(((EW29*1.1)*1.15)) -> 21.36585 | AI29: =(((EX29*1.1)*1.25)) -> 0 | AJ29: =(AS29) -> 0 | AK29: 5426.08 | AL29: 5229.82 | AM29: 7.54 | AN29: 0.5 | AO29: 188.72 | AP29: 0 | AQ29: 16.89 | AR29: 0 | AS29: 0 | AT29: 109 | AU29: 61 | AV29: 1.067 | AW29: 1 | AZ29: 1 | BA29: 54.99 | BB29: 12.07 | BC29: 0.75 | BH29: 0 | BI29: 1 | BJ29: ТСН-2001.3 Доп. 80, Сб. 17, т. 2, поз. 14 | BM29: 22 | BN29: 0 | BO29: 3.17-2-14 | BP29: 1 | BQ29: 30 | BR29: 0 | BS29: 54.99 | BT29: 1 | BU29: 1 | BV29: 1 | BW29: 1 | BX29: 1 | BZ29: 109 | CA29: 61 | CE29: 1566 | CF29: 0 | CG29: 0 | CM29: 0 | CN29: Поправка: Гл.12.Прил.8.п.8. 5_12.00.01.11.003 Наименование: При наличии усложненных условий производства работ (стесненность, сложность складирования и транспортной логистики, наличие в зоне производства работ действующего технологического оборудования или движения технологического транспорта и т.п.) для объектов, расположенных за пределами территории круговой магистральной системы улиц "Садовое кольцо" и за пределами Третьего транспортного кольца города Москвы пунктов "а" и "б", но в пределах Московской кольцевой автомобильной дороги Поправка: Гл.6.Прил.2.2.п.2.2.6_06.00.01.07.001 Наименование: При выполнении при капитальном ремонте и реконструкции работ, аналогичных технологическим процессам, характерным для нового строительства, и отсутствующих в сборниках на ремонтно-строительные работы ТСН-2001.6 | CO29: 0 | CP29: =(P29+Q29+S29) -> 903.33 | CQ29: =ROUND((ROUND((AC29*AW29*1),2)*BC29),2) -> 3922.37 | CR29: =(ROUND((ROUND(((((ET29*1.1)*1.25))*AV29*1),2)*BB29),2)+ROUND((ROUND(((AE29-(((EU29*1.1)*1.25)))*AV29*1),2)*BS29),2)) -> 133.49 | CS29: =(ROUND((ROUND(((((EU29*1.1)*1.25))*AV29*1),2)*BS29),2)+ROUND((ROUND(((AE29-(((EU29*1.1)*1.25)))*AV29*1),2)*BS29),2)) -> 40.14 | CT29: =ROUND((ROUND((AF29*AV29*1),2)*BA29),2) -> 14007.6 | CU29: =AG29 -> 0 | CV29: =(AH29*AV29) -> 22.797362 | CW29: =AI29 -> 0 | CX29: =AJ29 -> 0 | CY29: =(ROUND((((S29+ROUND((ROUND(((((EU29*1.1)*1.25))*AV29*1),2)*BS29),2))*AT29)/100),2)+ROUND(((ROUND((ROUND(((AE29-(((EU29*1.1)*1.25)))*AV29*1),2)*BS29),2)*AT29)/100),2)) -> 807.37 | CZ29: =(ROUND((((S29+ROUND((ROUND(((((EU29*1.1)*1.25))*AV29*1),2)*BS29),2))*AU29)/100),2)+ROUND(((ROUND((ROUND(((AE29-(((EU29*1.1)*1.25)))*AV29*1),2)*BS29),2)*AU29)/100),2)) -> 451.83 | DB29: 3 | DD29: *1)*1 | DE29: *1,1)*1,25 | DF29: *1,1)*1,25 | DG29: *1,1)*1,15 | DI29: *1,1)*1,15 | DJ29: *1,1)*1,25 | DN29: 0 | DO29: 0 | DP29: 1 | DQ29: 1 | DU29: 1010 | DV29: 100 шт. | DW29: 100 шт. | DX29: 100 | EE29: 59298928 | EF29: 30 | EG29: Строительные работы | EH29: 0 | EJ29: 1 | EK29: 22 | EL29: ТСН-2001.3-17. Водопровод и канализация - внутренние устройства | EM29: ТСН-2001.3-17-1 | EO29: Поправка: Гл.12.Прил.8.п.8. 5_12.00.01.11.003 Поправка: Гл.6.Прил.2.2.п.2.2.6_06.00.01.07.001 | EQ29: 0 | ER29: 5426.08 | ES29: 5229.82 | ET29: 7.54 | EU29: 0.5 | EV29: 188.72 | EW29: 16.89 | EX29: 0 | EY29: 0 | FQ29: 0 | FR29: 0 | FS29: 0 | FX29: 109 | FY29: 61 | GD29: 1 | GF29: -73133009 | GG29: 2 | GH29: 1 | GI29: 2 | GJ29: 0 | GK29: 0 | GL29: =ROUND(IF(AND(BH29=3,BI29=3,FS29<>0),P29,0),2) -> 0 | GM29: =ROUND(O29+X29+Y29,2)+GX29 -> 2098.04 | GN29: =IF(OR(BI29=0,BI29=1),GM29-GX29,0) -> 2098.04 | GO29: =IF(BI29=2,GM29-GX29,0) -> 0 | GP29: =IF(BI29=4,GM29-GX29,0) -> 0 | GR29: 0 | GS29: 3 | GT29: 0 | GV29: =ROUND((GT29),6) -> 0 | GW29: 1 | GX29: =ROUND(HC29*I29,2) -> 0 | HA29: 0 | HB29: 0 | HC29: =GV29*GW29 -> 0 | HS29: 0 | IK29: 0
A30: 17 | B30: 1 | E30: 2 | F30: 3.17-2-13 | G30: Установка гарнитуры туалетной: вешалок, подстаканников, дозаторов настенных и т.п./ крючки | H30: 100 шт. | I30: =ROUND(2/100,9) -> 0.02 | J30: 0 | K30: =ROUND(2/100,9) -> 0.02 | O30: =ROUND(CP30,2) -> 46.88 | P30: =ROUND((ROUND((AC30*AW30*I30),2)*BC30),2) -> 44.04 | Q30: =(ROUND((ROUND(((((ET30*1.1)*1.25))*AV30*I30),2)*BB30),2)+ROUND((ROUND(((AE30-(((EU30*1.1)*1.25)))*AV30*I30),2)*BS30),2)) -> 0.26 | R30: =(ROUND((ROUND(((((EU30*1.1)*1.25))*AV30*I30),2)*BS30),2)+ROUND((ROUND(((AE30-(((EU30*1.1)*1.25)))*AV30*I30),2)*BS30),2)) -> 0.03 | S30: =ROUND((ROUND((AF30*AV30*I30),2)*BA30),2) -> 2.58 | T30: =ROUND(CU30*I30,2) -> 0 | U30: =CV30*I30 -> 0.23161796 | V30: =CW30*I30 -> 0 | W30: =ROUND(CX30*I30,2) -> 0 | X30: =(ROUND((((S30+ROUND((ROUND(((((EU30*1.1)*1.25))*AV30*I30),2)*BS30),2))*AT30)/100),2)+ROUND(((ROUND((ROUND(((AE30-(((EU30*1.1)*1.25)))*AV30*I30),2)*BS30),2)*AT30)/100),2)) -> 2.84 | Y30: =(ROUND((((S30+ROUND((ROUND(((((EU30*1.1)*1.25))*AV30*I30),2)*BS30),2))*AU30)/100),2)+ROUND(((ROUND((ROUND(((AE30-(((EU30*1.1)*1.25)))*AV30*I30),2)*BS30),2)*AU30)/100),2)) -> 1.59 | AA30: 59499218 | AB30: =ROUND((AC30+AD30+AF30),6) -> 2335.2951 | AC30: =ROUND((((ES30*1)*1)),6) -> 2202.04 | AD30: =ROUND((((((ET30*1.1)*1.25))-(((EU30*1.1)*1.25)))+AE30),6) -> 12.33375 | AE30: =ROUND((((EU30*1.1)*1.25)),6) -> 1.38875 | AF30: =ROUND((((EV30*1.1)*1.15)),6) -> 120.92135 | AG30: =ROUND((AP30),6) -> 0 | AH30: =(((EW30*1.1)*1.15)) -> 10.8537 | AI30: =(((EX30*1.1)*1.25)) -> 0 | AJ30: =(AS30) -> 0 | AK30: 2306.6 | AL30: 2202.04 | AM30: 8.97 | AN30: 1.01 | AO30: 95.59 | AP30: 0 | AQ30: 8.58 | AR30: 0 | AS30: 0 | AT30: 109 | AU30: 61 | AV30: 1.067 | AW30: 1 | AZ30: 1 | BA30: 1 | BB30: 1 | BC30: 1 | BH30: 0 | BI30: 1 | BJ30: ТСН-2001.3 Доп. 80, Сб. 17, т. 2, поз. 13 | BM30: 22 | BN30: 0 | BO30: 3.17-2-13 | BP30: 1 | BQ30: 30 | BR30: 0 | BS30: 1 | BT30: 1 | BU30: 1 | BV30: 1 | BW30: 1 | BX30: 1 | BZ30: 109 | CA30: 61 | CE30: 1566 | CF30: 0 | CG30: 0 | CM30: 0 | CN30: Поправка: Гл.12.Прил.8.п.8. 5_12.00.01.11.003 Наименование: При наличии усложненных условий производства работ (стесненность, сложность складирования и транспортной логистики, наличие в зоне производства работ действующего технологического оборудования или движения технологического транспорта и т.п.) для объектов, расположенных за пределами территории круговой магистральной системы улиц "Садовое кольцо" и за пределами Третьего транспортного кольца города Москвы пунктов "а" и "б", но в пределах Московской кольцевой автомобильной дороги Поправка: Гл.6.Прил.2.2.п.2.2.6_06.00.01.07.001 Наименование: При выполнении при капитальном ремонте и реконструкции работ, аналогичных технологическим процессам, характерным для нового строительства, и отсутствующих в сборниках на ремонтно-строительные работы ТСН-2001.6 | CO30: 0 | CP30: =(P30+Q30+S30) -> 46.88 | CQ30: =ROUND((ROUND((AC30*AW30*1),2)*BC30),2) -> 2202.04 | CR30: =(ROUND((ROUND(((((ET30*1.1)*1.25))*AV30*1),2)*BB30),2)+ROUND((ROUND(((AE30-(((EU30*1.1)*1.25)))*AV30*1),2)*BS30),2)) -> 13.16 | CS30: =(ROUND((ROUND(((((EU30*1.1)*1.25))*AV30*1),2)*BS30),2)+ROUND((ROUND(((AE30-(((EU30*1.1)*1.25)))*AV30*1),2)*BS30),2)) -> 1.48 | CT30: =ROUND((ROUND((AF30*AV30*1),2)*BA30),2) -> 129.02 | CU30: =AG30 -> 0 | CV30: =(AH30*AV30) -> 11.580898 | CW30: =AI30 -> 0 | CX30: =AJ30 -> 0 | CY30: =(ROUND((((S30+ROUND((ROUND(((((EU30*1.1)*1.25))*AV30*1),2)*BS30),2))*AT30)/100),2)+ROUND(((ROUND((ROUND(((AE30-(((EU30*1.1)*1.25)))*AV30*1),2)*BS30),2)*AT30)/100),2)) -> 4.43 | CZ30: =(ROUND((((S30+ROUND((ROUND(((((EU30*1.1)*1.25))*AV30*1),2)*BS30),2))*AU30)/100),2)+ROUND(((ROUND((ROUND(((AE30-(((EU30*1.1)*1.25)))*AV30*1),2)*BS30),2)*AU30)/100),2)) -> 2.48 | DB30: 5 | DD30: *1)*1 | DE30: *1,1)*1,25 | DF30: *1,1)*1,25 | DG30: *1,1)*1,15 | DI30: *1,1)*1,15 | DJ30: *1,1)*1,25 | DN30: 0 | DO30: 0 | DP30: 1 | DQ30: 1 | DU30: 1010 | DV30: 100 шт. | DW30: 100 шт. | DX30: 100 | EE30: 59298928 | EF30: 30 | EG30: Строительные работы | EH30: 0 | EJ30: 1 | EK30: 22 | EL30: ТСН-2001.3-17. Водопровод и канализация - внутренние устройства | EM30: ТСН-2001.3-17-1 | EO30: Поправка: Гл.12.Прил.8.п.8. 5_12.00.01.11.003 Поправка: Гл.6.Прил.2.2.п.2.2.6_06.00.01.07.001 | EQ30: 0 | ER30: 2306.6 | ES30: 2202.04 | ET30: 8.97 | EU30: 1.01 | EV30: 95.59 | EW30: 8.58 | EX30: 0 | EY30: 0 | FQ30: 0 | FR30: 0 | FS30: 0 | FX30: 109 | FY30: 61 | GD30: 1 | GF30: -488901103 | GG30: 2 | GH30: 1 | GI30: 2 | GJ30: 0 | GK30: 0 | GL30: =ROUND(IF(AND(BH30=3,BI30=3,FS30<>0),P30,0),2) -> 0 | GM30: =ROUND(O30+X30+Y30,2)+GX30 -> 51.31 | GN30: =IF(OR(BI30=0,BI30=1),GM30-GX30,0) -> 51.31 | GO30: =IF(BI30=2,GM30-GX30,0) -> 0 | GP30: =IF(BI30=4,GM30-GX30,0) -> 0 | GR30: 0 | GS30: 3 | GT30: 0 | GV30: =ROUND((GT30),6) -> 0 | GW30: 1 | GX30: =ROUND(HC30*I30,2) -> 0 | HA30: 0 | HB30: 0 | HC30: =GV30*GW30 -> 0 | HS30: 0 | IK30: 0
A31: 17 | B31: 1 | E31: 2 | F31: 3.17-2-13 | G31: Установка гарнитуры туалетной: вешалок, подстаканников, дозаторов настенных и т.п./ крючки | H31: 100 шт. | I31: =ROUND(2/100,9) -> 0.02 | J31: 0 | K31: =ROUND(2/100,9) -> 0.02 | O31: =ROUND(CP31,2) -> 178.63 | P31: =ROUND((ROUND((AC31*AW31*I31),2)*BC31),2) -> 33.03 | Q31: =(ROUND((ROUND(((((ET31*1.1)*1.25))*AV31*I31),2)*BB31),2)+ROUND((ROUND(((AE31-(((EU31*1.1)*1.25)))*AV31*I31),2)*BS31),2)) -> 3.73 | R31: =(ROUND((ROUND(((((EU31*1.1)*1.25))*AV31*I31),2)*BS31),2)+ROUND((ROUND(((AE31-(((EU31*1.1)*1.25)))*AV31*I31),2)*BS31),2)) -> 1.65 | S31: =ROUND((ROUND((AF31*AV31*I31),2)*BA31),2) -> 141.87 | T31: =ROUND(CU31*I31,2) -> 0 | U31: =CV31*I31 -> 0.23161796 | V31: =CW31*I31 -> 0 | W31: =ROUND(CX31*I31,2) -> 0 | X31: =(ROUND((((S31+ROUND((ROUND(((((EU31*1.1)*1.25))*AV31*I31),2)*BS31),2))*AT31)/100),2)+ROUND(((ROUND((ROUND(((AE31-(((EU31*1.1)*1.25)))*AV31*I31),2)*BS31),2)*AT31)/100),2)) -> 156.44 | Y31: =(ROUND((((S31+ROUND((ROUND(((((EU31*1.1)*1.25))*AV31*I31),2)*BS31),2))*AU31)/100),2)+ROUND(((ROUND((ROUND(((AE31-(((EU31*1.1)*1.25)))*AV31*I31),2)*BS31),2)*AU31)/100),2)) -> 87.55 | AA31: 59499215 | AB31: =ROUND((AC31+AD31+AF31),6) -> 2335.2951 | AC31: =ROUND((((ES31*1)*1)),6) -> 2202.04 | AD31: =ROUND((((((ET31*1.1)*1.25))-(((EU31*1.1)*1.25)))+AE31),6) -> 12.33375 | AE31: =ROUND((((EU31*1.1)*1.25)),6) -> 1.38875 | AF31: =ROUND((((EV31*1.1)*1.15)),6) -> 120.92135 | AG31: =ROUND((AP31),6) -> 0 | AH31: =(((EW31*1.1)*1.15)) -> 10.8537 | AI31: =(((EX31*1.1)*1.25)) -> 0 | AJ31: =(AS31) -> 0 | AK31: 2306.6 | AL31: 2202.04 | AM31: 8.97 | AN31: 1.01 | AO31: 95.59 | AP31: 0 | AQ31: 8.58 | AR31: 0 | AS31: 0 | AT31: 109 | AU31: 61 | AV31: 1.067 | AW31: 1 | AZ31: 1 | BA31: 54.99 | BB31: 14.34 | BC31: 0.75 | BH31: 0 | BI31: 1 | BJ31: ТСН-2001.3 Доп. 80, Сб. 17, т. 2, поз. 13 | BM31: 22 | BN31: 0 | BO31: 3.17-2-13 | BP31: 1 | BQ31: 30 | BR31: 0 | BS31: 54.99 | BT31: 1 | BU31: 1 | BV31: 1 | BW31: 1 | BX31: 1 | BZ31: 109 | CA31: 61 | CE31: 1566 | CF31: 0 | CG31: 0 | CM31: 0 | CN31: Поправка: Гл.12.Прил.8.п.8. 5_12.00.01.11.003 Наименование: При наличии усложненных условий производства работ (стесненность, сложность складирования и транспортной логистики, наличие в зоне производства работ действующего технологического оборудования или движения технологического транспорта и т.п.) для объектов, расположенных за пределами территории круговой магистральной системы улиц "Садовое кольцо" и за пределами Третьего транспортного кольца города Москвы пунктов "а" и "б", но в пределах Московской кольцевой автомобильной дороги Поправка: Гл.6.Прил.2.2.п.2.2.6_06.00.01.07.001 Наименование: При выполнении при капитальном ремонте и реконструкции работ, аналогичных технологическим процессам, характерным для нового строительства, и отсутствующих в сборниках на ремонтно-строительные работы ТСН-2001.6 | CO31: 0 | CP31: =(P31+Q31+S31) -> 178.63 | CQ31: =ROUND((ROUND((AC31*AW31*1),2)*BC31),2) -> 1651.53 | CR31: =(ROUND((ROUND(((((ET31*1.1)*1.25))*AV31*1),2)*BB31),2)+ROUND((ROUND(((AE31-(((EU31*1.1)*1.25)))*AV31*1),2)*BS31),2)) -> 188.71 | CS31: =(ROUND((ROUND(((((EU31*1.1)*1.25))*AV31*1),2)*BS31),2)+ROUND((ROUND(((AE31-(((EU31*1.1)*1.25)))*AV31*1),2)*BS31),2)) -> 81.39 | CT31: =ROUND((ROUND((AF31*AV31*1),2)*BA31),2) -> 7094.81 | CU31: =AG31 -> 0 | CV31: =(AH31*AV31) -> 11.580898 | CW31: =AI31 -> 0 | CX31: =AJ31 -> 0 | CY31: =(ROUND((((S31+ROUND((ROUND(((((EU31*1.1)*1.25))*AV31*1),2)*BS31),2))*AT31)/100),2)+ROUND(((ROUND((ROUND(((AE31-(((EU31*1.1)*1.25)))*AV31*1),2)*BS31),2)*AT31)/100),2)) -> 243.35 | CZ31: =(ROUND((((S31+ROUND((ROUND(((((EU31*1.1)*1.25))*AV31*1),2)*BS31),2))*AU31)/100),2)+ROUND(((ROUND((ROUND(((AE31-(((EU31*1.1)*1.25)))*AV31*1),2)*BS31),2)*AU31)/100),2)) -> 136.19 | DB31: 7 | DD31: *1)*1 | DE31: *1,1)*1,25 | DF31: *1,1)*1,25 | DG31: *1,1)*1,15 | DI31: *1,1)*1,15 | DJ31: *1,1)*1,25 | DN31: 0 | DO31: 0 | DP31: 1 | DQ31: 1 | DU31: 1010 | DV31: 100 шт. | DW31: 100 шт. | DX31: 100 | EE31: 59298928 | EF31: 30 | EG31: Строительные работы | EH31: 0 | EJ31: 1 | EK31: 22 | EL31: ТСН-2001.3-17. Водопровод и канализация - внутренние устройства | EM31: ТСН-2001.3-17-1 | EO31: Поправка: Гл.12.Прил.8.п.8. 5_12.00.01.11.003 Поправка: Гл.6.Прил.2.2.п.2.2.6_06.00.01.07.001 | EQ31: 0 | ER31: 2306.6 | ES31: 2202.04 | ET31: 8.97 | EU31: 1.01 | EV31: 95.59 | EW31: 8.58 | EX31: 0 | EY31: 0 | FQ31: 0 | FR31: 0 | FS31: 0 | FX31: 109 | FY31: 61 | GD31: 1 | GF31: -488901103 | GG31: 2 | GH31: 1 | GI31: 2 | GJ31: 0 | GK31: 0 | GL31: =ROUND(IF(AND(BH31=3,BI31=3,FS31<>0),P31,0),2) -> 0 | GM31: =ROUND(O31+X31+Y31,2)+GX31 -> 422.62 | GN31: =IF(OR(BI31=0,BI31=1),GM31-GX31,0) -> 422.62 | GO31: =IF(BI31=2,GM31-GX31,0) -> 0 | GP31: =IF(BI31=4,GM31-GX31,0) -> 0 | GR31: 0 | GS31: 3 | GT31: 0 | GV31: =ROUND((GT31),6) -> 0 | GW31: 1 | GX31: =ROUND(HC31*I31,2) -> 0 | HA31: 0 | HB31: 0 | HC31: =GV31*GW31 -> 0 | HS31: 0 | IK31: 0
A32: 17 | B32: 1 | D32: =ROW(EtalonRes!A4) -> 4 | E32: 3 | F32: 3.17-2-5 | G32: Установка гарнитуры туалетной полочек/зеркало | H32: 1 ШТ. | I32: 1 | J32: 0 | K32: 1 | O32: =ROUND(CP32,2) -> 11.05 | P32: =ROUND((ROUND((AC32*AW32*I32),2)*BC32),2) -> 0.32 | Q32: =(ROUND((ROUND(((((ET32*1.25)*1.1))*AV32*I32),2)*BB32),2)+ROUND((ROUND(((AE32-(((EU32*1.25)*1.1)))*AV32*I32),2)*BS32),2)) -> 0 | R32: =(ROUND((ROUND(((((EU32*1.25)*1.1))*AV32*I32),2)*BS32),2)+ROUND((ROUND(((AE32-(((EU32*1.25)*1.1)))*AV32*I32),2)*BS32),2)) -> 0 | S32: =ROUND((ROUND((AF32*AV32*I32),2)*BA32),2) -> 10.73 | T32: =ROUND(CU32*I32,2) -> 0 | U32: =CV32*I32 -> 0.85034565 | V32: =CW32*I32 -> 0 | W32: =ROUND(CX32*I32,2) -> 0 | X32: =(ROUND((((S32+ROUND((ROUND(((((EU32*1.25)*1.1))*AV32*I32),2)*BS32),2))*AT32)/100),2)+ROUND(((ROUND((ROUND(((AE32-(((EU32*1.25)*1.1)))*AV32*I32),2)*BS32),2)*AT32)/100),2)) -> 11.7 | Y32: =(ROUND((((S32+ROUND((ROUND(((((EU32*1.25)*1.1))*AV32*I32),2)*BS32),2))*AU32)/100),2)+ROUND(((ROUND((ROUND(((AE32-(((EU32*1.25)*1.1)))*AV32*I32),2)*BS32),2)*AU32)/100),2)) -> 6.55 | AA32: 59499218 | AB32: =ROUND((AC32+AD32+AF32),6) -> 10.37675 | AC32: =ROUND((ES32),6) -> 0.32 | AD32: =ROUND((((((ET32*1.25)*1.1))-(((EU32*1.25)*1.1)))+AE32),6) -> 0 | AE32: =ROUND((((EU32*1.25)*1.1)),6) -> 0 | AF32: =ROUND((((EV32*1.15)*1.1)),6) -> 10.05675 | AG32: =ROUND((AP32),6) -> 0 | AH32: =(((EW32*1.15)*1.1)) -> 0.79695 | AI32: =(((EX32*1.25)*1.1)) -> 0 | AJ32: =(AS32) -> 0 | AK32: 8.27 | AL32: 0.32 | AM32: 0 | AN32: 0 | AO32: 7.95 | AP32: 0 | AQ32: 0.63 | AR32: 0 | AS32: 0 | AT32: 109 | AU32: 61 | AV32: 1.067 | AW32: 1 | AZ32: 1 | BA32: 1 | BB32: 1 | BC32: 1 | BH32: 0 | BI32: 1 | BJ32: ТСН-2001.3 Доп. 72, Сб. 17, т. 2, поз. 5 | BM32: 22 | BN32: 59298886 | BO32: 3.17-2-5 | BP32: 1 | BQ32: 30 | BR32: 0 | BS32: 1 | BT32: 1 | BU32: 1 | BV32: 1 | BW32: 1 | BX32: 1 | BZ32: 109 | CA32: 61 | CE32: 1566 | CF32: 0 | CG32: 0 | CM32: 0 | CN32: Поправка: О.П. п.3.4.30.в Наименование: При применении территориальных сметных нормативов для города Москвы затраты, учитывающие напряженные и стесненные условия производства работ (стесненность, сложность складирования и транспортной логистики и т.п.), исчисляются с применением коэффициентов к затратам труда и заработной плате рабочих, машинистов, времени эксплуатации машин и механизмов, стоимости эксплуатации машин в размере: для объектов, расположенных за пределами Третьего транспортного кольца города Москвы, но в пределах Московской кольцевой автомобильной дороги | CO32: 0 | CP32: =(P32+Q32+S32) -> 11.05 | CQ32: =ROUND((ROUND((AC32*AW32*1),2)*BC32),2) -> 0.32 | CR32: =(ROUND((ROUND(((((ET32*1.25)*1.1))*AV32*1),2)*BB32),2)+ROUND((ROUND(((AE32-(((EU32*1.25)*1.1)))*AV32*1),2)*BS32),2)) -> 0 | CS32: =(ROUND((ROUND(((((EU32*1.25)*1.1))*AV32*1),2)*BS32),2)+ROUND((ROUND(((AE32-(((EU32*1.25)*1.1)))*AV32*1),2)*BS32),2)) -> 0 | CT32: =ROUND((ROUND((AF32*AV32*1),2)*BA32),2) -> 10.73 | CU32: =AG32 -> 0 | CV32: =(AH32*AV32) -> 0.85034565 | CW32: =AI32 -> 0 | CX32: =AJ32 -> 0 | CY32: =(ROUND((((S32+ROUND((ROUND(((((EU32*1.25)*1.1))*AV32*1),2)*BS32),2))*AT32)/100),2)+ROUND(((ROUND((ROUND(((AE32-(((EU32*1.25)*1.1)))*AV32*1),2)*BS32),2)*AT32)/100),2)) -> 11.7 | CZ32: =(ROUND((((S32+ROUND((ROUND(((((EU32*1.25)*1.1))*AV32*1),2)*BS32),2))*AU32)/100),2)+ROUND(((ROUND((ROUND(((AE32-(((EU32*1.25)*1.1)))*AV32*1),2)*BS32),2)*AU32)/100),2)) -> 6.55 | DB32: 9 | DE32: *1,25)*1,1 | DF32: *1,25)*1,1 | DG32: *1,15)*1,1 | DI32: *1,15)*1,1 | DJ32: *1,25)*1,1 | DN32: 0 | DO32: 0 | DP32: 1 | DQ32: 1 | DU32: 1013 | DV32: 1 ШТ. | DW32: 1 ШТ. | DX32: 1 | EE32: 59298928 | EF32: 30 | EG32: Строительные работы | EH32: 0 | EJ32: 1 | EK32: 22 | EL32: ТСН-2001.3-17. Водопровод и канализация - внутренние устройства | EM32: ТСН-2001.3-17-1 | EO32: Поправка: О.П. п.3.4.30.в | EQ32: 0 | ER32: 8.27 | ES32: 0.32 | ET32: 0 | EU32: 0 | EV32: 7.95 | EW32: 0.63 | EX32: 0 | EY32: 0 | FQ32: 0 | FR32: 0 | FS32: 0 | FX32: 109 | FY32: 61 | GD32: 1 | GF32: -1951833034 | GG32: 2 | GH32: 1 | GI32: 2 | GJ32: 0 | GK32: 0 | GL32: =ROUND(IF(AND(BH32=3,BI32=3,FS32<>0),P32,0),2) -> 0 | GM32: =ROUND(O32+X32+Y32,2)+GX32 -> 29.3 | GN32: =IF(OR(BI32=0,BI32=1),GM32-GX32,0) -> 29.3 | GO32: =IF(BI32=2,GM32-GX32,0) -> 0 | GP32: =IF(BI32=4,GM32-GX32,0) -> 0 | GR32: 0 | GS32: 3 | GT32: 0 | GV32: =ROUND((GT32),6) -> 0 | GW32: 1 | GX32: =ROUND(HC32*I32,2) -> 0 | HA32: 0 | HB32: 0 | HC32: =GV32*GW32 -> 0 | HS32: 0 | IK32: 0
A33: 17 | B33: 1 | D33: =ROW(EtalonRes!A8) -> 8 | E33: 3 | F33: 3.17-2-5 | G33: Установка гарнитуры туалетной полочек/зеркало | H33: 1 ШТ. | I33: 1 | J33: 0 | K33: 1 | O33: =ROUND(CP33,2) -> 591.93 | P33: =ROUND((ROUND((AC33*AW33*I33),2)*BC33),2) -> 1.89 | Q33: =(ROUND((ROUND(((((ET33*1.25)*1.1))*AV33*I33),2)*BB33),2)+ROUND((ROUND(((AE33-(((EU33*1.25)*1.1)))*AV33*I33),2)*BS33),2)) -> 0 | R33: =(ROUND((ROUND(((((EU33*1.25)*1.1))*AV33*I33),2)*BS33),2)+ROUND((ROUND(((AE33-(((EU33*1.25)*1.1)))*AV33*I33),2)*BS33),2)) -> 0 | S33: =ROUND((ROUND((AF33*AV33*I33),2)*BA33),2) -> 590.04 | T33: =ROUND(CU33*I33,2) -> 0 | U33: =CV33*I33 -> 0.85034565 | V33: =CW33*I33 -> 0 | W33: =ROUND(CX33*I33,2) -> 0 | X33: =(ROUND((((S33+ROUND((ROUND(((((EU33*1.25)*1.1))*AV33*I33),2)*BS33),2))*AT33)/100),2)+ROUND(((ROUND((ROUND(((AE33-(((EU33*1.25)*1.1)))*AV33*I33),2)*BS33),2)*AT33)/100),2)) -> 643.14 | Y33: =(ROUND((((S33+ROUND((ROUND(((((EU33*1.25)*1.1))*AV33*I33),2)*BS33),2))*AU33)/100),2)+ROUND(((ROUND((ROUND(((AE33-(((EU33*1.25)*1.1)))*AV33*I33),2)*BS33),2)*AU33)/100),2)) -> 359.92 | AA33: 59499215 | AB33: =ROUND((AC33+AD33+AF33),6) -> 10.37675 | AC33: =ROUND((ES33),6) -> 0.32 | AD33: =ROUND((((((ET33*1.25)*1.1))-(((EU33*1.25)*1.1)))+AE33),6) -> 0 | AE33: =ROUND((((EU33*1.25)*1.1)),6) -> 0 | AF33: =ROUND((((EV33*1.15)*1.1)),6) -> 10.05675 | AG33: =ROUND((AP33),6) -> 0 | AH33: =(((EW33*1.15)*1.1)) -> 0.79695 | AI33: =(((EX33*1.25)*1.1)) -> 0 | AJ33: =(AS33) -> 0 | AK33: 8.27 | AL33: 0.32 | AM33: 0 | AN33: 0 | AO33: 7.95 | AP33: 0 | AQ33: 0.63 | AR33: 0 | AS33: 0 | AT33: 109 | AU33: 61 | AV33: 1.067 | AW33: 1 | AZ33: 1 | BA33: 54.99 | BB33: 1 | BC33: 5.91 | BH33: 0 | BI33: 1 | BJ33: ТСН-2001.3 Доп. 72, Сб. 17, т. 2, поз. 5 | BM33: 22 | BN33: 59298886 | BO33: 3.17-2-5 | BP33: 1 | BQ33: 30 | BR33: 0 | BS33: 54.99 | BT33: 1 | BU33: 1 | BV33: 1 | BW33: 1 | BX33: 1 | BZ33: 109 | CA33: 61 | CE33: 1566 | CF33: 0 | CG33: 0 | CM33: 0 | CN33: Поправка: О.П. п.3.4.30.в Наименование: При применении территориальных сметных нормативов для города Москвы затраты, учитывающие напряженные и стесненные условия производства работ (стесненность, сложность складирования и транспортной логистики и т.п.), исчисляются с применением коэффициентов к затратам труда и заработной плате рабочих, машинистов, времени эксплуатации машин и механизмов, стоимости эксплуатации машин в размере: для объектов, расположенных за пределами Третьего транспортного кольца города Москвы, но в пределах Московской кольцевой автомобильной дороги | CO33: 0 | CP33: =(P33+Q33+S33) -> 591.93 | CQ33: =ROUND((ROUND((AC33*AW33*1),2)*BC33),2) -> 1.89 | CR33: =(ROUND((ROUND(((((ET33*1.25)*1.1))*AV33*1),2)*BB33),2)+ROUND((ROUND(((AE33-(((EU33*1.25)*1.1)))*AV33*1),2)*BS33),2)) -> 0 | CS33: =(ROUND((ROUND(((((EU33*1.25)*1.1))*AV33*1),2)*BS33),2)+ROUND((ROUND(((AE33-(((EU33*1.25)*1.1)))*AV33*1),2)*BS33),2)) -> 0 | CT33: =ROUND((ROUND((AF33*AV33*1),2)*BA33),2) -> 590.04 | CU33: =AG33 -> 0 | CV33: =(AH33*AV33) -> 0.85034565 | CW33: =AI33 -> 0 | CX33: =AJ33 -> 0 | CY33: =(ROUND((((S33+ROUND((ROUND(((((EU33*1.25)*1.1))*AV33*1),2)*BS33),2))*AT33)/100),2)+ROUND(((ROUND((ROUND(((AE33-(((EU33*1.25)*1.1)))*AV33*1),2)*BS33),2)*AT33)/100),2)) -> 643.14 | CZ33: =(ROUND((((S33+ROUND((ROUND(((((EU33*1.25)*1.1))*AV33*1),2)*BS33),2))*AU33)/100),2)+ROUND(((ROUND((ROUND(((AE33-(((EU33*1.25)*1.1)))*AV33*1),2)*BS33),2)*AU33)/100),2)) -> 359.92 | DB33: 11 | DE33: *1,25)*1,1 | DF33: *1,25)*1,1 | DG33: *1,15)*1,1 | DI33: *1,15)*1,1 | DJ33: *1,25)*1,1 | DN33: 0 | DO33: 0 | DP33: 1 | DQ33: 1 | DU33: 1013 | DV33: 1 ШТ. | DW33: 1 ШТ. | DX33: 1 | EE33: 59298928 | EF33: 30 | EG33: Строительные работы | EH33: 0 | EJ33: 1 | EK33: 22 | EL33: ТСН-2001.3-17. Водопровод и канализация - внутренние устройства | EM33: ТСН-2001.3-17-1 | EO33: Поправка: О.П. п.3.4.30.в | EQ33: 0 | ER33: 8.27 | ES33: 0.32 | ET33: 0 | EU33: 0 | EV33: 7.95 | EW33: 0.63 | EX33: 0 | EY33: 0 | FQ33: 0 | FR33: 0 | FS33: 0 | FX33: 109 | FY33: 61 | GD33: 1 | GF33: -1951833034 | GG33: 2 | GH33: 1 | GI33: 2 | GJ33: 0 | GK33: 0 | GL33: =ROUND(IF(AND(BH33=3,BI33=3,FS33<>0),P33,0),2) -> 0 | GM33: =ROUND(O33+X33+Y33,2)+GX33 -> 1594.99 | GN33: =IF(OR(BI33=0,BI33=1),GM33-GX33,0) -> 1594.99 | GO33: =IF(BI33=2,GM33-GX33,0) -> 0 | GP33: =IF(BI33=4,GM33-GX33,0) -> 0 | GR33: 0 | GS33: 3 | GT33: 0 | GV33: =ROUND((GT33),6) -> 0 | GW33: 1 | GX33: =ROUND(HC33*I33,2) -> 0 | HA33: 0 | HB33: 0 | HC33: =GV33*GW33 -> 0 | HS33: 0 | IK33: 0
A34: 17 | B34: 1 | E34: 4 | F34: 3.17-2-13 | G34: Установка гарнитуры туалетной: вешалок, подстаканников, дозаторов настенных и т.п./диспенсер | H34: 100 шт. | I34: =ROUND(3/100,9) -> 0.03 | J34: 0 | K34: =ROUND(3/100,9) -> 0.03 | O34: =ROUND(CP34,2) -> 70.32 | P34: =ROUND((ROUND((AC34*AW34*I34),2)*BC34),2) -> 66.06 | Q34: =(ROUND((ROUND(((((ET34*1.1)*1.25))*AV34*I34),2)*BB34),2)+ROUND((ROUND(((AE34-(((EU34*1.1)*1.25)))*AV34*I34),2)*BS34),2)) -> 0.39 | R34: =(ROUND((ROUND(((((EU34*1.1)*1.25))*AV34*I34),2)*BS34),2)+ROUND((ROUND(((AE34-(((EU34*1.1)*1.25)))*AV34*I34),2)*BS34),2)) -> 0.04 | S34: =ROUND((ROUND((AF34*AV34*I34),2)*BA34),2) -> 3.87 | T34: =ROUND(CU34*I34,2) -> 0 | U34: =CV34*I34 -> 0.34742694 | V34: =CW34*I34 -> 0 | W34: =ROUND(CX34*I34,2) -> 0 | X34: =(ROUND((((S34+ROUND((ROUND(((((EU34*1.1)*1.25))*AV34*I34),2)*BS34),2))*AT34)/100),2)+ROUND(((ROUND((ROUND(((AE34-(((EU34*1.1)*1.25)))*AV34*I34),2)*BS34),2)*AT34)/100),2)) -> 4.26 | Y34: =(ROUND((((S34+ROUND((ROUND(((((EU34*1.1)*1.25))*AV34*I34),2)*BS34),2))*AU34)/100),2)+ROUND(((ROUND((ROUND(((AE34-(((EU34*1.1)*1.25)))*AV34*I34),2)*BS34),2)*AU34)/100),2)) -> 2.39 | AA34: 59499218 | AB34: =ROUND((AC34+AD34+AF34),6) -> 2335.2951 | AC34: =ROUND((((ES34*1)*1)),6) -> 2202.04 | AD34: =ROUND((((((ET34*1.1)*1.25))-(((EU34*1.1)*1.25)))+AE34),6) -> 12.33375 | AE34: =ROUND((((EU34*1.1)*1.25)),6) -> 1.38875 | AF34: =ROUND((((EV34*1.1)*1.15)),6) -> 120.92135 | AG34: =ROUND((AP34),6) -> 0 | AH34: =(((EW34*1.1)*1.15)) -> 10.8537 | AI34: =(((EX34*1.1)*1.25)) -> 0 | AJ34: =(AS34) -> 0 | AK34: 2306.6 | AL34: 2202.04 | AM34: 8.97 | AN34: 1.01 | AO34: 95.59 | AP34: 0 | AQ34: 8.58 | AR34: 0 | AS34: 0 | AT34: 109 | AU34: 61 | AV34: 1.067 | AW34: 1 | AZ34: 1 | BA34: 1 | BB34: 1 | BC34: 1 | BH34: 0 | BI34: 1 | BJ34: ТСН-2001.3 Доп. 80, Сб. 17, т. 2, поз. 13 | BM34: 22 | BN34: 0 | BO34: 3.17-2-13 | BP34: 1 | BQ34: 30 | BR34: 0 | BS34: 1 | BT34: 1 | BU34: 1 | BV34: 1 | BW34: 1 | BX34: 1 | BZ34: 109 | CA34: 61 | CE34: 1566 | CF34: 0 | CG34: 0 | CM34: 0 | CN34: Поправка: Гл.12.Прил.8.п.8. 5_12.00.01.11.003 Наименование: При наличии усложненных условий производства работ (стесненность, сложность складирования и транспортной логистики, наличие в зоне производства работ действующего технологического оборудования или движения технологического транспорта и т.п.) для объектов, расположенных за пределами территории круговой магистральной системы улиц "Садовое кольцо" и за пределами Третьего транспортного кольца города Москвы пунктов "а" и "б", но в пределах Московской кольцевой автомобильной дороги Поправка: Гл.6.Прил.2.2.п.2.2.6_06.00.01.07.001 Наименование: При выполнении при капитальном ремонте и реконструкции работ, аналогичных технологическим процессам, характерным для нового строительства, и отсутствующих в сборниках на ремонтно-строительные работы ТСН-2001.6 | CO34: 0 | CP34: =(P34+Q34+S34) -> 70.32 | CQ34: =ROUND((ROUND((AC34*AW34*1),2)*BC34),2) -> 2202.04 | CR34: =(ROUND((ROUND(((((ET34*1.1)*1.25))*AV34*1),2)*BB34),2)+ROUND((ROUND(((AE34-(((EU34*1.1)*1.25)))*AV34*1),2)*BS34),2)) -> 13.16 | CS34: =(ROUND((ROUND(((((EU34*1.1)*1.25))*AV34*1),2)*BS34),2)+ROUND((ROUND(((AE34-(((EU34*1.1)*1.25)))*AV34*1),2)*BS34),2)) -> 1.48 | CT34: =ROUND((ROUND((AF34*AV34*1),2)*BA34),2) -> 129.02 | CU34: =AG34 -> 0 | CV34: =(AH34*AV34) -> 11.580898 | CW34: =AI34 -> 0 | CX34: =AJ34 -> 0 | CY34: =(ROUND((((S34+ROUND((ROUND(((((EU34*1.1)*1.25))*AV34*1),2)*BS34),2))*AT34)/100),2)+ROUND(((ROUND((ROUND(((AE34-(((EU34*1.1)*1.25)))*AV34*1),2)*BS34),2)*AT34)/100),2)) -> 5.83 | CZ34: =(ROUND((((S34+ROUND((ROUND(((((EU34*1.1)*1.25))*AV34*1),2)*BS34),2))*AU34)/100),2)+ROUND(((ROUND((ROUND(((AE34-(((EU34*1.1)*1.25)))*AV34*1),2)*BS34),2)*AU34)/100),2)) -> 3.26 | DB34: 13 | DD34: *1)*1 | DE34: *1,1)*1,25 | DF34: *1,1)*1,25 | DG34: *1,1)*1,15 | DI34: *1,1)*1,15 | DJ34: *1,1)*1,25 | DN34: 0 | DO34: 0 | DP34: 1 | DQ34: 1 | DU34: 1010 | DV34: 100 шт. | DW34: 100 шт. | DX34: 100 | EE34: 59298928 | EF34: 30 | EG34: Строительные работы | EH34: 0 | EJ34: 1 | EK34: 22 | EL34: ТСН-2001.3-17. Водопровод и канализация - внутренние устройства | EM34: ТСН-2001.3-17-1 | EO34: Поправка: Гл.12.Прил.8.п.8. 5_12.00.01.11.003 Поправка: Гл.6.Прил.2.2.п.2.2.6_06.00.01.07.001 | EQ34: 0 | ER34: 2306.6 | ES34: 2202.04 | ET34: 8.97 | EU34: 1.01 | EV34: 95.59 | EW34: 8.58 | EX34: 0 | EY34: 0 | FQ34: 0 | FR34: 0 | FS34: 0 | FX34: 109 | FY34: 61 | GD34: 1 | GF34: 486003536 | GG34: 2 | GH34: 1 | GI34: 2 | GJ34: 0 | GK34: 0 | GL34: =ROUND(IF(AND(BH34=3,BI34=3,FS34<>0),P34,0),2) -> 0 | GM34: =ROUND(O34+X34+Y34,2)+GX34 -> 76.97 | GN34: =IF(OR(BI34=0,BI34=1),GM34-GX34,0) -> 76.97 | GO34: =IF(BI34=2,GM34-GX34,0) -> 0 | GP34: =IF(BI34=4,GM34-GX34,0) -> 0 | GR34: 0 | GS34: 3 | GT34: 0 | GV34: =ROUND((GT34),6) -> 0 | GW34: 1 | GX34: =ROUND(HC34*I34,2) -> 0 | HA34: 0 | HB34: 0 | HC34: =GV34*GW34 -> 0 | HS34: 0 | IK34: 0
A35: 17 | B35: 1 | E35: 4 | F35: 3.17-2-13 | G35: Установка гарнитуры туалетной: вешалок, подстаканников, дозаторов настенных и т.п./диспенсер | H35: 100 шт. | I35: =ROUND(3/100,9) -> 0.03 | J35: 0 | K35: =ROUND(3/100,9) -> 0.03 | O35: =ROUND(CP35,2) -> 267.95 | P35: =ROUND((ROUND((AC35*AW35*I35),2)*BC35),2) -> 49.55 | Q35: =(ROUND((ROUND(((((ET35*1.1)*1.25))*AV35*I35),2)*BB35),2)+ROUND((ROUND(((AE35-(((EU35*1.1)*1.25)))*AV35*I35),2)*BS35),2)) -> 5.59 | R35: =(ROUND((ROUND(((((EU35*1.1)*1.25))*AV35*I35),2)*BS35),2)+ROUND((ROUND(((AE35-(((EU35*1.1)*1.25)))*AV35*I35),2)*BS35),2)) -> 2.2 | S35: =ROUND((ROUND((AF35*AV35*I35),2)*BA35),2) -> 212.81 | T35: =ROUND(CU35*I35,2) -> 0 | U35: =CV35*I35 -> 0.34742694 | V35: =CW35*I35 -> 0 | W35: =ROUND(CX35*I35,2) -> 0 | X35: =(ROUND((((S35+ROUND((ROUND(((((EU35*1.1)*1.25))*AV35*I35),2)*BS35),2))*AT35)/100),2)+ROUND(((ROUND((ROUND(((AE35-(((EU35*1.1)*1.25)))*AV35*I35),2)*BS35),2)*AT35)/100),2)) -> 234.36 | Y35: =(ROUND((((S35+ROUND((ROUND(((((EU35*1.1)*1.25))*AV35*I35),2)*BS35),2))*AU35)/100),2)+ROUND(((ROUND((ROUND(((AE35-(((EU35*1.1)*1.25)))*AV35*I35),2)*BS35),2)*AU35)/100),2)) -> 131.16 | AA35: 59499215 | AB35: =ROUND((AC35+AD35+AF35),6) -> 2335.2951 | AC35: =ROUND((((ES35*1)*1)),6) -> 2202.04 | AD35: =ROUND((((((ET35*1.1)*1.25))-(((EU35*1.1)*1.25)))+AE35),6) -> 12.33375 | AE35: =ROUND((((EU35*1.1)*1.25)),6) -> 1.38875 | AF35: =ROUND((((EV35*1.1)*1.15)),6) -> 120.92135 | AG35: =ROUND((AP35),6) -> 0 | AH35: =(((EW35*1.1)*1.15)) -> 10.8537 | AI35: =(((EX35*1.1)*1.25)) -> 0 | AJ35: =(AS35) -> 0 | AK35: 2306.6 | AL35: 2202.04 | AM35: 8.97 | AN35: 1.01 | AO35: 95.59 | AP35: 0 | AQ35: 8.58 | AR35: 0 | AS35: 0 | AT35: 109 | AU35: 61 | AV35: 1.067 | AW35: 1 | AZ35: 1 | BA35: 54.99 | BB35: 14.34 | BC35: 0.75 | BH35: 0 | BI35: 1 | BJ35: ТСН-2001.3 Доп. 80, Сб. 17, т. 2, поз. 13 | BM35: 22 | BN35: 0 | BO35: 3.17-2-13 | BP35: 1 | BQ35: 30 | BR35: 0 | BS35: 54.99 | BT35: 1 | BU35: 1 | BV35: 1 | BW35: 1 | BX35: 1 | BZ35: 109 | CA35: 61 | CE35: 1566 | CF35: 0 | CG35: 0 | CM35: 0 | CN35: Поправка: Гл.12.Прил.8.п.8. 5_12.00.01.11.003 Наименование: При наличии усложненных условий производства работ (стесненность, сложность складирования и транспортной логистики, наличие в зоне производства работ действующего технологического оборудования или движения технологического транспорта и т.п.) для объектов, расположенных за пределами территории круговой магистральной системы улиц "Садовое кольцо" и за пределами Третьего транспортного кольца города Москвы пунктов "а" и "б", но в пределах Московской кольцевой автомобильной дороги Поправка: Гл.6.Прил.2.2.п.2.2.6_06.00.01.07.001 Наименование: При выполнении при капитальном ремонте и реконструкции работ, аналогичных технологическим процессам, характерным для нового строительства, и отсутствующих в сборниках на ремонтно-строительные работы ТСН-2001.6 | CO35: 0 | CP35: =(P35+Q35+S35) -> 267.95 | CQ35: =ROUND((ROUND((AC35*AW35*1),2)*BC35),2) -> 1651.53 | CR35: =(ROUND((ROUND(((((ET35*1.1)*1.25))*AV35*1),2)*BB35),2)+ROUND((ROUND(((AE35-(((EU35*1.1)*1.25)))*AV35*1),2)*BS35),2)) -> 188.71 | CS35: =(ROUND((ROUND(((((EU35*1.1)*1.25))*AV35*1),2)*BS35),2)+ROUND((ROUND(((AE35-(((EU35*1.1)*1.25)))*AV35*1),2)*BS35),2)) -> 81.39 | CT35: =ROUND((ROUND((AF35*AV35*1),2)*BA35),2) -> 7094.81 | CU35: =AG35 -> 0 | CV35: =(AH35*AV35) -> 11.580898 | CW35: =AI35 -> 0 | CX35: =AJ35 -> 0 | CY35: =(ROUND((((S35+ROUND((ROUND(((((EU35*1.1)*1.25))*AV35*1),2)*BS35),2))*AT35)/100),2)+ROUND(((ROUND((ROUND(((AE35-(((EU35*1.1)*1.25)))*AV35*1),2)*BS35),2)*AT35)/100),2)) -> 320.68 | CZ35: =(ROUND((((S35+ROUND((ROUND(((((EU35*1.1)*1.25))*AV35*1),2)*BS35),2))*AU35)/100),2)+ROUND(((ROUND((ROUND(((AE35-(((EU35*1.1)*1.25)))*AV35*1),2)*BS35),2)*AU35)/100),2)) -> 179.46 | DB35: 15 | DD35: *1)*1 | DE35: *1,1)*1,25 | DF35: *1,1)*1,25 | DG35: *1,1)*1,15 | DI35: *1,1)*1,15 | DJ35: *1,1)*1,25 | DN35: 0 | DO35: 0 | DP35: 1 | DQ35: 1 | DU35: 1010 | DV35: 100 шт. | DW35: 100 шт. | DX35: 100 | EE35: 59298928 | EF35: 30 | EG35: Строительные работы | EH35: 0 | EJ35: 1 | EK35: 22 | EL35: ТСН-2001.3-17. Водопровод и канализация - внутренние устройства | EM35: ТСН-2001.3-17-1 | EO35: Поправка: Гл.12.Прил.8.п.8. 5_12.00.01.11.003 Поправка: Гл.6.Прил.2.2.п.2.2.6_06.00.01.07.001 | EQ35: 0 | ER35: 2306.6 | ES35: 2202.04 | ET35: 8.97 | EU35: 1.01 | EV35: 95.59 | EW35: 8.58 | EX35: 0 | EY35: 0 | FQ35: 0 | FR35: 0 | FS35: 0 | FX35: 109 | FY35: 61 | GD35: 1 | GF35: 486003536 | GG35: 2 | GH35: 1 | GI35: 2 | GJ35: 0 | GK35: 0 | GL35: =ROUND(IF(AND(BH35=3,BI35=3,FS35<>0),P35,0),2) -> 0 | GM35: =ROUND(O35+X35+Y35,2)+GX35 -> 633.47 | GN35: =IF(OR(BI35=0,BI35=1),GM35-GX35,0) -> 633.47 | GO35: =IF(BI35=2,GM35-GX35,0) -> 0 | GP35: =IF(BI35=4,GM35-GX35,0) -> 0 | GR35: 0 | GS35: 3 | GT35: 0 | GV35: =ROUND((GT35),6) -> 0 | GW35: 1 | GX35: =ROUND(HC35*I35,2) -> 0 | HA35: 0 | HB35: 0 | HC35: =GV35*GW35 -> 0 | HS35: 0 | IK35: 0
A36: 17 | B36: 1 | E36: 5 | F36: 3.17-2-13 | G36: Установка гарнитуры туалетной: вешалок, подстаканников, дозаторов настенных и т.п./ туалетный ершик с креплением на стену | H36: 100 шт. | I36: =ROUND(1/100,9) -> 0.01 | J36: 0 | K36: =ROUND(1/100,9) -> 0.01 | O36: =ROUND(CP36,2) -> 23.44 | P36: =ROUND((ROUND((AC36*AW36*I36),2)*BC36),2) -> 22.02 | Q36: =(ROUND((ROUND(((((ET36*1.1)*1.25))*AV36*I36),2)*BB36),2)+ROUND((ROUND(((AE36-(((EU36*1.1)*1.25)))*AV36*I36),2)*BS36),2)) -> 0.13 | R36: =(ROUND((ROUND(((((EU36*1.1)*1.25))*AV36*I36),2)*BS36),2)+ROUND((ROUND(((AE36-(((EU36*1.1)*1.25)))*AV36*I36),2)*BS36),2)) -> 0.01 | S36: =ROUND((ROUND((AF36*AV36*I36),2)*BA36),2) -> 1.29 | T36: =ROUND(CU36*I36,2) -> 0 | U36: =CV36*I36 -> 0.11580898 | V36: =CW36*I36 -> 0 | W36: =ROUND(CX36*I36,2) -> 0 | X36: =(ROUND((((S36+ROUND((ROUND(((((EU36*1.1)*1.25))*AV36*I36),2)*BS36),2))*AT36)/100),2)+ROUND(((ROUND((ROUND(((AE36-(((EU36*1.1)*1.25)))*AV36*I36),2)*BS36),2)*AT36)/100),2)) -> 1.42 | Y36: =(ROUND((((S36+ROUND((ROUND(((((EU36*1.1)*1.25))*AV36*I36),2)*BS36),2))*AU36)/100),2)+ROUND(((ROUND((ROUND(((AE36-(((EU36*1.1)*1.25)))*AV36*I36),2)*BS36),2)*AU36)/100),2)) -> 0.79 | AA36: 59499218 | AB36: =ROUND((AC36+AD36+AF36),6) -> 2335.2951 | AC36: =ROUND((((ES36*1)*1)),6) -> 2202.04 | AD36: =ROUND((((((ET36*1.1)*1.25))-(((EU36*1.1)*1.25)))+AE36),6) -> 12.33375 | AE36: =ROUND((((EU36*1.1)*1.25)),6) -> 1.38875 | AF36: =ROUND((((EV36*1.1)*1.15)),6) -> 120.92135 | AG36: =ROUND((AP36),6) -> 0 | AH36: =(((EW36*1.1)*1.15)) -> 10.8537 | AI36: =(((EX36*1.1)*1.25)) -> 0 | AJ36: =(AS36) -> 0 | AK36: 2306.6 | AL36: 2202.04 | AM36: 8.97 | AN36: 1.01 | AO36: 95.59 | AP36: 0 | AQ36: 8.58 | AR36: 0 | AS36: 0 | AT36: 109 | AU36: 61 | AV36: 1.067 | AW36: 1 | AZ36: 1 | BA36: 1 | BB36: 1 | BC36: 1 | BH36: 0 | BI36: 1 | BJ36: ТСН-2001.3 Доп. 80, Сб. 17, т. 2, поз. 13 | BM36: 22 | BN36: 0 | BO36: 3.17-2-13 | BP36: 1 | BQ36: 30 | BR36: 0 | BS36: 1 | BT36: 1 | BU36: 1 | BV36: 1 | BW36: 1 | BX36: 1 | BZ36: 109 | CA36: 61 | CE36: 1566 | CF36: 0 | CG36: 0 | CM36: 0 | CN36: Поправка: Гл.12.Прил.8.п.8. 5_12.00.01.11.003 Наименование: При наличии усложненных условий производства работ (стесненность, сложность складирования и транспортной логистики, наличие в зоне производства работ действующего технологического оборудования или движения технологического транспорта и т.п.) для объектов, расположенных за пределами территории круговой магистральной системы улиц "Садовое кольцо" и за пределами Третьего транспортного кольца города Москвы пунктов "а" и "б", но в пределах Московской кольцевой автомобильной дороги Поправка: Гл.6.Прил.2.2.п.2.2.6_06.00.01.07.001 Наименование: При выполнении при капитальном ремонте и реконструкции работ, аналогичных технологическим процессам, характерным для нового строительства, и отсутствующих в сборниках на ремонтно-строительные работы ТСН-2001.6 | CO36: 0 | CP36: =(P36+Q36+S36) -> 23.44 | CQ36: =ROUND((ROUND((AC36*AW36*1),2)*BC36),2) -> 2202.04 | CR36: =(ROUND((ROUND(((((ET36*1.1)*1.25))*AV36*1),2)*BB36),2)+ROUND((ROUND(((AE36-(((EU36*1.1)*1.25)))*AV36*1),2)*BS36),2)) -> 13.16 | CS36: =(ROUND((ROUND(((((EU36*1.1)*1.25))*AV36*1),2)*BS36),2)+ROUND((ROUND(((AE36-(((EU36*1.1)*1.25)))*AV36*1),2)*BS36),2)) -> 1.48 | CT36: =ROUND((ROUND((AF36*AV36*1),2)*BA36),2) -> 129.02 | CU36: =AG36 -> 0 | CV36: =(AH36*AV36) -> 11.580898 | CW36: =AI36 -> 0 | CX36: =AJ36 -> 0 | CY36: =(ROUND((((S36+ROUND((ROUND(((((EU36*1.1)*1.25))*AV36*1),2)*BS36),2))*AT36)/100),2)+ROUND(((ROUND((ROUND(((AE36-(((EU36*1.1)*1.25)))*AV36*1),2)*BS36),2)*AT36)/100),2)) -> 3.02 | CZ36: =(ROUND((((S36+ROUND((ROUND(((((EU36*1.1)*1.25))*AV36*1),2)*BS36),2))*AU36)/100),2)+ROUND(((ROUND((ROUND(((AE36-(((EU36*1.1)*1.25)))*AV36*1),2)*BS36),2)*AU36)/100),2)) -> 1.69 | DB36: 17 | DD36: *1)*1 | DE36: *1,1)*1,25 | DF36: *1,1)*1,25 | DG36: *1,1)*1,15 | DI36: *1,1)*1,15 | DJ36: *1,1)*1,25 | DN36: 0 | DO36: 0 | DP36: 1 | DQ36: 1 | DU36: 1010 | DV36: 100 шт. | DW36: 100 шт. | DX36: 100 | EE36: 59298928 | EF36: 30 | EG36: Строительные работы | EH36: 0 | EJ36: 1 | EK36: 22 | EL36: ТСН-2001.3-17. Водопровод и канализация - внутренние устройства | EM36: ТСН-2001.3-17-1 | EO36: Поправка: Гл.12.Прил.8.п.8. 5_12.00.01.11.003 Поправка: Гл.6.Прил.2.2.п.2.2.6_06.00.01.07.001 | EQ36: 0 | ER36: 2306.6 | ES36: 2202.04 | ET36: 8.97 | EU36: 1.01 | EV36: 95.59 | EW36: 8.58 | EX36: 0 | EY36: 0 | FQ36: 0 | FR36: 0 | FS36: 0 | FX36: 109 | FY36: 61 | GD36: 1 | GF36: -907614113 | GG36: 2 | GH36: 1 | GI36: 2 | GJ36: 0 | GK36: 0 | GL36: =ROUND(IF(AND(BH36=3,BI36=3,FS36<>0),P36,0),2) -> 0 | GM36: =ROUND(O36+X36+Y36,2)+GX36 -> 25.65 | GN36: =IF(OR(BI36=0,BI36=1),GM36-GX36,0) -> 25.65 | GO36: =IF(BI36=2,GM36-GX36,0) -> 0 | GP36: =IF(BI36=4,GM36-GX36,0) -> 0 | GR36: 0 | GS36: 3 | GT36: 0 | GV36: =ROUND((GT36),6) -> 0 | GW36: 1 | GX36: =ROUND(HC36*I36,2) -> 0 | HA36: 0 | HB36: 0 | HC36: =GV36*GW36 -> 0 | HS36: 0 | IK36: 0
