Workbook

Sheet 02-01-06
A1: =Source!B1 -> Smeta.RU (495) 974-1589
J2: Форма № 4б
A3: Капитальный ремонт здания Государственного бюджетного общеобразовательного учреждения города Москвы "Школа №236" по адресу: г. Москва, улица Клязьминская, дом 7, корпус 4. | AP3: Капитальный ремонт здания Государственного бюджетного общеобразовательного учреждения города Москвы "Школа №236" по адресу: г. Москва, улица Клязьминская, дом 7, корпус 4. 02-01-06 Отопление
A4: (наименование стройки и/или объекта)
A6: =CONCATENATE( "ЛОКАЛЬНАЯ СМЕТА № ",IF(Source!F20<>"Новая локальная смета", Source!F20, "")) -> ЛОКАЛЬНАЯ СМЕТА № 02-01-06
A8: =IF(Source!G20<>"Новая локальная смета", Source!G20, "") -> Отопление
A9: (наименование работ и затрат)
A11: =CONCATENATE( "Основание: чертежи № ", Source!J20) -> Основание: чертежи № 2024-00272-00-0-ИОС4.1
I13: В базисном уровне цен | J13: В текущем уровне цен
E14: Сметная стоимость | I14: =I15+I16+I17+I18 -> 1090.71 | J14: =J15+J16+J17+J18 -> 14180.73 | K14: тыс.руб.
E15: Строительные работы | I15: =ROUND((Source!F411)/1000, 2) -> 1065.26 | J15: =ROUND((Source!P411)/1000, 2) -> 13845.9 | K15: тыс.руб.
E16: Работы по монтажу оборудования | I16: =ROUND((Source!F412)/1000, 2) -> 24.13 | J16: =ROUND((Source!P412)/1000, 2) -> 326.58 | K16: тыс.руб.
E17: Оборудование | I17: =ROUND((Source!F403)/1000, 2) -> 1.32 | J17: =ROUND((Source!P403)/1000, 2) -> 8.25 | K17: тыс.руб.
E18: Прочие работы и затраты | I18: =ROUND((Source!F413+Source!F414)/1000, 2) -> 0 | J18: =ROUND((Source!P413+Source!P414)/1000, 2) -> 0 | K18: тыс.руб.
E19: Средства на оплату труда | I19: =(Source!F409+ Source!F408)/1000 -> 41.32684 | J19: =((Source!P409 + Source!P408)/1000) -> 2272.5629 | K19: тыс.руб.
E20: Затраты труда | I20: =Source!F416 -> 3249.222 | K20: чел.-ч.
E21: Кроме того:
E22: Возврат материалов | I22: =SUM(Y28:Y595)/1000 -> 0 | J22: =SUM(Z28:Z595)/1000 -> 0 | K22: тыс.руб.
A24: Составлен(а) по ТСН-2001 с учетом Дополнения №: 80
A25: № и период сборника коэффициентов (индексов) пересчета: Коэффициенты к ТСН-2001 МГЭ Дополнение 80, ремонт №217/80 III квартал 2025 года и Коэффициенты к ТСН-2001.13-2 Дополнение 46 №62/46 III квартал 2025 года | AP25: № и период сборника коэффициентов (индексов) пересчета: Коэффициенты к ТСН-2001 МГЭ Дополнение 80, ремонт №217/80 III квартал 2025 года и Коэффициенты к ТСН-2001.13-2 Дополнение 46 №62/46 III квартал 2025 года
A26: № п/п | B26: Шифр расценки и коды ресурсов | C26: Наименование работ и затрат | D26: Ед. изм. | E26: Кол-во единиц | F26: Цена на ед. изм., руб. | G26: Попра- вочные коэффи- циенты | H26: Коэффи- циенты зимних удорожа- ний | I26: Всего в ценах на январь 2000 года, руб. | J26: Коэффи- циенты (индек- сы) пере- счета, нормы НР и СП | K26: ВСЕГО затрат в текущем уровне цен, руб.
A27: 1 | B27: 2 | C27: 3 | D27: 4 | E27: 5 | F27: 6 | G27: 7 | H27: 8 | I27: 9 | J27: 10 | K27: 11
A29: =CONCATENATE("Раздел: ",IF(Source!G24<>"Новый раздел", Source!G24, "")) -> Раздел: Конвекторы
A30: 1 | B30: =Source!F28 -> 4.8-254-1 | C30: Монтаж приборов нагревательных, электрополотенце/прим. конвектор электрический настенный 1000 Вт | D30: =Source!H28 -> 1 ШТ. | E30: =Source!I28 -> 3 | Q30: =Source!X28 -> 45.28 | R30: =Source!X29 -> 2489.93 | S30: =Source!Y28 -> 23.81 | T30: =Source!Y29 -> 1309.14 | U30: =ROUND((175/100)*ROUND(Source!R28, 2), 2) -> 0.79 | V30: =ROUND((0/100)*ROUND(Source!R29, 2), 2) -> 0 | AC30: 0
C31: ="Объем: "&Source!I28&"=1+"&"2" -> Объем: 3=1+2
C32: ЗП | F32: =Source!AO28 -> 13.38 | G32: =Source!DG28 -> *1,1 | H32: =Source!AV29 -> 1.047 | I32: =Source!S28 -> 46.23 | J32: =IF(Source!BA29<> 0, Source!BA29, 1) -> 54.99 | K32: =Source!S29 -> 2542.19
C33: ЭМ | F33: =Source!AM28 -> 0.91 | G33: =Source!DE28 -> *1,1 | H33: =Source!AV29 -> 1.047 | I33: =Source!Q28 -> 3.14 | J33: =IF(Source!BB29<> 0, Source!BB29, 1) -> 15.59 | K33: =Source!Q29 -> 48.95
C34: в т.ч. ЗПМ | F34: =Source!AN28 -> 0.13 | G34: =Source!DF28 -> *1,1 | H34: =Source!AV29 -> 1.047 | I34: =Source!R28 -> 0.45 | J34: =IF(Source!BS29<> 0, Source!BS29, 1) -> 54.99 | K34: =Source!R29 -> 24.75
C35: МР | F35: =Source!AL28 -> 0.41 | G35: =Source!DD28 | H35: =Source!AW29 -> 1 | I35: =Source!P28 -> 1.23 | J35: =IF(Source!BC29<> 0, Source!BC29, 1) -> 3.95 | K35: =Source!P29 -> 4.86
C36: НР от ФОТ | D36: % | E36: =Source!BZ29 -> 97 | I36: =SUM(Q30:Q35) -> 45.28 | J36: =Source!AT29 -> 97 | K36: =SUM(R30:R35) -> 2489.93
C37: СП от ФОТ | D37: % | E37: =Source!CA29 -> 51 | I37: =SUM(S30:S36) -> 23.81 | J37: =Source!AU29 -> 51 | K37: =SUM(T30:T36) -> 1309.14
C38: ЗТР | D38: чел-ч | E38: =Source!AQ28 -> 1.03 | G38: =Source!DI28 -> *1,1 | H38: =Source!AV29 -> 1.047 | I38: =Source!U28 -> 3.558753
C39: ВСЕГО работ по позиции: | H39: =I32+I33+I35+I36+I37+0-0-0 -> 119.69 | J39: =K32+K33+K35+K36+K37+0-0-0 -> 6395.07
C40: ВСЕГО оборудование по позиции: | H40: =0+0 -> 0 | J40: =0+0 -> 0
C41: ВСЕГО по позиции: | H41: =I32+I33+I35+I36+I37+0 -> 119.69 | J41: =K32+K33+K35+K36+K37+0 -> 6395.07 | O41: =I32+I33+I35+I36+I37+0 -> 119.69 | P41: =K32+K33+K35+K36+K37+0 -> 6395.07
A43: 2 | B43: =Source!F30 -> 13.1-11-142 | C43: ОБОРУДОВАНИЕ:_x000D_ Конвектор электрический, номинальная мощность 0,5 кВт, для отопления жилых и промышленных помещений | D43: =Source!H30 -> шт. | E43: =Source!I30 -> 1 | F43: =Source!AL30 -> 388.69 | G43: =Source!DD30 | H43: =Source!AW31 -> 1 | I43: =Source!P30 -> 388.69 | J43: =IF(Source!BC31<> 0, Source!BC31, 1) -> 6.57 | K43: =Source!P31 -> 2553.69 | Q43: =Source!X30 -> 0 | R43: =Source!X31 -> 0 | S43: =Source!Y30 -> 0 | T43: =Source!Y31 -> 0 | U43: =ROUND((175/100)*ROUND(Source!R30, 2), 2) -> 0 | V43: =ROUND((0/100)*ROUND(Source!R31, 2), 2) -> 0 | AC43: 5
C44: ВСЕГО по позиции: | H44: =I43+0 -> 388.69 | J44: =K43+0 -> 2553.69 | O44: =I43+0 -> 388.69 | P44: =K43+0 -> 2553.69
A46: 3 | B46: =Source!F32 -> 13.1-11-143 | C46: ОБОРУДОВАНИЕ:_x000D_ Конвектор электрический, номинальная мощность 1 кВт, для отопления жилых и промышленных помещений | D46: =Source!H32 -> шт. | E46: =Source!I32 -> 2 | F46: =Source!AL32 -> 464.74 | G46: =Source!DD32 | H46: =Source!AW33 -> 1 | I46: =Source!P32 -> 929.48 | J46: =IF(Source!BC33<> 0, Source!BC33, 1) -> 6.13 | K46: =Source!P33 -> 5697.71 | Q46: =Source!X32 -> 0 | R46: =Source!X33 -> 0 | S46: =Source!Y32 -> 0 | T46: =Source!Y33 -> 0 | U46: =ROUND((175/100)*ROUND(Source!R32, 2), 2) -> 0 | V46: =ROUND((0/100)*ROUND(Source!R33, 2), 2) -> 0 | AC46: 5
C47: ВСЕГО по позиции: | H47: =I46+0 -> 929.48 | J47: =K46+0 -> 5697.71 | O47: =I46+0 -> 929.48 | P47: =K46+0 -> 5697.71
A50: =CONCATENATE("Итого по разделу: ",IF(Source!G35<>"Новый раздел", Source!G35, "")) -> Итого по разделу: Конвекторы | H50: =SUM(O29:O49) -> 1437.86 | J50: =SUM(P29:P49) -> 14646.47
...

Sheet Ведомость объемов работ
A1: =Source!B1 -> Smeta.RU (495) 974-1589
B4: =CONCATENATE("Ведомость объемов работ ", IF(Source!AN15<>"", Source!AN15," ")) -> Ведомость объемов работ
B5: =CONCATENATE(Source!F12, " ", Source!G12) -> 02-01-06 Отопление
A8: № п/п | B8: № в ЛСР | C8: Наименование работ и затрат | D8: Единица измерения | E8: Количество | F8: Ссылка на чертежи, спецификации | G8: Формула расчета, расчет объемов работ и расхода материалов | H8: Примечание
A9: 1 | B9: 2 | C9: 3 | D9: 4 | E9: 5 | F9: 6 | G9: 7 | H9: 8
A10: =CONCATENATE("Локальная смета: ", Source!G20) -> Локальная смета: Отопление
A11: =CONCATENATE("Раздел: ", Source!G24) -> Раздел: Конвекторы
A12: 1 | B12: =Source!E28 -> 1 | C12: =Source!G28 -> Монтаж приборов нагревательных, электрополотенце/прим. конвектор электрический настенный 1000 Вт | D12: 1 ШТ. | E12: =Source!I28 -> 3 | F12: =Source!U24 | G12: ="=1+"&"2" -> =1+2
A13: 2 | B13: =Source!E30 -> 2 | C13: =Source!G30 -> Конвектор электрический, номинальная мощность 0,5 кВт, для отопления жилых и промышленных помещений | D13: шт. | E13: =Source!I30 -> 1 | F13: =Source!U24 | G13: =Source!I30 -> 1
A14: 3 | B14: =Source!E32 -> 3 | C14: =Source!G32 -> Конвектор электрический, номинальная мощность 1 кВт, для отопления жилых и промышленных помещений | D14: шт. | E14: =Source!I32 -> 2 | F14: =Source!U24 | G14: =Source!I32 -> 2
A15: =CONCATENATE("Раздел: ", Source!G65) -> Раздел: Радиаторы отопления
A16: 4 | B16: =Source!E69 -> 4 | C16: =Source!G69 -> Установка радиаторов стальных панельных однорядных с креплением к стене длиной до 1600 мм | D16: 100 шт. | E16: =Source!I69 -> 0.36 | F16: =Source!U65 | G16: ="=(1+"&"3+"&"2+"&"20+"&"1+"&"9)/"&"100" -> =(1+3+2+20+1+9)/100
A17: 5 | B17: =Source!E71 -> 5 | C17: =Source!G71 -> Радиатор стальной трубчатый GUARDO TORRE 3D, 400 мм (BK-VER-BLACK), черный 3D-400-350 (мощность 0,336 кВт) | D17: ШТ | E17: =Source!I71 -> 1 | F17: =Source!U65 | G17: =Source!I71 -> 1
A18: 6 | B18: =Source!E73 -> 6 | C18: =Source!G73 -> Радиатор стальной трубчатый GUARDO TORRE 3D, 400 мм (BK-VER-BLACK), черный 3D-400-750 (мощность 0,663 кВт) | D18: ШТ | E18: =Source!I73 -> 3 | F18: =Source!U65 | G18: =Source!I73 -> 3
A19: 7 | B19: =Source!E75 -> 7 | C19: =Source!G75 -> Радиатор стальной трубчатый GUARDO TORRE 3D, 400 мм (BK-VER-WHITE), белый 3D-400-1650 (мощность 1,330 кВт) | D19: ШТ | E19: =Source!I75 -> 2 | F19: =Source!U65 | G19: =Source!I75 -> 2
A20: 8 | B20: =Source!E77 -> 8 | C20: =Source!G77 -> Радиатор стальной трубчатый GUARDO TORRE 3D, 400 мм (BK-VER-WHITE), белый 3D-400-1950 (мощность 1,552 кВт) | D20: ШТ | E20: =Source!I77 -> 20 | F20: =Source!U65 | G20: =Source!I77 -> 20
A21: 9 | B21: =Source!E79 -> 9 | C21: =Source!G79 -> Радиатор стальной трубчатый GUARDO TORRE 3D, 400 мм (BK-VER-WHITE), белый 3D-400-350 (мощность 0,336 к Вт) | D21: ШТ | E21: =Source!I79 -> 1 | F21: =Source!U65 | G21: =Source!I79 -> 1
A22: 10 | B22: =Source!E81 -> 10 | C22: =Source!G81 -> Радиатор стальной трубчатый GUARDO TORRE 3D, 400 мм (BK-VER-WHITE), белый 3D-400-750 (мощность 0,663 кВт) | D22: ШТ | E22: =Source!I81 -> 9 | F22: =Source!U65 | G22: =Source!I81 -> 9
A23: 11 | B23: =Source!E83 -> 11 | C23: =Source!G83 -> Установка радиаторов стальных панельных однорядных с креплением к стене длиной до 1600 мм | D23: 100 шт. | E23: =Source!I83 -> 0.1 | F23: =Source!U65 | G23: ="=(1+"&"2+"&"1+"&"1+"&"3+"&"2)/"&"100" -> =(1+2+1+1+3+2)/100
A24: 12 | B24: =Source!E85 -> 12 | C24: =Source!G85 -> Стальной панельный радиатор, гигиеническое исполнение Royal Thermo H 20-0400-0400 (тепловая мощность 0,488 кВт) | D24: ШТ | E24: =Source!I85 -> 1 | F24: =Source!U65 | G24: =Source!I85 -> 1
A25: 13 | B25: =Source!E87 -> 13 | C25: =Source!G87 -> Стальной панельный радиатор, гигиеническое исполнение Royal Thermо H 20-0400-0600 (тепловая мощность 0,732 кВт) | D25: ШТ | E25: =Source!I87 -> 2 | F25: =Source!U65 | G25: =Source!I87 -> 2
A26: 14 | B26: =Source!E89 -> 14 | C26: =Source!G89 -> Стальной панельный радиатор, гигиеническое исполнение Royal Thermо H 20-0400-0800 (тепловая мощность 0,9759 кВт) | D26: ШТ | E26: =Source!I89 -> 1 | F26: =Source!U65 | G26: =Source!I89 -> 1
A27: 15 | B27: =Source!E91 -> 15 | C27: =Source!G91 -> Стальной панельный радиатор, гигиеническое исполнение Royal Thermо H 20-0400-1000 (тепловая мощность1,2199 кВт) | D27: ШТ | E27: =Source!I91 -> 1 | F27: =Source!U65 | G27: =Source!I91 -> 1
A28: 16 | B28: =Source!E93 -> 16 | C28: =Source!G93 -> Стальной панельный радиатор, гигиеническое исполнение Royal Thermо H 20-0400-1200 (тепловая мощность 1,4639 кВт) | D28: ШТ | E28: =Source!I93 -> 3 | F28: =Source!U65 | G28: =Source!I93 -> 3
A29: 17 | B29: =Source!E95 -> 17 | C29: =Source!G95 -> Стальной панельный радиатор, гигиеническое исполнение Royal Thermо H 20-0400-1400 (тепловая мощность 1,7079 кВт) | D29: ШТ | E29: =Source!I95 -> 2 | F29: =Source!U65 | G29: =Source!I95 -> 2
A30: 18 | B30: =Source!E97 -> 18 | C30: =Source!G97 -> Установка радиаторов стальных панельных однорядных с креплением к стене длиной до 1600 мм | D30: 100 шт. | E30: =Source!I97 -> 0.16 | F30: =Source!U65 | G30: ="=(1+"&"5+"&"8+"&"2)/"&"100" -> =(1+5+8+2)/100
A31: 19 | B31: =Source!E99 -> 19 | C31: =Source!G99 -> Стальной панельный радиатор, гигиеническое исполнение Royal Thermо H 10-0400-0600 (тепловая мощность 0,4221 кВт) | D31: ШТ | E31: =Source!I99 -> 1 | F31: =Source!U65 | G31: =Source!I99 -> 1
A32: 20 | B32: =Source!E101 -> 20 | C32: =Source!G101 -> Стальной панельный радиатор, гигиеническое исполнение Royal Thermо H 10-0400-1000 (тепловая мощность 0,7035 кВт) | D32: ШТ | E32: =Source!I101 -> 5 | F32: =Source!U65 | G32: =Source!I101 -> 5
A33: 21 | B33: =Source!E103 -> 21 | C33: =Source!G103 -> Стальной панельный радиатор, гигиеническое исполнение Royal Thermо H 10-0400-1400 (тепловая мощность 0,9849 кВт) | D33: ШТ | E33: =Source!I103 -> 8 | F33: =Source!U65 | G33: =Source!I103 -> 8
A34: 22 | B34: =Source!E105 -> 22 | C34: =Source!G105 -> Стальной панельный радиатор, гигиеническое исполнение Royal Thermо H 10-0400-1600 (тепловая мощность 1,1256 кВт) | D34: ШТ | E34: =Source!I105 -> 2 | F34: =Source!U65 | G34: =Source!I105 -> 2
A35: 23 | B35: =Source!E107 -> 23 | C35: =Source!G107 -> Установка радиаторов стальных панельных однорядных с креплением к стене длиной до 1600 мм | D35: 100 шт. | E35: =Source!I107 -> 0.01 | F35: =Source!U65 | G35: ="=1/"&"100" -> =1/100
A36: 24 | B36: =Source!E109 -> 24 | C36: =Source!G109 -> Стальной панельный радиатор, гигиеническое исполнение Royal Thermо H 30-0400-0600 (тепловая мощность 1,019 кВт) | D36: ШТ | E36: =Source!I109 -> 1 | F36: =Source!U65 | G36: =Source!I109 -> 1
A37: 25 | B37: =Source!E111 -> 25 | C37: =Source!G111 -> Установка радиаторов стальных панельных однорядных с креплением к стене длиной до 1600 мм | D37: 100 шт. | E37: =Source!I111 -> 1.44 | F37: =Source!U65 | G37: ="=(1+"&"43+"&"87+"&"13)/"&"100" -> =(1+43+87+13)/100
A38: 26 | B38: =Source!E113 -> 26 | C38: =Source!G113 -> Стальной панельный радиатор боковое подключение Royal Thermо С 11-0400-1000 (тепловая мощность 0,9956 кВт) | D38: ШТ | E38: =Source!I113 -> 1 | F38: =Source!U65 | G38: =Source!I113 -> 1
A39: 27 | B39: =Source!E115 -> 27 | C39: =Source!G115 -> Стальной панельный радиатор боковое подключение Royal Thermо С 11-0400-1200 (тепловая мощность 1.1948 кВт) | D39: ШТ | E39: =Source!I115 -> 43 | F39: =Source!U65 | G39: =Source!I115 -> 43
A40: 28 | B40: =Source!E117 -> 28 | C40: =Source!G117 -> Стальной панельный радиатор боковое подключение Royal Thermо С 11-0400-1400 (тепловая мощность 1.3939 кВт) | D40: ШТ | E40: =Source!I117 -> 87 | F40: =Source!U65 | G40: =Source!I117 -> 87
A41: 29 | B41: =Source!E119 -> 29 | C41: =Source!G119 -> Стальной панельный радиатор боковое подключение Royal Thermо С 11-0400-1600 (тепловая мощность 1.593 кВт) | D41: ШТ | E41: =Source!I119 -> 13 | F41: =Source!U65 | G41: =Source!I119 -> 13
A42: 30 | B42: =Source!E121 -> 30 | C42: =Source!G121 -> Установка радиаторов стальных панельных однорядных с креплением к стене длиной свыше 1600 до 2000 мм | D42: 100 шт. | E42: =Source!I121 -> 0.7 | F42: =Source!U65 | G42: ="=70/"&"100" -> =70/100
A43: 31 | B43: =Source!E123 -> 31 | C43: =Source!G123 -> Стальной панельный радиатор боковое подключение Royal Thermо С 11-0400-1800 (тепловая мощность 1.7922 кВт) | D43: ШТ | E43: =Source!I123 -> 70 | F43: =Source!U65 | G43: =Source!I123 -> 70
A44: 32 | B44: =Source!E125 -> 32 | C44: =Source!G125 -> Установка радиаторов стальных панельных однорядных с креплением к стене длиной до 1600 мм | D44: 100 шт. | E44: =Source!I125 -> 0.08 | F44: =Source!U65 | G44: ="=(1+"&"1+"&"4+"&"2)/"&"100" -> =(1+1+4+2)/100
...

Sheet Source
A1: 0 | B1: Smeta.RU (495) 974-1589 | D1: _PS_ | F1: 0 | G1: 0 | H1: 0 | I1: Smeta.RU | K1: 1 | L1: 74563 | M1: 10 | N1: 12 | O1: 0 | P1: 0 | Q1: 3
A4: 1 | B4: 1 | C4: -1 | G4: Капитальный ремонт здания Государственного бюджетного общеобразовательного учреждения города Москвы "Школа №236" по адресу: г. Москва, улица Клязьминская, дом 7, корпус 4 | EC4: 0
A12: 1 | B12: 465 | C12: 0 | D12: =ROW(A424) -> 424 | E12: 0 | G12: 02-01-06 Отопление | I12: 0 | J12: 2024-00272-00-0-ИОС4.1 | K12: 0 | L12: 0 | M12: 4098 | O12: 0 | P12: 0 | Q12: 0 | R12: 0 | S12: 0 | T12: 1 | V12: 0 | AB12: Соколова И.Н. | BB12: 0 | BH12: Сметные нормы списания | BI12: Коды ОКП для ТСН-2001 МГЭ Дополнение 80 | BJ12: 1 | BK12: 1 | BL12: 0 | BM12: 0 | BN12: 1 | BO12: 0 | BP12: 6 | BQ12: 2 | BR12: 1 | BS12: 1 | BT12: 0 | BU12: 0 | BV12: 0 | BW12: 0 | BX12: 0 | BZ12: Типовой расчет для ТСН-2001 МГЭ, Дополнение 80, ремонт (1) | CA12: Территориальные сметные нормативы для Москвы ТСН-2001 (МГЭ), дополнение 80 | CB12: Территориальные сметные нормативы для Москвы ТСН-2001 (МГЭ), дополнение 80 | CC12: Территориальные сметные нормативы для Москвы ТСН-2001 (МГЭ), дополнение 80 | CD12: Территориальные сметные нормативы для Москвы ТСН-2001 (МГЭ), дополнение 80 | CE12: Поправки для ТСН-2001 от 28.11.2025 г. доп.79 | CF12: 0 | CG12: 0 | CH12: 8200 | CK12: 80 | CQ12: Территориальные сметные нормативы для Москвы (ТСН-2001) | CR12: ТЕР | CS12: 41660 | CT12: 1 | CU12: 80 | CY12: 0 | EC12: 0
A15: 15 | B15: 1
A18: 52 | B18: =B424 -> 465 | C18: =C424 -> 1 | D18: =D424 -> 12 | E18: =E424 -> 0 | F18: =F424 | G18: =G424 -> 02-01-06 Отопление | O18: =O424 -> 1023233.4 | P18: =P424 -> 978175.47 | Q18: =Q424 -> 4626.47 | R18: =R424 -> 895.4 | S18: =S424 -> 40431.44 | T18: =T424 -> 0 | U18: =U424 -> 3249.222 | V18: =V424 -> 0 | ... GX18: =GX424 -> 0
A20: 3 | B20: 1 | D20: =ROW(A394) -> 394 | F20: 02-01-06 | G20: Отопление | I20: 0 | J20: 2024-00272-00-0-ИОС4.1 | K20: -1 | L20: 02-01-06 | S20: 0 | T20: 0 | V20: 0 | BX20: 0 | CF20: 0 | CG20: 0
A22: 52 | B22: =B394 -> 1 | C22: =C394 -> 3 | D22: =D394 -> 20 | E22: =E394 -> 0 | F22: =F394 -> 02-01-06 | G22: =G394 -> Отопление | O22: =O394 -> 1023233.4 | P22: =P394 -> 978175.47 | Q22: =Q394 -> 4626.47 | R22: =R394 -> 895.4 | S22: =S394 -> 40431.44 | T22: =T394 -> 0 | U22: =U394 -> 3249.222 | V22: =V394 -> 0 | ... GX22: =GX394 -> 0
A24: 4 | B24: 1 | D24: =ROW(A35) -> 35 | G24: Конвекторы | I24: 0 | K24: -1 | S24: 0 | T24: 0 | V24: 0 | BX24: 0 | CJ24: 0
A26: 52 | B26: =B35 -> 1 | C26: =C35 -> 4 | D26: =D35 -> 24 | E26: =E35 -> 0 | F26: =F35 | G26: =G35 -> Конвекторы | O26: =O35 -> 1368.77 | P26: =P35 -> 1319.4 | Q26: =Q35 -> 3.14 | R26: =R35 -> 0.45 | S26: =S35 -> 46.23 | T26: =T35 -> 0 | U26: =U35 -> 3.558753 | V26: =V35 -> 0 | ... GX26: =GX35 -> 0
A28: 17 | B28: 1 | C28: =ROW(SmtRes!A4) -> 4 | D28: =ROW(EtalonRes!A5) -> 5 | E28: 1 | F28: 4.8-254-1 | G28: Монтаж приборов нагревательных, электрополотенце/прим. конвектор электрический настенный 1000 Вт | H28: 1 ШТ. | I28: =ROUND(1+2,9) -> 3 | J28: 0 | K28: =ROUND(1+2,9) -> 3 | O28: =ROUND(CP28,2) -> 50.6 | P28: =ROUND((ROUND((AC28*AW28*I28),2)*BC28),2) -> 1.23 | Q28: =(ROUND((ROUND((((ET28*1.1))*AV28*I28),2)*BB28),2)+ROUND((ROUND(((AE28-((EU28*1.1)))*AV28*I28),2)*BS28),2)) -> 3.14 | R28: =(ROUND((ROUND((((EU28*1.1))*AV28*I28),2)*BS28),2)+ROUND((ROUND(((AE28-((EU28*1.1)))*AV28*I28),2)*BS28),2)) -> 0.45 | S28: =ROUND((ROUND((AF28*AV28*I28),2)*BA28),2) -> 46.23 | T28: =ROUND(CU28*I28,2) -> 0 | U28: =CV28*I28 -> 3.558753 | V28: =CW28*I28 -> 0 | W28: =ROUND(CX28*I28,2) -> 0 | X28: =(ROUND((((S28+ROUND((ROUND((((EU28*1.1))*AV28*I28),2)*BS28),2))*AT28)/100),2)+ROUND(((ROUND((ROUND(((AE28-((EU28*1.1)))*AV28*I28),2)*BS28),2)*AT28)/100),2)) -> 45.28 | Y28: =(ROUND((((S28+ROUND((ROUND((((EU28*1.1))*AV28*I28),2)*BS28),2))*AU28)/100),2)+ROUND(((ROUND((ROUND(((AE28-((EU28*1.1)))*AV28*I28),2)*BS28),2)*AU28)/100),2)) -> 23.81 | AA28: 60255014 | AB28: =ROUND((AC28+AD28+AF28),6) -> 16.129 | AC28: =ROUND((ES28),6) -> 0.41 | AD28: =ROUND(((((ET28*1.1))-((EU28*1.1)))+AE28),6) -> 1.001 | AE28: =ROUND(((EU28*1.1)),6) -> 0.143 | AF28: =ROUND(((EV28*1.1)),6) -> 14.718 | AG28: =ROUND((AP28),6) -> 0 | AH28: =((EW28*1.1)) -> 1.133 | AI28: =((EX28*1.1)) -> 0 | AJ28: =(AS28) -> 0 | AK28: 14.7 | AL28: 0.41 | AM28: 0.91 | AN28: 0.13 | AO28: 13.38 | AP28: 0 | AQ28: 1.03 | AR28: 0 | AS28: 0 | AT28: 97 | AU28: 51 | AV28: 1.047 | AW28: 1 | AZ28: 1 | BA28: 1 | BB28: 1 | BC28: 1 | BH28: 0 | BI28: 2 | BJ28: ТСН-2001.4 Доп. 68, Сб. 8, т. 254, поз. 1 | BM28: 67 | BN28: 58973374 | BO28: 4.8-254-1 | BP28: 1 | BQ28: 40 | BR28: 0 | BS28: 1 | BT28: 1 | BU28: 1 | BV28: 1 | BW28: 1 | BX28: 1 | BZ28: 97 | CA28: 51 | CE28: 1566 | CF28: 0 | CG28: 0 | CM28: 0 | CN28: Поправка: Гл.12.Прил.8.п.8. 5_12.00.01.11.003 Наименование: При наличии усложненных условий производства работ (стесненность, сложность складирования и транспортной логистики, наличие в зоне производства работ действующего технологического оборудования или движения технологического транспорта и т.п.) для объектов, расположенных за пределами территории круговой магистральной системы улиц "Садовое кольцо" и за пределами Третьего транспортного кольца города Москвы пунктов "а" и "б", но в пределах Московской кольцевой автомобильной дороги | CO28: 0 | CP28: =(P28+Q28+S28) -> 50.6 | CQ28: =ROUND((ROUND((AC28*AW28*1),2)*BC28),2) -> 0.41 | CR28: =(ROUND((ROUND((((ET28*1.1))*AV28*1),2)*BB28),2)+ROUND((ROUND(((AE28-((EU28*1.1)))*AV28*1),2)*BS28),2)) -> 1.05 | CS28: =(ROUND((ROUND((((EU28*1.1))*AV28*1),2)*BS28),2)+ROUND((ROUND(((AE28-((EU28*1.1)))*AV28*1),2)*BS28),2)) -> 0.15 | CT28: =ROUND((ROUND((AF28*AV28*1),2)*BA28),2) -> 15.41 | CU28: =AG28 -> 0 | CV28: =(AH28*AV28) -> 1.186251 | CW28: =AI28 -> 0 | CX28: =AJ28 -> 0 | CY28: =(ROUND((((S28+ROUND((ROUND((((EU28*1.1))*AV28*1),2)*BS28),2))*AT28)/100),2)+ROUND(((ROUND((ROUND(((AE28-((EU28*1.1)))*AV28*1),2)*BS28),2)*AT28)/100),2)) -> 44.99 | CZ28: =(ROUND((((S28+ROUND((ROUND((((EU28*1.1))*AV28*1),2)*BS28),2))*AU28)/100),2)+ROUND(((ROUND((ROUND(((AE28-((EU28*1.1)))*AV28*1),2)*BS28),2)*AU28)/100),2)) -> 23.65 | DE28: *1,1 | DF28: *1,1 | DG28: *1,1 | DI28: *1,1 | DJ28: *1,1 | DN28: 0 | DO28: 0 | DP28: 1 | DQ28: 1 | DU28: 1013 | DV28: 1 ШТ. | DW28: 1 ШТ. | DX28: 1 | EE28: 60088299 | EF28: 40 | EG28: Монтаж оборудования | EH28: 0 | EJ28: 2 | EK28: 67 | EL28: ТСН-2001.4-8. Электротехнические установки | EM28: ТСН-2001.4-8-1 | EO28: Поправка: Гл.12.Прил.8.п.8. 5_12.00.01.11.003 | EQ28: 0 | ER28: 14.7 | ES28: 0.41 | ET28: 0.91 | EU28: 0.13 | EV28: 13.38 | EW28: 1.03 | EX28: 0 | EY28: 0 | FQ28: 0 | FR28: 0 | FS28: 0 | FX28: 97 | FY28: 51 | GD28: 1 | GF28: -1561628963 | GG28: 2 | GH28: 1 | GI28: 2 | GJ28: 0 | GK28: 0 | GL28: =ROUND(IF(AND(BH28=3,BI28=3,FS28<>0),P28,0),2) -> 0 | GM28: =ROUND(O28+X28+Y28,2)+GX28 -> 119.69 | GN28: =IF(OR(BI28=0,BI28=1),GM28-GX28,0) -> 0 | GO28: =IF(BI28=2,GM28-GX28,0) -> 119.69 | GP28: =IF(BI28=4,GM28-GX28,0) -> 0 | GR28: 0 | GS28: 3 | GT28: 0 | GV28: =ROUND((GT28),6) -> 0 | GW28: 1 | GX28: =ROUND(HC28*I28,2) -> 0 | HA28: 0 | HB28: 0 | HC28: =GV28*GW28 -> 0 | HS28: 0 | IK28: 0
A29: 17 | B29: 1 | C29: =ROW(SmtRes!A8) -> 8 | D29: =ROW(EtalonRes!A10) -> 10 | E29: 1 | F29: 4.8-254-1 | G29: Монтаж приборов нагревательных, электрополотенце/прим. конвектор электрический настенный 1000 Вт | H29: 1 ШТ. | I29: =ROUND(1+2,9) -> 3 | J29: 0 | K29: =ROUND(1+2,9) -> 3 | O29: =ROUND(CP29,2) -> 2596 | P29: =ROUND((ROUND((AC29*AW29*I29),2)*BC29),2) -> 4.86 | Q29: =(ROUND((ROUND((((ET29*1.1))*AV29*I29),2)*BB29),2)+ROUND((ROUND(((AE29-((EU29*1.1)))*AV29*I29),2)*BS29),2)) -> 48.95 | R29: =(ROUND((ROUND((((EU29*1.1))*AV29*I29),2)*BS29),2)+ROUND((ROUND(((AE29-((EU29*1.1)))*AV29*I29),2)*BS29),2)) -> 24.75 | S29: =ROUND((ROUND((AF29*AV29*I29),2)*BA29),2) -> 2542.19 | T29: =ROUND(CU29*I29,2) -> 0 | U29: =CV29*I29 -> 3.558753 | V29: =CW29*I29 -> 0 | W29: =ROUND(CX29*I29,2) -> 0 | X29: =(ROUND((((S29+ROUND((ROUND((((EU29*1.1))*AV29*I29),2)*BS29),2))*AT29)/100),2)+ROUND(((ROUND((ROUND(((AE29-((EU29*1.1)))*AV29*I29),2)*BS29),2)*AT29)/100),2)) -> 2489.93 | Y29: =(ROUND((((S29+ROUND((ROUND((((EU29*1.1))*AV29*I29),2)*BS29),2))*AU29)/100),2)+ROUND(((ROUND((ROUND(((AE29-((EU29*1.1)))*AV29*I29),2)*BS29),2)*AU29)/100),2)) -> 1309.14 | AA29: 60255011 | AB29: =ROUND((AC29+AD29+AF29),6) -> 16.129 | AC29: =ROUND((ES29),6) -> 0.41 | AD29: =ROUND(((((ET29*1.1))-((EU29*1.1)))+AE29),6) -> 1.001 | AE29: =ROUND(((EU29*1.1)),6) -> 0.143 | AF29: =ROUND(((EV29*1.1)),6) -> 14.718 | AG29: =ROUND((AP29),6) -> 0 | AH29: =((EW29*1.1)) -> 1.133 | AI29: =((EX29*1.1)) -> 0 | AJ29: =(AS29) -> 0 | AK29: 14.7 | AL29: 0.41 | AM29: 0.91 | AN29: 0.13 | AO29: 13.38 | AP29: 0 | AQ29: 1.03 | AR29: 0 | AS29: 0 | AT29: 97 | AU29: 51 | AV29: 1.047 | AW29: 1 | AZ29: 1 | BA29: 54.99 | BB29: 15.59 | BC29: 3.95 | BH29: 0 | BI29: 2 | BJ29: ТСН-2001.4 Доп. 68, Сб. 8, т. 254, поз. 1 | BM29: 67 | BN29: 58973374 | BO29: 4.8-254-1 | BP29: 1 | BQ29: 40 | BR29: 0 | BS29: 54.99 | BT29: 1 | BU29: 1 | BV29: 1 | BW29: 1 | BX29: 1 | BZ29: 97 | CA29: 51 | CE29: 1566 | CF29: 0 | CG29: 0 | CM29: 0 | CN29: Поправка: Гл.12.Прил.8.п.8. 5_12.00.01.11.003 Наименование: При наличии усложненных условий производства работ (стесненность, сложность складирования и транспортной логистики, наличие в зоне производства работ действующего технологического оборудования или движения технологического транспорта и т.п.) для объектов, расположенных за пределами территории круговой магистральной системы улиц "Садовое кольцо" и за пределами Третьего транспортного кольца города Москвы пунктов "а" и "б", но в пределах Московской кольцевой автомобильной дороги | CO29: 0 | CP29: =(P29+Q29+S29) -> 2596 | CQ29: =ROUND((ROUND((AC29*AW29*1),2)*BC29),2) -> 1.62 | CR29: =(ROUND((ROUND((((ET29*1.1))*AV29*1),2)*BB29),2)+ROUND((ROUND(((AE29-((EU29*1.1)))*AV29*1),2)*BS29),2)) -> 16.37 | CS29: =(ROUND((ROUND((((EU29*1.1))*AV29*1),2)*BS29),2)+ROUND((ROUND(((AE29-((EU29*1.1)))*AV29*1),2)*BS29),2)) -> 8.25 | CT29: =ROUND((ROUND((AF29*AV29*1),2)*BA29),2) -> 847.4 | CU29: =AG29 -> 0 | CV29: =(AH29*AV29) -> 1.186251 | CW29: =AI29 -> 0 | CX29: =AJ29 -> 0 | CY29: =(ROUND((((S29+ROUND((ROUND((((EU29*1.1))*AV29*1),2)*BS29),2))*AT29)/100),2)+ROUND(((ROUND((ROUND(((AE29-((EU29*1.1)))*AV29*1),2)*BS29),2)*AT29)/100),2)) -> 2473.93 | CZ29: =(ROUND((((S29+ROUND((ROUND((((EU29*1.1))*AV29*1),2)*BS29),2))*AU29)/100),2)+ROUND(((ROUND((ROUND(((AE29-((EU29*1.1)))*AV29*1),2)*BS29),2)*AU29)/100),2)) -> 1300.72 | DE29: *1,1 | DF29: *1,1 | DG29: *1,1 | DI29: *1,1 | DJ29: *1,1 | DN29: 0 | DO29: 0 | DP29: 1 | DQ29: 1 | DU29: 1013 | DV29: 1 ШТ. | DW29: 1 ШТ. | DX29: 1 | EE29: 60088299 | EF29: 40 | EG29: Монтаж оборудования | EH29: 0 | EJ29: 2 | EK29: 67 | EL29: ТСН-2001.4-8. Электротехнические установки | EM29: ТСН-2001.4-8-1 | EO29: Поправка: Гл.12.Прил.8.п.8. 5_12.00.01.11.003 | EQ29: 0 | ER29: 14.7 | ES29: 0.41 | ET29: 0.91 | EU29: 0.13 | EV29: 13.38 | EW29: 1.03 | EX29: 0 | EY29: 0 | FQ29: 0 | FR29: 0 | FS29: 0 | FX29: 97 | FY29: 51 | GD29: 1 | GF29: -1561628963 | GG29: 2 | GH29: 1 | GI29: 2 | GJ29: 0 | GK29: 0 | GL29: =ROUND(IF(AND(BH29=3,BI29=3,FS29<>0),P29,0),2) -> 0 | GM29: =ROUND(O29+X29+Y29,2)+GX29 -> 6395.07 | GN29: =IF(OR(BI29=0,BI29=1),GM29-GX29,0) -> 0 | GO29: =IF(BI29=2,GM29-GX29,0) -> 6395.07 | GP29: =IF(BI29=4,GM29-GX29,0) -> 0 | GR29: 0 | GS29: 3 | GT29: 0 | GV29: =ROUND((GT29),6) -> 0 | GW29: 1 | GX29: =ROUND(HC29*I29,2) -> 0 | HA29: 0 | HB29: 0 | HC29: =GV29*GW29 -> 0 | HS29: 0 | IK29: 0
A30: 17 | B30: 1 | E30: 2 | F30: 13.1-11-142 | G30: Конвектор электрический, номинальная мощность 0,5 кВт, для отопления жилых и промышленных помещений | H30: шт. | I30: 1 | J30: 0 | K30: 1 | O30: =ROUND(CP30,2) -> 388.69 | P30: =ROUND((ROUND((AC30*I30),2)*BC30),2) -> 388.69 | Q30: =(ROUND((ROUND(((ET30)*AV30*I30),2)*BB30),2)+ROUND((ROUND(((AE30-(EU30))*AV30*I30),2)*BS30),2)) -> 0 | R30: =(ROUND((ROUND(((EU30)*AV30*I30),2)*BS30),2)+ROUND((ROUND(((AE30-(EU30))*AV30*I30),2)*BS30),2)) -> 0 | S30: =ROUND((ROUND((AF30*AV30*I30),2)*BA30),2) -> 0 | T30: =ROUND(CU30*I30,2) -> 0 | U30: =CV30*I30 -> 0 | V30: =CW30*I30 -> 0 | W30: =ROUND(CX30*I30,2) -> 0 | X30: =(ROUND((((S30+ROUND((ROUND(((EU30)*AV30*I30),2)*BS30),2))*AT30)/100),2)+ROUND(((ROUND((ROUND(((AE30-(EU30))*AV30*I30),2)*BS30),2)*AT30)/100),2)) -> 0 | Y30: =(ROUND((((S30+ROUND((ROUND(((EU30)*AV30*I30),2)*BS30),2))*AU30)/100),2)+ROUND(((ROUND((ROUND(((AE30-(EU30))*AV30*I30),2)*BS30),2)*AU30)/100),2)) -> 0 | AA30: 60255014 | AB30: =ROUND((AC30+AD30+AF30),6) -> 388.69 | AC30: =ROUND((ES30),6) -> 388.69 | AD30: =ROUND((((ET30)-(EU30))+AE30),6) -> 0 | AE30: =ROUND((EU30),6) -> 0 | AF30: =ROUND((EV30),6) -> 0 | AG30: =ROUND((AP30),6) -> 0 | AH30: =(EW30) -> 0 | AI30: =(EX30) -> 0 | AJ30: =(AS30) -> 0 | AK30: 388.69 | AL30: 388.69 | AM30: 0 | AN30: 0 | AO30: 0 | AP30: 0 | AQ30: 0 | AR30: 0 | AS30: 0 | AT30: 0 | AU30: 0 | AV30: 1 | AW30: 1 | AZ30: 1 | BA30: 1 | BB30: 1 | BC30: 1 | BH30: 3 | BI30: 3 | BM30: 746 | BN30: 58973374 | BP30: 0 | BQ30: 130 | BR30: 0 | BS30: 1 | BT30: 1 | BU30: 1 | BV30: 1 | BW30: 1 | BX30: 1 | BZ30: 0 | CA30: 0 | CE30: 1566 | CF30: 0 | CG30: 0 | CM30: 0 | CO30: 0 | CP30: =(P30+Q30+S30) -> 388.69 | CQ30: =ROUND((ROUND((AC30*1),2)*BC30),2) -> 388.69 | CR30: =(ROUND((ROUND(((ET30)*AV30*1),2)*BB30),2)+ROUND((ROUND(((AE30-(EU30))*AV30*1),2)*BS30),2)) -> 0 | CS30: =(ROUND((ROUND(((EU30)*AV30*1),2)*BS30),2)+ROUND((ROUND(((AE30-(EU30))*AV30*1),2)*BS30),2)) -> 0 | CT30: =ROUND((ROUND((AF30*AV30*1),2)*BA30),2) -> 0 | CU30: =AG30 -> 0 | CV30: =(AH30*AV30) -> 0 | CW30: =AI30 -> 0 | CX30: =AJ30 -> 0 | CY30: =(ROUND((((S30+ROUND((ROUND(((EU30)*AV30*1),2)*BS30),2))*AT30)/100),2)+ROUND(((ROUND((ROUND(((AE30-(EU30))*AV30*1),2)*BS30),2)*AT30)/100),2)) -> 0 | CZ30: =(ROUND((((S30+ROUND((ROUND(((EU30)*AV30*1),2)*BS30),2))*AU30)/100),2)+ROUND(((ROUND((ROUND(((AE30-(EU30))*AV30*1),2)*BS30),2)*AU30)/100),2)) -> 0 | DN30: 0 | DO30: 0 | DP30: 1 | DQ30: 1 | DU30: 1010 | DV30: шт. | DW30: шт. | DX30: 1 | EE30: 60088205 | EF30: 130 | EG30: Сметная стоимость оборудования | EH30: 0 | EJ30: 3 | EK30: 746 | EL30: ТСН-2001.13. Сметная стоимость оборудования | EM30: ТСН-2001.13 | EQ30: 0 | ER30: 388.69 | ES30: 388.69 | ET30: 0 | EU30: 0 | EV30: 0 | EW30: 0 | EX30: 0 | EY30: 0 | FQ30: 0 | FR30: =P30 -> 388.69 | FS30: 0 | FX30: 0 | FY30: 0 | GD30: 1 | GF30: -1177766710 | GG30: 2 | GH30: 1 | GI30: -2 | GJ30: 0 | GK30: 0 | GL30: =ROUND(IF(AND(BH30=3,BI30=3,FS30<>0),P30,0),2) -> 0 | GM30: =ROUND(O30+X30+Y30,2)+GX30 -> 388.69 | GN30: =IF(OR(BI30=0,BI30=1),GM30-GX30,0) -> 0 | GO30: =IF(BI30=2,GM30-GX30,0) -> 0 | GP30: =IF(BI30=4,GM30-GX30,0) -> 0 | GR30: 0 | GS30: 3 | GT30: 0 | GV30: =ROUND((GT30),6) -> 0 | GW30: 1 | GX30: =ROUND(HC30*I30,2) -> 0 | HA30: 0 | HB30: 0 | HC30: =GV30*GW30 -> 0 | HS30: 0 | IK30: 0
A31: 17 | B31: 1 | E31: 2 | F31: 13.1-11-142 | G31: Конвектор электрический, номинальная мощность 0,5 кВт, для отопления жилых и промышленных помещений | H31: шт. | I31: 1 | J31: 0 | K31: 1 | O31: =ROUND(CP31,2) -> 2553.69 | P31: =ROUND((ROUND((AC31*I31),2)*BC31),2) -> 2553.69 | Q31: =(ROUND((ROUND(((ET31)*AV31*I31),2)*BB31),2)+ROUND((ROUND(((AE31-(EU31))*AV31*I31),2)*BS31),2)) -> 0 | R31: =(ROUND((ROUND(((EU31)*AV31*I31),2)*BS31),2)+ROUND((ROUND(((AE31-(EU31))*AV31*I31),2)*BS31),2)) -> 0 | S31: =ROUND((ROUND((AF31*AV31*I31),2)*BA31),2) -> 0 | T31: =ROUND(CU31*I31,2) -> 0 | U31: =CV31*I31 -> 0 | V31: =CW31*I31 -> 0 | W31: =ROUND(CX31*I31,2) -> 0 | X31: =(ROUND((((S31+ROUND((ROUND(((EU31)*AV31*I31),2)*BS31),2))*AT31)/100),2)+ROUND(((ROUND((ROUND(((AE31-(EU31))*AV31*I31),2)*BS31),2)*AT31)/100),2)) -> 0 | Y31: =(ROUND((((S31+ROUND((ROUND(((EU31)*AV31*I31),2)*BS31),2))*AU31)/100),2)+ROUND(((ROUND((ROUND(((AE31-(EU31))*AV31*I31),2)*BS31),2)*AU31)/100),2)) -> 0 | AA31: 60255011 | AB31: =ROUND((AC31+AD31+AF31),6) -> 388.69 | AC31: =ROUND((ES31),6) -> 388.69 | AD31: =ROUND((((ET31)-(EU31))+AE31),6) -> 0 | AE31: =ROUND((EU31),6) -> 0 | AF31: =ROUND((EV31),6) -> 0 | AG31: =ROUND((AP31),6) -> 0 | AH31: =(EW31) -> 0 | AI31: =(EX31) -> 0 | AJ31: =(AS31) -> 0 | AK31: 388.69 | AL31: 388.69 | AM31: 0 | AN31: 0 | AO31: 0 | AP31: 0 | AQ31: 0 | AR31: 0 | AS31: 0 | AT31: 0 | AU31: 0 | AV31: 1 | AW31: 1 | AZ31: 1 | BA31: 1 | BB31: 1 | BC31: 6.57 | BH31: 3 | BI31: 3 | BM31: 746 | BN31: 58973374 | BP31: 0 | BQ31: 130 | BR31: 0 | BS31: 1 | BT31: 1 | BU31: 1 | BV31: 1 | BW31: 1 | BX31: 1 | BZ31: 0 | CA31: 0 | CE31: 1566 | CF31: 0 | CG31: 0 | CM31: 0 | CO31: 0 | CP31: =(P31+Q31+S31) -> 2553.69 | CQ31: =ROUND((ROUND((AC31*1),2)*BC31),2) -> 2553.69 | CR31: =(ROUND((ROUND(((ET31)*AV31*1),2)*BB31),2)+ROUND((ROUND(((AE31-(EU31))*AV31*1),2)*BS31),2)) -> 0 | CS31: =(ROUND((ROUND(((EU31)*AV31*1),2)*BS31),2)+ROUND((ROUND(((AE31-(EU31))*AV31*1),2)*BS31),2)) -> 0 | CT31: =ROUND((ROUND((AF31*AV31*1),2)*BA31),2) -> 0 | CU31: =AG31 -> 0 | CV31: =(AH31*AV31) -> 0 | CW31: =AI31 -> 0 | CX31: =AJ31 -> 0 | CY31: =(ROUND((((S31+ROUND((ROUND(((EU31)*AV31*1),2)*BS31),2))*AT31)/100),2)+ROUND(((ROUND((ROUND(((AE31-(EU31))*AV31*1),2)*BS31),2)*AT31)/100),2)) -> 0 | CZ31: =(ROUND((((S31+ROUND((ROUND(((EU31)*AV31*1),2)*BS31),2))*AU31)/100),2)+ROUND(((ROUND((ROUND(((AE31-(EU31))*AV31*1),2)*BS31),2)*AU31)/100),2)) -> 0 | DN31: 0 | DO31: 0 | DP31: 1 | DQ31: 1 | DU31: 1010 | DV31: шт. | DW31: шт. | DX31: 1 | EE31: 60088205 | EF31: 130 | EG31: Сметная стоимость оборудования | EH31: 0 | EJ31: 3 | EK31: 746 | EL31: ТСН-2001.13. Сметная стоимость оборудования | EM31: ТСН-2001.13 | EQ31: 0 | ER31: 388.69 | ES31: 388.69 | ET31: 0 | EU31: 0 | EV31: 0 | EW31: 0 | EX31: 0 | EY31: 0 | FQ31: 0 | FR31: =P31 -> 2553.69 | FS31: 0 | FX31: 0 | FY31: 0 | GD31: 1 | GF31: -1177766710 | GG31: 2 | GH31: 1 | GI31: 2 | GJ31: 0 | GK31: 0 | GL31: =ROUND(IF(AND(BH31=3,BI31=3,FS31<>0),P31,0),2) -> 0 | GM31: =ROUND(O31+X31+Y31,2)+GX31 -> 2553.69 | GN31: =IF(OR(BI31=0,BI31=1),GM31-GX31,0) -> 0 | GO31: =IF(BI31=2,GM31-GX31,0) -> 0 | GP31: =IF(BI31=4,GM31-GX31,0) -> 0 | GR31: 0 | GS31: 3 | GT31: 0 | GV31: =ROUND((GT31),6) -> 0 | GW31: 1 | GX31: =ROUND(HC31*I31,2) -> 0 | HA31: 0 | HB31: 0 | HC31: =GV31*GW31 -> 0 | HS31: 0 | IK31: 0
A32: 17 | B32: 1 | E32: 3 | F32: 13.1-11-143 | G32: Конвектор электрический, номинальная мощность 1 кВт, для отопления жилых и промышленных помещений | H32: шт. | I32: 2 | J32: 0 | K32: 2 | O32: =ROUND(CP32,2) -> 929.48 | P32: =ROUND((ROUND((AC32*I32),2)*BC32),2) -> 929.48 | Q32: =(ROUND((ROUND(((ET32)*AV32*I32),2)*BB32),2)+ROUND((ROUND(((AE32-(EU32))*AV32*I32),2)*BS32),2)) -> 0 | R32: =(ROUND((ROUND(((EU32)*AV32*I32),2)*BS32),2)+ROUND((ROUND(((AE32-(EU32))*AV32*I32),2)*BS32),2)) -> 0 | S32: =ROUND((ROUND((AF32*AV32*I32),2)*BA32),2) -> 0 | T32: =ROUND(CU32*I32,2) -> 0 | U32: =CV32*I32 -> 0 | V32: =CW32*I32 -> 0 | W32: =ROUND(CX32*I32,2) -> 0 | X32: =(ROUND((((S32+ROUND((ROUND(((EU32)*AV32*I32),2)*BS32),2))*AT32)/100),2)+ROUND(((ROUND((ROUND(((AE32-(EU32))*AV32*I32),2)*BS32),2)*AT32)/100),2)) -> 0 | Y32: =(ROUND((((S32+ROUND((ROUND(((EU32)*AV32*I32),2)*BS32),2))*AU32)/100),2)+ROUND(((ROUND((ROUND(((AE32-(EU32))*AV32*I32),2)*BS32),2)*AU32)/100),2)) -> 0 | AA32: 60255014 | AB32: =ROUND((AC32+AD32+AF32),6) -> 464.74 | AC32: =ROUND((ES32),6) -> 464.74 | AD32: =ROUND((((ET32)-(EU32))+AE32),6) -> 0 | AE32: =ROUND((EU32),6) -> 0 | AF32: =ROUND((EV32),6) -> 0 | AG32: =ROUND((AP32),6) -> 0 | AH32: =(EW32) -> 0 | AI32: =(EX32) -> 0 | AJ32: =(AS32) -> 0 | AK32: 464.74 | AL32: 464.74 | AM32: 0 | AN32: 0 | AO32: 0 | AP32: 0 | AQ32: 0 | AR32: 0 | AS32: 0 | AT32: 0 | AU32: 0 | AV32: 1 | AW32: 1 | AZ32: 1 | BA32: 1 | BB32: 1 | BC32: 1 | BH32: 3 | BI32: 3 | BM32: 746 | BN32: 58973374 | BP32: 0 | BQ32: 130 | BR32: 0 | BS32: 1 | BT32: 1 | BU32: 1 | BV32: 1 | BW32: 1 | BX32: 1 | BZ32: 0 | CA32: 0 | CE32: 1566 | CF32: 0 | CG32: 0 | CM32: 0 | CO32: 0 | CP32: =(P32+Q32+S32) -> 929.48 | CQ32: =ROUND((ROUND((AC32*1),2)*BC32),2) -> 464.74 | CR32: =(ROUND((ROUND(((ET32)*AV32*1),2)*BB32),2)+ROUND((ROUND(((AE32-(EU32))*AV32*1),2)*BS32),2)) -> 0 | CS32: =(ROUND((ROUND(((EU32)*AV32*1),2)*BS32),2)+ROUND((ROUND(((AE32-(EU32))*AV32*1),2)*BS32),2)) -> 0 | CT32: =ROUND((ROUND((AF32*AV32*1),2)*BA32),2) -> 0 | CU32: =AG32 -> 0 | CV32: =(AH32*AV32) -> 0 | CW32: =AI32 -> 0 | CX32: =AJ32 -> 0 | CY32: =(ROUND((((S32+ROUND((ROUND(((EU32)*AV32*1),2)*BS32),2))*AT32)/100),2)+ROUND(((ROUND((ROUND(((AE32-(EU32))*AV32*1),2)*BS32),2)*AT32)/100),2)) -> 0 | CZ32: =(ROUND((((S32+ROUND((ROUND(((EU32)*AV32*1),2)*BS32),2))*AU32)/100),2)+ROUND(((ROUND((ROUND(((AE32-(EU32))*AV32*1),2)*BS32),2)*AU32)/100),2)) -> 0 | DN32: 0 | DO32: 0 | DP32: 1 | DQ32: 1 | DU32: 1010 | DV32: шт. | DW32: шт. | DX32: 1 | EE32: 60088205 | EF32: 130 | EG32: Сметная стоимость оборудования | EH32: 0 | EJ32: 3 | EK32: 746 | EL32: ТСН-2001.13. Сметная стоимость оборудования | EM32: ТСН-2001.13 | EQ32: 0 | ER32: 464.74 | ES32: 464.74 | ET32: 0 | EU32: 0 | EV32: 0 | EW32: 0 | EX32: 0 | EY32: 0 | FQ32: 0 | FR32: =P32 -> 929.48 | FS32: 0 | FX32: 0 | FY32: 0 | GD32: 1 | GF32: 1803617062 | GG32: 2 | GH32: 1 | GI32: -2 | GJ32: 0 | GK32: 0 | GL32: =ROUND(IF(AND(BH32=3,BI32=3,FS32<>0),P32,0),2) -> 0 | GM32: =ROUND(O32+X32+Y32,2)+GX32 -> 929.48 | GN32: =IF(OR(BI32=0,BI32=1),GM32-GX32,0) -> 0 | GO32: =IF(BI32=2,GM32-GX32,0) -> 0 | GP32: =IF(BI32=4,GM32-GX32,0) -> 0 | GR32: 0 | GS32: 3 | GT32: 0 | GV32: =ROUND((GT32),6) -> 0 | GW32: 1 | GX32: =ROUND(HC32*I32,2) -> 0 | HA32: 0 | HB32: 0 | HC32: =GV32*GW32 -> 0 | HS32: 0 | IK32: 0
A33: 17 | B33: 1 | E33: 3 | F33: 13.1-11-143 | G33: Конвектор электрический, номинальная мощность 1 кВт, для отопления жилых и промышленных помещений | H33: шт. | I33: 2 | J33: 0 | K33: 2 | O33: =ROUND(CP33,2) -> 5697.71 | P33: =ROUND((ROUND((AC33*I33),2)*BC33),2) -> 5697.71 | Q33: =(ROUND((ROUND(((ET33)*AV33*I33),2)*BB33),2)+ROUND((ROUND(((AE33-(EU33))*AV33*I33),2)*BS33),2)) -> 0 | R33: =(ROUND((ROUND(((EU33)*AV33*I33),2)*BS33),2)+ROUND((ROUND(((AE33-(EU33))*AV33*I33),2)*BS33),2)) -> 0 | S33: =ROUND((ROUND((AF33*AV33*I33),2)*BA33),2) -> 0 | T33: =ROUND(CU33*I33,2) -> 0 | U33: =CV33*I33 -> 0 | V33: =CW33*I33 -> 0 | W33: =ROUND(CX33*I33,2) -> 0 | X33: =(ROUND((((S33+ROUND((ROUND(((EU33)*AV33*I33),2)*BS33),2))*AT33)/100),2)+ROUND(((ROUND((ROUND(((AE33-(EU33))*AV33*I33),2)*BS33),2)*AT33)/100),2)) -> 0 | Y33: =(ROUND((((S33+ROUND((ROUND(((EU33)*AV33*I33),2)*BS33),2))*AU33)/100),2)+ROUND(((ROUND((ROUND(((AE33-(EU33))*AV33*I33),2)*BS33),2)*AU33)/100),2)) -> 0 | AA33: 60255011 | AB33: =ROUND((AC33+AD33+AF33),6) -> 464.74 | AC33: =ROUND((ES33),6) -> 464.74 | AD33: =ROUND((((ET33)-(EU33))+AE33),6) -> 0 | AE33: =ROUND((EU33),6) -> 0 | AF33: =ROUND((EV33),6) -> 0 | AG33: =ROUND((AP33),6) -> 0 | AH33: =(EW33) -> 0 | AI33: =(EX33) -> 0 | AJ33: =(AS33) -> 0 | AK33: 464.74 | AL33: 464.74 | AM33: 0 | AN33: 0 | AO33: 0 | AP33: 0 | AQ33: 0 | AR33: 0 | AS33: 0 | AT33: 0 | AU33: 0 | AV33: 1 | AW33: 1 | AZ33: 1 | BA33: 1 | BB33: 1 | BC33: 6.13 | BH33: 3 | BI33: 3 | BM33: 746 | BN33: 58973374 | BP33: 0 | BQ33: 130 | BR33: 0 | BS33: 1 | BT33: 1 | BU33: 1 | BV33: 1 | BW33: 1 | BX33: 1 | BZ33: 0 | CA33: 0 | CE33: 1566 | CF33: 0 | CG33: 0 | CM33: 0 | CO33: 0 | CP33: =(P33+Q33+S33) -> 5697.71 | CQ33: =ROUND((ROUND((AC33*1),2)*BC33),2) -> 2848.86 | CR33: =(ROUND((ROUND(((ET33)*AV33*1),2)*BB33),2)+ROUND((ROUND(((AE33-(EU33))*AV33*1),2)*BS33),2)) -> 0 | CS33: =(ROUND((ROUND(((EU33)*AV33*1),2)*BS33),2)+ROUND((ROUND(((AE33-(EU33))*AV33*1),2)*BS33),2)) -> 0 | CT33: =ROUND((ROUND((AF33*AV33*1),2)*BA33),2) -> 0 | CU33: =AG33 -> 0 | CV33: =(AH33*AV33) -> 0 | CW33: =AI33 -> 0 | CX33: =AJ33 -> 0 | CY33: =(ROUND((((S33+ROUND((ROUND(((EU33)*AV33*1),2)*BS33),2))*AT33)/100),2)+ROUND(((ROUND((ROUND(((AE33-(EU33))*AV33*1),2)*BS33),2)*AT33)/100),2)) -> 0 | CZ33: =(ROUND((((S33+ROUND((ROUND(((EU33)*AV33*1),2)*BS33),2))*AU33)/100),2)+ROUND(((ROUND((ROUND(((AE33-(EU33))*AV33*1),2)*BS33),2)*AU33)/100),2)) -> 0 | DN33: 0 | DO33: 0 | DP33: 1 | DQ33: 1 | DU33: 1010 | DV33: шт. | DW33: шт. | DX33: 1 | EE33: 60088205 | EF33: 130 | EG33: Сметная стоимость оборудования | EH33: 0 | EJ33: 3 | EK33: 746 | EL33: ТСН-2001.13. Сметная стоимость оборудования | EM33: ТСН-2001.13 | EQ33: 0 | ER33: 464.74 | ES33: 464.74 | ET33: 0 | EU33: 0 | EV33: 0 | EW33: 0 | EX33: 0 | EY33: 0 | FQ33: 0 | FR33: =P33 -> 5697.71 | FS33: 0 | FX33: 0 | FY33: 0 | GD33: 1 | GF33: 1803617062 | GG33: 2 | GH33: 1 | GI33: 2 | GJ33: 0 | GK33: 0 | GL33: =ROUND(IF(AND(BH33=3,BI33=3,FS33<>0),P33,0),2) -> 0 | GM33: =ROUND(O33+X33+Y33,2)+GX33 -> 5697.71 | GN33: =IF(OR(BI33=0,BI33=1),GM33-GX33,0) -> 0 | GO33: =IF(BI33=2,GM33-GX33,0) -> 0 | GP33: =IF(BI33=4,GM33-GX33,0) -> 0 | GR33: 0 | GS33: 3 | GT33: 0 | GV33: =ROUND((GT33),6) -> 0 | GW33: 1 | GX33: =ROUND(HC33*I33,2) -> 0 | HA33: 0 | HB33: 0 | HC33: =GV33*GW33 -> 0 | HS33: 0 | IK33: 0
A35: 51 | B35: =B24 -> 1 | C35: =A24 -> 4 | D35: =ROW(A24) -> 24 | F35: =IF(F24<>"",F24,"") | G35: =IF(G24<>"",G24,"") -> Конвекторы | H35: 0 | O35: =ROUND(AB35,2) -> 1368.77 | P35: =ROUND(AC35,2) -> 1319.4 | Q35: =ROUND(AD35,2) -> 3.14 | R35: =ROUND(AE35,2) -> 0.45 | S35: =ROUND(AF35,2) -> 46.23 | T35: =ROUND(AG35,2) -> 0 | U35: =AH35 -> 3.558753 | V35: =AI35 -> 0 | W35: =ROUND(AJ35,2) -> 0 | X35: =ROUND(AK35,2) -> 45.28 | Y35: =ROUND(AL35,2) -> 23.81 | AB35: =ROUND(SUMIF(AA28:AA33,"=60255014",O28:O33),2) -> 1368.77 | AC35: =ROUND(SUMIF(AA28:AA33,"=60255014",P28:P33),2) -> 1319.4 | AD35: =ROUND(SUMIF(AA28:AA33,"=60255014",Q28:Q33),2) -> 3.14 | AE35: =ROUND(SUMIF(AA28:AA33,"=60255014",R28:R33),2) -> 0.45 | AF35: =ROUND(SUMIF(AA28:AA33,"=60255014",S28:S33),2) -> 46.23 | AG35: =ROUND(SUMIF(AA28:AA33,"=60255014",T28:T33),2) -> 0 | AH35: =SUMIF(AA28:AA33,"=60255014",U28:U33) -> 3.558753 | AI35: =SUMIF(AA28:AA33,"=60255014",V28:V33) -> 0 | AJ35: =ROUND(SUMIF(AA28:AA33,"=60255014",W28:W33),2) -> 0 | AK35: =ROUND(SUMIF(AA28:AA33,"=60255014",X28:X33),2) -> 45.28 | AL35: =ROUND(SUMIF(AA28:AA33,"=60255014",Y28:Y33),2) -> 23.81 | AO35: =ROUND(BX35,2) -> 0 | AP35: =ROUND(BY35,2) -> 1318.17 | AQ35: =ROUND(BZ35,2) -> 0 | AR35: =ROUND(CA35,2) -> 1437.86 | AS35: =ROUND(CB35,2) -> 0 | AT35: =ROUND(CC35,2) -> 119.69 | AU35: =ROUND(CD35,2) -> 0 | AV35: =ROUND(CE35,2) -> 1319.4 | ... BD35: =ROUND(CM35,2) -> 0 | BX35: =ROUND(SUMIF(AA28:AA33,"=60255014",FQ28:FQ33),2) -> 0 | BY35: =ROUND(SUMIF(AA28:AA33,"=60255014",FR28:FR33),2) -> 1318.17 | BZ35: =ROUND(SUMIF(AA28:AA33,"=60255014",GL28:GL33),2) -> 0 | CA35: =ROUND(SUMIF(AA28:AA33,"=60255014",GM28:GM33),2) -> 1437.86 | CB35: =ROUND(SUMIF(AA28:AA33,"=60255014",GN28:GN33),2) -> 0 | CC35: =ROUND(SUMIF(AA28:AA33,"=60255014",GO28:GO33),2) -> 119.69 | CD35: =ROUND(SUMIF(AA28:AA33,"=60255014",GP28:GP33),2) -> 0 | CE35: =AC35-BX35 -> 1319.4 | CF35: =AC35-BY35 -> 1.23 | CG35: =BX35-BZ35 -> 0 | CH35: =AC35-BX35-BY35+BZ35 -> 1.23 | CI35: =BY35-BZ35 -> 1318.17 | CJ35: =ROUND(SUMIF(AA28:AA33,"=60255014",GX28:GX33),2) -> 0 | CK35: =ROUND(SUMIF(AA28:AA33,"=60255014",GY28:GY33),2) -> 0 | CL35: =ROUND(SUMIF(AA28:AA33,"=60255014",GZ28:GZ33),2) -> 0 | CM35: =ROUND(SUMIF(AA28:AA33,"=60255014",HD28:HD33),2) -> 0 | DG35: =ROUND(DT35,2) -> 10847.4 | DH35: =ROUND(DU35,2) -> 8256.26 | DI35: =ROUND(DV35,2) -> 48.95 | DJ35: =ROUND(DW35,2) -> 24.75 | DK35: =ROUND(DX35,2) -> 2542.19 | DL35: =ROUND(DY35,2) -> 0 | DM35: =DZ35 -> 3.558753 | DN35: =EA35 -> 0 | DO35: =ROUND(EB35,2) -> 0 | DP35: =ROUND(EC35,2) -> 2489.93 | DQ35: =ROUND(ED35,2) -> 1309.14 | DT35: =ROUND(SUMIF(AA28:AA33,"=60255011",O28:O33),2) -> 10847.4 | DU35: =ROUND(SUMIF(AA28:AA33,"=60255011",P28:P33),2) -> 8256.26 | DV35: =ROUND(SUMIF(AA28:AA33,"=60255011",Q28:Q33),2) -> 48.95 | DW35: =ROUND(SUMIF(AA28:AA33,"=60255011",R28:R33),2) -> 24.75 | DX35: =ROUND(SUMIF(AA28:AA33,"=60255011",S28:S33),2) -> 2542.19 | DY35: =ROUND(SUMIF(AA28:AA33,"=60255011",T28:T33),2) -> 0 | DZ35: =SUMIF(AA28:AA33,"=60255011",U28:U33) -> 3.558753 | EA35: =SUMIF(AA28:AA33,"=60255011",V28:V33) -> 0 | EB35: =ROUND(SUMIF(AA28:AA33,"=60255011",W28:W33),2) -> 0 | EC35: =ROUND(SUMIF(AA28:AA33,"=60255011",X28:X33),2) -> 2489.93 | ED35: =ROUND(SUMIF(AA28:AA33,"=60255011",Y28:Y33),2) -> 1309.14 | EG35: =ROUND(FP35,2) -> 0 | EH35: =ROUND(FQ35,2) -> 8251.4 | EI35: =ROUND(FR35,2) -> 0 | EJ35: =ROUND(FS35,2) -> 14646.47 | EK35: =ROUND(FT35,2) -> 0 | EL35: =ROUND(FU35,2) -> 6395.07 | EM35: =ROUND(FV35,2) -> 0 | EN35: =ROUND(FW35,2) -> 8256.26 | ... EV35: =ROUND(GE35,2) -> 0 | FP35: =ROUND(SUMIF(AA28:AA33,"=60255011",FQ28:FQ33),2) -> 0 | FQ35: =ROUND(SUMIF(AA28:AA33,"=60255011",FR28:FR33),2) -> 8251.4 | FR35: =ROUND(SUMIF(AA28:AA33,"=60255011",GL28:GL33),2) -> 0 | FS35: =ROUND(SUMIF(AA28:AA33,"=60255011",GM28:GM33),2) -> 14646.47 | FT35: =ROUND(SUMIF(AA28:AA33,"=60255011",GN28:GN33),2) -> 0 | FU35: =ROUND(SUMIF(AA28:AA33,"=60255011",GO28:GO33),2) -> 6395.07 | FV35: =ROUND(SUMIF(AA28:AA33,"=60255011",GP28:GP33),2) -> 0 | FW35: =DU35-FP35 -> 8256.26 | FX35: =DU35-FQ35 -> 4.86 | FY35: =FP35-FR35 -> 0 | FZ35: =DU35-FP35-FQ35+FR35 -> 4.86 | GA35: =FQ35-FR35 -> 8251.4 | GB35: =ROUND(SUMIF(AA28:AA33,"=60255011",GX28:GX33),2) -> 0 | GC35: =ROUND(SUMIF(AA28:AA33,"=60255011",GY28:GY33),2) -> 0 | GD35: =ROUND(SUMIF(AA28:AA33,"=60255011",GZ28:GZ33),2) -> 0 | GE35: =ROUND(SUMIF(AA28:AA33,"=60255011",HD28:HD33),2) -> 0 | GX35: 0
A37: 50 | B37: 0 | C37: 0 | D37: 1 | E37: 201 | F37: =ROUND(Source!O35,O37) -> 1368.77 | G37: ПЗ | H37: Прямые затраты | K37: 201 | L37: 1 | M37: 3 | O37: 2 | P37: =ROUND(Source!DG35,O37) -> 10847.4 | W37: 1368.77 | X37: 1 | Y37: 1368.77 | Z37: 10847.4 | AA37: 1 | AB37: 10847.4
A38: 50 | B38: 0 | C38: 0 | D38: 1 | E38: 202 | F38: =ROUND(Source!P35,O38) -> 1319.4 | G38: СтМатОб | H38: Стоимость материальных ресурсов (всего) | K38: 202 | L38: 2 | M38: 3 | O38: 2 | P38: =ROUND(Source!DH35,O38) -> 8256.26 | W38: 1319.4 | X38: 1 | Y38: 1319.4 | Z38: 8256.26 | AA38: 1 | AB38: 8256.26
A39: 50 | B39: 0 | C39: 0 | D39: 1 | E39: 222 | F39: =ROUND(Source!AO35,O39) -> 0 | G39: СтМатОбЗак | H39: Стоимость материалов и оборудования заказчика | K39: 222 | L39: 3 | M39: 3 | O39: 2 | P39: =ROUND(Source!EG35,O39) -> 0 | W39: 0 | X39: 1 | Y39: 0 | Z39: 0 | AA39: 1 | AB39: 0
A40: 50 | B40: 0 | C40: 0 | D40: 1 | E40: 225 | F40: =ROUND(Source!AV35,O40) -> 1319.4 | G40: СтМатОбПод | H40: Стоимость материалов и оборудования подрядчика | K40: 225 | L40: 4 | M40: 3 | O40: 2 | P40: =ROUND(Source!EN35,O40) -> 8256.26 | W40: 1319.4 | X40: 1 | Y40: 1319.4 | Z40: 8256.26 | AA40: 1 | AB40: 8256.26
A41: 50 | B41: 0 | C41: 0 | D41: 1 | E41: 226 | F41: =ROUND(Source!AW35,O41) -> 1.23 | G41: СтМат | H41: Стоимость материалов (всего) | K41: 226 | L41: 5 | M41: 3 | O41: 2 | P41: =ROUND(Source!EO35,O41) -> 4.86 | W41: 1.23 | X41: 1 | Y41: 1.23 | Z41: 4.86 | AA41: 1 | AB41: 4.86
A42: 50 | B42: 0 | C42: 0 | D42: 1 | E42: 227 | F42: =ROUND(Source!AX35,O42) -> 0 | G42: СтМатЗак | H42: Стоимость материалов заказчика | K42: 227 | L42: 6 | M42: 3 | O42: 2 | P42: =ROUND(Source!EP35,O42) -> 0 | W42: 0 | X42: 1 | Y42: 0 | Z42: 0 | AA42: 1 | AB42: 0
A43: 50 | B43: 0 | C43: 0 | D43: 1 | E43: 228 | F43: =ROUND(Source!AY35,O43) -> 1.23 | G43: СтМатПод | H43: Стоимость материалов подрядчика | K43: 228 | L43: 7 | M43: 3 | O43: 2 | P43: =ROUND(Source!EQ35,O43) -> 4.86 | W43: 1.23 | X43: 1 | Y43: 1.23 | Z43: 4.86 | AA43: 1 | AB43: 4.86
A44: 50 | B44: 0 | C44: 0 | D44: 1 | E44: 216 | F44: =ROUND(Source!AP35,O44) -> 1318.17 | G44: Оборуд | H44: Стоимость оборудования (всего) | K44: 216 | L44: 8 | M44: 3 | O44: 2 | P44: =ROUND(Source!EH35,O44) -> 8251.4 | W44: 1318.17 | X44: 1 | Y44: 1318.17 | Z44: 8251.4 | AA44: 1 | AB44: 8251.4
A45: 50 | B45: 0 | C45: 0 | D45: 1 | E45: 223 | F45: =ROUND(Source!AQ35,O45) -> 0 | G45: ОборудЗак | H45: Стоимость оборудования заказчика | K45: 223 | L45: 9 | M45: 3 | O45: 2 | P45: =ROUND(Source!EI35,O45) -> 0 | W45: 0 | X45: 1 | Y45: 0 | Z45: 0 | AA45: 1 | AB45: 0
A46: 50 | B46: 0 | C46: 0 | D46: 1 | E46: 229 | F46: =ROUND(Source!AZ35,O46) -> 1318.17 | G46: ОборудПод | H46: Стоимость оборудования подрядчика | K46: 229 | L46: 10 | M46: 3 | O46: 2 | P46: =ROUND(Source!ER35,O46) -> 8251.4 | W46: 1318.17 | X46: 1 | Y46: 1318.17 | Z46: 8251.4 | AA46: 1 | AB46: 8251.4
A47: 50 | B47: 0 | C47: 0 | D47: 1 | E47: 203 | F47: =ROUND(Source!Q35,O47) -> 3.14 | G47: ЭММ | H47: Эксплуатация машин | K47: 203 | L47: 11 | M47: 3 | O47: 2 | P47: =ROUND(Source!DI35,O47) -> 48.95 | W47: 3.14 | X47: 1 | Y47: 3.14 | Z47: 48.95 | AA47: 1 | AB47: 48.95
A48: 50 | B48: 0 | C48: 0 | D48: 1 | E48: 231 | F48: =ROUND(Source!BB35,O48) -> 0 | G48: ЭММсНРиСП | H48: Эксплуатация машин по ТСН-2001.16 | K48: 231 | L48: 12 | M48: 3 | O48: 2 | P48: =ROUND(Source!ET35,O48) -> 0 | W48: 0 | X48: 1 | Y48: 0 | Z48: 0 | AA48: 1 | AB48: 0
A49: 50 | B49: 0 | C49: 0 | D49: 1 | E49: 204 | F49: =ROUND(Source!R35,O49) -> 0.45 | G49: ЗПМ | H49: ЗП машинистов | K49: 204 | L49: 13 | M49: 3 | O49: 2 | P49: =ROUND(Source!DJ35,O49) -> 24.75 | W49: 0.45 | X49: 1 | Y49: 0.45 | Z49: 24.75 | AA49: 1 | AB49: 24.75
A50: 50 | B50: 0 | C50: 0 | D50: 1 | E50: 205 | F50: =ROUND(Source!S35,O50) -> 46.23 | G50: ОЗП | H50: Основная ЗП рабочих | K50: 205 | L50: 14 | M50: 3 | O50: 2 | P50: =ROUND(Source!DK35,O50) -> 2542.19 | W50: 46.23 | X50: 1 | Y50: 46.23 | Z50: 2542.19 | AA50: 1 | AB50: 2542.19
A51: 50 | B51: 0 | C51: 0 | D51: 1 | E51: 232 | F51: =ROUND(Source!BC35,O51) -> 0 | G51: ОЗПсНРиСП | H51: Основная ЗП рабочих по ТСН-2001.16 | K51: 232 | L51: 15 | M51: 3 | O51: 2 | P51: =ROUND(Source!EU35,O51) -> 0 | W51: 0 | X51: 1 | Y51: 0 | Z51: 0 | AA51: 1 | AB51: 0
A52: 50 | B52: 0 | C52: 0 | D52: 1 | E52: 214 | F52: =ROUND(Source!AS35,O52) -> 0 | G52: Строит | H52: Строительные работы с НР и СП | K52: 214 | L52: 16 | M52: 3 | O52: 2 | P52: =ROUND(Source!EK35,O52) -> 0 | W52: 0 | X52: 1 | Y52: 0 | Z52: 0 | AA52: 1 | AB52: 0
A53: 50 | B53: 0 | C53: 0 | D53: 1 | E53: 215 | F53: =ROUND(Source!AT35,O53) -> 119.69 | G53: Монтаж | H53: Монтажные работы с НР и СП | K53: 215 | L53: 17 | M53: 3 | O53: 2 | P53: =ROUND(Source!EL35,O53) -> 6395.07 | W53: 119.69 | X53: 1 | Y53: 119.69 | Z53: 6395.07 | AA53: 1 | AB53: 6395.07
A54: 50 | B54: 0 | C54: 0 | D54: 1 | E54: 217 | F54: =ROUND(Source!AU35,O54) -> 0 | G54: Прочие | H54: Прочие работы с НР и СП | K54: 217 | L54: 18 | M54: 3 | O54: 2 | P54: =ROUND(Source!EM35,O54) -> 0 | W54: 0 | X54: 1 | Y54: 0 | Z54: 0 | AA54: 1 | AB54: 0
A55: 50 | B55: 0 | C55: 0 | D55: 1 | E55: 230 | F55: =ROUND(Source!BA35,O55) -> 0 | G55: ПрочиеЗатр | H55: Прочие затраты по ТСН-2001.16 | K55: 230 | L55: 19 | M55: 3 | O55: 2 | P55: =ROUND(Source!ES35,O55) -> 0 | W55: 0 | X55: 1 | Y55: 0 | Z55: 0 | AA55: 1 | AB55: 0
A56: 50 | B56: 0 | C56: 0 | D56: 1 | E56: 206 | F56: =ROUND(Source!T35,O56) -> 0 | G56: ВозврМат | H56: Возврат материалов | K56: 206 | L56: 20 | M56: 3 | O56: 2 | P56: =ROUND(Source!DL35,O56) -> 0 | W56: 0 | X56: 1 | Y56: 0 | Z56: 0 | AA56: 1 | AB56: 0
A57: 50 | B57: 0 | C57: 0 | D57: 1 | E57: 207 | F57: =Source!U35 -> 3.558753 | G57: ТрудСтр | H57: Трудозатраты строителей | K57: 207 | L57: 21 | M57: 3 | O57: -1 | P57: =Source!DM35 -> 3.558753 | W57: 3.558753 | X57: 1 | Y57: 3.558753 | Z57: 3.558753 | AA57: 1 | AB57: 3.558753
A58: 50 | B58: 0 | C58: 0 | D58: 1 | E58: 208 | F58: =Source!V35 -> 0 | G58: ТрудМаш | H58: Трудозатраты машинистов | K58: 208 | L58: 22 | M58: 3 | O58: -1 | P58: =Source!DN35 -> 0 | W58: 0 | X58: 1 | Y58: 0 | Z58: 0 | AA58: 1 | AB58: 0
A59: 50 | B59: 0 | C59: 0 | D59: 1 | E59: 209 | F59: =ROUND(Source!W35,O59) -> 0 | G59: ТранспМат | H59: Транспорт материалов | K59: 209 | L59: 23 | M59: 3 | O59: 2 | P59: =ROUND(Source!DO35,O59) -> 0 | W59: 0 | X59: 1 | Y59: 0 | Z59: 0 | AA59: 1 | AB59: 0
A60: 50 | B60: 0 | C60: 0 | D60: 1 | E60: 233 | F60: =ROUND(Source!BD35,O60) -> 0 | G60: Перевозка | H60: Перевозка грузов | K60: 233 | L60: 24 | M60: 3 | O60: 2 | P60: =ROUND(Source!EV35,O60) -> 0 | W60: 0 | X60: 1 | Y60: 0 | Z60: 0 | AA60: 1 | AB60: 0
...

Sheet SourceObSm
A1: 0 | B1: Smeta.RU (495) 974-1589 | D1: _OBSM_ | F1: 0 | G1: 0 | H1: 0 | I1: Smeta.RU | K1: 1 | L1: 74563 | M1: 10 | N1: 12 | O1: 0 | P1: 0 | Q1: 3
A4: 1 | B4: 1 | C4: -1 | G4: Капитальный ремонт здания Государственного бюджетного общеобразовательного учреждения города Москвы "Школа №236" по адресу: г. Москва, улица Клязьминская, дом 7, корпус 4 | EC4: 0
A12: 1 | B12: 51 | C12: 0 | E12: 0 | G12: 02-01-06 Отопление | I12: 0 | J12: 2024-00272-00-0-ИОС4.1 | K12: 0 | L12: 0 | M12: 4098 | O12: 0 | P12: 0 | Q12: 0 | R12: 0 | S12: 0 | T12: 1 | V12: 0 | AB12: Соколова И.Н. | BB12: 0 | BH12: Сметные нормы списания | BI12: Коды ОКП для ТСН-2001 МГЭ Дополнение 80 | BJ12: 1 | BK12: 1 | BL12: 0 | BM12: 0 | BN12: 1 | BO12: 0 | BP12: 6 | BQ12: 2 | BR12: 1 | BS12: 1 | BT12: 0 | BU12: 0 | BV12: 0 | BW12: 0 | BX12: 0 | BZ12: Типовой расчет для ТСН-2001 МГЭ, Дополнение 80, ремонт (1) | CA12: Территориальные сметные нормативы для Москвы ТСН-2001 (МГЭ), дополнение 80 | CB12: Территориальные сметные нормативы для Москвы ТСН-2001 (МГЭ), дополнение 80 | CC12: Территориальные сметные нормативы для Москвы ТСН-2001 (МГЭ), дополнение 80 | CD12: Территориальные сметные нормативы для Москвы ТСН-2001 (МГЭ), дополнение 80 | CE12: Поправки для ТСН-2001 от 28.11.2025 г. доп.79 | CF12: 0 | CG12: 0 | CH12: 8200 | CK12: 80 | CQ12: Территориальные сметные нормативы для Москвы (ТСН-2001) | CR12: ТЕР | CS12: 41660 | CT12: 1 | CU12: 80 | CY12: 0 | EC12: 0
A14: 22 | B14: 1 | C14: 0 | D14: 60255011 | E14: 60255014 | F14: 2 | G14: 1
A16: 3 | B16: 1 | C16: 02-01-06 | D16: Отопление | E16: =ROUND((Source!P411)/1000,2) -> 13845.9 | F16: =ROUND((Source!P412)/1000,2) -> 326.58 | G16: =ROUND((Source!P403)/1000,2) -> 8.25 | H16: =ROUND((Source!P413)/1000+(Source!P414)/1000,2) -> 0 | I16: =E16+F16+G16+H16 -> 14180.73 | J16: =ROUND((Source!P409+Source!P408)/1000,2) -> 2272.56 | K16: 18632.72 | L16: 0 | M16: 0 | N16: =I16+L16+M16 -> 14180.73 | T16: =ROUND((Source!F411)/1000,2) -> 1065.26 | U16: =ROUND((Source!F412)/1000,2) -> 24.13 | V16: =ROUND((Source!F403)/1000,2) -> 1.32 | W16: =ROUND((Source!F413)/1000+(Source!F414)/1000,2) -> 0 | X16: =T16+U16+V16+W16 -> 1090.71 | Y16: =ROUND((Source!F409+Source!F408)/1000,2) -> 41.33 | Z16: 2001.41 | AA16: 0 | AB16: 0 | AC16: =X16+AA16+AB16 -> 1090.71 | AI16: 0 | AJ16: -1 | AN16: 0 | AT16: 10470155 | AU16: 8162569.1 | AV16: 0 | AW16: 8251.4 | AX16: 0 | AY16: 84260.64 | AZ16: 49238.05 | BA16: 2223324.9 | BB16: 13845897 | BC16: 326582.11 | BD16: 0 | BE16: 0 | BF16: 3249.222 | BG16: 0 | BH16: 0 | BI16: 2385779.5 | BJ16: 1324796.8 | BK16: 14180731 | BR16: 1023233.4 | BS16: 978175.47 | BT16: 0 | BU16: 1318.17 | BV16: 0 | BW16: 4626.47 | BX16: 895.4 | BY16: 40431.44 | BZ16: 1065264.4 | CA16: 24128.06 | CB16: 0 | CC16: 0 | CD16: 3249.222 | CE16: 0 | CF16: 0 | CG16: 43385.69 | CH16: 24091.61 | CI16: 1090710.7
A18: 51 | E18: 13845.9 | F18: 326.58 | G18: 8.25 | H18: 0 | I18: 14180.73 | J18: 2272.56 | K18: 18632.72 | L18: 0 | M18: 0 | N18: 14180.73 | T18: 1065.26 | U18: 24.13 | V18: 1.32 | W18: 0 | X18: 1090.71 | Y18: 41.33 | Z18: 2001.41 | AA18: 0 | AB18: 0 | AC18: 1090.71
A20: 50 | B20: 0 | C20: 0 | D20: 1 | E20: 201 | F20: 10470155 | G20: ПЗ | H20: Прямые затраты | K20: 201 | L20: 1 | M20: 3 | O20: 2 | P20: 1023233.4
A21: 50 | B21: 0 | C21: 0 | D21: 1 | E21: 202 | F21: 8162569.1 | G21: СтМатОб | H21: Стоимость материальных ресурсов (всего) | K21: 202 | L21: 2 | M21: 3 | O21: 2 | P21: 978175.47
A22: 50 | B22: 0 | C22: 0 | D22: 1 | E22: 222 | F22: 0 | G22: СтМатОбЗак | H22: Стоимость материалов и оборудования заказчика | K22: 222 | L22: 3 | M22: 3 | O22: 2 | P22: 0
A23: 50 | B23: 0 | C23: 0 | D23: 1 | E23: 225 | F23: 8162569.1 | G23: СтМатОбПод | H23: Стоимость материалов и оборудования подрядчика | K23: 225 | L23: 4 | M23: 3 | O23: 2 | P23: 978175.47
A24: 50 | B24: 0 | C24: 0 | D24: 1 | E24: 226 | F24: 8154317.7 | G24: СтМат | H24: Стоимость материалов (всего) | K24: 226 | L24: 5 | M24: 3 | O24: 2 | P24: 976857.3
A25: 50 | B25: 0 | C25: 0 | D25: 1 | E25: 227 | F25: 0 | G25: СтМатЗак | H25: Стоимость материалов заказчика | K25: 227 | L25: 6 | M25: 3 | O25: 2 | P25: 0
A26: 50 | B26: 0 | C26: 0 | D26: 1 | E26: 228 | F26: 8154317.7 | G26: СтМатПод | H26: Стоимость материалов подрядчика | K26: 228 | L26: 7 | M26: 3 | O26: 2 | P26: 976857.3
A27: 50 | B27: 0 | C27: 0 | D27: 1 | E27: 216 | F27: 8251.4 | G27: Оборуд | H27: Стоимость оборудования (всего) | K27: 216 | L27: 8 | M27: 3 | O27: 2 | P27: 1318.17
A28: 50 | B28: 0 | C28: 0 | D28: 1 | E28: 223 | F28: 0 | G28: ОборудЗак | H28: Стоимость оборудования заказчика | K28: 223 | L28: 9 | M28: 3 | O28: 2 | P28: 0
A29: 50 | B29: 0 | C29: 0 | D29: 1 | E29: 229 | F29: 8251.4 | G29: ОборудПод | H29: Стоимость оборудования подрядчика | K29: 229 | L29: 10 | M29: 3 | O29: 2 | P29: 1318.17
A30: 50 | B30: 0 | C30: 0 | D30: 1 | E30: 203 | F30: 84260.64 | G30: ЭММ | H30: Эксплуатация машин | K30: 203 | L30: 11 | M30: 3 | O30: 2 | P30: 4626.47
A31: 50 | B31: 0 | C31: 0 | D31: 1 | E31: 231 | F31: 0 | G31: ЭММсНРиСП | H31: Эксплуатация машин по ТСН-2001.16 | K31: 231 | L31: 12 | M31: 3 | O31: 2 | P31: 0
... A46: 50 | B46: 0 | C46: 0 | D46: 1 | E46: 224 | F46: 14180731 | G46: Всего | H46: Всего с НР и СП | K46: 224 | L46: 27 | M46: 3 | O46: 2 | P46: 1090710.7
A48: -1
A51: 75 | B51: Текущий уровень цен | C51: 2025 | D51: 3 | E51: 0 | G51: 0 | H51: 1 | I51: 1 | J51: 3 | K51: 0 | L51: 0 | M51: 1 | N51: 60255011 | O51: 1
A52: 1 | B52: Сборник индексов | C52: Коэффициенты к ТСН-2001 МГЭ Дополнение 80, ремонт | D52: 2025 | E52: 9 | F52: 1 | G52: 1 | H52: 0 | I52: 2 | J52: 1 | K52: 9.88 | L52: 7.66 | M52: 1 | N52: 1 | O52: 9.88 | P52: 7.66 | Q52: 1 | AA52: 217/80 | AN52: 60255012
A53: 1 | B53: Сборник индексов | C53: Коэффициенты к ТСН-2001.13-2 Дополнение 46 | D53: 2025 | E53: 7 | F53: 1 | G53: 1 | H53: 0 | I53: 2 | J53: 1 | K53: 1 | L53: 1 | M53: 1 | N53: 1 | O53: 1 | P53: 1 | Q53: 1 | AA53: 62/46 | AN53: 60255013
A54: 75 | B54: Базовый уровень цен | C54: 2000 | D54: 0 | E54: 1 | F54: 0 | G54: 0 | H54: 1 | I54: 1 | J54: 3 | K54: 0 | L54: 0 | M54: 0 | N54: 60255014 | O54: 2
A55: 1 | B55: Сборник индексов | C55: Коэффициенты к ТСН-2001 МГЭ Дополнение 80, ремонт | D55: 2000 | E55: 1 | F55: 1 | G55: 1 | H55: 0 | I55: 2 | J55: 1 | K55: 1 | L55: 1 | M55: 1 | N55: 1 | O55: 1 | P55: 1 | Q55: 1 | AA55: 0 | AN55: 60255015

Sheet SmtRes
A1: =ROW(Source!A28) -> 28 | B1: 60255014 | C1: 60255128 | D1: 58999254 | E1: 1080 | F1: 1 | G1: 1080 | H1: 1 | I1: 9999990008 | K1: Трудозатраты рабочих | L1: 1191 | N1: 1013 | O1: чел.-ч. | P1: чел.-ч. | Q1: 1 | W1: 0 | X1: 476480486 | Y1: =(AT1*1.1) -> 1.133 | AA1: 0 | AB1: 0 | AC1: 0 | AD1: 0 | AE1: 0 | AF1: 0 | AG1: 0 | AH1: 0 | AI1: 1 | AJ1: 1 | AK1: 1 | AL1: 1 | AM1: -2 | AN1: 0 | AO1: 1 | AP1: 1 | AQ1: 0 | AR1: 0 | AT1: 1.03 | AU1: *1,1 | AV1: 1 | AW1: 2 | AX1: 60255866 | AY1: 1 | AZ1: 0 | BA1: 1 | BB1: 0 | BC1: 0 | BD1: 0 | BE1: 0 | BF1: 0 | BG1: 0 | BH1: 0 | BI1: 0 | BJ1: 0 | BK1: 0 | BL1: 0 | BM1: 0 | BN1: 0 | BO1: 0 | BP1: 0 | BQ1: 0 | BR1: 0 | BS1: 0 | BT1: 0 | BU1: 0 | BV1: 0 | BW1: 0 | CU1: =ROUND(AT1*Source!I28*AH1*AL1,2) -> 0 | CV1: =ROUND(Y1*Source!I28,9) -> 3.399 | CW1: 0 | CX1: =ROUND(Y1*Source!I28,9) -> 3.399 | CY1: =AD1 -> 0 | CZ1: =AH1 -> 0 | DA1: =AL1 -> 1 | DB1: =ROUND((ROUND(AT1*CZ1,2)*1.1),6) -> 0 | DC1: =ROUND((ROUND(AT1*AG1,2)*1.1),6) -> 0 | DF1: =ROUND(ROUND(AE1,2)*CX1,2) -> 0 | DG1: =ROUND(ROUND(AF1,2)*CX1,2) -> 0 | DH1: =ROUND(ROUND(AG1,2)*CX1,2) -> 0 | DI1: =ROUND(ROUND(AH1,2)*CX1,2) -> 0 | DJ1: =DI1 -> 0 | DK1: 0 | DM1: 0 | DO1: 0
A2: =ROW(Source!A28) -> 28 | B2: 60255014 | C2: 60255128 | D2: 59070669 | E2: 1 | F2: 1 | G2: 1080 | H2: 2 | I2: 2.1-18-7 | J2: ТСН-2001.2. Доп. 68. п.1-18-7 (183001) | K2: Автомобили грузовые бортовые, грузоподъемность до 5 т | L2: 1368 | N2: 1011 | O2: маш.-ч | P2: маш.-ч | Q2: 1 | W2: 0 | X2: -1985943078 | Y2: =(AT2*1.1) -> 0.011 | AA2: 0 | AB2: 87.01 | AC2: 13.21 | AD2: 0 | AE2: 0 | AF2: 83.1 | AG2: 12.62 | AH2: 0 | AI2: 1 | AJ2: 1 | AK2: 1 | AL2: 1 | AM2: -2 | AN2: 0 | AO2: 1 | AP2: 1 | AQ2: 0 | AR2: 0 | AT2: 0.01 | AU2: *1,1 | AV2: 0 | AW2: 2 | AX2: 60255867 | AY2: 1 | AZ2: 0 | BA2: 2 | BB2: 0 | BC2: 0 | BD2: 0 | BE2: 0 | BF2: 0 | BG2: 0 | BH2: 0 | BI2: 0 | BJ2: 0 | BK2: 0 | BL2: 0 | BM2: 0 | BN2: 0 | BO2: 0 | BP2: 0 | BQ2: 0 | BR2: 0 | BS2: 0 | BT2: 0 | BU2: 0 | BV2: 0 | BW2: 0 | CV2: 0 | CW2: =ROUND(Y2*Source!I28*DO2,9) -> 0.41646 | CX2: =ROUND(Y2*Source!I28,9) -> 0.033 | CY2: =AB2 -> 87.01 | CZ2: =AF2 -> 83.1 | DA2: =AJ2 -> 1 | DB2: =ROUND((ROUND(AT2*CZ2,2)*1.1),6) -> 0.913 | DC2: =ROUND((ROUND(AT2*AG2,2)*1.1),6) -> 0.143 | DF2: =ROUND(ROUND(AE2,2)*CX2,2) -> 0 | DG2: =ROUND(ROUND(AF2,2)*CX2,2) -> 2.74 | DH2: =ROUND(ROUND(AG2,2)*CX2,2) -> 0.42 | DI2: =ROUND(ROUND(AH2,2)*CX2,2) -> 0 | DJ2: =DG2 -> 2.74 | DK2: 0 | DL2: 9999990009 | DM2: 0 | DN2: чел.-ч. | DO2: 12.62
